{
  "version": 8,
  "blockIdVersion": 10,
  "anchorX": 0,
  "anchorY": 13,
  "anchorZ": 0,
  "blocks": [
    {
      "x": -50,
      "y": 0,
      "z": 4,
      "name": "Soil_Clay_Green"
    },
    {
      "x": -50,
      "y": 0,
      "z": 5,
      "name": "Soil_Clay_Green"
    },
    {
      "x": -50,
      "y": 29,
      "z": 10,
      "name": "Soil_Clay_Green"
    },
    {
      "x": -50,
      "y": 30,
      "z": 10,
      "name": "Soil_Seaweed_Block"
    },
    {
      "x": -50,
      "y": 31,
      "z": 10,
      "name": "Soil_Clay_Lime"
    },
    {
      "x": -50,
      "y": 32,
      "z": 10,
      "name": "Plant_Grass_Sharp"
    },
    {
      "x": -50,
      "y": 29,
      "z": 11,
      "name": "Soil_Clay_Green"
    },
    {
      "x": -50,
      "y": 30,
      "z": 11,
      "name": "Soil_Seaweed_Block"
    },
    {
      "x": -50,
      "y": 31,
      "z": 11,
      "name": "Soil_Clay_Lime"
    },
    {
      "x": -50,
      "y": 32,
      "z": 11,
      "name": "Plant_Grass_Sharp"
    },
    {
      "x": -50,
      "y": 29,
      "z": 12,
      "name": "Soil_Clay_Green"
    },
    {
      "x": -50,
      "y": 30,
      "z": 12,
      "name": "Soil_Seaweed_Block"
    },
    {
      "x": -49,
      "y": 0,
      "z": 3,
      "name": "Soil_Clay_Green"
    },
    {
      "x": -49,
      "y": 0,
      "z": 4,
      "name": "Soil_Clay_Green"
    },
    {
      "x": -49,
      "y": 28,
      "z": 10,
      "name": "Soil_Clay_Green"
    },
    {
      "x": -49,
      "y": 29,
      "z": 10,
      "name": "Soil_Clay_Green"
    },
    {
      "x": -49,
      "y": 30,
      "z": 10,
      "name": "Soil_Clay_Lime"
    },
    {
      "x": -49,
      "y": 31,
      "z": 10,
      "name": "Plant_Grass_Sharp"
    },
    {
      "x": -49,
      "y": 28,
      "z": 11,
      "name": "Soil_Clay_Green"
    },
    {
      "x": -49,
      "y": 29,
      "z": 11,
      "name": "Soil_Seaweed_Block"
    },
    {
      "x": -49,
      "y": 30,
      "z": 11,
      "name": "Soil_Clay_Lime"
    },
    {
      "x": -49,
      "y": 31,
      "z": 11,
      "name": "Plant_Grass_Sharp"
    },
    {
      "x": -49,
      "y": 29,
      "z": 12,
      "name": "Soil_Clay_Green"
    },
    {
      "x": -49,
      "y": 30,
      "z": 12,
      "name": "Soil_Seaweed_Block"
    },
    {
      "x": -49,
      "y": 10,
      "z": 20,
      "name": "Soil_Clay_Green"
    },
    {
      "x": -48,
      "y": 0,
      "z": 3,
      "name": "Soil_Clay_Green"
    },
    {
      "x": -48,
      "y": 28,
      "z": 9,
      "name": "Soil_Clay_Green"
    },
    {
      "x": -48,
      "y": 29,
      "z": 9,
      "name": "Soil_Clay_Green"
    },
    {
      "x": -48,
      "y": 30,
      "z": 9,
      "name": "Soil_Seaweed_Block"
    },
    {
      "x": -48,
      "y": 28,
      "z": 10,
      "name": "Soil_Clay_Green"
    },
    {
      "x": -48,
      "y": 29,
      "z": 10,
      "name": "Soil_Seaweed_Block"
    },
    {
      "x": -48,
      "y": 30,
      "z": 10,
      "name": "Soil_Clay_Lime"
    },
    {
      "x": -48,
      "y": 31,
      "z": 10,
      "name": "Plant_Grass_Sharp"
    },
    {
      "x": -48,
      "y": 27,
      "z": 11,
      "name": "Soil_Clay_Green"
    },
    {
      "x": -48,
      "y": 28,
      "z": 11,
      "name": "Soil_Clay_Green"
    },
    {
      "x": -48,
      "y": 29,
      "z": 11,
      "name": "Soil_Clay_Lime"
    },
    {
      "x": -48,
      "y": 30,
      "z": 11,
      "name": "Soil_Clay_Lime"
    },
    {
      "x": -48,
      "y": 31,
      "z": 11,
      "name": "Plant_Grass_Sharp"
    },
    {
      "x": -48,
      "y": 11,
      "z": 18,
      "name": "Soil_Clay_Green"
    },
    {
      "x": -48,
      "y": 10,
      "z": 19,
      "name": "Soil_Clay_Green"
    },
    {
      "x": -48,
      "y": 11,
      "z": 19,
      "name": "Soil_Clay_Green"
    },
    {
      "x": -47,
      "y": 0,
      "z": 3,
      "name": "Soil_Clay_Green"
    },
    {
      "x": -47,
      "y": 1,
      "z": 3,
      "name": "Soil_Seaweed_Block"
    },
    {
      "x": -47,
      "y": 0,
      "z": 4,
      "name": "Soil_Clay_Green"
    },
    {
      "x": -47,
      "y": 1,
      "z": 4,
      "name": "Soil_Seaweed_Block"
    },
    {
      "x": -47,
      "y": 31,
      "z": 7,
      "name": "Soil_Clay_Green"
    },
    {
      "x": -47,
      "y": 30,
      "z": 8,
      "name": "Soil_Seaweed_Block"
    },
    {
      "x": -47,
      "y": 31,
      "z": 8,
      "name": "Soil_Clay_Lime"
    },
    {
      "x": -47,
      "y": 32,
      "z": 8,
      "name": "Plant_Grass_Sharp"
    },
    {
      "x": -47,
      "y": 29,
      "z": 9,
      "name": "Soil_Seaweed_Block"
    },
    {
      "x": -47,
      "y": 30,
      "z": 9,
      "name": "Soil_Clay_Lime"
    },
    {
      "x": -47,
      "y": 31,
      "z": 9,
      "name": "Plant_Grass_Sharp"
    },
    {
      "x": -47,
      "y": 27,
      "z": 10,
      "name": "Soil_Clay_Green"
    },
    {
      "x": -47,
      "y": 28,
      "z": 10,
      "name": "Soil_Clay_Green"
    },
    {
      "x": -47,
      "y": 29,
      "z": 10,
      "name": "Soil_Clay_Lime"
    },
    {
      "x": -47,
      "y": 30,
      "z": 10,
      "name": "Soil_Clay_Lime"
    },
    {
      "x": -47,
      "y": 31,
      "z": 10,
      "name": "Plant_Grass_Sharp"
    },
    {
      "x": -47,
      "y": 26,
      "z": 11,
      "name": "Soil_Clay_Green"
    },
    {
      "x": -47,
      "y": 27,
      "z": 11,
      "name": "Soil_Seaweed_Block"
    },
    {
      "x": -47,
      "y": 28,
      "z": 11,
      "name": "Soil_Seaweed_Block"
    },
    {
      "x": -47,
      "y": 29,
      "z": 11,
      "name": "Soil_Clay_Lime"
    },
    {
      "x": -47,
      "y": 30,
      "z": 11,
      "name": "Plant_Grass_Sharp"
    },
    {
      "x": -47,
      "y": 27,
      "z": 12,
      "name": "Soil_Clay_Green"
    },
    {
      "x": -47,
      "y": 28,
      "z": 12,
      "name": "Soil_Seaweed_Block"
    },
    {
      "x": -47,
      "y": 12,
      "z": 18,
      "name": "Soil_Seaweed_Block"
    },
    {
      "x": -47,
      "y": 11,
      "z": 19,
      "name": "Soil_Clay_Green"
    },
    {
      "x": -47,
      "y": 12,
      "z": 19,
      "name": "Soil_Seaweed_Block"
    },
    {
      "x": -46,
      "y": 29,
      "z": 0,
      "name": "Soil_Clay_Green"
    },
    {
      "x": -46,
      "y": 30,
      "z": 0,
      "name": "Soil_Clay_Green"
    },
    {
      "x": -46,
      "y": 30,
      "z": 1,
      "name": "Soil_Clay_Green"
    },
    {
      "x": -46,
      "y": 31,
      "z": 1,
      "name": "Soil_Seaweed_Block"
    },
    {
      "x": -46,
      "y": 31,
      "z": 2,
      "name": "Soil_Clay_Green"
    },
    {
      "x": -46,
      "y": 32,
      "z": 2,
      "name": "Soil_Clay_Lime"
    },
    {
      "x": -46,
      "y": 33,
      "z": 2,
      "name": "Plant_Grass_Sharp"
    },
    {
      "x": -46,
      "y": 31,
      "z": 3,
      "name": "Soil_Clay_Green"
    },
    {
      "x": -46,
      "y": 32,
      "z": 3,
      "name": "Soil_Clay_Lime"
    },
    {
      "x": -46,
      "y": 33,
      "z": 3,
      "name": "Plant_Grass_Sharp"
    },
    {
      "x": -46,
      "y": 1,
      "z": 4,
      "name": "Soil_Clay_Green"
    },
    {
      "x": -46,
      "y": 32,
      "z": 4,
      "name": "Soil_Clay_Green"
    },
    {
      "x": -46,
      "y": 33,
      "z": 4,
      "name": "Soil_Clay_Lime"
    },
    {
      "x": -46,
      "y": 34,
      "z": 4,
      "name": "Plant_Grass_Sharp"
    },
    {
      "x": -46,
      "y": 32,
      "z": 5,
      "name": "Soil_Clay_Green"
    },
    {
      "x": -46,
      "y": 33,
      "z": 5,
      "name": "Soil_Clay_Lime"
    },
    {
      "x": -46,
      "y": 34,
      "z": 5,
      "name": "Plant_Grass_Sharp"
    },
    {
      "x": -46,
      "y": 31,
      "z": 6,
      "name": "Soil_Clay_Green"
    },
    {
      "x": -46,
      "y": 32,
      "z": 6,
      "name": "Soil_Seaweed_Block"
    },
    {
      "x": -46,
      "y": 33,
      "z": 6,
      "name": "Soil_Clay_Lime"
    },
    {
      "x": -46,
      "y": 34,
      "z": 6,
      "name": "Plant_Grass_Sharp"
    },
    {
      "x": -46,
      "y": 31,
      "z": 7,
      "name": "Soil_Clay_Green"
    },
    {
      "x": -46,
      "y": 32,
      "z": 7,
      "name": "Soil_Clay_Lime"
    },
    {
      "x": -46,
      "y": 33,
      "z": 7,
      "name": "Soil_Clay_Lime"
    },
    {
      "x": -46,
      "y": 34,
      "z": 7,
      "name": "Plant_Grass_Sharp"
    },
    {
      "x": -46,
      "y": 31,
      "z": 8,
      "name": "Soil_Seaweed_Block"
    },
    {
      "x": -46,
      "y": 26,
      "z": 10,
      "name": "Soil_Clay_Green"
    },
    {
      "x": -46,
      "y": 27,
      "z": 10,
      "name": "Soil_Clay_Green"
    },
    {
      "x": -46,
      "y": 28,
      "z": 10,
      "name": "Soil_Seaweed_Block"
    },
    {
      "x": -46,
      "y": 26,
      "z": 11,
      "name": "Soil_Clay_Green"
    },
    {
      "x": -46,
      "y": 27,
      "z": 11,
      "name": "Soil_Seaweed_Block"
    },
    {
      "x": -46,
      "y": 28,
      "z": 11,
      "name": "Soil_Clay_Lime"
    },
    {
      "x": -46,
      "y": 29,
      "z": 11,
      "name": "Plant_Grass_Sharp"
    },
    {
      "x": -46,
      "y": 26,
      "z": 12,
      "name": "Soil_Clay_Green"
    },
    {
      "x": -46,
      "y": 27,
      "z": 12,
      "name": "Soil_Seaweed_Block"
    },
    {
      "x": -46,
      "y": 28,
      "z": 12,
      "name": "Soil_Clay_Lime"
    },
    {
      "x": -46,
      "y": 29,
      "z": 12,
      "name": "Plant_Grass_Sharp"
    },
    {
      "x": -46,
      "y": 26,
      "z": 13,
      "name": "Soil_Clay_Green"
    },
    {
      "x": -46,
      "y": 27,
      "z": 13,
      "name": "Soil_Seaweed_Block"
    },
    {
      "x": -46,
      "y": 12,
      "z": 18,
      "name": "Soil_Clay_Green"
    },
    {
      "x": -46,
      "y": 13,
      "z": 18,
      "name": "Soil_Seaweed_Block"
    },
    {
      "x": -46,
      "y": 12,
      "z": 19,
      "name": "Soil_Clay_Green"
    },
    {
      "x": -45,
      "y": 2,
      "z": 3,
      "name": "Soil_Clay_Lime"
    },
    {
      "x": -45,
      "y": 3,
      "z": 3,
      "name": "Plant_Grass_Sharp"
    },
    {
      "x": -45,
      "y": 1,
      "z": 4,
      "name": "Soil_Clay_Green"
    },
    {
      "x": -45,
      "y": 2,
      "z": 4,
      "name": "Soil_Clay_Lime"
    },
    {
      "x": -45,
      "y": 3,
      "z": 4,
      "name": "Plant_Grass_Sharp"
    },
    {
      "x": -45,
      "y": 27,
      "z": 10,
      "name": "Soil_Clay_Green"
    },
    {
      "x": -45,
      "y": 26,
      "z": 11,
      "name": "Soil_Clay_Green"
    },
    {
      "x": -45,
      "y": 27,
      "z": 11,
      "name": "Soil_Seaweed_Block"
    },
    {
      "x": -45,
      "y": 28,
      "z": 11,
      "name": "Soil_Clay_Lime"
    },
    {
      "x": -45,
      "y": 29,
      "z": 11,
      "name": "Plant_Grass_Sharp"
    },
    {
      "x": -45,
      "y": 25,
      "z": 12,
      "name": "Soil_Clay_Green"
    },
    {
      "x": -45,
      "y": 26,
      "z": 12,
      "name": "Soil_Seaweed_Block"
    },
    {
      "x": -45,
      "y": 27,
      "z": 12,
      "name": "Soil_Seaweed_Block"
    },
    {
      "x": -45,
      "y": 28,
      "z": 12,
      "name": "Soil_Clay_Lime"
    },
    {
      "x": -45,
      "y": 29,
      "z": 12,
      "name": "Plant_Grass_Sharp"
    },
    {
      "x": -45,
      "y": 25,
      "z": 13,
      "name": "Soil_Clay_Green"
    },
    {
      "x": -45,
      "y": 26,
      "z": 13,
      "name": "Soil_Seaweed_Block"
    },
    {
      "x": -45,
      "y": 27,
      "z": 13,
      "name": "Soil_Seaweed_Block"
    },
    {
      "x": -45,
      "y": 26,
      "z": 14,
      "name": "Soil_Clay_Green"
    },
    {
      "x": -45,
      "y": 27,
      "z": 14,
      "name": "Soil_Seaweed_Block"
    },
    {
      "x": -45,
      "y": 12,
      "z": 17,
      "name": "Soil_Clay_Green"
    },
    {
      "x": -45,
      "y": 13,
      "z": 17,
      "name": "Soil_Clay_Green"
    },
    {
      "x": -45,
      "y": 12,
      "z": 18,
      "name": "Soil_Clay_Green"
    },
    {
      "x": -45,
      "y": 13,
      "z": 18,
      "name": "Soil_Clay_Green"
    },
    {
      "x": -45,
      "y": 14,
      "z": 18,
      "name": "Soil_Seaweed_Block"
    },
    {
      "x": -45,
      "y": 25,
      "z": 26,
      "name": "Soil_Clay_Green"
    },
    {
      "x": -45,
      "y": 26,
      "z": 26,
      "name": "Soil_Clay_Green"
    },
    {
      "x": -45,
      "y": 27,
      "z": 26,
      "name": "Soil_Clay_Lime"
    },
    {
      "x": -45,
      "y": 28,
      "z": 26,
      "name": "Plant_Grass_Sharp"
    },
    {
      "x": -44,
      "y": 1,
      "z": 3,
      "name": "Soil_Clay_Green"
    },
    {
      "x": -44,
      "y": 2,
      "z": 3,
      "name": "Soil_Clay_Lime"
    },
    {
      "x": -44,
      "y": 3,
      "z": 3,
      "name": "Plant_Grass_Sharp"
    },
    {
      "x": -44,
      "y": 1,
      "z": 4,
      "name": "Soil_Clay_Green"
    },
    {
      "x": -44,
      "y": 2,
      "z": 4,
      "name": "Soil_Seaweed_Block"
    },
    {
      "x": -44,
      "y": 26,
      "z": 11,
      "name": "Soil_Clay_Green"
    },
    {
      "x": -44,
      "y": 27,
      "z": 11,
      "name": "Soil_Seaweed_Block"
    },
    {
      "x": -44,
      "y": 25,
      "z": 12,
      "name": "Soil_Clay_Green"
    },
    {
      "x": -44,
      "y": 26,
      "z": 12,
      "name": "Soil_Seaweed_Block"
    },
    {
      "x": -44,
      "y": 27,
      "z": 12,
      "name": "Soil_Seaweed_Block"
    },
    {
      "x": -44,
      "y": 28,
      "z": 12,
      "name": "Soil_Clay_Lime"
    },
    {
      "x": -44,
      "y": 29,
      "z": 12,
      "name": "Plant_Grass_Sharp"
    },
    {
      "x": -44,
      "y": 25,
      "z": 13,
      "name": "Soil_Clay_Green"
    },
    {
      "x": -44,
      "y": 26,
      "z": 13,
      "name": "Soil_Seaweed_Block"
    },
    {
      "x": -44,
      "y": 27,
      "z": 13,
      "name": "Soil_Clay_Lime"
    },
    {
      "x": -44,
      "y": 28,
      "z": 13,
      "name": "Plant_Grass_Sharp"
    },
    {
      "x": -44,
      "y": 26,
      "z": 14,
      "name": "Soil_Seaweed_Block"
    },
    {
      "x": -44,
      "y": 27,
      "z": 14,
      "name": "Soil_Seaweed_Block"
    },
    {
      "x": -44,
      "y": 13,
      "z": 17,
      "name": "Soil_Clay_Green"
    },
    {
      "x": -44,
      "y": 14,
      "z": 17,
      "name": "Soil_Clay_Green"
    },
    {
      "x": -44,
      "y": 15,
      "z": 17,
      "name": "Soil_Seaweed_Block"
    },
    {
      "x": -44,
      "y": 13,
      "z": 18,
      "name": "Soil_Clay_Green"
    },
    {
      "x": -44,
      "y": 14,
      "z": 18,
      "name": "Soil_Seaweed_Block"
    },
    {
      "x": -44,
      "y": 15,
      "z": 18,
      "name": "Soil_Seaweed_Block"
    },
    {
      "x": -44,
      "y": 16,
      "z": 18,
      "name": "Soil_Seaweed_Block"
    },
    {
      "x": -44,
      "y": 13,
      "z": 19,
      "name": "Soil_Clay_Green"
    },
    {
      "x": -44,
      "y": 14,
      "z": 19,
      "name": "Soil_Clay_Green"
    },
    {
      "x": -44,
      "y": 15,
      "z": 19,
      "name": "Soil_Seaweed_Block"
    },
    {
      "x": -44,
      "y": 28,
      "z": 21,
      "name": "Soil_Seaweed_Block"
    },
    {
      "x": -44,
      "y": 28,
      "z": 22,
      "name": "Soil_Clay_Green"
    },
    {
      "x": -44,
      "y": 29,
      "z": 22,
      "name": "Soil_Clay_Lime"
    },
    {
      "x": -44,
      "y": 30,
      "z": 22,
      "name": "Plant_Grass_Sharp"
    },
    {
      "x": -44,
      "y": 28,
      "z": 23,
      "name": "Soil_Seaweed_Block"
    },
    {
      "x": -44,
      "y": 29,
      "z": 23,
      "name": "Soil_Clay_Lime"
    },
    {
      "x": -44,
      "y": 30,
      "z": 23,
      "name": "Plant_Grass_Sharp"
    },
    {
      "x": -44,
      "y": 27,
      "z": 24,
      "name": "Soil_Clay_Green"
    },
    {
      "x": -44,
      "y": 26,
      "z": 25,
      "name": "Soil_Clay_Green"
    },
    {
      "x": -44,
      "y": 27,
      "z": 25,
      "name": "Soil_Seaweed_Block"
    },
    {
      "x": -44,
      "y": 26,
      "z": 26,
      "name": "Soil_Clay_Green"
    },
    {
      "x": -44,
      "y": 27,
      "z": 26,
      "name": "Soil_Clay_Lime"
    },
    {
      "x": -44,
      "y": 28,
      "z": 26,
      "name": "Plant_Grass_Sharp"
    },
    {
      "x": -43,
      "y": 1,
      "z": 2,
      "name": "Soil_Clay_Green"
    },
    {
      "x": -43,
      "y": 1,
      "z": 3,
      "name": "Soil_Clay_Green"
    },
    {
      "x": -43,
      "y": 2,
      "z": 3,
      "name": "Soil_Clay_Lime"
    },
    {
      "x": -43,
      "y": 3,
      "z": 3,
      "name": "Plant_Grass_Sharp"
    },
    {
      "x": -43,
      "y": 1,
      "z": 4,
      "name": "Soil_Clay_Green"
    },
    {
      "x": -43,
      "y": 2,
      "z": 4,
      "name": "Soil_Seaweed_Block"
    },
    {
      "x": -43,
      "y": 24,
      "z": 12,
      "name": "Soil_Clay_Green"
    },
    {
      "x": -43,
      "y": 25,
      "z": 12,
      "name": "Soil_Clay_Green"
    },
    {
      "x": -43,
      "y": 26,
      "z": 12,
      "name": "Soil_Seaweed_Block"
    },
    {
      "x": -43,
      "y": 27,
      "z": 12,
      "name": "Soil_Clay_Lime"
    },
    {
      "x": -43,
      "y": 28,
      "z": 12,
      "name": "Plant_Grass_Sharp"
    },
    {
      "x": -43,
      "y": 24,
      "z": 13,
      "name": "Soil_Clay_Green"
    },
    {
      "x": -43,
      "y": 25,
      "z": 13,
      "name": "Soil_Seaweed_Block"
    },
    {
      "x": -43,
      "y": 26,
      "z": 13,
      "name": "Soil_Seaweed_Block"
    },
    {
      "x": -43,
      "y": 27,
      "z": 13,
      "name": "Soil_Clay_Lime"
    },
    {
      "x": -43,
      "y": 28,
      "z": 13,
      "name": "Plant_Grass_Sharp"
    },
    {
      "x": -43,
      "y": 25,
      "z": 14,
      "name": "Soil_Clay_Green"
    },
    {
      "x": -43,
      "y": 26,
      "z": 14,
      "name": "Soil_Seaweed_Block"
    },
    {
      "x": -43,
      "y": 27,
      "z": 14,
      "name": "Soil_Clay_Lime"
    },
    {
      "x": -43,
      "y": 28,
      "z": 14,
      "name": "Plant_Grass_Sharp"
    },
    {
      "x": -43,
      "y": 17,
      "z": 16,
      "name": "Soil_Seaweed_Block"
    },
    {
      "x": -43,
      "y": 14,
      "z": 17,
      "name": "Soil_Clay_Green"
    },
    {
      "x": -43,
      "y": 15,
      "z": 17,
      "name": "Soil_Clay_Green"
    },
    {
      "x": -43,
      "y": 16,
      "z": 17,
      "name": "Soil_Seaweed_Block"
    },
    {
      "x": -43,
      "y": 17,
      "z": 17,
      "name": "Soil_Seaweed_Block"
    },
    {
      "x": -43,
      "y": 13,
      "z": 18,
      "name": "Soil_Clay_Green"
    },
    {
      "x": -43,
      "y": 14,
      "z": 18,
      "name": "Soil_Clay_Green"
    },
    {
      "x": -43,
      "y": 15,
      "z": 18,
      "name": "Soil_Seaweed_Block"
    },
    {
      "x": -43,
      "y": 16,
      "z": 18,
      "name": "Soil_Seaweed_Block"
    },
    {
      "x": -43,
      "y": 17,
      "z": 18,
      "name": "Soil_Seaweed_Block"
    },
    {
      "x": -43,
      "y": 14,
      "z": 19,
      "name": "Soil_Clay_Green"
    },
    {
      "x": -43,
      "y": 15,
      "z": 19,
      "name": "Soil_Seaweed_Block"
    },
    {
      "x": -43,
      "y": 27,
      "z": 19,
      "name": "Soil_Seaweed_Block"
    },
    {
      "x": -43,
      "y": 28,
      "z": 20,
      "name": "Soil_Clay_Lime"
    },
    {
      "x": -43,
      "y": 29,
      "z": 20,
      "name": "Plant_Grass_Sharp"
    },
    {
      "x": -43,
      "y": 28,
      "z": 21,
      "name": "Soil_Seaweed_Block"
    },
    {
      "x": -43,
      "y": 28,
      "z": 22,
      "name": "Soil_Clay_Green"
    },
    {
      "x": -42,
      "y": 1,
      "z": 1,
      "name": "Soil_Clay_Green"
    },
    {
      "x": -42,
      "y": 46,
      "z": 1,
      "name": "Soil_Seaweed_Block"
    },
    {
      "x": -42,
      "y": 1,
      "z": 2,
      "name": "Soil_Clay_Green"
    },
    {
      "x": -42,
      "y": 2,
      "z": 2,
      "name": "Soil_Clay_Lime"
    },
    {
      "x": -42,
      "y": 3,
      "z": 2,
      "name": "Plant_Grass_Sharp"
    },
    {
      "x": -42,
      "y": 0,
      "z": 3,
      "name": "Soil_Clay_Green"
    },
    {
      "x": -42,
      "y": 1,
      "z": 3,
      "name": "Soil_Seaweed_Block"
    },
    {
      "x": -42,
      "y": 2,
      "z": 3,
      "name": "Soil_Clay_Lime"
    },
    {
      "x": -42,
      "y": 3,
      "z": 3,
      "name": "Plant_Grass_Sharp"
    },
    {
      "x": -42,
      "y": 1,
      "z": 4,
      "name": "Soil_Clay_Green"
    },
    {
      "x": -42,
      "y": 2,
      "z": 4,
      "name": "Soil_Clay_Lime"
    },
    {
      "x": -42,
      "y": 3,
      "z": 4,
      "name": "Plant_Grass_Sharp"
    },
    {
      "x": -42,
      "y": 23,
      "z": 11,
      "name": "Soil_Clay_Green"
    },
    {
      "x": -42,
      "y": 23,
      "z": 12,
      "name": "Soil_Clay_Green"
    },
    {
      "x": -42,
      "y": 24,
      "z": 12,
      "name": "Soil_Clay_Green"
    },
    {
      "x": -42,
      "y": 25,
      "z": 12,
      "name": "Soil_Seaweed_Block"
    },
    {
      "x": -42,
      "y": 26,
      "z": 12,
      "name": "Soil_Seaweed_Block"
    },
    {
      "x": -42,
      "y": 27,
      "z": 12,
      "name": "Soil_Clay_Lime"
    },
    {
      "x": -42,
      "y": 28,
      "z": 12,
      "name": "Plant_Grass_Sharp"
    },
    {
      "x": -42,
      "y": 23,
      "z": 13,
      "name": "Soil_Clay_Green"
    },
    {
      "x": -42,
      "y": 24,
      "z": 13,
      "name": "Soil_Seaweed_Block"
    },
    {
      "x": -42,
      "y": 25,
      "z": 13,
      "name": "Soil_Seaweed_Block"
    },
    {
      "x": -42,
      "y": 26,
      "z": 13,
      "name": "Soil_Seaweed_Block"
    },
    {
      "x": -42,
      "y": 27,
      "z": 13,
      "name": "Soil_Clay_Lime"
    },
    {
      "x": -42,
      "y": 28,
      "z": 13,
      "name": "Plant_Grass_Sharp"
    },
    {
      "x": -42,
      "y": 23,
      "z": 14,
      "name": "Soil_Clay_Green"
    },
    {
      "x": -42,
      "y": 24,
      "z": 14,
      "name": "Soil_Clay_Green"
    },
    {
      "x": -42,
      "y": 25,
      "z": 14,
      "name": "Soil_Seaweed_Block"
    },
    {
      "x": -42,
      "y": 26,
      "z": 14,
      "name": "Soil_Seaweed_Block"
    },
    {
      "x": -42,
      "y": 27,
      "z": 14,
      "name": "Soil_Clay_Lime"
    },
    {
      "x": -42,
      "y": 28,
      "z": 14,
      "name": "Plant_Grass_Sharp"
    },
    {
      "x": -42,
      "y": 24,
      "z": 15,
      "name": "Soil_Clay_Green"
    },
    {
      "x": -42,
      "y": 25,
      "z": 15,
      "name": "Soil_Seaweed_Block"
    },
    {
      "x": -42,
      "y": 26,
      "z": 15,
      "name": "Soil_Clay_Lime"
    },
    {
      "x": -42,
      "y": 27,
      "z": 15,
      "name": "Plant_Grass_Sharp"
    },
    {
      "x": -42,
      "y": 16,
      "z": 16,
      "name": "Soil_Clay_Green"
    },
    {
      "x": -42,
      "y": 17,
      "z": 16,
      "name": "Soil_Seaweed_Block"
    },
    {
      "x": -42,
      "y": 18,
      "z": 16,
      "name": "Soil_Seaweed_Block"
    },
    {
      "x": -42,
      "y": 15,
      "z": 17,
      "name": "Soil_Clay_Green"
    },
    {
      "x": -42,
      "y": 16,
      "z": 17,
      "name": "Soil_Seaweed_Block"
    },
    {
      "x": -42,
      "y": 17,
      "z": 17,
      "name": "Soil_Seaweed_Block"
    },
    {
      "x": -42,
      "y": 18,
      "z": 17,
      "name": "Soil_Seaweed_Block"
    },
    {
      "x": -42,
      "y": 15,
      "z": 18,
      "name": "Soil_Clay_Green"
    },
    {
      "x": -42,
      "y": 16,
      "z": 18,
      "name": "Soil_Clay_Green"
    },
    {
      "x": -42,
      "y": 17,
      "z": 18,
      "name": "Soil_Seaweed_Block"
    },
    {
      "x": -42,
      "y": 26,
      "z": 18,
      "name": "Soil_Clay_Green"
    },
    {
      "x": -42,
      "y": 27,
      "z": 18,
      "name": "Soil_Clay_Lime"
    },
    {
      "x": -42,
      "y": 28,
      "z": 18,
      "name": "Plant_Grass_Sharp"
    },
    {
      "x": -42,
      "y": 26,
      "z": 19,
      "name": "Soil_Clay_Green"
    },
    {
      "x": -42,
      "y": 27,
      "z": 19,
      "name": "Soil_Seaweed_Block"
    },
    {
      "x": -41,
      "y": 46,
      "z": 0,
      "name": "Soil_Seaweed_Block"
    },
    {
      "x": -41,
      "y": 1,
      "z": 1,
      "name": "Soil_Seaweed_Block"
    },
    {
      "x": -41,
      "y": 45,
      "z": 1,
      "name": "Soil_Seaweed_Block"
    },
    {
      "x": -41,
      "y": 46,
      "z": 1,
      "name": "Soil_Clay_Lime"
    },
    {
      "x": -41,
      "y": 47,
      "z": 1,
      "name": "Plant_Grass_Sharp"
    },
    {
      "x": -41,
      "y": 0,
      "z": 2,
      "name": "Soil_Clay_Green"
    },
    {
      "x": -41,
      "y": 1,
      "z": 2,
      "name": "Soil_Seaweed_Block"
    },
    {
      "x": -41,
      "y": 2,
      "z": 2,
      "name": "Soil_Clay_Lime"
    },
    {
      "x": -41,
      "y": 3,
      "z": 2,
      "name": "Plant_Grass_Sharp"
    },
    {
      "x": -41,
      "y": 45,
      "z": 2,
      "name": "Soil_Seaweed_Block"
    },
    {
      "x": -41,
      "y": 0,
      "z": 3,
      "name": "Soil_Clay_Green"
    },
    {
      "x": -41,
      "y": 1,
      "z": 3,
      "name": "Soil_Seaweed_Block"
    },
    {
      "x": -41,
      "y": 2,
      "z": 3,
      "name": "Soil_Clay_Lime"
    },
    {
      "x": -41,
      "y": 3,
      "z": 3,
      "name": "Plant_Grass_Sharp"
    },
    {
      "x": -41,
      "y": 0,
      "z": 4,
      "name": "Soil_Clay_Green"
    },
    {
      "x": -41,
      "y": 1,
      "z": 4,
      "name": "Soil_Seaweed_Block"
    },
    {
      "x": -41,
      "y": 2,
      "z": 4,
      "name": "Soil_Clay_Lime"
    },
    {
      "x": -41,
      "y": 3,
      "z": 4,
      "name": "Plant_Grass_Sharp"
    },
    {
      "x": -41,
      "y": 23,
      "z": 11,
      "name": "Soil_Clay_Green"
    },
    {
      "x": -41,
      "y": 22,
      "z": 12,
      "name": "Soil_Clay_Green"
    },
    {
      "x": -41,
      "y": 23,
      "z": 12,
      "name": "Soil_Seaweed_Block"
    },
    {
      "x": -41,
      "y": 24,
      "z": 12,
      "name": "Soil_Seaweed_Block"
    },
    {
      "x": -41,
      "y": 25,
      "z": 12,
      "name": "Soil_Seaweed_Block"
    },
    {
      "x": -41,
      "y": 22,
      "z": 13,
      "name": "Soil_Clay_Green"
    },
    {
      "x": -41,
      "y": 23,
      "z": 13,
      "name": "Soil_Seaweed_Block"
    },
    {
      "x": -41,
      "y": 24,
      "z": 13,
      "name": "Soil_Seaweed_Block"
    },
    {
      "x": -41,
      "y": 25,
      "z": 13,
      "name": "Soil_Seaweed_Block"
    },
    {
      "x": -41,
      "y": 26,
      "z": 13,
      "name": "Soil_Clay_Lime"
    },
    {
      "x": -41,
      "y": 27,
      "z": 13,
      "name": "Plant_Grass_Sharp"
    },
    {
      "x": -41,
      "y": 22,
      "z": 14,
      "name": "Soil_Clay_Green"
    },
    {
      "x": -41,
      "y": 23,
      "z": 14,
      "name": "Soil_Seaweed_Block"
    },
    {
      "x": -41,
      "y": 24,
      "z": 14,
      "name": "Soil_Seaweed_Block"
    },
    {
      "x": -41,
      "y": 25,
      "z": 14,
      "name": "Soil_Seaweed_Block"
    },
    {
      "x": -41,
      "y": 26,
      "z": 14,
      "name": "Soil_Clay_Lime"
    },
    {
      "x": -41,
      "y": 27,
      "z": 14,
      "name": "Plant_Grass_Sharp"
    },
    {
      "x": -41,
      "y": 18,
      "z": 15,
      "name": "Soil_Clay_Green"
    },
    {
      "x": -41,
      "y": 23,
      "z": 15,
      "name": "Soil_Clay_Green"
    },
    {
      "x": -41,
      "y": 24,
      "z": 15,
      "name": "Soil_Seaweed_Block"
    },
    {
      "x": -41,
      "y": 25,
      "z": 15,
      "name": "Soil_Seaweed_Block"
    },
    {
      "x": -41,
      "y": 26,
      "z": 15,
      "name": "Soil_Clay_Lime"
    },
    {
      "x": -41,
      "y": 27,
      "z": 15,
      "name": "Plant_Grass_Sharp"
    },
    {
      "x": -41,
      "y": 17,
      "z": 16,
      "name": "Soil_Clay_Green"
    },
    {
      "x": -41,
      "y": 18,
      "z": 16,
      "name": "Soil_Seaweed_Block"
    },
    {
      "x": -41,
      "y": 19,
      "z": 16,
      "name": "Soil_Seaweed_Block"
    },
    {
      "x": -41,
      "y": 24,
      "z": 16,
      "name": "Soil_Clay_Green"
    },
    {
      "x": -41,
      "y": 25,
      "z": 16,
      "name": "Soil_Seaweed_Block"
    },
    {
      "x": -41,
      "y": 26,
      "z": 16,
      "name": "Soil_Clay_Lime"
    },
    {
      "x": -41,
      "y": 27,
      "z": 16,
      "name": "Plant_Grass_Sharp"
    },
    {
      "x": -41,
      "y": 16,
      "z": 17,
      "name": "Soil_Clay_Green"
    },
    {
      "x": -41,
      "y": 17,
      "z": 17,
      "name": "Soil_Clay_Green"
    },
    {
      "x": -41,
      "y": 18,
      "z": 17,
      "name": "Soil_Seaweed_Block"
    },
    {
      "x": -41,
      "y": 19,
      "z": 17,
      "name": "Soil_Seaweed_Block"
    },
    {
      "x": -41,
      "y": 25,
      "z": 17,
      "name": "Soil_Clay_Green"
    },
    {
      "x": -41,
      "y": 26,
      "z": 17,
      "name": "Soil_Clay_Lime"
    },
    {
      "x": -41,
      "y": 27,
      "z": 17,
      "name": "Soil_Clay_Lime"
    },
    {
      "x": -41,
      "y": 28,
      "z": 17,
      "name": "Plant_Grass_Sharp"
    },
    {
      "x": -41,
      "y": 26,
      "z": 18,
      "name": "Soil_Clay_Green"
    },
    {
      "x": -41,
      "y": 27,
      "z": 18,
      "name": "Soil_Clay_Lime"
    },
    {
      "x": -41,
      "y": 28,
      "z": 18,
      "name": "Plant_Grass_Sharp"
    },
    {
      "x": -40,
      "y": 1,
      "z": 1,
      "name": "Soil_Seaweed_Block"
    },
    {
      "x": -40,
      "y": 45,
      "z": 1,
      "name": "Soil_Seaweed_Block"
    },
    {
      "x": -40,
      "y": 0,
      "z": 2,
      "name": "Soil_Clay_Green"
    },
    {
      "x": -40,
      "y": 1,
      "z": 2,
      "name": "Soil_Seaweed_Block"
    },
    {
      "x": -40,
      "y": 44,
      "z": 2,
      "name": "Soil_Clay_Green"
    },
    {
      "x": -40,
      "y": 45,
      "z": 2,
      "name": "Soil_Clay_Lime"
    },
    {
      "x": -40,
      "y": 46,
      "z": 2,
      "name": "Plant_Grass_Sharp"
    },
    {
      "x": -40,
      "y": 0,
      "z": 3,
      "name": "Soil_Clay_Green"
    },
    {
      "x": -40,
      "y": 1,
      "z": 3,
      "name": "Soil_Seaweed_Block"
    },
    {
      "x": -40,
      "y": 2,
      "z": 3,
      "name": "Soil_Clay_Lime"
    },
    {
      "x": -40,
      "y": 3,
      "z": 3,
      "name": "Plant_Grass_Sharp"
    },
    {
      "x": -40,
      "y": 0,
      "z": 4,
      "name": "Soil_Clay_Green"
    },
    {
      "x": -40,
      "y": 1,
      "z": 4,
      "name": "Soil_Clay_Green"
    },
    {
      "x": -40,
      "y": 22,
      "z": 12,
      "name": "Soil_Clay_Green"
    },
    {
      "x": -40,
      "y": 23,
      "z": 12,
      "name": "Soil_Clay_Green"
    },
    {
      "x": -40,
      "y": 24,
      "z": 12,
      "name": "Soil_Seaweed_Block"
    },
    {
      "x": -40,
      "y": 22,
      "z": 13,
      "name": "Soil_Clay_Green"
    },
    {
      "x": -40,
      "y": 23,
      "z": 13,
      "name": "Soil_Seaweed_Block"
    },
    {
      "x": -40,
      "y": 24,
      "z": 13,
      "name": "Soil_Seaweed_Block"
    },
    {
      "x": -40,
      "y": 25,
      "z": 13,
      "name": "Soil_Clay_Lime"
    },
    {
      "x": -40,
      "y": 26,
      "z": 13,
      "name": "Plant_Grass_Sharp"
    },
    {
      "x": -40,
      "y": 21,
      "z": 14,
      "name": "Soil_Clay_Green"
    },
    {
      "x": -40,
      "y": 22,
      "z": 14,
      "name": "Soil_Seaweed_Block"
    },
    {
      "x": -40,
      "y": 23,
      "z": 14,
      "name": "Soil_Seaweed_Block"
    },
    {
      "x": -40,
      "y": 24,
      "z": 14,
      "name": "Soil_Seaweed_Block"
    },
    {
      "x": -40,
      "y": 25,
      "z": 14,
      "name": "Soil_Clay_Lime"
    },
    {
      "x": -40,
      "y": 26,
      "z": 14,
      "name": "Plant_Grass_Sharp"
    },
    {
      "x": -40,
      "y": 18,
      "z": 15,
      "name": "Soil_Clay_Green"
    },
    {
      "x": -40,
      "y": 19,
      "z": 15,
      "name": "Soil_Clay_Green"
    },
    {
      "x": -40,
      "y": 20,
      "z": 15,
      "name": "Soil_Seaweed_Block"
    },
    {
      "x": -40,
      "y": 22,
      "z": 15,
      "name": "Soil_Clay_Green"
    },
    {
      "x": -40,
      "y": 23,
      "z": 15,
      "name": "Soil_Seaweed_Block"
    },
    {
      "x": -40,
      "y": 24,
      "z": 15,
      "name": "Soil_Seaweed_Block"
    },
    {
      "x": -40,
      "y": 25,
      "z": 15,
      "name": "Soil_Seaweed_Block"
    },
    {
      "x": -40,
      "y": 17,
      "z": 16,
      "name": "Soil_Clay_Green"
    },
    {
      "x": -40,
      "y": 18,
      "z": 16,
      "name": "Soil_Seaweed_Block"
    },
    {
      "x": -40,
      "y": 19,
      "z": 16,
      "name": "Soil_Seaweed_Block"
    },
    {
      "x": -40,
      "y": 20,
      "z": 16,
      "name": "Soil_Seaweed_Block"
    },
    {
      "x": -40,
      "y": 23,
      "z": 16,
      "name": "Soil_Clay_Green"
    },
    {
      "x": -40,
      "y": 24,
      "z": 16,
      "name": "Soil_Clay_Green"
    },
    {
      "x": -40,
      "y": 25,
      "z": 16,
      "name": "Soil_Seaweed_Block"
    },
    {
      "x": -40,
      "y": 17,
      "z": 17,
      "name": "Soil_Clay_Green"
    },
    {
      "x": -40,
      "y": 18,
      "z": 17,
      "name": "Soil_Clay_Green"
    },
    {
      "x": -40,
      "y": 19,
      "z": 17,
      "name": "Soil_Seaweed_Block"
    },
    {
      "x": -40,
      "y": 20,
      "z": 17,
      "name": "Soil_Seaweed_Block"
    },
    {
      "x": -39,
      "y": 0,
      "z": 2,
      "name": "Soil_Clay_Green"
    },
    {
      "x": -39,
      "y": 1,
      "z": 2,
      "name": "Soil_Clay_Green"
    },
    {
      "x": -39,
      "y": 43,
      "z": 2,
      "name": "Soil_Clay_Green"
    },
    {
      "x": -39,
      "y": 44,
      "z": 2,
      "name": "Soil_Seaweed_Block"
    },
    {
      "x": -39,
      "y": 0,
      "z": 3,
      "name": "Soil_Clay_Green"
    },
    {
      "x": -39,
      "y": 1,
      "z": 3,
      "name": "Soil_Clay_Green"
    },
    {
      "x": -39,
      "y": 43,
      "z": 3,
      "name": "Soil_Clay_Green"
    },
    {
      "x": -39,
      "y": 44,
      "z": 3,
      "name": "Soil_Seaweed_Block"
    },
    {
      "x": -39,
      "y": 0,
      "z": 4,
      "name": "Soil_Clay_Green"
    },
    {
      "x": -39,
      "y": 1,
      "z": 4,
      "name": "Soil_Clay_Green"
    },
    {
      "x": -39,
      "y": 21,
      "z": 12,
      "name": "Soil_Clay_Green"
    },
    {
      "x": -39,
      "y": 22,
      "z": 12,
      "name": "Soil_Clay_Green"
    },
    {
      "x": -39,
      "y": 23,
      "z": 12,
      "name": "Soil_Seaweed_Block"
    },
    {
      "x": -39,
      "y": 19,
      "z": 13,
      "name": "Soil_Clay_Green"
    },
    {
      "x": -39,
      "y": 20,
      "z": 13,
      "name": "Soil_Clay_Green"
    },
    {
      "x": -39,
      "y": 21,
      "z": 13,
      "name": "Soil_Clay_Green"
    },
    {
      "x": -39,
      "y": 22,
      "z": 13,
      "name": "Soil_Seaweed_Block"
    },
    {
      "x": -39,
      "y": 23,
      "z": 13,
      "name": "Soil_Seaweed_Block"
    },
    {
      "x": -39,
      "y": 24,
      "z": 13,
      "name": "Soil_Clay_Lime"
    },
    {
      "x": -39,
      "y": 25,
      "z": 13,
      "name": "Plant_Grass_Sharp"
    },
    {
      "x": -39,
      "y": 18,
      "z": 14,
      "name": "Soil_Clay_Green"
    },
    {
      "x": -39,
      "y": 19,
      "z": 14,
      "name": "Soil_Clay_Green"
    },
    {
      "x": -39,
      "y": 20,
      "z": 14,
      "name": "Soil_Clay_Green"
    },
    {
      "x": -39,
      "y": 21,
      "z": 14,
      "name": "Soil_Seaweed_Block"
    },
    {
      "x": -39,
      "y": 22,
      "z": 14,
      "name": "Soil_Seaweed_Block"
    },
    {
      "x": -39,
      "y": 23,
      "z": 14,
      "name": "Soil_Seaweed_Block"
    },
    {
      "x": -39,
      "y": 24,
      "z": 14,
      "name": "Soil_Clay_Lime"
    },
    {
      "x": -39,
      "y": 25,
      "z": 14,
      "name": "Plant_Grass_Sharp"
    },
    {
      "x": -39,
      "y": 18,
      "z": 15,
      "name": "Soil_Clay_Green"
    },
    {
      "x": -39,
      "y": 19,
      "z": 15,
      "name": "Soil_Seaweed_Block"
    },
    {
      "x": -39,
      "y": 20,
      "z": 15,
      "name": "Soil_Seaweed_Block"
    },
    {
      "x": -39,
      "y": 21,
      "z": 15,
      "name": "Soil_Seaweed_Block"
    },
    {
      "x": -39,
      "y": 22,
      "z": 15,
      "name": "Soil_Seaweed_Block"
    },
    {
      "x": -39,
      "y": 23,
      "z": 15,
      "name": "Soil_Seaweed_Block"
    },
    {
      "x": -39,
      "y": 24,
      "z": 15,
      "name": "Soil_Seaweed_Block"
    },
    {
      "x": -39,
      "y": 18,
      "z": 16,
      "name": "Soil_Clay_Green"
    },
    {
      "x": -39,
      "y": 19,
      "z": 16,
      "name": "Soil_Seaweed_Block"
    },
    {
      "x": -39,
      "y": 20,
      "z": 16,
      "name": "Soil_Seaweed_Block"
    },
    {
      "x": -39,
      "y": 21,
      "z": 16,
      "name": "Soil_Seaweed_Block"
    },
    {
      "x": -39,
      "y": 18,
      "z": 17,
      "name": "Soil_Clay_Green"
    },
    {
      "x": -39,
      "y": 19,
      "z": 17,
      "name": "Soil_Clay_Green"
    },
    {
      "x": -39,
      "y": 20,
      "z": 17,
      "name": "Soil_Seaweed_Block"
    },
    {
      "x": -39,
      "y": 10,
      "z": 41,
      "name": "Soil_Clay_Green"
    },
    {
      "x": -39,
      "y": 11,
      "z": 41,
      "name": "Soil_Seaweed_Block"
    },
    {
      "x": -39,
      "y": 9,
      "z": 42,
      "name": "Soil_Clay_Green"
    },
    {
      "x": -39,
      "y": 10,
      "z": 42,
      "name": "Soil_Clay_Green"
    },
    {
      "x": -39,
      "y": 11,
      "z": 42,
      "name": "Soil_Seaweed_Block"
    },
    {
      "x": -39,
      "y": 8,
      "z": 43,
      "name": "Soil_Clay_Green"
    },
    {
      "x": -39,
      "y": 9,
      "z": 43,
      "name": "Soil_Clay_Green"
    },
    {
      "x": -39,
      "y": 10,
      "z": 43,
      "name": "Soil_Clay_Green"
    },
    {
      "x": -39,
      "y": 11,
      "z": 43,
      "name": "Soil_Seaweed_Block"
    },
    {
      "x": -39,
      "y": 7,
      "z": 44,
      "name": "Soil_Clay_Green"
    },
    {
      "x": -39,
      "y": 8,
      "z": 44,
      "name": "Soil_Clay_Green"
    },
    {
      "x": -39,
      "y": 9,
      "z": 44,
      "name": "Soil_Seaweed_Block"
    },
    {
      "x": -39,
      "y": 7,
      "z": 45,
      "name": "Soil_Clay_Green"
    },
    {
      "x": -39,
      "y": 8,
      "z": 45,
      "name": "Soil_Seaweed_Block"
    },
    {
      "x": -39,
      "y": 7,
      "z": 46,
      "name": "Soil_Clay_Green"
    },
    {
      "x": -38,
      "y": 42,
      "z": 2,
      "name": "Soil_Clay_Green"
    },
    {
      "x": -38,
      "y": 43,
      "z": 2,
      "name": "Soil_Clay_Green"
    },
    {
      "x": -38,
      "y": 44,
      "z": 2,
      "name": "Soil_Clay_Lime"
    },
    {
      "x": -38,
      "y": 45,
      "z": 2,
      "name": "Plant_Grass_Sharp"
    },
    {
      "x": -38,
      "y": 0,
      "z": 3,
      "name": "Soil_Clay_Green"
    },
    {
      "x": -38,
      "y": 42,
      "z": 3,
      "name": "Soil_Clay_Green"
    },
    {
      "x": -38,
      "y": 43,
      "z": 3,
      "name": "Soil_Seaweed_Block"
    },
    {
      "x": -38,
      "y": 44,
      "z": 3,
      "name": "Soil_Clay_Lime"
    },
    {
      "x": -38,
      "y": 45,
      "z": 3,
      "name": "Plant_Grass_Sharp"
    },
    {
      "x": -38,
      "y": 0,
      "z": 4,
      "name": "Soil_Clay_Green"
    },
    {
      "x": -38,
      "y": 1,
      "z": 4,
      "name": "Soil_Clay_Green"
    },
    {
      "x": -38,
      "y": 2,
      "z": 4,
      "name": "Soil_Clay_Green"
    },
    {
      "x": -38,
      "y": 3,
      "z": 4,
      "name": "Soil_Seaweed_Block"
    },
    {
      "x": -38,
      "y": 4,
      "z": 4,
      "name": "Soil_Seaweed_Block"
    },
    {
      "x": -38,
      "y": 5,
      "z": 4,
      "name": "Soil_Seaweed_Block"
    },
    {
      "x": -38,
      "y": 43,
      "z": 4,
      "name": "Soil_Clay_Green"
    },
    {
      "x": -38,
      "y": 44,
      "z": 4,
      "name": "Soil_Seaweed_Block"
    },
    {
      "x": -38,
      "y": 3,
      "z": 5,
      "name": "Soil_Clay_Green"
    },
    {
      "x": -38,
      "y": 4,
      "z": 5,
      "name": "Soil_Seaweed_Block"
    },
    {
      "x": -38,
      "y": 5,
      "z": 5,
      "name": "Soil_Seaweed_Block"
    },
    {
      "x": -38,
      "y": 18,
      "z": 11,
      "name": "Soil_Clay_Green"
    },
    {
      "x": -38,
      "y": 19,
      "z": 11,
      "name": "Soil_Seaweed_Block"
    },
    {
      "x": -38,
      "y": 18,
      "z": 12,
      "name": "Soil_Clay_Green"
    },
    {
      "x": -38,
      "y": 19,
      "z": 12,
      "name": "Soil_Clay_Green"
    },
    {
      "x": -38,
      "y": 20,
      "z": 12,
      "name": "Soil_Seaweed_Block"
    },
    {
      "x": -38,
      "y": 21,
      "z": 12,
      "name": "Soil_Seaweed_Block"
    },
    {
      "x": -38,
      "y": 22,
      "z": 12,
      "name": "Soil_Seaweed_Block"
    },
    {
      "x": -38,
      "y": 23,
      "z": 12,
      "name": "Soil_Seaweed_Block"
    },
    {
      "x": -38,
      "y": 18,
      "z": 13,
      "name": "Soil_Clay_Green"
    },
    {
      "x": -38,
      "y": 19,
      "z": 13,
      "name": "Soil_Seaweed_Block"
    },
    {
      "x": -38,
      "y": 20,
      "z": 13,
      "name": "Soil_Seaweed_Block"
    },
    {
      "x": -38,
      "y": 21,
      "z": 13,
      "name": "Soil_Seaweed_Block"
    },
    {
      "x": -38,
      "y": 22,
      "z": 13,
      "name": "Soil_Seaweed_Block"
    },
    {
      "x": -38,
      "y": 23,
      "z": 13,
      "name": "Soil_Seaweed_Block"
    },
    {
      "x": -38,
      "y": 18,
      "z": 14,
      "name": "Soil_Clay_Green"
    },
    {
      "x": -38,
      "y": 19,
      "z": 14,
      "name": "Soil_Seaweed_Block"
    },
    {
      "x": -38,
      "y": 20,
      "z": 14,
      "name": "Soil_Seaweed_Block"
    },
    {
      "x": -38,
      "y": 21,
      "z": 14,
      "name": "Soil_Seaweed_Block"
    },
    {
      "x": -38,
      "y": 22,
      "z": 14,
      "name": "Soil_Seaweed_Block"
    },
    {
      "x": -38,
      "y": 23,
      "z": 14,
      "name": "Soil_Seaweed_Block"
    },
    {
      "x": -38,
      "y": 24,
      "z": 14,
      "name": "Soil_Clay_Lime"
    },
    {
      "x": -38,
      "y": 25,
      "z": 14,
      "name": "Plant_Grass_Sharp"
    },
    {
      "x": -38,
      "y": 18,
      "z": 15,
      "name": "Soil_Clay_Green"
    },
    {
      "x": -38,
      "y": 19,
      "z": 15,
      "name": "Soil_Seaweed_Block"
    },
    {
      "x": -38,
      "y": 20,
      "z": 15,
      "name": "Soil_Seaweed_Block"
    },
    {
      "x": -38,
      "y": 21,
      "z": 15,
      "name": "Soil_Seaweed_Block"
    },
    {
      "x": -38,
      "y": 22,
      "z": 15,
      "name": "Soil_Seaweed_Block"
    },
    {
      "x": -38,
      "y": 18,
      "z": 16,
      "name": "Soil_Clay_Green"
    },
    {
      "x": -38,
      "y": 19,
      "z": 16,
      "name": "Soil_Seaweed_Block"
    },
    {
      "x": -38,
      "y": 20,
      "z": 16,
      "name": "Soil_Seaweed_Block"
    },
    {
      "x": -38,
      "y": 21,
      "z": 16,
      "name": "Soil_Seaweed_Block"
    },
    {
      "x": -38,
      "y": 22,
      "z": 16,
      "name": "Soil_Seaweed_Block"
    },
    {
      "x": -38,
      "y": 19,
      "z": 17,
      "name": "Soil_Clay_Green"
    },
    {
      "x": -38,
      "y": 20,
      "z": 17,
      "name": "Soil_Seaweed_Block"
    },
    {
      "x": -38,
      "y": 10,
      "z": 41,
      "name": "Soil_Clay_Green"
    },
    {
      "x": -38,
      "y": 11,
      "z": 41,
      "name": "Soil_Clay_Green"
    },
    {
      "x": -38,
      "y": 12,
      "z": 41,
      "name": "Soil_Seaweed_Block"
    },
    {
      "x": -38,
      "y": 9,
      "z": 42,
      "name": "Soil_Clay_Green"
    },
    {
      "x": -38,
      "y": 10,
      "z": 42,
      "name": "Soil_Clay_Green"
    },
    {
      "x": -38,
      "y": 11,
      "z": 42,
      "name": "Soil_Seaweed_Block"
    },
    {
      "x": -38,
      "y": 12,
      "z": 42,
      "name": "Soil_Seaweed_Block"
    },
    {
      "x": -38,
      "y": 8,
      "z": 43,
      "name": "Soil_Clay_Green"
    },
    {
      "x": -38,
      "y": 9,
      "z": 43,
      "name": "Soil_Clay_Green"
    },
    {
      "x": -38,
      "y": 11,
      "z": 43,
      "name": "Soil_Clay_Green"
    },
    {
      "x": -38,
      "y": 7,
      "z": 44,
      "name": "Soil_Clay_Green"
    },
    {
      "x": -38,
      "y": 8,
      "z": 44,
      "name": "Soil_Clay_Green"
    },
    {
      "x": -38,
      "y": 6,
      "z": 45,
      "name": "Soil_Clay_Green"
    },
    {
      "x": -38,
      "y": 7,
      "z": 45,
      "name": "Soil_Clay_Green"
    },
    {
      "x": -38,
      "y": 8,
      "z": 45,
      "name": "Soil_Seaweed_Block"
    },
    {
      "x": -38,
      "y": 6,
      "z": 46,
      "name": "Soil_Clay_Green"
    },
    {
      "x": -38,
      "y": 7,
      "z": 46,
      "name": "Soil_Clay_Green"
    },
    {
      "x": -38,
      "y": 8,
      "z": 46,
      "name": "Soil_Clay_Lime"
    },
    {
      "x": -38,
      "y": 9,
      "z": 46,
      "name": "Plant_Grass_Sharp"
    },
    {
      "x": -38,
      "y": 6,
      "z": 47,
      "name": "Soil_Clay_Green"
    },
    {
      "x": -38,
      "y": 7,
      "z": 47,
      "name": "Soil_Clay_Green"
    },
    {
      "x": -37,
      "y": 42,
      "z": 2,
      "name": "Soil_Clay_Green"
    },
    {
      "x": -37,
      "y": 43,
      "z": 2,
      "name": "Soil_Seaweed_Block"
    },
    {
      "x": -37,
      "y": 1,
      "z": 3,
      "name": "Soil_Clay_Green"
    },
    {
      "x": -37,
      "y": 2,
      "z": 3,
      "name": "Soil_Clay_Green"
    },
    {
      "x": -37,
      "y": 3,
      "z": 3,
      "name": "Soil_Clay_Green"
    },
    {
      "x": -37,
      "y": 42,
      "z": 3,
      "name": "Soil_Clay_Green"
    },
    {
      "x": -37,
      "y": 43,
      "z": 3,
      "name": "Soil_Clay_Lime"
    },
    {
      "x": -37,
      "y": 44,
      "z": 3,
      "name": "Plant_Grass_Sharp"
    },
    {
      "x": -37,
      "y": 1,
      "z": 4,
      "name": "Soil_Clay_Green"
    },
    {
      "x": -37,
      "y": 2,
      "z": 4,
      "name": "Soil_Seaweed_Block"
    },
    {
      "x": -37,
      "y": 3,
      "z": 4,
      "name": "Soil_Seaweed_Block"
    },
    {
      "x": -37,
      "y": 4,
      "z": 4,
      "name": "Soil_Clay_Green"
    },
    {
      "x": -37,
      "y": 5,
      "z": 4,
      "name": "Soil_Seaweed_Block"
    },
    {
      "x": -37,
      "y": 6,
      "z": 4,
      "name": "Soil_Seaweed_Block"
    },
    {
      "x": -37,
      "y": 42,
      "z": 4,
      "name": "Soil_Clay_Green"
    },
    {
      "x": -37,
      "y": 43,
      "z": 4,
      "name": "Soil_Seaweed_Block"
    },
    {
      "x": -37,
      "y": 2,
      "z": 5,
      "name": "Soil_Clay_Green"
    },
    {
      "x": -37,
      "y": 3,
      "z": 5,
      "name": "Soil_Seaweed_Block"
    },
    {
      "x": -37,
      "y": 4,
      "z": 5,
      "name": "Soil_Seaweed_Block"
    },
    {
      "x": -37,
      "y": 5,
      "z": 5,
      "name": "Soil_Seaweed_Block"
    },
    {
      "x": -37,
      "y": 6,
      "z": 5,
      "name": "Soil_Seaweed_Block"
    },
    {
      "x": -37,
      "y": 3,
      "z": 6,
      "name": "Soil_Clay_Green"
    },
    {
      "x": -37,
      "y": 4,
      "z": 6,
      "name": "Soil_Clay_Green"
    },
    {
      "x": -37,
      "y": 5,
      "z": 6,
      "name": "Soil_Seaweed_Block"
    },
    {
      "x": -37,
      "y": 6,
      "z": 6,
      "name": "Soil_Seaweed_Block"
    },
    {
      "x": -37,
      "y": 7,
      "z": 6,
      "name": "Soil_Seaweed_Block"
    },
    {
      "x": -37,
      "y": 16,
      "z": 11,
      "name": "Soil_Clay_Green"
    },
    {
      "x": -37,
      "y": 17,
      "z": 11,
      "name": "Soil_Clay_Green"
    },
    {
      "x": -37,
      "y": 18,
      "z": 11,
      "name": "Soil_Seaweed_Block"
    },
    {
      "x": -37,
      "y": 19,
      "z": 11,
      "name": "Soil_Seaweed_Block"
    },
    {
      "x": -37,
      "y": 15,
      "z": 12,
      "name": "Soil_Clay_Green"
    },
    {
      "x": -37,
      "y": 16,
      "z": 12,
      "name": "Soil_Clay_Green"
    },
    {
      "x": -37,
      "y": 17,
      "z": 12,
      "name": "Soil_Clay_Green"
    },
    {
      "x": -37,
      "y": 18,
      "z": 12,
      "name": "Soil_Seaweed_Block"
    },
    {
      "x": -37,
      "y": 19,
      "z": 12,
      "name": "Soil_Seaweed_Block"
    },
    {
      "x": -37,
      "y": 20,
      "z": 12,
      "name": "Soil_Seaweed_Block"
    },
    {
      "x": -37,
      "y": 21,
      "z": 12,
      "name": "Soil_Seaweed_Block"
    },
    {
      "x": -37,
      "y": 15,
      "z": 13,
      "name": "Soil_Clay_Green"
    },
    {
      "x": -37,
      "y": 16,
      "z": 13,
      "name": "Soil_Clay_Green"
    },
    {
      "x": -37,
      "y": 17,
      "z": 13,
      "name": "Soil_Clay_Green"
    },
    {
      "x": -37,
      "y": 18,
      "z": 13,
      "name": "Soil_Seaweed_Block"
    },
    {
      "x": -37,
      "y": 19,
      "z": 13,
      "name": "Soil_Seaweed_Block"
    },
    {
      "x": -37,
      "y": 20,
      "z": 13,
      "name": "Soil_Seaweed_Block"
    },
    {
      "x": -37,
      "y": 21,
      "z": 13,
      "name": "Soil_Seaweed_Block"
    },
    {
      "x": -37,
      "y": 22,
      "z": 13,
      "name": "Soil_Seaweed_Block"
    },
    {
      "x": -37,
      "y": 15,
      "z": 14,
      "name": "Soil_Clay_Green"
    },
    {
      "x": -37,
      "y": 16,
      "z": 14,
      "name": "Soil_Clay_Green"
    },
    {
      "x": -37,
      "y": 17,
      "z": 14,
      "name": "Soil_Clay_Green"
    },
    {
      "x": -37,
      "y": 18,
      "z": 14,
      "name": "Soil_Seaweed_Block"
    },
    {
      "x": -37,
      "y": 19,
      "z": 14,
      "name": "Soil_Seaweed_Block"
    },
    {
      "x": -37,
      "y": 20,
      "z": 14,
      "name": "Soil_Seaweed_Block"
    },
    {
      "x": -37,
      "y": 21,
      "z": 14,
      "name": "Soil_Clay_Lime"
    },
    {
      "x": -37,
      "y": 22,
      "z": 14,
      "name": "Soil_Clay_Lime"
    },
    {
      "x": -37,
      "y": 23,
      "z": 14,
      "name": "Plant_Grass_Sharp"
    },
    {
      "x": -37,
      "y": 15,
      "z": 15,
      "name": "Soil_Clay_Green"
    },
    {
      "x": -37,
      "y": 16,
      "z": 15,
      "name": "Soil_Clay_Green"
    },
    {
      "x": -37,
      "y": 17,
      "z": 15,
      "name": "Soil_Clay_Green"
    },
    {
      "x": -37,
      "y": 18,
      "z": 15,
      "name": "Soil_Seaweed_Block"
    },
    {
      "x": -37,
      "y": 19,
      "z": 15,
      "name": "Soil_Seaweed_Block"
    },
    {
      "x": -37,
      "y": 20,
      "z": 15,
      "name": "Soil_Seaweed_Block"
    },
    {
      "x": -37,
      "y": 21,
      "z": 15,
      "name": "Soil_Seaweed_Block"
    },
    {
      "x": -37,
      "y": 22,
      "z": 15,
      "name": "Soil_Seaweed_Block"
    },
    {
      "x": -37,
      "y": 18,
      "z": 16,
      "name": "Soil_Clay_Green"
    },
    {
      "x": -37,
      "y": 19,
      "z": 16,
      "name": "Soil_Clay_Green"
    },
    {
      "x": -37,
      "y": 20,
      "z": 16,
      "name": "Soil_Seaweed_Block"
    },
    {
      "x": -37,
      "y": 21,
      "z": 16,
      "name": "Soil_Seaweed_Block"
    },
    {
      "x": -37,
      "y": 10,
      "z": 41,
      "name": "Soil_Clay_Green"
    },
    {
      "x": -37,
      "y": 11,
      "z": 41,
      "name": "Soil_Clay_Green"
    },
    {
      "x": -37,
      "y": 12,
      "z": 41,
      "name": "Soil_Clay_Green"
    },
    {
      "x": -37,
      "y": 13,
      "z": 41,
      "name": "Soil_Seaweed_Block"
    },
    {
      "x": -37,
      "y": 11,
      "z": 42,
      "name": "Soil_Clay_Green"
    },
    {
      "x": -37,
      "y": 12,
      "z": 42,
      "name": "Soil_Seaweed_Block"
    },
    {
      "x": -37,
      "y": 13,
      "z": 42,
      "name": "Soil_Clay_Lime"
    },
    {
      "x": -37,
      "y": 14,
      "z": 42,
      "name": "Plant_Grass_Sharp"
    },
    {
      "x": -37,
      "y": 12,
      "z": 43,
      "name": "Soil_Clay_Green"
    },
    {
      "x": -36,
      "y": 42,
      "z": 1,
      "name": "Soil_Clay_Green"
    },
    {
      "x": -36,
      "y": 42,
      "z": 2,
      "name": "Soil_Clay_Green"
    },
    {
      "x": -36,
      "y": 43,
      "z": 2,
      "name": "Soil_Clay_Lime"
    },
    {
      "x": -36,
      "y": 44,
      "z": 2,
      "name": "Plant_Grass_Sharp"
    },
    {
      "x": -36,
      "y": 2,
      "z": 3,
      "name": "Soil_Clay_Green"
    },
    {
      "x": -36,
      "y": 3,
      "z": 3,
      "name": "Soil_Clay_Green"
    },
    {
      "x": -36,
      "y": 42,
      "z": 3,
      "name": "Soil_Clay_Green"
    },
    {
      "x": -36,
      "y": 43,
      "z": 3,
      "name": "Soil_Clay_Lime"
    },
    {
      "x": -36,
      "y": 44,
      "z": 3,
      "name": "Plant_Grass_Sharp"
    },
    {
      "x": -36,
      "y": 1,
      "z": 4,
      "name": "Soil_Clay_Green"
    },
    {
      "x": -36,
      "y": 2,
      "z": 4,
      "name": "Soil_Clay_Green"
    },
    {
      "x": -36,
      "y": 3,
      "z": 4,
      "name": "Soil_Seaweed_Block"
    },
    {
      "x": -36,
      "y": 4,
      "z": 4,
      "name": "Soil_Clay_Green"
    },
    {
      "x": -36,
      "y": 5,
      "z": 4,
      "name": "Soil_Seaweed_Block"
    },
    {
      "x": -36,
      "y": 6,
      "z": 4,
      "name": "Soil_Seaweed_Block"
    },
    {
      "x": -36,
      "y": 2,
      "z": 5,
      "name": "Soil_Clay_Green"
    },
    {
      "x": -36,
      "y": 3,
      "z": 5,
      "name": "Soil_Seaweed_Block"
    },
    {
      "x": -36,
      "y": 4,
      "z": 5,
      "name": "Soil_Seaweed_Block"
    },
    {
      "x": -36,
      "y": 5,
      "z": 5,
      "name": "Soil_Seaweed_Block"
    },
    {
      "x": -36,
      "y": 6,
      "z": 5,
      "name": "Soil_Seaweed_Block"
    },
    {
      "x": -36,
      "y": 7,
      "z": 5,
      "name": "Soil_Seaweed_Block"
    },
    {
      "x": -36,
      "y": 3,
      "z": 6,
      "name": "Soil_Clay_Green"
    },
    {
      "x": -36,
      "y": 4,
      "z": 6,
      "name": "Soil_Clay_Green"
    },
    {
      "x": -36,
      "y": 5,
      "z": 6,
      "name": "Soil_Clay_Green"
    },
    {
      "x": -36,
      "y": 6,
      "z": 6,
      "name": "Soil_Seaweed_Block"
    },
    {
      "x": -36,
      "y": 7,
      "z": 6,
      "name": "Soil_Seaweed_Block"
    },
    {
      "x": -36,
      "y": 8,
      "z": 6,
      "name": "Soil_Seaweed_Block"
    },
    {
      "x": -36,
      "y": 9,
      "z": 6,
      "name": "Soil_Seaweed_Block"
    },
    {
      "x": -36,
      "y": 6,
      "z": 7,
      "name": "Soil_Clay_Green"
    },
    {
      "x": -36,
      "y": 7,
      "z": 7,
      "name": "Soil_Clay_Green"
    },
    {
      "x": -36,
      "y": 8,
      "z": 7,
      "name": "Soil_Seaweed_Block"
    },
    {
      "x": -36,
      "y": 9,
      "z": 7,
      "name": "Soil_Seaweed_Block"
    },
    {
      "x": -36,
      "y": 7,
      "z": 8,
      "name": "Soil_Clay_Green"
    },
    {
      "x": -36,
      "y": 8,
      "z": 8,
      "name": "Soil_Clay_Green"
    },
    {
      "x": -36,
      "y": 9,
      "z": 8,
      "name": "Soil_Seaweed_Block"
    },
    {
      "x": -36,
      "y": 8,
      "z": 9,
      "name": "Soil_Clay_Green"
    },
    {
      "x": -36,
      "y": 9,
      "z": 9,
      "name": "Soil_Clay_Green"
    },
    {
      "x": -36,
      "y": 10,
      "z": 9,
      "name": "Soil_Seaweed_Block"
    },
    {
      "x": -36,
      "y": 9,
      "z": 10,
      "name": "Soil_Clay_Green"
    },
    {
      "x": -36,
      "y": 10,
      "z": 10,
      "name": "Soil_Clay_Green"
    },
    {
      "x": -36,
      "y": 11,
      "z": 10,
      "name": "Soil_Seaweed_Block"
    },
    {
      "x": -36,
      "y": 9,
      "z": 11,
      "name": "Soil_Clay_Green"
    },
    {
      "x": -36,
      "y": 10,
      "z": 11,
      "name": "Soil_Clay_Green"
    },
    {
      "x": -36,
      "y": 11,
      "z": 11,
      "name": "Soil_Seaweed_Block"
    },
    {
      "x": -36,
      "y": 12,
      "z": 11,
      "name": "Soil_Seaweed_Block"
    },
    {
      "x": -36,
      "y": 16,
      "z": 11,
      "name": "Soil_Clay_Green"
    },
    {
      "x": -36,
      "y": 17,
      "z": 11,
      "name": "Soil_Clay_Green"
    },
    {
      "x": -36,
      "y": 18,
      "z": 11,
      "name": "Soil_Seaweed_Block"
    },
    {
      "x": -36,
      "y": 14,
      "z": 12,
      "name": "Soil_Clay_Green"
    },
    {
      "x": -36,
      "y": 15,
      "z": 12,
      "name": "Soil_Clay_Green"
    },
    {
      "x": -36,
      "y": 16,
      "z": 12,
      "name": "Soil_Seaweed_Block"
    },
    {
      "x": -36,
      "y": 17,
      "z": 12,
      "name": "Soil_Seaweed_Block"
    },
    {
      "x": -36,
      "y": 18,
      "z": 12,
      "name": "Soil_Seaweed_Block"
    },
    {
      "x": -36,
      "y": 19,
      "z": 12,
      "name": "Soil_Seaweed_Block"
    },
    {
      "x": -36,
      "y": 14,
      "z": 13,
      "name": "Soil_Clay_Green"
    },
    {
      "x": -36,
      "y": 15,
      "z": 13,
      "name": "Soil_Seaweed_Block"
    },
    {
      "x": -36,
      "y": 16,
      "z": 13,
      "name": "Soil_Seaweed_Block"
    },
    {
      "x": -36,
      "y": 17,
      "z": 13,
      "name": "Soil_Seaweed_Block"
    },
    {
      "x": -36,
      "y": 18,
      "z": 13,
      "name": "Soil_Seaweed_Block"
    },
    {
      "x": -36,
      "y": 19,
      "z": 13,
      "name": "Soil_Seaweed_Block"
    },
    {
      "x": -36,
      "y": 20,
      "z": 13,
      "name": "Soil_Clay_Lime"
    },
    {
      "x": -36,
      "y": 21,
      "z": 13,
      "name": "Plant_Grass_Sharp"
    },
    {
      "x": -36,
      "y": 14,
      "z": 14,
      "name": "Soil_Clay_Green"
    },
    {
      "x": -36,
      "y": 15,
      "z": 14,
      "name": "Soil_Seaweed_Block"
    },
    {
      "x": -36,
      "y": 16,
      "z": 14,
      "name": "Soil_Seaweed_Block"
    },
    {
      "x": -36,
      "y": 17,
      "z": 14,
      "name": "Soil_Seaweed_Block"
    },
    {
      "x": -36,
      "y": 18,
      "z": 14,
      "name": "Soil_Seaweed_Block"
    },
    {
      "x": -36,
      "y": 19,
      "z": 14,
      "name": "Soil_Seaweed_Block"
    },
    {
      "x": -36,
      "y": 20,
      "z": 14,
      "name": "Soil_Clay_Lime"
    },
    {
      "x": -36,
      "y": 21,
      "z": 14,
      "name": "Plant_Grass_Sharp"
    },
    {
      "x": -36,
      "y": 15,
      "z": 15,
      "name": "Soil_Clay_Green"
    },
    {
      "x": -36,
      "y": 16,
      "z": 15,
      "name": "Soil_Seaweed_Block"
    },
    {
      "x": -36,
      "y": 17,
      "z": 15,
      "name": "Soil_Seaweed_Block"
    },
    {
      "x": -36,
      "y": 18,
      "z": 15,
      "name": "Soil_Seaweed_Block"
    },
    {
      "x": -36,
      "y": 19,
      "z": 15,
      "name": "Soil_Seaweed_Block"
    },
    {
      "x": -36,
      "y": 20,
      "z": 15,
      "name": "Soil_Seaweed_Block"
    },
    {
      "x": -36,
      "y": 21,
      "z": 15,
      "name": "Soil_Seaweed_Block"
    },
    {
      "x": -36,
      "y": 15,
      "z": 16,
      "name": "Soil_Clay_Green"
    },
    {
      "x": -36,
      "y": 16,
      "z": 16,
      "name": "Soil_Clay_Green"
    },
    {
      "x": -36,
      "y": 17,
      "z": 16,
      "name": "Soil_Clay_Green"
    },
    {
      "x": -36,
      "y": 18,
      "z": 16,
      "name": "Soil_Clay_Green"
    },
    {
      "x": -36,
      "y": 19,
      "z": 16,
      "name": "Soil_Seaweed_Block"
    },
    {
      "x": -36,
      "y": 20,
      "z": 16,
      "name": "Soil_Seaweed_Block"
    },
    {
      "x": -36,
      "y": 12,
      "z": 41,
      "name": "Soil_Clay_Green"
    },
    {
      "x": -36,
      "y": 13,
      "z": 41,
      "name": "Soil_Clay_Green"
    },
    {
      "x": -36,
      "y": 14,
      "z": 41,
      "name": "Soil_Seaweed_Block"
    },
    {
      "x": -36,
      "y": 12,
      "z": 42,
      "name": "Soil_Clay_Green"
    },
    {
      "x": -36,
      "y": 13,
      "z": 42,
      "name": "Soil_Seaweed_Block"
    },
    {
      "x": -36,
      "y": 14,
      "z": 42,
      "name": "Soil_Clay_Lime"
    },
    {
      "x": -36,
      "y": 15,
      "z": 42,
      "name": "Plant_Grass_Sharp"
    },
    {
      "x": -36,
      "y": 12,
      "z": 43,
      "name": "Soil_Clay_Green"
    },
    {
      "x": -36,
      "y": 13,
      "z": 43,
      "name": "Soil_Clay_Green"
    },
    {
      "x": -36,
      "y": 14,
      "z": 43,
      "name": "Soil_Seaweed_Block"
    },
    {
      "x": -35,
      "y": 41,
      "z": 1,
      "name": "Soil_Clay_Green"
    },
    {
      "x": -35,
      "y": 42,
      "z": 1,
      "name": "Soil_Seaweed_Block"
    },
    {
      "x": -35,
      "y": 41,
      "z": 2,
      "name": "Soil_Clay_Green"
    },
    {
      "x": -35,
      "y": 42,
      "z": 2,
      "name": "Soil_Seaweed_Block"
    },
    {
      "x": -35,
      "y": 43,
      "z": 2,
      "name": "Soil_Clay_Lime"
    },
    {
      "x": -35,
      "y": 44,
      "z": 2,
      "name": "Plant_Grass_Sharp"
    },
    {
      "x": -35,
      "y": 41,
      "z": 3,
      "name": "Soil_Clay_Green"
    },
    {
      "x": -35,
      "y": 42,
      "z": 3,
      "name": "Soil_Seaweed_Block"
    },
    {
      "x": -35,
      "y": 3,
      "z": 4,
      "name": "Soil_Clay_Green"
    },
    {
      "x": -35,
      "y": 4,
      "z": 4,
      "name": "Soil_Clay_Green"
    },
    {
      "x": -35,
      "y": 5,
      "z": 4,
      "name": "Soil_Seaweed_Block"
    },
    {
      "x": -35,
      "y": 6,
      "z": 4,
      "name": "Soil_Seaweed_Block"
    },
    {
      "x": -35,
      "y": 3,
      "z": 5,
      "name": "Soil_Clay_Green"
    },
    {
      "x": -35,
      "y": 4,
      "z": 5,
      "name": "Soil_Clay_Green"
    },
    {
      "x": -35,
      "y": 5,
      "z": 5,
      "name": "Soil_Seaweed_Block"
    },
    {
      "x": -35,
      "y": 6,
      "z": 5,
      "name": "Soil_Seaweed_Block"
    },
    {
      "x": -35,
      "y": 7,
      "z": 5,
      "name": "Soil_Seaweed_Block"
    },
    {
      "x": -35,
      "y": 3,
      "z": 6,
      "name": "Soil_Clay_Green"
    },
    {
      "x": -35,
      "y": 4,
      "z": 6,
      "name": "Soil_Clay_Green"
    },
    {
      "x": -35,
      "y": 5,
      "z": 6,
      "name": "Soil_Seaweed_Block"
    },
    {
      "x": -35,
      "y": 6,
      "z": 6,
      "name": "Soil_Seaweed_Block"
    },
    {
      "x": -35,
      "y": 7,
      "z": 6,
      "name": "Soil_Seaweed_Block"
    },
    {
      "x": -35,
      "y": 8,
      "z": 6,
      "name": "Soil_Seaweed_Block"
    },
    {
      "x": -35,
      "y": 9,
      "z": 6,
      "name": "Soil_Seaweed_Block"
    },
    {
      "x": -35,
      "y": 4,
      "z": 7,
      "name": "Soil_Clay_Green"
    },
    {
      "x": -35,
      "y": 5,
      "z": 7,
      "name": "Soil_Clay_Green"
    },
    {
      "x": -35,
      "y": 6,
      "z": 7,
      "name": "Soil_Seaweed_Block"
    },
    {
      "x": -35,
      "y": 7,
      "z": 7,
      "name": "Soil_Seaweed_Block"
    },
    {
      "x": -35,
      "y": 8,
      "z": 7,
      "name": "Soil_Seaweed_Block"
    },
    {
      "x": -35,
      "y": 9,
      "z": 7,
      "name": "Soil_Seaweed_Block"
    },
    {
      "x": -35,
      "y": 10,
      "z": 7,
      "name": "Soil_Seaweed_Block"
    },
    {
      "x": -35,
      "y": 6,
      "z": 8,
      "name": "Soil_Clay_Green"
    },
    {
      "x": -35,
      "y": 7,
      "z": 8,
      "name": "Soil_Seaweed_Block"
    },
    {
      "x": -35,
      "y": 8,
      "z": 8,
      "name": "Soil_Seaweed_Block"
    },
    {
      "x": -35,
      "y": 9,
      "z": 8,
      "name": "Soil_Seaweed_Block"
    },
    {
      "x": -35,
      "y": 10,
      "z": 8,
      "name": "Soil_Seaweed_Block"
    },
    {
      "x": -35,
      "y": 11,
      "z": 8,
      "name": "Soil_Seaweed_Block"
    },
    {
      "x": -35,
      "y": 7,
      "z": 9,
      "name": "Soil_Clay_Green"
    },
    {
      "x": -35,
      "y": 8,
      "z": 9,
      "name": "Soil_Seaweed_Block"
    },
    {
      "x": -35,
      "y": 9,
      "z": 9,
      "name": "Soil_Seaweed_Block"
    },
    {
      "x": -35,
      "y": 10,
      "z": 9,
      "name": "Soil_Seaweed_Block"
    },
    {
      "x": -35,
      "y": 11,
      "z": 9,
      "name": "Soil_Seaweed_Block"
    },
    {
      "x": -35,
      "y": 12,
      "z": 9,
      "name": "Soil_Seaweed_Block"
    },
    {
      "x": -35,
      "y": 8,
      "z": 10,
      "name": "Soil_Clay_Green"
    },
    {
      "x": -35,
      "y": 9,
      "z": 10,
      "name": "Soil_Seaweed_Block"
    },
    {
      "x": -35,
      "y": 10,
      "z": 10,
      "name": "Soil_Seaweed_Block"
    },
    {
      "x": -35,
      "y": 11,
      "z": 10,
      "name": "Soil_Seaweed_Block"
    },
    {
      "x": -35,
      "y": 12,
      "z": 10,
      "name": "Soil_Seaweed_Block"
    },
    {
      "x": -35,
      "y": 9,
      "z": 11,
      "name": "Soil_Clay_Green"
    },
    {
      "x": -35,
      "y": 10,
      "z": 11,
      "name": "Soil_Seaweed_Block"
    },
    {
      "x": -35,
      "y": 11,
      "z": 11,
      "name": "Soil_Seaweed_Block"
    },
    {
      "x": -35,
      "y": 12,
      "z": 11,
      "name": "Soil_Seaweed_Block"
    },
    {
      "x": -35,
      "y": 13,
      "z": 11,
      "name": "Soil_Seaweed_Block"
    },
    {
      "x": -35,
      "y": 14,
      "z": 11,
      "name": "Soil_Clay_Green"
    },
    {
      "x": -35,
      "y": 15,
      "z": 11,
      "name": "Soil_Clay_Green"
    },
    {
      "x": -35,
      "y": 16,
      "z": 11,
      "name": "Soil_Seaweed_Block"
    },
    {
      "x": -35,
      "y": 17,
      "z": 11,
      "name": "Soil_Seaweed_Block"
    },
    {
      "x": -35,
      "y": 18,
      "z": 11,
      "name": "Soil_Seaweed_Block"
    },
    {
      "x": -35,
      "y": 9,
      "z": 12,
      "name": "Soil_Clay_Green"
    },
    {
      "x": -35,
      "y": 10,
      "z": 12,
      "name": "Soil_Clay_Green"
    },
    {
      "x": -35,
      "y": 11,
      "z": 12,
      "name": "Soil_Seaweed_Block"
    },
    {
      "x": -35,
      "y": 12,
      "z": 12,
      "name": "Soil_Seaweed_Block"
    },
    {
      "x": -35,
      "y": 13,
      "z": 12,
      "name": "Soil_Clay_Green"
    },
    {
      "x": -35,
      "y": 14,
      "z": 12,
      "name": "Soil_Seaweed_Block"
    },
    {
      "x": -35,
      "y": 15,
      "z": 12,
      "name": "Soil_Seaweed_Block"
    },
    {
      "x": -35,
      "y": 16,
      "z": 12,
      "name": "Soil_Seaweed_Block"
    },
    {
      "x": -35,
      "y": 17,
      "z": 12,
      "name": "Soil_Seaweed_Block"
    },
    {
      "x": -35,
      "y": 18,
      "z": 12,
      "name": "Soil_Seaweed_Block"
    },
    {
      "x": -35,
      "y": 10,
      "z": 13,
      "name": "Soil_Clay_Green"
    },
    {
      "x": -35,
      "y": 11,
      "z": 13,
      "name": "Soil_Clay_Green"
    },
    {
      "x": -35,
      "y": 12,
      "z": 13,
      "name": "Soil_Clay_Green"
    },
    {
      "x": -35,
      "y": 13,
      "z": 13,
      "name": "Soil_Clay_Green"
    },
    {
      "x": -35,
      "y": 14,
      "z": 13,
      "name": "Soil_Seaweed_Block"
    },
    {
      "x": -35,
      "y": 15,
      "z": 13,
      "name": "Soil_Seaweed_Block"
    },
    {
      "x": -35,
      "y": 16,
      "z": 13,
      "name": "Soil_Seaweed_Block"
    },
    {
      "x": -35,
      "y": 17,
      "z": 13,
      "name": "Soil_Seaweed_Block"
    },
    {
      "x": -35,
      "y": 18,
      "z": 13,
      "name": "Soil_Seaweed_Block"
    },
    {
      "x": -35,
      "y": 19,
      "z": 13,
      "name": "Soil_Clay_Lime"
    },
    {
      "x": -35,
      "y": 20,
      "z": 13,
      "name": "Plant_Grass_Sharp"
    },
    {
      "x": -35,
      "y": 10,
      "z": 14,
      "name": "Soil_Clay_Green"
    },
    {
      "x": -35,
      "y": 11,
      "z": 14,
      "name": "Soil_Clay_Green"
    },
    {
      "x": -35,
      "y": 12,
      "z": 14,
      "name": "Soil_Clay_Green"
    },
    {
      "x": -35,
      "y": 13,
      "z": 14,
      "name": "Soil_Clay_Green"
    },
    {
      "x": -35,
      "y": 14,
      "z": 14,
      "name": "Soil_Seaweed_Block"
    },
    {
      "x": -35,
      "y": 15,
      "z": 14,
      "name": "Soil_Seaweed_Block"
    },
    {
      "x": -35,
      "y": 16,
      "z": 14,
      "name": "Soil_Seaweed_Block"
    },
    {
      "x": -35,
      "y": 17,
      "z": 14,
      "name": "Soil_Seaweed_Block"
    },
    {
      "x": -35,
      "y": 18,
      "z": 14,
      "name": "Soil_Seaweed_Block"
    },
    {
      "x": -35,
      "y": 19,
      "z": 14,
      "name": "Soil_Seaweed_Block"
    },
    {
      "x": -35,
      "y": 20,
      "z": 14,
      "name": "Soil_Clay_Lime"
    },
    {
      "x": -35,
      "y": 21,
      "z": 14,
      "name": "Plant_Grass_Sharp"
    },
    {
      "x": -35,
      "y": 14,
      "z": 15,
      "name": "Soil_Clay_Green"
    },
    {
      "x": -35,
      "y": 15,
      "z": 15,
      "name": "Soil_Seaweed_Block"
    },
    {
      "x": -35,
      "y": 16,
      "z": 15,
      "name": "Soil_Seaweed_Block"
    },
    {
      "x": -35,
      "y": 17,
      "z": 15,
      "name": "Soil_Seaweed_Block"
    },
    {
      "x": -35,
      "y": 18,
      "z": 15,
      "name": "Soil_Seaweed_Block"
    },
    {
      "x": -35,
      "y": 19,
      "z": 15,
      "name": "Soil_Seaweed_Block"
    },
    {
      "x": -35,
      "y": 20,
      "z": 15,
      "name": "Soil_Seaweed_Block"
    },
    {
      "x": -35,
      "y": 15,
      "z": 16,
      "name": "Soil_Clay_Green"
    },
    {
      "x": -35,
      "y": 16,
      "z": 16,
      "name": "Soil_Clay_Green"
    },
    {
      "x": -35,
      "y": 17,
      "z": 16,
      "name": "Soil_Seaweed_Block"
    },
    {
      "x": -35,
      "y": 18,
      "z": 16,
      "name": "Soil_Seaweed_Block"
    },
    {
      "x": -35,
      "y": 13,
      "z": 41,
      "name": "Soil_Clay_Green"
    },
    {
      "x": -35,
      "y": 14,
      "z": 41,
      "name": "Soil_Seaweed_Block"
    },
    {
      "x": -35,
      "y": 15,
      "z": 41,
      "name": "Soil_Clay_Lime"
    },
    {
      "x": -35,
      "y": 16,
      "z": 41,
      "name": "Plant_Grass_Sharp"
    },
    {
      "x": -35,
      "y": 12,
      "z": 42,
      "name": "Soil_Clay_Green"
    },
    {
      "x": -35,
      "y": 13,
      "z": 42,
      "name": "Soil_Seaweed_Block"
    },
    {
      "x": -35,
      "y": 14,
      "z": 42,
      "name": "Soil_Seaweed_Block"
    },
    {
      "x": -35,
      "y": 15,
      "z": 42,
      "name": "Soil_Clay_Lime"
    },
    {
      "x": -35,
      "y": 16,
      "z": 42,
      "name": "Plant_Grass_Sharp"
    },
    {
      "x": -35,
      "y": 13,
      "z": 43,
      "name": "Soil_Clay_Green"
    },
    {
      "x": -35,
      "y": 14,
      "z": 43,
      "name": "Soil_Seaweed_Block"
    },
    {
      "x": -34,
      "y": 41,
      "z": 0,
      "name": "Soil_Clay_Green"
    },
    {
      "x": -34,
      "y": 42,
      "z": 0,
      "name": "Soil_Clay_Lime"
    },
    {
      "x": -34,
      "y": 43,
      "z": 0,
      "name": "Plant_Grass_Sharp"
    },
    {
      "x": -34,
      "y": 40,
      "z": 1,
      "name": "Soil_Clay_Green"
    },
    {
      "x": -34,
      "y": 41,
      "z": 1,
      "name": "Soil_Seaweed_Block"
    },
    {
      "x": -34,
      "y": 42,
      "z": 1,
      "name": "Soil_Clay_Lime"
    },
    {
      "x": -34,
      "y": 43,
      "z": 1,
      "name": "Plant_Grass_Sharp"
    },
    {
      "x": -34,
      "y": 40,
      "z": 2,
      "name": "Soil_Clay_Green"
    },
    {
      "x": -34,
      "y": 41,
      "z": 2,
      "name": "Soil_Clay_Green"
    },
    {
      "x": -34,
      "y": 42,
      "z": 2,
      "name": "Soil_Clay_Lime"
    },
    {
      "x": -34,
      "y": 43,
      "z": 2,
      "name": "Plant_Grass_Sharp"
    },
    {
      "x": -34,
      "y": 5,
      "z": 5,
      "name": "Soil_Clay_Green"
    },
    {
      "x": -34,
      "y": 6,
      "z": 5,
      "name": "Soil_Clay_Green"
    },
    {
      "x": -34,
      "y": 7,
      "z": 5,
      "name": "Soil_Clay_Green"
    },
    {
      "x": -34,
      "y": 8,
      "z": 5,
      "name": "Soil_Seaweed_Block"
    },
    {
      "x": -34,
      "y": 9,
      "z": 5,
      "name": "Soil_Seaweed_Block"
    },
    {
      "x": -34,
      "y": 5,
      "z": 6,
      "name": "Soil_Clay_Green"
    },
    {
      "x": -34,
      "y": 6,
      "z": 6,
      "name": "Soil_Seaweed_Block"
    },
    {
      "x": -34,
      "y": 7,
      "z": 6,
      "name": "Soil_Seaweed_Block"
    },
    {
      "x": -34,
      "y": 8,
      "z": 6,
      "name": "Soil_Seaweed_Block"
    },
    {
      "x": -34,
      "y": 9,
      "z": 6,
      "name": "Soil_Seaweed_Block"
    },
    {
      "x": -34,
      "y": 10,
      "z": 6,
      "name": "Soil_Seaweed_Block"
    },
    {
      "x": -34,
      "y": 6,
      "z": 7,
      "name": "Soil_Clay_Green"
    },
    {
      "x": -34,
      "y": 7,
      "z": 7,
      "name": "Soil_Seaweed_Block"
    },
    {
      "x": -34,
      "y": 8,
      "z": 7,
      "name": "Soil_Seaweed_Block"
    },
    {
      "x": -34,
      "y": 9,
      "z": 7,
      "name": "Soil_Seaweed_Block"
    },
    {
      "x": -34,
      "y": 10,
      "z": 7,
      "name": "Soil_Seaweed_Block"
    },
    {
      "x": -34,
      "y": 11,
      "z": 7,
      "name": "Soil_Clay_Lime"
    },
    {
      "x": -34,
      "y": 12,
      "z": 7,
      "name": "Plant_Grass_Sharp"
    },
    {
      "x": -34,
      "y": 7,
      "z": 8,
      "name": "Soil_Clay_Green"
    },
    {
      "x": -34,
      "y": 8,
      "z": 8,
      "name": "Soil_Seaweed_Block"
    },
    {
      "x": -34,
      "y": 9,
      "z": 8,
      "name": "Soil_Seaweed_Block"
    },
    {
      "x": -34,
      "y": 10,
      "z": 8,
      "name": "Soil_Seaweed_Block"
    },
    {
      "x": -34,
      "y": 11,
      "z": 8,
      "name": "Soil_Seaweed_Block"
    },
    {
      "x": -34,
      "y": 12,
      "z": 8,
      "name": "Soil_Seaweed_Block"
    },
    {
      "x": -34,
      "y": 7,
      "z": 9,
      "name": "Soil_Clay_Green"
    },
    {
      "x": -34,
      "y": 8,
      "z": 9,
      "name": "Soil_Seaweed_Block"
    },
    {
      "x": -34,
      "y": 9,
      "z": 9,
      "name": "Soil_Seaweed_Block"
    },
    {
      "x": -34,
      "y": 10,
      "z": 9,
      "name": "Soil_Seaweed_Block"
    },
    {
      "x": -34,
      "y": 11,
      "z": 9,
      "name": "Soil_Seaweed_Block"
    },
    {
      "x": -34,
      "y": 12,
      "z": 9,
      "name": "Soil_Seaweed_Block"
    },
    {
      "x": -34,
      "y": 8,
      "z": 10,
      "name": "Soil_Clay_Green"
    },
    {
      "x": -34,
      "y": 9,
      "z": 10,
      "name": "Soil_Seaweed_Block"
    },
    {
      "x": -34,
      "y": 10,
      "z": 10,
      "name": "Soil_Seaweed_Block"
    },
    {
      "x": -34,
      "y": 11,
      "z": 10,
      "name": "Soil_Seaweed_Block"
    },
    {
      "x": -34,
      "y": 12,
      "z": 10,
      "name": "Soil_Seaweed_Block"
    },
    {
      "x": -34,
      "y": 13,
      "z": 10,
      "name": "Soil_Seaweed_Block"
    },
    {
      "x": -34,
      "y": 14,
      "z": 10,
      "name": "Soil_Seaweed_Block"
    },
    {
      "x": -34,
      "y": 15,
      "z": 10,
      "name": "Soil_Seaweed_Block"
    },
    {
      "x": -34,
      "y": 8,
      "z": 11,
      "name": "Soil_Clay_Green"
    },
    {
      "x": -34,
      "y": 9,
      "z": 11,
      "name": "Soil_Seaweed_Block"
    },
    {
      "x": -34,
      "y": 10,
      "z": 11,
      "name": "Soil_Seaweed_Block"
    },
    {
      "x": -34,
      "y": 11,
      "z": 11,
      "name": "Soil_Seaweed_Block"
    },
    {
      "x": -34,
      "y": 12,
      "z": 11,
      "name": "Soil_Seaweed_Block"
    },
    {
      "x": -34,
      "y": 13,
      "z": 11,
      "name": "Soil_Seaweed_Block"
    },
    {
      "x": -34,
      "y": 14,
      "z": 11,
      "name": "Soil_Seaweed_Block"
    },
    {
      "x": -34,
      "y": 15,
      "z": 11,
      "name": "Soil_Seaweed_Block"
    },
    {
      "x": -34,
      "y": 16,
      "z": 11,
      "name": "Soil_Seaweed_Block"
    },
    {
      "x": -34,
      "y": 17,
      "z": 11,
      "name": "Soil_Seaweed_Block"
    },
    {
      "x": -34,
      "y": 9,
      "z": 12,
      "name": "Soil_Clay_Green"
    },
    {
      "x": -34,
      "y": 10,
      "z": 12,
      "name": "Soil_Seaweed_Block"
    },
    {
      "x": -34,
      "y": 11,
      "z": 12,
      "name": "Soil_Seaweed_Block"
    },
    {
      "x": -34,
      "y": 12,
      "z": 12,
      "name": "Soil_Seaweed_Block"
    },
    {
      "x": -34,
      "y": 13,
      "z": 12,
      "name": "Soil_Seaweed_Block"
    },
    {
      "x": -34,
      "y": 14,
      "z": 12,
      "name": "Soil_Seaweed_Block"
    },
    {
      "x": -34,
      "y": 15,
      "z": 12,
      "name": "Soil_Seaweed_Block"
    },
    {
      "x": -34,
      "y": 16,
      "z": 12,
      "name": "Soil_Seaweed_Block"
    },
    {
      "x": -34,
      "y": 17,
      "z": 12,
      "name": "Soil_Seaweed_Block"
    },
    {
      "x": -34,
      "y": 18,
      "z": 12,
      "name": "Soil_Clay_Lime"
    },
    {
      "x": -34,
      "y": 19,
      "z": 12,
      "name": "Plant_Grass_Sharp"
    },
    {
      "x": -34,
      "y": 9,
      "z": 13,
      "name": "Soil_Clay_Green"
    },
    {
      "x": -34,
      "y": 10,
      "z": 13,
      "name": "Soil_Seaweed_Block"
    },
    {
      "x": -34,
      "y": 11,
      "z": 13,
      "name": "Soil_Seaweed_Block"
    },
    {
      "x": -34,
      "y": 12,
      "z": 13,
      "name": "Soil_Seaweed_Block"
    },
    {
      "x": -34,
      "y": 13,
      "z": 13,
      "name": "Soil_Seaweed_Block"
    },
    {
      "x": -34,
      "y": 14,
      "z": 13,
      "name": "Soil_Seaweed_Block"
    },
    {
      "x": -34,
      "y": 15,
      "z": 13,
      "name": "Soil_Seaweed_Block"
    },
    {
      "x": -34,
      "y": 16,
      "z": 13,
      "name": "Soil_Seaweed_Block"
    },
    {
      "x": -34,
      "y": 17,
      "z": 13,
      "name": "Soil_Seaweed_Block"
    },
    {
      "x": -34,
      "y": 18,
      "z": 13,
      "name": "Soil_Seaweed_Block"
    },
    {
      "x": -34,
      "y": 19,
      "z": 13,
      "name": "Soil_Clay_Lime"
    },
    {
      "x": -34,
      "y": 20,
      "z": 13,
      "name": "Plant_Grass_Sharp"
    },
    {
      "x": -34,
      "y": 9,
      "z": 14,
      "name": "Soil_Clay_Green"
    },
    {
      "x": -34,
      "y": 10,
      "z": 14,
      "name": "Soil_Clay_Green"
    },
    {
      "x": -34,
      "y": 11,
      "z": 14,
      "name": "Soil_Clay_Green"
    },
    {
      "x": -34,
      "y": 12,
      "z": 14,
      "name": "Soil_Seaweed_Block"
    },
    {
      "x": -34,
      "y": 13,
      "z": 14,
      "name": "Soil_Seaweed_Block"
    },
    {
      "x": -34,
      "y": 14,
      "z": 14,
      "name": "Soil_Seaweed_Block"
    },
    {
      "x": -34,
      "y": 15,
      "z": 14,
      "name": "Soil_Seaweed_Block"
    },
    {
      "x": -34,
      "y": 16,
      "z": 14,
      "name": "Soil_Seaweed_Block"
    },
    {
      "x": -34,
      "y": 17,
      "z": 14,
      "name": "Soil_Seaweed_Block"
    },
    {
      "x": -34,
      "y": 18,
      "z": 14,
      "name": "Soil_Seaweed_Block"
    },
    {
      "x": -34,
      "y": 19,
      "z": 14,
      "name": "Soil_Clay_Lime"
    },
    {
      "x": -34,
      "y": 20,
      "z": 14,
      "name": "Plant_Grass_Sharp"
    },
    {
      "x": -34,
      "y": 12,
      "z": 15,
      "name": "Soil_Clay_Green"
    },
    {
      "x": -34,
      "y": 13,
      "z": 15,
      "name": "Soil_Clay_Green"
    },
    {
      "x": -34,
      "y": 14,
      "z": 15,
      "name": "Soil_Seaweed_Block"
    },
    {
      "x": -34,
      "y": 15,
      "z": 15,
      "name": "Soil_Seaweed_Block"
    },
    {
      "x": -34,
      "y": 16,
      "z": 15,
      "name": "Soil_Seaweed_Block"
    },
    {
      "x": -34,
      "y": 17,
      "z": 15,
      "name": "Soil_Seaweed_Block"
    },
    {
      "x": -34,
      "y": 18,
      "z": 15,
      "name": "Soil_Seaweed_Block"
    },
    {
      "x": -34,
      "y": 14,
      "z": 16,
      "name": "Soil_Clay_Green"
    },
    {
      "x": -34,
      "y": 15,
      "z": 16,
      "name": "Soil_Clay_Green"
    },
    {
      "x": -34,
      "y": 16,
      "z": 16,
      "name": "Soil_Seaweed_Block"
    },
    {
      "x": -34,
      "y": 20,
      "z": 28,
      "name": "Soil_Seaweed_Block"
    },
    {
      "x": -34,
      "y": 20,
      "z": 29,
      "name": "Soil_Seaweed_Block"
    },
    {
      "x": -34,
      "y": 14,
      "z": 41,
      "name": "Soil_Clay_Green"
    },
    {
      "x": -34,
      "y": 15,
      "z": 41,
      "name": "Soil_Seaweed_Block"
    },
    {
      "x": -34,
      "y": 13,
      "z": 42,
      "name": "Soil_Clay_Green"
    },
    {
      "x": -34,
      "y": 14,
      "z": 42,
      "name": "Soil_Seaweed_Block"
    },
    {
      "x": -34,
      "y": 15,
      "z": 42,
      "name": "Soil_Seaweed_Block"
    },
    {
      "x": -34,
      "y": 14,
      "z": 43,
      "name": "Soil_Seaweed_Block"
    },
    {
      "x": -34,
      "y": 15,
      "z": 43,
      "name": "Soil_Seaweed_Block"
    },
    {
      "x": -33,
      "y": 41,
      "z": -1,
      "name": "Soil_Seaweed_Block"
    },
    {
      "x": -33,
      "y": 42,
      "z": -1,
      "name": "Soil_Clay_Lime"
    },
    {
      "x": -33,
      "y": 43,
      "z": -1,
      "name": "Plant_Grass_Sharp"
    },
    {
      "x": -33,
      "y": 40,
      "z": 0,
      "name": "Soil_Clay_Green"
    },
    {
      "x": -33,
      "y": 41,
      "z": 0,
      "name": "Soil_Seaweed_Block"
    },
    {
      "x": -33,
      "y": 42,
      "z": 0,
      "name": "Soil_Clay_Lime"
    },
    {
      "x": -33,
      "y": 43,
      "z": 0,
      "name": "Plant_Grass_Sharp"
    },
    {
      "x": -33,
      "y": 40,
      "z": 1,
      "name": "Soil_Clay_Green"
    },
    {
      "x": -33,
      "y": 41,
      "z": 1,
      "name": "Soil_Seaweed_Block"
    },
    {
      "x": -33,
      "y": 42,
      "z": 1,
      "name": "Soil_Clay_Lime"
    },
    {
      "x": -33,
      "y": 43,
      "z": 1,
      "name": "Plant_Grass_Sharp"
    },
    {
      "x": -33,
      "y": 6,
      "z": 6,
      "name": "Soil_Clay_Green"
    },
    {
      "x": -33,
      "y": 7,
      "z": 6,
      "name": "Soil_Clay_Green"
    },
    {
      "x": -33,
      "y": 8,
      "z": 6,
      "name": "Soil_Clay_Green"
    },
    {
      "x": -33,
      "y": 9,
      "z": 6,
      "name": "Soil_Seaweed_Block"
    },
    {
      "x": -33,
      "y": 10,
      "z": 6,
      "name": "Soil_Seaweed_Block"
    },
    {
      "x": -33,
      "y": 6,
      "z": 7,
      "name": "Soil_Clay_Green"
    },
    {
      "x": -33,
      "y": 7,
      "z": 7,
      "name": "Soil_Seaweed_Block"
    },
    {
      "x": -33,
      "y": 8,
      "z": 7,
      "name": "Soil_Seaweed_Block"
    },
    {
      "x": -33,
      "y": 9,
      "z": 7,
      "name": "Soil_Seaweed_Block"
    },
    {
      "x": -33,
      "y": 10,
      "z": 7,
      "name": "Soil_Seaweed_Block"
    },
    {
      "x": -33,
      "y": 11,
      "z": 7,
      "name": "Soil_Seaweed_Block"
    },
    {
      "x": -33,
      "y": 7,
      "z": 8,
      "name": "Soil_Clay_Green"
    },
    {
      "x": -33,
      "y": 8,
      "z": 8,
      "name": "Soil_Seaweed_Block"
    },
    {
      "x": -33,
      "y": 9,
      "z": 8,
      "name": "Soil_Seaweed_Block"
    },
    {
      "x": -33,
      "y": 10,
      "z": 8,
      "name": "Soil_Seaweed_Block"
    },
    {
      "x": -33,
      "y": 11,
      "z": 8,
      "name": "Soil_Seaweed_Block"
    },
    {
      "x": -33,
      "y": 12,
      "z": 8,
      "name": "Soil_Seaweed_Block"
    },
    {
      "x": -33,
      "y": 7,
      "z": 9,
      "name": "Soil_Clay_Green"
    },
    {
      "x": -33,
      "y": 8,
      "z": 9,
      "name": "Soil_Seaweed_Block"
    },
    {
      "x": -33,
      "y": 9,
      "z": 9,
      "name": "Soil_Seaweed_Block"
    },
    {
      "x": -33,
      "y": 10,
      "z": 9,
      "name": "Soil_Seaweed_Block"
    },
    {
      "x": -33,
      "y": 11,
      "z": 9,
      "name": "Soil_Seaweed_Block"
    },
    {
      "x": -33,
      "y": 12,
      "z": 9,
      "name": "Soil_Seaweed_Block"
    },
    {
      "x": -33,
      "y": 13,
      "z": 9,
      "name": "Soil_Seaweed_Block"
    },
    {
      "x": -33,
      "y": 14,
      "z": 9,
      "name": "Soil_Seaweed_Block"
    },
    {
      "x": -33,
      "y": 8,
      "z": 10,
      "name": "Soil_Clay_Green"
    },
    {
      "x": -33,
      "y": 9,
      "z": 10,
      "name": "Soil_Seaweed_Block"
    },
    {
      "x": -33,
      "y": 10,
      "z": 10,
      "name": "Soil_Seaweed_Block"
    },
    {
      "x": -33,
      "y": 11,
      "z": 10,
      "name": "Soil_Seaweed_Block"
    },
    {
      "x": -33,
      "y": 12,
      "z": 10,
      "name": "Soil_Seaweed_Block"
    },
    {
      "x": -33,
      "y": 13,
      "z": 10,
      "name": "Soil_Seaweed_Block"
    },
    {
      "x": -33,
      "y": 14,
      "z": 10,
      "name": "Soil_Seaweed_Block"
    },
    {
      "x": -33,
      "y": 15,
      "z": 10,
      "name": "Soil_Seaweed_Block"
    },
    {
      "x": -33,
      "y": 8,
      "z": 11,
      "name": "Soil_Clay_Green"
    },
    {
      "x": -33,
      "y": 9,
      "z": 11,
      "name": "Soil_Seaweed_Block"
    },
    {
      "x": -33,
      "y": 10,
      "z": 11,
      "name": "Soil_Seaweed_Block"
    },
    {
      "x": -33,
      "y": 11,
      "z": 11,
      "name": "Soil_Seaweed_Block"
    },
    {
      "x": -33,
      "y": 12,
      "z": 11,
      "name": "Soil_Seaweed_Block"
    },
    {
      "x": -33,
      "y": 13,
      "z": 11,
      "name": "Soil_Seaweed_Block"
    },
    {
      "x": -33,
      "y": 14,
      "z": 11,
      "name": "Soil_Seaweed_Block"
    },
    {
      "x": -33,
      "y": 15,
      "z": 11,
      "name": "Soil_Seaweed_Block"
    },
    {
      "x": -33,
      "y": 16,
      "z": 11,
      "name": "Soil_Seaweed_Block"
    },
    {
      "x": -33,
      "y": 17,
      "z": 11,
      "name": "Soil_Clay_Lime"
    },
    {
      "x": -33,
      "y": 18,
      "z": 11,
      "name": "Plant_Grass_Sharp"
    },
    {
      "x": -33,
      "y": 8,
      "z": 12,
      "name": "Soil_Clay_Green"
    },
    {
      "x": -33,
      "y": 9,
      "z": 12,
      "name": "Soil_Seaweed_Block"
    },
    {
      "x": -33,
      "y": 10,
      "z": 12,
      "name": "Soil_Seaweed_Block"
    },
    {
      "x": -33,
      "y": 11,
      "z": 12,
      "name": "Soil_Seaweed_Block"
    },
    {
      "x": -33,
      "y": 12,
      "z": 12,
      "name": "Soil_Seaweed_Block"
    },
    {
      "x": -33,
      "y": 13,
      "z": 12,
      "name": "Soil_Seaweed_Block"
    },
    {
      "x": -33,
      "y": 14,
      "z": 12,
      "name": "Soil_Seaweed_Block"
    },
    {
      "x": -33,
      "y": 15,
      "z": 12,
      "name": "Soil_Seaweed_Block"
    },
    {
      "x": -33,
      "y": 16,
      "z": 12,
      "name": "Soil_Seaweed_Block"
    },
    {
      "x": -33,
      "y": 17,
      "z": 12,
      "name": "Soil_Clay_Lime"
    },
    {
      "x": -33,
      "y": 18,
      "z": 12,
      "name": "Plant_Grass_Sharp"
    },
    {
      "x": -33,
      "y": 8,
      "z": 13,
      "name": "Soil_Clay_Green"
    },
    {
      "x": -33,
      "y": 9,
      "z": 13,
      "name": "Soil_Seaweed_Block"
    },
    {
      "x": -33,
      "y": 10,
      "z": 13,
      "name": "Soil_Seaweed_Block"
    },
    {
      "x": -33,
      "y": 11,
      "z": 13,
      "name": "Soil_Seaweed_Block"
    },
    {
      "x": -33,
      "y": 12,
      "z": 13,
      "name": "Soil_Seaweed_Block"
    },
    {
      "x": -33,
      "y": 13,
      "z": 13,
      "name": "Soil_Seaweed_Block"
    },
    {
      "x": -33,
      "y": 14,
      "z": 13,
      "name": "Soil_Seaweed_Block"
    },
    {
      "x": -33,
      "y": 15,
      "z": 13,
      "name": "Soil_Seaweed_Block"
    },
    {
      "x": -33,
      "y": 16,
      "z": 13,
      "name": "Soil_Seaweed_Block"
    },
    {
      "x": -33,
      "y": 17,
      "z": 13,
      "name": "Soil_Seaweed_Block"
    },
    {
      "x": -33,
      "y": 18,
      "z": 13,
      "name": "Soil_Clay_Lime"
    },
    {
      "x": -33,
      "y": 19,
      "z": 13,
      "name": "Plant_Grass_Sharp"
    },
    {
      "x": -33,
      "y": 9,
      "z": 14,
      "name": "Soil_Clay_Green"
    },
    {
      "x": -33,
      "y": 10,
      "z": 14,
      "name": "Soil_Seaweed_Block"
    },
    {
      "x": -33,
      "y": 11,
      "z": 14,
      "name": "Soil_Seaweed_Block"
    },
    {
      "x": -33,
      "y": 12,
      "z": 14,
      "name": "Soil_Seaweed_Block"
    },
    {
      "x": -33,
      "y": 13,
      "z": 14,
      "name": "Soil_Seaweed_Block"
    },
    {
      "x": -33,
      "y": 14,
      "z": 14,
      "name": "Soil_Seaweed_Block"
    },
    {
      "x": -33,
      "y": 15,
      "z": 14,
      "name": "Soil_Seaweed_Block"
    },
    {
      "x": -33,
      "y": 16,
      "z": 14,
      "name": "Soil_Seaweed_Block"
    },
    {
      "x": -33,
      "y": 17,
      "z": 14,
      "name": "Soil_Seaweed_Block"
    },
    {
      "x": -33,
      "y": 18,
      "z": 14,
      "name": "Soil_Clay_Lime"
    },
    {
      "x": -33,
      "y": 19,
      "z": 14,
      "name": "Plant_Grass_Sharp"
    },
    {
      "x": -33,
      "y": 10,
      "z": 15,
      "name": "Soil_Clay_Green"
    },
    {
      "x": -33,
      "y": 11,
      "z": 15,
      "name": "Soil_Clay_Green"
    },
    {
      "x": -33,
      "y": 12,
      "z": 15,
      "name": "Soil_Seaweed_Block"
    },
    {
      "x": -33,
      "y": 13,
      "z": 15,
      "name": "Soil_Seaweed_Block"
    },
    {
      "x": -33,
      "y": 14,
      "z": 15,
      "name": "Soil_Seaweed_Block"
    },
    {
      "x": -33,
      "y": 15,
      "z": 15,
      "name": "Soil_Seaweed_Block"
    },
    {
      "x": -33,
      "y": 16,
      "z": 15,
      "name": "Soil_Seaweed_Block"
    },
    {
      "x": -33,
      "y": 17,
      "z": 15,
      "name": "Soil_Seaweed_Block"
    },
    {
      "x": -33,
      "y": 12,
      "z": 16,
      "name": "Soil_Clay_Green"
    },
    {
      "x": -33,
      "y": 13,
      "z": 16,
      "name": "Soil_Clay_Green"
    },
    {
      "x": -33,
      "y": 14,
      "z": 16,
      "name": "Soil_Clay_Green"
    },
    {
      "x": -33,
      "y": 15,
      "z": 16,
      "name": "Soil_Seaweed_Block"
    },
    {
      "x": -33,
      "y": 16,
      "z": 16,
      "name": "Soil_Seaweed_Block"
    },
    {
      "x": -33,
      "y": 20,
      "z": 27,
      "name": "Soil_Seaweed_Block"
    },
    {
      "x": -33,
      "y": 21,
      "z": 27,
      "name": "Soil_Clay_Lime"
    },
    {
      "x": -33,
      "y": 22,
      "z": 27,
      "name": "Plant_Grass_Sharp"
    },
    {
      "x": -33,
      "y": 20,
      "z": 28,
      "name": "Soil_Seaweed_Block"
    },
    {
      "x": -33,
      "y": 16,
      "z": 39,
      "name": "Soil_Clay_Green"
    },
    {
      "x": -33,
      "y": 17,
      "z": 39,
      "name": "Soil_Seaweed_Block"
    },
    {
      "x": -33,
      "y": 15,
      "z": 40,
      "name": "Soil_Clay_Green"
    },
    {
      "x": -33,
      "y": 16,
      "z": 40,
      "name": "Soil_Seaweed_Block"
    },
    {
      "x": -33,
      "y": 17,
      "z": 40,
      "name": "Soil_Clay_Lime"
    },
    {
      "x": -33,
      "y": 18,
      "z": 40,
      "name": "Soil_Clay_Lime"
    },
    {
      "x": -33,
      "y": 19,
      "z": 40,
      "name": "Plant_Grass_Sharp"
    },
    {
      "x": -33,
      "y": 14,
      "z": 41,
      "name": "Soil_Clay_Green"
    },
    {
      "x": -33,
      "y": 15,
      "z": 41,
      "name": "Soil_Seaweed_Block"
    },
    {
      "x": -33,
      "y": 16,
      "z": 41,
      "name": "Soil_Seaweed_Block"
    },
    {
      "x": -33,
      "y": 17,
      "z": 41,
      "name": "Soil_Clay_Lime"
    },
    {
      "x": -33,
      "y": 18,
      "z": 41,
      "name": "Plant_Grass_Sharp"
    },
    {
      "x": -33,
      "y": 14,
      "z": 42,
      "name": "Soil_Clay_Green"
    },
    {
      "x": -33,
      "y": 15,
      "z": 42,
      "name": "Soil_Clay_Green"
    },
    {
      "x": -32,
      "y": 40,
      "z": -2,
      "name": "Soil_Clay_Green"
    },
    {
      "x": -32,
      "y": 41,
      "z": -2,
      "name": "Soil_Seaweed_Block"
    },
    {
      "x": -32,
      "y": 42,
      "z": -2,
      "name": "Soil_Clay_Lime"
    },
    {
      "x": -32,
      "y": 43,
      "z": -2,
      "name": "Plant_Grass_Sharp"
    },
    {
      "x": -32,
      "y": 40,
      "z": -1,
      "name": "Soil_Clay_Green"
    },
    {
      "x": -32,
      "y": 41,
      "z": -1,
      "name": "Soil_Seaweed_Block"
    },
    {
      "x": -32,
      "y": 42,
      "z": -1,
      "name": "Soil_Clay_Lime"
    },
    {
      "x": -32,
      "y": 43,
      "z": -1,
      "name": "Plant_Grass_Sharp"
    },
    {
      "x": -32,
      "y": 40,
      "z": 0,
      "name": "Soil_Clay_Green"
    },
    {
      "x": -32,
      "y": 41,
      "z": 0,
      "name": "Soil_Seaweed_Block"
    },
    {
      "x": -32,
      "y": 42,
      "z": 0,
      "name": "Soil_Clay_Lime"
    },
    {
      "x": -32,
      "y": 43,
      "z": 0,
      "name": "Plant_Grass_Sharp"
    },
    {
      "x": -32,
      "y": 40,
      "z": 1,
      "name": "Soil_Clay_Green"
    },
    {
      "x": -32,
      "y": 41,
      "z": 1,
      "name": "Soil_Seaweed_Block"
    },
    {
      "x": -32,
      "y": 7,
      "z": 6,
      "name": "Soil_Clay_Green"
    },
    {
      "x": -32,
      "y": 8,
      "z": 6,
      "name": "Soil_Clay_Green"
    },
    {
      "x": -32,
      "y": 9,
      "z": 6,
      "name": "Soil_Seaweed_Block"
    },
    {
      "x": -32,
      "y": 7,
      "z": 7,
      "name": "Soil_Clay_Green"
    },
    {
      "x": -32,
      "y": 8,
      "z": 7,
      "name": "Soil_Seaweed_Block"
    },
    {
      "x": -32,
      "y": 9,
      "z": 7,
      "name": "Soil_Seaweed_Block"
    },
    {
      "x": -32,
      "y": 10,
      "z": 7,
      "name": "Soil_Seaweed_Block"
    },
    {
      "x": -32,
      "y": 11,
      "z": 7,
      "name": "Soil_Seaweed_Block"
    },
    {
      "x": -32,
      "y": 7,
      "z": 8,
      "name": "Soil_Clay_Green"
    },
    {
      "x": -32,
      "y": 8,
      "z": 8,
      "name": "Soil_Seaweed_Block"
    },
    {
      "x": -32,
      "y": 9,
      "z": 8,
      "name": "Soil_Seaweed_Block"
    },
    {
      "x": -32,
      "y": 10,
      "z": 8,
      "name": "Soil_Seaweed_Block"
    },
    {
      "x": -32,
      "y": 11,
      "z": 8,
      "name": "Soil_Seaweed_Block"
    },
    {
      "x": -32,
      "y": 12,
      "z": 8,
      "name": "Soil_Seaweed_Block"
    },
    {
      "x": -32,
      "y": 13,
      "z": 8,
      "name": "Soil_Seaweed_Block"
    },
    {
      "x": -32,
      "y": 7,
      "z": 9,
      "name": "Soil_Clay_Green"
    },
    {
      "x": -32,
      "y": 8,
      "z": 9,
      "name": "Soil_Seaweed_Block"
    },
    {
      "x": -32,
      "y": 9,
      "z": 9,
      "name": "Soil_Seaweed_Block"
    },
    {
      "x": -32,
      "y": 10,
      "z": 9,
      "name": "Soil_Seaweed_Block"
    },
    {
      "x": -32,
      "y": 11,
      "z": 9,
      "name": "Soil_Seaweed_Block"
    },
    {
      "x": -32,
      "y": 12,
      "z": 9,
      "name": "Soil_Seaweed_Block"
    },
    {
      "x": -32,
      "y": 13,
      "z": 9,
      "name": "Soil_Seaweed_Block"
    },
    {
      "x": -32,
      "y": 14,
      "z": 9,
      "name": "Soil_Seaweed_Block"
    },
    {
      "x": -32,
      "y": 8,
      "z": 10,
      "name": "Soil_Clay_Green"
    },
    {
      "x": -32,
      "y": 9,
      "z": 10,
      "name": "Soil_Seaweed_Block"
    },
    {
      "x": -32,
      "y": 10,
      "z": 10,
      "name": "Soil_Seaweed_Block"
    },
    {
      "x": -32,
      "y": 11,
      "z": 10,
      "name": "Soil_Seaweed_Block"
    },
    {
      "x": -32,
      "y": 12,
      "z": 10,
      "name": "Soil_Seaweed_Block"
    },
    {
      "x": -32,
      "y": 13,
      "z": 10,
      "name": "Soil_Seaweed_Block"
    },
    {
      "x": -32,
      "y": 14,
      "z": 10,
      "name": "Soil_Seaweed_Block"
    },
    {
      "x": -32,
      "y": 15,
      "z": 10,
      "name": "Soil_Seaweed_Block"
    },
    {
      "x": -32,
      "y": 8,
      "z": 11,
      "name": "Soil_Clay_Green"
    },
    {
      "x": -32,
      "y": 9,
      "z": 11,
      "name": "Soil_Seaweed_Block"
    },
    {
      "x": -32,
      "y": 10,
      "z": 11,
      "name": "Soil_Seaweed_Block"
    },
    {
      "x": -32,
      "y": 11,
      "z": 11,
      "name": "Soil_Seaweed_Block"
    },
    {
      "x": -32,
      "y": 12,
      "z": 11,
      "name": "Soil_Seaweed_Block"
    },
    {
      "x": -32,
      "y": 13,
      "z": 11,
      "name": "Soil_Seaweed_Block"
    },
    {
      "x": -32,
      "y": 14,
      "z": 11,
      "name": "Soil_Seaweed_Block"
    },
    {
      "x": -32,
      "y": 15,
      "z": 11,
      "name": "Soil_Seaweed_Block"
    },
    {
      "x": -32,
      "y": 16,
      "z": 11,
      "name": "Soil_Clay_Lime"
    },
    {
      "x": -32,
      "y": 17,
      "z": 11,
      "name": "Soil_Clay_Lime"
    },
    {
      "x": -32,
      "y": 18,
      "z": 11,
      "name": "Plant_Grass_Sharp"
    },
    {
      "x": -32,
      "y": 8,
      "z": 12,
      "name": "Soil_Clay_Green"
    },
    {
      "x": -32,
      "y": 9,
      "z": 12,
      "name": "Soil_Seaweed_Block"
    },
    {
      "x": -32,
      "y": 10,
      "z": 12,
      "name": "Soil_Seaweed_Block"
    },
    {
      "x": -32,
      "y": 11,
      "z": 12,
      "name": "Soil_Seaweed_Block"
    },
    {
      "x": -32,
      "y": 12,
      "z": 12,
      "name": "Soil_Seaweed_Block"
    },
    {
      "x": -32,
      "y": 13,
      "z": 12,
      "name": "Soil_Seaweed_Block"
    },
    {
      "x": -32,
      "y": 14,
      "z": 12,
      "name": "Soil_Seaweed_Block"
    },
    {
      "x": -32,
      "y": 15,
      "z": 12,
      "name": "Soil_Seaweed_Block"
    },
    {
      "x": -32,
      "y": 16,
      "z": 12,
      "name": "Soil_Seaweed_Block"
    },
    {
      "x": -32,
      "y": 17,
      "z": 12,
      "name": "Soil_Clay_Lime"
    },
    {
      "x": -32,
      "y": 18,
      "z": 12,
      "name": "Plant_Grass_Sharp"
    },
    {
      "x": -32,
      "y": 8,
      "z": 13,
      "name": "Soil_Clay_Green"
    },
    {
      "x": -32,
      "y": 9,
      "z": 13,
      "name": "Soil_Seaweed_Block"
    },
    {
      "x": -32,
      "y": 10,
      "z": 13,
      "name": "Soil_Seaweed_Block"
    },
