{
  "version": 8,
  "blockIdVersion": 10,
  "anchorX": 0,
  "anchorY": 15,
  "anchorZ": 0,
  "blocks": [
    {
      "x": -36,
      "y": 10,
      "z": 43,
      "name": "Soil_Clay_Green"
    },
    {
      "x": -36,
      "y": 10,
      "z": 44,
      "name": "Soil_Clay_Green"
    },
    {
      "x": -36,
      "y": 10,
      "z": 45,
      "name": "Soil_Seaweed_Block"
    },
    {
      "x": -36,
      "y": 10,
      "z": 46,
      "name": "Soil_Seaweed_Block"
    },
    {
      "x": -36,
      "y": 10,
      "z": 47,
      "name": "Soil_Clay_Green"
    },
    {
      "x": -35,
      "y": 10,
      "z": 43,
      "name": "Soil_Clay_Green"
    },
    {
      "x": -35,
      "y": 9,
      "z": 44,
      "name": "Soil_Clay_Green"
    },
    {
      "x": -35,
      "y": 10,
      "z": 44,
      "name": "Soil_Clay_Green"
    },
    {
      "x": -34,
      "y": 9,
      "z": 37,
      "name": "Soil_Clay_Green"
    },
    {
      "x": -34,
      "y": 10,
      "z": 37,
      "name": "Soil_Seaweed_Block"
    },
    {
      "x": -34,
      "y": 9,
      "z": 38,
      "name": "Soil_Clay_Green"
    },
    {
      "x": -34,
      "y": 10,
      "z": 38,
      "name": "Soil_Seaweed_Block"
    },
    {
      "x": -34,
      "y": 10,
      "z": 39,
      "name": "Soil_Seaweed_Block"
    },
    {
      "x": -34,
      "y": 10,
      "z": 40,
      "name": "Soil_Seaweed_Block"
    },
    {
      "x": -34,
      "y": 11,
      "z": 41,
      "name": "Soil_Clay_Lime"
    },
    {
      "x": -34,
      "y": 12,
      "z": 41,
      "name": "Plant_Grass_Sharp"
    },
    {
      "x": -34,
      "y": 10,
      "z": 42,
      "name": "Soil_Clay_Green"
    },
    {
      "x": -34,
      "y": 11,
      "z": 42,
      "name": "Soil_Clay_Lime"
    },
    {
      "x": -34,
      "y": 12,
      "z": 42,
      "name": "Plant_Grass_Sharp"
    },
    {
      "x": -34,
      "y": 10,
      "z": 43,
      "name": "Soil_Clay_Green"
    },
    {
      "x": -34,
      "y": 10,
      "z": 44,
      "name": "Soil_Clay_Green"
    },
    {
      "x": -33,
      "y": 8,
      "z": 36,
      "name": "Soil_Clay_Green"
    },
    {
      "x": -33,
      "y": 9,
      "z": 36,
      "name": "Soil_Clay_Green"
    },
    {
      "x": -33,
      "y": 10,
      "z": 36,
      "name": "Soil_Clay_Lime"
    },
    {
      "x": -33,
      "y": 11,
      "z": 36,
      "name": "Plant_Grass_Sharp"
    },
    {
      "x": -33,
      "y": 8,
      "z": 37,
      "name": "Soil_Clay_Green"
    },
    {
      "x": -33,
      "y": 9,
      "z": 37,
      "name": "Soil_Seaweed_Block"
    },
    {
      "x": -33,
      "y": 10,
      "z": 37,
      "name": "Soil_Clay_Lime"
    },
    {
      "x": -33,
      "y": 11,
      "z": 37,
      "name": "Plant_Grass_Sharp"
    },
    {
      "x": -33,
      "y": 8,
      "z": 38,
      "name": "Soil_Clay_Green"
    },
    {
      "x": -33,
      "y": 9,
      "z": 38,
      "name": "Soil_Seaweed_Block"
    },
    {
      "x": -33,
      "y": 10,
      "z": 38,
      "name": "Soil_Seaweed_Block"
    },
    {
      "x": -33,
      "y": 11,
      "z": 38,
      "name": "Soil_Clay_Lime"
    },
    {
      "x": -33,
      "y": 12,
      "z": 38,
      "name": "Plant_Grass_Sharp"
    },
    {
      "x": -33,
      "y": 9,
      "z": 39,
      "name": "Soil_Clay_Green"
    },
    {
      "x": -33,
      "y": 10,
      "z": 39,
      "name": "Soil_Seaweed_Block"
    },
    {
      "x": -33,
      "y": 11,
      "z": 39,
      "name": "Soil_Clay_Lime"
    },
    {
      "x": -33,
      "y": 12,
      "z": 39,
      "name": "Plant_Grass_Sharp"
    },
    {
      "x": -33,
      "y": 9,
      "z": 40,
      "name": "Soil_Clay_Green"
    },
    {
      "x": -33,
      "y": 10,
      "z": 40,
      "name": "Soil_Seaweed_Block"
    },
    {
      "x": -33,
      "y": 11,
      "z": 40,
      "name": "Soil_Clay_Lime"
    },
    {
      "x": -33,
      "y": 12,
      "z": 40,
      "name": "Plant_Grass_Sharp"
    },
    {
      "x": -33,
      "y": 10,
      "z": 41,
      "name": "Soil_Clay_Green"
    },
    {
      "x": -33,
      "y": 11,
      "z": 41,
      "name": "Soil_Clay_Lime"
    },
    {
      "x": -33,
      "y": 12,
      "z": 41,
      "name": "Plant_Grass_Sharp"
    },
    {
      "x": -33,
      "y": 10,
      "z": 42,
      "name": "Soil_Clay_Green"
    },
    {
      "x": -33,
      "y": 11,
      "z": 42,
      "name": "Soil_Clay_Lime"
    },
    {
      "x": -33,
      "y": 12,
      "z": 42,
      "name": "Plant_Grass_Sharp"
    },
    {
      "x": -32,
      "y": 8,
      "z": 36,
      "name": "Soil_Clay_Green"
    },
    {
      "x": -32,
      "y": 9,
      "z": 36,
      "name": "Soil_Clay_Green"
    },
    {
      "x": -32,
      "y": 8,
      "z": 37,
      "name": "Soil_Clay_Green"
    },
    {
      "x": -32,
      "y": 9,
      "z": 37,
      "name": "Soil_Seaweed_Block"
    },
    {
      "x": -32,
      "y": 10,
      "z": 37,
      "name": "Soil_Clay_Lime"
    },
    {
      "x": -32,
      "y": 11,
      "z": 37,
      "name": "Plant_Grass_Sharp"
    },
    {
      "x": -32,
      "y": 8,
      "z": 38,
      "name": "Soil_Clay_Green"
    },
    {
      "x": -32,
      "y": 9,
      "z": 38,
      "name": "Soil_Clay_Green"
    },
    {
      "x": -32,
      "y": 10,
      "z": 38,
      "name": "Soil_Clay_Lime"
    },
    {
      "x": -32,
      "y": 11,
      "z": 38,
      "name": "Plant_Grass_Sharp"
    },
    {
      "x": -32,
      "y": 9,
      "z": 39,
      "name": "Soil_Clay_Green"
    },
    {
      "x": -32,
      "y": 10,
      "z": 39,
      "name": "Soil_Seaweed_Block"
    },
    {
      "x": -32,
      "y": 10,
      "z": 40,
      "name": "Soil_Seaweed_Block"
    },
    {
      "x": -31,
      "y": 23,
      "z": -38,
      "name": "Soil_Clay_Green"
    },
    {
      "x": -31,
      "y": 9,
      "z": 35,
      "name": "Soil_Clay_Green"
    },
    {
      "x": -31,
      "y": 8,
      "z": 36,
      "name": "Soil_Clay_Green"
    },
    {
      "x": -31,
      "y": 9,
      "z": 36,
      "name": "Soil_Clay_Green"
    },
    {
      "x": -31,
      "y": 8,
      "z": 37,
      "name": "Soil_Clay_Green"
    },
    {
      "x": -31,
      "y": 9,
      "z": 37,
      "name": "Soil_Clay_Green"
    },
    {
      "x": -31,
      "y": 10,
      "z": 39,
      "name": "Soil_Seaweed_Block"
    },
    {
      "x": -30,
      "y": 22,
      "z": -45,
      "name": "Soil_Clay_Green"
    },
    {
      "x": -30,
      "y": 24,
      "z": -38,
      "name": "Soil_Seaweed_Block"
    },
    {
      "x": -30,
      "y": 8,
      "z": 34,
      "name": "Soil_Clay_Green"
    },
    {
      "x": -30,
      "y": 9,
      "z": 34,
      "name": "Soil_Clay_Green"
    },
    {
      "x": -30,
      "y": 10,
      "z": 34,
      "name": "Soil_Seaweed_Block"
    },
    {
      "x": -30,
      "y": 8,
      "z": 35,
      "name": "Soil_Clay_Green"
    },
    {
      "x": -30,
      "y": 9,
      "z": 35,
      "name": "Soil_Seaweed_Block"
    },
    {
      "x": -30,
      "y": 10,
      "z": 35,
      "name": "Soil_Seaweed_Block"
    },
    {
      "x": -30,
      "y": 9,
      "z": 36,
      "name": "Soil_Clay_Green"
    },
    {
      "x": -30,
      "y": 10,
      "z": 36,
      "name": "Soil_Seaweed_Block"
    },
    {
      "x": -30,
      "y": 11,
      "z": 36,
      "name": "Soil_Clay_Lime"
    },
    {
      "x": -30,
      "y": 12,
      "z": 36,
      "name": "Plant_Grass_Sharp"
    },
    {
      "x": -29,
      "y": 22,
      "z": -48,
      "name": "Soil_Clay_Green"
    },
    {
      "x": -29,
      "y": 22,
      "z": -47,
      "name": "Soil_Clay_Green"
    },
    {
      "x": -29,
      "y": 22,
      "z": -46,
      "name": "Soil_Clay_Green"
    },
    {
      "x": -29,
      "y": 22,
      "z": -45,
      "name": "Soil_Clay_Green"
    },
    {
      "x": -29,
      "y": 22,
      "z": -44,
      "name": "Soil_Clay_Green"
    },
    {
      "x": -29,
      "y": 29,
      "z": -44,
      "name": "Soil_Seaweed_Block"
    },
    {
      "x": -29,
      "y": 29,
      "z": -43,
      "name": "Soil_Clay_Lime"
    },
    {
      "x": -29,
      "y": 30,
      "z": -43,
      "name": "Plant_Grass_Sharp"
    },
    {
      "x": -29,
      "y": 23,
      "z": -37,
      "name": "Soil_Seaweed_Block"
    },
    {
      "x": -29,
      "y": 22,
      "z": -36,
      "name": "Soil_Clay_Green"
    },
    {
      "x": -29,
      "y": 23,
      "z": -36,
      "name": "Soil_Seaweed_Block"
    },
    {
      "x": -29,
      "y": 9,
      "z": 34,
      "name": "Soil_Clay_Green"
    },
    {
      "x": -29,
      "y": 10,
      "z": 34,
      "name": "Soil_Clay_Green"
    },
    {
      "x": -29,
      "y": 11,
      "z": 34,
      "name": "Soil_Seaweed_Block"
    },
    {
      "x": -29,
      "y": 8,
      "z": 35,
      "name": "Soil_Clay_Green"
    },
    {
      "x": -29,
      "y": 9,
      "z": 35,
      "name": "Soil_Seaweed_Block"
    },
    {
      "x": -29,
      "y": 10,
      "z": 35,
      "name": "Soil_Seaweed_Block"
    },
    {
      "x": -29,
      "y": 11,
      "z": 35,
      "name": "Soil_Clay_Lime"
    },
    {
      "x": -29,
      "y": 12,
      "z": 35,
      "name": "Plant_Grass_Sharp"
    },
    {
      "x": -29,
      "y": 9,
      "z": 36,
      "name": "Soil_Clay_Green"
    },
    {
      "x": -29,
      "y": 10,
      "z": 36,
      "name": "Soil_Seaweed_Block"
    },
    {
      "x": -29,
      "y": 11,
      "z": 36,
      "name": "Soil_Seaweed_Block"
    },
    {
      "x": -29,
      "y": 12,
      "z": 36,
      "name": "Soil_Clay_Lime"
    },
    {
      "x": -29,
      "y": 13,
      "z": 36,
      "name": "Plant_Grass_Sharp"
    },
    {
      "x": -29,
      "y": 10,
      "z": 37,
      "name": "Soil_Clay_Green"
    },
    {
      "x": -29,
      "y": 11,
      "z": 37,
      "name": "Soil_Seaweed_Block"
    },
    {
      "x": -28,
      "y": 22,
      "z": -47,
      "name": "Soil_Clay_Green"
    },
    {
      "x": -28,
      "y": 23,
      "z": -47,
      "name": "Soil_Seaweed_Block"
    },
    {
      "x": -28,
      "y": 22,
      "z": -46,
      "name": "Soil_Clay_Green"
    },
    {
      "x": -28,
      "y": 23,
      "z": -46,
      "name": "Soil_Clay_Lime"
    },
    {
      "x": -28,
      "y": 24,
      "z": -46,
      "name": "Plant_Grass_Sharp"
    },
    {
      "x": -28,
      "y": 22,
      "z": -45,
      "name": "Soil_Clay_Green"
    },
    {
      "x": -28,
      "y": 23,
      "z": -45,
      "name": "Soil_Clay_Lime"
    },
    {
      "x": -28,
      "y": 24,
      "z": -45,
      "name": "Plant_Grass_Sharp"
    },
    {
      "x": -28,
      "y": 22,
      "z": -44,
      "name": "Soil_Clay_Green"
    },
    {
      "x": -28,
      "y": 23,
      "z": -44,
      "name": "Soil_Clay_Lime"
    },
    {
      "x": -28,
      "y": 24,
      "z": -44,
      "name": "Plant_Grass_Sharp"
    },
    {
      "x": -28,
      "y": 28,
      "z": -44,
      "name": "Soil_Clay_Green"
    },
    {
      "x": -28,
      "y": 28,
      "z": -43,
      "name": "Soil_Seaweed_Block"
    },
    {
      "x": -28,
      "y": 27,
      "z": -42,
      "name": "Soil_Clay_Green"
    },
    {
      "x": -28,
      "y": 28,
      "z": -42,
      "name": "Soil_Seaweed_Block"
    },
    {
      "x": -28,
      "y": 27,
      "z": -41,
      "name": "Soil_Clay_Green"
    },
    {
      "x": -28,
      "y": 23,
      "z": -36,
      "name": "Soil_Seaweed_Block"
    },
    {
      "x": -28,
      "y": 22,
      "z": -35,
      "name": "Soil_Clay_Green"
    },
    {
      "x": -28,
      "y": 9,
      "z": 34,
      "name": "Soil_Clay_Green"
    },
    {
      "x": -28,
      "y": 10,
      "z": 34,
      "name": "Soil_Clay_Green"
    },
    {
      "x": -28,
      "y": 11,
      "z": 34,
      "name": "Soil_Seaweed_Block"
    },
    {
      "x": -28,
      "y": 12,
      "z": 34,
      "name": "Soil_Seaweed_Block"
    },
    {
      "x": -28,
      "y": 9,
      "z": 35,
      "name": "Soil_Clay_Green"
    },
    {
      "x": -28,
      "y": 10,
      "z": 35,
      "name": "Soil_Seaweed_Block"
    },
    {
      "x": -28,
      "y": 11,
      "z": 35,
      "name": "Soil_Seaweed_Block"
    },
    {
      "x": -28,
      "y": 12,
      "z": 35,
      "name": "Soil_Clay_Lime"
    },
    {
      "x": -28,
      "y": 13,
      "z": 35,
      "name": "Plant_Grass_Sharp"
    },
    {
      "x": -28,
      "y": 9,
      "z": 36,
      "name": "Soil_Clay_Green"
    },
    {
      "x": -28,
      "y": 10,
      "z": 36,
      "name": "Soil_Clay_Green"
    },
    {
      "x": -28,
      "y": 11,
      "z": 36,
      "name": "Soil_Seaweed_Block"
    },
    {
      "x": -28,
      "y": 12,
      "z": 36,
      "name": "Soil_Clay_Lime"
    },
    {
      "x": -28,
      "y": 13,
      "z": 36,
      "name": "Plant_Grass_Sharp"
    },
    {
      "x": -28,
      "y": 11,
      "z": 37,
      "name": "Soil_Seaweed_Block"
    },
    {
      "x": -28,
      "y": 12,
      "z": 37,
      "name": "Soil_Seaweed_Block"
    },
    {
      "x": -27,
      "y": 22,
      "z": -46,
      "name": "Soil_Clay_Green"
    },
    {
      "x": -27,
      "y": 22,
      "z": -45,
      "name": "Soil_Clay_Green"
    },
    {
      "x": -27,
      "y": 23,
      "z": -45,
      "name": "Soil_Clay_Lime"
    },
    {
      "x": -27,
      "y": 24,
      "z": -45,
      "name": "Plant_Grass_Sharp"
    },
    {
      "x": -27,
      "y": 22,
      "z": -44,
      "name": "Soil_Clay_Green"
    },
    {
      "x": -27,
      "y": 23,
      "z": -44,
      "name": "Soil_Clay_Lime"
    },
    {
      "x": -27,
      "y": 24,
      "z": -44,
      "name": "Plant_Grass_Sharp"
    },
    {
      "x": -27,
      "y": 22,
      "z": -43,
      "name": "Soil_Clay_Green"
    },
    {
      "x": -27,
      "y": 23,
      "z": -43,
      "name": "Soil_Seaweed_Block"
    },
    {
      "x": -27,
      "y": 28,
      "z": -42,
      "name": "Soil_Seaweed_Block"
    },
    {
      "x": -27,
      "y": 27,
      "z": -41,
      "name": "Soil_Clay_Green"
    },
    {
      "x": -27,
      "y": 28,
      "z": -41,
      "name": "Soil_Clay_Lime"
    },
    {
      "x": -27,
      "y": 29,
      "z": -41,
      "name": "Plant_Grass_Sharp"
    },
    {
      "x": -27,
      "y": 27,
      "z": -40,
      "name": "Soil_Clay_Green"
    },
    {
      "x": -27,
      "y": 22,
      "z": -35,
      "name": "Soil_Clay_Green"
    },
    {
      "x": -27,
      "y": 23,
      "z": -35,
      "name": "Soil_Clay_Lime"
    },
    {
      "x": -27,
      "y": 24,
      "z": -35,
      "name": "Plant_Grass_Sharp"
    },
    {
      "x": -27,
      "y": 22,
      "z": -34,
      "name": "Soil_Clay_Green"
    },
    {
      "x": -27,
      "y": 23,
      "z": -34,
      "name": "Soil_Seaweed_Block"
    },
    {
      "x": -27,
      "y": 9,
      "z": 34,
      "name": "Soil_Clay_Green"
    },
    {
      "x": -27,
      "y": 10,
      "z": 34,
      "name": "Soil_Clay_Green"
    },
    {
      "x": -27,
      "y": 11,
      "z": 34,
      "name": "Soil_Clay_Green"
    },
    {
      "x": -27,
      "y": 12,
      "z": 34,
      "name": "Soil_Seaweed_Block"
    },
    {
      "x": -27,
      "y": 13,
      "z": 34,
      "name": "Soil_Clay_Lime"
    },
    {
      "x": -27,
      "y": 14,
      "z": 34,
      "name": "Plant_Grass_Sharp"
    },
    {
      "x": -27,
      "y": 9,
      "z": 35,
      "name": "Soil_Clay_Green"
    },
    {
      "x": -27,
      "y": 10,
      "z": 35,
      "name": "Soil_Seaweed_Block"
    },
    {
      "x": -27,
      "y": 11,
      "z": 35,
      "name": "Soil_Seaweed_Block"
    },
    {
      "x": -27,
      "y": 12,
      "z": 35,
      "name": "Soil_Seaweed_Block"
    },
    {
      "x": -27,
      "y": 13,
      "z": 35,
      "name": "Soil_Clay_Lime"
    },
    {
      "x": -27,
      "y": 14,
      "z": 35,
      "name": "Plant_Grass_Sharp"
    },
    {
      "x": -27,
      "y": 9,
      "z": 36,
      "name": "Soil_Clay_Green"
    },
    {
      "x": -27,
      "y": 10,
      "z": 36,
      "name": "Soil_Clay_Green"
    },
    {
      "x": -27,
      "y": 11,
      "z": 36,
      "name": "Soil_Clay_Green"
    },
    {
      "x": -27,
      "y": 12,
      "z": 36,
      "name": "Soil_Seaweed_Block"
    },
    {
      "x": -27,
      "y": 13,
      "z": 36,
      "name": "Soil_Clay_Lime"
    },
    {
      "x": -27,
      "y": 14,
      "z": 36,
      "name": "Plant_Grass_Sharp"
    },
    {
      "x": -26,
      "y": 22,
      "z": -44,
      "name": "Soil_Clay_Green"
    },
    {
      "x": -26,
      "y": 23,
      "z": -44,
      "name": "Soil_Clay_Lime"
    },
    {
      "x": -26,
      "y": 24,
      "z": -44,
      "name": "Plant_Grass_Sharp"
    },
    {
      "x": -26,
      "y": 22,
      "z": -43,
      "name": "Soil_Clay_Green"
    },
    {
      "x": -26,
      "y": 23,
      "z": -43,
      "name": "Soil_Clay_Lime"
    },
    {
      "x": -26,
      "y": 24,
      "z": -43,
      "name": "Soil_Clay_Lime"
    },
    {
      "x": -26,
      "y": 25,
      "z": -43,
      "name": "Plant_Grass_Sharp"
    },
    {
      "x": -26,
      "y": 27,
      "z": -41,
      "name": "Soil_Clay_Green"
    },
    {
      "x": -26,
      "y": 27,
      "z": -40,
      "name": "Soil_Clay_Green"
    },
    {
      "x": -26,
      "y": 28,
      "z": -40,
      "name": "Soil_Clay_Lime"
    },
    {
      "x": -26,
      "y": 29,
      "z": -40,
      "name": "Plant_Grass_Sharp"
    },
    {
      "x": -26,
      "y": 22,
      "z": -35,
      "name": "Soil_Clay_Green"
    },
    {
      "x": -26,
      "y": 23,
      "z": -35,
      "name": "Soil_Clay_Lime"
    },
    {
      "x": -26,
      "y": 24,
      "z": -35,
      "name": "Plant_Grass_Sharp"
    },
    {
      "x": -26,
      "y": 22,
      "z": -34,
      "name": "Soil_Clay_Green"
    },
    {
      "x": -26,
      "y": 11,
      "z": 33,
      "name": "Soil_Clay_Green"
    },
    {
      "x": -26,
      "y": 12,
      "z": 33,
      "name": "Soil_Seaweed_Block"
    },
    {
      "x": -26,
      "y": 10,
      "z": 34,
      "name": "Soil_Clay_Green"
    },
    {
      "x": -26,
      "y": 11,
      "z": 34,
      "name": "Soil_Seaweed_Block"
    },
    {
      "x": -26,
      "y": 12,
      "z": 34,
      "name": "Soil_Seaweed_Block"
    },
    {
      "x": -26,
      "y": 13,
      "z": 34,
      "name": "Soil_Clay_Lime"
    },
    {
      "x": -26,
      "y": 14,
      "z": 34,
      "name": "Plant_Grass_Sharp"
    },
    {
      "x": -26,
      "y": 10,
      "z": 35,
      "name": "Soil_Clay_Green"
    },
    {
      "x": -26,
      "y": 11,
      "z": 35,
      "name": "Soil_Seaweed_Block"
    },
    {
      "x": -26,
      "y": 12,
      "z": 35,
      "name": "Soil_Seaweed_Block"
    },
    {
      "x": -26,
      "y": 13,
      "z": 35,
      "name": "Soil_Clay_Lime"
    },
    {
      "x": -26,
      "y": 14,
      "z": 35,
      "name": "Plant_Grass_Sharp"
    },
    {
      "x": -26,
      "y": 11,
      "z": 36,
      "name": "Soil_Clay_Green"
    },
    {
      "x": -26,
      "y": 12,
      "z": 36,
      "name": "Soil_Seaweed_Block"
    },
    {
      "x": -26,
      "y": 13,
      "z": 36,
      "name": "Soil_Clay_Lime"
    },
    {
      "x": -26,
      "y": 14,
      "z": 36,
      "name": "Plant_Grass_Sharp"
    },
    {
      "x": -25,
      "y": 12,
      "z": -45,
      "name": "Soil_Clay_Green"
    },
    {
      "x": -25,
      "y": 13,
      "z": -45,
      "name": "Soil_Seaweed_Block"
    },
    {
      "x": -25,
      "y": 12,
      "z": -44,
      "name": "Soil_Clay_Green"
    },
    {
      "x": -25,
      "y": 13,
      "z": -44,
      "name": "Soil_Seaweed_Block"
    },
    {
      "x": -25,
      "y": 12,
      "z": -43,
      "name": "Soil_Clay_Green"
    },
    {
      "x": -25,
      "y": 13,
      "z": -43,
      "name": "Soil_Seaweed_Block"
    },
    {
      "x": -25,
      "y": 22,
      "z": -43,
      "name": "Soil_Clay_Green"
    },
    {
      "x": -25,
      "y": 23,
      "z": -43,
      "name": "Soil_Seaweed_Block"
    },
    {
      "x": -25,
      "y": 22,
      "z": -42,
      "name": "Soil_Clay_Green"
    },
    {
      "x": -25,
      "y": 23,
      "z": -42,
      "name": "Soil_Clay_Green"
    },
    {
      "x": -25,
      "y": 27,
      "z": -40,
      "name": "Soil_Clay_Lime"
    },
    {
      "x": -25,
      "y": 28,
      "z": -40,
      "name": "Soil_Clay_Lime"
    },
    {
      "x": -25,
      "y": 29,
      "z": -40,
      "name": "Plant_Grass_Sharp"
    },
    {
      "x": -25,
      "y": 22,
      "z": -36,
      "name": "Soil_Clay_Green"
    },
    {
      "x": -25,
      "y": 23,
      "z": -36,
      "name": "Soil_Seaweed_Block"
    },
    {
      "x": -25,
      "y": 22,
      "z": -35,
      "name": "Soil_Clay_Green"
    },
    {
      "x": -25,
      "y": 23,
      "z": -35,
      "name": "Soil_Clay_Lime"
    },
    {
      "x": -25,
      "y": 24,
      "z": -35,
      "name": "Plant_Grass_Sharp"
    },
    {
      "x": -25,
      "y": 17,
      "z": -30,
      "name": "Soil_Seaweed_Block"
    },
    {
      "x": -25,
      "y": 11,
      "z": 33,
      "name": "Soil_Clay_Green"
    },
    {
      "x": -25,
      "y": 12,
      "z": 33,
      "name": "Soil_Clay_Green"
    },
    {
      "x": -25,
      "y": 13,
      "z": 33,
      "name": "Soil_Seaweed_Block"
    },
    {
      "x": -25,
      "y": 14,
      "z": 33,
      "name": "Soil_Clay_Lime"
    },
    {
      "x": -25,
      "y": 15,
      "z": 33,
      "name": "Plant_Grass_Sharp"
    },
    {
      "x": -25,
      "y": 11,
      "z": 34,
      "name": "Soil_Clay_Green"
    },
    {
      "x": -25,
      "y": 12,
      "z": 34,
      "name": "Soil_Seaweed_Block"
    },
    {
      "x": -25,
      "y": 13,
      "z": 34,
      "name": "Soil_Clay_Lime"
    },
    {
      "x": -25,
      "y": 14,
      "z": 34,
      "name": "Plant_Grass_Sharp"
    },
    {
      "x": -25,
      "y": 11,
      "z": 35,
      "name": "Soil_Clay_Green"
    },
    {
      "x": -25,
      "y": 12,
      "z": 35,
      "name": "Soil_Seaweed_Block"
    },
    {
      "x": -25,
      "y": 13,
      "z": 35,
      "name": "Soil_Seaweed_Block"
    },
    {
      "x": -25,
      "y": 14,
      "z": 35,
      "name": "Soil_Clay_Lime"
    },
    {
      "x": -25,
      "y": 15,
      "z": 35,
      "name": "Plant_Grass_Sharp"
    },
    {
      "x": -25,
      "y": 11,
      "z": 36,
      "name": "Soil_Clay_Green"
    },
    {
      "x": -25,
      "y": 12,
      "z": 36,
      "name": "Soil_Clay_Green"
    },
    {
      "x": -25,
      "y": 13,
      "z": 36,
      "name": "Soil_Seaweed_Block"
    },
    {
      "x": -25,
      "y": 37,
      "z": 41,
      "name": "Soil_Clay_Green"
    },
    {
      "x": -25,
      "y": 38,
      "z": 41,
      "name": "Soil_Seaweed_Block"
    },
    {
      "x": -24,
      "y": 12,
      "z": -45,
      "name": "Soil_Clay_Green"
    },
    {
      "x": -24,
      "y": 13,
      "z": -45,
      "name": "Soil_Seaweed_Block"
    },
    {
      "x": -24,
      "y": 12,
      "z": -44,
      "name": "Soil_Clay_Green"
    },
    {
      "x": -24,
      "y": 13,
      "z": -44,
      "name": "Soil_Seaweed_Block"
    },
    {
      "x": -24,
      "y": 12,
      "z": -43,
      "name": "Soil_Clay_Green"
    },
    {
      "x": -24,
      "y": 13,
      "z": -43,
      "name": "Soil_Seaweed_Block"
    },
    {
      "x": -24,
      "y": 22,
      "z": -43,
      "name": "Soil_Clay_Green"
    },
    {
      "x": -24,
      "y": 23,
      "z": -43,
      "name": "Soil_Seaweed_Block"
    },
    {
      "x": -24,
      "y": 12,
      "z": -42,
      "name": "Soil_Clay_Green"
    },
    {
      "x": -24,
      "y": 13,
      "z": -42,
      "name": "Soil_Seaweed_Block"
    },
    {
      "x": -24,
      "y": 22,
      "z": -42,
      "name": "Soil_Clay_Green"
    },
    {
      "x": -24,
      "y": 23,
      "z": -42,
      "name": "Soil_Seaweed_Block"
    },
    {
      "x": -24,
      "y": 24,
      "z": -42,
      "name": "Soil_Clay_Lime"
    },
    {
      "x": -24,
      "y": 25,
      "z": -42,
      "name": "Plant_Grass_Sharp"
    },
    {
      "x": -24,
      "y": 23,
      "z": -41,
      "name": "Soil_Clay_Green"
    },
    {
      "x": -24,
      "y": 24,
      "z": -41,
      "name": "Soil_Seaweed_Block"
    },
    {
      "x": -24,
      "y": 23,
      "z": -40,
      "name": "Soil_Clay_Green"
    },
    {
      "x": -24,
      "y": 24,
      "z": -40,
      "name": "Soil_Seaweed_Block"
    },
    {
      "x": -24,
      "y": 25,
      "z": -40,
      "name": "Soil_Seaweed_Block"
    },
    {
      "x": -24,
      "y": 26,
      "z": -40,
      "name": "Soil_Clay_Lime"
    },
    {
      "x": -24,
      "y": 27,
      "z": -40,
      "name": "Soil_Clay_Lime"
    },
    {
      "x": -24,
      "y": 28,
      "z": -40,
      "name": "Plant_Grass_Sharp"
    },
    {
      "x": -24,
      "y": 24,
      "z": -39,
      "name": "Soil_Clay_Green"
    },
    {
      "x": -24,
      "y": 26,
      "z": -39,
      "name": "Soil_Seaweed_Block"
    },
    {
      "x": -24,
      "y": 26,
      "z": -38,
      "name": "Soil_Seaweed_Block"
    },
    {
      "x": -24,
      "y": 22,
      "z": -36,
      "name": "Soil_Clay_Green"
    },
    {
      "x": -24,
      "y": 23,
      "z": -36,
      "name": "Soil_Seaweed_Block"
    },
    {
      "x": -24,
      "y": 22,
      "z": -35,
      "name": "Soil_Clay_Green"
    },
    {
      "x": -24,
      "y": 23,
      "z": -35,
      "name": "Soil_Clay_Lime"
    },
    {
      "x": -24,
      "y": 24,
      "z": -35,
      "name": "Plant_Grass_Sharp"
    },
    {
      "x": -24,
      "y": 22,
      "z": -34,
      "name": "Soil_Clay_Green"
    },
    {
      "x": -24,
      "y": 23,
      "z": -34,
      "name": "Soil_Seaweed_Block"
    },
    {
      "x": -24,
      "y": 16,
      "z": -33,
      "name": "Soil_Seaweed_Block"
    },
    {
      "x": -24,
      "y": 17,
      "z": -33,
      "name": "Soil_Seaweed_Block"
    },
    {
      "x": -24,
      "y": 16,
      "z": -32,
      "name": "Soil_Clay_Green"
    },
    {
      "x": -24,
      "y": 17,
      "z": -32,
      "name": "Soil_Seaweed_Block"
    },
    {
      "x": -24,
      "y": 12,
      "z": -31,
      "name": "Soil_Clay_Green"
    },
    {
      "x": -24,
      "y": 13,
      "z": -31,
      "name": "Soil_Clay_Green"
    },
    {
      "x": -24,
      "y": 14,
      "z": -31,
      "name": "Soil_Clay_Green"
    },
    {
      "x": -24,
      "y": 9,
      "z": -30,
      "name": "Soil_Clay_Green"
    },
    {
      "x": -24,
      "y": 10,
      "z": -30,
      "name": "Soil_Clay_Green"
    },
    {
      "x": -24,
      "y": 12,
      "z": -30,
      "name": "Soil_Clay_Green"
    },
    {
      "x": -24,
      "y": 16,
      "z": -30,
      "name": "Soil_Clay_Green"
    },
    {
      "x": -24,
      "y": 17,
      "z": -30,
      "name": "Soil_Seaweed_Block"
    },
    {
      "x": -24,
      "y": 18,
      "z": -30,
      "name": "Soil_Seaweed_Block"
    },
    {
      "x": -24,
      "y": 9,
      "z": -29,
      "name": "Soil_Clay_Green"
    },
    {
      "x": -24,
      "y": 10,
      "z": -29,
      "name": "Soil_Clay_Green"
    },
    {
      "x": -24,
      "y": 12,
      "z": -29,
      "name": "Soil_Seaweed_Block"
    },
    {
      "x": -24,
      "y": 16,
      "z": -29,
      "name": "Soil_Seaweed_Block"
    },
    {
      "x": -24,
      "y": 17,
      "z": -29,
      "name": "Soil_Seaweed_Block"
    },
    {
      "x": -24,
      "y": 12,
      "z": -28,
      "name": "Soil_Seaweed_Block"
    },
    {
      "x": -24,
      "y": 12,
      "z": -27,
      "name": "Soil_Clay_Green"
    },
    {
      "x": -24,
      "y": 12,
      "z": -26,
      "name": "Soil_Clay_Green"
    },
    {
      "x": -24,
      "y": 12,
      "z": -25,
      "name": "Soil_Clay_Green"
    },
    {
      "x": -24,
      "y": 13,
      "z": -25,
      "name": "Soil_Seaweed_Block"
    },
    {
      "x": -24,
      "y": 14,
      "z": -25,
      "name": "Soil_Seaweed_Block"
    },
    {
      "x": -24,
      "y": 12,
      "z": -24,
      "name": "Soil_Clay_Green"
    },
    {
      "x": -24,
      "y": 13,
      "z": -24,
      "name": "Soil_Seaweed_Block"
    },
    {
      "x": -24,
      "y": 14,
      "z": -24,
      "name": "Soil_Seaweed_Block"
    },
    {
      "x": -24,
      "y": 12,
      "z": -23,
      "name": "Soil_Clay_Green"
    },
    {
      "x": -24,
      "y": 13,
      "z": -23,
      "name": "Soil_Seaweed_Block"
    },
    {
      "x": -24,
      "y": 14,
      "z": -23,
      "name": "Soil_Seaweed_Block"
    },
    {
      "x": -24,
      "y": 12,
      "z": -22,
      "name": "Soil_Clay_Green"
    },
    {
      "x": -24,
      "y": 12,
      "z": 32,
      "name": "Soil_Clay_Green"
    },
    {
      "x": -24,
      "y": 11,
      "z": 33,
      "name": "Soil_Clay_Green"
    },
    {
      "x": -24,
      "y": 12,
      "z": 33,
      "name": "Soil_Seaweed_Block"
    },
    {
      "x": -24,
      "y": 13,
      "z": 33,
      "name": "Soil_Seaweed_Block"
    },
    {
      "x": -24,
      "y": 14,
      "z": 33,
      "name": "Soil_Clay_Lime"
    },
    {
      "x": -24,
      "y": 15,
      "z": 33,
      "name": "Soil_Clay_Lime"
    },
    {
      "x": -24,
      "y": 16,
      "z": 33,
      "name": "Plant_Grass_Sharp"
    },
    {
      "x": -24,
      "y": 11,
      "z": 34,
      "name": "Soil_Clay_Green"
    },
    {
      "x": -24,
      "y": 12,
      "z": 34,
      "name": "Soil_Seaweed_Block"
    },
    {
      "x": -24,
      "y": 13,
      "z": 34,
      "name": "Soil_Seaweed_Block"
    },
    {
      "x": -24,
      "y": 14,
      "z": 34,
      "name": "Soil_Clay_Lime"
    },
    {
      "x": -24,
      "y": 15,
      "z": 34,
      "name": "Plant_Grass_Sharp"
    },
    {
      "x": -24,
      "y": 11,
      "z": 35,
      "name": "Soil_Clay_Green"
    },
    {
      "x": -24,
      "y": 12,
      "z": 35,
      "name": "Soil_Seaweed_Block"
    },
    {
      "x": -24,
      "y": 13,
      "z": 35,
      "name": "Soil_Seaweed_Block"
    },
    {
      "x": -24,
      "y": 14,
      "z": 35,
      "name": "Soil_Clay_Lime"
    },
    {
      "x": -24,
      "y": 15,
      "z": 35,
      "name": "Plant_Grass_Sharp"
    },
    {
      "x": -24,
      "y": 12,
      "z": 36,
      "name": "Soil_Clay_Green"
    },
    {
      "x": -24,
      "y": 13,
      "z": 36,
      "name": "Soil_Seaweed_Block"
    },
    {
      "x": -24,
      "y": 14,
      "z": 36,
      "name": "Soil_Clay_Lime"
    },
    {
      "x": -24,
      "y": 15,
      "z": 36,
      "name": "Plant_Grass_Sharp"
    },
    {
      "x": -24,
      "y": 37,
      "z": 42,
      "name": "Soil_Clay_Green"
    },
    {
      "x": -24,
      "y": 38,
      "z": 42,
      "name": "Soil_Seaweed_Block"
    },
    {
      "x": -23,
      "y": 13,
      "z": -43,
      "name": "Soil_Seaweed_Block"
    },
    {
      "x": -23,
      "y": 12,
      "z": -42,
      "name": "Soil_Clay_Green"
    },
    {
      "x": -23,
      "y": 13,
      "z": -42,
      "name": "Soil_Seaweed_Block"
    },
    {
      "x": -23,
      "y": 22,
      "z": -42,
      "name": "Soil_Clay_Green"
    },
    {
      "x": -23,
      "y": 23,
      "z": -42,
      "name": "Soil_Clay_Green"
    },
    {
      "x": -23,
      "y": 24,
      "z": -42,
      "name": "Soil_Seaweed_Block"
    },
    {
      "x": -23,
      "y": 13,
      "z": -41,
      "name": "Soil_Clay_Green"
    },
    {
      "x": -23,
      "y": 14,
      "z": -41,
      "name": "Soil_Clay_Lime"
    },
    {
      "x": -23,
      "y": 15,
      "z": -41,
      "name": "Plant_Grass_Sharp"
    },
    {
      "x": -23,
      "y": 22,
      "z": -41,
      "name": "Soil_Clay_Green"
    },
    {
      "x": -23,
      "y": 23,
      "z": -41,
      "name": "Soil_Seaweed_Block"
    },
    {
      "x": -23,
      "y": 24,
      "z": -41,
      "name": "Soil_Seaweed_Block"
    },
    {
      "x": -23,
      "y": 25,
      "z": -41,
      "name": "Soil_Clay_Lime"
    },
    {
      "x": -23,
      "y": 26,
      "z": -41,
      "name": "Plant_Grass_Sharp"
    },
    {
      "x": -23,
      "y": 23,
      "z": -40,
      "name": "Soil_Clay_Green"
    },
    {
      "x": -23,
      "y": 24,
      "z": -40,
      "name": "Soil_Seaweed_Block"
    },
    {
      "x": -23,
      "y": 25,
      "z": -40,
      "name": "Soil_Seaweed_Block"
    },
    {
      "x": -23,
      "y": 26,
      "z": -40,
      "name": "Soil_Clay_Lime"
    },
    {
      "x": -23,
      "y": 27,
      "z": -40,
      "name": "Plant_Grass_Sharp"
    },
    {
      "x": -23,
      "y": 14,
      "z": -39,
      "name": "Soil_Seaweed_Block"
    },
    {
      "x": -23,
      "y": 24,
      "z": -39,
      "name": "Soil_Clay_Green"
    },
    {
      "x": -23,
      "y": 25,
      "z": -39,
      "name": "Soil_Seaweed_Block"
    },
    {
      "x": -23,
      "y": 26,
      "z": -39,
      "name": "Soil_Clay_Lime"
    },
    {
      "x": -23,
      "y": 27,
      "z": -39,
      "name": "Plant_Grass_Sharp"
    },
    {
      "x": -23,
      "y": 14,
      "z": -38,
      "name": "Soil_Seaweed_Block"
    },
    {
      "x": -23,
      "y": 13,
      "z": -37,
      "name": "Soil_Clay_Green"
    },
    {
      "x": -23,
      "y": 14,
      "z": -37,
      "name": "Soil_Seaweed_Block"
    },
    {
      "x": -23,
      "y": 13,
      "z": -36,
      "name": "Soil_Clay_Green"
    },
    {
      "x": -23,
      "y": 14,
      "z": -36,
      "name": "Soil_Clay_Green"
    },
    {
      "x": -23,
      "y": 22,
      "z": -36,
      "name": "Soil_Clay_Green"
    },
    {
      "x": -23,
      "y": 23,
      "z": -36,
      "name": "Soil_Seaweed_Block"
    },
    {
      "x": -23,
      "y": 21,
      "z": -35,
      "name": "Soil_Clay_Green"
    },
    {
      "x": -23,
      "y": 22,
      "z": -35,
      "name": "Soil_Clay_Green"
    },
    {
      "x": -23,
      "y": 23,
      "z": -35,
      "name": "Soil_Seaweed_Block"
    },
    {
      "x": -23,
      "y": 16,
      "z": -34,
      "name": "Soil_Seaweed_Block"
    },
    {
      "x": -23,
      "y": 14,
      "z": -33,
      "name": "Soil_Clay_Green"
    },
    {
      "x": -23,
      "y": 15,
      "z": -33,
      "name": "Soil_Clay_Green"
    },
    {
      "x": -23,
      "y": 16,
      "z": -33,
      "name": "Soil_Seaweed_Block"
    },
    {
      "x": -23,
      "y": 17,
      "z": -33,
      "name": "Soil_Seaweed_Block"
    },
    {
      "x": -23,
      "y": 18,
      "z": -33,
      "name": "Soil_Seaweed_Block"
    },
    {
      "x": -23,
      "y": 19,
      "z": -33,
      "name": "Soil_Seaweed_Block"
    },
    {
      "x": -23,
      "y": 11,
      "z": -32,
      "name": "Soil_Clay_Green"
    },
    {
      "x": -23,
      "y": 12,
      "z": -32,
      "name": "Soil_Clay_Green"
    },
    {
      "x": -23,
      "y": 14,
      "z": -32,
      "name": "Soil_Clay_Green"
    },
    {
      "x": -23,
      "y": 15,
      "z": -32,
      "name": "Soil_Clay_Green"
    },
    {
      "x": -23,
      "y": 16,
      "z": -32,
      "name": "Soil_Seaweed_Block"
    },
    {
      "x": -23,
      "y": 17,
      "z": -32,
      "name": "Soil_Seaweed_Block"
    },
    {
      "x": -23,
      "y": 18,
      "z": -32,
      "name": "Soil_Seaweed_Block"
    },
    {
      "x": -23,
      "y": 19,
      "z": -32,
      "name": "Soil_Seaweed_Block"
    },
    {
      "x": -23,
      "y": 10,
      "z": -31,
      "name": "Soil_Clay_Green"
    },
    {
      "x": -23,
      "y": 11,
      "z": -31,
      "name": "Soil_Clay_Green"
    },
    {
      "x": -23,
      "y": 12,
      "z": -31,
      "name": "Soil_Seaweed_Block"
    },
    {
      "x": -23,
      "y": 13,
      "z": -31,
      "name": "Soil_Clay_Green"
    },
    {
      "x": -23,
      "y": 14,
      "z": -31,
      "name": "Soil_Seaweed_Block"
    },
    {
      "x": -23,
      "y": 15,
      "z": -31,
      "name": "Soil_Clay_Green"
    },
    {
      "x": -23,
      "y": 16,
      "z": -31,
      "name": "Soil_Clay_Green"
    },
    {
      "x": -23,
      "y": 17,
      "z": -31,
      "name": "Soil_Seaweed_Block"
    },
    {
      "x": -23,
      "y": 18,
      "z": -31,
      "name": "Soil_Seaweed_Block"
    },
    {
      "x": -23,
      "y": 19,
      "z": -31,
      "name": "Soil_Seaweed_Block"
    },
    {
      "x": -23,
      "y": 9,
      "z": -30,
      "name": "Soil_Clay_Green"
    },
    {
      "x": -23,
      "y": 10,
      "z": -30,
      "name": "Soil_Seaweed_Block"
    },
    {
      "x": -23,
      "y": 11,
      "z": -30,
      "name": "Soil_Clay_Green"
    },
    {
      "x": -23,
      "y": 12,
      "z": -30,
      "name": "Soil_Seaweed_Block"
    },
    {
      "x": -23,
      "y": 13,
      "z": -30,
      "name": "Soil_Seaweed_Block"
    },
    {
      "x": -23,
      "y": 14,
      "z": -30,
      "name": "Soil_Seaweed_Block"
    },
    {
      "x": -23,
      "y": 15,
      "z": -30,
      "name": "Soil_Clay_Green"
    },
    {
      "x": -23,
      "y": 16,
      "z": -30,
      "name": "Soil_Seaweed_Block"
    },
    {
      "x": -23,
      "y": 17,
      "z": -30,
      "name": "Soil_Seaweed_Block"
    },
    {
      "x": -23,
      "y": 18,
      "z": -30,
      "name": "Soil_Seaweed_Block"
    },
    {
      "x": -23,
      "y": 19,
      "z": -30,
      "name": "Soil_Seaweed_Block"
    },
    {
      "x": -23,
      "y": 9,
      "z": -29,
      "name": "Soil_Clay_Green"
    },
    {
      "x": -23,
      "y": 10,
      "z": -29,
      "name": "Soil_Seaweed_Block"
    },
    {
      "x": -23,
      "y": 11,
      "z": -29,
      "name": "Soil_Clay_Green"
    },
    {
      "x": -23,
      "y": 12,
      "z": -29,
      "name": "Soil_Seaweed_Block"
    },
    {
      "x": -23,
      "y": 13,
      "z": -29,
      "name": "Soil_Seaweed_Block"
    },
    {
      "x": -23,
      "y": 14,
      "z": -29,
      "name": "Soil_Seaweed_Block"
    },
    {
      "x": -23,
      "y": 15,
      "z": -29,
      "name": "Soil_Clay_Green"
    },
    {
      "x": -23,
      "y": 16,
      "z": -29,
      "name": "Soil_Seaweed_Block"
    },
    {
      "x": -23,
      "y": 17,
      "z": -29,
      "name": "Soil_Seaweed_Block"
    },
    {
      "x": -23,
      "y": 18,
      "z": -29,
      "name": "Soil_Seaweed_Block"
    },
    {
      "x": -23,
      "y": 19,
      "z": -29,
      "name": "Soil_Seaweed_Block"
    },
    {
      "x": -23,
      "y": 10,
      "z": -28,
      "name": "Soil_Clay_Green"
    },
    {
      "x": -23,
      "y": 11,
      "z": -28,
      "name": "Soil_Clay_Green"
    },
    {
      "x": -23,
      "y": 12,
      "z": -28,
      "name": "Soil_Seaweed_Block"
    },
    {
      "x": -23,
      "y": 13,
      "z": -28,
      "name": "Soil_Seaweed_Block"
    },
    {
      "x": -23,
      "y": 14,
      "z": -28,
      "name": "Soil_Seaweed_Block"
    },
    {
      "x": -23,
      "y": 15,
      "z": -28,
      "name": "Soil_Clay_Green"
    },
    {
      "x": -23,
      "y": 16,
      "z": -28,
      "name": "Soil_Seaweed_Block"
    },
    {
      "x": -23,
      "y": 18,
      "z": -28,
      "name": "Soil_Seaweed_Block"
    },
    {
      "x": -23,
      "y": 19,
      "z": -28,
      "name": "Soil_Seaweed_Block"
    },
    {
      "x": -23,
      "y": 10,
      "z": -27,
      "name": "Soil_Clay_Green"
    },
    {
      "x": -23,
      "y": 11,
      "z": -27,
      "name": "Soil_Clay_Green"
    },
    {
      "x": -23,
      "y": 12,
      "z": -27,
      "name": "Soil_Seaweed_Block"
    },
    {
      "x": -23,
      "y": 13,
      "z": -27,
      "name": "Soil_Seaweed_Block"
    },
    {
      "x": -23,
      "y": 14,
      "z": -27,
      "name": "Soil_Seaweed_Block"
    },
    {
      "x": -23,
      "y": 15,
      "z": -27,
      "name": "Soil_Seaweed_Block"
    },
    {
      "x": -23,
      "y": 16,
      "z": -27,
      "name": "Soil_Seaweed_Block"
    },
    {
      "x": -23,
      "y": 8,
      "z": -26,
      "name": "Soil_Clay_Green"
    },
    {
      "x": -23,
      "y": 9,
      "z": -26,
      "name": "Soil_Clay_Green"
    },
    {
      "x": -23,
      "y": 10,
      "z": -26,
      "name": "Soil_Clay_Green"
    },
    {
      "x": -23,
      "y": 11,
      "z": -26,
      "name": "Soil_Clay_Green"
    },
    {
      "x": -23,
      "y": 12,
      "z": -26,
      "name": "Soil_Seaweed_Block"
    },
    {
      "x": -23,
      "y": 13,
      "z": -26,
      "name": "Soil_Seaweed_Block"
    },
    {
      "x": -23,
      "y": 14,
      "z": -26,
      "name": "Soil_Seaweed_Block"
    },
    {
      "x": -23,
      "y": 15,
      "z": -26,
      "name": "Soil_Seaweed_Block"
    },
    {
      "x": -23,
      "y": 16,
      "z": -26,
      "name": "Soil_Seaweed_Block"
    },
    {
      "x": -23,
      "y": 8,
      "z": -25,
      "name": "Soil_Clay_Green"
    },
    {
      "x": -23,
      "y": 9,
      "z": -25,
      "name": "Soil_Clay_Green"
    },
    {
      "x": -23,
      "y": 10,
      "z": -25,
      "name": "Soil_Clay_Green"
    },
    {
      "x": -23,
      "y": 11,
      "z": -25,
      "name": "Soil_Clay_Green"
    },
    {
      "x": -23,
      "y": 12,
      "z": -25,
      "name": "Soil_Seaweed_Block"
    },
    {
      "x": -23,
      "y": 13,
      "z": -25,
      "name": "Soil_Seaweed_Block"
    },
    {
      "x": -23,
      "y": 14,
      "z": -25,
      "name": "Soil_Seaweed_Block"
    },
    {
      "x": -23,
      "y": 15,
      "z": -25,
      "name": "Soil_Seaweed_Block"
    },
    {
      "x": -23,
      "y": 16,
      "z": -25,
      "name": "Soil_Seaweed_Block"
    },
    {
      "x": -23,
      "y": 10,
      "z": -24,
      "name": "Soil_Clay_Green"
    },
    {
      "x": -23,
      "y": 11,
      "z": -24,
      "name": "Soil_Clay_Green"
    },
    {
      "x": -23,
      "y": 12,
      "z": -24,
      "name": "Soil_Seaweed_Block"
    },
    {
      "x": -23,
      "y": 13,
      "z": -24,
      "name": "Soil_Seaweed_Block"
    },
    {
      "x": -23,
      "y": 14,
      "z": -24,
      "name": "Soil_Seaweed_Block"
    },
    {
      "x": -23,
      "y": 15,
      "z": -24,
      "name": "Soil_Seaweed_Block"
    },
    {
      "x": -23,
      "y": 16,
      "z": -24,
      "name": "Soil_Seaweed_Block"
    },
    {
      "x": -23,
      "y": 10,
      "z": -23,
      "name": "Soil_Clay_Green"
    },
    {
      "x": -23,
      "y": 11,
      "z": -23,
      "name": "Soil_Clay_Green"
    },
    {
      "x": -23,
      "y": 12,
      "z": -23,
      "name": "Soil_Seaweed_Block"
    },
    {
      "x": -23,
      "y": 13,
      "z": -23,
      "name": "Soil_Seaweed_Block"
    },
    {
      "x": -23,
      "y": 14,
      "z": -23,
      "name": "Soil_Seaweed_Block"
    },
    {
      "x": -23,
      "y": 15,
      "z": -23,
      "name": "Soil_Seaweed_Block"
    },
    {
      "x": -23,
      "y": 16,
      "z": -23,
      "name": "Soil_Seaweed_Block"
    },
    {
      "x": -23,
      "y": 10,
      "z": -22,
      "name": "Soil_Clay_Green"
    },
    {
      "x": -23,
      "y": 11,
      "z": -22,
      "name": "Soil_Clay_Green"
    },
    {
      "x": -23,
      "y": 12,
      "z": -22,
      "name": "Soil_Seaweed_Block"
    },
    {
      "x": -23,
      "y": 13,
      "z": -22,
      "name": "Soil_Seaweed_Block"
    },
    {
      "x": -23,
      "y": 14,
      "z": -22,
      "name": "Soil_Seaweed_Block"
    },
    {
      "x": -23,
      "y": 11,
      "z": -21,
      "name": "Soil_Clay_Green"
    },
    {
      "x": -23,
      "y": 12,
      "z": -21,
      "name": "Soil_Clay_Green"
    },
    {
      "x": -23,
      "y": 13,
      "z": -21,
      "name": "Soil_Seaweed_Block"
    },
    {
      "x": -23,
      "y": 14,
      "z": -21,
      "name": "Soil_Seaweed_Block"
    },
    {
      "x": -23,
      "y": 14,
      "z": -20,
      "name": "Soil_Seaweed_Block"
    },
    {
      "x": -23,
      "y": 14,
      "z": -19,
      "name": "Soil_Seaweed_Block"
    },
    {
      "x": -23,
      "y": 8,
      "z": 24,
      "name": "Soil_Clay_Green"
    },
    {
      "x": -23,
      "y": 9,
      "z": 24,
      "name": "Soil_Clay_Green"
    },
    {
      "x": -23,
      "y": 8,
      "z": 25,
      "name": "Soil_Clay_Green"
    },
    {
      "x": -23,
      "y": 9,
      "z": 25,
      "name": "Soil_Clay_Green"
    },
    {
      "x": -23,
      "y": 9,
      "z": 26,
      "name": "Soil_Clay_Green"
    },
    {
      "x": -23,
      "y": 10,
      "z": 26,
      "name": "Soil_Seaweed_Block"
    },
    {
      "x": -23,
      "y": 11,
      "z": 32,
      "name": "Soil_Clay_Green"
    },
    {
      "x": -23,
      "y": 12,
      "z": 32,
      "name": "Soil_Clay_Green"
    },
    {
      "x": -23,
      "y": 13,
      "z": 32,
      "name": "Soil_Seaweed_Block"
    },
    {
      "x": -23,
      "y": 11,
      "z": 33,
      "name": "Soil_Clay_Green"
    },
    {
      "x": -23,
      "y": 12,
      "z": 33,
      "name": "Soil_Seaweed_Block"
    },
    {
      "x": -23,
      "y": 13,
      "z": 33,
      "name": "Soil_Seaweed_Block"
    },
    {
      "x": -23,
      "y": 14,
      "z": 33,
      "name": "Soil_Clay_Lime"
    },
    {
      "x": -23,
      "y": 15,
      "z": 33,
      "name": "Soil_Clay_Lime"
    },
    {
      "x": -23,
      "y": 16,
      "z": 33,
      "name": "Plant_Grass_Sharp"
    },
    {
      "x": -23,
      "y": 11,
      "z": 34,
      "name": "Soil_Clay_Green"
    },
    {
      "x": -23,
      "y": 12,
      "z": 34,
      "name": "Soil_Seaweed_Block"
    },
    {
      "x": -23,
      "y": 13,
      "z": 34,
      "name": "Soil_Seaweed_Block"
    },
    {
      "x": -23,
      "y": 14,
      "z": 34,
      "name": "Soil_Seaweed_Block"
    },
    {
      "x": -23,
      "y": 15,
      "z": 34,
      "name": "Soil_Clay_Lime"
    },
    {
      "x": -23,
      "y": 16,
      "z": 34,
      "name": "Plant_Grass_Sharp"
    },
    {
      "x": -23,
      "y": 11,
      "z": 35,
      "name": "Soil_Clay_Green"
    },
    {
      "x": -23,
      "y": 12,
      "z": 35,
      "name": "Soil_Seaweed_Block"
    },
    {
      "x": -23,
      "y": 13,
      "z": 35,
      "name": "Soil_Seaweed_Block"
    },
    {
      "x": -23,
      "y": 14,
      "z": 35,
      "name": "Soil_Clay_Lime"
    },
    {
      "x": -23,
      "y": 15,
      "z": 35,
      "name": "Plant_Grass_Sharp"
    },
    {
      "x": -23,
      "y": 11,
      "z": 36,
      "name": "Soil_Clay_Green"
    },
    {
      "x": -23,
      "y": 12,
      "z": 36,
      "name": "Soil_Clay_Green"
    },
    {
      "x": -23,
      "y": 13,
      "z": 36,
      "name": "Soil_Seaweed_Block"
    },
    {
      "x": -23,
      "y": 14,
      "z": 36,
      "name": "Soil_Seaweed_Block"
    },
    {
      "x": -23,
      "y": 13,
      "z": 37,
      "name": "Soil_Seaweed_Block"
    },
    {
      "x": -23,
      "y": 38,
      "z": 42,
      "name": "Soil_Seaweed_Block"
    },
    {
      "x": -23,
      "y": 39,
      "z": 42,
      "name": "Soil_Clay_Lime"
    },
    {
      "x": -23,
      "y": 40,
      "z": 42,
      "name": "Plant_Grass_Sharp"
    },
    {
      "x": -22,
      "y": 12,
      "z": -42,
      "name": "Soil_Clay_Green"
    },
    {
      "x": -22,
      "y": 13,
      "z": -42,
      "name": "Soil_Clay_Green"
    },
    {
      "x": -22,
      "y": 14,
      "z": -42,
      "name": "Soil_Clay_Lime"
    },
    {
      "x": -22,
      "y": 15,
      "z": -42,
      "name": "Plant_Grass_Sharp"
    },
    {
      "x": -22,
      "y": 22,
      "z": -42,
      "name": "Soil_Clay_Green"
    },
    {
      "x": -22,
      "y": 23,
      "z": -42,
      "name": "Soil_Clay_Green"
    },
    {
      "x": -22,
      "y": 12,
      "z": -41,
      "name": "Soil_Clay_Green"
    },
    {
      "x": -22,
      "y": 13,
      "z": -41,
      "name": "Soil_Seaweed_Block"
    },
    {
      "x": -22,
      "y": 14,
      "z": -41,
      "name": "Soil_Clay_Lime"
    },
    {
      "x": -22,
      "y": 15,
      "z": -41,
      "name": "Plant_Grass_Sharp"
    },
    {
      "x": -22,
      "y": 22,
      "z": -41,
      "name": "Soil_Clay_Green"
    },
    {
      "x": -22,
      "y": 23,
      "z": -41,
      "name": "Soil_Seaweed_Block"
    },
    {
      "x": -22,
      "y": 24,
      "z": -41,
      "name": "Soil_Seaweed_Block"
    },
    {
      "x": -22,
      "y": 12,
      "z": -40,
      "name": "Soil_Clay_Green"
    },
    {
      "x": -22,
      "y": 13,
      "z": -40,
      "name": "Soil_Clay_Green"
    },
    {
      "x": -22,
      "y": 14,
      "z": -40,
      "name": "Soil_Clay_Lime"
    },
    {
      "x": -22,
      "y": 15,
      "z": -40,
      "name": "Plant_Grass_Sharp"
    },
    {
      "x": -22,
      "y": 23,
      "z": -40,
      "name": "Soil_Clay_Green"
    },
    {
      "x": -22,
      "y": 24,
      "z": -40,
      "name": "Soil_Seaweed_Block"
    },
    {
      "x": -22,
      "y": 25,
      "z": -40,
      "name": "Soil_Clay_Lime"
    },
    {
      "x": -22,
      "y": 26,
      "z": -40,
      "name": "Soil_Clay_Lime"
    },
    {
      "x": -22,
      "y": 27,
      "z": -40,
      "name": "Plant_Grass_Sharp"
    },
    {
      "x": -22,
      "y": 13,
      "z": -39,
      "name": "Soil_Clay_Green"
    },
    {
      "x": -22,
      "y": 14,
      "z": -39,
      "name": "Soil_Seaweed_Block"
    },
    {
      "x": -22,
      "y": 23,
      "z": -39,
      "name": "Soil_Clay_Green"
    },
    {
      "x": -22,
      "y": 24,
      "z": -39,
      "name": "Soil_Seaweed_Block"
    },
    {
      "x": -22,
      "y": 25,
      "z": -39,
      "name": "Soil_Clay_Lime"
    },
    {
      "x": -22,
      "y": 26,
      "z": -39,
      "name": "Plant_Grass_Sharp"
    },
    {
      "x": -22,
      "y": 12,
      "z": -38,
      "name": "Soil_Clay_Green"
    },
    {
      "x": -22,
      "y": 13,
      "z": -38,
      "name": "Soil_Clay_Green"
    },
    {
      "x": -22,
      "y": 14,
      "z": -38,
      "name": "Soil_Seaweed_Block"
    },
    {
      "x": -22,
      "y": 15,
      "z": -38,
      "name": "Soil_Clay_Lime"
    },
    {
      "x": -22,
      "y": 16,
      "z": -38,
      "name": "Plant_Grass_Sharp"
    },
    {
      "x": -22,
      "y": 24,
      "z": -38,
      "name": "Soil_Clay_Green"
    },
    {
      "x": -22,
      "y": 25,
      "z": -38,
      "name": "Soil_Clay_Lime"
    },
    {
      "x": -22,
      "y": 26,
      "z": -38,
      "name": "Plant_Grass_Sharp"
    },
    {
      "x": -22,
      "y": 12,
      "z": -37,
      "name": "Soil_Clay_Green"
    },
    {
      "x": -22,
      "y": 13,
      "z": -37,
      "name": "Soil_Seaweed_Block"
    },
    {
      "x": -22,
      "y": 14,
      "z": -37,
      "name": "Soil_Seaweed_Block"
    },
    {
      "x": -22,
      "y": 15,
      "z": -37,
      "name": "Soil_Clay_Lime"
    },
    {
      "x": -22,
      "y": 16,
      "z": -37,
      "name": "Plant_Grass_Sharp"
    },
    {
      "x": -22,
      "y": 25,
      "z": -37,
      "name": "Soil_Clay_Lime"
    },
    {
      "x": -22,
      "y": 26,
      "z": -37,
      "name": "Plant_Grass_Sharp"
    },
    {
      "x": -22,
      "y": 13,
      "z": -36,
      "name": "Soil_Clay_Green"
    },
    {
      "x": -22,
      "y": 14,
      "z": -36,
      "name": "Soil_Seaweed_Block"
    },
    {
      "x": -22,
      "y": 15,
      "z": -36,
      "name": "Soil_Seaweed_Block"
    },
    {
      "x": -22,
      "y": 22,
      "z": -36,
      "name": "Soil_Clay_Green"
    },
    {
      "x": -22,
      "y": 23,
      "z": -36,
      "name": "Soil_Seaweed_Block"
    },
    {
      "x": -22,
      "y": 13,
      "z": -35,
      "name": "Soil_Clay_Green"
    },
    {
      "x": -22,
      "y": 14,
      "z": -35,
      "name": "Soil_Clay_Green"
    },
    {
      "x": -22,
      "y": 15,
      "z": -35,
      "name": "Soil_Seaweed_Block"
    },
    {
      "x": -22,
      "y": 16,
      "z": -35,
      "name": "Soil_Seaweed_Block"
    },
    {
      "x": -22,
      "y": 21,
      "z": -35,
      "name": "Soil_Clay_Green"
    },
    {
      "x": -22,
      "y": 22,
      "z": -35,
      "name": "Soil_Seaweed_Block"
    },
    {
      "x": -22,
      "y": 23,
      "z": -35,
      "name": "Soil_Seaweed_Block"
    },
    {
      "x": -22,
      "y": 24,
      "z": -35,
      "name": "Soil_Clay_Lime"
    },
    {
      "x": -22,
      "y": 25,
      "z": -35,
      "name": "Plant_Grass_Sharp"
    },
    {
      "x": -22,
      "y": 13,
      "z": -34,
      "name": "Soil_Clay_Green"
    },
    {
      "x": -22,
      "y": 14,
      "z": -34,
      "name": "Soil_Clay_Green"
    },
    {
      "x": -22,
      "y": 15,
      "z": -34,
      "name": "Soil_Clay_Green"
    },
    {
      "x": -22,
      "y": 16,
      "z": -34,
      "name": "Soil_Seaweed_Block"
    },
    {
      "x": -22,
      "y": 17,
      "z": -34,
      "name": "Soil_Seaweed_Block"
    },
    {
      "x": -22,
      "y": 18,
      "z": -34,
      "name": "Soil_Seaweed_Block"
    },
    {
      "x": -22,
      "y": 21,
      "z": -34,
      "name": "Soil_Clay_Green"
    },
    {
      "x": -22,
      "y": 22,
      "z": -34,
      "name": "Soil_Seaweed_Block"
    },
    {
      "x": -22,
      "y": 23,
      "z": -34,
      "name": "Soil_Clay_Lime"
    },
    {
      "x": -22,
      "y": 24,
      "z": -34,
      "name": "Plant_Grass_Sharp"
    },
    {
      "x": -22,
      "y": 13,
      "z": -33,
      "name": "Soil_Clay_Green"
    },
    {
      "x": -22,
      "y": 14,
      "z": -33,
      "name": "Soil_Seaweed_Block"
    },
    {
      "x": -22,
      "y": 15,
      "z": -33,
      "name": "Soil_Seaweed_Block"
    },
    {
      "x": -22,
      "y": 16,
      "z": -33,
      "name": "Soil_Seaweed_Block"
    },
    {
      "x": -22,
      "y": 17,
      "z": -33,
      "name": "Soil_Seaweed_Block"
    },
    {
      "x": -22,
      "y": 18,
      "z": -33,
      "name": "Soil_Seaweed_Block"
    },
    {
      "x": -22,
      "y": 19,
      "z": -33,
      "name": "Soil_Seaweed_Block"
    },
    {
      "x": -22,
      "y": 20,
      "z": -33,
      "name": "Soil_Seaweed_Block"
    },
    {
      "x": -22,
      "y": 21,
      "z": -33,
      "name": "Soil_Seaweed_Block"
    },
    {
      "x": -22,
      "y": 10,
      "z": -32,
      "name": "Soil_Clay_Green"
    },
    {
      "x": -22,
      "y": 11,
      "z": -32,
      "name": "Soil_Clay_Green"
    },
    {
      "x": -22,
      "y": 12,
      "z": -32,
      "name": "Soil_Clay_Green"
    },
    {
      "x": -22,
      "y": 13,
      "z": -32,
      "name": "Soil_Clay_Green"
    },
    {
      "x": -22,
      "y": 14,
      "z": -32,
      "name": "Soil_Seaweed_Block"
    },
    {
      "x": -22,
      "y": 15,
      "z": -32,
      "name": "Soil_Seaweed_Block"
    },
    {
      "x": -22,
      "y": 16,
      "z": -32,
      "name": "Soil_Seaweed_Block"
    },
    {
      "x": -22,
      "y": 17,
      "z": -32,
      "name": "Soil_Seaweed_Block"
    },
    {
      "x": -22,
      "y": 18,
      "z": -32,
      "name": "Soil_Seaweed_Block"
    },
    {
      "x": -22,
      "y": 19,
      "z": -32,
      "name": "Soil_Seaweed_Block"
    },
    {
      "x": -22,
      "y": 20,
      "z": -32,
      "name": "Soil_Seaweed_Block"
    },
    {
      "x": -22,
      "y": 21,
      "z": -32,
      "name": "Soil_Seaweed_Block"
    },
    {
      "x": -22,
      "y": 9,
      "z": -31,
      "name": "Soil_Clay_Green"
    },
    {
      "x": -22,
      "y": 10,
      "z": -31,
      "name": "Soil_Seaweed_Block"
    },
    {
      "x": -22,
      "y": 11,
      "z": -31,
      "name": "Soil_Seaweed_Block"
    },
    {
      "x": -22,
      "y": 12,
      "z": -31,
      "name": "Soil_Seaweed_Block"
    },
    {
      "x": -22,
      "y": 13,
      "z": -31,
      "name": "Soil_Seaweed_Block"
    },
    {
      "x": -22,
      "y": 14,
      "z": -31,
      "name": "Soil_Seaweed_Block"
    },
    {
      "x": -22,
      "y": 15,
      "z": -31,
      "name": "Soil_Seaweed_Block"
    },
    {
      "x": -22,
      "y": 16,
      "z": -31,
      "name": "Soil_Seaweed_Block"
    },
    {
      "x": -22,
      "y": 17,
      "z": -31,
      "name": "Soil_Seaweed_Block"
    },
    {
      "x": -22,
      "y": 18,
      "z": -31,
      "name": "Soil_Seaweed_Block"
    },
    {
      "x": -22,
      "y": 19,
      "z": -31,
      "name": "Soil_Seaweed_Block"
    },
    {
      "x": -22,
      "y": 20,
      "z": -31,
      "name": "Soil_Seaweed_Block"
    },
    {
      "x": -22,
      "y": 9,
      "z": -30,
      "name": "Soil_Clay_Green"
    },
    {
      "x": -22,
      "y": 10,
      "z": -30,
      "name": "Soil_Seaweed_Block"
    },
    {
      "x": -22,
      "y": 11,
      "z": -30,
      "name": "Soil_Seaweed_Block"
    },
    {
      "x": -22,
      "y": 12,
      "z": -30,
      "name": "Soil_Seaweed_Block"
    },
    {
      "x": -22,
      "y": 13,
      "z": -30,
      "name": "Soil_Seaweed_Block"
    },
    {
      "x": -22,
      "y": 14,
      "z": -30,
      "name": "Soil_Seaweed_Block"
    },
    {
      "x": -22,
      "y": 15,
      "z": -30,
      "name": "Soil_Seaweed_Block"
    },
    {
      "x": -22,
      "y": 16,
      "z": -30,
      "name": "Soil_Seaweed_Block"
    },
    {
      "x": -22,
      "y": 17,
      "z": -30,
      "name": "Soil_Seaweed_Block"
    },
    {
      "x": -22,
      "y": 18,
      "z": -30,
      "name": "Soil_Seaweed_Block"
    },
    {
      "x": -22,
      "y": 19,
      "z": -30,
      "name": "Soil_Seaweed_Block"
    },
    {
      "x": -22,
      "y": 20,
      "z": -30,
      "name": "Soil_Seaweed_Block"
    },
    {
      "x": -22,
      "y": 9,
      "z": -29,
      "name": "Soil_Clay_Green"
    },
    {
      "x": -22,
      "y": 10,
      "z": -29,
      "name": "Soil_Seaweed_Block"
    },
    {
      "x": -22,
      "y": 11,
      "z": -29,
      "name": "Soil_Seaweed_Block"
    },
    {
      "x": -22,
      "y": 12,
      "z": -29,
      "name": "Soil_Seaweed_Block"
    },
    {
      "x": -22,
      "y": 13,
      "z": -29,
      "name": "Soil_Seaweed_Block"
    },
    {
      "x": -22,
      "y": 14,
      "z": -29,
      "name": "Soil_Seaweed_Block"
    },
    {
      "x": -22,
      "y": 15,
      "z": -29,
      "name": "Soil_Seaweed_Block"
    },
    {
      "x": -22,
      "y": 16,
      "z": -29,
      "name": "Soil_Seaweed_Block"
    },
    {
      "x": -22,
      "y": 17,
      "z": -29,
      "name": "Soil_Seaweed_Block"
    },
    {
      "x": -22,
      "y": 18,
      "z": -29,
      "name": "Soil_Seaweed_Block"
    },
    {
      "x": -22,
      "y": 19,
      "z": -29,
      "name": "Soil_Seaweed_Block"
    },
    {
      "x": -22,
      "y": 20,
      "z": -29,
      "name": "Soil_Seaweed_Block"
    },
    {
      "x": -22,
      "y": 21,
      "z": -29,
      "name": "Soil_Clay_Lime"
    },
    {
      "x": -22,
      "y": 22,
      "z": -29,
      "name": "Plant_Grass_Sharp"
    },
    {
      "x": -22,
      "y": 9,
      "z": -28,
      "name": "Soil_Clay_Green"
    },
    {
      "x": -22,
      "y": 10,
      "z": -28,
      "name": "Soil_Seaweed_Block"
    },
    {
      "x": -22,
      "y": 11,
      "z": -28,
      "name": "Soil_Seaweed_Block"
    },
    {
      "x": -22,
      "y": 12,
      "z": -28,
      "name": "Soil_Seaweed_Block"
    },
    {
      "x": -22,
      "y": 13,
      "z": -28,
      "name": "Soil_Seaweed_Block"
    },
    {
      "x": -22,
      "y": 14,
      "z": -28,
      "name": "Soil_Seaweed_Block"
    },
    {
      "x": -22,
      "y": 15,
      "z": -28,
      "name": "Soil_Seaweed_Block"
    },
    {
      "x": -22,
      "y": 16,
      "z": -28,
      "name": "Soil_Seaweed_Block"
    },
    {
      "x": -22,
      "y": 17,
      "z": -28,
      "name": "Soil_Seaweed_Block"
    },
    {
      "x": -22,
      "y": 18,
      "z": -28,
      "name": "Soil_Seaweed_Block"
    },
    {
      "x": -22,
      "y": 19,
      "z": -28,
      "name": "Soil_Seaweed_Block"
    },
    {
      "x": -22,
      "y": 9,
      "z": -27,
      "name": "Soil_Clay_Green"
    },
    {
      "x": -22,
      "y": 10,
      "z": -27,
      "name": "Soil_Seaweed_Block"
    },
    {
      "x": -22,
      "y": 11,
      "z": -27,
      "name": "Soil_Seaweed_Block"
    },
    {
      "x": -22,
      "y": 12,
      "z": -27,
      "name": "Soil_Seaweed_Block"
    },
    {
      "x": -22,
      "y": 13,
      "z": -27,
      "name": "Soil_Seaweed_Block"
    },
    {
      "x": -22,
      "y": 14,
      "z": -27,
      "name": "Soil_Seaweed_Block"
    },
    {
      "x": -22,
      "y": 15,
      "z": -27,
      "name": "Soil_Seaweed_Block"
    },
    {
      "x": -22,
      "y": 16,
      "z": -27,
      "name": "Soil_Seaweed_Block"
    },
    {
      "x": -22,
      "y": 17,
      "z": -27,
      "name": "Soil_Seaweed_Block"
    },
    {
      "x": -22,
      "y": 18,
      "z": -27,
      "name": "Soil_Seaweed_Block"
    },
    {
      "x": -22,
      "y": 8,
      "z": -26,
      "name": "Soil_Clay_Green"
    },
    {
      "x": -22,
      "y": 9,
      "z": -26,
      "name": "Soil_Seaweed_Block"
    },
    {
      "x": -22,
      "y": 10,
      "z": -26,
      "name": "Soil_Seaweed_Block"
    },
    {
      "x": -22,
      "y": 11,
      "z": -26,
      "name": "Soil_Seaweed_Block"
    },
    {
      "x": -22,
      "y": 12,
      "z": -26,
      "name": "Soil_Seaweed_Block"
    },
    {
      "x": -22,
      "y": 13,
      "z": -26,
      "name": "Soil_Seaweed_Block"
    },
    {
      "x": -22,
      "y": 14,
      "z": -26,
      "name": "Soil_Seaweed_Block"
    },
    {
      "x": -22,
      "y": 15,
      "z": -26,
      "name": "Soil_Seaweed_Block"
    },
    {
      "x": -22,
      "y": 16,
      "z": -26,
      "name": "Soil_Seaweed_Block"
    },
    {
      "x": -22,
      "y": 17,
      "z": -26,
      "name": "Soil_Seaweed_Block"
    },
    {
      "x": -22,
      "y": 18,
      "z": -26,
      "name": "Soil_Seaweed_Block"
    },
    {
      "x": -22,
      "y": 8,
      "z": -25,
      "name": "Soil_Clay_Green"
    },
    {
      "x": -22,
      "y": 9,
      "z": -25,
      "name": "Soil_Seaweed_Block"
    },
    {
      "x": -22,
      "y": 10,
      "z": -25,
      "name": "Soil_Seaweed_Block"
    },
    {
      "x": -22,
      "y": 11,
      "z": -25,
      "name": "Soil_Seaweed_Block"
    },
    {
      "x": -22,
      "y": 12,
      "z": -25,
      "name": "Soil_Seaweed_Block"
    },
    {
      "x": -22,
      "y": 13,
      "z": -25,
      "name": "Soil_Seaweed_Block"
    },
    {
      "x": -22,
      "y": 14,
      "z": -25,
      "name": "Soil_Seaweed_Block"
    },
    {
      "x": -22,
      "y": 15,
      "z": -25,
      "name": "Soil_Seaweed_Block"
    },
    {
      "x": -22,
      "y": 16,
      "z": -25,
      "name": "Soil_Seaweed_Block"
    },
    {
      "x": -22,
      "y": 17,
      "z": -25,
      "name": "Soil_Seaweed_Block"
    },
    {
      "x": -22,
      "y": 18,
      "z": -25,
      "name": "Soil_Seaweed_Block"
    },
    {
      "x": -22,
      "y": 9,
      "z": -24,
      "name": "Soil_Clay_Green"
    },
    {
      "x": -22,
      "y": 10,
      "z": -24,
      "name": "Soil_Seaweed_Block"
    },
    {
      "x": -22,
      "y": 11,
      "z": -24,
      "name": "Soil_Seaweed_Block"
    },
    {
      "x": -22,
      "y": 12,
      "z": -24,
      "name": "Soil_Seaweed_Block"
    },
    {
      "x": -22,
      "y": 13,
      "z": -24,
      "name": "Soil_Seaweed_Block"
    },
    {
      "x": -22,
      "y": 14,
      "z": -24,
      "name": "Soil_Seaweed_Block"
    },
    {
      "x": -22,
      "y": 15,
      "z": -24,
      "name": "Soil_Seaweed_Block"
    },
    {
      "x": -22,
      "y": 16,
      "z": -24,
      "name": "Soil_Seaweed_Block"
    },
    {
      "x": -22,
      "y": 17,
      "z": -24,
      "name": "Soil_Seaweed_Block"
    },
    {
      "x": -22,
      "y": 18,
      "z": -24,
      "name": "Soil_Seaweed_Block"
    },
    {
      "x": -22,
      "y": 9,
      "z": -23,
      "name": "Soil_Clay_Green"
    },
    {
      "x": -22,
      "y": 10,
      "z": -23,
      "name": "Soil_Seaweed_Block"
    },
    {
      "x": -22,
      "y": 11,
      "z": -23,
      "name": "Soil_Seaweed_Block"
    },
    {
      "x": -22,
      "y": 12,
      "z": -23,
      "name": "Soil_Seaweed_Block"
    },
    {
      "x": -22,
      "y": 13,
      "z": -23,
      "name": "Soil_Seaweed_Block"
    },
    {
      "x": -22,
      "y": 14,
      "z": -23,
      "name": "Soil_Seaweed_Block"
    },
    {
      "x": -22,
      "y": 15,
      "z": -23,
      "name": "Soil_Seaweed_Block"
    },
    {
      "x": -22,
      "y": 16,
      "z": -23,
      "name": "Soil_Seaweed_Block"
    },
    {
      "x": -22,
      "y": 9,
      "z": -22,
      "name": "Soil_Clay_Green"
    },
    {
      "x": -22,
      "y": 10,
      "z": -22,
      "name": "Soil_Seaweed_Block"
    },
    {
      "x": -22,
      "y": 11,
      "z": -22,
      "name": "Soil_Seaweed_Block"
    },
    {
      "x": -22,
      "y": 12,
      "z": -22,
      "name": "Soil_Seaweed_Block"
    },
    {
      "x": -22,
      "y": 13,
      "z": -22,
      "name": "Soil_Seaweed_Block"
    },
    {
      "x": -22,
      "y": 14,
      "z": -22,
      "name": "Soil_Seaweed_Block"
    },
    {
      "x": -22,
      "y": 15,
      "z": -22,
      "name": "Soil_Seaweed_Block"
    },
    {
      "x": -22,
      "y": 16,
      "z": -22,
      "name": "Soil_Seaweed_Block"
    },
    {
      "x": -22,
      "y": 10,
      "z": -21,
      "name": "Soil_Clay_Green"
    },
    {
      "x": -22,
      "y": 11,
      "z": -21,
      "name": "Soil_Seaweed_Block"
    },
    {
      "x": -22,
      "y": 12,
      "z": -21,
      "name": "Soil_Seaweed_Block"
    },
    {
      "x": -22,
      "y": 13,
      "z": -21,
      "name": "Soil_Seaweed_Block"
    },
    {
      "x": -22,
      "y": 14,
      "z": -21,
      "name": "Soil_Seaweed_Block"
    },
    {
      "x": -22,
      "y": 15,
      "z": -21,
      "name": "Soil_Seaweed_Block"
    },
    {
      "x": -22,
      "y": 16,
      "z": -21,
      "name": "Soil_Seaweed_Block"
    },
    {
      "x": -22,
      "y": 11,
      "z": -20,
      "name": "Soil_Clay_Green"
    },
    {
      "x": -22,
      "y": 12,
      "z": -20,
      "name": "Soil_Clay_Green"
    },
    {
      "x": -22,
      "y": 13,
      "z": -20,
      "name": "Soil_Clay_Green"
    },
    {
      "x": -22,
      "y": 14,
      "z": -20,
      "name": "Soil_Seaweed_Block"
    },
    {
      "x": -22,
      "y": 15,
      "z": -20,
      "name": "Soil_Seaweed_Block"
    },
    {
      "x": -22,
      "y": 16,
      "z": -20,
      "name": "Soil_Seaweed_Block"
    },
    {
      "x": -22,
      "y": 12,
      "z": -19,
      "name": "Soil_Clay_Green"
    },
    {
      "x": -22,
      "y": 13,
      "z": -19,
      "name": "Soil_Clay_Green"
    },
    {
      "x": -22,
      "y": 14,
      "z": -19,
      "name": "Soil_Seaweed_Block"
    },
    {
      "x": -22,
      "y": 15,
      "z": -19,
      "name": "Soil_Seaweed_Block"
    },
    {
      "x": -22,
      "y": 16,
      "z": -19,
      "name": "Soil_Seaweed_Block"
    },
    {
      "x": -22,
      "y": 13,
      "z": -18,
      "name": "Soil_Clay_Green"
    },
    {
      "x": -22,
      "y": 14,
      "z": -18,
      "name": "Soil_Seaweed_Block"
    },
    {
      "x": -22,
      "y": 8,
      "z": 24,
      "name": "Soil_Clay_Green"
    },
    {
      "x": -22,
      "y": 9,
      "z": 24,
      "name": "Soil_Clay_Green"
    },
    {
      "x": -22,
      "y": 8,
      "z": 25,
      "name": "Soil_Clay_Green"
    },
    {
      "x": -22,
      "y": 9,
      "z": 25,
      "name": "Soil_Clay_Green"
    },
    {
      "x": -22,
      "y": 10,
      "z": 25,
      "name": "Soil_Seaweed_Block"
    },
    {
      "x": -22,
      "y": 9,
      "z": 26,
      "name": "Soil_Clay_Green"
    },
    {
      "x": -22,
      "y": 10,
      "z": 26,
      "name": "Soil_Seaweed_Block"
    },
    {
      "x": -22,
      "y": 11,
      "z": 26,
      "name": "Soil_Clay_Lime"
    },
    {
      "x": -22,
      "y": 12,
      "z": 26,
      "name": "Plant_Grass_Sharp"
    },
    {
      "x": -22,
      "y": 10,
      "z": 27,
      "name": "Soil_Clay_Green"
    },
    {
      "x": -22,
      "y": 11,
      "z": 27,
      "name": "Soil_Clay_Lime"
    },
    {
      "x": -22,
      "y": 12,
      "z": 27,
      "name": "Plant_Grass_Sharp"
    },
    {
      "x": -22,
      "y": 11,
      "z": 32,
      "name": "Soil_Clay_Green"
    },
    {
      "x": -22,
      "y": 12,
      "z": 32,
      "name": "Soil_Clay_Green"
    },
    {
      "x": -22,
      "y": 13,
      "z": 32,
      "name": "Soil_Seaweed_Block"
    },
    {
      "x": -22,
      "y": 14,
      "z": 32,
      "name": "Soil_Seaweed_Block"
    },
    {
      "x": -22,
      "y": 11,
      "z": 33,
      "name": "Soil_Clay_Green"
    },
    {
      "x": -22,
      "y": 12,
      "z": 33,
      "name": "Soil_Seaweed_Block"
    },
    {
      "x": -22,
      "y": 13,
      "z": 33,
      "name": "Soil_Seaweed_Block"
    },
    {
      "x": -22,
      "y": 14,
      "z": 33,
      "name": "Soil_Seaweed_Block"
    },
    {
      "x": -22,
      "y": 15,
      "z": 33,
      "name": "Soil_Clay_Lime"
    },
    {
      "x": -22,
      "y": 16,
      "z": 33,
      "name": "Plant_Grass_Sharp"
    },
    {
      "x": -22,
      "y": 11,
      "z": 34,
      "name": "Soil_Clay_Green"
    },
    {
      "x": -22,
      "y": 12,
      "z": 34,
      "name": "Soil_Seaweed_Block"
    },
    {
      "x": -22,
      "y": 13,
      "z": 34,
      "name": "Soil_Seaweed_Block"
    },
    {
      "x": -22,
      "y": 14,
      "z": 34,
      "name": "Soil_Seaweed_Block"
    },
    {
      "x": -22,
      "y": 15,
      "z": 34,
      "name": "Soil_Clay_Lime"
    },
    {
      "x": -22,
      "y": 16,
      "z": 34,
      "name": "Plant_Grass_Sharp"
    },
    {
      "x": -22,
      "y": 11,
      "z": 35,
      "name": "Soil_Clay_Green"
    },
    {
      "x": -22,
      "y": 12,
      "z": 35,
      "name": "Soil_Seaweed_Block"
    },
    {
      "x": -22,
      "y": 13,
      "z": 35,
      "name": "Soil_Seaweed_Block"
    },
    {
      "x": -22,
      "y": 14,
      "z": 35,
      "name": "Soil_Seaweed_Block"
    },
    {
      "x": -22,
      "y": 15,
      "z": 35,
      "name": "Soil_Clay_Lime"
    },
    {
      "x": -22,
      "y": 16,
      "z": 35,
      "name": "Plant_Grass_Sharp"
    },
    {
      "x": -22,
      "y": 12,
      "z": 36,
      "name": "Soil_Clay_Green"
    },
    {
      "x": -22,
      "y": 13,
      "z": 36,
      "name": "Soil_Seaweed_Block"
    },
    {
      "x": -22,
      "y": 14,
      "z": 36,
      "name": "Soil_Seaweed_Block"
    },
    {
      "x": -22,
      "y": 12,
      "z": 37,
      "name": "Soil_Clay_Green"
    },
    {
      "x": -22,
      "y": 13,
      "z": 37,
      "name": "Soil_Clay_Green"
    },
    {
      "x": -22,
      "y": 14,
      "z": 37,
      "name": "Soil_Seaweed_Block"
    },
    {
      "x": -22,
      "y": 38,
      "z": 42,
      "name": "Soil_Clay_Green"
    },
    {
      "x": -22,
      "y": 39,
      "z": 42,
      "name": "Soil_Clay_Lime"
    },
    {
      "x": -22,
      "y": 40,
      "z": 42,
      "name": "Plant_Grass_Sharp"
    },
    {
      "x": -22,
      "y": 37,
      "z": 43,
      "name": "Soil_Clay_Green"
    },
    {
      "x": -21,
      "y": 20,
      "z": -47,
      "name": "Soil_Clay_Green"
    },
    {
      "x": -21,
      "y": 20,
      "z": -46,
      "name": "Soil_Clay_Green"
    },
    {
      "x": -21,
      "y": 21,
      "z": -46,
      "name": "Soil_Seaweed_Block"
    },
    {
      "x": -21,
      "y": 20,
      "z": -45,
      "name": "Soil_Clay_Green"
    },
    {
      "x": -21,
      "y": 21,
      "z": -45,
      "name": "Soil_Seaweed_Block"
    },
    {
      "x": -21,
      "y": 13,
      "z": -42,
      "name": "Soil_Clay_Green"
    },
    {
      "x": -21,
      "y": 14,
      "z": -42,
      "name": "Soil_Clay_Lime"
    },
    {
      "x": -21,
      "y": 15,
      "z": -42,
      "name": "Plant_Grass_Sharp"
    },
    {
      "x": -21,
      "y": 12,
      "z": -41,
      "name": "Soil_Clay_Green"
    },
    {
      "x": -21,
      "y": 13,
      "z": -41,
      "name": "Soil_Seaweed_Block"
    },
    {
      "x": -21,
      "y": 14,
      "z": -41,
      "name": "Soil_Clay_Lime"
    },
    {
      "x": -21,
      "y": 15,
      "z": -41,
      "name": "Plant_Grass_Sharp"
    },
    {
      "x": -21,
      "y": 23,
      "z": -41,
      "name": "Soil_Clay_Green"
    },
    {
      "x": -21,
      "y": 24,
      "z": -41,
      "name": "Soil_Seaweed_Block"
    },
    {
      "x": -21,
      "y": 25,
      "z": -41,
      "name": "Soil_Clay_Lime"
    },
    {
      "x": -21,
      "y": 26,
      "z": -41,
      "name": "Plant_Grass_Sharp"
    },
    {
      "x": -21,
      "y": 12,
      "z": -40,
      "name": "Soil_Clay_Green"
    },
    {
      "x": -21,
      "y": 13,
      "z": -40,
      "name": "Soil_Seaweed_Block"
    },
    {
      "x": -21,
      "y": 14,
      "z": -40,
      "name": "Soil_Clay_Lime"
    },
    {
      "x": -21,
      "y": 15,
      "z": -40,
      "name": "Plant_Grass_Sharp"
    },
    {
      "x": -21,
      "y": 23,
      "z": -40,
      "name": "Soil_Clay_Green"
    },
    {
      "x": -21,
      "y": 24,
      "z": -40,
      "name": "Soil_Seaweed_Block"
    },
    {
      "x": -21,
      "y": 25,
      "z": -40,
      "name": "Soil_Seaweed_Block"
    },
    {
      "x": -21,
      "y": 26,
      "z": -40,
      "name": "Soil_Clay_Lime"
    },
    {
      "x": -21,
      "y": 27,
      "z": -40,
      "name": "Plant_Grass_Sharp"
    },
    {
      "x": -21,
      "y": 12,
      "z": -39,
      "name": "Soil_Clay_Green"
    },
    {
      "x": -21,
      "y": 13,
      "z": -39,
      "name": "Soil_Seaweed_Block"
    },
    {
      "x": -21,
      "y": 14,
      "z": -39,
      "name": "Soil_Clay_Lime"
    },
    {
      "x": -21,
      "y": 15,
      "z": -39,
      "name": "Plant_Grass_Sharp"
    },
    {
      "x": -21,
      "y": 23,
      "z": -39,
      "name": "Soil_Clay_Green"
    },
    {
      "x": -21,
      "y": 24,
      "z": -39,
      "name": "Soil_Seaweed_Block"
    },
    {
      "x": -21,
      "y": 25,
      "z": -39,
      "name": "Soil_Clay_Lime"
    },
    {
      "x": -21,
      "y": 26,
      "z": -39,
      "name": "Plant_Grass_Sharp"
    },
    {
      "x": -21,
      "y": 13,
      "z": -38,
      "name": "Soil_Clay_Green"
    },
    {
      "x": -21,
      "y": 14,
      "z": -38,
      "name": "Soil_Seaweed_Block"
    },
    {
      "x": -21,
      "y": 15,
      "z": -38,
      "name": "Soil_Clay_Lime"
    },
    {
      "x": -21,
      "y": 16,
      "z": -38,
      "name": "Plant_Grass_Sharp"
    },
    {
      "x": -21,
      "y": 23,
      "z": -38,
      "name": "Soil_Clay_Green"
    },
    {
      "x": -21,
      "y": 24,
      "z": -38,
      "name": "Soil_Seaweed_Block"
    },
    {
      "x": -21,
      "y": 25,
      "z": -38,
      "name": "Soil_Clay_Lime"
    },
    {
      "x": -21,
      "y": 26,
      "z": -38,
      "name": "Plant_Grass_Sharp"
    },
    {
      "x": -21,
      "y": 13,
      "z": -37,
      "name": "Soil_Clay_Green"
    },
    {
      "x": -21,
      "y": 14,
      "z": -37,
      "name": "Soil_Seaweed_Block"
    },
    {
      "x": -21,
      "y": 15,
      "z": -37,
      "name": "Soil_Clay_Lime"
    },
    {
      "x": -21,
      "y": 16,
      "z": -37,
      "name": "Plant_Grass_Sharp"
    },
    {
      "x": -21,
      "y": 23,
      "z": -37,
      "name": "Soil_Clay_Green"
    },
    {
      "x": -21,
      "y": 24,
      "z": -37,
      "name": "Soil_Clay_Lime"
    },
    {
      "x": -21,
      "y": 25,
      "z": -37,
      "name": "Soil_Clay_Lime"
    },
    {
      "x": -21,
      "y": 26,
      "z": -37,
      "name": "Plant_Grass_Sharp"
    },
    {
      "x": -21,
      "y": 13,
      "z": -36,
      "name": "Soil_Clay_Green"
    },
    {
      "x": -21,
      "y": 14,
      "z": -36,
      "name": "Soil_Seaweed_Block"
    },
    {
      "x": -21,
      "y": 15,
      "z": -36,
      "name": "Soil_Seaweed_Block"
    },
    {
      "x": -21,
      "y": 16,
      "z": -36,
      "name": "Soil_Clay_Lime"
    },
    {
      "x": -21,
      "y": 17,
      "z": -36,
      "name": "Plant_Grass_Sharp"
    },
    {
      "x": -21,
      "y": 23,
      "z": -36,
      "name": "Soil_Clay_Green"
    },
    {
      "x": -21,
      "y": 24,
      "z": -36,
      "name": "Soil_Clay_Lime"
    },
    {
      "x": -21,
      "y": 25,
      "z": -36,
      "name": "Soil_Clay_Lime"
    },
    {
      "x": -21,
      "y": 26,
      "z": -36,
      "name": "Plant_Grass_Sharp"
    },
    {
      "x": -21,
      "y": 13,
      "z": -35,
      "name": "Soil_Clay_Green"
    },
    {
      "x": -21,
      "y": 14,
      "z": -35,
      "name": "Soil_Seaweed_Block"
    },
    {
      "x": -21,
      "y": 15,
      "z": -35,
      "name": "Soil_Seaweed_Block"
    },
    {
      "x": -21,
      "y": 16,
      "z": -35,
      "name": "Soil_Seaweed_Block"
    },
    {
      "x": -21,
      "y": 17,
      "z": -35,
      "name": "Soil_Seaweed_Block"
    },
    {
      "x": -21,
      "y": 18,
      "z": -35,
      "name": "Soil_Seaweed_Block"
    },
    {
      "x": -21,
      "y": 19,
      "z": -35,
      "name": "Soil_Seaweed_Block"
    },
    {
      "x": -21,
      "y": 20,
      "z": -35,
      "name": "Soil_Clay_Green"
    },
    {
      "x": -21,
      "y": 21,
      "z": -35,
      "name": "Soil_Clay_Green"
    },
    {
      "x": -21,
      "y": 22,
      "z": -35,
      "name": "Soil_Clay_Green"
    },
    {
      "x": -21,
      "y": 23,
      "z": -35,
      "name": "Soil_Seaweed_Block"
    },
    {
      "x": -21,
      "y": 24,
      "z": -35,
      "name": "Soil_Clay_Lime"
    },
    {
      "x": -21,
      "y": 25,
      "z": -35,
      "name": "Plant_Grass_Sharp"
    },
    {
      "x": -21,
      "y": 13,
      "z": -34,
      "name": "Soil_Clay_Green"
    },
    {
      "x": -21,
      "y": 14,
      "z": -34,
      "name": "Soil_Seaweed_Block"
    },
    {
      "x": -21,
      "y": 15,
      "z": -34,
      "name": "Soil_Seaweed_Block"
    },
    {
      "x": -21,
      "y": 16,
      "z": -34,
      "name": "Soil_Seaweed_Block"
    },
    {
      "x": -21,
      "y": 17,
      "z": -34,
      "name": "Soil_Seaweed_Block"
    },
    {
      "x": -21,
      "y": 18,
      "z": -34,
      "name": "Soil_Seaweed_Block"
    },
    {
      "x": -21,
      "y": 19,
      "z": -34,
      "name": "Soil_Seaweed_Block"
    },
    {
      "x": -21,
      "y": 20,
      "z": -34,
      "name": "Soil_Clay_Green"
    },
    {
      "x": -21,
      "y": 21,
      "z": -34,
      "name": "Soil_Seaweed_Block"
    },
    {
      "x": -21,
      "y": 22,
      "z": -34,
      "name": "Soil_Seaweed_Block"
    },
    {
      "x": -21,
      "y": 23,
      "z": -34,
      "name": "Soil_Seaweed_Block"
    },
    {
      "x": -21,
      "y": 24,
      "z": -34,
      "name": "Soil_Clay_Lime"
    },
    {
      "x": -21,
      "y": 25,
      "z": -34,
      "name": "Plant_Grass_Sharp"
    },
    {
      "x": -21,
      "y": 10,
      "z": -33,
      "name": "Soil_Clay_Green"
    },
    {
      "x": -21,
      "y": 11,
      "z": -33,
      "name": "Soil_Clay_Green"
    },
    {
      "x": -21,
      "y": 12,
      "z": -33,
      "name": "Soil_Clay_Green"
    },
    {
      "x": -21,
      "y": 13,
      "z": -33,
      "name": "Soil_Seaweed_Block"
    },
    {
      "x": -21,
      "y": 14,
      "z": -33,
      "name": "Soil_Seaweed_Block"
    },
    {
      "x": -21,
      "y": 15,
      "z": -33,
      "name": "Soil_Seaweed_Block"
    },
    {
      "x": -21,
      "y": 16,
      "z": -33,
      "name": "Soil_Seaweed_Block"
    },
    {
      "x": -21,
      "y": 17,
      "z": -33,
      "name": "Soil_Seaweed_Block"
    },
    {
      "x": -21,
      "y": 18,
      "z": -33,
      "name": "Soil_Seaweed_Block"
    },
    {
      "x": -21,
      "y": 19,
      "z": -33,
      "name": "Soil_Seaweed_Block"
    },
    {
      "x": -21,
      "y": 20,
      "z": -33,
      "name": "Soil_Seaweed_Block"
    },
    {
      "x": -21,
      "y": 21,
      "z": -33,
      "name": "Soil_Seaweed_Block"
    },
    {
      "x": -21,
      "y": 22,
      "z": -33,
      "name": "Soil_Seaweed_Block"
    },
    {
      "x": -21,
      "y": 23,
      "z": -33,
      "name": "Soil_Clay_Lime"
    },
    {
      "x": -21,
      "y": 24,
      "z": -33,
      "name": "Plant_Grass_Sharp"
    },
    {
      "x": -21,
      "y": 9,
      "z": -32,
      "name": "Soil_Clay_Green"
    },
    {
      "x": -21,
      "y": 10,
      "z": -32,
      "name": "Soil_Seaweed_Block"
    },
    {
      "x": -21,
      "y": 11,
      "z": -32,
      "name": "Soil_Seaweed_Block"
    },
    {
      "x": -21,
      "y": 12,
      "z": -32,
      "name": "Soil_Seaweed_Block"
    },
    {
      "x": -21,
      "y": 13,
      "z": -32,
      "name": "Soil_Seaweed_Block"
    },
    {
      "x": -21,
      "y": 14,
      "z": -32,
      "name": "Soil_Seaweed_Block"
    },
    {
      "x": -21,
      "y": 15,
      "z": -32,
      "name": "Soil_Seaweed_Block"
    },
    {
      "x": -21,
      "y": 16,
      "z": -32,
      "name": "Soil_Seaweed_Block"
    },
    {
      "x": -21,
      "y": 17,
      "z": -32,
      "name": "Soil_Seaweed_Block"
    },
    {
      "x": -21,
      "y": 18,
      "z": -32,
      "name": "Soil_Seaweed_Block"
    },
    {
      "x": -21,
      "y": 19,
      "z": -32,
      "name": "Soil_Seaweed_Block"
    },
    {
      "x": -21,
      "y": 20,
      "z": -32,
      "name": "Soil_Seaweed_Block"
    },
    {
      "x": -21,
      "y": 21,
      "z": -32,
      "name": "Soil_Seaweed_Block"
    },
    {
      "x": -21,
      "y": 22,
      "z": -32,
      "name": "Soil_Clay_Lime"
    },
    {
      "x": -21,
      "y": 23,
      "z": -32,
      "name": "Soil_Clay_Lime"
    },
    {
      "x": -21,
      "y": 24,
      "z": -32,
      "name": "Plant_Grass_Sharp"
    },
    {
      "x": -21,
      "y": 8,
      "z": -31,
      "name": "Soil_Clay_Green"
    },
    {
      "x": -21,
      "y": 9,
      "z": -31,
      "name": "Soil_Seaweed_Block"
    },
    {
      "x": -21,
      "y": 10,
      "z": -31,
      "name": "Soil_Seaweed_Block"
    },
    {
      "x": -21,
      "y": 11,
      "z": -31,
      "name": "Soil_Seaweed_Block"
    },
    {
      "x": -21,
      "y": 12,
      "z": -31,
      "name": "Soil_Seaweed_Block"
    },
    {
      "x": -21,
      "y": 13,
      "z": -31,
      "name": "Soil_Seaweed_Block"
    },
    {
      "x": -21,
      "y": 14,
      "z": -31,
      "name": "Soil_Seaweed_Block"
    },
    {
      "x": -21,
      "y": 15,
      "z": -31,
      "name": "Soil_Seaweed_Block"
    },
    {
      "x": -21,
      "y": 16,
      "z": -31,
      "name": "Soil_Seaweed_Block"
    },
    {
      "x": -21,
      "y": 17,
      "z": -31,
      "name": "Soil_Seaweed_Block"
    },
    {
      "x": -21,
      "y": 18,
      "z": -31,
      "name": "Soil_Seaweed_Block"
    },
    {
      "x": -21,
      "y": 19,
      "z": -31,
      "name": "Soil_Seaweed_Block"
    },
    {
      "x": -21,
      "y": 20,
      "z": -31,
      "name": "Soil_Seaweed_Block"
    },
    {
      "x": -21,
      "y": 21,
      "z": -31,
      "name": "Soil_Clay_Lime"
    },
    {
      "x": -21,
      "y": 22,
      "z": -31,
      "name": "Plant_Grass_Sharp"
    },
    {
      "x": -21,
      "y": 8,
      "z": -30,
      "name": "Soil_Clay_Green"
    },
    {
      "x": -21,
      "y": 9,
      "z": -30,
      "name": "Soil_Seaweed_Block"
    },
    {
      "x": -21,
      "y": 10,
      "z": -30,
      "name": "Soil_Seaweed_Block"
    },
    {
      "x": -21,
      "y": 11,
      "z": -30,
      "name": "Soil_Seaweed_Block"
    },
    {
      "x": -21,
      "y": 12,
      "z": -30,
      "name": "Soil_Seaweed_Block"
    },
    {
      "x": -21,
      "y": 13,
      "z": -30,
      "name": "Soil_Seaweed_Block"
    },
    {
      "x": -21,
      "y": 14,
      "z": -30,
      "name": "Soil_Seaweed_Block"
    },
    {
      "x": -21,
      "y": 15,
      "z": -30,
      "name": "Soil_Seaweed_Block"
    },
    {
      "x": -21,
      "y": 16,
      "z": -30,
      "name": "Soil_Seaweed_Block"
    },
    {
      "x": -21,
      "y": 17,
      "z": -30,
      "name": "Soil_Seaweed_Block"
    },
    {
      "x": -21,
      "y": 18,
      "z": -30,
      "name": "Soil_Seaweed_Block"
    },
    {
      "x": -21,
      "y": 19,
      "z": -30,
      "name": "Soil_Seaweed_Block"
    },
    {
      "x": -21,
      "y": 20,
      "z": -30,
      "name": "Soil_Seaweed_Block"
    },
    {
      "x": -21,
      "y": 21,
      "z": -30,
      "name": "Soil_Clay_Lime"
    },
    {
      "x": -21,
      "y": 22,
      "z": -30,
      "name": "Plant_Grass_Sharp"
    },
    {
      "x": -21,
      "y": 7,
      "z": -29,
      "name": "Soil_Clay_Green"
    },
    {
      "x": -21,
      "y": 8,
      "z": -29,
      "name": "Soil_Clay_Green"
    },
    {
      "x": -21,
      "y": 9,
      "z": -29,
      "name": "Soil_Seaweed_Block"
    },
    {
      "x": -21,
      "y": 10,
      "z": -29,
      "name": "Soil_Seaweed_Block"
    },
    {
      "x": -21,
      "y": 11,
      "z": -29,
      "name": "Soil_Seaweed_Block"
    },
    {
      "x": -21,
      "y": 12,
      "z": -29,
      "name": "Soil_Seaweed_Block"
    },
    {
      "x": -21,
      "y": 13,
      "z": -29,
      "name": "Soil_Seaweed_Block"
    },
    {
      "x": -21,
      "y": 14,
      "z": -29,
      "name": "Soil_Seaweed_Block"
    },
    {
      "x": -21,
      "y": 15,
      "z": -29,
      "name": "Soil_Seaweed_Block"
    },
    {
      "x": -21,
      "y": 16,
      "z": -29,
      "name": "Soil_Seaweed_Block"
    },
    {
      "x": -21,
      "y": 17,
      "z": -29,
      "name": "Soil_Seaweed_Block"
    },
    {
      "x": -21,
      "y": 18,
      "z": -29,
      "name": "Soil_Seaweed_Block"
    },
    {
      "x": -21,
      "y": 19,
      "z": -29,
      "name": "Soil_Seaweed_Block"
    },
    {
      "x": -21,
      "y": 20,
      "z": -29,
      "name": "Soil_Seaweed_Block"
    },
    {
      "x": -21,
      "y": 21,
      "z": -29,
      "name": "Soil_Seaweed_Block"
    },
    {
      "x": -21,
      "y": 22,
      "z": -29,
      "name": "Soil_Clay_Lime"
    },
    {
      "x": -21,
      "y": 23,
      "z": -29,
      "name": "Plant_Grass_Sharp"
    },
    {
      "x": -21,
      "y": 7,
      "z": -28,
      "name": "Soil_Clay_Green"
    },
    {
      "x": -21,
      "y": 8,
      "z": -28,
      "name": "Soil_Clay_Green"
    },
    {
      "x": -21,
      "y": 9,
      "z": -28,
      "name": "Soil_Seaweed_Block"
    },
    {
      "x": -21,
      "y": 10,
      "z": -28,
      "name": "Soil_Seaweed_Block"
    },
    {
      "x": -21,
      "y": 11,
      "z": -28,
      "name": "Soil_Seaweed_Block"
    },
    {
      "x": -21,
      "y": 12,
      "z": -28,
      "name": "Soil_Seaweed_Block"
    },
    {
      "x": -21,
      "y": 13,
      "z": -28,
      "name": "Soil_Seaweed_Block"
    },
    {
      "x": -21,
      "y": 14,
      "z": -28,
      "name": "Soil_Seaweed_Block"
    },
    {
      "x": -21,
      "y": 15,
      "z": -28,
      "name": "Soil_Seaweed_Block"
    },
    {
      "x": -21,
      "y": 16,
      "z": -28,
      "name": "Soil_Seaweed_Block"
    },
    {
      "x": -21,
      "y": 17,
      "z": -28,
      "name": "Soil_Seaweed_Block"
    },
    {
      "x": -21,
      "y": 18,
      "z": -28,
      "name": "Soil_Seaweed_Block"
    },
    {
      "x": -21,
      "y": 19,
      "z": -28,
      "name": "Soil_Seaweed_Block"
    },
    {
      "x": -21,
      "y": 20,
      "z": -28,
      "name": "Soil_Seaweed_Block"
    },
    {
      "x": -21,
      "y": 21,
      "z": -28,
      "name": "Soil_Seaweed_Block"
    },
    {
      "x": -21,
      "y": 7,
      "z": -27,
      "name": "Soil_Clay_Green"
    },
    {
      "x": -21,
      "y": 8,
      "z": -27,
      "name": "Soil_Clay_Green"
    },
    {
      "x": -21,
      "y": 9,
      "z": -27,
      "name": "Soil_Seaweed_Block"
    },
    {
      "x": -21,
      "y": 10,
      "z": -27,
      "name": "Soil_Seaweed_Block"
    },
    {
      "x": -21,
      "y": 11,
      "z": -27,
      "name": "Soil_Seaweed_Block"
    },
    {
      "x": -21,
      "y": 12,
      "z": -27,
      "name": "Soil_Seaweed_Block"
    },
    {
      "x": -21,
      "y": 13,
      "z": -27,
      "name": "Soil_Seaweed_Block"
    },
    {
      "x": -21,
      "y": 14,
      "z": -27,
      "name": "Soil_Seaweed_Block"
    },
    {
      "x": -21,
      "y": 15,
      "z": -27,
      "name": "Soil_Seaweed_Block"
    },
    {
      "x": -21,
      "y": 16,
      "z": -27,
      "name": "Soil_Seaweed_Block"
    },
    {
      "x": -21,
      "y": 17,
      "z": -27,
      "name": "Soil_Seaweed_Block"
    },
    {
      "x": -21,
      "y": 18,
      "z": -27,
      "name": "Soil_Seaweed_Block"
    },
    {
      "x": -21,
      "y": 19,
      "z": -27,
      "name": "Soil_Seaweed_Block"
    },
    {
      "x": -21,
      "y": 20,
      "z": -27,
      "name": "Soil_Seaweed_Block"
    },
    {
      "x": -21,
      "y": 21,
      "z": -27,
      "name": "Soil_Seaweed_Block"
    },
    {
      "x": -21,
      "y": 7,
      "z": -26,
      "name": "Soil_Clay_Green"
    },
    {
      "x": -21,
      "y": 8,
      "z": -26,
      "name": "Soil_Seaweed_Block"
    },
    {
      "x": -21,
      "y": 9,
      "z": -26,
      "name": "Soil_Seaweed_Block"
    },
    {
      "x": -21,
      "y": 10,
      "z": -26,
      "name": "Soil_Seaweed_Block"
    },
    {
      "x": -21,
      "y": 11,
      "z": -26,
      "name": "Soil_Seaweed_Block"
    },
    {
      "x": -21,
      "y": 12,
      "z": -26,
      "name": "Soil_Seaweed_Block"
    },
    {
      "x": -21,
      "y": 13,
      "z": -26,
      "name": "Soil_Seaweed_Block"
    },
    {
      "x": -21,
      "y": 14,
      "z": -26,
      "name": "Soil_Seaweed_Block"
    },
    {
      "x": -21,
      "y": 15,
      "z": -26,
      "name": "Soil_Seaweed_Block"
    },
    {
      "x": -21,
      "y": 16,
      "z": -26,
      "name": "Soil_Seaweed_Block"
    },
    {
      "x": -21,
      "y": 17,
      "z": -26,
      "name": "Soil_Seaweed_Block"
    },
    {
      "x": -21,
      "y": 18,
      "z": -26,
      "name": "Soil_Seaweed_Block"
    },
    {
      "x": -21,
      "y": 19,
      "z": -26,
      "name": "Soil_Seaweed_Block"
    },
    {
      "x": -21,
      "y": 20,
      "z": -26,
      "name": "Soil_Seaweed_Block"
    },
    {
      "x": -21,
      "y": 21,
      "z": -26,
      "name": "Soil_Seaweed_Block"
    },
    {
      "x": -21,
      "y": 7,
      "z": -25,
      "name": "Soil_Clay_Green"
    },
    {
      "x": -21,
      "y": 8,
      "z": -25,
      "name": "Soil_Seaweed_Block"
    },
    {
      "x": -21,
      "y": 9,
      "z": -25,
      "name": "Soil_Seaweed_Block"
    },
    {
      "x": -21,
      "y": 10,
      "z": -25,
      "name": "Soil_Seaweed_Block"
    },
    {
      "x": -21,
      "y": 11,
      "z": -25,
      "name": "Soil_Seaweed_Block"
    },
    {
      "x": -21,
      "y": 12,
      "z": -25,
      "name": "Soil_Seaweed_Block"
    },
    {
      "x": -21,
      "y": 13,
      "z": -25,
      "name": "Soil_Seaweed_Block"
    },
    {
      "x": -21,
      "y": 14,
      "z": -25,
      "name": "Soil_Seaweed_Block"
    },
    {
      "x": -21,
      "y": 15,
      "z": -25,
      "name": "Soil_Seaweed_Block"
    },
    {
      "x": -21,
      "y": 16,
      "z": -25,
      "name": "Soil_Seaweed_Block"
    },
    {
      "x": -21,
      "y": 17,
      "z": -25,
      "name": "Soil_Seaweed_Block"
    },
    {
      "x": -21,
      "y": 18,
      "z": -25,
      "name": "Soil_Seaweed_Block"
    },
    {
      "x": -21,
      "y": 19,
      "z": -25,
      "name": "Soil_Seaweed_Block"
    },
    {
      "x": -21,
      "y": 8,
      "z": -24,
      "name": "Soil_Clay_Green"
    },
    {
      "x": -21,
      "y": 9,
      "z": -24,
      "name": "Soil_Seaweed_Block"
    },
    {
      "x": -21,
      "y": 10,
      "z": -24,
      "name": "Soil_Seaweed_Block"
    },
    {
      "x": -21,
      "y": 11,
      "z": -24,
      "name": "Soil_Seaweed_Block"
    },
    {
      "x": -21,
      "y": 12,
      "z": -24,
      "name": "Soil_Seaweed_Block"
    },
    {
      "x": -21,
      "y": 13,
      "z": -24,
      "name": "Soil_Seaweed_Block"
    },
    {
      "x": -21,
      "y": 14,
      "z": -24,
      "name": "Soil_Seaweed_Block"
    },
    {
      "x": -21,
      "y": 15,
      "z": -24,
      "name": "Soil_Seaweed_Block"
    },
    {
      "x": -21,
      "y": 16,
      "z": -24,
      "name": "Soil_Seaweed_Block"
    },
    {
      "x": -21,
      "y": 17,
      "z": -24,
      "name": "Soil_Seaweed_Block"
    },
    {
      "x": -21,
      "y": 18,
      "z": -24,
      "name": "Soil_Seaweed_Block"
    },
    {
      "x": -21,
      "y": 19,
      "z": -24,
      "name": "Soil_Seaweed_Block"
    },
    {
      "x": -21,
      "y": 8,
      "z": -23,
      "name": "Soil_Clay_Green"
    },
    {
      "x": -21,
      "y": 9,
      "z": -23,
      "name": "Soil_Seaweed_Block"
    },
    {
      "x": -21,
      "y": 10,
      "z": -23,
      "name": "Soil_Seaweed_Block"
    },
    {
      "x": -21,
      "y": 11,
      "z": -23,
      "name": "Soil_Seaweed_Block"
    },
    {
      "x": -21,
      "y": 12,
      "z": -23,
      "name": "Soil_Seaweed_Block"
    },
    {
      "x": -21,
      "y": 13,
      "z": -23,
      "name": "Soil_Seaweed_Block"
    },
    {
      "x": -21,
      "y": 14,
      "z": -23,
      "name": "Soil_Seaweed_Block"
    },
    {
      "x": -21,
      "y": 15,
      "z": -23,
      "name": "Soil_Seaweed_Block"
    },
    {
      "x": -21,
      "y": 16,
      "z": -23,
      "name": "Soil_Seaweed_Block"
    },
    {
      "x": -21,
      "y": 17,
      "z": -23,
      "name": "Soil_Seaweed_Block"
    },
    {
      "x": -21,
      "y": 18,
      "z": -23,
      "name": "Soil_Seaweed_Block"
    },
    {
      "x": -21,
      "y": 8,
      "z": -22,
      "name": "Soil_Clay_Green"
    },
    {
      "x": -21,
      "y": 9,
      "z": -22,
      "name": "Soil_Seaweed_Block"
    },
    {
      "x": -21,
      "y": 10,
      "z": -22,
      "name": "Soil_Seaweed_Block"
    },
    {
      "x": -21,
      "y": 11,
      "z": -22,
      "name": "Soil_Seaweed_Block"
    },
    {
      "x": -21,
      "y": 12,
      "z": -22,
      "name": "Soil_Seaweed_Block"
    },
    {
      "x": -21,
      "y": 13,
      "z": -22,
      "name": "Soil_Seaweed_Block"
    },
    {
      "x": -21,
      "y": 14,
      "z": -22,
      "name": "Soil_Seaweed_Block"
    },
    {
      "x": -21,
      "y": 15,
      "z": -22,
      "name": "Soil_Seaweed_Block"
    },
    {
      "x": -21,
      "y": 16,
      "z": -22,
      "name": "Soil_Seaweed_Block"
    },
    {
      "x": -21,
      "y": 17,
      "z": -22,
      "name": "Soil_Seaweed_Block"
    },
    {
      "x": -21,
      "y": 18,
      "z": -22,
      "name": "Soil_Seaweed_Block"
    },
    {
      "x": -21,
      "y": 9,
      "z": -21,
      "name": "Soil_Clay_Green"
    },
    {
      "x": -21,
      "y": 10,
      "z": -21,
      "name": "Soil_Seaweed_Block"
    },
    {
      "x": -21,
      "y": 11,
      "z": -21,
      "name": "Soil_Seaweed_Block"
    },
    {
      "x": -21,
      "y": 12,
      "z": -21,
      "name": "Soil_Seaweed_Block"
    },
    {
      "x": -21,
      "y": 13,
      "z": -21,
      "name": "Soil_Seaweed_Block"
    },
    {
      "x": -21,
      "y": 14,
      "z": -21,
      "name": "Soil_Seaweed_Block"
    },
    {
      "x": -21,
      "y": 15,
      "z": -21,
      "name": "Soil_Seaweed_Block"
    },
    {
      "x": -21,
      "y": 16,
      "z": -21,
      "name": "Soil_Seaweed_Block"
    },
    {
      "x": -21,
      "y": 17,
      "z": -21,
      "name": "Soil_Seaweed_Block"
    },
    {
      "x": -21,
      "y": 10,
      "z": -20,
      "name": "Soil_Clay_Green"
    },
    {
      "x": -21,
      "y": 11,
      "z": -20,
      "name": "Soil_Seaweed_Block"
    },
    {
      "x": -21,
      "y": 12,
      "z": -20,
      "name": "Soil_Seaweed_Block"
    },
    {
      "x": -21,
      "y": 13,
      "z": -20,
      "name": "Soil_Seaweed_Block"
    },
    {
      "x": -21,
      "y": 14,
      "z": -20,
      "name": "Soil_Seaweed_Block"
    },
    {
      "x": -21,
      "y": 15,
      "z": -20,
      "name": "Soil_Seaweed_Block"
    },
    {
      "x": -21,
      "y": 16,
      "z": -20,
      "name": "Soil_Seaweed_Block"
    },
    {
      "x": -21,
      "y": 17,
      "z": -20,
      "name": "Soil_Seaweed_Block"
    },
    {
      "x": -21,
      "y": 10,
      "z": -19,
      "name": "Soil_Clay_Green"
    },
    {
      "x": -21,
      "y": 11,
      "z": -19,
      "name": "Soil_Clay_Green"
    },
    {
      "x": -21,
      "y": 12,
      "z": -19,
      "name": "Soil_Clay_Green"
    },
    {
      "x": -21,
      "y": 13,
      "z": -19,
      "name": "Soil_Clay_Green"
    },
    {
      "x": -21,
      "y": 14,
      "z": -19,
      "name": "Soil_Seaweed_Block"
    },
    {
      "x": -21,
      "y": 15,
      "z": -19,
      "name": "Soil_Seaweed_Block"
    },
    {
      "x": -21,
      "y": 16,
      "z": -19,
      "name": "Soil_Seaweed_Block"
    },
    {
      "x": -21,
      "y": 17,
      "z": -19,
      "name": "Soil_Seaweed_Block"
    },
    {
      "x": -21,
      "y": 18,
      "z": -19,
      "name": "Soil_Seaweed_Block"
    },
    {
      "x": -21,
      "y": 14,
      "z": -18,
      "name": "Soil_Seaweed_Block"
    },
    {
      "x": -21,
      "y": 10,
      "z": 25,
      "name": "Soil_Seaweed_Block"
    },
    {
      "x": -21,
      "y": 10,
      "z": 26,
      "name": "Soil_Seaweed_Block"
    },
    {
      "x": -21,
      "y": 11,
      "z": 26,
      "name": "Soil_Clay_Lime"
    },
    {
      "x": -21,
      "y": 12,
      "z": 26,
      "name": "Plant_Grass_Sharp"
    },
    {
      "x": -21,
      "y": 9,
      "z": 27,
      "name": "Soil_Clay_Green"
    },
    {
      "x": -21,
      "y": 10,
      "z": 27,
      "name": "Soil_Seaweed_Block"
    },
    {
      "x": -21,
      "y": 11,
      "z": 27,
      "name": "Soil_Clay_Lime"
    },
    {
      "x": -21,
      "y": 12,
      "z": 27,
      "name": "Plant_Grass_Sharp"
    },
    {
      "x": -21,
      "y": 9,
      "z": 28,
      "name": "Soil_Clay_Green"
    },
    {
      "x": -21,
      "y": 10,
      "z": 28,
      "name": "Soil_Clay_Green"
    },
    {
      "x": -21,
      "y": 11,
      "z": 28,
      "name": "Soil_Seaweed_Block"
    },
    {
      "x": -21,
      "y": 10,
      "z": 29,
      "name": "Soil_Clay_Green"
    },
    {
      "x": -21,
      "y": 11,
      "z": 29,
      "name": "Soil_Clay_Green"
    },
    {
      "x": -21,
      "y": 10,
      "z": 30,
      "name": "Soil_Clay_Green"
    },
    {
      "x": -21,
      "y": 11,
      "z": 30,
      "name": "Soil_Clay_Green"
    },
    {
      "x": -21,
      "y": 12,
      "z": 30,
      "name": "Soil_Seaweed_Block"
    },
    {
      "x": -21,
      "y": 13,
      "z": 30,
      "name": "Soil_Seaweed_Block"
    },
    {
      "x": -21,
      "y": 12,
      "z": 31,
      "name": "Soil_Clay_Green"
    },
    {
      "x": -21,
      "y": 13,
      "z": 31,
      "name": "Soil_Seaweed_Block"
    },
    {
      "x": -21,
      "y": 14,
      "z": 31,
      "name": "Soil_Seaweed_Block"
    },
    {
      "x": -21,
      "y": 11,
      "z": 32,
      "name": "Soil_Clay_Green"
    },
    {
      "x": -21,
      "y": 12,
      "z": 32,
      "name": "Soil_Seaweed_Block"
    },
    {
      "x": -21,
      "y": 13,
      "z": 32,
      "name": "Soil_Seaweed_Block"
    },
    {
      "x": -21,
      "y": 14,
      "z": 32,
      "name": "Soil_Seaweed_Block"
    },
    {
      "x": -21,
      "y": 15,
      "z": 32,
