{
  "version": 8,
  "blockIdVersion": 10,
  "anchorX": 0,
  "anchorY": 16,
  "anchorZ": 0,
  "blocks": [
    {
      "x": -51,
      "y": 17,
      "z": 26,
      "name": "Soil_Clay_Green"
    },
    {
      "x": -50,
      "y": 17,
      "z": 25,
      "name": "Soil_Seaweed_Block"
    },
    {
      "x": -50,
      "y": 17,
      "z": 26,
      "name": "Soil_Seaweed_Block"
    },
    {
      "x": -49,
      "y": 17,
      "z": 24,
      "name": "Soil_Clay_Lime"
    },
    {
      "x": -49,
      "y": 18,
      "z": 24,
      "name": "Plant_Grass_Sharp"
    },
    {
      "x": -49,
      "y": 17,
      "z": 25,
      "name": "Soil_Seaweed_Block"
    },
    {
      "x": -48,
      "y": 16,
      "z": 23,
      "name": "Soil_Clay_Green"
    },
    {
      "x": -48,
      "y": 16,
      "z": 24,
      "name": "Soil_Clay_Green"
    },
    {
      "x": -48,
      "y": 17,
      "z": 24,
      "name": "Soil_Clay_Lime"
    },
    {
      "x": -48,
      "y": 18,
      "z": 24,
      "name": "Plant_Grass_Sharp"
    },
    {
      "x": -48,
      "y": 17,
      "z": 25,
      "name": "Soil_Seaweed_Block"
    },
    {
      "x": -47,
      "y": 15,
      "z": 23,
      "name": "Soil_Clay_Green"
    },
    {
      "x": -47,
      "y": 16,
      "z": 23,
      "name": "Soil_Seaweed_Block"
    },
    {
      "x": -46,
      "y": 15,
      "z": 23,
      "name": "Soil_Clay_Green"
    },
    {
      "x": -46,
      "y": 16,
      "z": 23,
      "name": "Soil_Clay_Lime"
    },
    {
      "x": -46,
      "y": 17,
      "z": 23,
      "name": "Plant_Grass_Sharp"
    },
    {
      "x": -46,
      "y": 11,
      "z": 27,
      "name": "Soil_Clay_Green"
    },
    {
      "x": -46,
      "y": 12,
      "z": 27,
      "name": "Soil_Seaweed_Block"
    },
    {
      "x": -46,
      "y": 11,
      "z": 28,
      "name": "Soil_Clay_Green"
    },
    {
      "x": -45,
      "y": 14,
      "z": 22,
      "name": "Soil_Clay_Green"
    },
    {
      "x": -45,
      "y": 15,
      "z": 22,
      "name": "Soil_Seaweed_Block"
    },
    {
      "x": -45,
      "y": 15,
      "z": 23,
      "name": "Soil_Clay_Lime"
    },
    {
      "x": -45,
      "y": 16,
      "z": 23,
      "name": "Plant_Grass_Sharp"
    },
    {
      "x": -45,
      "y": 11,
      "z": 26,
      "name": "Soil_Clay_Green"
    },
    {
      "x": -45,
      "y": 12,
      "z": 26,
      "name": "Soil_Clay_Green"
    },
    {
      "x": -45,
      "y": 11,
      "z": 27,
      "name": "Soil_Clay_Green"
    },
    {
      "x": -45,
      "y": 12,
      "z": 27,
      "name": "Soil_Seaweed_Block"
    },
    {
      "x": -45,
      "y": 11,
      "z": 28,
      "name": "Soil_Clay_Green"
    },
    {
      "x": -45,
      "y": 12,
      "z": 28,
      "name": "Soil_Seaweed_Block"
    },
    {
      "x": -45,
      "y": 11,
      "z": 29,
      "name": "Soil_Clay_Green"
    },
    {
      "x": -44,
      "y": 13,
      "z": 23,
      "name": "Soil_Clay_Green"
    },
    {
      "x": -44,
      "y": 14,
      "z": 23,
      "name": "Soil_Seaweed_Block"
    },
    {
      "x": -44,
      "y": 15,
      "z": 23,
      "name": "Soil_Clay_Lime"
    },
    {
      "x": -44,
      "y": 16,
      "z": 23,
      "name": "Plant_Grass_Sharp"
    },
    {
      "x": -44,
      "y": 11,
      "z": 26,
      "name": "Soil_Clay_Green"
    },
    {
      "x": -44,
      "y": 12,
      "z": 26,
      "name": "Soil_Clay_Green"
    },
    {
      "x": -44,
      "y": 13,
      "z": 26,
      "name": "Soil_Clay_Lime"
    },
    {
      "x": -44,
      "y": 14,
      "z": 26,
      "name": "Plant_Grass_Sharp"
    },
    {
      "x": -44,
      "y": 11,
      "z": 27,
      "name": "Soil_Clay_Green"
    },
    {
      "x": -44,
      "y": 12,
      "z": 27,
      "name": "Soil_Seaweed_Block"
    },
    {
      "x": -44,
      "y": 13,
      "z": 27,
      "name": "Soil_Clay_Lime"
    },
    {
      "x": -44,
      "y": 14,
      "z": 27,
      "name": "Plant_Grass_Sharp"
    },
    {
      "x": -44,
      "y": 11,
      "z": 28,
      "name": "Soil_Clay_Green"
    },
    {
      "x": -44,
      "y": 12,
      "z": 28,
      "name": "Soil_Seaweed_Block"
    },
    {
      "x": -43,
      "y": 13,
      "z": 23,
      "name": "Soil_Clay_Green"
    },
    {
      "x": -43,
      "y": 14,
      "z": 23,
      "name": "Soil_Seaweed_Block"
    },
    {
      "x": -43,
      "y": 15,
      "z": 23,
      "name": "Soil_Clay_Lime"
    },
    {
      "x": -43,
      "y": 16,
      "z": 23,
      "name": "Plant_Grass_Sharp"
    },
    {
      "x": -43,
      "y": 13,
      "z": 24,
      "name": "Soil_Clay_Green"
    },
    {
      "x": -43,
      "y": 14,
      "z": 24,
      "name": "Soil_Clay_Lime"
    },
    {
      "x": -43,
      "y": 15,
      "z": 24,
      "name": "Plant_Grass_Sharp"
    },
    {
      "x": -43,
      "y": 12,
      "z": 25,
      "name": "Soil_Clay_Green"
    },
    {
      "x": -43,
      "y": 13,
      "z": 25,
      "name": "Soil_Clay_Green"
    },
    {
      "x": -43,
      "y": 14,
      "z": 25,
      "name": "Soil_Clay_Lime"
    },
    {
      "x": -43,
      "y": 15,
      "z": 25,
      "name": "Plant_Grass_Sharp"
    },
    {
      "x": -43,
      "y": 11,
      "z": 26,
      "name": "Soil_Clay_Green"
    },
    {
      "x": -43,
      "y": 12,
      "z": 26,
      "name": "Soil_Seaweed_Block"
    },
    {
      "x": -43,
      "y": 13,
      "z": 26,
      "name": "Soil_Seaweed_Block"
    },
    {
      "x": -43,
      "y": 14,
      "z": 26,
      "name": "Soil_Clay_Lime"
    },
    {
      "x": -43,
      "y": 15,
      "z": 26,
      "name": "Plant_Grass_Sharp"
    },
    {
      "x": -43,
      "y": 12,
      "z": 27,
      "name": "Soil_Clay_Green"
    },
    {
      "x": -43,
      "y": 13,
      "z": 27,
      "name": "Soil_Clay_Lime"
    },
    {
      "x": -43,
      "y": 14,
      "z": 27,
      "name": "Plant_Grass_Sharp"
    },
    {
      "x": -42,
      "y": 14,
      "z": 21,
      "name": "Soil_Seaweed_Block"
    },
    {
      "x": -42,
      "y": 14,
      "z": 22,
      "name": "Soil_Seaweed_Block"
    },
    {
      "x": -42,
      "y": 13,
      "z": 23,
      "name": "Soil_Clay_Green"
    },
    {
      "x": -42,
      "y": 14,
      "z": 23,
      "name": "Soil_Seaweed_Block"
    },
    {
      "x": -42,
      "y": 15,
      "z": 23,
      "name": "Soil_Clay_Lime"
    },
    {
      "x": -42,
      "y": 16,
      "z": 23,
      "name": "Plant_Grass_Sharp"
    },
    {
      "x": -42,
      "y": 12,
      "z": 24,
      "name": "Soil_Clay_Green"
    },
    {
      "x": -42,
      "y": 13,
      "z": 24,
      "name": "Soil_Seaweed_Block"
    },
    {
      "x": -42,
      "y": 14,
      "z": 24,
      "name": "Soil_Clay_Lime"
    },
    {
      "x": -42,
      "y": 15,
      "z": 24,
      "name": "Plant_Grass_Sharp"
    },
    {
      "x": -42,
      "y": 12,
      "z": 25,
      "name": "Soil_Clay_Green"
    },
    {
      "x": -42,
      "y": 13,
      "z": 25,
      "name": "Soil_Seaweed_Block"
    },
    {
      "x": -42,
      "y": 14,
      "z": 25,
      "name": "Soil_Clay_Lime"
    },
    {
      "x": -42,
      "y": 15,
      "z": 25,
      "name": "Plant_Grass_Sharp"
    },
    {
      "x": -42,
      "y": 12,
      "z": 26,
      "name": "Soil_Clay_Green"
    },
    {
      "x": -42,
      "y": 13,
      "z": 26,
      "name": "Soil_Seaweed_Block"
    },
    {
      "x": -42,
      "y": 14,
      "z": 26,
      "name": "Soil_Clay_Lime"
    },
    {
      "x": -42,
      "y": 15,
      "z": 26,
      "name": "Plant_Grass_Sharp"
    },
    {
      "x": -41,
      "y": 13,
      "z": 21,
      "name": "Soil_Clay_Green"
    },
    {
      "x": -41,
      "y": 14,
      "z": 21,
      "name": "Soil_Clay_Green"
    },
    {
      "x": -41,
      "y": 15,
      "z": 21,
      "name": "Soil_Clay_Lime"
    },
    {
      "x": -41,
      "y": 16,
      "z": 21,
      "name": "Plant_Grass_Sharp"
    },
    {
      "x": -41,
      "y": 12,
      "z": 22,
      "name": "Soil_Clay_Green"
    },
    {
      "x": -41,
      "y": 13,
      "z": 22,
      "name": "Soil_Clay_Green"
    },
    {
      "x": -41,
      "y": 14,
      "z": 22,
      "name": "Soil_Seaweed_Block"
    },
    {
      "x": -41,
      "y": 15,
      "z": 22,
      "name": "Soil_Clay_Lime"
    },
    {
      "x": -41,
      "y": 16,
      "z": 22,
      "name": "Plant_Grass_Sharp"
    },
    {
      "x": -41,
      "y": 12,
      "z": 23,
      "name": "Soil_Clay_Green"
    },
    {
      "x": -41,
      "y": 13,
      "z": 23,
      "name": "Soil_Seaweed_Block"
    },
    {
      "x": -41,
      "y": 14,
      "z": 23,
      "name": "Soil_Seaweed_Block"
    },
    {
      "x": -41,
      "y": 15,
      "z": 23,
      "name": "Soil_Clay_Lime"
    },
    {
      "x": -41,
      "y": 16,
      "z": 23,
      "name": "Plant_Grass_Sharp"
    },
    {
      "x": -41,
      "y": 12,
      "z": 24,
      "name": "Soil_Clay_Green"
    },
    {
      "x": -41,
      "y": 13,
      "z": 24,
      "name": "Soil_Seaweed_Block"
    },
    {
      "x": -41,
      "y": 14,
      "z": 24,
      "name": "Soil_Clay_Lime"
    },
    {
      "x": -41,
      "y": 15,
      "z": 24,
      "name": "Plant_Grass_Sharp"
    },
    {
      "x": -41,
      "y": 13,
      "z": 25,
      "name": "Soil_Clay_Green"
    },
    {
      "x": -41,
      "y": 14,
      "z": 25,
      "name": "Soil_Seaweed_Block"
    },
    {
      "x": -41,
      "y": 19,
      "z": 30,
      "name": "Soil_Clay_Green"
    },
    {
      "x": -41,
      "y": 20,
      "z": 30,
      "name": "Soil_Clay_Green"
    },
    {
      "x": -40,
      "y": 14,
      "z": 20,
      "name": "Soil_Clay_Green"
    },
    {
      "x": -40,
      "y": 15,
      "z": 20,
      "name": "Soil_Seaweed_Block"
    },
    {
      "x": -40,
      "y": 14,
      "z": 21,
      "name": "Soil_Clay_Green"
    },
    {
      "x": -40,
      "y": 15,
      "z": 21,
      "name": "Soil_Clay_Lime"
    },
    {
      "x": -40,
      "y": 16,
      "z": 21,
      "name": "Plant_Grass_Sharp"
    },
    {
      "x": -40,
      "y": 13,
      "z": 22,
      "name": "Soil_Clay_Green"
    },
    {
      "x": -40,
      "y": 14,
      "z": 22,
      "name": "Soil_Seaweed_Block"
    },
    {
      "x": -40,
      "y": 15,
      "z": 22,
      "name": "Soil_Clay_Lime"
    },
    {
      "x": -40,
      "y": 16,
      "z": 22,
      "name": "Plant_Grass_Sharp"
    },
    {
      "x": -40,
      "y": 12,
      "z": 23,
      "name": "Soil_Clay_Green"
    },
    {
      "x": -40,
      "y": 13,
      "z": 23,
      "name": "Soil_Clay_Green"
    },
    {
      "x": -40,
      "y": 14,
      "z": 23,
      "name": "Soil_Seaweed_Block"
    },
    {
      "x": -40,
      "y": 15,
      "z": 23,
      "name": "Soil_Clay_Lime"
    },
    {
      "x": -40,
      "y": 16,
      "z": 23,
      "name": "Plant_Grass_Sharp"
    },
    {
      "x": -40,
      "y": 13,
      "z": 24,
      "name": "Soil_Clay_Green"
    },
    {
      "x": -40,
      "y": 14,
      "z": 24,
      "name": "Soil_Seaweed_Block"
    },
    {
      "x": -40,
      "y": 13,
      "z": 25,
      "name": "Soil_Clay_Green"
    },
    {
      "x": -40,
      "y": 14,
      "z": 25,
      "name": "Soil_Seaweed_Block"
    },
    {
      "x": -40,
      "y": 22,
      "z": 28,
      "name": "Soil_Seaweed_Block"
    },
    {
      "x": -40,
      "y": 20,
      "z": 29,
      "name": "Soil_Clay_Green"
    },
    {
      "x": -40,
      "y": 21,
      "z": 29,
      "name": "Soil_Clay_Green"
    },
    {
      "x": -40,
      "y": 22,
      "z": 29,
      "name": "Soil_Clay_Lime"
    },
    {
      "x": -40,
      "y": 23,
      "z": 29,
      "name": "Plant_Grass_Sharp"
    },
    {
      "x": -40,
      "y": 20,
      "z": 30,
      "name": "Soil_Clay_Green"
    },
    {
      "x": -40,
      "y": 21,
      "z": 30,
      "name": "Soil_Clay_Green"
    },
    {
      "x": -39,
      "y": 14,
      "z": 20,
      "name": "Soil_Clay_Green"
    },
    {
      "x": -39,
      "y": 15,
      "z": 20,
      "name": "Soil_Seaweed_Block"
    },
    {
      "x": -39,
      "y": 14,
      "z": 21,
      "name": "Soil_Clay_Green"
    },
    {
      "x": -39,
      "y": 15,
      "z": 21,
      "name": "Soil_Clay_Lime"
    },
    {
      "x": -39,
      "y": 16,
      "z": 21,
      "name": "Plant_Grass_Sharp"
    },
    {
      "x": -39,
      "y": 14,
      "z": 22,
      "name": "Soil_Seaweed_Block"
    },
    {
      "x": -39,
      "y": 15,
      "z": 22,
      "name": "Soil_Clay_Lime"
    },
    {
      "x": -39,
      "y": 16,
      "z": 22,
      "name": "Plant_Grass_Sharp"
    },
    {
      "x": -39,
      "y": 14,
      "z": 23,
      "name": "Soil_Seaweed_Block"
    },
    {
      "x": -39,
      "y": 15,
      "z": 23,
      "name": "Soil_Clay_Lime"
    },
    {
      "x": -39,
      "y": 16,
      "z": 23,
      "name": "Plant_Grass_Sharp"
    },
    {
      "x": -39,
      "y": 22,
      "z": 27,
      "name": "Soil_Clay_Green"
    },
    {
      "x": -39,
      "y": 11,
      "z": 28,
      "name": "Soil_Seaweed_Block"
    },
    {
      "x": -39,
      "y": 22,
      "z": 28,
      "name": "Soil_Clay_Lime"
    },
    {
      "x": -39,
      "y": 23,
      "z": 28,
      "name": "Plant_Grass_Sharp"
    },
    {
      "x": -39,
      "y": 22,
      "z": 29,
      "name": "Soil_Clay_Lime"
    },
    {
      "x": -39,
      "y": 23,
      "z": 29,
      "name": "Plant_Grass_Sharp"
    },
    {
      "x": -38,
      "y": 14,
      "z": 20,
      "name": "Soil_Clay_Green"
    },
    {
      "x": -38,
      "y": 15,
      "z": 20,
      "name": "Soil_Clay_Lime"
    },
    {
      "x": -38,
      "y": 16,
      "z": 20,
      "name": "Plant_Grass_Sharp"
    },
    {
      "x": -38,
      "y": 14,
      "z": 21,
      "name": "Soil_Clay_Green"
    },
    {
      "x": -38,
      "y": 15,
      "z": 21,
      "name": "Soil_Clay_Lime"
    },
    {
      "x": -38,
      "y": 16,
      "z": 21,
      "name": "Plant_Grass_Sharp"
    },
    {
      "x": -38,
      "y": 14,
      "z": 22,
      "name": "Soil_Clay_Green"
    },
    {
      "x": -38,
      "y": 15,
      "z": 22,
      "name": "Soil_Clay_Lime"
    },
    {
      "x": -38,
      "y": 16,
      "z": 22,
      "name": "Plant_Grass_Sharp"
    },
    {
      "x": -38,
      "y": 11,
      "z": 26,
      "name": "Soil_Clay_Green"
    },
    {
      "x": -38,
      "y": 23,
      "z": 26,
      "name": "Soil_Seaweed_Block"
    },
    {
      "x": -38,
      "y": 11,
      "z": 27,
      "name": "Soil_Clay_Green"
    },
    {
      "x": -38,
      "y": 23,
      "z": 27,
      "name": "Soil_Clay_Lime"
    },
    {
      "x": -38,
      "y": 24,
      "z": 27,
      "name": "Plant_Grass_Sharp"
    },
    {
      "x": -38,
      "y": 11,
      "z": 28,
      "name": "Soil_Clay_Green"
    },
    {
      "x": -38,
      "y": 22,
      "z": 28,
      "name": "Soil_Clay_Green"
    },
    {
      "x": -38,
      "y": 22,
      "z": 29,
      "name": "Soil_Seaweed_Block"
    },
    {
      "x": -37,
      "y": 14,
      "z": 19,
      "name": "Soil_Clay_Green"
    },
    {
      "x": -37,
      "y": 15,
      "z": 19,
      "name": "Soil_Seaweed_Block"
    },
    {
      "x": -37,
      "y": 14,
      "z": 20,
      "name": "Soil_Clay_Green"
    },
    {
      "x": -37,
      "y": 15,
      "z": 20,
      "name": "Soil_Clay_Lime"
    },
    {
      "x": -37,
      "y": 16,
      "z": 20,
      "name": "Plant_Grass_Sharp"
    },
    {
      "x": -37,
      "y": 14,
      "z": 21,
      "name": "Soil_Clay_Green"
    },
    {
      "x": -37,
      "y": 15,
      "z": 21,
      "name": "Soil_Clay_Lime"
    },
    {
      "x": -37,
      "y": 16,
      "z": 21,
      "name": "Plant_Grass_Sharp"
    },
    {
      "x": -37,
      "y": 12,
      "z": 24,
      "name": "Soil_Clay_Green"
    },
    {
      "x": -37,
      "y": 11,
      "z": 25,
      "name": "Soil_Clay_Green"
    },
    {
      "x": -37,
      "y": 12,
      "z": 25,
      "name": "Soil_Seaweed_Block"
    },
    {
      "x": -37,
      "y": 23,
      "z": 25,
      "name": "Soil_Clay_Green"
    },
    {
      "x": -37,
      "y": 11,
      "z": 26,
      "name": "Soil_Clay_Green"
    },
    {
      "x": -37,
      "y": 23,
      "z": 26,
      "name": "Soil_Clay_Green"
    },
    {
      "x": -37,
      "y": 10,
      "z": 27,
      "name": "Soil_Clay_Green"
    },
    {
      "x": -37,
      "y": 11,
      "z": 27,
      "name": "Soil_Clay_Green"
    },
    {
      "x": -37,
      "y": 23,
      "z": 27,
      "name": "Soil_Clay_Green"
    },
    {
      "x": -36,
      "y": 14,
      "z": 19,
      "name": "Soil_Clay_Green"
    },
    {
      "x": -36,
      "y": 15,
      "z": 19,
      "name": "Soil_Seaweed_Block"
    },
    {
      "x": -36,
      "y": 14,
      "z": 20,
      "name": "Soil_Clay_Green"
    },
    {
      "x": -36,
      "y": 15,
      "z": 20,
      "name": "Soil_Clay_Lime"
    },
    {
      "x": -36,
      "y": 16,
      "z": 20,
      "name": "Plant_Grass_Sharp"
    },
    {
      "x": -36,
      "y": 14,
      "z": 21,
      "name": "Soil_Clay_Green"
    },
    {
      "x": -36,
      "y": 15,
      "z": 21,
      "name": "Soil_Clay_Lime"
    },
    {
      "x": -36,
      "y": 16,
      "z": 21,
      "name": "Plant_Grass_Sharp"
    },
    {
      "x": -36,
      "y": 14,
      "z": 22,
      "name": "Soil_Seaweed_Block"
    },
    {
      "x": -36,
      "y": 12,
      "z": 23,
      "name": "Soil_Clay_Green"
    },
    {
      "x": -36,
      "y": 12,
      "z": 24,
      "name": "Soil_Clay_Green"
    },
    {
      "x": -36,
      "y": 12,
      "z": 25,
      "name": "Soil_Clay_Lime"
    },
    {
      "x": -36,
      "y": 13,
      "z": 25,
      "name": "Plant_Grass_Sharp"
    },
    {
      "x": -36,
      "y": 11,
      "z": 26,
      "name": "Soil_Clay_Green"
    },
    {
      "x": -36,
      "y": 12,
      "z": 26,
      "name": "Soil_Clay_Lime"
    },
    {
      "x": -36,
      "y": 13,
      "z": 26,
      "name": "Plant_Grass_Sharp"
    },
    {
      "x": -36,
      "y": 23,
      "z": 26,
      "name": "Soil_Clay_Green"
    },
    {
      "x": -36,
      "y": 24,
      "z": 26,
      "name": "Soil_Clay_Lime"
    },
    {
      "x": -36,
      "y": 25,
      "z": 26,
      "name": "Plant_Grass_Sharp"
    },
    {
      "x": -36,
      "y": 23,
      "z": 27,
      "name": "Soil_Clay_Green"
    },
    {
      "x": -36,
      "y": 24,
      "z": 27,
      "name": "Soil_Seaweed_Block"
    },
    {
      "x": -36,
      "y": 13,
      "z": 31,
      "name": "Soil_Clay_Green"
    },
    {
      "x": -36,
      "y": 13,
      "z": 32,
      "name": "Soil_Clay_Green"
    },
    {
      "x": -36,
      "y": 14,
      "z": 32,
      "name": "Soil_Clay_Lime"
    },
    {
      "x": -36,
      "y": 15,
      "z": 32,
      "name": "Plant_Grass_Sharp"
    },
    {
      "x": -36,
      "y": 26,
      "z": 32,
      "name": "Soil_Clay_Green"
    },
    {
      "x": -36,
      "y": 27,
      "z": 32,
      "name": "Soil_Clay_Green"
    },
    {
      "x": -36,
      "y": 13,
      "z": 33,
      "name": "Soil_Clay_Green"
    },
    {
      "x": -36,
      "y": 14,
      "z": 33,
      "name": "Soil_Seaweed_Block"
    },
    {
      "x": -36,
      "y": 16,
      "z": 36,
      "name": "Soil_Clay_Green"
    },
    {
      "x": -35,
      "y": 14,
      "z": 19,
      "name": "Soil_Clay_Green"
    },
    {
      "x": -35,
      "y": 15,
      "z": 19,
      "name": "Soil_Clay_Lime"
    },
    {
      "x": -35,
      "y": 16,
      "z": 19,
      "name": "Plant_Grass_Sharp"
    },
    {
      "x": -35,
      "y": 14,
      "z": 20,
      "name": "Soil_Clay_Green"
    },
    {
      "x": -35,
      "y": 15,
      "z": 20,
      "name": "Soil_Clay_Lime"
    },
    {
      "x": -35,
      "y": 16,
      "z": 20,
      "name": "Plant_Grass_Sharp"
    },
    {
      "x": -35,
      "y": 13,
      "z": 21,
      "name": "Soil_Clay_Green"
    },
    {
      "x": -35,
      "y": 14,
      "z": 21,
      "name": "Soil_Seaweed_Block"
    },
    {
      "x": -35,
      "y": 15,
      "z": 21,
      "name": "Soil_Clay_Lime"
    },
    {
      "x": -35,
      "y": 16,
      "z": 21,
      "name": "Plant_Grass_Sharp"
    },
    {
      "x": -35,
      "y": 13,
      "z": 22,
      "name": "Soil_Clay_Green"
    },
    {
      "x": -35,
      "y": 14,
      "z": 22,
      "name": "Soil_Seaweed_Block"
    },
    {
      "x": -35,
      "y": 12,
      "z": 23,
      "name": "Soil_Clay_Green"
    },
    {
      "x": -35,
      "y": 13,
      "z": 23,
      "name": "Soil_Clay_Green"
    },
    {
      "x": -35,
      "y": 12,
      "z": 24,
      "name": "Soil_Clay_Green"
    },
    {
      "x": -35,
      "y": 12,
      "z": 25,
      "name": "Soil_Seaweed_Block"
    },
    {
      "x": -35,
      "y": 24,
      "z": 25,
      "name": "Soil_Clay_Green"
    },
    {
      "x": -35,
      "y": 25,
      "z": 25,
      "name": "Soil_Clay_Lime"
    },
    {
      "x": -35,
      "y": 26,
      "z": 25,
      "name": "Plant_Grass_Sharp"
    },
    {
      "x": -35,
      "y": 23,
      "z": 26,
      "name": "Soil_Clay_Green"
    },
    {
      "x": -35,
      "y": 24,
      "z": 26,
      "name": "Soil_Clay_Green"
    },
    {
      "x": -35,
      "y": 25,
      "z": 26,
      "name": "Soil_Clay_Lime"
    },
    {
      "x": -35,
      "y": 26,
      "z": 26,
      "name": "Plant_Grass_Sharp"
    },
    {
      "x": -35,
      "y": 23,
      "z": 27,
      "name": "Soil_Clay_Green"
    },
    {
      "x": -35,
      "y": 24,
      "z": 27,
      "name": "Soil_Clay_Green"
    },
    {
      "x": -35,
      "y": 25,
      "z": 27,
      "name": "Soil_Clay_Lime"
    },
    {
      "x": -35,
      "y": 26,
      "z": 27,
      "name": "Plant_Grass_Sharp"
    },
    {
      "x": -35,
      "y": 28,
      "z": 29,
      "name": "Soil_Clay_Green"
    },
    {
      "x": -35,
      "y": 27,
      "z": 30,
      "name": "Soil_Clay_Green"
    },
    {
      "x": -35,
      "y": 28,
      "z": 30,
      "name": "Soil_Clay_Green"
    },
    {
      "x": -35,
      "y": 13,
      "z": 31,
      "name": "Soil_Seaweed_Block"
    },
    {
      "x": -35,
      "y": 27,
      "z": 31,
      "name": "Soil_Clay_Green"
    },
    {
      "x": -35,
      "y": 28,
      "z": 31,
      "name": "Soil_Seaweed_Block"
    },
    {
      "x": -35,
      "y": 13,
      "z": 32,
      "name": "Soil_Seaweed_Block"
    },
    {
      "x": -35,
      "y": 13,
      "z": 33,
      "name": "Soil_Seaweed_Block"
    },
    {
      "x": -35,
      "y": 16,
      "z": 36,
      "name": "Soil_Clay_Green"
    },
    {
      "x": -34,
      "y": 14,
      "z": 19,
      "name": "Soil_Clay_Green"
    },
    {
      "x": -34,
      "y": 15,
      "z": 19,
      "name": "Soil_Clay_Lime"
    },
    {
      "x": -34,
      "y": 16,
      "z": 19,
      "name": "Plant_Grass_Sharp"
    },
    {
      "x": -34,
      "y": 13,
      "z": 20,
      "name": "Soil_Clay_Green"
    },
    {
      "x": -34,
      "y": 14,
      "z": 20,
      "name": "Soil_Seaweed_Block"
    },
    {
      "x": -34,
      "y": 15,
      "z": 20,
      "name": "Soil_Clay_Lime"
    },
    {
      "x": -34,
      "y": 16,
      "z": 20,
      "name": "Plant_Grass_Sharp"
    },
    {
      "x": -34,
      "y": 13,
      "z": 21,
      "name": "Soil_Clay_Green"
    },
    {
      "x": -34,
      "y": 14,
      "z": 21,
      "name": "Soil_Seaweed_Block"
    },
    {
      "x": -34,
      "y": 13,
      "z": 22,
      "name": "Soil_Clay_Green"
    },
    {
      "x": -34,
      "y": 14,
      "z": 22,
      "name": "Soil_Seaweed_Block"
    },
    {
      "x": -34,
      "y": 13,
      "z": 23,
      "name": "Soil_Clay_Green"
    },
    {
      "x": -34,
      "y": 24,
      "z": 25,
      "name": "Soil_Clay_Green"
    },
    {
      "x": -34,
      "y": 25,
      "z": 25,
      "name": "Soil_Seaweed_Block"
    },
    {
      "x": -34,
      "y": 28,
      "z": 28,
      "name": "Soil_Clay_Green"
    },
    {
      "x": -34,
      "y": 29,
      "z": 28,
      "name": "Soil_Seaweed_Block"
    },
    {
      "x": -34,
      "y": 28,
      "z": 29,
      "name": "Soil_Clay_Green"
    },
    {
      "x": -34,
      "y": 12,
      "z": 30,
      "name": "Soil_Seaweed_Block"
    },
    {
      "x": -34,
      "y": 13,
      "z": 30,
      "name": "Soil_Seaweed_Block"
    },
    {
      "x": -34,
      "y": 28,
      "z": 30,
      "name": "Soil_Clay_Green"
    },
    {
      "x": -34,
      "y": 13,
      "z": 31,
      "name": "Soil_Seaweed_Block"
    },
    {
      "x": -34,
      "y": 16,
      "z": 36,
      "name": "Soil_Clay_Green"
    },
    {
      "x": -34,
      "y": 17,
      "z": 36,
      "name": "Soil_Seaweed_Block"
    },
    {
      "x": -34,
      "y": 24,
      "z": 36,
      "name": "Soil_Clay_Green"
    },
    {
      "x": -34,
      "y": 24,
      "z": 37,
      "name": "Soil_Clay_Green"
    },
    {
      "x": -33,
      "y": 13,
      "z": 18,
      "name": "Soil_Clay_Green"
    },
    {
      "x": -33,
      "y": 14,
      "z": 18,
      "name": "Soil_Seaweed_Block"
    },
    {
      "x": -33,
      "y": 15,
      "z": 18,
      "name": "Soil_Seaweed_Block"
    },
    {
      "x": -33,
      "y": 13,
      "z": 19,
      "name": "Soil_Clay_Green"
    },
    {
      "x": -33,
      "y": 14,
      "z": 19,
      "name": "Soil_Seaweed_Block"
    },
    {
      "x": -33,
      "y": 15,
      "z": 19,
      "name": "Soil_Clay_Lime"
    },
    {
      "x": -33,
      "y": 16,
      "z": 19,
      "name": "Plant_Grass_Sharp"
    },
    {
      "x": -33,
      "y": 13,
      "z": 20,
      "name": "Soil_Clay_Green"
    },
    {
      "x": -33,
      "y": 14,
      "z": 20,
      "name": "Soil_Seaweed_Block"
    },
    {
      "x": -33,
      "y": 15,
      "z": 20,
      "name": "Soil_Clay_Lime"
    },
    {
      "x": -33,
      "y": 16,
      "z": 20,
      "name": "Plant_Grass_Sharp"
    },
    {
      "x": -33,
      "y": 13,
      "z": 21,
      "name": "Soil_Clay_Green"
    },
    {
      "x": -33,
      "y": 14,
      "z": 21,
      "name": "Soil_Seaweed_Block"
    },
    {
      "x": -33,
      "y": 13,
      "z": 22,
      "name": "Soil_Clay_Green"
    },
    {
      "x": -33,
      "y": 24,
      "z": 25,
      "name": "Soil_Clay_Green"
    },
    {
      "x": -33,
      "y": 25,
      "z": 25,
      "name": "Soil_Seaweed_Block"
    },
    {
      "x": -33,
      "y": 24,
      "z": 26,
      "name": "Soil_Clay_Green"
    },
    {
      "x": -33,
      "y": 25,
      "z": 26,
      "name": "Soil_Clay_Lime"
    },
    {
      "x": -33,
      "y": 26,
      "z": 26,
      "name": "Plant_Grass_Sharp"
    },
    {
      "x": -33,
      "y": 25,
      "z": 27,
      "name": "Soil_Seaweed_Block"
    },
    {
      "x": -33,
      "y": 29,
      "z": 27,
      "name": "Soil_Seaweed_Block"
    },
    {
      "x": -33,
      "y": 28,
      "z": 28,
      "name": "Soil_Clay_Green"
    },
    {
      "x": -33,
      "y": 29,
      "z": 28,
      "name": "Soil_Clay_Lime"
    },
    {
      "x": -33,
      "y": 30,
      "z": 28,
      "name": "Plant_Grass_Sharp"
    },
    {
      "x": -33,
      "y": 28,
      "z": 29,
      "name": "Soil_Clay_Green"
    },
    {
      "x": -33,
      "y": 29,
      "z": 29,
      "name": "Soil_Clay_Lime"
    },
    {
      "x": -33,
      "y": 30,
      "z": 29,
      "name": "Soil_Clay_Lime"
    },
    {
      "x": -33,
      "y": 31,
      "z": 29,
      "name": "Plant_Grass_Sharp"
    },
    {
      "x": -33,
      "y": 10,
      "z": 31,
      "name": "Soil_Seaweed_Block"
    },
    {
      "x": -33,
      "y": 11,
      "z": 31,
      "name": "Soil_Seaweed_Block"
    },
    {
      "x": -33,
      "y": 12,
      "z": 31,
      "name": "Soil_Clay_Lime"
    },
    {
      "x": -33,
      "y": 13,
      "z": 31,
      "name": "Plant_Grass_Sharp"
    },
    {
      "x": -33,
      "y": 10,
      "z": 32,
      "name": "Soil_Seaweed_Block"
    },
    {
      "x": -33,
      "y": 17,
      "z": 34,
      "name": "Soil_Clay_Green"
    },
    {
      "x": -33,
      "y": 16,
      "z": 35,
      "name": "Soil_Clay_Green"
    },
    {
      "x": -33,
      "y": 17,
      "z": 35,
      "name": "Soil_Clay_Green"
    },
    {
      "x": -33,
      "y": 7,
      "z": 36,
      "name": "Soil_Clay_Green"
    },
    {
      "x": -33,
      "y": 8,
      "z": 36,
      "name": "Soil_Seaweed_Block"
    },
    {
      "x": -33,
      "y": 24,
      "z": 36,
      "name": "Soil_Clay_Green"
    },
    {
      "x": -33,
      "y": 24,
      "z": 37,
      "name": "Soil_Clay_Green"
    },
    {
      "x": -33,
      "y": 14,
      "z": 44,
      "name": "Soil_Clay_Green"
    },
    {
      "x": -32,
      "y": 13,
      "z": 19,
      "name": "Soil_Clay_Green"
    },
    {
      "x": -32,
      "y": 14,
      "z": 19,
      "name": "Soil_Seaweed_Block"
    },
    {
      "x": -32,
      "y": 15,
      "z": 19,
      "name": "Soil_Clay_Lime"
    },
    {
      "x": -32,
      "y": 16,
      "z": 19,
      "name": "Plant_Grass_Sharp"
    },
    {
      "x": -32,
      "y": 12,
      "z": 20,
      "name": "Soil_Clay_Green"
    },
    {
      "x": -32,
      "y": 13,
      "z": 20,
      "name": "Soil_Seaweed_Block"
    },
    {
      "x": -32,
      "y": 14,
      "z": 20,
      "name": "Soil_Seaweed_Block"
    },
    {
      "x": -32,
      "y": 15,
      "z": 20,
      "name": "Soil_Clay_Lime"
    },
    {
      "x": -32,
      "y": 16,
      "z": 20,
      "name": "Plant_Grass_Sharp"
    },
    {
      "x": -32,
      "y": 12,
      "z": 21,
      "name": "Soil_Clay_Green"
    },
    {
      "x": -32,
      "y": 13,
      "z": 21,
      "name": "Soil_Seaweed_Block"
    },
    {
      "x": -32,
      "y": 14,
      "z": 21,
      "name": "Soil_Seaweed_Block"
    },
    {
      "x": -32,
      "y": 15,
      "z": 21,
      "name": "Soil_Clay_Lime"
    },
    {
      "x": -32,
      "y": 16,
      "z": 21,
      "name": "Plant_Grass_Sharp"
    },
    {
      "x": -32,
      "y": 13,
      "z": 22,
      "name": "Soil_Clay_Green"
    },
    {
      "x": -32,
      "y": 14,
      "z": 22,
      "name": "Soil_Seaweed_Block"
    },
    {
      "x": -32,
      "y": 25,
      "z": 25,
      "name": "Soil_Seaweed_Block"
    },
    {
      "x": -32,
      "y": 26,
      "z": 25,
      "name": "Soil_Seaweed_Block"
    },
    {
      "x": -32,
      "y": 14,
      "z": 26,
      "name": "Soil_Seaweed_Block"
    },
    {
      "x": -32,
      "y": 24,
      "z": 26,
      "name": "Soil_Clay_Green"
    },
    {
      "x": -32,
      "y": 25,
      "z": 26,
      "name": "Soil_Seaweed_Block"
    },
    {
      "x": -32,
      "y": 26,
      "z": 26,
      "name": "Soil_Seaweed_Block"
    },
    {
      "x": -32,
      "y": 13,
      "z": 27,
      "name": "Soil_Clay_Green"
    },
    {
      "x": -32,
      "y": 14,
      "z": 27,
      "name": "Soil_Seaweed_Block"
    },
    {
      "x": -32,
      "y": 24,
      "z": 27,
      "name": "Soil_Clay_Green"
    },
    {
      "x": -32,
      "y": 25,
      "z": 27,
      "name": "Soil_Seaweed_Block"
    },
    {
      "x": -32,
      "y": 26,
      "z": 27,
      "name": "Soil_Seaweed_Block"
    },
    {
      "x": -32,
      "y": 29,
      "z": 27,
      "name": "Soil_Clay_Lime"
    },
    {
      "x": -32,
      "y": 30,
      "z": 27,
      "name": "Plant_Grass_Sharp"
    },
    {
      "x": -32,
      "y": 28,
      "z": 28,
      "name": "Soil_Seaweed_Block"
    },
    {
      "x": -32,
      "y": 29,
      "z": 28,
      "name": "Soil_Seaweed_Block"
    },
    {
      "x": -32,
      "y": 30,
      "z": 28,
      "name": "Soil_Clay_Lime"
    },
    {
      "x": -32,
      "y": 31,
      "z": 28,
      "name": "Plant_Grass_Sharp"
    },
    {
      "x": -32,
      "y": 29,
      "z": 29,
      "name": "Soil_Seaweed_Block"
    },
    {
      "x": -32,
      "y": 9,
      "z": 31,
      "name": "Soil_Clay_Green"
    },
    {
      "x": -32,
      "y": 10,
      "z": 31,
      "name": "Soil_Seaweed_Block"
    },
    {
      "x": -32,
      "y": 11,
      "z": 31,
      "name": "Soil_Clay_Lime"
    },
    {
      "x": -32,
      "y": 12,
      "z": 31,
      "name": "Plant_Grass_Sharp"
    },
    {
      "x": -32,
      "y": 9,
      "z": 32,
      "name": "Soil_Seaweed_Block"
    },
    {
      "x": -32,
      "y": 10,
      "z": 32,
      "name": "Soil_Clay_Lime"
    },
    {
      "x": -32,
      "y": 11,
      "z": 32,
      "name": "Plant_Grass_Sharp"
    },
    {
      "x": -32,
      "y": 8,
      "z": 33,
      "name": "Soil_Clay_Green"
    },
    {
      "x": -32,
      "y": 9,
      "z": 33,
      "name": "Soil_Seaweed_Block"
    },
    {
      "x": -32,
      "y": 18,
      "z": 33,
      "name": "Soil_Seaweed_Block"
    },
    {
      "x": -32,
      "y": 7,
      "z": 34,
      "name": "Soil_Clay_Green"
    },
    {
      "x": -32,
      "y": 8,
      "z": 34,
      "name": "Soil_Clay_Green"
    },
    {
      "x": -32,
      "y": 17,
      "z": 34,
      "name": "Soil_Clay_Green"
    },
    {
      "x": -32,
      "y": 18,
      "z": 34,
      "name": "Soil_Clay_Lime"
    },
    {
      "x": -32,
      "y": 19,
      "z": 34,
      "name": "Plant_Grass_Sharp"
    },
    {
      "x": -32,
      "y": 7,
      "z": 35,
      "name": "Soil_Clay_Green"
    },
    {
      "x": -32,
      "y": 8,
      "z": 35,
      "name": "Soil_Seaweed_Block"
    },
    {
      "x": -32,
      "y": 17,
      "z": 35,
      "name": "Soil_Clay_Green"
    },
    {
      "x": -32,
      "y": 24,
      "z": 36,
      "name": "Soil_Clay_Green"
    },
    {
      "x": -32,
      "y": 24,
      "z": 37,
      "name": "Soil_Clay_Green"
    },
    {
      "x": -32,
      "y": 14,
      "z": 44,
      "name": "Soil_Clay_Green"
    },
    {
      "x": -31,
      "y": 13,
      "z": 18,
      "name": "Soil_Clay_Green"
    },
    {
      "x": -31,
      "y": 12,
      "z": 19,
      "name": "Soil_Clay_Green"
    },
    {
      "x": -31,
      "y": 13,
      "z": 19,
      "name": "Soil_Seaweed_Block"
    },
    {
      "x": -31,
      "y": 14,
      "z": 19,
      "name": "Soil_Seaweed_Block"
    },
    {
      "x": -31,
      "y": 12,
      "z": 20,
      "name": "Soil_Clay_Green"
    },
    {
      "x": -31,
      "y": 13,
      "z": 20,
      "name": "Soil_Seaweed_Block"
    },
    {
      "x": -31,
      "y": 14,
      "z": 20,
      "name": "Soil_Seaweed_Block"
    },
    {
      "x": -31,
      "y": 15,
      "z": 20,
      "name": "Soil_Clay_Lime"
    },
    {
      "x": -31,
      "y": 16,
      "z": 20,
      "name": "Plant_Grass_Sharp"
    },
    {
      "x": -31,
      "y": 12,
      "z": 21,
      "name": "Soil_Clay_Green"
    },
    {
      "x": -31,
      "y": 13,
      "z": 21,
      "name": "Soil_Seaweed_Block"
    },
    {
      "x": -31,
      "y": 14,
      "z": 21,
      "name": "Soil_Clay_Lime"
    },
    {
      "x": -31,
      "y": 15,
      "z": 21,
      "name": "Plant_Grass_Sharp"
    },
    {
      "x": -31,
      "y": 13,
      "z": 22,
      "name": "Soil_Clay_Green"
    },
    {
      "x": -31,
      "y": 14,
      "z": 22,
      "name": "Soil_Seaweed_Block"
    },
    {
      "x": -31,
      "y": 22,
      "z": 25,
      "name": "Soil_Clay_Green"
    },
    {
      "x": -31,
      "y": 23,
      "z": 25,
      "name": "Soil_Clay_Green"
    },
    {
      "x": -31,
      "y": 24,
      "z": 25,
      "name": "Soil_Clay_Green"
    },
    {
      "x": -31,
      "y": 23,
      "z": 26,
      "name": "Soil_Clay_Green"
    },
    {
      "x": -31,
      "y": 24,
      "z": 26,
      "name": "Soil_Seaweed_Block"
    },
    {
      "x": -31,
      "y": 25,
      "z": 26,
      "name": "Soil_Seaweed_Block"
    },
    {
      "x": -31,
      "y": 26,
      "z": 26,
      "name": "Soil_Clay_Lime"
    },
    {
      "x": -31,
      "y": 27,
      "z": 26,
      "name": "Soil_Seaweed_Block"
    },
    {
      "x": -31,
      "y": 13,
      "z": 27,
      "name": "Soil_Seaweed_Block"
    },
    {
      "x": -31,
      "y": 14,
      "z": 27,
      "name": "Soil_Clay_Lime"
    },
    {
      "x": -31,
      "y": 15,
      "z": 27,
      "name": "Plant_Grass_Sharp"
    },
    {
      "x": -31,
      "y": 23,
      "z": 27,
      "name": "Soil_Clay_Green"
    },
    {
      "x": -31,
      "y": 24,
      "z": 27,
      "name": "Soil_Clay_Green"
    },
    {
      "x": -31,
      "y": 25,
      "z": 27,
      "name": "Soil_Seaweed_Block"
    },
    {
      "x": -31,
      "y": 26,
      "z": 27,
      "name": "Soil_Clay_Lime"
    },
    {
      "x": -31,
      "y": 27,
      "z": 27,
      "name": "Soil_Clay_Lime"
    },
    {
      "x": -31,
      "y": 28,
      "z": 27,
      "name": "Soil_Clay_Lime"
    },
    {
      "x": -31,
      "y": 29,
      "z": 27,
      "name": "Soil_Seaweed_Block"
    },
    {
      "x": -31,
      "y": 28,
      "z": 28,
      "name": "Soil_Seaweed_Block"
    },
    {
      "x": -31,
      "y": 29,
      "z": 28,
      "name": "Soil_Seaweed_Block"
    },
    {
      "x": -31,
      "y": 8,
      "z": 30,
      "name": "Soil_Clay_Green"
    },
    {
      "x": -31,
      "y": 9,
      "z": 30,
      "name": "Soil_Clay_Green"
    },
    {
      "x": -31,
      "y": 10,
      "z": 30,
      "name": "Soil_Seaweed_Block"
    },
    {
      "x": -31,
      "y": 8,
      "z": 31,
      "name": "Soil_Clay_Green"
    },
    {
      "x": -31,
      "y": 9,
      "z": 31,
      "name": "Soil_Seaweed_Block"
    },
    {
      "x": -31,
      "y": 10,
      "z": 31,
      "name": "Soil_Clay_Lime"
    },
    {
      "x": -31,
      "y": 11,
      "z": 31,
      "name": "Plant_Grass_Sharp"
    },
    {
      "x": -31,
      "y": 8,
      "z": 32,
      "name": "Soil_Clay_Green"
    },
    {
      "x": -31,
      "y": 9,
      "z": 32,
      "name": "Soil_Seaweed_Block"
    },
    {
      "x": -31,
      "y": 10,
      "z": 32,
      "name": "Soil_Clay_Lime"
    },
    {
      "x": -31,
      "y": 11,
      "z": 32,
      "name": "Plant_Grass_Sharp"
    },
    {
      "x": -31,
      "y": 8,
      "z": 33,
      "name": "Soil_Clay_Green"
    },
    {
      "x": -31,
      "y": 9,
      "z": 33,
      "name": "Soil_Seaweed_Block"
    },
    {
      "x": -31,
      "y": 18,
      "z": 33,
      "name": "Soil_Clay_Green"
    },
    {
      "x": -31,
      "y": 7,
      "z": 34,
      "name": "Soil_Clay_Green"
    },
    {
      "x": -31,
      "y": 8,
      "z": 34,
      "name": "Soil_Clay_Green"
    },
    {
      "x": -31,
      "y": 18,
      "z": 34,
      "name": "Soil_Clay_Green"
    },
    {
      "x": -31,
      "y": 25,
      "z": 35,
      "name": "Soil_Seaweed_Block"
    },
    {
      "x": -31,
      "y": 25,
      "z": 36,
      "name": "Soil_Seaweed_Block"
    },
    {
      "x": -31,
      "y": 15,
      "z": 40,
      "name": "Soil_Clay_Green"
    },
    {
      "x": -31,
      "y": 16,
      "z": 40,
      "name": "Soil_Seaweed_Block"
    },
    {
      "x": -31,
      "y": 15,
      "z": 41,
      "name": "Soil_Clay_Green"
    },
    {
      "x": -31,
      "y": 15,
      "z": 42,
      "name": "Soil_Seaweed_Block"
    },
    {
      "x": -31,
      "y": 14,
      "z": 43,
      "name": "Soil_Clay_Green"
    },
    {
      "x": -31,
      "y": 15,
      "z": 43,
      "name": "Soil_Seaweed_Block"
    },
    {
      "x": -31,
      "y": 14,
      "z": 44,
      "name": "Soil_Clay_Green"
    },
    {
      "x": -31,
      "y": 15,
      "z": 44,
      "name": "Soil_Seaweed_Block"
    },
    {
      "x": -31,
      "y": 14,
      "z": 45,
      "name": "Soil_Clay_Green"
    },
    {
      "x": -30,
      "y": 11,
      "z": 18,
      "name": "Soil_Clay_Green"
    },
    {
      "x": -30,
      "y": 12,
      "z": 18,
      "name": "Soil_Clay_Green"
    },
    {
      "x": -30,
      "y": 13,
      "z": 18,
      "name": "Soil_Seaweed_Block"
    },
    {
      "x": -30,
      "y": 11,
      "z": 19,
      "name": "Soil_Clay_Green"
    },
    {
      "x": -30,
      "y": 12,
      "z": 19,
      "name": "Soil_Seaweed_Block"
    },
    {
      "x": -30,
      "y": 13,
      "z": 19,
      "name": "Soil_Seaweed_Block"
    },
    {
      "x": -30,
      "y": 14,
      "z": 19,
      "name": "Soil_Seaweed_Block"
    },
    {
      "x": -30,
      "y": 11,
      "z": 20,
      "name": "Soil_Clay_Green"
    },
    {
      "x": -30,
      "y": 12,
      "z": 20,
      "name": "Soil_Seaweed_Block"
    },
    {
      "x": -30,
      "y": 13,
      "z": 20,
      "name": "Soil_Seaweed_Block"
    },
    {
      "x": -30,
      "y": 14,
      "z": 20,
      "name": "Soil_Seaweed_Block"
    },
    {
      "x": -30,
      "y": 15,
      "z": 20,
      "name": "Soil_Clay_Lime"
    },
    {
      "x": -30,
      "y": 16,
      "z": 20,
      "name": "Plant_Grass_Sharp"
    },
    {
      "x": -30,
      "y": 12,
      "z": 21,
      "name": "Soil_Clay_Green"
    },
    {
      "x": -30,
      "y": 13,
      "z": 21,
      "name": "Soil_Seaweed_Block"
    },
    {
      "x": -30,
      "y": 14,
      "z": 21,
      "name": "Soil_Seaweed_Block"
    },
    {
      "x": -30,
      "y": 15,
      "z": 21,
      "name": "Soil_Clay_Lime"
    },
    {
      "x": -30,
      "y": 16,
      "z": 21,
      "name": "Plant_Grass_Sharp"
    },
    {
      "x": -30,
      "y": 13,
      "z": 22,
      "name": "Soil_Clay_Green"
    },
    {
      "x": -30,
      "y": 14,
      "z": 22,
      "name": "Soil_Seaweed_Block"
    },
    {
      "x": -30,
      "y": 22,
      "z": 25,
      "name": "Soil_Clay_Green"
    },
    {
      "x": -30,
      "y": 23,
      "z": 25,
      "name": "Soil_Clay_Green"
    },
    {
      "x": -30,
      "y": 24,
      "z": 25,
      "name": "Soil_Seaweed_Block"
    },
    {
      "x": -30,
      "y": 13,
      "z": 26,
      "name": "Soil_Seaweed_Block"
    },
    {
      "x": -30,
      "y": 22,
      "z": 26,
      "name": "Soil_Clay_Green"
    },
    {
      "x": -30,
      "y": 23,
      "z": 26,
      "name": "Soil_Clay_Green"
    },
    {
      "x": -30,
      "y": 24,
      "z": 26,
      "name": "Soil_Seaweed_Block"
    },
    {
      "x": -30,
      "y": 25,
      "z": 26,
      "name": "Soil_Clay_Lime"
    },
    {
      "x": -30,
      "y": 26,
      "z": 26,
      "name": "Soil_Clay_Lime"
    },
    {
      "x": -30,
      "y": 27,
      "z": 26,
      "name": "Soil_Seaweed_Block"
    },
    {
      "x": -30,
      "y": 13,
      "z": 27,
      "name": "Soil_Seaweed_Block"
    },
    {
      "x": -30,
      "y": 24,
      "z": 27,
      "name": "Soil_Seaweed_Block"
    },
    {
      "x": -30,
      "y": 25,
      "z": 27,
      "name": "Soil_Seaweed_Block"
    },
    {
      "x": -30,
      "y": 26,
      "z": 27,
      "name": "Soil_Seaweed_Block"
    },
    {
      "x": -30,
      "y": 27,
      "z": 27,
      "name": "Soil_Clay_Lime"
    },
    {
      "x": -30,
      "y": 28,
      "z": 27,
      "name": "Soil_Seaweed_Block"
    },
    {
      "x": -30,
      "y": 24,
      "z": 28,
      "name": "Soil_Clay_Green"
    },
    {
      "x": -30,
      "y": 25,
      "z": 28,
      "name": "Soil_Seaweed_Block"
    },
    {
      "x": -30,
      "y": 26,
      "z": 28,
      "name": "Soil_Clay_Lime"
    },
    {
      "x": -30,
      "y": 27,
      "z": 28,
      "name": "Plant_Grass_Sharp"
    },
    {
      "x": -30,
      "y": 10,
      "z": 29,
      "name": "Soil_Seaweed_Block"
    },
    {
      "x": -30,
      "y": 25,
      "z": 29,
      "name": "Soil_Seaweed_Block"
    },
    {
      "x": -30,
      "y": 8,
      "z": 30,
      "name": "Soil_Clay_Green"
    },
    {
      "x": -30,
      "y": 9,
      "z": 30,
      "name": "Soil_Clay_Green"
    },
    {
      "x": -30,
      "y": 10,
      "z": 30,
      "name": "Soil_Seaweed_Block"
    },
    {
      "x": -30,
      "y": 8,
      "z": 31,
      "name": "Soil_Clay_Green"
    },
    {
      "x": -30,
      "y": 9,
      "z": 31,
      "name": "Soil_Seaweed_Block"
    },
    {
      "x": -30,
      "y": 10,
      "z": 31,
      "name": "Soil_Clay_Lime"
    },
    {
      "x": -30,
      "y": 11,
      "z": 31,
      "name": "Plant_Grass_Sharp"
    },
    {
      "x": -30,
      "y": 8,
      "z": 32,
      "name": "Soil_Clay_Green"
    },
    {
      "x": -30,
      "y": 9,
      "z": 32,
      "name": "Soil_Clay_Green"
    },
    {
      "x": -30,
      "y": 10,
      "z": 32,
      "name": "Soil_Clay_Lime"
    },
    {
      "x": -30,
      "y": 11,
      "z": 32,
      "name": "Plant_Grass_Sharp"
    },
    {
      "x": -30,
      "y": 19,
      "z": 32,
      "name": "Soil_Seaweed_Block"
    },
    {
      "x": -30,
      "y": 8,
      "z": 33,
      "name": "Soil_Clay_Green"
    },
    {
      "x": -30,
      "y": 18,
      "z": 33,
      "name": "Soil_Clay_Green"
    },
    {
      "x": -30,
      "y": 19,
      "z": 33,
      "name": "Soil_Seaweed_Block"
    },
    {
      "x": -30,
      "y": 8,
      "z": 34,
      "name": "Soil_Clay_Green"
    },
    {
      "x": -30,
      "y": 25,
      "z": 35,
      "name": "Soil_Clay_Lime"
    },
    {
      "x": -30,
      "y": 26,
      "z": 35,
      "name": "Plant_Grass_Sharp"
    },
    {
      "x": -30,
      "y": 17,
      "z": 36,
      "name": "Soil_Clay_Green"
    },
    {
      "x": -30,
      "y": 18,
      "z": 36,
      "name": "Soil_Clay_Green"
    },
    {
      "x": -30,
      "y": 25,
      "z": 36,
      "name": "Soil_Seaweed_Block"
    },
    {
      "x": -30,
      "y": 17,
      "z": 37,
      "name": "Soil_Clay_Green"
    },
    {
      "x": -30,
      "y": 18,
      "z": 37,
      "name": "Soil_Seaweed_Block"
    },
    {
      "x": -30,
      "y": 16,
      "z": 39,
      "name": "Soil_Clay_Green"
    },
    {
      "x": -30,
      "y": 15,
      "z": 40,
      "name": "Soil_Clay_Green"
    },
    {
      "x": -30,
      "y": 16,
      "z": 40,
      "name": "Soil_Seaweed_Block"
    },
    {
      "x": -30,
      "y": 15,
      "z": 41,
      "name": "Soil_Clay_Green"
    },
    {
      "x": -30,
      "y": 16,
      "z": 41,
      "name": "Soil_Clay_Lime"
    },
    {
      "x": -30,
      "y": 17,
      "z": 41,
      "name": "Plant_Grass_Sharp"
    },
    {
      "x": -30,
      "y": 14,
      "z": 42,
      "name": "Soil_Clay_Green"
    },
    {
      "x": -30,
      "y": 15,
      "z": 42,
      "name": "Soil_Seaweed_Block"
    },
    {
      "x": -30,
      "y": 16,
      "z": 42,
      "name": "Soil_Clay_Lime"
    },
    {
      "x": -30,
      "y": 17,
      "z": 42,
      "name": "Plant_Grass_Sharp"
    },
    {
      "x": -30,
      "y": 14,
      "z": 43,
      "name": "Soil_Clay_Green"
    },
    {
      "x": -30,
      "y": 15,
      "z": 43,
      "name": "Soil_Seaweed_Block"
    },
    {
      "x": -30,
      "y": 14,
      "z": 44,
      "name": "Soil_Clay_Green"
    },
    {
      "x": -29,
      "y": 11,
      "z": 18,
      "name": "Soil_Clay_Green"
    },
    {
      "x": -29,
      "y": 12,
      "z": 18,
      "name": "Soil_Clay_Green"
    },
    {
      "x": -29,
      "y": 13,
      "z": 18,
      "name": "Soil_Seaweed_Block"
    },
    {
      "x": -29,
      "y": 11,
      "z": 19,
      "name": "Soil_Clay_Green"
    },
    {
      "x": -29,
      "y": 12,
      "z": 19,
      "name": "Soil_Seaweed_Block"
    },
    {
      "x": -29,
      "y": 13,
      "z": 19,
      "name": "Soil_Seaweed_Block"
    },
    {
      "x": -29,
      "y": 14,
      "z": 19,
      "name": "Soil_Seaweed_Block"
    },
    {
      "x": -29,
      "y": 15,
      "z": 19,
      "name": "Soil_Clay_Lime"
    },
    {
      "x": -29,
      "y": 16,
      "z": 19,
      "name": "Plant_Grass_Sharp"
    },
    {
      "x": -29,
      "y": 11,
      "z": 20,
      "name": "Soil_Clay_Green"
    },
    {
      "x": -29,
      "y": 12,
      "z": 20,
      "name": "Soil_Seaweed_Block"
    },
    {
      "x": -29,
      "y": 13,
      "z": 20,
      "name": "Soil_Seaweed_Block"
    },
    {
      "x": -29,
      "y": 14,
      "z": 20,
      "name": "Soil_Seaweed_Block"
    },
    {
      "x": -29,
      "y": 15,
      "z": 20,
      "name": "Soil_Clay_Lime"
    },
    {
      "x": -29,
      "y": 16,
      "z": 20,
      "name": "Plant_Grass_Sharp"
    },
    {
      "x": -29,
      "y": 10,
      "z": 21,
      "name": "Soil_Clay_Green"
    },
    {
      "x": -29,
      "y": 11,
      "z": 21,
      "name": "Soil_Clay_Green"
    },
    {
      "x": -29,
      "y": 12,
      "z": 21,
      "name": "Soil_Seaweed_Block"
    },
    {
      "x": -29,
      "y": 13,
      "z": 21,
      "name": "Soil_Seaweed_Block"
    },
    {
      "x": -29,
      "y": 14,
      "z": 21,
      "name": "Soil_Seaweed_Block"
    },
    {
      "x": -29,
      "y": 15,
      "z": 21,
      "name": "Soil_Clay_Lime"
    },
    {
      "x": -29,
      "y": 16,
      "z": 21,
      "name": "Soil_Clay_Lime"
    },
    {
      "x": -29,
      "y": 17,
      "z": 21,
      "name": "Plant_Grass_Sharp"
    },
    {
      "x": -29,
      "y": 19,
      "z": 21,
      "name": "Soil_Seaweed_Block"
    },
    {
      "x": -29,
      "y": 20,
      "z": 21,
      "name": "Soil_Seaweed_Block"
    },
    {
      "x": -29,
      "y": 12,
      "z": 22,
      "name": "Soil_Clay_Green"
    },
    {
      "x": -29,
      "y": 13,
      "z": 22,
      "name": "Soil_Seaweed_Block"
    },
    {
      "x": -29,
      "y": 12,
      "z": 23,
      "name": "Soil_Clay_Green"
    },
    {
      "x": -29,
      "y": 13,
      "z": 23,
      "name": "Soil_Seaweed_Block"
    },
    {
      "x": -29,
      "y": 20,
      "z": 25,
      "name": "Soil_Clay_Green"
    },
    {
      "x": -29,
      "y": 21,
      "z": 25,
      "name": "Soil_Clay_Green"
    },
    {
      "x": -29,
      "y": 22,
      "z": 25,
      "name": "Soil_Clay_Green"
    },
    {
      "x": -29,
      "y": 23,
      "z": 25,
      "name": "Soil_Seaweed_Block"
    },
    {
      "x": -29,
      "y": 24,
      "z": 25,
      "name": "Soil_Seaweed_Block"
    },
    {
      "x": -29,
      "y": 21,
      "z": 26,
      "name": "Soil_Clay_Green"
    },
    {
      "x": -29,
      "y": 22,
      "z": 26,
      "name": "Soil_Seaweed_Block"
    },
    {
      "x": -29,
      "y": 23,
      "z": 26,
      "name": "Soil_Seaweed_Block"
    },
    {
      "x": -29,
      "y": 24,
      "z": 26,
      "name": "Soil_Seaweed_Block"
    },
    {
      "x": -29,
      "y": 25,
      "z": 26,
      "name": "Soil_Seaweed_Block"
    },
    {
      "x": -29,
      "y": 13,
      "z": 27,
      "name": "Soil_Seaweed_Block"
    },
    {
      "x": -29,
      "y": 21,
      "z": 27,
      "name": "Soil_Clay_Green"
    },
    {
      "x": -29,
      "y": 22,
      "z": 27,
      "name": "Soil_Clay_Green"
    },
    {
      "x": -29,
      "y": 23,
      "z": 27,
      "name": "Soil_Seaweed_Block"
    },
    {
      "x": -29,
      "y": 24,
      "z": 27,
      "name": "Soil_Seaweed_Block"
    },
    {
      "x": -29,
      "y": 25,
      "z": 27,
      "name": "Soil_Clay_Lime"
    },
    {
      "x": -29,
      "y": 26,
      "z": 27,
      "name": "Soil_Seaweed_Block"
    },
    {
      "x": -29,
      "y": 10,
      "z": 28,
      "name": "Soil_Clay_Green"
    },
    {
      "x": -29,
      "y": 11,
      "z": 28,
      "name": "Soil_Clay_Green"
    },
    {
      "x": -29,
      "y": 13,
      "z": 28,
      "name": "Soil_Seaweed_Block"
    },
    {
      "x": -29,
      "y": 22,
      "z": 28,
      "name": "Soil_Clay_Green"
    },
    {
      "x": -29,
      "y": 23,
      "z": 28,
      "name": "Soil_Clay_Green"
    },
    {
      "x": -29,
      "y": 24,
      "z": 28,
      "name": "Soil_Seaweed_Block"
    },
    {
      "x": -29,
      "y": 25,
      "z": 28,
      "name": "Soil_Seaweed_Block"
    },
    {
      "x": -29,
      "y": 26,
      "z": 28,
      "name": "Soil_Seaweed_Block"
    },
    {
      "x": -29,
      "y": 9,
      "z": 29,
      "name": "Soil_Clay_Green"
    },
    {
      "x": -29,
      "y": 10,
      "z": 29,
      "name": "Soil_Seaweed_Block"
    },
    {
      "x": -29,
      "y": 11,
      "z": 29,
      "name": "Soil_Seaweed_Block"
    },
    {
      "x": -29,
      "y": 24,
      "z": 29,
      "name": "Soil_Clay_Green"
    },
    {
      "x": -29,
      "y": 25,
      "z": 29,
      "name": "Soil_Seaweed_Block"
    },
    {
      "x": -29,
      "y": 9,
      "z": 30,
      "name": "Soil_Clay_Green"
    },
    {
      "x": -29,
      "y": 10,
      "z": 30,
      "name": "Soil_Seaweed_Block"
    },
    {
      "x": -29,
      "y": 11,
      "z": 30,
      "name": "Soil_Clay_Lime"
    },
    {
      "x": -29,
      "y": 12,
      "z": 30,
      "name": "Plant_Grass_Sharp"
    },
    {
      "x": -29,
      "y": 24,
      "z": 30,
      "name": "Soil_Clay_Green"
    },
    {
      "x": -29,
      "y": 25,
      "z": 30,
      "name": "Soil_Seaweed_Block"
    },
    {
      "x": -29,
      "y": 8,
      "z": 31,
      "name": "Soil_Clay_Green"
    },
    {
      "x": -29,
      "y": 9,
      "z": 31,
      "name": "Soil_Seaweed_Block"
    },
    {
      "x": -29,
      "y": 10,
      "z": 31,
      "name": "Soil_Clay_Lime"
    },
    {
      "x": -29,
      "y": 11,
      "z": 31,
      "name": "Plant_Grass_Sharp"
    },
    {
      "x": -29,
      "y": 24,
      "z": 31,
      "name": "Soil_Clay_Green"
    },
    {
      "x": -29,
      "y": 25,
      "z": 31,
      "name": "Soil_Clay_Lime"
    },
    {
      "x": -29,
      "y": 26,
      "z": 31,
      "name": "Plant_Grass_Sharp"
    },
    {
      "x": -29,
      "y": 9,
      "z": 32,
      "name": "Soil_Clay_Green"
    },
    {
      "x": -29,
      "y": 10,
      "z": 32,
      "name": "Soil_Seaweed_Block"
    },
    {
      "x": -29,
      "y": 19,
      "z": 32,
      "name": "Soil_Clay_Green"
    },
    {
      "x": -29,
      "y": 18,
      "z": 33,
      "name": "Soil_Clay_Green"
    },
    {
      "x": -29,
      "y": 19,
      "z": 33,
      "name": "Soil_Seaweed_Block"
    },
    {
      "x": -29,
      "y": 20,
      "z": 33,
      "name": "Soil_Seaweed_Block"
    },
    {
      "x": -29,
      "y": 24,
      "z": 33,
      "name": "Soil_Clay_Green"
    },
    {
      "x": -29,
      "y": 18,
      "z": 34,
      "name": "Soil_Clay_Green"
    },
    {
      "x": -29,
      "y": 19,
      "z": 34,
      "name": "Soil_Clay_Green"
    },
    {
      "x": -29,
      "y": 20,
      "z": 34,
      "name": "Soil_Clay_Lime"
    },
    {
      "x": -29,
      "y": 21,
      "z": 34,
      "name": "Plant_Grass_Sharp"
    },
    {
      "x": -29,
      "y": 24,
      "z": 34,
      "name": "Soil_Clay_Green"
    },
    {
      "x": -29,
      "y": 25,
      "z": 34,
      "name": "Soil_Seaweed_Block"
    },
    {
      "x": -29,
      "y": 18,
      "z": 35,
      "name": "Soil_Clay_Green"
    },
    {
      "x": -29,
      "y": 19,
      "z": 35,
      "name": "Soil_Seaweed_Block"
    },
    {
      "x": -29,
      "y": 20,
      "z": 35,
      "name": "Soil_Clay_Lime"
    },
    {
      "x": -29,
      "y": 21,
      "z": 35,
      "name": "Plant_Grass_Sharp"
    },
    {
      "x": -29,
      "y": 24,
      "z": 35,
      "name": "Soil_Clay_Green"
    },
    {
      "x": -29,
      "y": 25,
      "z": 35,
      "name": "Soil_Clay_Lime"
    },
    {
      "x": -29,
      "y": 26,
      "z": 35,
      "name": "Plant_Grass_Sharp"
    },
    {
      "x": -29,
      "y": 17,
      "z": 36,
      "name": "Soil_Clay_Green"
    },
    {
      "x": -29,
      "y": 18,
      "z": 36,
      "name": "Soil_Seaweed_Block"
    },
    {
      "x": -29,
      "y": 19,
      "z": 36,
      "name": "Soil_Seaweed_Block"
    },
    {
      "x": -29,
      "y": 20,
      "z": 36,
      "name": "Soil_Clay_Lime"
    },
    {
      "x": -29,
      "y": 21,
      "z": 36,
      "name": "Plant_Grass_Sharp"
    },
    {
      "x": -29,
      "y": 25,
      "z": 36,
      "name": "Soil_Seaweed_Block"
    },
    {
      "x": -29,
      "y": 16,
      "z": 37,
      "name": "Soil_Clay_Green"
    },
    {
      "x": -29,
      "y": 17,
      "z": 37,
      "name": "Soil_Seaweed_Block"
    },
    {
      "x": -29,
      "y": 18,
      "z": 37,
      "name": "Soil_Seaweed_Block"
    },
    {
      "x": -29,
      "y": 19,
      "z": 37,
      "name": "Soil_Seaweed_Block"
    },
    {
      "x": -29,
      "y": 16,
      "z": 38,
      "name": "Soil_Clay_Green"
    },
    {
      "x": -29,
      "y": 17,
      "z": 38,
      "name": "Soil_Clay_Green"
    },
    {
      "x": -29,
      "y": 18,
      "z": 38,
      "name": "Soil_Seaweed_Block"
    },
    {
      "x": -29,
      "y": 16,
      "z": 39,
      "name": "Soil_Clay_Green"
    },
    {
      "x": -29,
      "y": 17,
      "z": 39,
      "name": "Soil_Clay_Lime"
    },
    {
      "x": -29,
      "y": 18,
      "z": 39,
      "name": "Plant_Grass_Sharp"
    },
    {
      "x": -29,
      "y": 15,
      "z": 40,
      "name": "Soil_Clay_Green"
    },
    {
      "x": -29,
      "y": 16,
      "z": 40,
      "name": "Soil_Clay_Lime"
    },
    {
      "x": -29,
      "y": 17,
      "z": 40,
      "name": "Plant_Grass_Sharp"
    },
    {
      "x": -29,
      "y": 15,
      "z": 41,
      "name": "Soil_Clay_Green"
    },
    {
      "x": -29,
      "y": 16,
      "z": 41,
      "name": "Soil_Clay_Lime"
    },
    {
      "x": -29,
      "y": 17,
      "z": 41,
      "name": "Plant_Grass_Sharp"
    },
    {
      "x": -29,
      "y": 14,
      "z": 42,
      "name": "Soil_Clay_Green"
    },
    {
      "x": -29,
      "y": 15,
      "z": 42,
      "name": "Soil_Seaweed_Block"
    },
    {
      "x": -29,
      "y": 14,
      "z": 43,
      "name": "Soil_Clay_Green"
    },
    {
      "x": -29,
      "y": 15,
      "z": 43,
      "name": "Soil_Seaweed_Block"
    },
    {
      "x": -29,
      "y": 14,
      "z": 44,
      "name": "Soil_Clay_Green"
    },
    {
      "x": -28,
      "y": 10,
      "z": 18,
      "name": "Soil_Clay_Green"
    },
    {
      "x": -28,
      "y": 11,
      "z": 18,
      "name": "Soil_Clay_Green"
    },
    {
      "x": -28,
      "y": 12,
      "z": 18,
      "name": "Soil_Clay_Green"
    },
    {
      "x": -28,
      "y": 13,
      "z": 18,
      "name": "Soil_Seaweed_Block"
    },
    {
      "x": -28,
      "y": 14,
      "z": 18,
      "name": "Soil_Seaweed_Block"
    },
    {
      "x": -28,
      "y": 10,
      "z": 19,
      "name": "Soil_Clay_Green"
    },
    {
      "x": -28,
      "y": 11,
      "z": 19,
      "name": "Soil_Seaweed_Block"
    },
    {
      "x": -28,
      "y": 12,
      "z": 19,
      "name": "Soil_Seaweed_Block"
    },
    {
      "x": -28,
      "y": 13,
      "z": 19,
      "name": "Soil_Seaweed_Block"
    },
    {
      "x": -28,
      "y": 14,
      "z": 19,
      "name": "Soil_Seaweed_Block"
    },
    {
      "x": -28,
      "y": 15,
      "z": 19,
      "name": "Soil_Seaweed_Block"
    },
    {
      "x": -28,
      "y": 10,
      "z": 20,
      "name": "Soil_Clay_Green"
    },
    {
      "x": -28,
      "y": 11,
      "z": 20,
      "name": "Soil_Seaweed_Block"
    },
    {
      "x": -28,
      "y": 12,
      "z": 20,
      "name": "Soil_Seaweed_Block"
    },
    {
      "x": -28,
      "y": 13,
      "z": 20,
      "name": "Soil_Seaweed_Block"
    },
    {
      "x": -28,
      "y": 14,
      "z": 20,
      "name": "Soil_Seaweed_Block"
    },
    {
      "x": -28,
      "y": 15,
      "z": 20,
      "name": "Soil_Seaweed_Block"
    },
    {
      "x": -28,
      "y": 16,
      "z": 20,
      "name": "Soil_Clay_Lime"
    },
    {
      "x": -28,
      "y": 17,
      "z": 20,
      "name": "Plant_Grass_Sharp"
    },
    {
      "x": -28,
      "y": 10,
      "z": 21,
      "name": "Soil_Clay_Green"
    },
    {
      "x": -28,
      "y": 11,
      "z": 21,
      "name": "Soil_Seaweed_Block"
    },
    {
      "x": -28,
      "y": 12,
      "z": 21,
      "name": "Soil_Seaweed_Block"
    },
    {
      "x": -28,
      "y": 13,
      "z": 21,
      "name": "Soil_Seaweed_Block"
    },
    {
      "x": -28,
      "y": 14,
      "z": 21,
      "name": "Soil_Seaweed_Block"
    },
    {
      "x": -28,
      "y": 15,
      "z": 21,
      "name": "Soil_Seaweed_Block"
    },
    {
      "x": -28,
      "y": 16,
      "z": 21,
      "name": "Soil_Seaweed_Block"
    },
    {
      "x": -28,
      "y": 17,
      "z": 21,
      "name": "Soil_Seaweed_Block"
    },
    {
      "x": -28,
      "y": 18,
      "z": 21,
      "name": "Soil_Seaweed_Block"
    },
    {
      "x": -28,
      "y": 19,
      "z": 21,
      "name": "Soil_Seaweed_Block"
    },
    {
      "x": -28,
      "y": 20,
      "z": 21,
      "name": "Soil_Seaweed_Block"
    },
    {
      "x": -28,
      "y": 10,
      "z": 22,
      "name": "Soil_Clay_Green"
    },
    {
      "x": -28,
      "y": 11,
      "z": 22,
      "name": "Soil_Clay_Green"
    },
    {
      "x": -28,
      "y": 12,
      "z": 22,
      "name": "Soil_Seaweed_Block"
    },
    {
      "x": -28,
      "y": 13,
      "z": 22,
      "name": "Soil_Seaweed_Block"
    },
    {
      "x": -28,
      "y": 14,
      "z": 22,
      "name": "Soil_Seaweed_Block"
    },
    {
      "x": -28,
      "y": 15,
      "z": 22,
      "name": "Soil_Seaweed_Block"
    },
    {
      "x": -28,
      "y": 16,
      "z": 22,
      "name": "Soil_Seaweed_Block"
    },
    {
      "x": -28,
      "y": 17,
      "z": 22,
      "name": "Soil_Seaweed_Block"
    },
    {
      "x": -28,
      "y": 18,
      "z": 22,
      "name": "Soil_Seaweed_Block"
    },
    {
      "x": -28,
      "y": 19,
      "z": 22,
      "name": "Soil_Seaweed_Block"
    },
    {
      "x": -28,
      "y": 20,
      "z": 22,
      "name": "Soil_Seaweed_Block"
    },
    {
      "x": -28,
      "y": 12,
      "z": 23,
      "name": "Soil_Seaweed_Block"
    },
    {
      "x": -28,
      "y": 13,
      "z": 23,
      "name": "Soil_Seaweed_Block"
    },
    {
      "x": -28,
      "y": 10,
      "z": 24,
      "name": "Soil_Clay_Green"
    },
    {
      "x": -28,
      "y": 11,
      "z": 24,
      "name": "Soil_Clay_Green"
    },
    {
      "x": -28,
      "y": 12,
      "z": 24,
      "name": "Soil_Seaweed_Block"
    },
    {
      "x": -28,
      "y": 19,
      "z": 24,
      "name": "Soil_Clay_Green"
    },
    {
      "x": -28,
      "y": 20,
      "z": 24,
      "name": "Soil_Clay_Green"
    },
    {
      "x": -28,
      "y": 21,
      "z": 24,
      "name": "Soil_Seaweed_Block"
    },
    {
      "x": -28,
      "y": 10,
      "z": 25,
      "name": "Soil_Clay_Green"
    },
    {
      "x": -28,
      "y": 11,
      "z": 25,
      "name": "Soil_Clay_Green"
    },
    {
      "x": -28,
      "y": 12,
      "z": 25,
      "name": "Soil_Seaweed_Block"
    },
    {
      "x": -28,
      "y": 20,
      "z": 25,
      "name": "Soil_Clay_Green"
    },
    {
      "x": -28,
      "y": 21,
      "z": 25,
      "name": "Soil_Seaweed_Block"
    },
    {
      "x": -28,
      "y": 22,
      "z": 25,
      "name": "Soil_Seaweed_Block"
    },
    {
      "x": -28,
      "y": 23,
      "z": 25,
      "name": "Soil_Seaweed_Block"
    },
    {
      "x": -28,
      "y": 20,
      "z": 26,
      "name": "Soil_Clay_Green"
    },
    {
      "x": -28,
      "y": 21,
      "z": 26,
      "name": "Soil_Seaweed_Block"
    },
    {
      "x": -28,
      "y": 22,
      "z": 26,
      "name": "Soil_Seaweed_Block"
    },
    {
      "x": -28,
      "y": 23,
      "z": 26,
      "name": "Soil_Seaweed_Block"
    },
    {
      "x": -28,
      "y": 24,
      "z": 26,
      "name": "Soil_Seaweed_Block"
    },
    {
      "x": -28,
      "y": 10,
      "z": 27,
      "name": "Soil_Clay_Green"
    },
    {
      "x": -28,
      "y": 11,
      "z": 27,
      "name": "Soil_Clay_Green"
    },
    {
      "x": -28,
      "y": 12,
      "z": 27,
      "name": "Soil_Seaweed_Block"
    },
    {
      "x": -28,
      "y": 13,
      "z": 27,
      "name": "Soil_Seaweed_Block"
    },
    {
      "x": -28,
      "y": 21,
      "z": 27,
      "name": "Soil_Clay_Green"
    },
    {
      "x": -28,
      "y": 22,
      "z": 27,
      "name": "Soil_Seaweed_Block"
    },
    {
      "x": -28,
      "y": 23,
      "z": 27,
      "name": "Soil_Seaweed_Block"
    },
    {
      "x": -28,
      "y": 10,
      "z": 28,
      "name": "Soil_Clay_Green"
    },
    {
      "x": -28,
      "y": 11,
      "z": 28,
      "name": "Soil_Seaweed_Block"
    },
    {
      "x": -28,
      "y": 12,
      "z": 28,
      "name": "Soil_Seaweed_Block"
    },
    {
      "x": -28,
      "y": 13,
      "z": 28,
      "name": "Soil_Seaweed_Block"
    },
    {
      "x": -28,
      "y": 21,
      "z": 28,
      "name": "Soil_Clay_Green"
    },
    {
      "x": -28,
      "y": 22,
      "z": 28,
      "name": "Soil_Clay_Green"
    },
    {
      "x": -28,
      "y": 23,
      "z": 28,
      "name": "Soil_Clay_Green"
    },
    {
      "x": -28,
      "y": 9,
      "z": 29,
      "name": "Soil_Clay_Green"
    },
    {
      "x": -28,
      "y": 10,
      "z": 29,
      "name": "Soil_Seaweed_Block"
    },
    {
      "x": -28,
      "y": 11,
      "z": 29,
      "name": "Soil_Seaweed_Block"
    },
    {
      "x": -28,
      "y": 12,
      "z": 29,
      "name": "Soil_Seaweed_Block"
    },
    {
      "x": -28,
      "y": 13,
      "z": 29,
      "name": "Soil_Seaweed_Block"
    },
    {
      "x": -28,
      "y": 9,
      "z": 30,
      "name": "Soil_Clay_Green"
    },
    {
      "x": -28,
      "y": 10,
      "z": 30,
      "name": "Soil_Seaweed_Block"
    },
    {
      "x": -28,
      "y": 11,
      "z": 30,
      "name": "Soil_Seaweed_Block"
    },
    {
      "x": -28,
      "y": 12,
      "z": 30,
      "name": "Soil_Seaweed_Block"
    },
    {
      "x": -28,
      "y": 24,
      "z": 30,
      "name": "Soil_Clay_Green"
    },
    {
      "x": -28,
      "y": 25,
      "z": 30,
      "name": "Soil_Seaweed_Block"
    },
    {
      "x": -28,
      "y": 8,
      "z": 31,
      "name": "Soil_Clay_Green"
    },
    {
      "x": -28,
      "y": 9,
      "z": 31,
      "name": "Soil_Seaweed_Block"
    },
    {
      "x": -28,
      "y": 10,
      "z": 31,
      "name": "Soil_Seaweed_Block"
    },
    {
      "x": -28,
      "y": 11,
      "z": 31,
      "name": "Soil_Seaweed_Block"
    },
    {
      "x": -28,
      "y": 24,
      "z": 31,
      "name": "Soil_Clay_Green"
    },
    {
      "x": -28,
      "y": 25,
      "z": 31,
      "name": "Soil_Seaweed_Block"
    },
    {
      "x": -28,
      "y": 9,
      "z": 32,
      "name": "Soil_Clay_Green"
    },
    {
      "x": -28,
      "y": 10,
      "z": 32,
      "name": "Soil_Seaweed_Block"
    },
    {
      "x": -28,
      "y": 19,
      "z": 32,
      "name": "Soil_Clay_Green"
    },
    {
      "x": -28,
      "y": 24,
      "z": 32,
      "name": "Soil_Clay_Green"
    },
    {
      "x": -28,
      "y": 19,
      "z": 33,
      "name": "Soil_Clay_Green"
    },
    {
      "x": -28,
      "y": 20,
      "z": 33,
      "name": "Soil_Clay_Lime"
    },
    {
      "x": -28,
      "y": 21,
      "z": 33,
      "name": "Soil_Clay_Lime"
    },
    {
      "x": -28,
      "y": 22,
      "z": 33,
      "name": "Plant_Grass_Sharp"
    },
    {
      "x": -28,
      "y": 18,
      "z": 34,
      "name": "Soil_Clay_Green"
    },
    {
      "x": -28,
      "y": 19,
      "z": 34,
      "name": "Soil_Seaweed_Block"
    },
    {
      "x": -28,
      "y": 20,
      "z": 34,
      "name": "Soil_Seaweed_Block"
    },
    {
      "x": -28,
      "y": 21,
      "z": 34,
      "name": "Soil_Clay_Lime"
    },
    {
      "x": -28,
      "y": 22,
      "z": 34,
      "name": "Plant_Grass_Sharp"
    },
    {
      "x": -28,
      "y": 24,
      "z": 34,
      "name": "Soil_Clay_Green"
    },
    {
      "x": -28,
      "y": 18,
      "z": 35,
      "name": "Soil_Clay_Green"
    },
    {
      "x": -28,
      "y": 19,
      "z": 35,
      "name": "Soil_Seaweed_Block"
    },
    {
      "x": -28,
      "y": 20,
      "z": 35,
      "name": "Soil_Seaweed_Block"
    },
    {
      "x": -28,
      "y": 21,
      "z": 35,
      "name": "Soil_Clay_Lime"
    },
    {
      "x": -28,
      "y": 22,
      "z": 35,
      "name": "Plant_Grass_Sharp"
    },
    {
      "x": -28,
      "y": 24,
      "z": 35,
      "name": "Soil_Clay_Green"
    },
    {
      "x": -28,
      "y": 17,
      "z": 36,
      "name": "Soil_Clay_Green"
    },
    {
      "x": -28,
      "y": 18,
      "z": 36,
      "name": "Soil_Seaweed_Block"
    },
    {
      "x": -28,
      "y": 19,
      "z": 36,
      "name": "Soil_Seaweed_Block"
    },
    {
      "x": -28,
      "y": 20,
      "z": 36,
      "name": "Soil_Clay_Lime"
    },
    {
      "x": -28,
      "y": 21,
      "z": 36,
      "name": "Plant_Grass_Sharp"
    },
    {
      "x": -28,
      "y": 17,
      "z": 37,
      "name": "Soil_Clay_Green"
    },
    {
      "x": -28,
      "y": 18,
      "z": 37,
      "name": "Soil_Clay_Green"
    },
    {
      "x": -28,
      "y": 19,
      "z": 37,
      "name": "Soil_Seaweed_Block"
    },
    {
      "x": -28,
      "y": 16,
      "z": 38,
      "name": "Soil_Clay_Green"
    },
    {
      "x": -28,
      "y": 17,
      "z": 38,
      "name": "Soil_Clay_Green"
    },
    {
      "x": -28,
      "y": 15,
      "z": 39,
      "name": "Soil_Clay_Green"
    },
    {
      "x": -28,
      "y": 16,
      "z": 39,
      "name": "Soil_Clay_Green"
    },
    {
      "x": -28,
      "y": 17,
      "z": 39,
      "name": "Soil_Seaweed_Block"
    },
    {
      "x": -28,
      "y": 15,
      "z": 40,
      "name": "Soil_Clay_Green"
    },
    {
      "x": -28,
      "y": 16,
      "z": 40,
      "name": "Soil_Seaweed_Block"
    },
    {
      "x": -28,
      "y": 15,
      "z": 41,
      "name": "Soil_Clay_Green"
    },
    {
      "x": -28,
      "y": 14,
      "z": 42,
      "name": "Soil_Clay_Green"
    },
    {
      "x": -28,
      "y": 15,
      "z": 42,
      "name": "Soil_Seaweed_Block"
    },
    {
      "x": -27,
      "y": 10,
      "z": 17,
      "name": "Soil_Clay_Green"
    },
    {
      "x": -27,
      "y": 11,
      "z": 17,
      "name": "Soil_Clay_Green"
    },
    {
      "x": -27,
      "y": 12,
      "z": 17,
      "name": "Soil_Seaweed_Block"
    },
    {
      "x": -27,
      "y": 8,
      "z": 18,
      "name": "Soil_Clay_Green"
    },
    {
      "x": -27,
      "y": 9,
      "z": 18,
      "name": "Soil_Clay_Green"
    },
    {
      "x": -27,
      "y": 10,
      "z": 18,
      "name": "Soil_Seaweed_Block"
    },
    {
      "x": -27,
      "y": 11,
      "z": 18,
      "name": "Soil_Seaweed_Block"
    },
    {
      "x": -27,
      "y": 12,
      "z": 18,
      "name": "Soil_Seaweed_Block"
    },
    {
      "x": -27,
      "y": 13,
      "z": 18,
      "name": "Soil_Seaweed_Block"
    },
    {
      "x": -27,
      "y": 14,
      "z": 18,
      "name": "Soil_Seaweed_Block"
    },
    {
      "x": -27,
      "y": 15,
      "z": 18,
      "name": "Soil_Seaweed_Block"
    },
    {
      "x": -27,
      "y": 10,
      "z": 19,
      "name": "Soil_Clay_Green"
    },
    {
      "x": -27,
      "y": 11,
      "z": 19,
      "name": "Soil_Seaweed_Block"
    },
    {
      "x": -27,
      "y": 12,
      "z": 19,
      "name": "Soil_Seaweed_Block"
    },
    {
      "x": -27,
      "y": 13,
      "z": 19,
      "name": "Soil_Seaweed_Block"
    },
    {
      "x": -27,
      "y": 14,
      "z": 19,
      "name": "Soil_Seaweed_Block"
    },
    {
      "x": -27,
      "y": 15,
      "z": 19,
      "name": "Soil_Seaweed_Block"
    },
    {
      "x": -27,
      "y": 16,
      "z": 19,
      "name": "Soil_Seaweed_Block"
    },
    {
      "x": -27,
      "y": 10,
      "z": 20,
      "name": "Soil_Clay_Green"
    },
    {
      "x": -27,
      "y": 11,
      "z": 20,
      "name": "Soil_Seaweed_Block"
    },
    {
      "x": -27,
      "y": 12,
      "z": 20,
      "name": "Soil_Seaweed_Block"
    },
    {
      "x": -27,
      "y": 13,
      "z": 20,
      "name": "Soil_Seaweed_Block"
    },
    {
      "x": -27,
      "y": 14,
      "z": 20,
      "name": "Soil_Seaweed_Block"
    },
    {
      "x": -27,
      "y": 15,
      "z": 20,
      "name": "Soil_Seaweed_Block"
    },
    {
      "x": -27,
      "y": 16,
      "z": 20,
      "name": "Soil_Seaweed_Block"
    },
    {
      "x": -27,
      "y": 10,
      "z": 21,
      "name": "Soil_Clay_Green"
    },
    {
      "x": -27,
      "y": 11,
      "z": 21,
      "name": "Soil_Seaweed_Block"
    },
    {
      "x": -27,
      "y": 12,
      "z": 21,
      "name": "Soil_Seaweed_Block"
    },
    {
      "x": -27,
      "y": 13,
      "z": 21,
      "name": "Soil_Seaweed_Block"
    },
    {
      "x": -27,
      "y": 14,
      "z": 21,
      "name": "Soil_Seaweed_Block"
    },
    {
      "x": -27,
      "y": 15,
      "z": 21,
      "name": "Soil_Seaweed_Block"
    },
    {
      "x": -27,
      "y": 16,
      "z": 21,
      "name": "Soil_Seaweed_Block"
    },
    {
      "x": -27,
      "y": 17,
      "z": 21,
      "name": "Soil_Seaweed_Block"
    },
    {
      "x": -27,
      "y": 18,
      "z": 21,
      "name": "Soil_Seaweed_Block"
    },
    {
      "x": -27,
      "y": 8,
      "z": 22,
      "name": "Soil_Clay_Green"
    },
    {
      "x": -27,
      "y": 9,
      "z": 22,
      "name": "Soil_Clay_Green"
    },
    {
      "x": -27,
      "y": 10,
      "z": 22,
      "name": "Soil_Seaweed_Block"
    },
    {
      "x": -27,
      "y": 11,
      "z": 22,
      "name": "Soil_Seaweed_Block"
    },
    {
      "x": -27,
      "y": 12,
      "z": 22,
      "name": "Soil_Seaweed_Block"
    },
    {
      "x": -27,
      "y": 13,
      "z": 22,
      "name": "Soil_Seaweed_Block"
    },
    {
      "x": -27,
      "y": 14,
      "z": 22,
      "name": "Soil_Seaweed_Block"
    },
    {
      "x": -27,
      "y": 15,
      "z": 22,
      "name": "Soil_Seaweed_Block"
    },
    {
      "x": -27,
      "y": 16,
      "z": 22,
      "name": "Soil_Seaweed_Block"
    },
    {
      "x": -27,
      "y": 17,
      "z": 22,
      "name": "Soil_Seaweed_Block"
    },
    {
      "x": -27,
      "y": 18,
      "z": 22,
      "name": "Soil_Seaweed_Block"
    },
    {
      "x": -27,
      "y": 19,
      "z": 22,
      "name": "Soil_Seaweed_Block"
    },
    {
      "x": -27,
      "y": 20,
      "z": 22,
      "name": "Soil_Clay_Lime"
    },
    {
      "x": -27,
      "y": 21,
      "z": 22,
      "name": "Plant_Grass_Sharp"
    },
    {
      "x": -27,
      "y": 9,
      "z": 23,
      "name": "Soil_Clay_Green"
    },
    {
      "x": -27,
      "y": 10,
      "z": 23,
      "name": "Soil_Clay_Green"
    },
    {
      "x": -27,
      "y": 11,
      "z": 23,
      "name": "Soil_Clay_Green"
    },
    {
      "x": -27,
      "y": 12,
      "z": 23,
      "name": "Soil_Seaweed_Block"
    },
    {
      "x": -27,
      "y": 13,
      "z": 23,
      "name": "Soil_Seaweed_Block"
    },
    {
      "x": -27,
      "y": 14,
      "z": 23,
      "name": "Soil_Seaweed_Block"
    },
    {
      "x": -27,
      "y": 15,
      "z": 23,
      "name": "Soil_Seaweed_Block"
    },
    {
      "x": -27,
      "y": 16,
      "z": 23,
      "name": "Soil_Clay_Green"
    },
    {
      "x": -27,
      "y": 17,
      "z": 23,
      "name": "Soil_Clay_Green"
    },
    {
      "x": -27,
      "y": 18,
      "z": 23,
      "name": "Soil_Clay_Green"
    },
    {
      "x": -27,
      "y": 19,
      "z": 23,
      "name": "Soil_Seaweed_Block"
    },
    {
      "x": -27,
      "y": 20,
      "z": 23,
      "name": "Soil_Clay_Lime"
    },
    {
      "x": -27,
      "y": 21,
      "z": 23,
      "name": "Plant_Grass_Sharp"
    },
    {
      "x": -27,
      "y": 9,
      "z": 24,
      "name": "Soil_Clay_Green"
    },
    {
      "x": -27,
      "y": 10,
      "z": 24,
      "name": "Soil_Seaweed_Block"
    },
    {
      "x": -27,
      "y": 11,
      "z": 24,
      "name": "Soil_Seaweed_Block"
    },
    {
      "x": -27,
      "y": 12,
      "z": 24,
      "name": "Soil_Seaweed_Block"
    },
    {
      "x": -27,
      "y": 13,
      "z": 24,
      "name": "Soil_Seaweed_Block"
    },
    {
      "x": -27,
      "y": 16,
      "z": 24,
      "name": "Soil_Seaweed_Block"
    },
    {
      "x": -27,
      "y": 17,
      "z": 24,
      "name": "Soil_Clay_Green"
    },
    {
      "x": -27,
      "y": 18,
      "z": 24,
      "name": "Soil_Clay_Green"
    },
    {
      "x": -27,
      "y": 19,
      "z": 24,
      "name": "Soil_Clay_Green"
    },
    {
      "x": -27,
      "y": 20,
      "z": 24,
      "name": "Soil_Seaweed_Block"
    },
    {
      "x": -27,
      "y": 21,
      "z": 24,
      "name": "Soil_Clay_Lime"
    },
    {
      "x": -27,
      "y": 22,
      "z": 24,
      "name": "Plant_Grass_Sharp"
    },
    {
      "x": -27,
      "y": 10,
      "z": 25,
      "name": "Soil_Clay_Green"
    },
    {
      "x": -27,
      "y": 11,
      "z": 25,
      "name": "Soil_Seaweed_Block"
    },
    {
      "x": -27,
      "y": 12,
      "z": 25,
      "name": "Soil_Seaweed_Block"
    },
    {
      "x": -27,
      "y": 20,
      "z": 25,
      "name": "Soil_Clay_Green"
    },
    {
      "x": -27,
      "y": 21,
      "z": 25,
      "name": "Soil_Seaweed_Block"
    },
    {
      "x": -27,
      "y": 22,
      "z": 25,
      "name": "Soil_Clay_Lime"
    },
    {
      "x": -27,
      "y": 23,
      "z": 25,
      "name": "Soil_Clay_Lime"
    },
    {
      "x": -27,
      "y": 24,
      "z": 25,
      "name": "Plant_Grass_Sharp"
    },
    {
      "x": -27,
      "y": 10,
      "z": 26,
      "name": "Soil_Clay_Green"
    },
    {
      "x": -27,
      "y": 11,
      "z": 26,
      "name": "Soil_Clay_Green"
    },
    {
      "x": -27,
      "y": 12,
      "z": 26,
      "name": "Soil_Seaweed_Block"
    },
    {
      "x": -27,
      "y": 13,
      "z": 26,
      "name": "Soil_Seaweed_Block"
    },
    {
      "x": -27,
      "y": 20,
      "z": 26,
      "name": "Soil_Clay_Green"
    },
    {
      "x": -27,
      "y": 21,
      "z": 26,
      "name": "Soil_Seaweed_Block"
    },
    {
      "x": -27,
      "y": 22,
      "z": 26,
      "name": "Soil_Seaweed_Block"
    },
    {
      "x": -27,
      "y": 23,
      "z": 26,
      "name": "Soil_Clay_Lime"
    },
    {
      "x": -27,
      "y": 24,
      "z": 26,
      "name": "Plant_Grass_Sharp"
    },
    {
      "x": -27,
      "y": 10,
      "z": 27,
      "name": "Soil_Clay_Green"
    },
    {
      "x": -27,
      "y": 11,
      "z": 27,
      "name": "Soil_Seaweed_Block"
    },
    {
      "x": -27,
      "y": 12,
      "z": 27,
      "name": "Soil_Seaweed_Block"
    },
    {
      "x": -27,
      "y": 13,
      "z": 27,
      "name": "Soil_Seaweed_Block"
    },
    {
      "x": -27,
      "y": 14,
      "z": 27,
      "name": "Soil_Clay_Lime"
    },
    {
      "x": -27,
      "y": 15,
      "z": 27,
      "name": "Plant_Grass_Sharp"
    },
    {
      "x": -27,
      "y": 21,
      "z": 27,
      "name": "Soil_Clay_Green"
    },
    {
      "x": -27,
      "y": 22,
      "z": 27,
      "name": "Soil_Seaweed_Block"
    },
    {
      "x": -27,
      "y": 10,
      "z": 28,
      "name": "Soil_Clay_Green"
    },
    {
      "x": -27,
      "y": 11,
      "z": 28,
      "name": "Soil_Seaweed_Block"
    },
    {
      "x": -27,
      "y": 12,
      "z": 28,
      "name": "Soil_Seaweed_Block"
    },
    {
      "x": -27,
      "y": 13,
      "z": 28,
      "name": "Soil_Seaweed_Block"
    },
    {
      "x": -27,
      "y": 14,
      "z": 28,
      "name": "Soil_Clay_Lime"
    },
    {
      "x": -27,
      "y": 15,
      "z": 28,
      "name": "Plant_Grass_Sharp"
    },
    {
      "x": -27,
      "y": 21,
      "z": 28,
      "name": "Soil_Clay_Green"
    },
    {
      "x": -27,
      "y": 22,
      "z": 28,
      "name": "Soil_Clay_Green"
    },
    {
      "x": -27,
      "y": 9,
      "z": 29,
      "name": "Soil_Clay_Green"
    },
    {
      "x": -27,
      "y": 10,
      "z": 29,
      "name": "Soil_Seaweed_Block"
    },
    {
      "x": -27,
      "y": 11,
      "z": 29,
      "name": "Soil_Seaweed_Block"
    },
    {
      "x": -27,
      "y": 12,
      "z": 29,
      "name": "Soil_Seaweed_Block"
    },
    {
      "x": -27,
      "y": 13,
      "z": 29,
      "name": "Soil_Seaweed_Block"
    },
    {
      "x": -27,
      "y": 14,
      "z": 29,
      "name": "Soil_Seaweed_Block"
    },
    {
      "x": -27,
      "y": 8,
      "z": 30,
      "name": "Soil_Clay_Green"
    },
    {
      "x": -27,
      "y": 9,
      "z": 30,
      "name": "Soil_Seaweed_Block"
    },
    {
      "x": -27,
      "y": 10,
      "z": 30,
      "name": "Soil_Clay_Green"
    },
    {
      "x": -27,
      "y": 11,
      "z": 30,
      "name": "Soil_Seaweed_Block"
    },
    {
      "x": -27,
      "y": 12,
      "z": 30,
      "name": "Soil_Seaweed_Block"
    },
    {
      "x": -27,
      "y": 9,
      "z": 31,
      "name": "Soil_Clay_Green"
    },
    {
      "x": -27,
      "y": 19,
      "z": 31,
      "name": "Soil_Clay_Green"
    },
    {
      "x": -27,
      "y": 20,
      "z": 31,
      "name": "Soil_Seaweed_Block"
    },
    {
      "x": -27,
      "y": 21,
      "z": 31,
      "name": "Soil_Clay_Lime"
    },
    {
      "x": -27,
      "y": 22,
      "z": 31,
      "name": "Plant_Grass_Sharp"
    },
    {
      "x": -27,
      "y": 19,
      "z": 32,
      "name": "Soil_Clay_Green"
    },
    {
      "x": -27,
      "y": 20,
      "z": 32,
      "name": "Soil_Clay_Lime"
    },
    {
      "x": -27,
      "y": 21,
      "z": 32,
      "name": "Soil_Clay_Lime"
    },
    {
      "x": -27,
      "y": 22,
      "z": 32,
      "name": "Plant_Grass_Sharp"
    },
    {
      "x": -27,
      "y": 18,
      "z": 33,
      "name": "Soil_Clay_Green"
    },
    {
      "x": -27,
      "y": 19,
      "z": 33,
      "name": "Soil_Seaweed_Block"
    },
    {
      "x": -27,
      "y": 20,
      "z": 33,
      "name": "Soil_Seaweed_Block"
    },
    {
      "x": -27,
      "y": 21,
      "z": 33,
      "name": "Soil_Clay_Lime"
    },
    {
      "x": -27,
      "y": 22,
      "z": 33,
      "name": "Plant_Grass_Sharp"
    },
    {
      "x": -27,
      "y": 18,
      "z": 34,
      "name": "Soil_Clay_Green"
    },
    {
      "x": -27,
      "y": 19,
      "z": 34,
      "name": "Soil_Seaweed_Block"
    },
    {
      "x": -27,
      "y": 20,
      "z": 34,
      "name": "Soil_Seaweed_Block"
    },
    {
      "x": -27,
      "y": 21,
      "z": 34,
      "name": "Soil_Clay_Lime"
    },
    {
      "x": -27,
      "y": 22,
      "z": 34,
      "name": "Plant_Grass_Sharp"
    },
    {
      "x": -27,
      "y": 18,
      "z": 35,
      "name": "Soil_Clay_Green"
    },
    {
      "x": -27,
      "y": 19,
      "z": 35,
      "name": "Soil_Seaweed_Block"
    },
    {
      "x": -27,
      "y": 20,
      "z": 35,
      "name": "Soil_Seaweed_Block"
    },
    {
      "x": -27,
      "y": 21,
      "z": 35,
      "name": "Soil_Clay_Lime"
    },
    {
      "x": -27,
      "y": 22,
      "z": 35,
      "name": "Plant_Grass_Sharp"
    },
    {
      "x": -27,
      "y": 18,
      "z": 36,
      "name": "Soil_Clay_Green"
    },
    {
      "x": -27,
      "y": 19,
      "z": 36,
      "name": "Soil_Seaweed_Block"
    },
    {
      "x": -27,
      "y": 20,
      "z": 36,
      "name": "Soil_Clay_Lime"
    },
    {
      "x": -27,
      "y": 21,
      "z": 36,
      "name": "Plant_Grass_Sharp"
    },
    {
      "x": -27,
      "y": 17,
      "z": 37,
      "name": "Soil_Clay_Green"
    },
    {
      "x": -27,
      "y": 18,
      "z": 37,
      "name": "Soil_Seaweed_Block"
    },
    {
      "x": -27,
      "y": 19,
      "z": 37,
      "name": "Soil_Seaweed_Block"
    },
    {
      "x": -27,
      "y": 17,
      "z": 38,
      "name": "Soil_Clay_Green"
    },
    {
      "x": -27,
      "y": 18,
      "z": 38,
      "name": "Soil_Clay_Green"
    },
    {
      "x": -27,
      "y": 19,
      "z": 38,
      "name": "Soil_Seaweed_Block"
    },
    {
      "x": -27,
      "y": 20,
      "z": 43,
      "name": "Soil_Seaweed_Block"
    },
    {
      "x": -27,
      "y": 20,
      "z": 44,
      "name": "Soil_Seaweed_Block"
    },
    {
      "x": -27,
      "y": 20,
      "z": 45,
      "name": "Soil_Seaweed_Block"
    },
    {
      "x": -26,
      "y": 19,
      "z": -16,
      "name": "Soil_Clay_Green"
    },
    {
      "x": -26,
      "y": 20,
      "z": -16,
      "name": "Soil_Seaweed_Block"
    },
    {
      "x": -26,
      "y": 19,
      "z": -15,
      "name": "Soil_Clay_Green"
    },
    {
      "x": -26,
      "y": 20,
      "z": -15,
      "name": "Soil_Seaweed_Block"
    },
    {
      "x": -26,
      "y": 9,
      "z": 17,
      "name": "Soil_Clay_Green"
    },
    {
      "x": -26,
      "y": 10,
      "z": 17,
      "name": "Soil_Clay_Green"
    },
    {
      "x": -26,
      "y": 11,
      "z": 17,
      "name": "Soil_Clay_Green"
    },
    {
      "x": -26,
      "y": 12,
      "z": 17,
      "name": "Soil_Seaweed_Block"
    },
    {
      "x": -26,
      "y": 7,
      "z": 18,
      "name": "Soil_Clay_Green"
    },
    {
      "x": -26,
      "y": 8,
      "z": 18,
      "name": "Soil_Clay_Green"
    },
    {
      "x": -26,
      "y": 9,
      "z": 18,
      "name": "Soil_Seaweed_Block"
    },
    {
      "x": -26,
      "y": 10,
      "z": 18,
      "name": "Soil_Seaweed_Block"
    },
    {
      "x": -26,
      "y": 11,
      "z": 18,
      "name": "Soil_Seaweed_Block"
    },
    {
      "x": -26,
      "y": 12,
      "z": 18,
      "name": "Soil_Seaweed_Block"
    },
    {
      "x": -26,
      "y": 13,
      "z": 18,
      "name": "Soil_Seaweed_Block"
    },
    {
      "x": -26,
      "y": 14,
      "z": 18,
      "name": "Soil_Seaweed_Block"
    },
    {
      "x": -26,
      "y": 15,
      "z": 18,
      "name": "Soil_Seaweed_Block"
    },
    {
      "x": -26,
      "y": 16,
      "z": 18,
      "name": "Soil_Seaweed_Block"
    },
    {
      "x": -26,
      "y": 8,
      "z": 19,
      "name": "Soil_Clay_Green"
    },
    {
      "x": -26,
      "y": 9,
      "z": 19,
      "name": "Soil_Clay_Green"
    },
    {
      "x": -26,
      "y": 10,
      "z": 19,
      "name": "Soil_Seaweed_Block"
    },
    {
      "x": -26,
      "y": 11,
      "z": 19,
      "name": "Soil_Seaweed_Block"
    },
    {
      "x": -26,
      "y": 12,
      "z": 19,
      "name": "Soil_Seaweed_Block"
    },
    {
      "x": -26,
      "y": 13,
      "z": 19,
      "name": "Soil_Seaweed_Block"
    },
    {
      "x": -26,
      "y": 14,
      "z": 19,
      "name": "Soil_Seaweed_Block"
    },
    {
      "x": -26,
      "y": 15,
      "z": 19,
      "name": "Soil_Seaweed_Block"
    },
    {
      "x": -26,
      "y": 16,
      "z": 19,
      "name": "Soil_Seaweed_Block"
    },
    {
      "x": -26,
      "y": 17,
      "z": 19,
      "name": "Soil_Seaweed_Block"
    },
    {
      "x": -26,
      "y": 9,
      "z": 20,
      "name": "Soil_Clay_Green"
    },
    {
      "x": -26,
      "y": 10,
      "z": 20,
      "name": "Soil_Seaweed_Block"
    },
    {
      "x": -26,
      "y": 11,
      "z": 20,
      "name": "Soil_Seaweed_Block"
    },
    {
      "x": -26,
      "y": 12,
      "z": 20,
      "name": "Soil_Seaweed_Block"
    },
    {
      "x": -26,
      "y": 13,
      "z": 20,
      "name": "Soil_Seaweed_Block"
    },
    {
      "x": -26,
      "y": 14,
      "z": 20,
      "name": "Soil_Seaweed_Block"
    },
    {
      "x": -26,
      "y": 15,
      "z": 20,
      "name": "Soil_Seaweed_Block"
    },
    {
      "x": -26,
      "y": 16,
      "z": 20,
      "name": "Soil_Seaweed_Block"
    },
    {
      "x": -26,
      "y": 17,
      "z": 20,
      "name": "Soil_Seaweed_Block"
    },
    {
      "x": -26,
      "y": 18,
      "z": 20,
      "name": "Soil_Seaweed_Block"
    },
    {
      "x": -26,
      "y": 8,
      "z": 21,
      "name": "Soil_Clay_Green"
    },
    {
      "x": -26,
      "y": 9,
      "z": 21,
      "name": "Soil_Clay_Green"
    },
    {
      "x": -26,
      "y": 10,
      "z": 21,
      "name": "Soil_Seaweed_Block"
    },
    {
      "x": -26,
      "y": 11,
      "z": 21,
      "name": "Soil_Seaweed_Block"
    },
    {
      "x": -26,
      "y": 12,
      "z": 21,
      "name": "Soil_Seaweed_Block"
    },
    {
      "x": -26,
      "y": 13,
      "z": 21,
      "name": "Soil_Seaweed_Block"
    },
    {
      "x": -26,
      "y": 14,
      "z": 21,
      "name": "Soil_Seaweed_Block"
    },
    {
      "x": -26,
      "y": 15,
      "z": 21,
      "name": "Soil_Seaweed_Block"
    },
    {
      "x": -26,
      "y": 16,
      "z": 21,
      "name": "Soil_Seaweed_Block"
    },
    {
      "x": -26,
      "y": 17,
      "z": 21,
      "name": "Soil_Seaweed_Block"
    },
    {
      "x": -26,
      "y": 18,
      "z": 21,
      "name": "Soil_Seaweed_Block"
    },
    {
      "x": -26,
      "y": 19,
      "z": 21,
      "name": "Soil_Clay_Lime"
    },
    {
      "x": -26,
      "y": 20,
      "z": 21,
      "name": "Plant_Grass_Sharp"
    },
    {
      "x": -26,
      "y": 7,
      "z": 22,
      "name": "Soil_Clay_Green"
    },
    {
      "x": -26,
      "y": 8,
      "z": 22,
      "name": "Soil_Seaweed_Block"
    },
    {
      "x": -26,
      "y": 9,
      "z": 22,
      "name": "Soil_Seaweed_Block"
    },
    {
      "x": -26,
      "y": 10,
      "z": 22,
      "name": "Soil_Seaweed_Block"
    },
    {
      "x": -26,
      "y": 11,
      "z": 22,
      "name": "Soil_Seaweed_Block"
    },
    {
      "x": -26,
      "y": 12,
      "z": 22,
      "name": "Soil_Seaweed_Block"
    },
    {
      "x": -26,
      "y": 13,
      "z": 22,
      "name": "Soil_Seaweed_Block"
    },
    {
      "x": -26,
      "y": 14,
      "z": 22,
      "name": "Soil_Seaweed_Block"
    },
    {
      "x": -26,
      "y": 15,
      "z": 22,
      "name": "Soil_Seaweed_Block"
    },
    {
      "x": -26,
      "y": 16,
      "z": 22,
      "name": "Soil_Seaweed_Block"
    },
    {
      "x": -26,
      "y": 17,
      "z": 22,
      "name": "Soil_Seaweed_Block"
    },
    {
      "x": -26,
      "y": 18,
      "z": 22,
      "name": "Soil_Seaweed_Block"
    },
    {
      "x": -26,
      "y": 19,
      "z": 22,
      "name": "Soil_Seaweed_Block"
    },
    {
      "x": -26,
      "y": 20,
      "z": 22,
      "name": "Soil_Clay_Lime"
    },
    {
      "x": -26,
      "y": 21,
      "z": 22,
      "name": "Plant_Grass_Sharp"
    },
    {
      "x": -26,
      "y": 8,
      "z": 23,
      "name": "Soil_Clay_Green"
    },
    {
      "x": -26,
      "y": 9,
      "z": 23,
      "name": "Soil_Seaweed_Block"
    },
    {
      "x": -26,
      "y": 10,
      "z": 23,
      "name": "Soil_Seaweed_Block"
    },
    {
      "x": -26,
      "y": 11,
      "z": 23,
      "name": "Soil_Seaweed_Block"
    },
    {
      "x": -26,
      "y": 12,
      "z": 23,
      "name": "Soil_Seaweed_Block"
    },
    {
      "x": -26,
      "y": 13,
      "z": 23,
      "name": "Soil_Seaweed_Block"
    },
    {
      "x": -26,
      "y": 14,
      "z": 23,
      "name": "Soil_Seaweed_Block"
    },
    {
      "x": -26,
      "y": 15,
      "z": 23,
      "name": "Soil_Seaweed_Block"
    },
    {
      "x": -26,
      "y": 16,
      "z": 23,
      "name": "Soil_Seaweed_Block"
    },
    {
      "x": -26,
      "y": 17,
      "z": 23,
      "name": "Soil_Seaweed_Block"
    },
    {
      "x": -26,
      "y": 18,
      "z": 23,
      "name": "Soil_Seaweed_Block"
    },
    {
      "x": -26,
      "y": 19,
      "z": 23,
      "name": "Soil_Seaweed_Block"
    },
    {
      "x": -26,
      "y": 20,
      "z": 23,
      "name": "Soil_Seaweed_Block"
    },
    {
      "x": -26,
      "y": 21,
      "z": 23,
      "name": "Soil_Clay_Lime"
    },
    {
      "x": -26,
      "y": 22,
      "z": 23,
      "name": "Plant_Grass_Sharp"
    },
    {
      "x": -26,
      "y": 8,
      "z": 24,
      "name": "Soil_Clay_Green"
    },
    {
      "x": -26,
      "y": 9,
      "z": 24,
      "name": "Soil_Seaweed_Block"
    },
    {
      "x": -26,
      "y": 10,
      "z": 24,
      "name": "Soil_Seaweed_Block"
    },
    {
      "x": -26,
      "y": 11,
      "z": 24,
      "name": "Soil_Seaweed_Block"
    },
    {
      "x": -26,
      "y": 12,
      "z": 24,
      "name": "Soil_Seaweed_Block"
    },
    {
      "x": -26,
      "y": 13,
      "z": 24,
      "name": "Soil_Seaweed_Block"
    },
    {
      "x": -26,
      "y": 14,
      "z": 24,
      "name": "Soil_Seaweed_Block"
    },
    {
      "x": -26,
      "y": 15,
      "z": 24,
      "name": "Soil_Seaweed_Block"
    },
    {
      "x": -26,
      "y": 16,
      "z": 24,
      "name": "Soil_Seaweed_Block"
    },
    {
      "x": -26,
      "y": 17,
      "z": 24,
      "name": "Soil_Clay_Green"
    },
    {
      "x": -26,
      "y": 18,
      "z": 24,
      "name": "Soil_Clay_Green"
    },
    {
      "x": -26,
      "y": 19,
      "z": 24,
      "name": "Soil_Seaweed_Block"
    },
    {
      "x": -26,
      "y": 20,
      "z": 24,
      "name": "Soil_Seaweed_Block"
    },
    {
      "x": -26,
      "y": 21,
      "z": 24,
      "name": "Soil_Clay_Lime"
    },
    {
      "x": -26,
      "y": 22,
      "z": 24,
      "name": "Plant_Grass_Sharp"
    },
    {
      "x": -26,
      "y": 8,
      "z": 25,
      "name": "Soil_Clay_Green"
    },
    {
      "x": -26,
      "y": 9,
      "z": 25,
      "name": "Soil_Clay_Green"
    },
    {
      "x": -26,
      "y": 10,
      "z": 25,
      "name": "Soil_Seaweed_Block"
    },
    {
      "x": -26,
      "y": 11,
      "z": 25,
      "name": "Soil_Seaweed_Block"
    },
    {
      "x": -26,
      "y": 12,
      "z": 25,
      "name": "Soil_Seaweed_Block"
    },
    {
      "x": -26,
      "y": 13,
      "z": 25,
      "name": "Soil_Seaweed_Block"
    },
    {
      "x": -26,
      "y": 19,
      "z": 25,
      "name": "Soil_Clay_Green"
    },
    {
      "x": -26,
      "y": 20,
      "z": 25,
      "name": "Soil_Seaweed_Block"
    },
    {
      "x": -26,
      "y": 21,
      "z": 25,
      "name": "Soil_Clay_Lime"
    },
    {
      "x": -26,
      "y": 22,
      "z": 25,
      "name": "Plant_Grass_Sharp"
    },
    {
      "x": -26,
      "y": 9,
      "z": 26,
      "name": "Soil_Clay_Green"
    },
    {
      "x": -26,
      "y": 10,
      "z": 26,
      "name": "Soil_Seaweed_Block"
    },
    {
      "x": -26,
      "y": 11,
      "z": 26,
      "name": "Soil_Seaweed_Block"
    },
    {
      "x": -26,
      "y": 12,
      "z": 26,
      "name": "Soil_Seaweed_Block"
    },
    {
      "x": -26,
      "y": 13,
      "z": 26,
      "name": "Soil_Seaweed_Block"
    },
    {
      "x": -26,
      "y": 14,
      "z": 26,
      "name": "Soil_Clay_Lime"
    },
    {
      "x": -26,
      "y": 15,
      "z": 26,
      "name": "Plant_Grass_Sharp"
    },
    {
      "x": -26,
      "y": 20,
      "z": 26,
      "name": "Soil_Clay_Green"
    },
    {
      "x": -26,
      "y": 21,
      "z": 26,
      "name": "Soil_Seaweed_Block"
    },
    {
      "x": -26,
      "y": 22,
      "z": 26,
      "name": "Soil_Seaweed_Block"
    },
    {
      "x": -26,
      "y": 9,
      "z": 27,
      "name": "Soil_Clay_Green"
    },
    {
      "x": -26,
      "y": 10,
      "z": 27,
      "name": "Soil_Seaweed_Block"
    },
    {
      "x": -26,
      "y": 11,
      "z": 27,
      "name": "Soil_Seaweed_Block"
    },
    {
      "x": -26,
      "y": 12,
      "z": 27,
      "name": "Soil_Seaweed_Block"
    },
    {
      "x": -26,
      "y": 13,
      "z": 27,
      "name": "Soil_Seaweed_Block"
    },
    {
      "x": -26,
      "y": 14,
      "z": 27,
      "name": "Soil_Clay_Lime"
    },
    {
      "x": -26,
      "y": 15,
      "z": 27,
      "name": "Plant_Grass_Sharp"
    },
    {
      "x": -26,
      "y": 9,
      "z": 28,
      "name": "Soil_Clay_Green"
    },
    {
      "x": -26,
      "y": 10,
      "z": 28,
      "name": "Soil_Seaweed_Block"
    },
    {
      "x": -26,
      "y": 11,
      "z": 28,
      "name": "Soil_Seaweed_Block"
    },
    {
      "x": -26,
      "y": 12,
      "z": 28,
      "name": "Soil_Seaweed_Block"
    },
    {
      "x": -26,
      "y": 13,
      "z": 28,
      "name": "Soil_Seaweed_Block"
    },
    {
      "x": -26,
      "y": 14,
      "z": 28,
      "name": "Soil_Seaweed_Block"
    },
    {
      "x": -26,
      "y": 15,
      "z": 28,
      "name": "Soil_Clay_Lime"
    },
    {
      "x": -26,
      "y": 16,
      "z": 28,
      "name": "Plant_Grass_Sharp"
    },
    {
      "x": -26,
      "y": 9,
      "z": 29,
      "name": "Soil_Clay_Green"
    },
    {
      "x": -26,
      "y": 10,
      "z": 29,
      "name": "Soil_Seaweed_Block"
    },
    {
      "x": -26,
      "y": 11,
      "z": 29,
      "name": "Soil_Seaweed_Block"
    },
    {
      "x": -26,
      "y": 12,
      "z": 29,
      "name": "Soil_Seaweed_Block"
    },
    {
      "x": -26,
      "y": 13,
      "z": 29,
      "name": "Soil_Seaweed_Block"
    },
    {
      "x": -26,
      "y": 14,
      "z": 29,
      "name": "Soil_Seaweed_Block"
    },
    {
      "x": -26,
      "y": 15,
      "z": 29,
      "name": "Soil_Seaweed_Block"
    },
    {
      "x": -26,
      "y": 9,
      "z": 30,
      "name": "Soil_Clay_Green"
    },
    {
      "x": -26,
      "y": 10,
      "z": 30,
      "name": "Soil_Clay_Green"
    },
    {
      "x": -26,
      "y": 11,
      "z": 30,
      "name": "Soil_Seaweed_Block"
    },
    {
      "x": -26,
      "y": 12,
      "z": 30,
      "name": "Soil_Seaweed_Block"
    },
    {
      "x": -26,
      "y": 13,
      "z": 30,
      "name": "Soil_Seaweed_Block"
    },
    {
      "x": -26,
      "y": 14,
      "z": 30,
      "name": "Soil_Seaweed_Block"
    },
    {
      "x": -26,
      "y": 18,
      "z": 30,
      "name": "Soil_Clay_Green"
    },
    {
      "x": -26,
      "y": 19,
      "z": 30,
      "name": "Soil_Seaweed_Block"
    },
    {
      "x": -26,
      "y": 8,
      "z": 31,
      "name": "Soil_Clay_Green"
    },
    {
      "x": -26,
      "y": 9,
      "z": 31,
      "name": "Soil_Clay_Green"
    },
    {
      "x": -26,
      "y": 10,
      "z": 31,
      "name": "Soil_Clay_Green"
    },
    {
      "x": -26,
      "y": 18,
      "z": 31,
      "name": "Soil_Clay_Green"
    },
    {
      "x": -26,
      "y": 19,
      "z": 31,
      "name": "Soil_Seaweed_Block"
    },
    {
      "x": -26,
      "y": 20,
      "z": 31,
      "name": "Soil_Clay_Lime"
    },
    {
      "x": -26,
      "y": 21,
      "z": 31,
      "name": "Plant_Grass_Sharp"
    },
    {
      "x": -26,
      "y": 18,
      "z": 32,
      "name": "Soil_Clay_Green"
    },
    {
      "x": -26,
      "y": 19,
      "z": 32,
      "name": "Soil_Seaweed_Block"
    },
    {
      "x": -26,
      "y": 20,
      "z": 32,
      "name": "Soil_Seaweed_Block"
    },
    {
      "x": -26,
      "y": 21,
      "z": 32,
      "name": "Soil_Clay_Lime"
    },
    {
      "x": -26,
      "y": 22,
      "z": 32,
      "name": "Plant_Grass_Sharp"
    },
    {
      "x": -26,
      "y": 18,
      "z": 33,
      "name": "Soil_Clay_Green"
    },
    {
      "x": -26,
      "y": 19,
      "z": 33,
      "name": "Soil_Seaweed_Block"
    },
    {
      "x": -26,
      "y": 20,
      "z": 33,
      "name": "Soil_Seaweed_Block"
    },
    {
      "x": -26,
      "y": 21,
      "z": 33,
      "name": "Soil_Clay_Lime"
    },
    {
      "x": -26,
      "y": 22,
      "z": 33,
      "name": "Plant_Grass_Sharp"
    },
    {
      "x": -26,
      "y": 19,
      "z": 34,
      "name": "Soil_Clay_Green"
    },
    {
      "x": -26,
      "y": 20,
      "z": 34,
      "name": "Soil_Seaweed_Block"
    },
    {
      "x": -26,
      "y": 21,
      "z": 34,
      "name": "Soil_Clay_Lime"
    },
    {
      "x": -26,
      "y": 22,
      "z": 34,
      "name": "Plant_Grass_Sharp"
    },
    {
      "x": -26,
      "y": 19,
      "z": 35,
      "name": "Soil_Clay_Green"
    },
    {
      "x": -26,
      "y": 20,
      "z": 35,
      "name": "Soil_Clay_Lime"
    },
    {
      "x": -26,
      "y": 21,
      "z": 35,
      "name": "Soil_Clay_Lime"
    },
    {
      "x": -26,
      "y": 22,
      "z": 35,
      "name": "Plant_Grass_Sharp"
    },
    {
      "x": -26,
      "y": 19,
      "z": 36,
      "name": "Soil_Clay_Green"
    },
    {
