{
  "version": 8,
  "blockIdVersion": 10,
  "anchorX": 0,
  "anchorY": 10,
  "anchorZ": 0,
  "blocks": [
    {
      "x": -56,
      "y": 17,
      "z": 3,
      "name": "Soil_Clay_Green"
    },
    {
      "x": -56,
      "y": 17,
      "z": 4,
      "name": "Soil_Clay_Green"
    },
    {
      "x": -55,
      "y": 17,
      "z": 3,
      "name": "Soil_Seaweed_Block"
    },
    {
      "x": -55,
      "y": 17,
      "z": 4,
      "name": "Soil_Seaweed_Block"
    },
    {
      "x": -54,
      "y": 17,
      "z": 3,
      "name": "Soil_Clay_Lime"
    },
    {
      "x": -54,
      "y": 18,
      "z": 3,
      "name": "Plant_Grass_Sharp"
    },
    {
      "x": -54,
      "y": 17,
      "z": 4,
      "name": "Soil_Clay_Lime"
    },
    {
      "x": -54,
      "y": 18,
      "z": 4,
      "name": "Plant_Grass_Sharp"
    },
    {
      "x": -53,
      "y": 16,
      "z": 3,
      "name": "Soil_Seaweed_Block"
    },
    {
      "x": -53,
      "y": 13,
      "z": 9,
      "name": "Soil_Clay_Green"
    },
    {
      "x": -53,
      "y": 13,
      "z": 10,
      "name": "Soil_Clay_Green"
    },
    {
      "x": -53,
      "y": 13,
      "z": 11,
      "name": "Soil_Clay_Green"
    },
    {
      "x": -52,
      "y": 14,
      "z": 3,
      "name": "Soil_Clay_Green"
    },
    {
      "x": -52,
      "y": 15,
      "z": 3,
      "name": "Soil_Clay_Green"
    },
    {
      "x": -52,
      "y": 16,
      "z": 3,
      "name": "Soil_Seaweed_Block"
    },
    {
      "x": -52,
      "y": 15,
      "z": 4,
      "name": "Soil_Clay_Green"
    },
    {
      "x": -52,
      "y": 13,
      "z": 9,
      "name": "Soil_Clay_Green"
    },
    {
      "x": -52,
      "y": 14,
      "z": 9,
      "name": "Soil_Clay_Green"
    },
    {
      "x": -52,
      "y": 13,
      "z": 10,
      "name": "Soil_Clay_Green"
    },
    {
      "x": -52,
      "y": 14,
      "z": 10,
      "name": "Soil_Clay_Green"
    },
    {
      "x": -52,
      "y": 13,
      "z": 11,
      "name": "Soil_Clay_Green"
    },
    {
      "x": -51,
      "y": 15,
      "z": 3,
      "name": "Soil_Clay_Green"
    },
    {
      "x": -51,
      "y": 16,
      "z": 3,
      "name": "Soil_Clay_Lime"
    },
    {
      "x": -51,
      "y": 17,
      "z": 3,
      "name": "Plant_Grass_Sharp"
    },
    {
      "x": -51,
      "y": 15,
      "z": 4,
      "name": "Soil_Clay_Green"
    },
    {
      "x": -51,
      "y": 16,
      "z": 4,
      "name": "Soil_Clay_Lime"
    },
    {
      "x": -51,
      "y": 17,
      "z": 4,
      "name": "Plant_Grass_Sharp"
    },
    {
      "x": -51,
      "y": 13,
      "z": 9,
      "name": "Soil_Clay_Green"
    },
    {
      "x": -51,
      "y": 14,
      "z": 9,
      "name": "Soil_Clay_Green"
    },
    {
      "x": -51,
      "y": 15,
      "z": 9,
      "name": "Soil_Clay_Lime"
    },
    {
      "x": -51,
      "y": 16,
      "z": 9,
      "name": "Plant_Grass_Sharp"
    },
    {
      "x": -51,
      "y": 13,
      "z": 10,
      "name": "Soil_Clay_Green"
    },
    {
      "x": -51,
      "y": 14,
      "z": 10,
      "name": "Soil_Clay_Green"
    },
    {
      "x": -51,
      "y": 15,
      "z": 10,
      "name": "Soil_Clay_Lime"
    },
    {
      "x": -51,
      "y": 16,
      "z": 10,
      "name": "Plant_Grass_Sharp"
    },
    {
      "x": -50,
      "y": 15,
      "z": 3,
      "name": "Soil_Clay_Green"
    },
    {
      "x": -50,
      "y": 16,
      "z": 3,
      "name": "Soil_Clay_Lime"
    },
    {
      "x": -50,
      "y": 17,
      "z": 3,
      "name": "Plant_Grass_Sharp"
    },
    {
      "x": -50,
      "y": 14,
      "z": 4,
      "name": "Soil_Clay_Green"
    },
    {
      "x": -50,
      "y": 15,
      "z": 4,
      "name": "Soil_Seaweed_Block"
    },
    {
      "x": -50,
      "y": 16,
      "z": 4,
      "name": "Soil_Clay_Lime"
    },
    {
      "x": -50,
      "y": 17,
      "z": 4,
      "name": "Plant_Grass_Sharp"
    },
    {
      "x": -50,
      "y": 15,
      "z": 5,
      "name": "Soil_Seaweed_Block"
    },
    {
      "x": -50,
      "y": 14,
      "z": 8,
      "name": "Soil_Clay_Green"
    },
    {
      "x": -50,
      "y": 15,
      "z": 8,
      "name": "Soil_Clay_Lime"
    },
    {
      "x": -50,
      "y": 16,
      "z": 8,
      "name": "Soil_Clay_Lime"
    },
    {
      "x": -50,
      "y": 17,
      "z": 8,
      "name": "Plant_Grass_Sharp"
    },
    {
      "x": -50,
      "y": 13,
      "z": 9,
      "name": "Soil_Clay_Green"
    },
    {
      "x": -50,
      "y": 14,
      "z": 9,
      "name": "Soil_Seaweed_Block"
    },
    {
      "x": -50,
      "y": 15,
      "z": 9,
      "name": "Soil_Seaweed_Block"
    },
    {
      "x": -50,
      "y": 16,
      "z": 9,
      "name": "Soil_Clay_Lime"
    },
    {
      "x": -50,
      "y": 17,
      "z": 9,
      "name": "Plant_Grass_Sharp"
    },
    {
      "x": -50,
      "y": 23,
      "z": 9,
      "name": "Soil_Clay_Green"
    },
    {
      "x": -50,
      "y": 14,
      "z": 10,
      "name": "Soil_Clay_Green"
    },
    {
      "x": -50,
      "y": 15,
      "z": 10,
      "name": "Soil_Seaweed_Block"
    },
    {
      "x": -50,
      "y": 22,
      "z": 10,
      "name": "Soil_Clay_Green"
    },
    {
      "x": -50,
      "y": 23,
      "z": 10,
      "name": "Soil_Clay_Green"
    },
    {
      "x": -50,
      "y": 24,
      "z": 27,
      "name": "Soil_Clay_Green"
    },
    {
      "x": -50,
      "y": 24,
      "z": 28,
      "name": "Soil_Clay_Green"
    },
    {
      "x": -49,
      "y": 14,
      "z": 5,
      "name": "Soil_Clay_Green"
    },
    {
      "x": -49,
      "y": 15,
      "z": 5,
      "name": "Soil_Seaweed_Block"
    },
    {
      "x": -49,
      "y": 13,
      "z": 6,
      "name": "Soil_Clay_Green"
    },
    {
      "x": -49,
      "y": 14,
      "z": 7,
      "name": "Soil_Clay_Green"
    },
    {
      "x": -49,
      "y": 15,
      "z": 7,
      "name": "Soil_Seaweed_Block"
    },
    {
      "x": -49,
      "y": 14,
      "z": 8,
      "name": "Soil_Clay_Green"
    },
    {
      "x": -49,
      "y": 15,
      "z": 8,
      "name": "Soil_Seaweed_Block"
    },
    {
      "x": -49,
      "y": 16,
      "z": 8,
      "name": "Soil_Clay_Lime"
    },
    {
      "x": -49,
      "y": 17,
      "z": 8,
      "name": "Plant_Grass_Sharp"
    },
    {
      "x": -49,
      "y": 14,
      "z": 9,
      "name": "Soil_Clay_Green"
    },
    {
      "x": -49,
      "y": 15,
      "z": 9,
      "name": "Soil_Seaweed_Block"
    },
    {
      "x": -49,
      "y": 16,
      "z": 9,
      "name": "Soil_Clay_Lime"
    },
    {
      "x": -49,
      "y": 17,
      "z": 9,
      "name": "Plant_Grass_Sharp"
    },
    {
      "x": -49,
      "y": 23,
      "z": 9,
      "name": "Soil_Clay_Green"
    },
    {
      "x": -49,
      "y": 24,
      "z": 9,
      "name": "Soil_Seaweed_Block"
    },
    {
      "x": -49,
      "y": 25,
      "z": 9,
      "name": "Soil_Clay_Lime"
    },
    {
      "x": -49,
      "y": 26,
      "z": 9,
      "name": "Plant_Grass_Sharp"
    },
    {
      "x": -49,
      "y": 23,
      "z": 10,
      "name": "Soil_Clay_Green"
    },
    {
      "x": -49,
      "y": 24,
      "z": 10,
      "name": "Soil_Seaweed_Block"
    },
    {
      "x": -49,
      "y": 24,
      "z": 27,
      "name": "Soil_Clay_Green"
    },
    {
      "x": -49,
      "y": 24,
      "z": 28,
      "name": "Soil_Clay_Green"
    },
    {
      "x": -49,
      "y": 25,
      "z": 29,
      "name": "Soil_Seaweed_Block"
    },
    {
      "x": -48,
      "y": 14,
      "z": 6,
      "name": "Soil_Clay_Green"
    },
    {
      "x": -48,
      "y": 15,
      "z": 6,
      "name": "Soil_Seaweed_Block"
    },
    {
      "x": -48,
      "y": 14,
      "z": 7,
      "name": "Soil_Clay_Green"
    },
    {
      "x": -48,
      "y": 15,
      "z": 7,
      "name": "Soil_Seaweed_Block"
    },
    {
      "x": -48,
      "y": 13,
      "z": 8,
      "name": "Soil_Clay_Green"
    },
    {
      "x": -48,
      "y": 14,
      "z": 8,
      "name": "Soil_Seaweed_Block"
    },
    {
      "x": -48,
      "y": 15,
      "z": 8,
      "name": "Soil_Seaweed_Block"
    },
    {
      "x": -48,
      "y": 16,
      "z": 8,
      "name": "Soil_Clay_Lime"
    },
    {
      "x": -48,
      "y": 17,
      "z": 8,
      "name": "Plant_Grass_Sharp"
    },
    {
      "x": -48,
      "y": 24,
      "z": 8,
      "name": "Soil_Clay_Green"
    },
    {
      "x": -48,
      "y": 14,
      "z": 9,
      "name": "Soil_Clay_Green"
    },
    {
      "x": -48,
      "y": 15,
      "z": 9,
      "name": "Soil_Seaweed_Block"
    },
    {
      "x": -48,
      "y": 16,
      "z": 9,
      "name": "Soil_Clay_Lime"
    },
    {
      "x": -48,
      "y": 17,
      "z": 9,
      "name": "Plant_Grass_Sharp"
    },
    {
      "x": -48,
      "y": 23,
      "z": 9,
      "name": "Soil_Clay_Green"
    },
    {
      "x": -48,
      "y": 24,
      "z": 9,
      "name": "Soil_Clay_Green"
    },
    {
      "x": -48,
      "y": 25,
      "z": 9,
      "name": "Soil_Clay_Lime"
    },
    {
      "x": -48,
      "y": 26,
      "z": 9,
      "name": "Plant_Grass_Sharp"
    },
    {
      "x": -48,
      "y": 23,
      "z": 10,
      "name": "Soil_Clay_Green"
    },
    {
      "x": -48,
      "y": 24,
      "z": 10,
      "name": "Soil_Clay_Green"
    },
    {
      "x": -48,
      "y": 23,
      "z": 19,
      "name": "Soil_Clay_Green"
    },
    {
      "x": -48,
      "y": 23,
      "z": 20,
      "name": "Soil_Clay_Green"
    },
    {
      "x": -48,
      "y": 24,
      "z": 27,
      "name": "Soil_Clay_Green"
    },
    {
      "x": -48,
      "y": 25,
      "z": 27,
      "name": "Soil_Seaweed_Block"
    },
    {
      "x": -48,
      "y": 24,
      "z": 28,
      "name": "Soil_Clay_Green"
    },
    {
      "x": -48,
      "y": 25,
      "z": 28,
      "name": "Soil_Seaweed_Block"
    },
    {
      "x": -48,
      "y": 25,
      "z": 29,
      "name": "Soil_Seaweed_Block"
    },
    {
      "x": -47,
      "y": 14,
      "z": 5,
      "name": "Soil_Clay_Green"
    },
    {
      "x": -47,
      "y": 15,
      "z": 5,
      "name": "Soil_Seaweed_Block"
    },
    {
      "x": -47,
      "y": 14,
      "z": 6,
      "name": "Soil_Clay_Green"
    },
    {
      "x": -47,
      "y": 15,
      "z": 6,
      "name": "Soil_Seaweed_Block"
    },
    {
      "x": -47,
      "y": 16,
      "z": 6,
      "name": "Soil_Clay_Lime"
    },
    {
      "x": -47,
      "y": 17,
      "z": 6,
      "name": "Plant_Grass_Sharp"
    },
    {
      "x": -47,
      "y": 13,
      "z": 7,
      "name": "Soil_Clay_Green"
    },
    {
      "x": -47,
      "y": 14,
      "z": 7,
      "name": "Soil_Seaweed_Block"
    },
    {
      "x": -47,
      "y": 15,
      "z": 7,
      "name": "Soil_Seaweed_Block"
    },
    {
      "x": -47,
      "y": 16,
      "z": 7,
      "name": "Soil_Clay_Lime"
    },
    {
      "x": -47,
      "y": 17,
      "z": 7,
      "name": "Plant_Grass_Sharp"
    },
    {
      "x": -47,
      "y": 13,
      "z": 8,
      "name": "Soil_Clay_Green"
    },
    {
      "x": -47,
      "y": 14,
      "z": 8,
      "name": "Soil_Clay_Green"
    },
    {
      "x": -47,
      "y": 15,
      "z": 8,
      "name": "Soil_Seaweed_Block"
    },
    {
      "x": -47,
      "y": 16,
      "z": 8,
      "name": "Soil_Clay_Lime"
    },
    {
      "x": -47,
      "y": 17,
      "z": 8,
      "name": "Plant_Grass_Sharp"
    },
    {
      "x": -47,
      "y": 24,
      "z": 8,
      "name": "Soil_Clay_Green"
    },
    {
      "x": -47,
      "y": 15,
      "z": 9,
      "name": "Soil_Seaweed_Block"
    },
    {
      "x": -47,
      "y": 16,
      "z": 9,
      "name": "Soil_Clay_Lime"
    },
    {
      "x": -47,
      "y": 17,
      "z": 9,
      "name": "Plant_Grass_Sharp"
    },
    {
      "x": -47,
      "y": 25,
      "z": 9,
      "name": "Soil_Clay_Lime"
    },
    {
      "x": -47,
      "y": 26,
      "z": 9,
      "name": "Plant_Grass_Sharp"
    },
    {
      "x": -47,
      "y": 30,
      "z": 11,
      "name": "Soil_Clay_Green"
    },
    {
      "x": -47,
      "y": 31,
      "z": 11,
      "name": "Soil_Clay_Green"
    },
    {
      "x": -47,
      "y": 14,
      "z": 12,
      "name": "Soil_Clay_Green"
    },
    {
      "x": -47,
      "y": 30,
      "z": 12,
      "name": "Soil_Clay_Green"
    },
    {
      "x": -47,
      "y": 31,
      "z": 12,
      "name": "Soil_Clay_Green"
    },
    {
      "x": -47,
      "y": 14,
      "z": 13,
      "name": "Soil_Clay_Green"
    },
    {
      "x": -47,
      "y": 15,
      "z": 14,
      "name": "Soil_Seaweed_Block"
    },
    {
      "x": -47,
      "y": 18,
      "z": 16,
      "name": "Soil_Clay_Green"
    },
    {
      "x": -47,
      "y": 19,
      "z": 16,
      "name": "Soil_Seaweed_Block"
    },
    {
      "x": -47,
      "y": 18,
      "z": 17,
      "name": "Soil_Clay_Green"
    },
    {
      "x": -47,
      "y": 19,
      "z": 17,
      "name": "Soil_Seaweed_Block"
    },
    {
      "x": -47,
      "y": 30,
      "z": 17,
      "name": "Soil_Clay_Green"
    },
    {
      "x": -47,
      "y": 31,
      "z": 17,
      "name": "Soil_Seaweed_Block"
    },
    {
      "x": -47,
      "y": 30,
      "z": 18,
      "name": "Soil_Clay_Green"
    },
    {
      "x": -47,
      "y": 31,
      "z": 18,
      "name": "Soil_Seaweed_Block"
    },
    {
      "x": -47,
      "y": 23,
      "z": 20,
      "name": "Soil_Clay_Green"
    },
    {
      "x": -47,
      "y": 25,
      "z": 25,
      "name": "Soil_Seaweed_Block"
    },
    {
      "x": -47,
      "y": 25,
      "z": 26,
      "name": "Soil_Seaweed_Block"
    },
    {
      "x": -47,
      "y": 24,
      "z": 27,
      "name": "Soil_Clay_Green"
    },
    {
      "x": -47,
      "y": 25,
      "z": 27,
      "name": "Soil_Clay_Lime"
    },
    {
      "x": -47,
      "y": 26,
      "z": 27,
      "name": "Plant_Grass_Sharp"
    },
    {
      "x": -47,
      "y": 24,
      "z": 28,
      "name": "Soil_Clay_Green"
    },
    {
      "x": -47,
      "y": 25,
      "z": 28,
      "name": "Soil_Seaweed_Block"
    },
    {
      "x": -47,
      "y": 25,
      "z": 29,
      "name": "Soil_Seaweed_Block"
    },
    {
      "x": -46,
      "y": 14,
      "z": 5,
      "name": "Soil_Clay_Green"
    },
    {
      "x": -46,
      "y": 15,
      "z": 5,
      "name": "Soil_Seaweed_Block"
    },
    {
      "x": -46,
      "y": 14,
      "z": 6,
      "name": "Soil_Clay_Green"
    },
    {
      "x": -46,
      "y": 15,
      "z": 6,
      "name": "Soil_Seaweed_Block"
    },
    {
      "x": -46,
      "y": 16,
      "z": 6,
      "name": "Soil_Clay_Lime"
    },
    {
      "x": -46,
      "y": 17,
      "z": 6,
      "name": "Plant_Grass_Sharp"
    },
    {
      "x": -46,
      "y": 13,
      "z": 7,
      "name": "Soil_Clay_Green"
    },
    {
      "x": -46,
      "y": 14,
      "z": 7,
      "name": "Soil_Clay_Green"
    },
    {
      "x": -46,
      "y": 15,
      "z": 7,
      "name": "Soil_Seaweed_Block"
    },
    {
      "x": -46,
      "y": 16,
      "z": 7,
      "name": "Soil_Clay_Lime"
    },
    {
      "x": -46,
      "y": 17,
      "z": 7,
      "name": "Plant_Grass_Sharp"
    },
    {
      "x": -46,
      "y": 25,
      "z": 7,
      "name": "Soil_Clay_Green"
    },
    {
      "x": -46,
      "y": 13,
      "z": 8,
      "name": "Soil_Clay_Green"
    },
    {
      "x": -46,
      "y": 14,
      "z": 8,
      "name": "Soil_Clay_Green"
    },
    {
      "x": -46,
      "y": 15,
      "z": 8,
      "name": "Soil_Seaweed_Block"
    },
    {
      "x": -46,
      "y": 16,
      "z": 8,
      "name": "Soil_Clay_Lime"
    },
    {
      "x": -46,
      "y": 17,
      "z": 8,
      "name": "Plant_Grass_Sharp"
    },
    {
      "x": -46,
      "y": 25,
      "z": 8,
      "name": "Soil_Clay_Green"
    },
    {
      "x": -46,
      "y": 26,
      "z": 8,
      "name": "Soil_Clay_Lime"
    },
    {
      "x": -46,
      "y": 27,
      "z": 8,
      "name": "Plant_Grass_Sharp"
    },
    {
      "x": -46,
      "y": 14,
      "z": 9,
      "name": "Soil_Clay_Green"
    },
    {
      "x": -46,
      "y": 15,
      "z": 9,
      "name": "Soil_Seaweed_Block"
    },
    {
      "x": -46,
      "y": 16,
      "z": 9,
      "name": "Soil_Seaweed_Block"
    },
    {
      "x": -46,
      "y": 25,
      "z": 9,
      "name": "Soil_Clay_Green"
    },
    {
      "x": -46,
      "y": 26,
      "z": 9,
      "name": "Soil_Clay_Lime"
    },
    {
      "x": -46,
      "y": 27,
      "z": 9,
      "name": "Plant_Grass_Sharp"
    },
    {
      "x": -46,
      "y": 32,
      "z": 10,
      "name": "Soil_Clay_Lime"
    },
    {
      "x": -46,
      "y": 33,
      "z": 10,
      "name": "Plant_Grass_Sharp"
    },
    {
      "x": -46,
      "y": 31,
      "z": 11,
      "name": "Soil_Clay_Green"
    },
    {
      "x": -46,
      "y": 32,
      "z": 11,
      "name": "Soil_Clay_Lime"
    },
    {
      "x": -46,
      "y": 33,
      "z": 11,
      "name": "Plant_Grass_Sharp"
    },
    {
      "x": -46,
      "y": 14,
      "z": 12,
      "name": "Soil_Clay_Green"
    },
    {
      "x": -46,
      "y": 31,
      "z": 12,
      "name": "Soil_Clay_Green"
    },
    {
      "x": -46,
      "y": 32,
      "z": 12,
      "name": "Soil_Seaweed_Block"
    },
    {
      "x": -46,
      "y": 14,
      "z": 13,
      "name": "Soil_Clay_Green"
    },
    {
      "x": -46,
      "y": 15,
      "z": 14,
      "name": "Soil_Seaweed_Block"
    },
    {
      "x": -46,
      "y": 18,
      "z": 16,
      "name": "Soil_Clay_Green"
    },
    {
      "x": -46,
      "y": 18,
      "z": 17,
      "name": "Soil_Clay_Green"
    },
    {
      "x": -46,
      "y": 19,
      "z": 17,
      "name": "Soil_Clay_Lime"
    },
    {
      "x": -46,
      "y": 20,
      "z": 17,
      "name": "Plant_Grass_Sharp"
    },
    {
      "x": -46,
      "y": 30,
      "z": 17,
      "name": "Soil_Clay_Green"
    },
    {
      "x": -46,
      "y": 31,
      "z": 17,
      "name": "Soil_Seaweed_Block"
    },
    {
      "x": -46,
      "y": 19,
      "z": 18,
      "name": "Soil_Seaweed_Block"
    },
    {
      "x": -46,
      "y": 30,
      "z": 18,
      "name": "Soil_Clay_Green"
    },
    {
      "x": -46,
      "y": 31,
      "z": 18,
      "name": "Soil_Seaweed_Block"
    },
    {
      "x": -46,
      "y": 23,
      "z": 19,
      "name": "Soil_Clay_Green"
    },
    {
      "x": -46,
      "y": 15,
      "z": 23,
      "name": "Soil_Clay_Green"
    },
    {
      "x": -46,
      "y": 16,
      "z": 23,
      "name": "Soil_Seaweed_Block"
    },
    {
      "x": -46,
      "y": 24,
      "z": 24,
      "name": "Soil_Clay_Green"
    },
    {
      "x": -46,
      "y": 25,
      "z": 24,
      "name": "Soil_Seaweed_Block"
    },
    {
      "x": -46,
      "y": 24,
      "z": 25,
      "name": "Soil_Clay_Green"
    },
    {
      "x": -46,
      "y": 25,
      "z": 25,
      "name": "Soil_Seaweed_Block"
    },
    {
      "x": -46,
      "y": 25,
      "z": 26,
      "name": "Soil_Clay_Lime"
    },
    {
      "x": -46,
      "y": 26,
      "z": 26,
      "name": "Soil_Clay_Lime"
    },
    {
      "x": -46,
      "y": 27,
      "z": 26,
      "name": "Plant_Grass_Sharp"
    },
    {
      "x": -46,
      "y": 24,
      "z": 27,
      "name": "Soil_Clay_Green"
    },
    {
      "x": -46,
      "y": 25,
      "z": 27,
      "name": "Soil_Clay_Lime"
    },
    {
      "x": -46,
      "y": 26,
      "z": 27,
      "name": "Plant_Grass_Sharp"
    },
    {
      "x": -46,
      "y": 24,
      "z": 28,
      "name": "Soil_Clay_Green"
    },
    {
      "x": -46,
      "y": 25,
      "z": 28,
      "name": "Soil_Seaweed_Block"
    },
    {
      "x": -46,
      "y": 31,
      "z": 28,
      "name": "Soil_Seaweed_Block"
    },
    {
      "x": -45,
      "y": 14,
      "z": 5,
      "name": "Soil_Clay_Green"
    },
    {
      "x": -45,
      "y": 15,
      "z": 5,
      "name": "Soil_Seaweed_Block"
    },
    {
      "x": -45,
      "y": 14,
      "z": 6,
      "name": "Soil_Clay_Green"
    },
    {
      "x": -45,
      "y": 15,
      "z": 6,
      "name": "Soil_Seaweed_Block"
    },
    {
      "x": -45,
      "y": 16,
      "z": 6,
      "name": "Soil_Clay_Lime"
    },
    {
      "x": -45,
      "y": 17,
      "z": 6,
      "name": "Plant_Grass_Sharp"
    },
    {
      "x": -45,
      "y": 15,
      "z": 7,
      "name": "Soil_Seaweed_Block"
    },
    {
      "x": -45,
      "y": 16,
      "z": 7,
      "name": "Soil_Clay_Lime"
    },
    {
      "x": -45,
      "y": 17,
      "z": 7,
      "name": "Plant_Grass_Sharp"
    },
    {
      "x": -45,
      "y": 25,
      "z": 7,
      "name": "Soil_Clay_Green"
    },
    {
      "x": -45,
      "y": 15,
      "z": 8,
      "name": "Soil_Clay_Green"
    },
    {
      "x": -45,
      "y": 16,
      "z": 8,
      "name": "Soil_Clay_Lime"
    },
    {
      "x": -45,
      "y": 17,
      "z": 8,
      "name": "Plant_Grass_Sharp"
    },
    {
      "x": -45,
      "y": 25,
      "z": 8,
      "name": "Soil_Clay_Green"
    },
    {
      "x": -45,
      "y": 26,
      "z": 8,
      "name": "Soil_Clay_Lime"
    },
    {
      "x": -45,
      "y": 27,
      "z": 8,
      "name": "Plant_Grass_Sharp"
    },
    {
      "x": -45,
      "y": 25,
      "z": 9,
      "name": "Soil_Clay_Green"
    },
    {
      "x": -45,
      "y": 26,
      "z": 9,
      "name": "Soil_Seaweed_Block"
    },
    {
      "x": -45,
      "y": 31,
      "z": 10,
      "name": "Soil_Clay_Green"
    },
    {
      "x": -45,
      "y": 32,
      "z": 10,
      "name": "Soil_Clay_Lime"
    },
    {
      "x": -45,
      "y": 33,
      "z": 10,
      "name": "Plant_Grass_Sharp"
    },
    {
      "x": -45,
      "y": 14,
      "z": 12,
      "name": "Soil_Clay_Green"
    },
    {
      "x": -45,
      "y": 14,
      "z": 13,
      "name": "Soil_Clay_Green"
    },
    {
      "x": -45,
      "y": 18,
      "z": 16,
      "name": "Soil_Clay_Green"
    },
    {
      "x": -45,
      "y": 18,
      "z": 17,
      "name": "Soil_Seaweed_Block"
    },
    {
      "x": -45,
      "y": 19,
      "z": 17,
      "name": "Soil_Clay_Lime"
    },
    {
      "x": -45,
      "y": 20,
      "z": 17,
      "name": "Plant_Grass_Sharp"
    },
    {
      "x": -45,
      "y": 30,
      "z": 17,
      "name": "Soil_Clay_Green"
    },
    {
      "x": -45,
      "y": 31,
      "z": 17,
      "name": "Soil_Seaweed_Block"
    },
    {
      "x": -45,
      "y": 19,
      "z": 18,
      "name": "Soil_Clay_Lime"
    },
    {
      "x": -45,
      "y": 20,
      "z": 18,
      "name": "Plant_Grass_Sharp"
    },
    {
      "x": -45,
      "y": 23,
      "z": 18,
      "name": "Soil_Clay_Green"
    },
    {
      "x": -45,
      "y": 30,
      "z": 18,
      "name": "Soil_Clay_Green"
    },
    {
      "x": -45,
      "y": 31,
      "z": 18,
      "name": "Soil_Seaweed_Block"
    },
    {
      "x": -45,
      "y": 24,
      "z": 19,
      "name": "Soil_Clay_Green"
    },
    {
      "x": -45,
      "y": 15,
      "z": 22,
      "name": "Soil_Clay_Green"
    },
    {
      "x": -45,
      "y": 14,
      "z": 23,
      "name": "Soil_Clay_Green"
    },
    {
      "x": -45,
      "y": 15,
      "z": 23,
      "name": "Soil_Clay_Green"
    },
    {
      "x": -45,
      "y": 16,
      "z": 23,
      "name": "Soil_Clay_Lime"
    },
    {
      "x": -45,
      "y": 17,
      "z": 23,
      "name": "Plant_Grass_Sharp"
    },
    {
      "x": -45,
      "y": 24,
      "z": 24,
      "name": "Soil_Clay_Green"
    },
    {
      "x": -45,
      "y": 25,
      "z": 24,
      "name": "Soil_Clay_Green"
    },
    {
      "x": -45,
      "y": 24,
      "z": 25,
      "name": "Soil_Clay_Green"
    },
    {
      "x": -45,
      "y": 25,
      "z": 25,
      "name": "Soil_Seaweed_Block"
    },
    {
      "x": -45,
      "y": 25,
      "z": 26,
      "name": "Soil_Seaweed_Block"
    },
    {
      "x": -45,
      "y": 26,
      "z": 26,
      "name": "Soil_Clay_Lime"
    },
    {
      "x": -45,
      "y": 27,
      "z": 26,
      "name": "Plant_Grass_Sharp"
    },
    {
      "x": -45,
      "y": 25,
      "z": 27,
      "name": "Soil_Seaweed_Block"
    },
    {
      "x": -45,
      "y": 24,
      "z": 28,
      "name": "Soil_Clay_Green"
    },
    {
      "x": -45,
      "y": 25,
      "z": 28,
      "name": "Soil_Seaweed_Block"
    },
    {
      "x": -45,
      "y": 31,
      "z": 28,
      "name": "Soil_Seaweed_Block"
    },
    {
      "x": -44,
      "y": 14,
      "z": 5,
      "name": "Soil_Clay_Green"
    },
    {
      "x": -44,
      "y": 15,
      "z": 5,
      "name": "Soil_Clay_Green"
    },
    {
      "x": -44,
      "y": 15,
      "z": 6,
      "name": "Soil_Clay_Green"
    },
    {
      "x": -44,
      "y": 16,
      "z": 6,
      "name": "Soil_Clay_Lime"
    },
    {
      "x": -44,
      "y": 17,
      "z": 6,
      "name": "Plant_Grass_Sharp"
    },
    {
      "x": -44,
      "y": 15,
      "z": 7,
      "name": "Soil_Clay_Green"
    },
    {
      "x": -44,
      "y": 16,
      "z": 7,
      "name": "Soil_Clay_Lime"
    },
    {
      "x": -44,
      "y": 17,
      "z": 7,
      "name": "Plant_Grass_Sharp"
    },
    {
      "x": -44,
      "y": 25,
      "z": 7,
      "name": "Soil_Clay_Green"
    },
    {
      "x": -44,
      "y": 15,
      "z": 8,
      "name": "Soil_Clay_Green"
    },
    {
      "x": -44,
      "y": 16,
      "z": 8,
      "name": "Soil_Seaweed_Block"
    },
    {
      "x": -44,
      "y": 25,
      "z": 8,
      "name": "Soil_Clay_Green"
    },
    {
      "x": -44,
      "y": 26,
      "z": 8,
      "name": "Soil_Clay_Lime"
    },
    {
      "x": -44,
      "y": 27,
      "z": 8,
      "name": "Soil_Clay_Lime"
    },
    {
      "x": -44,
      "y": 28,
      "z": 8,
      "name": "Plant_Grass_Sharp"
    },
    {
      "x": -44,
      "y": 26,
      "z": 9,
      "name": "Soil_Seaweed_Block"
    },
    {
      "x": -44,
      "y": 31,
      "z": 9,
      "name": "Soil_Clay_Green"
    },
    {
      "x": -44,
      "y": 32,
      "z": 10,
      "name": "Soil_Clay_Lime"
    },
    {
      "x": -44,
      "y": 33,
      "z": 10,
      "name": "Plant_Grass_Sharp"
    },
    {
      "x": -44,
      "y": 14,
      "z": 12,
      "name": "Soil_Clay_Green"
    },
    {
      "x": -44,
      "y": 15,
      "z": 12,
      "name": "Soil_Clay_Lime"
    },
    {
      "x": -44,
      "y": 16,
      "z": 12,
      "name": "Plant_Grass_Sharp"
    },
    {
      "x": -44,
      "y": 14,
      "z": 13,
      "name": "Soil_Clay_Green"
    },
    {
      "x": -44,
      "y": 15,
      "z": 13,
      "name": "Soil_Seaweed_Block"
    },
    {
      "x": -44,
      "y": 31,
      "z": 16,
      "name": "Soil_Clay_Green"
    },
    {
      "x": -44,
      "y": 17,
      "z": 17,
      "name": "Soil_Clay_Green"
    },
    {
      "x": -44,
      "y": 18,
      "z": 17,
      "name": "Soil_Seaweed_Block"
    },
    {
      "x": -44,
      "y": 24,
      "z": 17,
      "name": "Soil_Clay_Green"
    },
    {
      "x": -44,
      "y": 31,
      "z": 17,
      "name": "Soil_Clay_Green"
    },
    {
      "x": -44,
      "y": 32,
      "z": 17,
      "name": "Soil_Clay_Lime"
    },
    {
      "x": -44,
      "y": 33,
      "z": 17,
      "name": "Plant_Grass_Sharp"
    },
    {
      "x": -44,
      "y": 16,
      "z": 18,
      "name": "Soil_Clay_Green"
    },
    {
      "x": -44,
      "y": 24,
      "z": 18,
      "name": "Soil_Clay_Green"
    },
    {
      "x": -44,
      "y": 16,
      "z": 19,
      "name": "Soil_Clay_Green"
    },
    {
      "x": -44,
      "y": 15,
      "z": 20,
      "name": "Soil_Clay_Green"
    },
    {
      "x": -44,
      "y": 16,
      "z": 20,
      "name": "Soil_Seaweed_Block"
    },
    {
      "x": -44,
      "y": 15,
      "z": 21,
      "name": "Soil_Clay_Green"
    },
    {
      "x": -44,
      "y": 25,
      "z": 21,
      "name": "Soil_Clay_Green"
    },
    {
      "x": -44,
      "y": 26,
      "z": 21,
      "name": "Soil_Seaweed_Block"
    },
    {
      "x": -44,
      "y": 15,
      "z": 22,
      "name": "Soil_Clay_Green"
    },
    {
      "x": -44,
      "y": 24,
      "z": 22,
      "name": "Soil_Clay_Green"
    },
    {
      "x": -44,
      "y": 25,
      "z": 22,
      "name": "Soil_Clay_Green"
    },
    {
      "x": -44,
      "y": 26,
      "z": 22,
      "name": "Soil_Seaweed_Block"
    },
    {
      "x": -44,
      "y": 14,
      "z": 23,
      "name": "Soil_Clay_Green"
    },
    {
      "x": -44,
      "y": 15,
      "z": 23,
      "name": "Soil_Clay_Green"
    },
    {
      "x": -44,
      "y": 16,
      "z": 23,
      "name": "Soil_Clay_Lime"
    },
    {
      "x": -44,
      "y": 17,
      "z": 23,
      "name": "Plant_Grass_Sharp"
    },
    {
      "x": -44,
      "y": 24,
      "z": 23,
      "name": "Soil_Clay_Green"
    },
    {
      "x": -44,
      "y": 25,
      "z": 23,
      "name": "Soil_Clay_Green"
    },
    {
      "x": -44,
      "y": 26,
      "z": 23,
      "name": "Soil_Clay_Lime"
    },
    {
      "x": -44,
      "y": 27,
      "z": 23,
      "name": "Plant_Grass_Sharp"
    },
    {
      "x": -44,
      "y": 25,
      "z": 24,
      "name": "Soil_Clay_Green"
    },
    {
      "x": -44,
      "y": 26,
      "z": 24,
      "name": "Soil_Clay_Lime"
    },
    {
      "x": -44,
      "y": 27,
      "z": 24,
      "name": "Plant_Grass_Sharp"
    },
    {
      "x": -44,
      "y": 25,
      "z": 25,
      "name": "Soil_Clay_Green"
    },
    {
      "x": -44,
      "y": 25,
      "z": 26,
      "name": "Soil_Seaweed_Block"
    },
    {
      "x": -44,
      "y": 31,
      "z": 27,
      "name": "Soil_Clay_Lime"
    },
    {
      "x": -44,
      "y": 32,
      "z": 27,
      "name": "Plant_Grass_Sharp"
    },
    {
      "x": -44,
      "y": 30,
      "z": 28,
      "name": "Soil_Clay_Green"
    },
    {
      "x": -44,
      "y": 31,
      "z": 28,
      "name": "Soil_Clay_Lime"
    },
    {
      "x": -44,
      "y": 32,
      "z": 28,
      "name": "Plant_Grass_Sharp"
    },
    {
      "x": -43,
      "y": 14,
      "z": 5,
      "name": "Soil_Clay_Green"
    },
    {
      "x": -43,
      "y": 15,
      "z": 5,
      "name": "Soil_Clay_Green"
    },
    {
      "x": -43,
      "y": 15,
      "z": 6,
      "name": "Soil_Clay_Green"
    },
    {
      "x": -43,
      "y": 16,
      "z": 6,
      "name": "Soil_Clay_Lime"
    },
    {
      "x": -43,
      "y": 17,
      "z": 6,
      "name": "Plant_Grass_Sharp"
    },
    {
      "x": -43,
      "y": 15,
      "z": 7,
      "name": "Soil_Clay_Green"
    },
    {
      "x": -43,
      "y": 16,
      "z": 7,
      "name": "Soil_Clay_Lime"
    },
    {
      "x": -43,
      "y": 17,
      "z": 7,
      "name": "Plant_Grass_Sharp"
    },
    {
      "x": -43,
      "y": 27,
      "z": 7,
      "name": "Soil_Seaweed_Block"
    },
    {
      "x": -43,
      "y": 15,
      "z": 8,
      "name": "Soil_Clay_Green"
    },
    {
      "x": -43,
      "y": 25,
      "z": 8,
      "name": "Soil_Clay_Green"
    },
    {
      "x": -43,
      "y": 26,
      "z": 8,
      "name": "Soil_Clay_Green"
    },
    {
      "x": -43,
      "y": 27,
      "z": 8,
      "name": "Soil_Clay_Lime"
    },
    {
      "x": -43,
      "y": 28,
      "z": 8,
      "name": "Soil_Clay_Lime"
    },
    {
      "x": -43,
      "y": 29,
      "z": 8,
      "name": "Plant_Grass_Sharp"
    },
    {
      "x": -43,
      "y": 32,
      "z": 8,
      "name": "Soil_Seaweed_Block"
    },
    {
      "x": -43,
      "y": 26,
      "z": 9,
      "name": "Soil_Clay_Green"
    },
    {
      "x": -43,
      "y": 31,
      "z": 9,
      "name": "Soil_Clay_Green"
    },
    {
      "x": -43,
      "y": 32,
      "z": 9,
      "name": "Soil_Seaweed_Block"
    },
    {
      "x": -43,
      "y": 15,
      "z": 11,
      "name": "Soil_Clay_Lime"
    },
    {
      "x": -43,
      "y": 16,
      "z": 11,
      "name": "Plant_Grass_Sharp"
    },
    {
      "x": -43,
      "y": 15,
      "z": 12,
      "name": "Soil_Clay_Lime"
    },
    {
      "x": -43,
      "y": 16,
      "z": 12,
      "name": "Plant_Grass_Sharp"
    },
    {
      "x": -43,
      "y": 31,
      "z": 16,
      "name": "Soil_Clay_Green"
    },
    {
      "x": -43,
      "y": 24,
      "z": 17,
      "name": "Soil_Clay_Green"
    },
    {
      "x": -43,
      "y": 31,
      "z": 17,
      "name": "Soil_Clay_Green"
    },
    {
      "x": -43,
      "y": 32,
      "z": 17,
      "name": "Soil_Clay_Lime"
    },
    {
      "x": -43,
      "y": 33,
      "z": 17,
      "name": "Plant_Grass_Sharp"
    },
    {
      "x": -43,
      "y": 17,
      "z": 18,
      "name": "Soil_Seaweed_Block"
    },
    {
      "x": -43,
      "y": 18,
      "z": 18,
      "name": "Soil_Clay_Lime"
    },
    {
      "x": -43,
      "y": 19,
      "z": 18,
      "name": "Plant_Grass_Sharp"
    },
    {
      "x": -43,
      "y": 24,
      "z": 18,
      "name": "Soil_Clay_Green"
    },
    {
      "x": -43,
      "y": 32,
      "z": 18,
      "name": "Soil_Clay_Lime"
    },
    {
      "x": -43,
      "y": 33,
      "z": 18,
      "name": "Plant_Grass_Sharp"
    },
    {
      "x": -43,
      "y": 15,
      "z": 19,
      "name": "Soil_Clay_Green"
    },
    {
      "x": -43,
      "y": 16,
      "z": 19,
      "name": "Soil_Seaweed_Block"
    },
    {
      "x": -43,
      "y": 17,
      "z": 19,
      "name": "Soil_Clay_Lime"
    },
    {
      "x": -43,
      "y": 18,
      "z": 19,
      "name": "Plant_Grass_Sharp"
    },
    {
      "x": -43,
      "y": 15,
      "z": 20,
      "name": "Soil_Clay_Green"
    },
    {
      "x": -43,
      "y": 16,
      "z": 20,
      "name": "Soil_Seaweed_Block"
    },
    {
      "x": -43,
      "y": 17,
      "z": 20,
      "name": "Soil_Clay_Lime"
    },
    {
      "x": -43,
      "y": 18,
      "z": 20,
      "name": "Plant_Grass_Sharp"
    },
    {
      "x": -43,
      "y": 27,
      "z": 20,
      "name": "Soil_Seaweed_Block"
    },
    {
      "x": -43,
      "y": 15,
      "z": 21,
      "name": "Soil_Clay_Green"
    },
    {
      "x": -43,
      "y": 16,
      "z": 21,
      "name": "Soil_Clay_Lime"
    },
    {
      "x": -43,
      "y": 17,
      "z": 21,
      "name": "Plant_Grass_Sharp"
    },
    {
      "x": -43,
      "y": 25,
      "z": 21,
      "name": "Soil_Clay_Green"
    },
    {
      "x": -43,
      "y": 26,
      "z": 21,
      "name": "Soil_Clay_Green"
    },
    {
      "x": -43,
      "y": 27,
      "z": 21,
      "name": "Soil_Seaweed_Block"
    },
    {
      "x": -43,
      "y": 15,
      "z": 22,
      "name": "Soil_Clay_Green"
    },
    {
      "x": -43,
      "y": 25,
      "z": 22,
      "name": "Soil_Clay_Green"
    },
    {
      "x": -43,
      "y": 26,
      "z": 22,
      "name": "Soil_Seaweed_Block"
    },
    {
      "x": -43,
      "y": 27,
      "z": 22,
      "name": "Soil_Clay_Lime"
    },
    {
      "x": -43,
      "y": 28,
      "z": 22,
      "name": "Plant_Grass_Sharp"
    },
    {
      "x": -43,
      "y": 16,
      "z": 23,
      "name": "Soil_Seaweed_Block"
    },
    {
      "x": -43,
      "y": 24,
      "z": 23,
      "name": "Soil_Clay_Green"
    },
    {
      "x": -43,
      "y": 25,
      "z": 23,
      "name": "Soil_Seaweed_Block"
    },
    {
      "x": -43,
      "y": 26,
      "z": 23,
      "name": "Soil_Seaweed_Block"
    },
    {
      "x": -43,
      "y": 25,
      "z": 24,
      "name": "Soil_Clay_Green"
    },
    {
      "x": -43,
      "y": 26,
      "z": 24,
      "name": "Soil_Seaweed_Block"
    },
    {
      "x": -43,
      "y": 31,
      "z": 26,
      "name": "Soil_Clay_Lime"
    },
    {
      "x": -43,
      "y": 32,
      "z": 26,
      "name": "Plant_Grass_Sharp"
    },
    {
      "x": -43,
      "y": 29,
      "z": 27,
      "name": "Soil_Clay_Green"
    },
    {
      "x": -43,
      "y": 30,
      "z": 27,
      "name": "Soil_Clay_Green"
    },
    {
      "x": -43,
      "y": 30,
      "z": 28,
      "name": "Soil_Clay_Green"
    },
    {
      "x": -42,
      "y": 14,
      "z": 5,
      "name": "Soil_Clay_Green"
    },
    {
      "x": -42,
      "y": 15,
      "z": 5,
      "name": "Soil_Clay_Green"
    },
    {
      "x": -42,
      "y": 15,
      "z": 6,
      "name": "Soil_Clay_Green"
    },
    {
      "x": -42,
      "y": 16,
      "z": 6,
      "name": "Soil_Clay_Lime"
    },
    {
      "x": -42,
      "y": 17,
      "z": 6,
      "name": "Plant_Grass_Sharp"
    },
    {
      "x": -42,
      "y": 15,
      "z": 7,
      "name": "Soil_Clay_Green"
    },
    {
      "x": -42,
      "y": 16,
      "z": 7,
      "name": "Soil_Clay_Lime"
    },
    {
      "x": -42,
      "y": 17,
      "z": 7,
      "name": "Plant_Grass_Sharp"
    },
    {
      "x": -42,
      "y": 27,
      "z": 7,
      "name": "Soil_Seaweed_Block"
    },
    {
      "x": -42,
      "y": 15,
      "z": 8,
      "name": "Soil_Clay_Green"
    },
    {
      "x": -42,
      "y": 25,
      "z": 8,
      "name": "Soil_Clay_Green"
    },
    {
      "x": -42,
      "y": 26,
      "z": 8,
      "name": "Soil_Clay_Green"
    },
    {
      "x": -42,
      "y": 32,
      "z": 8,
      "name": "Soil_Seaweed_Block"
    },
    {
      "x": -42,
      "y": 28,
      "z": 9,
      "name": "Soil_Seaweed_Block"
    },
    {
      "x": -42,
      "y": 31,
      "z": 9,
      "name": "Soil_Seaweed_Block"
    },
    {
      "x": -42,
      "y": 32,
      "z": 9,
      "name": "Soil_Seaweed_Block"
    },
    {
      "x": -42,
      "y": 33,
      "z": 9,
      "name": "Soil_Clay_Lime"
    },
    {
      "x": -42,
      "y": 34,
      "z": 9,
      "name": "Plant_Grass_Sharp"
    },
    {
      "x": -42,
      "y": 32,
      "z": 10,
      "name": "Soil_Seaweed_Block"
    },
    {
      "x": -42,
      "y": 33,
      "z": 10,
      "name": "Soil_Clay_Lime"
    },
    {
      "x": -42,
      "y": 34,
      "z": 10,
      "name": "Plant_Grass_Sharp"
    },
    {
      "x": -42,
      "y": 15,
      "z": 11,
      "name": "Soil_Seaweed_Block"
    },
    {
      "x": -42,
      "y": 15,
      "z": 12,
      "name": "Soil_Seaweed_Block"
    },
    {
      "x": -42,
      "y": 24,
      "z": 17,
      "name": "Soil_Clay_Green"
    },
    {
      "x": -42,
      "y": 25,
      "z": 17,
      "name": "Soil_Clay_Green"
    },
    {
      "x": -42,
      "y": 31,
      "z": 17,
      "name": "Soil_Clay_Green"
    },
    {
      "x": -42,
      "y": 32,
      "z": 17,
      "name": "Soil_Clay_Lime"
    },
    {
      "x": -42,
      "y": 33,
      "z": 17,
      "name": "Plant_Grass_Sharp"
    },
    {
      "x": -42,
      "y": 24,
      "z": 18,
      "name": "Soil_Clay_Green"
    },
    {
      "x": -42,
      "y": 25,
      "z": 18,
      "name": "Soil_Clay_Green"
    },
    {
      "x": -42,
      "y": 31,
      "z": 18,
      "name": "Soil_Seaweed_Block"
    },
    {
      "x": -42,
      "y": 14,
      "z": 19,
      "name": "Soil_Clay_Green"
    },
    {
      "x": -42,
      "y": 15,
      "z": 19,
      "name": "Soil_Clay_Green"
    },
    {
      "x": -42,
      "y": 16,
      "z": 19,
      "name": "Soil_Seaweed_Block"
    },
    {
      "x": -42,
      "y": 27,
      "z": 19,
      "name": "Soil_Seaweed_Block"
    },
    {
      "x": -42,
      "y": 14,
      "z": 20,
      "name": "Soil_Clay_Green"
    },
    {
      "x": -42,
      "y": 15,
      "z": 20,
      "name": "Soil_Seaweed_Block"
    },
    {
      "x": -42,
      "y": 16,
      "z": 20,
      "name": "Soil_Seaweed_Block"
    },
    {
      "x": -42,
      "y": 17,
      "z": 20,
      "name": "Soil_Clay_Lime"
    },
    {
      "x": -42,
      "y": 18,
      "z": 20,
      "name": "Plant_Grass_Sharp"
    },
    {
      "x": -42,
      "y": 25,
      "z": 20,
      "name": "Soil_Clay_Green"
    },
    {
      "x": -42,
      "y": 26,
      "z": 20,
      "name": "Soil_Clay_Green"
    },
    {
      "x": -42,
      "y": 27,
      "z": 20,
      "name": "Soil_Seaweed_Block"
    },
    {
      "x": -42,
      "y": 15,
      "z": 21,
      "name": "Soil_Clay_Green"
    },
    {
      "x": -42,
      "y": 16,
      "z": 21,
      "name": "Soil_Clay_Lime"
    },
    {
      "x": -42,
      "y": 17,
      "z": 21,
      "name": "Plant_Grass_Sharp"
    },
    {
      "x": -42,
      "y": 26,
      "z": 21,
      "name": "Soil_Clay_Green"
    },
    {
      "x": -42,
      "y": 27,
      "z": 21,
      "name": "Soil_Seaweed_Block"
    },
    {
      "x": -42,
      "y": 28,
      "z": 21,
      "name": "Soil_Clay_Lime"
    },
    {
      "x": -42,
      "y": 29,
      "z": 21,
      "name": "Plant_Grass_Sharp"
    },
    {
      "x": -42,
      "y": 15,
      "z": 22,
      "name": "Soil_Clay_Green"
    },
    {
      "x": -42,
      "y": 25,
      "z": 22,
      "name": "Soil_Clay_Green"
    },
    {
      "x": -42,
      "y": 26,
      "z": 22,
      "name": "Soil_Seaweed_Block"
    },
    {
      "x": -42,
      "y": 27,
      "z": 22,
      "name": "Soil_Clay_Lime"
    },
    {
      "x": -42,
      "y": 28,
      "z": 22,
      "name": "Plant_Grass_Sharp"
    },
    {
      "x": -42,
      "y": 16,
      "z": 23,
      "name": "Soil_Seaweed_Block"
    },
    {
      "x": -42,
      "y": 25,
      "z": 23,
      "name": "Soil_Clay_Green"
    },
    {
      "x": -42,
      "y": 26,
      "z": 23,
      "name": "Soil_Clay_Green"
    },
    {
      "x": -42,
      "y": 30,
      "z": 23,
      "name": "Soil_Clay_Lime"
    },
    {
      "x": -42,
      "y": 31,
      "z": 23,
      "name": "Plant_Grass_Sharp"
    },
    {
      "x": -42,
      "y": 29,
      "z": 24,
      "name": "Soil_Seaweed_Block"
    },
    {
      "x": -42,
      "y": 30,
      "z": 24,
      "name": "Soil_Clay_Lime"
    },
    {
      "x": -42,
      "y": 31,
      "z": 24,
      "name": "Plant_Grass_Sharp"
    },
    {
      "x": -42,
      "y": 29,
      "z": 25,
      "name": "Soil_Clay_Green"
    },
    {
      "x": -42,
      "y": 30,
      "z": 25,
      "name": "Soil_Clay_Lime"
    },
    {
      "x": -42,
      "y": 31,
      "z": 25,
      "name": "Soil_Clay_Lime"
    },
    {
      "x": -42,
      "y": 32,
      "z": 25,
      "name": "Plant_Grass_Sharp"
    },
    {
      "x": -42,
      "y": 29,
      "z": 26,
      "name": "Soil_Clay_Green"
    },
    {
      "x": -42,
      "y": 30,
      "z": 26,
      "name": "Soil_Seaweed_Block"
    },
    {
      "x": -42,
      "y": 29,
      "z": 27,
      "name": "Soil_Clay_Green"
    },
    {
      "x": -42,
      "y": 30,
      "z": 28,
      "name": "Soil_Clay_Green"
    },
    {
      "x": -41,
      "y": 14,
      "z": 5,
      "name": "Soil_Clay_Green"
    },
    {
      "x": -41,
      "y": 15,
      "z": 5,
      "name": "Soil_Clay_Green"
    },
    {
      "x": -41,
      "y": 15,
      "z": 6,
      "name": "Soil_Clay_Green"
    },
    {
      "x": -41,
      "y": 16,
      "z": 6,
      "name": "Soil_Clay_Lime"
    },
    {
      "x": -41,
      "y": 17,
      "z": 6,
      "name": "Plant_Grass_Sharp"
    },
    {
      "x": -41,
      "y": 15,
      "z": 7,
      "name": "Soil_Clay_Green"
    },
    {
      "x": -41,
      "y": 16,
      "z": 7,
      "name": "Soil_Clay_Lime"
    },
    {
      "x": -41,
      "y": 17,
      "z": 7,
      "name": "Plant_Grass_Sharp"
    },
    {
      "x": -41,
      "y": 27,
      "z": 7,
      "name": "Soil_Clay_Green"
    },
    {
      "x": -41,
      "y": 14,
      "z": 8,
      "name": "Soil_Clay_Green"
    },
    {
      "x": -41,
      "y": 15,
      "z": 8,
      "name": "Soil_Seaweed_Block"
    },
    {
      "x": -41,
      "y": 16,
      "z": 8,
      "name": "Soil_Clay_Lime"
    },
    {
      "x": -41,
      "y": 17,
      "z": 8,
      "name": "Plant_Grass_Sharp"
    },
    {
      "x": -41,
      "y": 25,
      "z": 8,
      "name": "Soil_Clay_Green"
    },
    {
      "x": -41,
      "y": 26,
      "z": 8,
      "name": "Soil_Clay_Green"
    },
    {
      "x": -41,
      "y": 27,
      "z": 8,
      "name": "Soil_Clay_Green"
    },
    {
      "x": -41,
      "y": 28,
      "z": 8,
      "name": "Soil_Seaweed_Block"
    },
    {
      "x": -41,
      "y": 32,
      "z": 8,
      "name": "Soil_Seaweed_Block"
    },
    {
      "x": -41,
      "y": 14,
      "z": 9,
      "name": "Soil_Clay_Green"
    },
    {
      "x": -41,
      "y": 15,
      "z": 9,
      "name": "Soil_Clay_Green"
    },
    {
      "x": -41,
      "y": 16,
      "z": 9,
      "name": "Soil_Clay_Lime"
    },
    {
      "x": -41,
      "y": 17,
      "z": 9,
      "name": "Plant_Grass_Sharp"
    },
    {
      "x": -41,
      "y": 26,
      "z": 9,
      "name": "Soil_Clay_Green"
    },
    {
      "x": -41,
      "y": 27,
      "z": 9,
      "name": "Soil_Clay_Green"
    },
    {
      "x": -41,
      "y": 28,
      "z": 9,
      "name": "Soil_Seaweed_Block"
    },
    {
      "x": -41,
      "y": 29,
      "z": 9,
      "name": "Soil_Clay_Lime"
    },
    {
      "x": -41,
      "y": 30,
      "z": 9,
      "name": "Plant_Grass_Sharp"
    },
    {
      "x": -41,
      "y": 32,
      "z": 9,
      "name": "Soil_Clay_Lime"
    },
    {
      "x": -41,
      "y": 33,
      "z": 9,
      "name": "Plant_Grass_Sharp"
    },
    {
      "x": -41,
      "y": 15,
      "z": 10,
      "name": "Soil_Clay_Green"
    },
    {
      "x": -41,
      "y": 27,
      "z": 10,
      "name": "Soil_Clay_Green"
    },
    {
      "x": -41,
      "y": 28,
      "z": 10,
      "name": "Soil_Seaweed_Block"
    },
    {
      "x": -41,
      "y": 29,
      "z": 10,
      "name": "Soil_Seaweed_Block"
    },
    {
      "x": -41,
      "y": 18,
      "z": 14,
      "name": "Soil_Seaweed_Block"
    },
    {
      "x": -41,
      "y": 30,
      "z": 16,
      "name": "Soil_Clay_Green"
    },
    {
      "x": -41,
      "y": 31,
      "z": 16,
      "name": "Soil_Clay_Lime"
    },
    {
      "x": -41,
      "y": 32,
      "z": 16,
      "name": "Plant_Grass_Sharp"
    },
    {
      "x": -41,
      "y": 25,
      "z": 17,
      "name": "Soil_Clay_Green"
    },
    {
      "x": -41,
      "y": 30,
      "z": 17,
      "name": "Soil_Clay_Green"
    },
    {
      "x": -41,
      "y": 31,
      "z": 17,
      "name": "Soil_Seaweed_Block"
    },
    {
      "x": -41,
      "y": 25,
      "z": 18,
      "name": "Soil_Clay_Green"
    },
    {
      "x": -41,
      "y": 26,
      "z": 18,
      "name": "Soil_Clay_Green"
    },
    {
      "x": -41,
      "y": 27,
      "z": 18,
      "name": "Soil_Seaweed_Block"
    },
    {
      "x": -41,
      "y": 31,
      "z": 18,
      "name": "Soil_Seaweed_Block"
    },
    {
      "x": -41,
      "y": 15,
      "z": 19,
      "name": "Soil_Clay_Green"
    },
    {
      "x": -41,
      "y": 16,
      "z": 19,
      "name": "Soil_Clay_Green"
    },
    {
      "x": -41,
      "y": 25,
      "z": 19,
      "name": "Soil_Clay_Green"
    },
    {
      "x": -41,
      "y": 26,
      "z": 19,
      "name": "Soil_Clay_Green"
    },
    {
      "x": -41,
      "y": 27,
      "z": 19,
      "name": "Soil_Seaweed_Block"
    },
    {
      "x": -41,
      "y": 28,
      "z": 19,
      "name": "Soil_Clay_Lime"
    },
    {
      "x": -41,
      "y": 29,
      "z": 19,
      "name": "Plant_Grass_Sharp"
    },
    {
      "x": -41,
      "y": 15,
      "z": 20,
      "name": "Soil_Clay_Green"
    },
    {
      "x": -41,
      "y": 16,
      "z": 20,
      "name": "Soil_Seaweed_Block"
    },
    {
      "x": -41,
      "y": 17,
      "z": 20,
      "name": "Soil_Clay_Lime"
    },
    {
      "x": -41,
      "y": 18,
      "z": 20,
      "name": "Plant_Grass_Sharp"
    },
    {
      "x": -41,
      "y": 25,
      "z": 20,
      "name": "Soil_Clay_Green"
    },
    {
      "x": -41,
      "y": 26,
      "z": 20,
      "name": "Soil_Seaweed_Block"
    },
    {
      "x": -41,
      "y": 27,
      "z": 20,
      "name": "Soil_Seaweed_Block"
    },
    {
      "x": -41,
      "y": 28,
      "z": 20,
      "name": "Soil_Clay_Lime"
    },
    {
      "x": -41,
      "y": 29,
      "z": 20,
      "name": "Plant_Grass_Sharp"
    },
    {
      "x": -41,
      "y": 15,
      "z": 21,
      "name": "Soil_Clay_Green"
    },
    {
      "x": -41,
      "y": 16,
      "z": 21,
      "name": "Soil_Seaweed_Block"
    },
    {
      "x": -41,
      "y": 26,
      "z": 21,
      "name": "Soil_Clay_Green"
    },
    {
      "x": -41,
      "y": 27,
      "z": 21,
      "name": "Soil_Seaweed_Block"
    },
    {
      "x": -41,
      "y": 28,
      "z": 21,
      "name": "Soil_Clay_Lime"
    },
    {
      "x": -41,
      "y": 29,
      "z": 21,
      "name": "Plant_Grass_Sharp"
    },
    {
      "x": -41,
      "y": 26,
      "z": 22,
      "name": "Soil_Clay_Green"
    },
    {
      "x": -41,
      "y": 27,
      "z": 22,
      "name": "Soil_Seaweed_Block"
    },
    {
      "x": -41,
      "y": 28,
      "z": 22,
      "name": "Soil_Clay_Lime"
    },
    {
      "x": -41,
      "y": 29,
      "z": 22,
      "name": "Plant_Grass_Sharp"
    },
    {
      "x": -41,
      "y": 27,
      "z": 23,
      "name": "Soil_Clay_Green"
    },
    {
      "x": -41,
      "y": 28,
      "z": 23,
      "name": "Soil_Seaweed_Block"
    },
    {
      "x": -41,
      "y": 29,
      "z": 23,
      "name": "Soil_Clay_Lime"
    },
    {
      "x": -41,
      "y": 30,
      "z": 23,
      "name": "Soil_Clay_Lime"
    },
    {
      "x": -41,
      "y": 31,
      "z": 23,
      "name": "Plant_Grass_Sharp"
    },
    {
      "x": -41,
      "y": 27,
      "z": 24,
      "name": "Soil_Clay_Green"
    },
    {
      "x": -41,
      "y": 29,
      "z": 24,
      "name": "Soil_Seaweed_Block"
    },
    {
      "x": -41,
      "y": 30,
      "z": 24,
      "name": "Soil_Clay_Lime"
    },
    {
      "x": -41,
      "y": 31,
      "z": 24,
      "name": "Plant_Grass_Sharp"
    },
    {
      "x": -41,
      "y": 29,
      "z": 25,
      "name": "Soil_Clay_Green"
    },
    {
      "x": -40,
      "y": 15,
      "z": 6,
      "name": "Soil_Clay_Green"
    },
    {
      "x": -40,
      "y": 16,
      "z": 6,
      "name": "Soil_Clay_Lime"
    },
    {
      "x": -40,
      "y": 17,
      "z": 6,
      "name": "Plant_Grass_Sharp"
    },
    {
      "x": -40,
      "y": 15,
      "z": 7,
      "name": "Soil_Clay_Green"
    },
    {
      "x": -40,
      "y": 16,
      "z": 7,
      "name": "Soil_Clay_Lime"
    },
    {
      "x": -40,
      "y": 17,
      "z": 7,
      "name": "Plant_Grass_Sharp"
    },
    {
      "x": -40,
      "y": 27,
      "z": 7,
      "name": "Soil_Clay_Green"
    },
    {
      "x": -40,
      "y": 14,
      "z": 8,
      "name": "Soil_Clay_Green"
    },
    {
      "x": -40,
      "y": 15,
      "z": 8,
      "name": "Soil_Seaweed_Block"
    },
    {
      "x": -40,
      "y": 16,
      "z": 8,
      "name": "Soil_Clay_Lime"
    },
    {
      "x": -40,
      "y": 17,
      "z": 8,
      "name": "Plant_Grass_Sharp"
    },
    {
      "x": -40,
      "y": 27,
      "z": 8,
      "name": "Soil_Clay_Green"
    },
    {
      "x": -40,
      "y": 28,
      "z": 8,
      "name": "Soil_Seaweed_Block"
    },
    {
      "x": -40,
      "y": 29,
      "z": 8,
      "name": "Soil_Seaweed_Block"
    },
    {
      "x": -40,
      "y": 32,
      "z": 8,
      "name": "Soil_Seaweed_Block"
    },
    {
      "x": -40,
      "y": 14,
      "z": 9,
      "name": "Soil_Clay_Green"
    },
    {
      "x": -40,
      "y": 15,
      "z": 9,
      "name": "Soil_Seaweed_Block"
    },
    {
      "x": -40,
      "y": 16,
      "z": 9,
      "name": "Soil_Clay_Lime"
    },
    {
      "x": -40,
      "y": 17,
      "z": 9,
      "name": "Plant_Grass_Sharp"
    },
    {
      "x": -40,
      "y": 27,
      "z": 9,
      "name": "Soil_Clay_Green"
    },
    {
      "x": -40,
      "y": 28,
      "z": 9,
      "name": "Soil_Seaweed_Block"
    },
    {
      "x": -40,
      "y": 29,
      "z": 9,
      "name": "Soil_Seaweed_Block"
    },
    {
      "x": -40,
      "y": 30,
      "z": 9,
      "name": "Soil_Clay_Lime"
    },
    {
      "x": -40,
      "y": 31,
      "z": 9,
      "name": "Soil_Clay_Lime"
    },
    {
      "x": -40,
      "y": 32,
      "z": 9,
      "name": "Soil_Clay_Lime"
    },
    {
      "x": -40,
      "y": 33,
      "z": 9,
      "name": "Plant_Grass_Sharp"
    },
    {
      "x": -40,
      "y": 15,
      "z": 10,
      "name": "Soil_Clay_Green"
    },
    {
      "x": -40,
      "y": 16,
      "z": 10,
      "name": "Soil_Seaweed_Block"
    },
    {
      "x": -40,
      "y": 27,
      "z": 10,
      "name": "Soil_Clay_Green"
    },
    {
      "x": -40,
      "y": 28,
      "z": 10,
      "name": "Soil_Seaweed_Block"
    },
    {
      "x": -40,
      "y": 29,
      "z": 10,
      "name": "Soil_Seaweed_Block"
    },
    {
      "x": -40,
      "y": 30,
      "z": 10,
      "name": "Soil_Clay_Lime"
    },
    {
      "x": -40,
      "y": 31,
      "z": 10,
      "name": "Soil_Clay_Lime"
    },
    {
      "x": -40,
      "y": 32,
      "z": 10,
      "name": "Plant_Grass_Sharp"
    },
    {
      "x": -40,
      "y": 27,
      "z": 11,
      "name": "Soil_Clay_Green"
    },
    {
      "x": -40,
      "y": 28,
      "z": 11,
      "name": "Soil_Clay_Green"
    },
    {
      "x": -40,
      "y": 29,
      "z": 11,
      "name": "Soil_Seaweed_Block"
    },
    {
      "x": -40,
      "y": 30,
      "z": 11,
      "name": "Soil_Clay_Lime"
    },
    {
      "x": -40,
      "y": 31,
      "z": 11,
      "name": "Plant_Grass_Sharp"
    },
    {
      "x": -40,
      "y": 29,
      "z": 12,
      "name": "Soil_Seaweed_Block"
    },
    {
      "x": -40,
      "y": 30,
      "z": 12,
      "name": "Soil_Clay_Lime"
    },
    {
      "x": -40,
      "y": 31,
      "z": 12,
      "name": "Plant_Grass_Sharp"
    },
    {
      "x": -40,
      "y": 29,
      "z": 13,
      "name": "Soil_Seaweed_Block"
    },
    {
      "x": -40,
      "y": 30,
      "z": 13,
      "name": "Soil_Clay_Lime"
    },
    {
      "x": -40,
      "y": 31,
      "z": 13,
      "name": "Plant_Grass_Sharp"
    },
    {
      "x": -40,
      "y": 18,
      "z": 14,
      "name": "Soil_Seaweed_Block"
    },
    {
      "x": -40,
      "y": 29,
      "z": 14,
      "name": "Soil_Clay_Green"
    },
    {
      "x": -40,
      "y": 30,
      "z": 14,
      "name": "Soil_Clay_Lime"
    },
    {
      "x": -40,
      "y": 31,
      "z": 14,
      "name": "Plant_Grass_Sharp"
    },
    {
      "x": -40,
      "y": 17,
      "z": 15,
      "name": "Soil_Clay_Green"
    },
    {
      "x": -40,
      "y": 18,
      "z": 15,
      "name": "Soil_Seaweed_Block"
    },
    {
      "x": -40,
      "y": 30,
      "z": 15,
      "name": "Soil_Seaweed_Block"
    },
    {
      "x": -40,
      "y": 18,
      "z": 16,
      "name": "Soil_Seaweed_Block"
    },
    {
      "x": -40,
      "y": 30,
      "z": 16,
      "name": "Soil_Seaweed_Block"
    },
    {
      "x": -40,
      "y": 16,
      "z": 17,
      "name": "Soil_Clay_Green"
    },
    {
      "x": -40,
      "y": 16,
      "z": 18,
      "name": "Soil_Clay_Green"
    },
    {
      "x": -40,
      "y": 17,
      "z": 18,
      "name": "Soil_Seaweed_Block"
    },
    {
      "x": -40,
      "y": 25,
      "z": 18,
      "name": "Soil_Clay_Green"
    },
    {
      "x": -40,
      "y": 26,
      "z": 18,
      "name": "Soil_Clay_Green"
    },
    {
      "x": -40,
      "y": 27,
      "z": 18,
      "name": "Soil_Seaweed_Block"
    },
    {
      "x": -40,
      "y": 28,
      "z": 18,
      "name": "Soil_Clay_Lime"
    },
    {
      "x": -40,
      "y": 29,
      "z": 18,
      "name": "Plant_Grass_Sharp"
    },
    {
      "x": -40,
      "y": 15,
      "z": 19,
      "name": "Soil_Clay_Green"
    },
    {
      "x": -40,
      "y": 16,
      "z": 19,
      "name": "Soil_Clay_Green"
    },
    {
      "x": -40,
      "y": 26,
      "z": 19,
      "name": "Soil_Clay_Green"
    },
    {
      "x": -40,
      "y": 27,
      "z": 19,
      "name": "Soil_Seaweed_Block"
    },
    {
      "x": -40,
      "y": 28,
      "z": 19,
      "name": "Soil_Clay_Lime"
    },
    {
      "x": -40,
      "y": 29,
      "z": 19,
      "name": "Plant_Grass_Sharp"
    },
    {
      "x": -40,
      "y": 15,
      "z": 20,
      "name": "Soil_Clay_Green"
    },
    {
      "x": -40,
      "y": 16,
      "z": 20,
      "name": "Soil_Seaweed_Block"
    },
    {
      "x": -40,
      "y": 17,
      "z": 20,
      "name": "Soil_Clay_Lime"
    },
    {
      "x": -40,
      "y": 18,
      "z": 20,
      "name": "Plant_Grass_Sharp"
    },
    {
      "x": -40,
      "y": 25,
      "z": 20,
      "name": "Soil_Clay_Green"
    },
    {
      "x": -40,
      "y": 26,
      "z": 20,
      "name": "Soil_Seaweed_Block"
    },
    {
      "x": -40,
      "y": 27,
      "z": 20,
      "name": "Soil_Seaweed_Block"
    },
    {
      "x": -40,
      "y": 28,
      "z": 20,
      "name": "Soil_Seaweed_Block"
    },
    {
      "x": -40,
      "y": 29,
      "z": 20,
      "name": "Soil_Clay_Lime"
    },
    {
      "x": -40,
      "y": 30,
      "z": 20,
      "name": "Plant_Grass_Sharp"
    },
    {
      "x": -40,
      "y": 15,
      "z": 21,
      "name": "Soil_Clay_Green"
    },
    {
      "x": -40,
      "y": 16,
      "z": 21,
      "name": "Soil_Seaweed_Block"
    },
    {
      "x": -40,
      "y": 17,
      "z": 21,
      "name": "Soil_Clay_Lime"
    },
    {
      "x": -40,
      "y": 18,
      "z": 21,
      "name": "Plant_Grass_Sharp"
    },
    {
      "x": -40,
      "y": 26,
      "z": 21,
      "name": "Soil_Clay_Green"
    },
    {
      "x": -40,
      "y": 27,
      "z": 21,
      "name": "Soil_Seaweed_Block"
    },
    {
      "x": -40,
      "y": 28,
      "z": 21,
      "name": "Soil_Seaweed_Block"
    },
    {
      "x": -40,
      "y": 29,
      "z": 21,
      "name": "Soil_Clay_Lime"
    },
    {
      "x": -40,
      "y": 30,
      "z": 21,
      "name": "Plant_Grass_Sharp"
    },
    {
      "x": -40,
      "y": 16,
      "z": 22,
      "name": "Soil_Seaweed_Block"
    },
    {
      "x": -40,
      "y": 28,
      "z": 22,
      "name": "Soil_Seaweed_Block"
    },
    {
      "x": -40,
      "y": 29,
      "z": 23,
      "name": "Soil_Seaweed_Block"
    },
    {
      "x": -40,
      "y": 26,
      "z": 29,
      "name": "Soil_Seaweed_Block"
    },
    {
      "x": -40,
      "y": 25,
      "z": 30,
      "name": "Soil_Clay_Green"
    },
    {
      "x": -39,
      "y": 15,
      "z": 6,
      "name": "Soil_Clay_Green"
    },
    {
      "x": -39,
      "y": 16,
      "z": 6,
      "name": "Soil_Seaweed_Block"
    },
    {
      "x": -39,
      "y": 15,
      "z": 7,
      "name": "Soil_Clay_Green"
    },
    {
      "x": -39,
      "y": 16,
      "z": 7,
      "name": "Soil_Clay_Lime"
    },
    {
      "x": -39,
      "y": 17,
      "z": 7,
      "name": "Plant_Grass_Sharp"
    },
    {
      "x": -39,
      "y": 14,
      "z": 8,
      "name": "Soil_Clay_Green"
    },
    {
      "x": -39,
      "y": 15,
      "z": 8,
      "name": "Soil_Seaweed_Block"
    },
    {
      "x": -39,
      "y": 16,
      "z": 8,
      "name": "Soil_Clay_Lime"
    },
    {
      "x": -39,
      "y": 17,
      "z": 8,
      "name": "Plant_Grass_Sharp"
    },
    {
      "x": -39,
      "y": 28,
      "z": 8,
      "name": "Soil_Seaweed_Block"
    },
    {
      "x": -39,
      "y": 14,
      "z": 9,
      "name": "Soil_Clay_Green"
    },
    {
      "x": -39,
      "y": 15,
      "z": 9,
      "name": "Soil_Seaweed_Block"
    },
    {
      "x": -39,
      "y": 16,
      "z": 9,
      "name": "Soil_Clay_Lime"
    },
    {
      "x": -39,
      "y": 17,
      "z": 9,
      "name": "Plant_Grass_Sharp"
    },
    {
      "x": -39,
      "y": 27,
      "z": 9,
      "name": "Soil_Clay_Green"
    },
    {
      "x": -39,
      "y": 29,
      "z": 9,
      "name": "Soil_Clay_Lime"
    },
    {
      "x": -39,
      "y": 30,
      "z": 9,
      "name": "Soil_Clay_Lime"
    },
    {
      "x": -39,
      "y": 31,
      "z": 9,
      "name": "Plant_Grass_Sharp"
    },
    {
      "x": -39,
      "y": 15,
      "z": 10,
      "name": "Soil_Clay_Green"
    },
    {
      "x": -39,
      "y": 16,
      "z": 10,
      "name": "Soil_Seaweed_Block"
    },
    {
      "x": -39,
      "y": 25,
      "z": 10,
      "name": "Soil_Clay_Green"
    },
    {
      "x": -39,
      "y": 26,
      "z": 10,
      "name": "Soil_Clay_Green"
    },
    {
      "x": -39,
      "y": 27,
      "z": 10,
      "name": "Soil_Seaweed_Block"
    },
    {
      "x": -39,
      "y": 28,
      "z": 10,
      "name": "Soil_Seaweed_Block"
    },
    {
      "x": -39,
      "y": 29,
      "z": 10,
      "name": "Soil_Seaweed_Block"
    },
    {
      "x": -39,
      "y": 30,
      "z": 10,
      "name": "Soil_Clay_Lime"
    },
    {
      "x": -39,
      "y": 31,
      "z": 10,
      "name": "Plant_Grass_Sharp"
    },
    {
      "x": -39,
      "y": 26,
      "z": 11,
      "name": "Soil_Clay_Green"
    },
    {
      "x": -39,
      "y": 27,
      "z": 11,
      "name": "Soil_Seaweed_Block"
    },
    {
      "x": -39,
      "y": 28,
      "z": 11,
      "name": "Soil_Seaweed_Block"
    },
    {
      "x": -39,
      "y": 29,
      "z": 11,
      "name": "Soil_Seaweed_Block"
    },
    {
      "x": -39,
      "y": 30,
      "z": 11,
      "name": "Soil_Clay_Lime"
    },
    {
      "x": -39,
      "y": 31,
      "z": 11,
      "name": "Plant_Grass_Sharp"
    },
    {
      "x": -39,
      "y": 26,
      "z": 12,
      "name": "Soil_Clay_Green"
    },
    {
      "x": -39,
      "y": 27,
      "z": 12,
      "name": "Soil_Clay_Green"
    },
    {
      "x": -39,
      "y": 28,
      "z": 12,
      "name": "Soil_Seaweed_Block"
    },
    {
      "x": -39,
      "y": 29,
      "z": 12,
      "name": "Soil_Clay_Lime"
    },
    {
      "x": -39,
      "y": 30,
      "z": 12,
      "name": "Soil_Clay_Lime"
    },
    {
      "x": -39,
      "y": 31,
      "z": 12,
      "name": "Plant_Grass_Sharp"
    },
    {
      "x": -39,
      "y": 26,
      "z": 13,
      "name": "Soil_Clay_Green"
    },
    {
      "x": -39,
      "y": 27,
      "z": 13,
      "name": "Soil_Clay_Green"
    },
    {
      "x": -39,
      "y": 28,
      "z": 13,
      "name": "Soil_Seaweed_Block"
    },
    {
      "x": -39,
      "y": 29,
      "z": 13,
      "name": "Soil_Clay_Lime"
    },
    {
      "x": -39,
      "y": 30,
      "z": 13,
      "name": "Soil_Clay_Lime"
    },
    {
      "x": -39,
      "y": 31,
      "z": 13,
      "name": "Plant_Grass_Sharp"
    },
    {
      "x": -39,
      "y": 29,
      "z": 14,
      "name": "Soil_Seaweed_Block"
    },
    {
      "x": -39,
      "y": 30,
      "z": 14,
      "name": "Soil_Seaweed_Block"
    },
    {
      "x": -39,
      "y": 17,
      "z": 15,
      "name": "Soil_Clay_Green"
    },
    {
      "x": -39,
      "y": 18,
      "z": 15,
      "name": "Soil_Seaweed_Block"
    },
    {
      "x": -39,
      "y": 30,
      "z": 15,
      "name": "Soil_Seaweed_Block"
    },
    {
      "x": -39,
      "y": 18,
      "z": 16,
      "name": "Soil_Seaweed_Block"
    },
    {
      "x": -39,
      "y": 16,
      "z": 17,
      "name": "Soil_Clay_Green"
    },
    {
      "x": -39,
      "y": 18,
      "z": 17,
      "name": "Soil_Seaweed_Block"
    },
    {
      "x": -39,
      "y": 26,
      "z": 17,
      "name": "Soil_Clay_Green"
    },
    {
      "x": -39,
      "y": 27,
      "z": 17,
      "name": "Soil_Seaweed_Block"
    },
    {
      "x": -39,
      "y": 16,
      "z": 18,
      "name": "Soil_Clay_Green"
    },
    {
      "x": -39,
      "y": 17,
      "z": 18,
      "name": "Soil_Seaweed_Block"
    },
    {
      "x": -39,
      "y": 18,
      "z": 18,
      "name": "Soil_Clay_Lime"
    },
    {
      "x": -39,
      "y": 19,
      "z": 18,
      "name": "Plant_Grass_Sharp"
    },
    {
      "x": -39,
      "y": 25,
      "z": 18,
      "name": "Soil_Clay_Green"
    },
    {
      "x": -39,
      "y": 26,
      "z": 18,
      "name": "Soil_Seaweed_Block"
    },
    {
      "x": -39,
      "y": 27,
      "z": 18,
      "name": "Soil_Seaweed_Block"
    },
    {
      "x": -39,
      "y": 28,
      "z": 18,
      "name": "Soil_Clay_Lime"
    },
    {
      "x": -39,
      "y": 29,
      "z": 18,
      "name": "Plant_Grass_Sharp"
    },
    {
      "x": -39,
      "y": 15,
      "z": 19,
      "name": "Soil_Clay_Green"
    },
    {
      "x": -39,
      "y": 16,
      "z": 19,
      "name": "Soil_Seaweed_Block"
    },
    {
      "x": -39,
      "y": 17,
      "z": 19,
      "name": "Soil_Seaweed_Block"
    },
    {
      "x": -39,
      "y": 18,
      "z": 19,
      "name": "Soil_Clay_Lime"
    },
    {
      "x": -39,
      "y": 19,
      "z": 19,
      "name": "Plant_Grass_Sharp"
    },
    {
      "x": -39,
      "y": 26,
      "z": 19,
      "name": "Soil_Clay_Green"
    },
    {
      "x": -39,
      "y": 27,
      "z": 19,
      "name": "Soil_Seaweed_Block"
    },
    {
      "x": -39,
      "y": 28,
      "z": 19,
      "name": "Soil_Clay_Lime"
    },
    {
      "x": -39,
      "y": 29,
      "z": 19,
      "name": "Plant_Grass_Sharp"
    },
    {
      "x": -39,
      "y": 15,
      "z": 20,
      "name": "Soil_Clay_Green"
    },
    {
      "x": -39,
      "y": 16,
      "z": 20,
      "name": "Soil_Seaweed_Block"
    },
    {
      "x": -39,
      "y": 17,
      "z": 20,
      "name": "Soil_Clay_Lime"
    },
    {
      "x": -39,
      "y": 18,
      "z": 20,
      "name": "Soil_Clay_Lime"
    },
    {
      "x": -39,
      "y": 19,
      "z": 20,
      "name": "Plant_Grass_Sharp"
    },
    {
      "x": -39,
      "y": 25,
      "z": 20,
      "name": "Soil_Clay_Green"
    },
    {
      "x": -39,
      "y": 26,
      "z": 20,
      "name": "Soil_Clay_Green"
    },
    {
      "x": -39,
      "y": 27,
      "z": 20,
      "name": "Soil_Seaweed_Block"
    },
    {
      "x": -39,
      "y": 28,
      "z": 20,
      "name": "Soil_Clay_Lime"
    },
    {
      "x": -39,
      "y": 29,
      "z": 20,
      "name": "Plant_Grass_Sharp"
    },
    {
      "x": -39,
      "y": 16,
      "z": 21,
      "name": "Soil_Clay_Green"
    },
    {
      "x": -39,
      "y": 27,
      "z": 21,
      "name": "Soil_Seaweed_Block"
    },
    {
      "x": -39,
      "y": 28,
      "z": 21,
      "name": "Soil_Clay_Lime"
    },
    {
      "x": -39,
      "y": 29,
      "z": 21,
      "name": "Soil_Clay_Lime"
    },
    {
      "x": -39,
      "y": 30,
      "z": 21,
      "name": "Plant_Grass_Sharp"
    },
    {
      "x": -39,
      "y": 16,
      "z": 22,
      "name": "Soil_Clay_Green"
    },
    {
      "x": -39,
      "y": 25,
      "z": 29,
      "name": "Soil_Clay_Green"
    },
    {
      "x": -39,
      "y": 26,
      "z": 29,
      "name": "Soil_Seaweed_Block"
    },
    {
      "x": -38,
      "y": 14,
      "z": 7,
      "name": "Soil_Clay_Green"
    },
    {
      "x": -38,
      "y": 15,
      "z": 7,
      "name": "Soil_Clay_Green"
    },
    {
      "x": -38,
      "y": 16,
      "z": 7,
      "name": "Soil_Seaweed_Block"
    },
    {
      "x": -38,
      "y": 14,
      "z": 8,
      "name": "Soil_Clay_Green"
    },
    {
      "x": -38,
      "y": 15,
      "z": 8,
      "name": "Soil_Seaweed_Block"
    },
    {
      "x": -38,
      "y": 16,
      "z": 8,
      "name": "Soil_Seaweed_Block"
    },
    {
      "x": -38,
      "y": 17,
      "z": 8,
      "name": "Soil_Clay_Lime"
    },
    {
      "x": -38,
      "y": 18,
      "z": 8,
      "name": "Plant_Grass_Sharp"
    },
    {
      "x": -38,
      "y": 14,
      "z": 9,
      "name": "Soil_Clay_Green"
    },
    {
      "x": -38,
      "y": 15,
      "z": 9,
      "name": "Soil_Seaweed_Block"
    },
    {
      "x": -38,
      "y": 16,
      "z": 9,
      "name": "Soil_Clay_Lime"
    },
    {
      "x": -38,
      "y": 17,
      "z": 9,
      "name": "Plant_Grass_Sharp"
    },
    {
      "x": -38,
      "y": 27,
      "z": 9,
      "name": "Soil_Clay_Green"
    },
    {
      "x": -38,
      "y": 15,
      "z": 10,
      "name": "Soil_Clay_Green"
    },
    {
      "x": -38,
      "y": 16,
      "z": 10,
      "name": "Soil_Seaweed_Block"
    },
    {
      "x": -38,
      "y": 25,
      "z": 10,
      "name": "Soil_Clay_Green"
    },
    {
      "x": -38,
      "y": 26,
      "z": 10,
      "name": "Soil_Clay_Green"
    },
    {
      "x": -38,
      "y": 27,
      "z": 10,
      "name": "Soil_Seaweed_Block"
    },
    {
      "x": -38,
      "y": 28,
      "z": 10,
      "name": "Soil_Seaweed_Block"
    },
    {
      "x": -38,
      "y": 29,
      "z": 10,
      "name": "Soil_Seaweed_Block"
    },
    {
      "x": -38,
      "y": 30,
      "z": 10,
      "name": "Soil_Seaweed_Block"
    },
    {
      "x": -38,
      "y": 16,
      "z": 11,
      "name": "Soil_Seaweed_Block"
    },
    {
      "x": -38,
      "y": 17,
      "z": 11,
      "name": "Soil_Clay_Lime"
    },
    {
      "x": -38,
      "y": 18,
      "z": 11,
      "name": "Plant_Grass_Sharp"
    },
    {
      "x": -38,
      "y": 25,
      "z": 11,
      "name": "Soil_Clay_Green"
    },
    {
      "x": -38,
      "y": 26,
      "z": 11,
      "name": "Soil_Seaweed_Block"
    },
    {
      "x": -38,
      "y": 27,
      "z": 11,
      "name": "Soil_Seaweed_Block"
    },
    {
      "x": -38,
      "y": 28,
      "z": 11,
      "name": "Soil_Seaweed_Block"
    },
    {
      "x": -38,
      "y": 29,
      "z": 11,
      "name": "Soil_Clay_Lime"
    },
    {
      "x": -38,
      "y": 30,
      "z": 11,
      "name": "Plant_Grass_Sharp"
    },
    {
      "x": -38,
      "y": 25,
      "z": 12,
      "name": "Soil_Clay_Green"
    },
    {
      "x": -38,
      "y": 26,
      "z": 12,
      "name": "Soil_Seaweed_Block"
    },
    {
      "x": -38,
      "y": 27,
      "z": 12,
      "name": "Soil_Seaweed_Block"
    },
    {
      "x": -38,
      "y": 25,
      "z": 13,
      "name": "Soil_Clay_Green"
    },
    {
      "x": -38,
      "y": 26,
      "z": 13,
      "name": "Soil_Seaweed_Block"
    },
    {
      "x": -38,
      "y": 27,
      "z": 13,
      "name": "Soil_Seaweed_Block"
    },
    {
      "x": -38,
      "y": 26,
      "z": 14,
      "name": "Soil_Clay_Green"
    },
    {
      "x": -38,
      "y": 27,
      "z": 14,
      "name": "Soil_Seaweed_Block"
    },
    {
      "x": -38,
      "y": 18,
      "z": 16,
      "name": "Soil_Seaweed_Block"
    },
    {
      "x": -38,
      "y": 16,
      "z": 17,
      "name": "Soil_Clay_Green"
    },
    {
      "x": -38,
      "y": 17,
      "z": 17,
      "name": "Soil_Clay_Green"
    },
    {
      "x": -38,
      "y": 18,
      "z": 17,
      "name": "Soil_Seaweed_Block"
    },
    {
      "x": -38,
      "y": 26,
      "z": 17,
      "name": "Soil_Clay_Green"
    },
    {
      "x": -38,
      "y": 16,
      "z": 18,
      "name": "Soil_Clay_Green"
    },
    {
      "x": -38,
      "y": 17,
      "z": 18,
      "name": "Soil_Seaweed_Block"
    },
    {
      "x": -38,
      "y": 18,
      "z": 18,
      "name": "Soil_Seaweed_Block"
    },
    {
      "x": -38,
      "y": 19,
      "z": 18,
      "name": "Soil_Clay_Lime"
    },
    {
      "x": -38,
      "y": 20,
      "z": 18,
      "name": "Plant_Grass_Sharp"
    },
    {
      "x": -38,
      "y": 25,
      "z": 18,
      "name": "Soil_Clay_Green"
    },
    {
      "x": -38,
      "y": 26,
      "z": 18,
      "name": "Soil_Seaweed_Block"
    },
    {
      "x": -38,
      "y": 27,
      "z": 18,
      "name": "Soil_Seaweed_Block"
    },
    {
      "x": -38,
      "y": 28,
      "z": 18,
      "name": "Soil_Clay_Lime"
    },
    {
      "x": -38,
      "y": 29,
      "z": 18,
      "name": "Plant_Grass_Sharp"
    },
    {
      "x": -38,
      "y": 16,
      "z": 19,
      "name": "Soil_Clay_Green"
    },
    {
      "x": -38,
      "y": 17,
      "z": 19,
      "name": "Soil_Seaweed_Block"
    },
    {
      "x": -38,
      "y": 18,
      "z": 19,
      "name": "Soil_Seaweed_Block"
    },
    {
      "x": -38,
      "y": 19,
      "z": 19,
      "name": "Soil_Seaweed_Block"
    },
    {
      "x": -38,
      "y": 25,
      "z": 19,
      "name": "Soil_Clay_Green"
    },
    {
      "x": -38,
      "y": 26,
      "z": 19,
      "name": "Soil_Seaweed_Block"
    },
    {
      "x": -38,
      "y": 27,
      "z": 19,
      "name": "Soil_Seaweed_Block"
    },
    {
      "x": -38,
      "y": 28,
      "z": 19,
      "name": "Soil_Clay_Lime"
    },
    {
      "x": -38,
      "y": 29,
      "z": 19,
      "name": "Plant_Grass_Sharp"
    },
    {
      "x": -38,
      "y": 15,
      "z": 20,
      "name": "Soil_Clay_Green"
    },
    {
      "x": -38,
      "y": 16,
      "z": 20,
      "name": "Soil_Seaweed_Block"
    },
    {
      "x": -38,
      "y": 17,
      "z": 20,
      "name": "Soil_Seaweed_Block"
    },
    {
      "x": -38,
      "y": 18,
      "z": 20,
      "name": "Soil_Clay_Lime"
    },
    {
      "x": -38,
      "y": 19,
      "z": 20,
      "name": "Plant_Grass_Sharp"
    },
    {
      "x": -38,
      "y": 25,
      "z": 20,
      "name": "Soil_Clay_Green"
    },
    {
      "x": -38,
      "y": 26,
      "z": 20,
      "name": "Soil_Clay_Green"
    },
    {
      "x": -38,
      "y": 27,
      "z": 20,
      "name": "Soil_Clay_Lime"
    },
    {
      "x": -38,
      "y": 28,
      "z": 20,
      "name": "Plant_Grass_Sharp"
    },
    {
      "x": -38,
      "y": 16,
      "z": 21,
      "name": "Soil_Clay_Green"
    },
    {
      "x": -38,
      "y": 17,
      "z": 21,
      "name": "Soil_Seaweed_Block"
    },
    {
      "x": -38,
      "y": 27,
      "z": 21,
      "name": "Soil_Clay_Lime"
    },
    {
      "x": -38,
      "y": 28,
      "z": 21,
      "name": "Soil_Clay_Lime"
    },
    {
      "x": -38,
      "y": 29,
      "z": 21,
      "name": "Plant_Grass_Sharp"
    },
    {
      "x": -38,
      "y": 15,
      "z": 22,
      "name": "Soil_Clay_Green"
    },
    {
      "x": -38,
      "y": 16,
      "z": 22,
      "name": "Soil_Clay_Green"
    },
    {
      "x": -38,
      "y": 25,
      "z": 27,
      "name": "Soil_Clay_Green"
    },
    {
      "x": -38,
      "y": 25,
      "z": 28,
      "name": "Soil_Clay_Green"
    },
    {
      "x": -38,
      "y": 26,
      "z": 28,
      "name": "Soil_Clay_Lime"
    },
    {
      "x": -38,
      "y": 27,
      "z": 28,
      "name": "Plant_Grass_Sharp"
    },
    {
      "x": -38,
      "y": 26,
      "z": 29,
      "name": "Soil_Clay_Lime"
    },
    {
      "x": -38,
      "y": 27,
      "z": 29,
      "name": "Plant_Grass_Sharp"
    },
    {
      "x": -37,
      "y": 14,
      "z": 7,
      "name": "Soil_Clay_Green"
    },
    {
      "x": -37,
      "y": 15,
      "z": 7,
      "name": "Soil_Clay_Green"
    },
    {
      "x": -37,
      "y": 16,
      "z": 7,
      "name": "Soil_Seaweed_Block"
    },
    {
      "x": -37,
      "y": 14,
      "z": 8,
      "name": "Soil_Clay_Green"
    },
    {
      "x": -37,
      "y": 15,
      "z": 8,
      "name": "Soil_Seaweed_Block"
    },
    {
      "x": -37,
      "y": 16,
      "z": 8,
      "name": "Soil_Seaweed_Block"
    },
    {
      "x": -37,
      "y": 17,
      "z": 8,
      "name": "Soil_Clay_Lime"
    },
    {
      "x": -37,
      "y": 18,
      "z": 8,
      "name": "Plant_Grass_Sharp"
    },
    {
      "x": -37,
      "y": 14,
      "z": 9,
      "name": "Soil_Clay_Green"
    },
    {
      "x": -37,
      "y": 15,
      "z": 9,
      "name": "Soil_Seaweed_Block"
    },
    {
      "x": -37,
      "y": 16,
      "z": 9,
      "name": "Soil_Seaweed_Block"
    },
    {
      "x": -37,
      "y": 17,
      "z": 9,
      "name": "Soil_Clay_Lime"
    },
    {
      "x": -37,
      "y": 18,
      "z": 9,
      "name": "Plant_Grass_Sharp"
    },
    {
      "x": -37,
      "y": 14,
      "z": 10,
      "name": "Soil_Clay_Green"
    },
    {
      "x": -37,
      "y": 15,
      "z": 10,
      "name": "Soil_Seaweed_Block"
    },
    {
      "x": -37,
      "y": 16,
      "z": 10,
      "name": "Soil_Seaweed_Block"
    },
    {
      "x": -37,
      "y": 17,
      "z": 10,
      "name": "Soil_Clay_Lime"
    },
    {
      "x": -37,
      "y": 18,
      "z": 10,
      "name": "Plant_Grass_Sharp"
    },
    {
      "x": -37,
      "y": 25,
      "z": 10,
      "name": "Soil_Clay_Green"
    },
    {
      "x": -37,
      "y": 26,
      "z": 10,
      "name": "Soil_Clay_Green"
    },
    {
      "x": -37,
      "y": 27,
      "z": 10,
      "name": "Soil_Seaweed_Block"
    },
    {
      "x": -37,
      "y": 15,
      "z": 11,
      "name": "Soil_Clay_Green"
    },
    {
      "x": -37,
      "y": 16,
      "z": 11,
      "name": "Soil_Seaweed_Block"
    },
    {
      "x": -37,
      "y": 17,
      "z": 11,
      "name": "Soil_Seaweed_Block"
    },
    {
      "x": -37,
      "y": 25,
      "z": 11,
      "name": "Soil_Clay_Green"
    },
    {
      "x": -37,
      "y": 26,
      "z": 11,
      "name": "Soil_Seaweed_Block"
    },
    {
      "x": -37,
      "y": 27,
      "z": 11,
      "name": "Soil_Seaweed_Block"
    },
    {
      "x": -37,
      "y": 28,
      "z": 11,
      "name": "Soil_Seaweed_Block"
    },
    {
      "x": -37,
      "y": 24,
      "z": 12,
      "name": "Soil_Clay_Green"
    },
    {
      "x": -37,
      "y": 25,
      "z": 12,
      "name": "Soil_Seaweed_Block"
    },
    {
      "x": -37,
      "y": 26,
      "z": 12,
      "name": "Soil_Seaweed_Block"
    },
    {
      "x": -37,
      "y": 27,
      "z": 12,
      "name": "Soil_Clay_Lime"
    },
    {
      "x": -37,
      "y": 28,
      "z": 12,
      "name": "Plant_Grass_Sharp"
    },
    {
      "x": -37,
      "y": 24,
      "z": 13,
      "name": "Soil_Clay_Green"
    },
    {
      "x": -37,
      "y": 25,
      "z": 13,
      "name": "Soil_Clay_Green"
    },
    {
      "x": -37,
      "y": 26,
      "z": 13,
      "name": "Soil_Seaweed_Block"
    },
    {
      "x": -37,
      "y": 27,
      "z": 13,
      "name": "Soil_Seaweed_Block"
    },
    {
      "x": -37,
      "y": 26,
      "z": 14,
      "name": "Soil_Seaweed_Block"
    },
    {
      "x": -37,
      "y": 27,
      "z": 14,
      "name": "Soil_Seaweed_Block"
    },
    {
      "x": -37,
      "y": 16,
      "z": 17,
      "name": "Soil_Clay_Green"
    },
    {
      "x": -37,
      "y": 17,
      "z": 17,
      "name": "Soil_Clay_Green"
    },
    {
      "x": -37,
      "y": 18,
      "z": 17,
      "name": "Soil_Seaweed_Block"
    },
    {
      "x": -37,
      "y": 19,
      "z": 17,
      "name": "Soil_Seaweed_Block"
    },
    {
      "x": -37,
      "y": 20,
      "z": 17,
      "name": "Soil_Seaweed_Block"
    },
    {
      "x": -37,
      "y": 26,
      "z": 17,
      "name": "Soil_Seaweed_Block"
    },
    {
      "x": -37,
      "y": 16,
      "z": 18,
      "name": "Soil_Clay_Green"
    },
    {
      "x": -37,
      "y": 17,
      "z": 18,
      "name": "Soil_Seaweed_Block"
    },
    {
      "x": -37,
      "y": 18,
      "z": 18,
      "name": "Soil_Seaweed_Block"
    },
    {
      "x": -37,
      "y": 19,
      "z": 18,
      "name": "Soil_Seaweed_Block"
    },
    {
      "x": -37,
      "y": 20,
      "z": 18,
      "name": "Soil_Seaweed_Block"
    },
    {
      "x": -37,
      "y": 24,
      "z": 18,
      "name": "Soil_Clay_Green"
    },
    {
      "x": -37,
      "y": 25,
      "z": 18,
      "name": "Soil_Clay_Green"
    },
    {
      "x": -37,
      "y": 26,
      "z": 18,
      "name": "Soil_Seaweed_Block"
    },
    {
      "x": -37,
      "y": 27,
      "z": 18,
      "name": "Soil_Clay_Lime"
    },
    {
      "x": -37,
      "y": 28,
      "z": 18,
      "name": "Plant_Grass_Sharp"
    },
    {
      "x": -37,
      "y": 16,
      "z": 19,
      "name": "Soil_Clay_Green"
    },
    {
      "x": -37,
      "y": 17,
      "z": 19,
      "name": "Soil_Seaweed_Block"
    },
    {
      "x": -37,
      "y": 18,
      "z": 19,
      "name": "Soil_Seaweed_Block"
    },
    {
      "x": -37,
      "y": 19,
      "z": 19,
      "name": "Soil_Seaweed_Block"
    },
    {
      "x": -37,
      "y": 20,
      "z": 19,
      "name": "Soil_Seaweed_Block"
    },
    {
      "x": -37,
      "y": 21,
      "z": 19,
      "name": "Soil_Seaweed_Block"
    },
    {
      "x": -37,
      "y": 22,
      "z": 19,
      "name": "Soil_Clay_Green"
    },
    {
      "x": -37,
      "y": 23,
      "z": 19,
      "name": "Soil_Clay_Green"
    },
    {
      "x": -37,
      "y": 24,
      "z": 19,
      "name": "Soil_Clay_Green"
    },
    {
      "x": -37,
      "y": 25,
      "z": 19,
      "name": "Soil_Seaweed_Block"
    },
    {
      "x": -37,
      "y": 26,
      "z": 19,
      "name": "Soil_Seaweed_Block"
    },
    {
      "x": -37,
      "y": 27,
      "z": 19,
      "name": "Soil_Clay_Lime"
    },
    {
      "x": -37,
      "y": 28,
      "z": 19,
      "name": "Plant_Grass_Sharp"
    },
    {
      "x": -37,
      "y": 15,
      "z": 20,
      "name": "Soil_Clay_Green"
    },
    {
      "x": -37,
      "y": 16,
      "z": 20,
      "name": "Soil_Seaweed_Block"
    },
    {
      "x": -37,
      "y": 17,
      "z": 20,
      "name": "Soil_Seaweed_Block"
    },
    {
      "x": -37,
      "y": 18,
      "z": 20,
      "name": "Soil_Seaweed_Block"
    },
    {
      "x": -37,
      "y": 21,
      "z": 20,
      "name": "Soil_Seaweed_Block"
    },
    {
      "x": -37,
      "y": 22,
      "z": 20,
      "name": "Soil_Clay_Green"
    },
    {
      "x": -37,
      "y": 23,
      "z": 20,
      "name": "Soil_Clay_Green"
    },
    {
      "x": -37,
      "y": 24,
      "z": 20,
      "name": "Soil_Clay_Green"
    },
    {
      "x": -37,
      "y": 25,
      "z": 20,
      "name": "Soil_Seaweed_Block"
    },
    {
      "x": -37,
      "y": 26,
      "z": 20,
      "name": "Soil_Seaweed_Block"
    },
    {
      "x": -37,
      "y": 27,
      "z": 20,
      "name": "Soil_Clay_Lime"
    },
    {
      "x": -37,
      "y": 28,
      "z": 20,
      "name": "Plant_Grass_Sharp"
    },
    {
      "x": -37,
      "y": 16,
      "z": 21,
      "name": "Soil_Clay_Green"
    },
    {
      "x": -37,
      "y": 17,
      "z": 21,
      "name": "Soil_Seaweed_Block"
    },
    {
      "x": -37,
      "y": 23,
      "z": 21,
      "name": "Soil_Clay_Green"
    },
    {
      "x": -37,
      "y": 24,
      "z": 21,
      "name": "Soil_Clay_Green"
    },
    {
      "x": -37,
      "y": 25,
      "z": 21,
      "name": "Soil_Clay_Green"
    },
    {
      "x": -37,
      "y": 26,
      "z": 21,
      "name": "Soil_Seaweed_Block"
    },
    {
      "x": -37,
      "y": 27,
      "z": 21,
      "name": "Soil_Clay_Lime"
    },
    {
      "x": -37,
      "y": 28,
      "z": 21,
      "name": "Plant_Grass_Sharp"
    },
    {
      "x": -37,
      "y": 24,
      "z": 22,
      "name": "Soil_Clay_Green"
    },
    {
      "x": -37,
      "y": 25,
      "z": 22,
      "name": "Soil_Clay_Green"
    },
    {
      "x": -37,
      "y": 26,
      "z": 22,
      "name": "Soil_Seaweed_Block"
    },
    {
      "x": -37,
      "y": 24,
      "z": 23,
      "name": "Soil_Clay_Green"
    },
    {
      "x": -37,
      "y": 25,
      "z": 23,
      "name": "Soil_Clay_Green"
    },
    {
      "x": -37,
      "y": 26,
      "z": 23,
      "name": "Soil_Clay_Lime"
    },
    {
      "x": -37,
      "y": 27,
      "z": 23,
      "name": "Plant_Grass_Sharp"
    },
    {
      "x": -37,
      "y": 24,
      "z": 24,
      "name": "Soil_Clay_Green"
    },
    {
      "x": -37,
      "y": 25,
      "z": 24,
      "name": "Soil_Clay_Green"
    },
    {
      "x": -37,
      "y": 26,
      "z": 24,
      "name": "Soil_Clay_Lime"
    },
    {
      "x": -37,
      "y": 27,
      "z": 24,
      "name": "Plant_Grass_Sharp"
    },
    {
      "x": -37,
      "y": 24,
      "z": 25,
      "name": "Soil_Clay_Green"
    },
    {
      "x": -37,
      "y": 25,
      "z": 25,
      "name": "Soil_Clay_Green"
    },
    {
      "x": -37,
      "y": 26,
      "z": 25,
      "name": "Soil_Clay_Lime"
    },
    {
      "x": -37,
      "y": 27,
      "z": 25,
      "name": "Plant_Grass_Sharp"
    },
    {
      "x": -37,
      "y": 25,
      "z": 26,
      "name": "Soil_Clay_Green"
    },
    {
      "x": -37,
      "y": 24,
      "z": 27,
      "name": "Soil_Clay_Green"
    },
    {
      "x": -37,
      "y": 25,
      "z": 27,
      "name": "Soil_Clay_Green"
    },
    {
      "x": -37,
      "y": 25,
      "z": 28,
      "name": "Soil_Clay_Green"
    },
    {
      "x": -37,
      "y": 26,
      "z": 28,
      "name": "Soil_Clay_Lime"
    },
    {
      "x": -37,
      "y": 27,
      "z": 28,
      "name": "Plant_Grass_Sharp"
    },
    {
      "x": -37,
      "y": 25,
      "z": 29,
      "name": "Soil_Clay_Green"
    },
    {
      "x": -37,
      "y": 26,
      "z": 29,
      "name": "Soil_Seaweed_Block"
    },
    {
      "x": -36,
      "y": 14,
      "z": 8,
      "name": "Soil_Clay_Green"
    },
    {
      "x": -36,
      "y": 15,
      "z": 8,
      "name": "Soil_Clay_Green"
    },
    {
      "x": -36,
      "y": 16,
      "z": 8,
      "name": "Soil_Seaweed_Block"
    },
    {
      "x": -36,
      "y": 14,
      "z": 9,
      "name": "Soil_Clay_Green"
    },
    {
      "x": -36,
      "y": 15,
      "z": 9,
      "name": "Soil_Seaweed_Block"
    },
    {
      "x": -36,
      "y": 16,
      "z": 9,
      "name": "Soil_Seaweed_Block"
    },
    {
      "x": -36,
      "y": 17,
      "z": 9,
      "name": "Soil_Clay_Lime"
    },
    {
      "x": -36,
      "y": 18,
      "z": 9,
      "name": "Plant_Grass_Sharp"
    },
    {
      "x": -36,
      "y": 14,
      "z": 10,
      "name": "Soil_Clay_Green"
    },
    {
      "x": -36,
      "y": 15,
      "z": 10,
      "name": "Soil_Seaweed_Block"
    },
    {
      "x": -36,
      "y": 16,
      "z": 10,
      "name": "Soil_Seaweed_Block"
    },
    {
      "x": -36,
      "y": 17,
      "z": 10,
      "name": "Soil_Seaweed_Block"
    },
    {
      "x": -36,
      "y": 18,
      "z": 10,
      "name": "Soil_Clay_Lime"
    },
    {
      "x": -36,
      "y": 19,
      "z": 10,
      "name": "Plant_Grass_Sharp"
    },
    {
      "x": -36,
      "y": 13,
      "z": 11,
      "name": "Soil_Clay_Green"
    },
    {
      "x": -36,
      "y": 14,
      "z": 11,
      "name": "Soil_Clay_Green"
    },
    {
      "x": -36,
      "y": 15,
      "z": 11,
      "name": "Soil_Seaweed_Block"
    },
    {
      "x": -36,
      "y": 16,
      "z": 11,
      "name": "Soil_Seaweed_Block"
    },
    {
      "x": -36,
      "y": 17,
      "z": 11,
      "name": "Soil_Seaweed_Block"
    },
    {
      "x": -36,
      "y": 23,
      "z": 11,
      "name": "Soil_Clay_Green"
    },
    {
      "x": -36,
      "y": 24,
      "z": 11,
      "name": "Soil_Clay_Green"
    },
    {
      "x": -36,
      "y": 25,
      "z": 11,
      "name": "Soil_Clay_Green"
    },
    {
      "x": -36,
      "y": 26,
      "z": 11,
      "name": "Soil_Seaweed_Block"
    },
    {
      "x": -36,
      "y": 27,
      "z": 11,
      "name": "Soil_Seaweed_Block"
    },
    {
      "x": -36,
      "y": 15,
      "z": 12,
      "name": "Soil_Clay_Green"
    },
    {
      "x": -36,
      "y": 16,
      "z": 12,
      "name": "Soil_Seaweed_Block"
    },
    {
      "x": -36,
      "y": 24,
      "z": 12,
      "name": "Soil_Clay_Green"
    },
    {
      "x": -36,
      "y": 25,
      "z": 12,
      "name": "Soil_Seaweed_Block"
    },
    {
      "x": -36,
      "y": 26,
      "z": 12,
      "name": "Soil_Seaweed_Block"
    },
    {
      "x": -36,
      "y": 27,
      "z": 12,
      "name": "Soil_Clay_Lime"
    },
    {
      "x": -36,
      "y": 28,
      "z": 12,
      "name": "Plant_Grass_Sharp"
    },
    {
      "x": -36,
      "y": 15,
      "z": 13,
      "name": "Soil_Clay_Green"
    },
    {
      "x": -36,
      "y": 16,
      "z": 13,
      "name": "Soil_Seaweed_Block"
    },
    {
      "x": -36,
      "y": 24,
      "z": 13,
      "name": "Soil_Clay_Green"
    },
    {
      "x": -36,
      "y": 25,
      "z": 13,
      "name": "Soil_Seaweed_Block"
    },
    {
      "x": -36,
      "y": 26,
      "z": 13,
      "name": "Soil_Seaweed_Block"
    },
    {
      "x": -36,
      "y": 27,
      "z": 13,
      "name": "Soil_Clay_Lime"
    },
    {
      "x": -36,
      "y": 28,
      "z": 13,
      "name": "Plant_Grass_Sharp"
    },
    {
      "x": -36,
      "y": 25,
      "z": 14,
      "name": "Soil_Clay_Green"
    },
    {
      "x": -36,
      "y": 26,
      "z": 14,
      "name": "Soil_Seaweed_Block"
    },
    {
      "x": -36,
      "y": 27,
      "z": 14,
      "name": "Soil_Clay_Lime"
    },
    {
      "x": -36,
      "y": 28,
      "z": 14,
      "name": "Plant_Grass_Sharp"
    },
    {
      "x": -36,
      "y": 16,
      "z": 15,
      "name": "Soil_Clay_Green"
    },
    {
      "x": -36,
      "y": 15,
      "z": 16,
      "name": "Soil_Clay_Green"
    },
    {
      "x": -36,
      "y": 16,
      "z": 16,
      "name": "Soil_Clay_Green"
    },
    {
      "x": -36,
      "y": 17,
      "z": 16,
      "name": "Soil_Clay_Green"
    },
    {
      "x": -36,
      "y": 15,
      "z": 17,
      "name": "Soil_Clay_Green"
    },
    {
      "x": -36,
      "y": 16,
      "z": 17,
      "name": "Soil_Seaweed_Block"
    },
    {
      "x": -36,
      "y": 17,
      "z": 17,
      "name": "Soil_Seaweed_Block"
    },
    {
      "x": -36,
      "y": 18,
      "z": 17,
      "name": "Soil_Seaweed_Block"
    },
    {
      "x": -36,
      "y": 19,
      "z": 17,
      "name": "Soil_Seaweed_Block"
    },
    {
      "x": -36,
      "y": 20,
      "z": 17,
      "name": "Soil_Seaweed_Block"
    },
    {
      "x": -36,
      "y": 24,
      "z": 17,
      "name": "Soil_Clay_Green"
    },
    {
      "x": -36,
      "y": 25,
      "z": 17,
      "name": "Soil_Seaweed_Block"
    },
    {
      "x": -36,
      "y": 16,
      "z": 18,
      "name": "Soil_Clay_Green"
    },
    {
      "x": -36,
      "y": 17,
      "z": 18,
      "name": "Soil_Seaweed_Block"
    },
    {
      "x": -36,
      "y": 18,
      "z": 18,
      "name": "Soil_Seaweed_Block"
    },
    {
      "x": -36,
      "y": 19,
      "z": 18,
      "name": "Soil_Seaweed_Block"
    },
    {
      "x": -36,
      "y": 20,
      "z": 18,
      "name": "Soil_Seaweed_Block"
    },
    {
      "x": -36,
      "y": 21,
      "z": 18,
      "name": "Soil_Seaweed_Block"
    },
    {
      "x": -36,
      "y": 22,
      "z": 18,
      "name": "Soil_Seaweed_Block"
    },
    {
      "x": -36,
      "y": 23,
      "z": 18,
      "name": "Soil_Clay_Green"
    },
    {
      "x": -36,
      "y": 24,
      "z": 18,
      "name": "Soil_Seaweed_Block"
    },
    {
      "x": -36,
      "y": 25,
      "z": 18,
      "name": "Soil_Seaweed_Block"
    },
    {
      "x": -36,
      "y": 26,
      "z": 18,
      "name": "Soil_Seaweed_Block"
    },
    {
      "x": -36,
      "y": 27,
      "z": 18,
      "name": "Soil_Clay_Lime"
    },
    {
      "x": -36,
      "y": 28,
      "z": 18,
      "name": "Plant_Grass_Sharp"
    },
    {
      "x": -36,
      "y": 15,
      "z": 19,
      "name": "Soil_Clay_Green"
    },
    {
      "x": -36,
      "y": 16,
      "z": 19,
      "name": "Soil_Seaweed_Block"
    },
    {
      "x": -36,
      "y": 17,
      "z": 19,
      "name": "Soil_Seaweed_Block"
    },
    {
      "x": -36,
      "y": 18,
      "z": 19,
      "name": "Soil_Seaweed_Block"
    },
    {
      "x": -36,
      "y": 19,
      "z": 19,
      "name": "Soil_Seaweed_Block"
    },
    {
      "x": -36,
      "y": 20,
      "z": 19,
      "name": "Soil_Seaweed_Block"
    },
    {
      "x": -36,
      "y": 21,
      "z": 19,
      "name": "Soil_Seaweed_Block"
    },
    {
      "x": -36,
      "y": 22,
      "z": 19,
      "name": "Soil_Seaweed_Block"
    },
    {
      "x": -36,
      "y": 23,
      "z": 19,
      "name": "Soil_Seaweed_Block"
    },
    {
      "x": -36,
      "y": 24,
      "z": 19,
      "name": "Soil_Seaweed_Block"
    },
    {
      "x": -36,
      "y": 25,
      "z": 19,
      "name": "Soil_Seaweed_Block"
    },
    {
      "x": -36,
      "y": 26,
      "z": 19,
      "name": "Soil_Seaweed_Block"
    },
    {
      "x": -36,
      "y": 27,
      "z": 19,
      "name": "Soil_Clay_Lime"
    },
    {
      "x": -36,
      "y": 28,
      "z": 19,
      "name": "Plant_Grass_Sharp"
    },
    {
      "x": -36,
      "y": 15,
      "z": 20,
      "name": "Soil_Clay_Green"
    },
    {
      "x": -36,
      "y": 16,
      "z": 20,
      "name": "Soil_Seaweed_Block"
    },
    {
      "x": -36,
      "y": 17,
      "z": 20,
      "name": "Soil_Clay_Green"
    },
    {
      "x": -36,
      "y": 18,
      "z": 20,
      "name": "Soil_Seaweed_Block"
    },
    {
      "x": -36,
      "y": 19,
      "z": 20,
      "name": "Soil_Seaweed_Block"
    },
    {
      "x": -36,
      "y": 20,
      "z": 20,
      "name": "Soil_Seaweed_Block"
    },
    {
      "x": -36,
      "y": 21,
      "z": 20,
      "name": "Soil_Seaweed_Block"
    },
    {
      "x": -36,
      "y": 22,
      "z": 20,
      "name": "Soil_Seaweed_Block"
    },
    {
      "x": -36,
      "y": 23,
      "z": 20,
      "name": "Soil_Seaweed_Block"
    },
    {
      "x": -36,
      "y": 24,
      "z": 20,
      "name": "Soil_Seaweed_Block"
    },
    {
      "x": -36,
      "y": 25,
      "z": 20,
      "name": "Soil_Seaweed_Block"
    },
    {
      "x": -36,
      "y": 26,
      "z": 20,
      "name": "Soil_Seaweed_Block"
    },
    {
      "x": -36,
      "y": 27,
      "z": 20,
      "name": "Soil_Clay_Lime"
    },
    {
      "x": -36,
      "y": 28,
      "z": 20,
      "name": "Plant_Grass_Sharp"
    },
    {
      "x": -36,
      "y": 16,
      "z": 21,
      "name": "Soil_Clay_Green"
    },
    {
      "x": -36,
      "y": 18,
      "z": 21,
      "name": "Soil_Seaweed_Block"
    },
    {
      "x": -36,
      "y": 19,
      "z": 21,
      "name": "Soil_Seaweed_Block"
    },
    {
      "x": -36,
      "y": 20,
      "z": 21,
      "name": "Soil_Seaweed_Block"
    },
    {
      "x": -36,
      "y": 21,
      "z": 21,
      "name": "Soil_Seaweed_Block"
    },
    {
      "x": -36,
      "y": 22,
      "z": 21,
      "name": "Soil_Clay_Green"
    },
    {
      "x": -36,
      "y": 23,
      "z": 21,
      "name": "Soil_Clay_Green"
    },
    {
      "x": -36,
      "y": 24,
      "z": 21,
      "name": "Soil_Seaweed_Block"
    },
    {
      "x": -36,
      "y": 25,
      "z": 21,
      "name": "Soil_Seaweed_Block"
    },
    {
      "x": -36,
      "y": 26,
      "z": 21,
      "name": "Soil_Clay_Lime"
    },
    {
      "x": -36,
      "y": 27,
      "z": 21,
      "name": "Soil_Clay_Lime"
    },
    {
      "x": -36,
      "y": 28,
      "z": 21,
      "name": "Plant_Grass_Sharp"
    },
    {
      "x": -36,
      "y": 19,
      "z": 22,
      "name": "Soil_Seaweed_Block"
    },
    {
      "x": -36,
      "y": 20,
      "z": 22,
      "name": "Soil_Seaweed_Block"
    },
    {
      "x": -36,
      "y": 21,
      "z": 22,
      "name": "Soil_Seaweed_Block"
    },
    {
      "x": -36,
      "y": 24,
      "z": 22,
      "name": "Soil_Clay_Green"
    },
    {
      "x": -36,
      "y": 25,
      "z": 22,
      "name": "Soil_Seaweed_Block"
    },
    {
      "x": -36,
      "y": 26,
      "z": 22,
      "name": "Soil_Clay_Lime"
    },
    {
      "x": -36,
      "y": 27,
      "z": 22,
      "name": "Plant_Grass_Sharp"
    },
    {
      "x": -36,
      "y": 24,
      "z": 23,
      "name": "Soil_Clay_Green"
    },
    {
      "x": -36,
      "y": 25,
      "z": 23,
      "name": "Soil_Seaweed_Block"
    },
    {
      "x": -36,
      "y": 26,
      "z": 23,
      "name": "Soil_Clay_Lime"
    },
    {
      "x": -36,
      "y": 27,
      "z": 23,
      "name": "Plant_Grass_Sharp"
    },
    {
      "x": -36,
      "y": 25,
      "z": 24,
      "name": "Soil_Clay_Green"
    },
    {
      "x": -36,
      "y": 26,
      "z": 24,
      "name": "Soil_Clay_Lime"
    },
    {
      "x": -36,
      "y": 27,
      "z": 24,
      "name": "Plant_Grass_Sharp"
    },
    {
      "x": -36,
      "y": 25,
      "z": 25,
      "name": "Soil_Clay_Green"
    },
    {
      "x": -36,
      "y": 25,
      "z": 26,
      "name": "Soil_Clay_Green"
    },
    {
      "x": -36,
      "y": 25,
      "z": 27,
      "name": "Soil_Clay_Green"
    },
    {
      "x": -36,
      "y": 25,
      "z": 28,
      "name": "Soil_Clay_Green"
    },
    {
      "x": -35,
      "y": 14,
      "z": 8,
      "name": "Soil_Clay_Green"
    },
    {
      "x": -35,
      "y": 13,
      "z": 9,
      "name": "Soil_Clay_Green"
    },
    {
      "x": -35,
      "y": 14,
      "z": 9,
      "name": "Soil_Seaweed_Block"
    },
    {
      "x": -35,
      "y": 15,
      "z": 9,
      "name": "Soil_Clay_Green"
    },
    {
      "x": -35,
      "y": 16,
      "z": 9,
      "name": "Soil_Seaweed_Block"
    },
    {
      "x": -35,
      "y": 17,
      "z": 9,
      "name": "Soil_Seaweed_Block"
    },
    {
      "x": -35,
      "y": 22,
      "z": 9,
      "name": "Soil_Clay_Green"
    },
    {
      "x": -35,
      "y": 23,
      "z": 9,
      "name": "Soil_Seaweed_Block"
    },
    {
      "x": -35,
      "y": 13,
      "z": 10,
      "name": "Soil_Clay_Green"
    },
    {
      "x": -35,
      "y": 14,
      "z": 10,
      "name": "Soil_Seaweed_Block"
    },
    {
      "x": -35,
      "y": 15,
      "z": 10,
      "name": "Soil_Seaweed_Block"
    },
    {
      "x": -35,
      "y": 16,
      "z": 10,
      "name": "Soil_Seaweed_Block"
    },
    {
      "x": -35,
      "y": 17,
      "z": 10,
      "name": "Soil_Seaweed_Block"
    },
    {
      "x": -35,
      "y": 18,
      "z": 10,
      "name": "Soil_Clay_Lime"
    },
    {
      "x": -35,
      "y": 19,
      "z": 10,
      "name": "Soil_Seaweed_Block"
    },
    {
      "x": -35,
      "y": 20,
      "z": 10,
      "name": "Soil_Seaweed_Block"
    },
    {
      "x": -35,
      "y": 21,
      "z": 10,
      "name": "Soil_Clay_Green"
    },
    {
      "x": -35,
      "y": 14,
      "z": 11,
      "name": "Soil_Clay_Green"
    },
    {
      "x": -35,
      "y": 15,
      "z": 11,
      "name": "Soil_Seaweed_Block"
    },
    {
      "x": -35,
      "y": 16,
      "z": 11,
      "name": "Soil_Seaweed_Block"
    },
    {
      "x": -35,
      "y": 17,
      "z": 11,
      "name": "Soil_Seaweed_Block"
    },
    {
      "x": -35,
      "y": 18,
      "z": 11,
      "name": "Soil_Seaweed_Block"
    },
    {
      "x": -35,
      "y": 19,
      "z": 11,
      "name": "Soil_Seaweed_Block"
    },
    {
      "x": -35,
      "y": 22,
      "z": 11,
      "name": "Soil_Clay_Green"
    },
    {
      "x": -35,
      "y": 23,
      "z": 11,
      "name": "Soil_Clay_Green"
    },
    {
      "x": -35,
      "y": 24,
      "z": 11,
      "name": "Soil_Seaweed_Block"
    },
    {
      "x": -35,
      "y": 13,
      "z": 12,
      "name": "Soil_Clay_Green"
    },
    {
      "x": -35,
      "y": 14,
      "z": 12,
      "name": "Soil_Clay_Green"
    },
    {
      "x": -35,
      "y": 15,
      "z": 12,
      "name": "Soil_Seaweed_Block"
    },
    {
      "x": -35,
      "y": 16,
      "z": 12,
      "name": "Soil_Seaweed_Block"
    },
    {
      "x": -35,
      "y": 17,
      "z": 12,
      "name": "Soil_Seaweed_Block"
    },
    {
      "x": -35,
      "y": 18,
      "z": 12,
      "name": "Soil_Seaweed_Block"
    },
    {
      "x": -35,
      "y": 19,
      "z": 12,
      "name": "Soil_Seaweed_Block"
    },
    {
      "x": -35,
      "y": 20,
      "z": 12,
      "name": "Soil_Seaweed_Block"
    },
    {
      "x": -35,
      "y": 21,
      "z": 12,
      "name": "Soil_Clay_Green"
    },
    {
      "x": -35,
      "y": 22,
      "z": 12,
      "name": "Soil_Clay_Green"
    },
    {
      "x": -35,
      "y": 23,
      "z": 12,
      "name": "Soil_Clay_Green"
    },
    {
      "x": -35,
      "y": 24,
      "z": 12,
      "name": "Soil_Seaweed_Block"
    },
    {
      "x": -35,
      "y": 25,
      "z": 12,
      "name": "Soil_Seaweed_Block"
    },
    {
      "x": -35,
      "y": 26,
      "z": 12,
      "name": "Soil_Clay_Lime"
    },
    {
      "x": -35,
      "y": 27,
      "z": 12,
      "name": "Plant_Grass_Sharp"
    },
    {
      "x": -35,
      "y": 13,
      "z": 13,
      "name": "Soil_Clay_Green"
