{
  "version": 8,
  "blockIdVersion": 10,
  "anchorX": 0,
  "anchorY": 0,
  "anchorZ": 0,
  "blocks": [
    {
      "x": -12,
      "y": 6,
      "z": 2,
      "name": "Rock_Sandstone_Red"
    },
    {
      "x": -12,
      "y": 7,
      "z": 2,
      "name": "Rock_Sandstone_Red"
    },
    {
      "x": -12,
      "y": 8,
      "z": 2,
      "name": "Rock_Sandstone_Red"
    },
    {
      "x": -12,
      "y": 9,
      "z": 2,
      "name": "Rock_Sandstone"
    },
    {
      "x": -12,
      "y": 10,
      "z": 2,
      "name": "Soil_Clay_Orange"
    },
    {
      "x": -12,
      "y": 11,
      "z": 2,
      "name": "Soil_Clay_Orange"
    },
    {
      "x": -12,
      "y": 12,
      "z": 2,
      "name": "Soil_Clay_Orange"
    },
    {
      "x": -12,
      "y": 13,
      "z": 2,
      "name": "Soil_Clay_Orange"
    },
    {
      "x": -12,
      "y": 4,
      "z": 3,
      "name": "Rock_Sandstone_Red"
    },
    {
      "x": -12,
      "y": 5,
      "z": 3,
      "name": "Rock_Sandstone_Red"
    },
    {
      "x": -12,
      "y": 6,
      "z": 3,
      "name": "Rock_Sandstone_Red"
    },
    {
      "x": -12,
      "y": 7,
      "z": 3,
      "name": "Rock_Sandstone_Red"
    },
    {
      "x": -12,
      "y": 8,
      "z": 3,
      "name": "Rock_Sandstone_Red"
    },
    {
      "x": -12,
      "y": 9,
      "z": 3,
      "name": "Rock_Sandstone"
    },
    {
      "x": -12,
      "y": 10,
      "z": 3,
      "name": "Soil_Clay_Orange"
    },
    {
      "x": -12,
      "y": 11,
      "z": 3,
      "name": "Soil_Clay_Orange"
    },
    {
      "x": -12,
      "y": 12,
      "z": 3,
      "name": "Soil_Clay_Orange"
    },
    {
      "x": -12,
      "y": 13,
      "z": 3,
      "name": "Soil_Clay_Orange"
    },
    {
      "x": -11,
      "y": 4,
      "z": 1,
      "name": "Rock_Sandstone_Red"
    },
    {
      "x": -11,
      "y": 5,
      "z": 1,
      "name": "Rock_Sandstone_Red"
    },
    {
      "x": -11,
      "y": 6,
      "z": 1,
      "name": "Rock_Sandstone_Red"
    },
    {
      "x": -11,
      "y": 7,
      "z": 1,
      "name": "Rock_Sandstone_Red"
    },
    {
      "x": -11,
      "y": 8,
      "z": 1,
      "name": "Rock_Sandstone_Red"
    },
    {
      "x": -11,
      "y": 9,
      "z": 1,
      "name": "Soil_Clay_Orange"
    },
    {
      "x": -11,
      "y": 10,
      "z": 1,
      "name": "Rock_Sandstone_Red"
    },
    {
      "x": -11,
      "y": 11,
      "z": 1,
      "name": "Soil_Clay_Orange"
    },
    {
      "x": -11,
      "y": 12,
      "z": 1,
      "name": "Soil_Clay_Orange"
    },
    {
      "x": -11,
      "y": 13,
      "z": 1,
      "name": "Soil_Clay_Orange"
    },
    {
      "x": -11,
      "y": 4,
      "z": 2,
      "name": "Rock_Sandstone_Red"
    },
    {
      "x": -11,
      "y": 5,
      "z": 2,
      "name": "Rock_Sandstone_Red"
    },
    {
      "x": -11,
      "y": 6,
      "z": 2,
      "name": "Rock_Sandstone_Red"
    },
    {
      "x": -11,
      "y": 7,
      "z": 2,
      "name": "Rock_Sandstone_Red"
    },
    {
      "x": -11,
      "y": 8,
      "z": 2,
      "name": "Rock_Sandstone_Red"
    },
    {
      "x": -11,
      "y": 9,
      "z": 2,
      "name": "Soil_Clay_Orange"
    },
    {
      "x": -11,
      "y": 10,
      "z": 2,
      "name": "Soil_Clay_Orange"
    },
    {
      "x": -11,
      "y": 11,
      "z": 2,
      "name": "Soil_Clay_Orange"
    },
    {
      "x": -11,
      "y": 12,
      "z": 2,
      "name": "Soil_Clay_Orange"
    },
    {
      "x": -11,
      "y": 13,
      "z": 2,
      "name": "Soil_Clay_Orange"
    },
    {
      "x": -11,
      "y": 3,
      "z": 3,
      "name": "Rock_Sandstone_Red"
    },
    {
      "x": -11,
      "y": 4,
      "z": 3,
      "name": "Rock_Sandstone_Red"
    },
    {
      "x": -11,
      "y": 5,
      "z": 3,
      "name": "Rock_Sandstone_Red"
    },
    {
      "x": -11,
      "y": 6,
      "z": 3,
      "name": "Rock_Sandstone_Red"
    },
    {
      "x": -11,
      "y": 7,
      "z": 3,
      "name": "Rock_Sandstone_Red"
    },
    {
      "x": -11,
      "y": 8,
      "z": 3,
      "name": "Rock_Sandstone_Red"
    },
    {
      "x": -11,
      "y": 9,
      "z": 3,
      "name": "Soil_Clay_Orange"
    },
    {
      "x": -11,
      "y": 10,
      "z": 3,
      "name": "Soil_Clay_Orange"
    },
    {
      "x": -11,
      "y": 11,
      "z": 3,
      "name": "Soil_Clay_Orange"
    },
    {
      "x": -11,
      "y": 12,
      "z": 3,
      "name": "Soil_Clay_Orange"
    },
    {
      "x": -11,
      "y": 13,
      "z": 3,
      "name": "Soil_Clay_Smooth_Red"
    },
    {
      "x": -11,
      "y": 3,
      "z": 4,
      "name": "Rock_Sandstone_Red"
    },
    {
      "x": -11,
      "y": 4,
      "z": 4,
      "name": "Rock_Sandstone_Red"
    },
    {
      "x": -11,
      "y": 5,
      "z": 4,
      "name": "Rock_Sandstone_Red"
    },
    {
      "x": -11,
      "y": 6,
      "z": 4,
      "name": "Rock_Sandstone_Red"
    },
    {
      "x": -11,
      "y": 7,
      "z": 4,
      "name": "Rock_Sandstone_Red"
    },
    {
      "x": -11,
      "y": 8,
      "z": 4,
      "name": "Rock_Sandstone_Red"
    },
    {
      "x": -11,
      "y": 9,
      "z": 4,
      "name": "Soil_Clay_Orange"
    },
    {
      "x": -11,
      "y": 10,
      "z": 4,
      "name": "Soil_Clay_Orange"
    },
    {
      "x": -11,
      "y": 11,
      "z": 4,
      "name": "Soil_Clay_Orange"
    },
    {
      "x": -11,
      "y": 12,
      "z": 4,
      "name": "Soil_Clay_Orange"
    },
    {
      "x": -11,
      "y": 13,
      "z": 4,
      "name": "Soil_Clay_Smooth_Red"
    },
    {
      "x": -11,
      "y": 4,
      "z": 5,
      "name": "Rock_Sandstone_Red"
    },
    {
      "x": -11,
      "y": 5,
      "z": 5,
      "name": "Rock_Sandstone_Red"
    },
    {
      "x": -11,
      "y": 11,
      "z": 5,
      "name": "Soil_Clay_Orange"
    },
    {
      "x": -11,
      "y": 12,
      "z": 5,
      "name": "Soil_Clay_Orange"
    },
    {
      "x": -11,
      "y": 13,
      "z": 5,
      "name": "Soil_Clay_Orange"
    },
    {
      "x": -10,
      "y": 4,
      "z": -6,
      "name": "Rock_Sandstone_Red"
    },
    {
      "x": -10,
      "y": 5,
      "z": -6,
      "name": "Rock_Sandstone_Red"
    },
    {
      "x": -10,
      "y": 6,
      "z": -6,
      "name": "Rock_Sandstone_Red"
    },
    {
      "x": -10,
      "y": 7,
      "z": -6,
      "name": "Rock_Sandstone_Red"
    },
    {
      "x": -10,
      "y": 8,
      "z": -6,
      "name": "Soil_Clay_Orange"
    },
    {
      "x": -10,
      "y": 9,
      "z": -6,
      "name": "Rock_Sandstone"
    },
    {
      "x": -10,
      "y": 10,
      "z": -6,
      "name": "Rock_Sandstone_Red"
    },
    {
      "x": -10,
      "y": 11,
      "z": -6,
      "name": "Rock_Sandstone_Red"
    },
    {
      "x": -10,
      "y": 12,
      "z": -6,
      "name": "Rock_Sandstone_Red"
    },
    {
      "x": -10,
      "y": 13,
      "z": -6,
      "name": "Rock_Sandstone"
    },
    {
      "x": -10,
      "y": 20,
      "z": -6,
      "name": "Rock_Sandstone_Red"
    },
    {
      "x": -10,
      "y": 21,
      "z": -6,
      "name": "Rock_Sandstone_Red"
    },
    {
      "x": -10,
      "y": 4,
      "z": -5,
      "name": "Rock_Sandstone_Red"
    },
    {
      "x": -10,
      "y": 6,
      "z": -5,
      "name": "Rock_Sandstone_Red"
    },
    {
      "x": -10,
      "y": 7,
      "z": -5,
      "name": "Rock_Sandstone_Red"
    },
    {
      "x": -10,
      "y": 8,
      "z": -5,
      "name": "Rock_Sandstone_Red"
    },
    {
      "x": -10,
      "y": 9,
      "z": -5,
      "name": "Soil_Clay_Orange"
    },
    {
      "x": -10,
      "y": 10,
      "z": -5,
      "name": "Rock_Sandstone_Red"
    },
    {
      "x": -10,
      "y": 11,
      "z": -5,
      "name": "Rock_Sandstone_Red"
    },
    {
      "x": -10,
      "y": 12,
      "z": -5,
      "name": "Rock_Sandstone_Red"
    },
    {
      "x": -10,
      "y": 13,
      "z": -5,
      "name": "Rock_Sandstone"
    },
    {
      "x": -10,
      "y": 20,
      "z": -5,
      "name": "Rock_Sandstone_Red"
    },
    {
      "x": -10,
      "y": 21,
      "z": -5,
      "name": "Rock_Sandstone_Red"
    },
    {
      "x": -10,
      "y": 3,
      "z": -4,
      "name": "Rock_Sandstone_Red"
    },
    {
      "x": -10,
      "y": 4,
      "z": -4,
      "name": "Rock_Sandstone_Red"
    },
    {
      "x": -10,
      "y": 5,
      "z": -4,
      "name": "Rock_Sandstone_Red"
    },
    {
      "x": -10,
      "y": 6,
      "z": -4,
      "name": "Rock_Sandstone_Red"
    },
    {
      "x": -10,
      "y": 7,
      "z": -4,
      "name": "Rock_Sandstone_Red"
    },
    {
      "x": -10,
      "y": 8,
      "z": -4,
      "name": "Rock_Sandstone_Red"
    },
    {
      "x": -10,
      "y": 9,
      "z": -4,
      "name": "Soil_Clay_Orange"
    },
    {
      "x": -10,
      "y": 10,
      "z": -4,
      "name": "Rock_Sandstone_Red"
    },
    {
      "x": -10,
      "y": 11,
      "z": -4,
      "name": "Rock_Sandstone_Red"
    },
    {
      "x": -10,
      "y": 12,
      "z": -4,
      "name": "Rock_Sandstone_Red"
    },
    {
      "x": -10,
      "y": 13,
      "z": -4,
      "name": "Soil_Clay_Orange"
    },
    {
      "x": -10,
      "y": 20,
      "z": -4,
      "name": "Rock_Sandstone_Red"
    },
    {
      "x": -10,
      "y": 21,
      "z": -4,
      "name": "Rock_Sandstone_Red"
    },
    {
      "x": -10,
      "y": 4,
      "z": -3,
      "name": "Rock_Sandstone_Red"
    },
    {
      "x": -10,
      "y": 5,
      "z": -3,
      "name": "Rock_Sandstone_Red"
    },
    {
      "x": -10,
      "y": 7,
      "z": -3,
      "name": "Rock_Sandstone_Red"
    },
    {
      "x": -10,
      "y": 8,
      "z": -3,
      "name": "Rock_Sandstone_Red"
    },
    {
      "x": -10,
      "y": 9,
      "z": -3,
      "name": "Soil_Clay_Orange"
    },
    {
      "x": -10,
      "y": 10,
      "z": -3,
      "name": "Rock_Sandstone_Red"
    },
    {
      "x": -10,
      "y": 11,
      "z": -3,
      "name": "Rock_Sandstone_Red"
    },
    {
      "x": -10,
      "y": 12,
      "z": -3,
      "name": "Soil_Clay_Orange"
    },
    {
      "x": -10,
      "y": 13,
      "z": -3,
      "name": "Soil_Clay_Orange"
    },
    {
      "x": -10,
      "y": 14,
      "z": -3,
      "name": "Rock_Sandstone"
    },
    {
      "x": -10,
      "y": 3,
      "z": -2,
      "name": "Rock_Sandstone_Red"
    },
    {
      "x": -10,
      "y": 4,
      "z": -2,
      "name": "Rock_Sandstone_Red"
    },
    {
      "x": -10,
      "y": 5,
      "z": -2,
      "name": "Rock_Sandstone_Red"
    },
    {
      "x": -10,
      "y": 7,
      "z": -2,
      "name": "Rock_Sandstone_Red"
    },
    {
      "x": -10,
      "y": 8,
      "z": -2,
      "name": "Rock_Sandstone_Red"
    },
    {
      "x": -10,
      "y": 9,
      "z": -2,
      "name": "Soil_Clay_Orange"
    },
    {
      "x": -10,
      "y": 10,
      "z": -2,
      "name": "Rock_Sandstone_Red"
    },
    {
      "x": -10,
      "y": 11,
      "z": -2,
      "name": "Soil_Clay_Orange"
    },
    {
      "x": -10,
      "y": 12,
      "z": -2,
      "name": "Soil_Clay_Orange"
    },
    {
      "x": -10,
      "y": 13,
      "z": -2,
      "name": "Soil_Clay_Orange"
    },
    {
      "x": -10,
      "y": 14,
      "z": -2,
      "name": "Rock_Sandstone"
    },
    {
      "x": -10,
      "y": 3,
      "z": 0,
      "name": "Rock_Sandstone_Red"
    },
    {
      "x": -10,
      "y": 4,
      "z": 0,
      "name": "Rock_Sandstone_Red"
    },
    {
      "x": -10,
      "y": 5,
      "z": 0,
      "name": "Rock_Sandstone_Red"
    },
    {
      "x": -10,
      "y": 7,
      "z": 0,
      "name": "Rock_Sandstone_Red"
    },
    {
      "x": -10,
      "y": 8,
      "z": 0,
      "name": "Rock_Sandstone_Red"
    },
    {
      "x": -10,
      "y": 9,
      "z": 0,
      "name": "Rock_Sandstone_Red"
    },
    {
      "x": -10,
      "y": 10,
      "z": 0,
      "name": "Rock_Sandstone_Red"
    },
    {
      "x": -10,
      "y": 11,
      "z": 0,
      "name": "Rock_Sandstone_Red"
    },
    {
      "x": -10,
      "y": 12,
      "z": 0,
      "name": "Soil_Clay_Orange"
    },
    {
      "x": -10,
      "y": 13,
      "z": 0,
      "name": "Soil_Clay_Orange"
    },
    {
      "x": -10,
      "y": 3,
      "z": 1,
      "name": "Rock_Sandstone_Red"
    },
    {
      "x": -10,
      "y": 4,
      "z": 1,
      "name": "Rock_Sandstone_Red"
    },
    {
      "x": -10,
      "y": 5,
      "z": 1,
      "name": "Rock_Sandstone_Red"
    },
    {
      "x": -10,
      "y": 6,
      "z": 1,
      "name": "Rock_Sandstone_Red"
    },
    {
      "x": -10,
      "y": 7,
      "z": 1,
      "name": "Rock_Sandstone_Red"
    },
    {
      "x": -10,
      "y": 8,
      "z": 1,
      "name": "Rock_Sandstone_Red"
    },
    {
      "x": -10,
      "y": 9,
      "z": 1,
      "name": "Rock_Sandstone_Red"
    },
    {
      "x": -10,
      "y": 10,
      "z": 1,
      "name": "Rock_Sandstone_Red"
    },
    {
      "x": -10,
      "y": 11,
      "z": 1,
      "name": "Rock_Sandstone_Red"
    },
    {
      "x": -10,
      "y": 12,
      "z": 1,
      "name": "Soil_Clay_Orange"
    },
    {
      "x": -10,
      "y": 13,
      "z": 1,
      "name": "Soil_Clay_Orange"
    },
    {
      "x": -10,
      "y": 14,
      "z": 1,
      "name": "Soil_Clay_Smooth_Red"
    },
    {
      "x": -10,
      "y": 3,
      "z": 2,
      "name": "Rock_Sandstone_Red"
    },
    {
      "x": -10,
      "y": 4,
      "z": 2,
      "name": "Rock_Sandstone_Red"
    },
    {
      "x": -10,
      "y": 5,
      "z": 2,
      "name": "Rock_Sandstone_Red"
    },
    {
      "x": -10,
      "y": 6,
      "z": 2,
      "name": "Rock_Sandstone_Red"
    },
    {
      "x": -10,
      "y": 7,
      "z": 2,
      "name": "Rock_Sandstone_Red"
    },
    {
      "x": -10,
      "y": 8,
      "z": 2,
      "name": "Rock_Sandstone_Red"
    },
    {
      "x": -10,
      "y": 9,
      "z": 2,
      "name": "Soil_Clay_Orange"
    },
    {
      "x": -10,
      "y": 10,
      "z": 2,
      "name": "Rock_Sandstone_Red"
    },
    {
      "x": -10,
      "y": 11,
      "z": 2,
      "name": "Soil_Clay_Orange"
    },
    {
      "x": -10,
      "y": 12,
      "z": 2,
      "name": "Soil_Clay_Orange"
    },
    {
      "x": -10,
      "y": 13,
      "z": 2,
      "name": "Soil_Clay_Orange"
    },
    {
      "x": -10,
      "y": 14,
      "z": 2,
      "name": "Soil_Clay_Smooth_Red"
    },
    {
      "x": -10,
      "y": 4,
      "z": 3,
      "name": "Rock_Sandstone_Red"
    },
    {
      "x": -10,
      "y": 5,
      "z": 3,
      "name": "Rock_Sandstone_Red"
    },
    {
      "x": -10,
      "y": 6,
      "z": 3,
      "name": "Rock_Sandstone_Red"
    },
    {
      "x": -10,
      "y": 7,
      "z": 3,
      "name": "Rock_Sandstone_Red"
    },
    {
      "x": -10,
      "y": 8,
      "z": 3,
      "name": "Soil_Clay_Orange"
    },
    {
      "x": -10,
      "y": 9,
      "z": 3,
      "name": "Soil_Clay_Orange"
    },
    {
      "x": -10,
      "y": 10,
      "z": 3,
      "name": "Soil_Clay_Orange"
    },
    {
      "x": -10,
      "y": 11,
      "z": 3,
      "name": "Soil_Clay_Orange"
    },
    {
      "x": -10,
      "y": 12,
      "z": 3,
      "name": "Soil_Clay_Orange"
    },
    {
      "x": -10,
      "y": 13,
      "z": 3,
      "name": "Soil_Clay_Orange"
    },
    {
      "x": -10,
      "y": 14,
      "z": 3,
      "name": "Soil_Clay_Smooth_Red"
    },
    {
      "x": -10,
      "y": 3,
      "z": 4,
      "name": "Rock_Sandstone_Red"
    },
    {
      "x": -10,
      "y": 4,
      "z": 4,
      "name": "Rock_Sandstone_Red"
    },
    {
      "x": -10,
      "y": 5,
      "z": 4,
      "name": "Rock_Sandstone_Red"
    },
    {
      "x": -10,
      "y": 6,
      "z": 4,
      "name": "Rock_Sandstone_Red"
    },
    {
      "x": -10,
      "y": 7,
      "z": 4,
      "name": "Rock_Sandstone_Red"
    },
    {
      "x": -10,
      "y": 8,
      "z": 4,
      "name": "Soil_Clay_Orange"
    },
    {
      "x": -10,
      "y": 9,
      "z": 4,
      "name": "Soil_Clay_Orange"
    },
    {
      "x": -10,
      "y": 10,
      "z": 4,
      "name": "Soil_Clay_Orange"
    },
    {
      "x": -10,
      "y": 11,
      "z": 4,
      "name": "Soil_Clay_Orange"
    },
    {
      "x": -10,
      "y": 12,
      "z": 4,
      "name": "Soil_Clay_Orange"
    },
    {
      "x": -10,
      "y": 13,
      "z": 4,
      "name": "Soil_Clay_Smooth_Red"
    },
    {
      "x": -10,
      "y": 3,
      "z": 5,
      "name": "Rock_Sandstone_Red"
    },
    {
      "x": -10,
      "y": 4,
      "z": 5,
      "name": "Rock_Sandstone_Red"
    },
    {
      "x": -10,
      "y": 5,
      "z": 5,
      "name": "Rock_Sandstone_Red"
    },
    {
      "x": -10,
      "y": 6,
      "z": 5,
      "name": "Rock_Sandstone_Red"
    },
    {
      "x": -10,
      "y": 7,
      "z": 5,
      "name": "Soil_Clay_Orange"
    },
    {
      "x": -10,
      "y": 8,
      "z": 5,
      "name": "Rock_Sandstone_Red"
    },
    {
      "x": -10,
      "y": 9,
      "z": 5,
      "name": "Soil_Clay_Orange"
    },
    {
      "x": -10,
      "y": 10,
      "z": 5,
      "name": "Soil_Clay_Orange"
    },
    {
      "x": -10,
      "y": 11,
      "z": 5,
      "name": "Soil_Clay_Orange"
    },
    {
      "x": -10,
      "y": 12,
      "z": 5,
      "name": "Soil_Clay_Orange"
    },
    {
      "x": -10,
      "y": 13,
      "z": 5,
      "name": "Soil_Clay_Smooth_Red"
    },
    {
      "x": -10,
      "y": 4,
      "z": 6,
      "name": "Rock_Sandstone_Red"
    },
    {
      "x": -10,
      "y": 5,
      "z": 6,
      "name": "Rock_Sandstone_Red"
    },
    {
      "x": -10,
      "y": 6,
      "z": 6,
      "name": "Soil_Clay_Orange"
    },
    {
      "x": -10,
      "y": 7,
      "z": 6,
      "name": "Rock_Sandstone_Red"
    },
    {
      "x": -10,
      "y": 8,
      "z": 6,
      "name": "Rock_Sandstone_Red"
    },
    {
      "x": -10,
      "y": 9,
      "z": 6,
      "name": "Rock_Sandstone_Red"
    },
    {
      "x": -10,
      "y": 10,
      "z": 6,
      "name": "Soil_Clay_Orange"
    },
    {
      "x": -10,
      "y": 11,
      "z": 6,
      "name": "Soil_Clay_Orange"
    },
    {
      "x": -10,
      "y": 12,
      "z": 6,
      "name": "Soil_Clay_Orange"
    },
    {
      "x": -10,
      "y": 13,
      "z": 6,
      "name": "Soil_Clay_Orange"
    },
    {
      "x": -9,
      "y": 3,
      "z": -7,
      "name": "Rock_Sandstone_Red"
    },
    {
      "x": -9,
      "y": 4,
      "z": -7,
      "name": "Rock_Sandstone_Red"
    },
    {
      "x": -9,
      "y": 5,
      "z": -7,
      "name": "Rock_Sandstone_Red"
    },
    {
      "x": -9,
      "y": 6,
      "z": -7,
      "name": "Rock_Sandstone_Red"
    },
    {
      "x": -9,
      "y": 7,
      "z": -7,
      "name": "Rock_Sandstone_Red"
    },
    {
      "x": -9,
      "y": 8,
      "z": -7,
      "name": "Rock_Sandstone"
    },
    {
      "x": -9,
      "y": 10,
      "z": -7,
      "name": "Rock_Sandstone_Red"
    },
    {
      "x": -9,
      "y": 11,
      "z": -7,
      "name": "Rock_Sandstone_Red"
    },
    {
      "x": -9,
      "y": 12,
      "z": -7,
      "name": "Rock_Sandstone_Red"
    },
    {
      "x": -9,
      "y": 13,
      "z": -7,
      "name": "Rock_Sandstone"
    },
    {
      "x": -9,
      "y": 21,
      "z": -7,
      "name": "Soil_Clay_Orange"
    },
    {
      "x": -9,
      "y": 3,
      "z": -6,
      "name": "Rock_Sandstone_Red"
    },
    {
      "x": -9,
      "y": 4,
      "z": -6,
      "name": "Rock_Sandstone_Red"
    },
    {
      "x": -9,
      "y": 5,
      "z": -6,
      "name": "Rock_Sandstone_Red"
    },
    {
      "x": -9,
      "y": 6,
      "z": -6,
      "name": "Rock_Sandstone_Red"
    },
    {
      "x": -9,
      "y": 7,
      "z": -6,
      "name": "Rock_Sandstone_Red"
    },
    {
      "x": -9,
      "y": 8,
      "z": -6,
      "name": "Soil_Clay_Orange"
    },
    {
      "x": -9,
      "y": 9,
      "z": -6,
      "name": "Soil_Clay_Orange"
    },
    {
      "x": -9,
      "y": 10,
      "z": -6,
      "name": "Rock_Sandstone_Red"
    },
    {
      "x": -9,
      "y": 11,
      "z": -6,
      "name": "Rock_Sandstone_Red"
    },
    {
      "x": -9,
      "y": 12,
      "z": -6,
      "name": "Rock_Sandstone_Red"
    },
    {
      "x": -9,
      "y": 13,
      "z": -6,
      "name": "Soil_Clay_Orange"
    },
    {
      "x": -9,
      "y": 14,
      "z": -6,
      "name": "Soil_Clay_Smooth_Red"
    },
    {
      "x": -9,
      "y": 20,
      "z": -6,
      "name": "Rock_Sandstone_Red"
    },
    {
      "x": -9,
      "y": 21,
      "z": -6,
      "name": "Rock_Sandstone_Red"
    },
    {
      "x": -9,
      "y": 3,
      "z": -5,
      "name": "Rock_Sandstone_Red"
    },
    {
      "x": -9,
      "y": 4,
      "z": -5,
      "name": "Rock_Sandstone_Red"
    },
    {
      "x": -9,
      "y": 5,
      "z": -5,
      "name": "Rock_Sandstone_Red"
    },
    {
      "x": -9,
      "y": 6,
      "z": -5,
      "name": "Rock_Sandstone_Red"
    },
    {
      "x": -9,
      "y": 7,
      "z": -5,
      "name": "Rock_Sandstone_Red"
    },
    {
      "x": -9,
      "y": 8,
      "z": -5,
      "name": "Rock_Sandstone_Red"
    },
    {
      "x": -9,
      "y": 9,
      "z": -5,
      "name": "Soil_Clay_Orange"
    },
    {
      "x": -9,
      "y": 10,
      "z": -5,
      "name": "Rock_Sandstone_Red"
    },
    {
      "x": -9,
      "y": 11,
      "z": -5,
      "name": "Rock_Sandstone_Red"
    },
    {
      "x": -9,
      "y": 12,
      "z": -5,
      "name": "Rock_Sandstone_Red"
    },
    {
      "x": -9,
      "y": 13,
      "z": -5,
      "name": "Soil_Clay_Orange"
    },
    {
      "x": -9,
      "y": 14,
      "z": -5,
      "name": "Soil_Clay_Smooth_Red"
    },
    {
      "x": -9,
      "y": 19,
      "z": -5,
      "name": "Rock_Sandstone_Red"
    },
    {
      "x": -9,
      "y": 20,
      "z": -5,
      "name": "Rock_Sandstone_Red"
    },
    {
      "x": -9,
      "y": 21,
      "z": -5,
      "name": "Soil_Clay_Smooth_Red"
    },
    {
      "x": -9,
      "y": 3,
      "z": -4,
      "name": "Rock_Sandstone_Red"
    },
    {
      "x": -9,
      "y": 4,
      "z": -4,
      "name": "Rock_Sandstone_Red"
    },
    {
      "x": -9,
      "y": 5,
      "z": -4,
      "name": "Rock_Sandstone_Red"
    },
    {
      "x": -9,
      "y": 6,
      "z": -4,
      "name": "Rock_Sandstone_Red"
    },
    {
      "x": -9,
      "y": 7,
      "z": -4,
      "name": "Rock_Sandstone_Red"
    },
    {
      "x": -9,
      "y": 8,
      "z": -4,
      "name": "Rock_Sandstone_Red"
    },
    {
      "x": -9,
      "y": 9,
      "z": -4,
      "name": "Soil_Clay_Orange"
    },
    {
      "x": -9,
      "y": 10,
      "z": -4,
      "name": "Rock_Sandstone_Red"
    },
    {
      "x": -9,
      "y": 11,
      "z": -4,
      "name": "Rock_Sandstone_Red"
    },
    {
      "x": -9,
      "y": 12,
      "z": -4,
      "name": "Soil_Clay_Orange"
    },
    {
      "x": -9,
      "y": 13,
      "z": -4,
      "name": "Soil_Clay_Orange"
    },
    {
      "x": -9,
      "y": 14,
      "z": -4,
      "name": "Soil_Clay_Smooth_Red"
    },
    {
      "x": -9,
      "y": 19,
      "z": -4,
      "name": "Rock_Sandstone_Red"
    },
    {
      "x": -9,
      "y": 20,
      "z": -4,
      "name": "Rock_Sandstone_Red"
    },
    {
      "x": -9,
      "y": 21,
      "z": -4,
      "name": "Soil_Clay_Smooth_Red"
    },
    {
      "x": -9,
      "y": 3,
      "z": -3,
      "name": "Rock_Sandstone_Red"
    },
    {
      "x": -9,
      "y": 4,
      "z": -3,
      "name": "Rock_Sandstone_Red"
    },
    {
      "x": -9,
      "y": 5,
      "z": -3,
      "name": "Rock_Sandstone_Red"
    },
    {
      "x": -9,
      "y": 6,
      "z": -3,
      "name": "Rock_Sandstone_Red"
    },
    {
      "x": -9,
      "y": 7,
      "z": -3,
      "name": "Rock_Sandstone_Red"
    },
    {
      "x": -9,
      "y": 8,
      "z": -3,
      "name": "Rock_Sandstone_Red"
    },
    {
      "x": -9,
      "y": 9,
      "z": -3,
      "name": "Rock_Sandstone_Red"
    },
    {
      "x": -9,
      "y": 10,
      "z": -3,
      "name": "Rock_Sandstone_Red"
    },
    {
      "x": -9,
      "y": 11,
      "z": -3,
      "name": "Rock_Sandstone_Red"
    },
    {
      "x": -9,
      "y": 12,
      "z": -3,
      "name": "Rock_Sandstone_Red"
    },
    {
      "x": -9,
      "y": 13,
      "z": -3,
      "name": "Soil_Clay_Orange"
    },
    {
      "x": -9,
      "y": 14,
      "z": -3,
      "name": "Soil_Clay_Smooth_Red"
    },
    {
      "x": -9,
      "y": 19,
      "z": -3,
      "name": "Rock_Sandstone_Red"
    },
    {
      "x": -9,
      "y": 20,
      "z": -3,
      "name": "Rock_Sandstone_Red"
    },
    {
      "x": -9,
      "y": 21,
      "z": -3,
      "name": "Soil_Clay_Smooth_Red"
    },
    {
      "x": -9,
      "y": 3,
      "z": -2,
      "name": "Rock_Sandstone_Red"
    },
    {
      "x": -9,
      "y": 4,
      "z": -2,
      "name": "Rock_Sandstone_Red"
    },
    {
      "x": -9,
      "y": 5,
      "z": -2,
      "name": "Rock_Sandstone_Red"
    },
    {
      "x": -9,
      "y": 6,
      "z": -2,
      "name": "Rock_Sandstone_Red"
    },
    {
      "x": -9,
      "y": 7,
      "z": -2,
      "name": "Rock_Sandstone_Red"
    },
    {
      "x": -9,
      "y": 8,
      "z": -2,
      "name": "Rock_Sandstone_Red"
    },
    {
      "x": -9,
      "y": 9,
      "z": -2,
      "name": "Rock_Sandstone_Red"
    },
    {
      "x": -9,
      "y": 10,
      "z": -2,
      "name": "Rock_Sandstone_Red"
    },
    {
      "x": -9,
      "y": 11,
      "z": -2,
      "name": "Rock_Sandstone_Red"
    },
    {
      "x": -9,
      "y": 12,
      "z": -2,
      "name": "Rock_Sandstone_Red"
    },
    {
      "x": -9,
      "y": 13,
      "z": -2,
      "name": "Soil_Clay_Orange"
    },
    {
      "x": -9,
      "y": 14,
      "z": -2,
      "name": "Soil_Clay_Smooth_Red"
    },
    {
      "x": -9,
      "y": 20,
      "z": -2,
      "name": "Rock_Sandstone_Red"
    },
    {
      "x": -9,
      "y": 21,
      "z": -2,
      "name": "Soil_Clay_Smooth_Red"
    },
    {
      "x": -9,
      "y": 2,
      "z": -1,
      "name": "Rock_Sandstone_Red"
    },
    {
      "x": -9,
      "y": 3,
      "z": -1,
      "name": "Rock_Sandstone_Red"
    },
    {
      "x": -9,
      "y": 4,
      "z": -1,
      "name": "Rock_Sandstone_Red"
    },
    {
      "x": -9,
      "y": 5,
      "z": -1,
      "name": "Rock_Sandstone_Red"
    },
    {
      "x": -9,
      "y": 6,
      "z": -1,
      "name": "Rock_Sandstone_Red"
    },
    {
      "x": -9,
      "y": 7,
      "z": -1,
      "name": "Rock_Sandstone_Red"
    },
    {
      "x": -9,
      "y": 8,
      "z": -1,
      "name": "Rock_Sandstone_Red"
    },
    {
      "x": -9,
      "y": 9,
      "z": -1,
      "name": "Rock_Sandstone_Red"
    },
    {
      "x": -9,
      "y": 10,
      "z": -1,
      "name": "Rock_Sandstone_Red"
    },
    {
      "x": -9,
      "y": 11,
      "z": -1,
      "name": "Rock_Sandstone_Red"
    },
    {
      "x": -9,
      "y": 12,
      "z": -1,
      "name": "Rock_Sandstone_Red"
    },
    {
      "x": -9,
      "y": 13,
      "z": -1,
      "name": "Soil_Clay_Orange"
    },
    {
      "x": -9,
      "y": 14,
      "z": -1,
      "name": "Soil_Clay_Smooth_Red"
    },
    {
      "x": -9,
      "y": 2,
      "z": 0,
      "name": "Rock_Sandstone_Red"
    },
    {
      "x": -9,
      "y": 3,
      "z": 0,
      "name": "Rock_Sandstone_Red"
    },
    {
      "x": -9,
      "y": 4,
      "z": 0,
      "name": "Rock_Sandstone_Red"
    },
    {
      "x": -9,
      "y": 5,
      "z": 0,
      "name": "Rock_Sandstone_Red"
    },
    {
      "x": -9,
      "y": 6,
      "z": 0,
      "name": "Rock_Sandstone_Red"
    },
    {
      "x": -9,
      "y": 7,
      "z": 0,
      "name": "Rock_Sandstone_Red"
    },
    {
      "x": -9,
      "y": 8,
      "z": 0,
      "name": "Rock_Sandstone_Red"
    },
    {
      "x": -9,
      "y": 9,
      "z": 0,
      "name": "Rock_Sandstone_Red"
    },
    {
      "x": -9,
      "y": 10,
      "z": 0,
      "name": "Rock_Sandstone_Red"
    },
    {
      "x": -9,
      "y": 11,
      "z": 0,
      "name": "Rock_Sandstone_Red"
    },
    {
      "x": -9,
      "y": 12,
      "z": 0,
      "name": "Rock_Sandstone_Red"
    },
    {
      "x": -9,
      "y": 13,
      "z": 0,
      "name": "Soil_Clay_Orange"
    },
    {
      "x": -9,
      "y": 14,
      "z": 0,
      "name": "Soil_Clay_Smooth_Red"
    },
    {
      "x": -9,
      "y": 2,
      "z": 1,
      "name": "Rock_Sandstone_Red"
    },
    {
      "x": -9,
      "y": 3,
      "z": 1,
      "name": "Rock_Sandstone_Red"
    },
    {
      "x": -9,
      "y": 4,
      "z": 1,
      "name": "Rock_Sandstone_Red"
    },
    {
      "x": -9,
      "y": 5,
      "z": 1,
      "name": "Rock_Sandstone_Red"
    },
    {
      "x": -9,
      "y": 6,
      "z": 1,
      "name": "Rock_Sandstone_Red"
    },
    {
      "x": -9,
      "y": 7,
      "z": 1,
      "name": "Rock_Sandstone_Red"
    },
    {
      "x": -9,
      "y": 8,
      "z": 1,
      "name": "Rock_Sandstone_Red"
    },
    {
      "x": -9,
      "y": 9,
      "z": 1,
      "name": "Rock_Sandstone_Red"
    },
    {
      "x": -9,
      "y": 10,
      "z": 1,
      "name": "Rock_Sandstone_Red"
    },
    {
      "x": -9,
      "y": 11,
      "z": 1,
      "name": "Rock_Sandstone_Red"
    },
    {
      "x": -9,
      "y": 12,
      "z": 1,
      "name": "Rock_Sandstone_Red"
    },
    {
      "x": -9,
      "y": 13,
      "z": 1,
      "name": "Soil_Clay_Orange"
    },
    {
      "x": -9,
      "y": 14,
      "z": 1,
      "name": "Soil_Clay_Smooth_Red"
    },
    {
      "x": -9,
      "y": 3,
      "z": 2,
      "name": "Rock_Sandstone_Red"
    },
    {
      "x": -9,
      "y": 4,
      "z": 2,
      "name": "Rock_Sandstone_Red"
    },
    {
      "x": -9,
      "y": 5,
      "z": 2,
      "name": "Rock_Sandstone_Red"
    },
    {
      "x": -9,
      "y": 6,
      "z": 2,
      "name": "Rock_Sandstone_Red"
    },
    {
      "x": -9,
      "y": 7,
      "z": 2,
      "name": "Rock_Sandstone_Red"
    },
    {
      "x": -9,
      "y": 8,
      "z": 2,
      "name": "Soil_Clay_Orange"
    },
    {
      "x": -9,
      "y": 9,
      "z": 2,
      "name": "Soil_Clay_Orange"
    },
    {
      "x": -9,
      "y": 10,
      "z": 2,
      "name": "Soil_Clay_Orange"
    },
    {
      "x": -9,
      "y": 11,
      "z": 2,
      "name": "Soil_Clay_Orange"
    },
    {
      "x": -9,
      "y": 12,
      "z": 2,
      "name": "Rock_Sandstone_Red"
    },
    {
      "x": -9,
      "y": 13,
      "z": 2,
      "name": "Soil_Clay_Orange"
    },
    {
      "x": -9,
      "y": 14,
      "z": 2,
      "name": "Soil_Clay_Smooth_Red"
    },
    {
      "x": -9,
      "y": 3,
      "z": 3,
      "name": "Rock_Sandstone_Red"
    },
    {
      "x": -9,
      "y": 4,
      "z": 3,
      "name": "Rock_Sandstone_Red"
    },
    {
      "x": -9,
      "y": 5,
      "z": 3,
      "name": "Rock_Sandstone_Red"
    },
    {
      "x": -9,
      "y": 6,
      "z": 3,
      "name": "Rock_Sandstone_Red"
    },
    {
      "x": -9,
      "y": 7,
      "z": 3,
      "name": "Soil_Clay_Orange"
    },
    {
      "x": -9,
      "y": 8,
      "z": 3,
      "name": "Soil_Clay_Orange"
    },
    {
      "x": -9,
      "y": 9,
      "z": 3,
      "name": "Soil_Clay_Orange"
    },
    {
      "x": -9,
      "y": 10,
      "z": 3,
      "name": "Soil_Clay_Orange"
    },
    {
      "x": -9,
      "y": 11,
      "z": 3,
      "name": "Soil_Clay_Orange"
    },
    {
      "x": -9,
      "y": 12,
      "z": 3,
      "name": "Rock_Sandstone_Red"
    },
    {
      "x": -9,
      "y": 13,
      "z": 3,
      "name": "Soil_Clay_Orange"
    },
    {
      "x": -9,
      "y": 14,
      "z": 3,
      "name": "Soil_Clay_Smooth_Red"
    },
    {
      "x": -9,
      "y": 3,
      "z": 4,
      "name": "Rock_Sandstone_Red"
    },
    {
      "x": -9,
      "y": 4,
      "z": 4,
      "name": "Rock_Sandstone_Red"
    },
    {
      "x": -9,
      "y": 5,
      "z": 4,
      "name": "Rock_Sandstone_Red"
    },
    {
      "x": -9,
      "y": 6,
      "z": 4,
      "name": "Rock_Sandstone_Red"
    },
    {
      "x": -9,
      "y": 7,
      "z": 4,
      "name": "Soil_Clay_Orange"
    },
    {
      "x": -9,
      "y": 8,
      "z": 4,
      "name": "Soil_Clay_Orange"
    },
    {
      "x": -9,
      "y": 9,
      "z": 4,
      "name": "Soil_Clay_Orange"
    },
    {
      "x": -9,
      "y": 10,
      "z": 4,
      "name": "Soil_Clay_Orange"
    },
    {
      "x": -9,
      "y": 11,
      "z": 4,
      "name": "Soil_Clay_Orange"
    },
    {
      "x": -9,
      "y": 12,
      "z": 4,
      "name": "Soil_Clay_Orange"
    },
    {
      "x": -9,
      "y": 13,
      "z": 4,
      "name": "Soil_Clay_Orange"
    },
    {
      "x": -9,
      "y": 14,
      "z": 4,
      "name": "Soil_Clay_Smooth_Red"
    },
    {
      "x": -9,
      "y": 3,
      "z": 5,
      "name": "Rock_Sandstone_Red"
    },
    {
      "x": -9,
      "y": 4,
      "z": 5,
      "name": "Rock_Sandstone_Red"
    },
    {
      "x": -9,
      "y": 5,
      "z": 5,
      "name": "Rock_Sandstone_Red"
    },
    {
      "x": -9,
      "y": 6,
      "z": 5,
      "name": "Rock_Sandstone_Red"
    },
    {
      "x": -9,
      "y": 7,
      "z": 5,
      "name": "Soil_Clay_Orange"
    },
    {
      "x": -9,
      "y": 8,
      "z": 5,
      "name": "Soil_Clay_Orange"
    },
    {
      "x": -9,
      "y": 9,
      "z": 5,
      "name": "Soil_Clay_Orange"
    },
    {
      "x": -9,
      "y": 10,
      "z": 5,
      "name": "Soil_Clay_Orange"
    },
    {
      "x": -9,
      "y": 11,
      "z": 5,
      "name": "Soil_Clay_Orange"
    },
    {
      "x": -9,
      "y": 12,
      "z": 5,
      "name": "Soil_Clay_Orange"
    },
    {
      "x": -9,
      "y": 13,
      "z": 5,
      "name": "Soil_Clay_Orange"
    },
    {
      "x": -9,
      "y": 14,
      "z": 5,
      "name": "Soil_Clay_Smooth_Red"
    },
    {
      "x": -9,
      "y": 4,
      "z": 6,
      "name": "Rock_Sandstone_Red"
    },
    {
      "x": -9,
      "y": 5,
      "z": 6,
      "name": "Rock_Sandstone_Red"
    },
    {
      "x": -9,
      "y": 6,
      "z": 6,
      "name": "Rock_Sandstone_Red"
    },
    {
      "x": -9,
      "y": 7,
      "z": 6,
      "name": "Soil_Clay_Orange"
    },
    {
      "x": -9,
      "y": 8,
      "z": 6,
      "name": "Rock_Sandstone_Red"
    },
    {
      "x": -9,
      "y": 9,
      "z": 6,
      "name": "Soil_Clay_Orange"
    },
    {
      "x": -9,
      "y": 10,
      "z": 6,
      "name": "Soil_Clay_Orange"
    },
    {
      "x": -9,
      "y": 11,
      "z": 6,
      "name": "Soil_Clay_Orange"
    },
    {
      "x": -9,
      "y": 12,
      "z": 6,
      "name": "Soil_Clay_Orange"
    },
    {
      "x": -9,
      "y": 13,
      "z": 6,
      "name": "Soil_Clay_Orange"
    },
    {
      "x": -8,
      "y": 4,
      "z": -8,
      "name": "Rock_Sandstone_Red"
    },
    {
      "x": -8,
      "y": 5,
      "z": -8,
      "name": "Rock_Sandstone_Red"
    },
    {
      "x": -8,
      "y": 6,
      "z": -8,
      "name": "Rock_Sandstone_Red"
    },
    {
      "x": -8,
      "y": 7,
      "z": -8,
      "name": "Rock_Sandstone_Red"
    },
    {
      "x": -8,
      "y": 8,
      "z": -8,
      "name": "Rock_Sandstone"
    },
    {
      "x": -8,
      "y": 9,
      "z": -8,
      "name": "Soil_Clay_Orange"
    },
    {
      "x": -8,
      "y": 10,
      "z": -8,
      "name": "Rock_Sandstone_Red"
    },
    {
      "x": -8,
      "y": 11,
      "z": -8,
      "name": "Rock_Sandstone_Red"
    },
    {
      "x": -8,
      "y": 14,
      "z": -8,
      "name": "Soil_Clay_Orange"
    },
    {
      "x": -8,
      "y": 3,
      "z": -7,
      "name": "Rock_Sandstone_Red"
    },
    {
      "x": -8,
      "y": 4,
      "z": -7,
      "name": "Rock_Sandstone_Red"
    },
    {
      "x": -8,
      "y": 5,
      "z": -7,
      "name": "Rock_Sandstone_Red"
    },
    {
      "x": -8,
      "y": 6,
      "z": -7,
      "name": "Rock_Sandstone_Red"
    },
    {
      "x": -8,
      "y": 7,
      "z": -7,
      "name": "Rock_Sandstone_Red"
    },
    {
      "x": -8,
      "y": 8,
      "z": -7,
      "name": "Rock_Sandstone"
    },
    {
      "x": -8,
      "y": 9,
      "z": -7,
      "name": "Soil_Clay_Orange"
    },
    {
      "x": -8,
      "y": 10,
      "z": -7,
      "name": "Rock_Sandstone_Red"
    },
    {
      "x": -8,
      "y": 11,
      "z": -7,
      "name": "Rock_Sandstone_Red"
    },
    {
      "x": -8,
      "y": 12,
      "z": -7,
      "name": "Rock_Sandstone_Red"
    },
    {
      "x": -8,
      "y": 13,
      "z": -7,
      "name": "Soil_Clay_Orange"
    },
    {
      "x": -8,
      "y": 14,
      "z": -7,
      "name": "Soil_Clay_Smooth_Red"
    },
    {
      "x": -8,
      "y": 20,
      "z": -7,
      "name": "Rock_Sandstone_Red"
    },
    {
      "x": -8,
      "y": 21,
      "z": -7,
      "name": "Rock_Sandstone_Red"
    },
    {
      "x": -8,
      "y": 3,
      "z": -6,
      "name": "Rock_Sandstone_Red"
    },
    {
      "x": -8,
      "y": 4,
      "z": -6,
      "name": "Rock_Sandstone_Red"
    },
    {
      "x": -8,
      "y": 5,
      "z": -6,
      "name": "Rock_Sandstone_Red"
    },
    {
      "x": -8,
      "y": 6,
      "z": -6,
      "name": "Rock_Sandstone_Red"
    },
    {
      "x": -8,
      "y": 7,
      "z": -6,
      "name": "Rock_Sandstone_Red"
    },
    {
      "x": -8,
      "y": 8,
      "z": -6,
      "name": "Soil_Clay_Orange"
    },
    {
      "x": -8,
      "y": 9,
      "z": -6,
      "name": "Rock_Sandstone_Red"
    },
    {
      "x": -8,
      "y": 10,
      "z": -6,
      "name": "Rock_Sandstone_Red"
    },
    {
      "x": -8,
      "y": 11,
      "z": -6,
      "name": "Rock_Sandstone_Red"
    },
    {
      "x": -8,
      "y": 12,
      "z": -6,
      "name": "Rock_Sandstone_Red"
    },
    {
      "x": -8,
      "y": 13,
      "z": -6,
      "name": "Soil_Clay_Orange"
    },
    {
      "x": -8,
      "y": 14,
      "z": -6,
      "name": "Soil_Clay_Smooth_Red"
    },
    {
      "x": -8,
      "y": 20,
      "z": -6,
      "name": "Rock_Sandstone_Red"
    },
    {
      "x": -8,
      "y": 21,
      "z": -6,
      "name": "Soil_Clay_Smooth_Red"
    },
    {
      "x": -8,
      "y": 3,
      "z": -5,
      "name": "Rock_Sandstone_Red"
    },
    {
      "x": -8,
      "y": 4,
      "z": -5,
      "name": "Rock_Sandstone_Red"
    },
    {
      "x": -8,
      "y": 5,
      "z": -5,
      "name": "Rock_Sandstone_Red"
    },
    {
      "x": -8,
      "y": 6,
      "z": -5,
      "name": "Rock_Sandstone_Red"
    },
    {
      "x": -8,
      "y": 7,
      "z": -5,
      "name": "Rock_Sandstone_Red"
    },
    {
      "x": -8,
      "y": 8,
      "z": -5,
      "name": "Rock_Sandstone_Red"
    },
    {
      "x": -8,
      "y": 9,
      "z": -5,
      "name": "Rock_Sandstone_Red"
    },
    {
      "x": -8,
      "y": 10,
      "z": -5,
      "name": "Rock_Sandstone_Red"
    },
    {
      "x": -8,
      "y": 11,
      "z": -5,
      "name": "Rock_Sandstone_Red"
    },
    {
      "x": -8,
      "y": 12,
      "z": -5,
      "name": "Rock_Sandstone_Red"
    },
    {
      "x": -8,
      "y": 13,
      "z": -5,
      "name": "Soil_Clay_Orange"
    },
    {
      "x": -8,
      "y": 14,
      "z": -5,
      "name": "Soil_Clay_Smooth_Red"
    },
    {
      "x": -8,
      "y": 20,
      "z": -5,
      "name": "Rock_Sandstone_Red"
    },
    {
      "x": -8,
      "y": 21,
      "z": -5,
      "name": "Soil_Clay_Smooth_Red"
    },
    {
      "x": -8,
      "y": 3,
      "z": -4,
      "name": "Rock_Sandstone_Red"
    },
    {
      "x": -8,
      "y": 4,
      "z": -4,
      "name": "Rock_Sandstone_Red"
    },
    {
      "x": -8,
      "y": 5,
      "z": -4,
      "name": "Rock_Sandstone_Red"
    },
    {
      "x": -8,
      "y": 6,
      "z": -4,
      "name": "Rock_Sandstone_Red"
    },
    {
      "x": -8,
      "y": 7,
      "z": -4,
      "name": "Rock_Sandstone_Red"
    },
    {
      "x": -8,
      "y": 8,
      "z": -4,
      "name": "Rock_Sandstone_Red"
    },
    {
      "x": -8,
      "y": 9,
      "z": -4,
      "name": "Rock_Sandstone_Red"
    },
    {
      "x": -8,
      "y": 10,
      "z": -4,
      "name": "Rock_Sandstone_Red"
    },
    {
      "x": -8,
      "y": 11,
      "z": -4,
      "name": "Rock_Sandstone_Red"
    },
    {
      "x": -8,
      "y": 12,
      "z": -4,
      "name": "Rock_Sandstone_Red"
    },
    {
      "x": -8,
      "y": 13,
      "z": -4,
      "name": "Soil_Clay_Orange"
    },
    {
      "x": -8,
      "y": 14,
      "z": -4,
      "name": "Soil_Clay_Orange"
    },
    {
      "x": -8,
      "y": 15,
      "z": -4,
      "name": "Soil_Clay_Smooth_Red"
    },
    {
      "x": -8,
      "y": 20,
      "z": -4,
      "name": "Rock_Sandstone_Red"
    },
    {
      "x": -8,
      "y": 21,
      "z": -4,
      "name": "Soil_Clay_Smooth_Red"
    },
    {
      "x": -8,
      "y": 2,
      "z": -3,
      "name": "Rock_Sandstone_Red"
    },
    {
      "x": -8,
      "y": 3,
      "z": -3,
      "name": "Rock_Sandstone_Red"
    },
    {
      "x": -8,
      "y": 4,
      "z": -3,
      "name": "Rock_Sandstone_Red"
    },
    {
      "x": -8,
      "y": 5,
      "z": -3,
      "name": "Rock_Sandstone_Red"
    },
    {
      "x": -8,
      "y": 6,
      "z": -3,
      "name": "Rock_Sandstone_Red"
    },
    {
      "x": -8,
      "y": 7,
      "z": -3,
      "name": "Rock_Sandstone_Red"
    },
    {
      "x": -8,
      "y": 8,
      "z": -3,
      "name": "Rock_Sandstone_Red"
    },
    {
      "x": -8,
      "y": 9,
      "z": -3,
      "name": "Rock_Sandstone_Red"
    },
    {
      "x": -8,
      "y": 10,
      "z": -3,
      "name": "Rock_Sandstone_Red"
    },
    {
      "x": -8,
      "y": 11,
      "z": -3,
      "name": "Rock_Sandstone_Red"
    },
    {
      "x": -8,
      "y": 12,
      "z": -3,
      "name": "Rock_Sandstone_Red"
    },
    {
      "x": -8,
      "y": 13,
      "z": -3,
      "name": "Rock_Sandstone_Red"
    },
    {
      "x": -8,
      "y": 14,
      "z": -3,
      "name": "Soil_Clay_Orange"
    },
    {
      "x": -8,
      "y": 15,
      "z": -3,
      "name": "Soil_Clay_Smooth_Red"
    },
    {
      "x": -8,
      "y": 19,
      "z": -3,
      "name": "Rock_Sandstone_Red"
    },
    {
      "x": -8,
      "y": 20,
      "z": -3,
      "name": "Rock_Sandstone_Red"
    },
    {
      "x": -8,
      "y": 21,
      "z": -3,
      "name": "Soil_Clay_Smooth_Red"
    },
    {
      "x": -8,
      "y": 2,
      "z": -2,
      "name": "Rock_Sandstone_Red"
    },
    {
      "x": -8,
      "y": 3,
      "z": -2,
      "name": "Rock_Sandstone_Red"
    },
    {
      "x": -8,
      "y": 4,
      "z": -2,
      "name": "Rock_Sandstone_Red"
    },
    {
      "x": -8,
      "y": 5,
      "z": -2,
      "name": "Rock_Sandstone_Red"
    },
    {
      "x": -8,
      "y": 6,
      "z": -2,
      "name": "Rock_Sandstone_Red"
    },
    {
      "x": -8,
      "y": 7,
      "z": -2,
      "name": "Rock_Sandstone_Red"
    },
    {
      "x": -8,
      "y": 8,
      "z": -2,
      "name": "Rock_Sandstone_Red"
    },
    {
      "x": -8,
      "y": 9,
      "z": -2,
      "name": "Rock_Sandstone_Red"
    },
    {
      "x": -8,
      "y": 10,
      "z": -2,
      "name": "Rock_Sandstone_Red"
    },
    {
      "x": -8,
      "y": 11,
      "z": -2,
      "name": "Rock_Sandstone_Red"
    },
    {
      "x": -8,
      "y": 12,
      "z": -2,
      "name": "Rock_Sandstone_Red"
    },
    {
      "x": -8,
      "y": 13,
      "z": -2,
      "name": "Rock_Sandstone_Red"
    },
    {
      "x": -8,
      "y": 14,
      "z": -2,
      "name": "Soil_Clay_Orange"
    },
    {
      "x": -8,
      "y": 15,
      "z": -2,
      "name": "Soil_Clay_Smooth_Red"
    },
    {
      "x": -8,
      "y": 19,
      "z": -2,
      "name": "Rock_Sandstone_Red"
    },
    {
      "x": -8,
      "y": 20,
      "z": -2,
      "name": "Rock_Sandstone_Red"
    },
    {
      "x": -8,
      "y": 21,
      "z": -2,
      "name": "Soil_Clay_Smooth_Red"
    },
    {
      "x": -8,
      "y": 2,
      "z": -1,
      "name": "Rock_Sandstone_Red"
    },
    {
      "x": -8,
      "y": 3,
      "z": -1,
      "name": "Rock_Sandstone_Red"
    },
    {
      "x": -8,
      "y": 4,
      "z": -1,
      "name": "Rock_Sandstone_Red"
    },
    {
      "x": -8,
      "y": 5,
      "z": -1,
      "name": "Rock_Sandstone_Red"
    },
    {
      "x": -8,
      "y": 6,
      "z": -1,
      "name": "Rock_Sandstone_Red"
    },
    {
      "x": -8,
      "y": 7,
      "z": -1,
      "name": "Rock_Sandstone_Red"
    },
    {
      "x": -8,
      "y": 8,
      "z": -1,
      "name": "Soil_Clay_Orange"
    },
    {
      "x": -8,
      "y": 9,
      "z": -1,
      "name": "Rock_Sandstone_Red"
    },
    {
      "x": -8,
      "y": 10,
      "z": -1,
      "name": "Rock_Sandstone_Red"
    },
    {
      "x": -8,
      "y": 11,
      "z": -1,
      "name": "Rock_Sandstone_Red"
    },
    {
      "x": -8,
      "y": 12,
      "z": -1,
      "name": "Rock_Sandstone_Red"
    },
    {
      "x": -8,
      "y": 13,
      "z": -1,
      "name": "Rock_Sandstone_Red"
    },
    {
      "x": -8,
      "y": 14,
      "z": -1,
      "name": "Soil_Clay_Orange"
    },
    {
      "x": -8,
      "y": 15,
      "z": -1,
      "name": "Soil_Clay_Smooth_Red"
    },
    {
      "x": -8,
      "y": 19,
      "z": -1,
      "name": "Rock_Sandstone_Red"
    },
    {
      "x": -8,
      "y": 20,
      "z": -1,
      "name": "Rock_Sandstone_Red"
    },
    {
      "x": -8,
      "y": 21,
      "z": -1,
      "name": "Soil_Clay_Smooth_Red"
    },
    {
      "x": -8,
      "y": 2,
      "z": 0,
      "name": "Rock_Sandstone_Red"
    },
    {
      "x": -8,
      "y": 3,
      "z": 0,
      "name": "Rock_Sandstone_Red"
    },
    {
      "x": -8,
      "y": 4,
      "z": 0,
      "name": "Rock_Sandstone_Red"
    },
    {
      "x": -8,
      "y": 5,
      "z": 0,
      "name": "Rock_Sandstone_Red"
    },
    {
      "x": -8,
      "y": 6,
      "z": 0,
      "name": "Rock_Sandstone_Red"
    },
    {
      "x": -8,
      "y": 7,
      "z": 0,
      "name": "Rock_Sandstone_Red"
    },
    {
      "x": -8,
      "y": 8,
      "z": 0,
      "name": "Soil_Clay_Orange"
    },
    {
      "x": -8,
      "y": 9,
      "z": 0,
      "name": "Rock_Sandstone_Red"
    },
    {
      "x": -8,
      "y": 10,
      "z": 0,
      "name": "Rock_Sandstone_Red"
    },
    {
      "x": -8,
      "y": 11,
      "z": 0,
      "name": "Rock_Sandstone_Red"
    },
    {
      "x": -8,
      "y": 12,
      "z": 0,
      "name": "Rock_Sandstone_Red"
    },
    {
      "x": -8,
      "y": 13,
      "z": 0,
      "name": "Rock_Sandstone_Red"
    },
    {
      "x": -8,
      "y": 14,
      "z": 0,
      "name": "Soil_Clay_Orange"
    },
    {
      "x": -8,
      "y": 15,
      "z": 0,
      "name": "Soil_Clay_Smooth_Red"
    },
    {
      "x": -8,
      "y": 2,
      "z": 1,
      "name": "Rock_Sandstone_Red"
    },
    {
      "x": -8,
      "y": 3,
      "z": 1,
      "name": "Rock_Sandstone_Red"
    },
    {
      "x": -8,
      "y": 4,
      "z": 1,
      "name": "Rock_Sandstone_Red"
    },
    {
      "x": -8,
      "y": 5,
      "z": 1,
      "name": "Rock_Sandstone_Red"
    },
    {
      "x": -8,
      "y": 6,
      "z": 1,
      "name": "Rock_Sandstone_Red"
    },
    {
      "x": -8,
      "y": 7,
      "z": 1,
      "name": "Rock_Sandstone_Red"
    },
    {
      "x": -8,
      "y": 8,
      "z": 1,
      "name": "Soil_Clay_Orange"
    },
    {
      "x": -8,
      "y": 9,
      "z": 1,
      "name": "Rock_Sandstone_Red"
    },
    {
      "x": -8,
      "y": 10,
      "z": 1,
      "name": "Rock_Sandstone_Red"
    },
    {
      "x": -8,
      "y": 11,
      "z": 1,
      "name": "Rock_Sandstone_Red"
    },
    {
      "x": -8,
      "y": 12,
      "z": 1,
      "name": "Rock_Sandstone_Red"
    },
    {
      "x": -8,
      "y": 13,
      "z": 1,
      "name": "Rock_Sandstone_Red"
    },
    {
      "x": -8,
      "y": 14,
      "z": 1,
      "name": "Soil_Clay_Orange"
    },
    {
      "x": -8,
      "y": 15,
      "z": 1,
      "name": "Soil_Clay_Smooth_Red"
    },
    {
      "x": -8,
      "y": 2,
      "z": 2,
      "name": "Rock_Sandstone_Red"
    },
    {
      "x": -8,
      "y": 3,
      "z": 2,
      "name": "Rock_Sandstone_Red"
    },
    {
      "x": -8,
      "y": 4,
      "z": 2,
      "name": "Rock_Sandstone_Red"
    },
    {
      "x": -8,
      "y": 5,
      "z": 2,
      "name": "Rock_Sandstone_Red"
    },
    {
      "x": -8,
      "y": 6,
      "z": 2,
      "name": "Rock_Sandstone_Red"
    },
    {
      "x": -8,
      "y": 7,
      "z": 2,
      "name": "Soil_Clay_Orange"
    },
    {
      "x": -8,
      "y": 8,
      "z": 2,
      "name": "Soil_Clay_Orange"
    },
    {
      "x": -8,
      "y": 9,
      "z": 2,
      "name": "Soil_Clay_Orange"
    },
    {
      "x": -8,
      "y": 10,
      "z": 2,
      "name": "Soil_Clay_Orange"
    },
    {
      "x": -8,
      "y": 11,
      "z": 2,
      "name": "Rock_Sandstone_Red"
    },
    {
      "x": -8,
      "y": 12,
      "z": 2,
      "name": "Rock_Sandstone_Red"
    },
    {
      "x": -8,
      "y": 13,
      "z": 2,
      "name": "Rock_Sandstone_Red"
    },
    {
      "x": -8,
      "y": 14,
      "z": 2,
      "name": "Soil_Clay_Orange"
    },
    {
      "x": -8,
      "y": 15,
      "z": 2,
      "name": "Soil_Clay_Smooth_Red"
    },
    {
      "x": -8,
      "y": 2,
      "z": 3,
      "name": "Rock_Sandstone_Red"
    },
    {
      "x": -8,
      "y": 3,
      "z": 3,
      "name": "Rock_Sandstone_Red"
    },
    {
      "x": -8,
      "y": 4,
      "z": 3,
      "name": "Rock_Sandstone_Red"
    },
    {
      "x": -8,
      "y": 5,
      "z": 3,
      "name": "Rock_Sandstone_Red"
    },
    {
      "x": -8,
      "y": 6,
      "z": 3,
      "name": "Rock_Sandstone_Red"
    },
    {
      "x": -8,
      "y": 7,
      "z": 3,
      "name": "Soil_Clay_Orange"
    },
    {
      "x": -8,
      "y": 8,
      "z": 3,
      "name": "Soil_Clay_Orange"
    },
    {
      "x": -8,
      "y": 9,
      "z": 3,
      "name": "Soil_Clay_Orange"
    },
    {
      "x": -8,
      "y": 10,
      "z": 3,
      "name": "Soil_Clay_Orange"
    },
    {
      "x": -8,
      "y": 11,
      "z": 3,
      "name": "Rock_Sandstone_Red"
    },
    {
      "x": -8,
      "y": 12,
      "z": 3,
      "name": "Rock_Sandstone_Red"
    },
    {
      "x": -8,
      "y": 13,
      "z": 3,
      "name": "Rock_Sandstone_Red"
    },
    {
      "x": -8,
      "y": 14,
      "z": 3,
      "name": "Soil_Clay_Orange"
    },
    {
      "x": -8,
      "y": 15,
      "z": 3,
      "name": "Soil_Clay_Smooth_Red"
    },
    {
      "x": -8,
      "y": 2,
      "z": 4,
      "name": "Rock_Sandstone_Red"
    },
    {
      "x": -8,
      "y": 3,
      "z": 4,
      "name": "Rock_Sandstone_Red"
    },
    {
      "x": -8,
      "y": 4,
      "z": 4,
      "name": "Rock_Sandstone_Red"
    },
    {
      "x": -8,
      "y": 5,
      "z": 4,
      "name": "Rock_Sandstone_Red"
    },
    {
      "x": -8,
      "y": 6,
      "z": 4,
      "name": "Rock_Sandstone_Red"
    },
    {
      "x": -8,
      "y": 7,
      "z": 4,
      "name": "Soil_Clay_Orange"
    },
    {
      "x": -8,
      "y": 8,
      "z": 4,
      "name": "Soil_Clay_Orange"
    },
    {
      "x": -8,
      "y": 9,
      "z": 4,
      "name": "Soil_Clay_Orange"
    },
    {
      "x": -8,
      "y": 10,
      "z": 4,
      "name": "Soil_Clay_Orange"
    },
    {
      "x": -8,
      "y": 11,
      "z": 4,
      "name": "Soil_Clay_Orange"
    },
    {
      "x": -8,
      "y": 12,
      "z": 4,
      "name": "Rock_Sandstone_Red"
    },
    {
      "x": -8,
      "y": 13,
      "z": 4,
      "name": "Soil_Clay_Orange"
    },
    {
      "x": -8,
      "y": 14,
      "z": 4,
      "name": "Soil_Clay_Smooth_Red"
    },
    {
      "x": -8,
      "y": 3,
      "z": 5,
      "name": "Rock_Sandstone_Red"
    },
    {
      "x": -8,
      "y": 4,
      "z": 5,
      "name": "Rock_Sandstone_Red"
    },
    {
      "x": -8,
      "y": 5,
      "z": 5,
      "name": "Rock_Sandstone_Red"
    },
    {
      "x": -8,
      "y": 6,
      "z": 5,
      "name": "Rock_Sandstone_Red"
    },
    {
      "x": -8,
      "y": 7,
      "z": 5,
      "name": "Soil_Clay_Orange"
    },
    {
      "x": -8,
      "y": 8,
      "z": 5,
      "name": "Soil_Clay_Orange"
    },
    {
      "x": -8,
      "y": 9,
      "z": 5,
      "name": "Soil_Clay_Orange"
    },
    {
      "x": -8,
      "y": 10,
      "z": 5,
      "name": "Soil_Clay_Orange"
    },
    {
      "x": -8,
      "y": 11,
      "z": 5,
      "name": "Soil_Clay_Orange"
    },
    {
      "x": -8,
      "y": 12,
      "z": 5,
      "name": "Soil_Clay_Orange"
    },
    {
      "x": -8,
      "y": 13,
      "z": 5,
      "name": "Soil_Clay_Orange"
    },
    {
      "x": -8,
      "y": 14,
      "z": 5,
      "name": "Soil_Clay_Smooth_Red"
    },
    {
      "x": -8,
      "y": 3,
      "z": 6,
      "name": "Rock_Sandstone_Red"
    },
    {
      "x": -8,
      "y": 4,
      "z": 6,
      "name": "Rock_Sandstone_Red"
    },
    {
      "x": -8,
      "y": 5,
      "z": 6,
      "name": "Rock_Sandstone_Red"
    },
    {
      "x": -8,
      "y": 6,
      "z": 6,
      "name": "Rock_Sandstone_Red"
    },
    {
      "x": -8,
      "y": 7,
      "z": 6,
      "name": "Soil_Clay_Orange"
    },
    {
      "x": -8,
      "y": 8,
      "z": 6,
      "name": "Soil_Clay_Orange"
    },
    {
      "x": -8,
      "y": 9,
      "z": 6,
      "name": "Soil_Clay_Orange"
    },
    {
      "x": -8,
      "y": 10,
      "z": 6,
      "name": "Soil_Clay_Orange"
    },
    {
      "x": -8,
      "y": 11,
      "z": 6,
      "name": "Soil_Clay_Orange"
    },
    {
      "x": -8,
      "y": 12,
      "z": 6,
      "name": "Soil_Clay_Orange"
    },
    {
      "x": -8,
      "y": 13,
      "z": 6,
      "name": "Rock_Sandstone"
    },
    {
      "x": -8,
      "y": 4,
      "z": 7,
      "name": "Rock_Sandstone_Red"
    },
    {
      "x": -8,
      "y": 5,
      "z": 7,
      "name": "Rock_Sandstone_Red"
    },
    {
      "x": -8,
      "y": 6,
      "z": 7,
      "name": "Rock_Sandstone_Red"
    },
    {
      "x": -8,
      "y": 7,
      "z": 7,
      "name": "Soil_Clay_Orange"
    },
    {
      "x": -8,
      "y": 8,
      "z": 7,
      "name": "Soil_Clay_Orange"
    },
    {
      "x": -8,
      "y": 9,
      "z": 7,
      "name": "Soil_Clay_Orange"
    },
    {
      "x": -8,
      "y": 10,
      "z": 7,
      "name": "Soil_Clay_Orange"
    },
    {
      "x": -8,
      "y": 11,
      "z": 7,
      "name": "Soil_Clay_Orange"
    },
    {
      "x": -8,
      "y": 12,
      "z": 7,
      "name": "Soil_Clay_Orange"
    },
    {
      "x": -8,
      "y": 13,
      "z": 7,
      "name": "Rock_Sandstone"
    },
    {
      "x": -7,
      "y": 4,
      "z": -9,
      "name": "Rock_Sandstone_Red"
    },
    {
      "x": -7,
      "y": 5,
      "z": -9,
      "name": "Rock_Sandstone_Red"
    },
    {
      "x": -7,
      "y": 6,
      "z": -9,
      "name": "Rock_Sandstone_Red"
    },
    {
      "x": -7,
      "y": 7,
      "z": -9,
      "name": "Soil_Clay_Orange"
    },
    {
      "x": -7,
      "y": 8,
      "z": -9,
      "name": "Rock_Sandstone"
    },
    {
      "x": -7,
      "y": 9,
      "z": -9,
      "name": "Rock_Sandstone_Red"
    },
    {
      "x": -7,
      "y": 10,
      "z": -9,
      "name": "Rock_Sandstone_Red"
    },
    {
      "x": -7,
      "y": 11,
      "z": -9,
      "name": "Rock_Sandstone_Red"
    },
    {
      "x": -7,
      "y": 12,
      "z": -9,
      "name": "Rock_Sandstone_Red"
    },
    {
      "x": -7,
      "y": 13,
      "z": -9,
      "name": "Rock_Sandstone_Red"
    },
    {
      "x": -7,
      "y": 3,
      "z": -8,
      "name": "Rock_Sandstone_Red"
    },
    {
      "x": -7,
      "y": 4,
      "z": -8,
      "name": "Rock_Sandstone_Red"
    },
    {
      "x": -7,
      "y": 5,
      "z": -8,
      "name": "Rock_Sandstone_Red"
    },
    {
      "x": -7,
      "y": 6,
      "z": -8,
      "name": "Rock_Sandstone_Red"
    },
    {
      "x": -7,
      "y": 7,
      "z": -8,
      "name": "Soil_Clay_Orange"
    },
    {
      "x": -7,
      "y": 8,
      "z": -8,
      "name": "Rock_Sandstone"
    },
    {
      "x": -7,
      "y": 9,
      "z": -8,
      "name": "Rock_Sandstone_Red"
    },
    {
      "x": -7,
      "y": 10,
      "z": -8,
      "name": "Rock_Sandstone_Red"
    },
    {
      "x": -7,
      "y": 11,
      "z": -8,
      "name": "Rock_Sandstone_Red"
    },
    {
      "x": -7,
      "y": 12,
      "z": -8,
      "name": "Rock_Sandstone_Red"
    },
    {
      "x": -7,
      "y": 13,
      "z": -8,
      "name": "Rock_Sandstone_Red"
    },
    {
      "x": -7,
      "y": 14,
      "z": -8,
      "name": "Soil_Clay_Smooth_Red"
    },
    {
      "x": -7,
      "y": 20,
      "z": -8,
      "name": "Rock_Sandstone_Red"
    },
    {
      "x": -7,
      "y": 21,
      "z": -8,
      "name": "Rock_Sandstone_Red"
    },
    {
      "x": -7,
      "y": 3,
      "z": -7,
      "name": "Rock_Sandstone_Red"
    },
    {
      "x": -7,
      "y": 4,
      "z": -7,
      "name": "Rock_Sandstone_Red"
    },
    {
      "x": -7,
      "y": 5,
      "z": -7,
      "name": "Rock_Sandstone_Red"
    },
    {
      "x": -7,
      "y": 6,
      "z": -7,
      "name": "Rock_Sandstone_Red"
    },
    {
      "x": -7,
      "y": 7,
      "z": -7,
      "name": "Rock_Sandstone_Red"
    },
    {
      "x": -7,
      "y": 8,
      "z": -7,
      "name": "Rock_Sandstone"
    },
    {
      "x": -7,
      "y": 9,
      "z": -7,
      "name": "Rock_Sandstone_Red"
    },
    {
      "x": -7,
      "y": 10,
      "z": -7,
      "name": "Rock_Sandstone_Red"
    },
    {
      "x": -7,
      "y": 11,
      "z": -7,
      "name": "Rock_Sandstone_Red"
    },
    {
      "x": -7,
      "y": 12,
      "z": -7,
      "name": "Rock_Sandstone_Red"
    },
    {
      "x": -7,
      "y": 13,
      "z": -7,
      "name": "Rock_Sandstone_Red"
    },
    {
      "x": -7,
      "y": 14,
      "z": -7,
      "name": "Soil_Clay_Smooth_Red"
    },
    {
      "x": -7,
      "y": 20,
      "z": -7,
      "name": "Rock_Sandstone_Red"
    },
    {
      "x": -7,
      "y": 21,
      "z": -7,
      "name": "Soil_Clay_Smooth_Red"
    },
    {
      "x": -7,
      "y": 3,
      "z": -6,
      "name": "Rock_Sandstone_Red"
    },
    {
      "x": -7,
      "y": 4,
      "z": -6,
      "name": "Rock_Sandstone_Red"
    },
    {
      "x": -7,
      "y": 5,
      "z": -6,
      "name": "Rock_Sandstone_Red"
    },
    {
      "x": -7,
      "y": 6,
      "z": -6,
      "name": "Rock_Sandstone_Red"
    },
    {
      "x": -7,
      "y": 7,
      "z": -6,
      "name": "Rock_Sandstone_Red"
    },
    {
      "x": -7,
      "y": 8,
      "z": -6,
      "name": "Rock_Sandstone_Red"
    },
    {
      "x": -7,
      "y": 9,
      "z": -6,
      "name": "Rock_Sandstone_Red"
    },
    {
      "x": -7,
      "y": 10,
      "z": -6,
      "name": "Rock_Sandstone_Red"
    },
    {
      "x": -7,
      "y": 11,
      "z": -6,
      "name": "Rock_Sandstone_Red"
    },
    {
      "x": -7,
      "y": 12,
      "z": -6,
      "name": "Rock_Sandstone_Red"
    },
    {
      "x": -7,
      "y": 13,
      "z": -6,
      "name": "Rock_Sandstone_Red"
    },
    {
      "x": -7,
      "y": 14,
      "z": -6,
      "name": "Soil_Clay_Orange"
    },
    {
      "x": -7,
      "y": 15,
      "z": -6,
      "name": "Soil_Clay_Smooth_Red"
    },
    {
      "x": -7,
      "y": 19,
      "z": -6,
      "name": "Rock_Sandstone_Red"
    },
    {
      "x": -7,
      "y": 20,
      "z": -6,
      "name": "Rock_Sandstone_Red"
    },
    {
      "x": -7,
      "y": 21,
      "z": -6,
      "name": "Soil_Clay_Smooth_Red"
    },
    {
      "x": -7,
      "y": 2,
      "z": -5,
      "name": "Rock_Sandstone_Red"
    },
    {
      "x": -7,
      "y": 3,
      "z": -5,
      "name": "Rock_Sandstone_Red"
    },
    {
      "x": -7,
      "y": 4,
      "z": -5,
      "name": "Rock_Sandstone_Red"
    },
    {
      "x": -7,
      "y": 5,
      "z": -5,
      "name": "Rock_Sandstone_Red"
    },
    {
      "x": -7,
      "y": 6,
      "z": -5,
      "name": "Rock_Sandstone_Red"
    },
    {
      "x": -7,
      "y": 7,
      "z": -5,
      "name": "Rock_Sandstone_Red"
    },
    {
      "x": -7,
      "y": 8,
      "z": -5,
      "name": "Rock_Sandstone_Red"
    },
    {
      "x": -7,
      "y": 9,
      "z": -5,
      "name": "Rock_Sandstone_Red"
    },
    {
      "x": -7,
      "y": 10,
      "z": -5,
      "name": "Rock_Sandstone_Red"
    },
    {
      "x": -7,
      "y": 11,
      "z": -5,
      "name": "Rock_Sandstone_Red"
    },
    {
      "x": -7,
      "y": 12,
      "z": -5,
      "name": "Rock_Sandstone_Red"
    },
    {
      "x": -7,
      "y": 13,
      "z": -5,
      "name": "Rock_Sandstone_Red"
    },
    {
      "x": -7,
      "y": 14,
      "z": -5,
      "name": "Soil_Clay_Orange"
    },
    {
      "x": -7,
      "y": 15,
      "z": -5,
      "name": "Soil_Clay_Smooth_Red"
    },
    {
      "x": -7,
      "y": 20,
      "z": -5,
      "name": "Rock_Sandstone_Red"
    },
    {
      "x": -7,
      "y": 21,
      "z": -5,
      "name": "Soil_Clay_Smooth_Red"
    },
    {
      "x": -7,
      "y": 2,
      "z": -4,
      "name": "Rock_Sandstone_Red"
    },
    {
      "x": -7,
      "y": 3,
      "z": -4,
      "name": "Rock_Sandstone_Red"
    },
    {
      "x": -7,
      "y": 4,
      "z": -4,
      "name": "Rock_Sandstone_Red"
    },
    {
      "x": -7,
      "y": 5,
      "z": -4,
      "name": "Rock_Sandstone_Red"
    },
    {
      "x": -7,
      "y": 6,
      "z": -4,
      "name": "Rock_Sandstone_Red"
    },
    {
      "x": -7,
      "y": 7,
      "z": -4,
      "name": "Rock_Sandstone_Red"
    },
    {
      "x": -7,
      "y": 8,
      "z": -4,
      "name": "Rock_Sandstone_Red"
    },
    {
      "x": -7,
      "y": 9,
      "z": -4,
      "name": "Rock_Sandstone_Red"
    },
    {
      "x": -7,
      "y": 10,
      "z": -4,
      "name": "Rock_Sandstone_Red"
    },
    {
      "x": -7,
      "y": 11,
      "z": -4,
      "name": "Rock_Sandstone_Red"
    },
    {
      "x": -7,
      "y": 12,
      "z": -4,
      "name": "Rock_Sandstone_Red"
    },
    {
      "x": -7,
      "y": 13,
      "z": -4,
      "name": "Rock_Sandstone_Red"
    },
    {
      "x": -7,
      "y": 14,
      "z": -4,
      "name": "Soil_Clay_Orange"
    },
    {
      "x": -7,
      "y": 15,
      "z": -4,
      "name": "Soil_Clay_Smooth_Red"
    },
    {
      "x": -7,
      "y": 19,
      "z": -4,
      "name": "Rock_Sandstone_Red"
    },
    {
      "x": -7,
      "y": 20,
      "z": -4,
      "name": "Rock_Sandstone_Red"
    },
    {
      "x": -7,
      "y": 21,
      "z": -4,
      "name": "Soil_Clay_Smooth_Red"
    },
    {
      "x": -7,
      "y": 2,
      "z": -3,
      "name": "Rock_Sandstone_Red"
    },
    {
      "x": -7,
      "y": 3,
      "z": -3,
      "name": "Rock_Sandstone_Red"
    },
    {
      "x": -7,
      "y": 4,
      "z": -3,
      "name": "Rock_Sandstone_Red"
    },
    {
      "x": -7,
      "y": 5,
      "z": -3,
      "name": "Rock_Sandstone_Red"
    },
    {
      "x": -7,
      "y": 6,
      "z": -3,
      "name": "Rock_Sandstone_Red"
    },
    {
      "x": -7,
      "y": 7,
      "z": -3,
      "name": "Rock_Sandstone_Red"
    },
    {
      "x": -7,
      "y": 8,
      "z": -3,
      "name": "Rock_Sandstone_Red"
    },
    {
      "x": -7,
      "y": 9,
      "z": -3,
      "name": "Rock_Sandstone_Red"
    },
    {
      "x": -7,
      "y": 10,
      "z": -3,
      "name": "Rock_Sandstone_Red"
    },
    {
      "x": -7,
      "y": 11,
      "z": -3,
      "name": "Rock_Sandstone_Red"
    },
    {
      "x": -7,
      "y": 12,
      "z": -3,
      "name": "Rock_Sandstone_Red"
    },
    {
      "x": -7,
      "y": 13,
      "z": -3,
      "name": "Rock_Sandstone_Red"
    },
    {
      "x": -7,
      "y": 14,
      "z": -3,
      "name": "Soil_Clay_Orange"
    },
    {
      "x": -7,
      "y": 15,
      "z": -3,
      "name": "Soil_Clay_Smooth_Red"
    },
    {
      "x": -7,
      "y": 19,
      "z": -3,
      "name": "Rock_Sandstone_Red"
    },
    {
      "x": -7,
      "y": 20,
      "z": -3,
      "name": "Rock_Sandstone_Red"
    },
    {
      "x": -7,
      "y": 21,
      "z": -3,
      "name": "Soil_Clay_Smooth_Red"
    },
    {
      "x": -7,
      "y": 1,
      "z": -2,
      "name": "Soil_Clay_Orange"
    },
    {
      "x": -7,
      "y": 2,
      "z": -2,
      "name": "Rock_Sandstone_Red"
    },
    {
      "x": -7,
      "y": 3,
      "z": -2,
      "name": "Rock_Sandstone_Red"
    },
    {
      "x": -7,
      "y": 4,
      "z": -2,
      "name": "Rock_Sandstone_Red"
    },
    {
      "x": -7,
      "y": 5,
      "z": -2,
      "name": "Rock_Sandstone_Red"
    },
    {
      "x": -7,
      "y": 6,
      "z": -2,
      "name": "Rock_Sandstone_Red"
    },
    {
      "x": -7,
      "y": 7,
      "z": -2,
      "name": "Rock_Sandstone_Red"
    },
    {
      "x": -7,
      "y": 8,
      "z": -2,
      "name": "Soil_Clay_Orange"
    },
    {
      "x": -7,
      "y": 9,
      "z": -2,
      "name": "Rock_Sandstone_Red"
    },
    {
      "x": -7,
      "y": 10,
      "z": -2,
      "name": "Rock_Sandstone_Red"
    },
    {
      "x": -7,
      "y": 11,
      "z": -2,
      "name": "Rock_Sandstone_Red"
    },
    {
      "x": -7,
      "y": 12,
      "z": -2,
      "name": "Rock_Sandstone_Red"
    },
    {
      "x": -7,
      "y": 13,
      "z": -2,
      "name": "Rock_Sandstone_Red"
    },
    {
      "x": -7,
      "y": 14,
      "z": -2,
      "name": "Soil_Clay_Orange"
    },
    {
      "x": -7,
      "y": 15,
      "z": -2,
      "name": "Soil_Clay_Smooth_Red"
    },
    {
      "x": -7,
      "y": 18,
      "z": -2,
      "name": "Soil_Clay_Orange"
    },
    {
      "x": -7,
      "y": 19,
      "z": -2,
      "name": "Rock_Sandstone_Red"
    },
    {
      "x": -7,
      "y": 20,
      "z": -2,
      "name": "Rock_Sandstone_Red"
    },
    {
      "x": -7,
      "y": 21,
      "z": -2,
      "name": "Soil_Clay_Smooth_Red"
    },
    {
      "x": -7,
      "y": 1,
      "z": -1,
      "name": "Soil_Clay_Orange"
    },
    {
      "x": -7,
      "y": 2,
      "z": -1,
      "name": "Rock_Sandstone_Red"
    },
    {
      "x": -7,
      "y": 3,
      "z": -1,
      "name": "Rock_Sandstone_Red"
    },
    {
      "x": -7,
      "y": 4,
      "z": -1,
      "name": "Rock_Sandstone_Red"
    },
    {
      "x": -7,
      "y": 5,
      "z": -1,
      "name": "Rock_Sandstone_Red"
    },
    {
      "x": -7,
      "y": 6,
      "z": -1,
      "name": "Rock_Sandstone_Red"
    },
    {
      "x": -7,
      "y": 7,
      "z": -1,
      "name": "Soil_Clay_Orange"
    },
    {
      "x": -7,
      "y": 8,
      "z": -1,
      "name": "Soil_Clay_Orange"
    },
    {
      "x": -7,
      "y": 9,
      "z": -1,
      "name": "Rock_Sandstone_Red"
    },
    {
      "x": -7,
      "y": 10,
      "z": -1,
      "name": "Rock_Sandstone_Red"
    },
    {
      "x": -7,
      "y": 11,
      "z": -1,
      "name": "Rock_Sandstone_Red"
    },
    {
      "x": -7,
      "y": 12,
      "z": -1,
      "name": "Rock_Sandstone_Red"
    },
    {
      "x": -7,
      "y": 13,
      "z": -1,
      "name": "Rock_Sandstone_Red"
    },
    {
      "x": -7,
      "y": 14,
      "z": -1,
      "name": "Soil_Clay_Orange"
    },
    {
      "x": -7,
      "y": 15,
      "z": -1,
      "name": "Soil_Clay_Smooth_Red"
    },
    {
      "x": -7,
      "y": 18,
      "z": -1,
      "name": "Soil_Clay_Orange"
    },
    {
      "x": -7,
      "y": 19,
      "z": -1,
      "name": "Rock_Sandstone_Red"
    },
    {
      "x": -7,
      "y": 20,
      "z": -1,
      "name": "Rock_Sandstone_Red"
    },
    {
      "x": -7,
      "y": 21,
      "z": -1,
      "name": "Soil_Clay_Smooth_Red"
    },
    {
      "x": -7,
      "y": 1,
      "z": 0,
      "name": "Soil_Clay_Orange"
    },
    {
      "x": -7,
      "y": 2,
      "z": 0,
      "name": "Rock_Sandstone_Red"
    },
    {
      "x": -7,
      "y": 3,
      "z": 0,
      "name": "Rock_Sandstone_Red"
    },
    {
      "x": -7,
      "y": 4,
      "z": 0,
      "name": "Rock_Sandstone_Red"
    },
    {
      "x": -7,
      "y": 5,
      "z": 0,
      "name": "Rock_Sandstone_Red"
    },
    {
      "x": -7,
      "y": 6,
      "z": 0,
      "name": "Rock_Sandstone_Red"
    },
    {
      "x": -7,
      "y": 7,
      "z": 0,
      "name": "Soil_Clay_Orange"
    },
    {
      "x": -7,
      "y": 8,
      "z": 0,
      "name": "Soil_Clay_Orange"
    },
    {
      "x": -7,
      "y": 9,
      "z": 0,
      "name": "Rock_Sandstone_Red"
    },
    {
      "x": -7,
      "y": 10,
      "z": 0,
      "name": "Rock_Sandstone_Red"
    },
    {
      "x": -7,
      "y": 11,
      "z": 0,
      "name": "Rock_Sandstone_Red"
    },
    {
      "x": -7,
      "y": 12,
      "z": 0,
      "name": "Rock_Sandstone_Red"
    },
    {
      "x": -7,
      "y": 13,
      "z": 0,
      "name": "Rock_Sandstone_Red"
    },
    {
      "x": -7,
      "y": 14,
      "z": 0,
      "name": "Soil_Clay_Orange"
    },
    {
      "x": -7,
      "y": 15,
      "z": 0,
      "name": "Soil_Clay_Smooth_Red"
    },
    {
      "x": -7,
      "y": 18,
      "z": 0,
      "name": "Soil_Clay_Orange"
    },
    {
      "x": -7,
      "y": 19,
      "z": 0,
      "name": "Soil_Clay_Orange"
    },
    {
      "x": -7,
      "y": 20,
      "z": 0,
      "name": "Rock_Sandstone_Red"
    },
    {
      "x": -7,
      "y": 21,
      "z": 0,
      "name": "Soil_Clay_Smooth_Red"
    },
    {
      "x": -7,
      "y": 1,
      "z": 1,
      "name": "Soil_Clay_Orange"
    },
    {
      "x": -7,
      "y": 2,
      "z": 1,
      "name": "Rock_Sandstone_Red"
    },
    {
      "x": -7,
      "y": 3,
      "z": 1,
      "name": "Rock_Sandstone_Red"
    },
    {
      "x": -7,
      "y": 4,
      "z": 1,
      "name": "Rock_Sandstone_Red"
    },
    {
      "x": -7,
      "y": 5,
      "z": 1,
      "name": "Rock_Sandstone_Red"
    },
    {
      "x": -7,
      "y": 6,
      "z": 1,
      "name": "Rock_Sandstone_Red"
    },
    {
      "x": -7,
      "y": 7,
      "z": 1,
      "name": "Soil_Clay_Orange"
    },
    {
      "x": -7,
      "y": 8,
      "z": 1,
      "name": "Soil_Clay_Orange"
    },
    {
      "x": -7,
      "y": 9,
      "z": 1,
      "name": "Rock_Sandstone_Red"
    },
    {
      "x": -7,
      "y": 10,
      "z": 1,
      "name": "Rock_Sandstone_Red"
    },
    {
      "x": -7,
      "y": 11,
      "z": 1,
      "name": "Rock_Sandstone_Red"
    },
    {
      "x": -7,
      "y": 12,
      "z": 1,
      "name": "Rock_Sandstone_Red"
    },
    {
      "x": -7,
      "y": 13,
      "z": 1,
      "name": "Rock_Sandstone_Red"
    },
    {
      "x": -7,
      "y": 14,
      "z": 1,
      "name": "Soil_Clay_Orange"
    },
    {
      "x": -7,
      "y": 15,
      "z": 1,
      "name": "Soil_Clay_Smooth_Red"
    },
    {
      "x": -7,
      "y": 20,
      "z": 1,
      "name": "Rock_Sandstone_Red"
    },
    {
      "x": -7,
      "y": 21,
      "z": 1,
      "name": "Soil_Clay_Smooth_Red"
    },
    {
      "x": -7,
      "y": 2,
      "z": 2,
      "name": "Soil_Clay_Orange"
    },
    {
      "x": -7,
      "y": 3,
      "z": 2,
      "name": "Rock_Sandstone_Red"
    },
    {
      "x": -7,
      "y": 4,
      "z": 2,
      "name": "Rock_Sandstone_Red"
    },
    {
      "x": -7,
      "y": 5,
      "z": 2,
      "name": "Rock_Sandstone_Red"
    },
    {
      "x": -7,
      "y": 6,
      "z": 2,
      "name": "Rock_Sandstone_Red"
    },
    {
      "x": -7,
      "y": 7,
      "z": 2,
      "name": "Soil_Clay_Orange"
    },
    {
      "x": -7,
      "y": 8,
      "z": 2,
      "name": "Soil_Clay_Orange"
    },
    {
      "x": -7,
      "y": 9,
      "z": 2,
      "name": "Soil_Clay_Orange"
    },
    {
      "x": -7,
      "y": 10,
      "z": 2,
      "name": "Rock_Sandstone_Red"
    },
    {
      "x": -7,
      "y": 11,
      "z": 2,
      "name": "Rock_Sandstone_Red"
    },
    {
      "x": -7,
      "y": 12,
      "z": 2,
      "name": "Rock_Sandstone_Red"
    },
    {
      "x": -7,
      "y": 13,
      "z": 2,
      "name": "Rock_Sandstone_Red"
    },
    {
      "x": -7,
      "y": 14,
      "z": 2,
      "name": "Soil_Clay_Orange"
    },
    {
      "x": -7,
      "y": 15,
      "z": 2,
      "name": "Soil_Clay_Smooth_Red"
    },
    {
      "x": -7,
      "y": 2,
      "z": 3,
      "name": "Soil_Clay_Orange"
    },
    {
      "x": -7,
      "y": 3,
      "z": 3,
      "name": "Rock_Sandstone_Red"
    },
    {
      "x": -7,
      "y": 4,
      "z": 3,
      "name": "Rock_Sandstone_Red"
    },
    {
      "x": -7,
      "y": 5,
      "z": 3,
      "name": "Rock_Sandstone_Red"
    },
    {
      "x": -7,
      "y": 6,
      "z": 3,
      "name": "Rock_Sandstone_Red"
    },
    {
      "x": -7,
      "y": 7,
      "z": 3,
      "name": "Soil_Clay_Orange"
    },
    {
      "x": -7,
      "y": 8,
      "z": 3,
      "name": "Soil_Clay_Orange"
    },
    {
      "x": -7,
      "y": 9,
      "z": 3,
      "name": "Soil_Clay_Orange"
    },
    {
      "x": -7,
      "y": 10,
      "z": 3,
      "name": "Soil_Clay_Orange"
    },
    {
      "x": -7,
      "y": 11,
      "z": 3,
      "name": "Rock_Sandstone_Red"
    },
    {
      "x": -7,
      "y": 12,
      "z": 3,
      "name": "Rock_Sandstone_Red"
    },
    {
      "x": -7,
      "y": 13,
      "z": 3,
      "name": "Rock_Sandstone_Red"
    },
    {
      "x": -7,
      "y": 14,
      "z": 3,
      "name": "Soil_Clay_Orange"
    },
    {
      "x": -7,
      "y": 15,
      "z": 3,
      "name": "Soil_Clay_Smooth_Red"
    },
    {
      "x": -7,
      "y": 2,
      "z": 4,
      "name": "Soil_Clay_Orange"
    },
    {
      "x": -7,
      "y": 3,
      "z": 4,
      "name": "Rock_Sandstone_Red"
    },
    {
      "x": -7,
      "y": 4,
      "z": 4,
      "name": "Rock_Sandstone_Red"
    },
    {
      "x": -7,
      "y": 5,
      "z": 4,
      "name": "Rock_Sandstone_Red"
    },
    {
      "x": -7,
      "y": 6,
      "z": 4,
      "name": "Rock_Sandstone_Red"
    },
    {
      "x": -7,
      "y": 7,
      "z": 4,
      "name": "Soil_Clay_Orange"
    },
    {
      "x": -7,
      "y": 8,
      "z": 4,
      "name": "Soil_Clay_Orange"
    },
    {
      "x": -7,
      "y": 9,
      "z": 4,
      "name": "Soil_Clay_Orange"
    },
    {
      "x": -7,
      "y": 10,
      "z": 4,
      "name": "Soil_Clay_Orange"
    },
    {
      "x": -7,
      "y": 11,
      "z": 4,
      "name": "Rock_Sandstone_Red"
    },
    {
      "x": -7,
      "y": 12,
      "z": 4,
      "name": "Rock_Sandstone_Red"
    },
    {
      "x": -7,
      "y": 13,
      "z": 4,
      "name": "Soil_Clay_Orange"
    },
    {
      "x": -7,
      "y": 14,
      "z": 4,
      "name": "Rock_Sandstone"
    },
    {
      "x": -7,
      "y": 15,
      "z": 4,
      "name": "Soil_Clay_Smooth_Red"
    },
    {
      "x": -7,
      "y": 39,
      "z": 4,
      "name": "Rock_Sandstone_Red"
    },
    {
      "x": -7,
      "y": 40,
      "z": 4,
      "name": "Rock_Sandstone_Red"
    },
    {
      "x": -7,
      "y": 41,
      "z": 4,
      "name": "Rock_Sandstone_Red"
    },
    {
      "x": -7,
      "y": 42,
      "z": 4,
      "name": "Soil_Clay_Orange"
    },
    {
      "x": -7,
      "y": 43,
      "z": 4,
      "name": "Soil_Clay_Orange"
    },
    {
      "x": -7,
      "y": 44,
      "z": 4,
      "name": "Rock_Sandstone_Red"
    },
    {
      "x": -7,
      "y": 2,
      "z": 5,
      "name": "Soil_Clay_Orange"
    },
    {
      "x": -7,
      "y": 3,
      "z": 5,
      "name": "Rock_Sandstone_Red"
    },
    {
      "x": -7,
      "y": 4,
      "z": 5,
      "name": "Rock_Sandstone_Red"
    },
    {
      "x": -7,
      "y": 5,
      "z": 5,
      "name": "Rock_Sandstone_Red"
    },
    {
      "x": -7,
      "y": 6,
      "z": 5,
      "name": "Rock_Sandstone_Red"
    },
    {
      "x": -7,
      "y": 7,
      "z": 5,
      "name": "Soil_Clay_Orange"
    },
    {
      "x": -7,
      "y": 8,
      "z": 5,
      "name": "Soil_Clay_Orange"
    },
    {
      "x": -7,
      "y": 9,
      "z": 5,
      "name": "Soil_Clay_Orange"
    },
    {
      "x": -7,
      "y": 10,
      "z": 5,
      "name": "Soil_Clay_Orange"
    },
    {
      "x": -7,
      "y": 11,
      "z": 5,
      "name": "Rock_Sandstone_Red"
    },
    {
      "x": -7,
      "y": 12,
      "z": 5,
      "name": "Soil_Clay_Orange"
    },
    {
      "x": -7,
      "y": 13,
      "z": 5,
      "name": "Soil_Clay_Orange"
    },
    {
      "x": -7,
      "y": 14,
      "z": 5,
      "name": "Rock_Sandstone"
    },
    {
      "x": -7,
      "y": 15,
      "z": 5,
      "name": "Soil_Clay_Orange"
    },
    {
      "x": -7,
      "y": 16,
      "z": 5,
      "name": "Rock_Sandstone"
    },
    {
      "x": -7,
      "y": 17,
      "z": 5,
      "name": "Soil_Clay_Yellow"
    },
    {
      "x": -7,
      "y": 18,
      "z": 5,
      "name": "Rock_Sandstone_Red"
    },
    {
      "x": -7,
      "y": 19,
      "z": 5,
      "name": "Rock_Sandstone_Red"
    },
    {
      "x": -7,
      "y": 38,
      "z": 5,
      "name": "Rock_Sandstone_Red"
    },
    {
      "x": -7,
      "y": 39,
      "z": 5,
      "name": "Rock_Sandstone_Red"
    },
    {
      "x": -7,
      "y": 40,
      "z": 5,
      "name": "Rock_Sandstone_Red"
    },
    {
      "x": -7,
      "y": 41,
      "z": 5,
      "name": "Rock_Sandstone_Red"
    },
    {
      "x": -7,
      "y": 42,
      "z": 5,
      "name": "Soil_Clay_Orange"
    },
    {
      "x": -7,
      "y": 43,
      "z": 5,
      "name": "Rock_Sandstone_Red"
    },
    {
      "x": -7,
      "y": 44,
      "z": 5,
      "name": "Rock_Sandstone_Red"
    },
    {
      "x": -7,
      "y": 3,
      "z": 6,
      "name": "Rock_Sandstone_Red"
    },
    {
      "x": -7,
      "y": 4,
      "z": 6,
      "name": "Rock_Sandstone_Red"
    },
    {
      "x": -7,
      "y": 5,
      "z": 6,
      "name": "Rock_Sandstone_Red"
    },
    {
      "x": -7,
      "y": 6,
      "z": 6,
      "name": "Rock_Sandstone_Red"
    },
    {
      "x": -7,
      "y": 7,
      "z": 6,
      "name": "Soil_Clay_Orange"
    },
    {
      "x": -7,
      "y": 8,
      "z": 6,
      "name": "Soil_Clay_Orange"
    },
    {
      "x": -7,
      "y": 9,
      "z": 6,
      "name": "Soil_Clay_Orange"
    },
    {
      "x": -7,
      "y": 10,
      "z": 6,
      "name": "Soil_Clay_Orange"
    },
    {
      "x": -7,
      "y": 11,
      "z": 6,
      "name": "Rock_Sandstone_Red"
    },
    {
      "x": -7,
      "y": 12,
      "z": 6,
      "name": "Soil_Clay_Orange"
    },
    {
      "x": -7,
      "y": 13,
      "z": 6,
      "name": "Soil_Clay_Orange"
    },
    {
      "x": -7,
      "y": 14,
      "z": 6,
      "name": "Rock_Sandstone"
    },
    {
      "x": -7,
      "y": 15,
      "z": 6,
      "name": "Soil_Clay_Orange"
    },
    {
      "x": -7,
      "y": 17,
      "z": 6,
      "name": "Rock_Sandstone_White"
    },
    {
      "x": -7,
      "y": 18,
      "z": 6,
      "name": "Rock_Sandstone"
    },
    {
      "x": -7,
      "y": 19,
      "z": 6,
      "name": "Rock_Sandstone_Red"
    },
    {
      "x": -7,
      "y": 3,
      "z": 7,
      "name": "Rock_Sandstone_Red"
    },
    {
      "x": -7,
      "y": 4,
      "z": 7,
      "name": "Rock_Sandstone_Red"
    },
    {
      "x": -7,
      "y": 5,
      "z": 7,
      "name": "Rock_Sandstone_Red"
    },
    {
      "x": -7,
      "y": 6,
      "z": 7,
      "name": "Rock_Sandstone_Red"
    },
    {
      "x": -7,
      "y": 7,
      "z": 7,
      "name": "Rock_Sandstone_Red"
    },
    {
      "x": -7,
      "y": 8,
      "z": 7,
      "name": "Soil_Clay_Orange"
    },
    {
      "x": -7,
      "y": 9,
      "z": 7,
      "name": "Soil_Clay_Orange"
    },
    {
      "x": -7,
      "y": 10,
      "z": 7,
      "name": "Soil_Clay_Orange"
    },
    {
      "x": -7,
      "y": 11,
      "z": 7,
      "name": "Soil_Clay_Orange"
    },
    {
      "x": -7,
      "y": 12,
      "z": 7,
      "name": "Soil_Clay_Orange"
    },
    {
      "x": -7,
      "y": 13,
      "z": 7,
      "name": "Rock_Sandstone"
    },
    {
      "x": -7,
      "y": 14,
      "z": 7,
      "name": "Rock_Sandstone"
    },
    {
      "x": -7,
      "y": 15,
      "z": 7,
      "name": "Soil_Clay_Orange"
    },
    {
      "x": -7,
      "y": 16,
      "z": 7,
      "name": "Rock_Sandstone"
    },
    {
      "x": -7,
      "y": 18,
      "z": 7,
      "name": "Rock_Sandstone"
    },
    {
      "x": -7,
      "y": 19,
      "z": 7,
      "name": "Rock_Sandstone_Red"
    },
    {
      "x": -6,
      "y": 4,
      "z": -9,
      "name": "Rock_Sandstone_Red"
    },
    {
      "x": -6,
      "y": 5,
      "z": -9,
      "name": "Rock_Sandstone_Red"
    },
    {
      "x": -6,
      "y": 6,
      "z": -9,
      "name": "Rock_Sandstone_Red"
    },
    {
      "x": -6,
      "y": 7,
      "z": -9,
      "name": "Soil_Clay_Orange"
    },
    {
      "x": -6,
      "y": 8,
      "z": -9,
      "name": "Rock_Sandstone"
    },
    {
      "x": -6,
      "y": 9,
      "z": -9,
      "name": "Rock_Sandstone_Red"
    },
    {
      "x": -6,
      "y": 10,
      "z": -9,
      "name": "Rock_Sandstone_Red"
    },
    {
      "x": -6,
      "y": 11,
      "z": -9,
      "name": "Rock_Sandstone_Red"
    },
    {
      "x": -6,
      "y": 12,
      "z": -9,
      "name": "Rock_Sandstone_Red"
    },
    {
      "x": -6,
      "y": 13,
      "z": -9,
      "name": "Rock_Sandstone_Red"
    },
    {
      "x": -6,
      "y": 14,
      "z": -9,
      "name": "Soil_Clay_Orange"
    },
    {
      "x": -6,
      "y": 3,
      "z": -8,
      "name": "Rock_Sandstone_Red"
    },
    {
      "x": -6,
      "y": 4,
      "z": -8,
      "name": "Rock_Sandstone_Red"
    },
    {
      "x": -6,
      "y": 5,
      "z": -8,
      "name": "Rock_Sandstone_Red"
    },
    {
      "x": -6,
      "y": 6,
      "z": -8,
      "name": "Rock_Sandstone_Red"
    },
    {
      "x": -6,
      "y": 7,
      "z": -8,
      "name": "Soil_Clay_Orange"
    },
    {
      "x": -6,
      "y": 8,
      "z": -8,
      "name": "Rock_Sandstone"
    },
    {
      "x": -6,
      "y": 9,
      "z": -8,
      "name": "Rock_Sandstone_Red"
    },
    {
      "x": -6,
      "y": 10,
      "z": -8,
      "name": "Rock_Sandstone_Red"
    },
    {
      "x": -6,
      "y": 11,
      "z": -8,
      "name": "Rock_Sandstone_Red"
    },
    {
      "x": -6,
      "y": 12,
      "z": -8,
      "name": "Rock_Sandstone_Red"
    },
    {
      "x": -6,
      "y": 13,
      "z": -8,
      "name": "Rock_Sandstone_Red"
    },
    {
      "x": -6,
      "y": 14,
      "z": -8,
      "name": "Soil_Clay_Smooth_Red"
    },
    {
      "x": -6,
      "y": 20,
      "z": -8,
      "name": "Rock_Sandstone_Red"
    },
    {
      "x": -6,
      "y": 21,
      "z": -8,
      "name": "Soil_Clay_Smooth_Red"
    },
    {
      "x": -6,
      "y": 3,
      "z": -7,
      "name": "Rock_Sandstone_Red"
    },
    {
      "x": -6,
      "y": 4,
      "z": -7,
      "name": "Rock_Sandstone_Red"
    },
    {
      "x": -6,
      "y": 5,
      "z": -7,
      "name": "Rock_Sandstone_Red"
    },
    {
      "x": -6,
      "y": 6,
      "z": -7,
      "name": "Rock_Sandstone_Red"
    },
    {
      "x": -6,
      "y": 7,
      "z": -7,
      "name": "Rock_Sandstone_Red"
    },
    {
      "x": -6,
      "y": 8,
      "z": -7,
      "name": "Soil_Clay_Orange"
    },
    {
      "x": -6,
      "y": 9,
      "z": -7,
      "name": "Rock_Sandstone_Red"
    },
    {
      "x": -6,
      "y": 10,
      "z": -7,
      "name": "Rock_Sandstone_Red"
    },
    {
      "x": -6,
      "y": 11,
      "z": -7,
      "name": "Rock_Sandstone_Red"
    },
    {
      "x": -6,
      "y": 12,
      "z": -7,
      "name": "Rock_Sandstone_Red"
    },
    {
      "x": -6,
      "y": 13,
      "z": -7,
      "name": "Rock_Sandstone_Red"
    },
    {
      "x": -6,
      "y": 14,
      "z": -7,
      "name": "Soil_Clay_Orange"
    },
    {
      "x": -6,
      "y": 15,
      "z": -7,
      "name": "Soil_Clay_Smooth_Red"
    },
    {
      "x": -6,
      "y": 19,
      "z": -7,
      "name": "Soil_Clay_Orange"
    },
    {
      "x": -6,
      "y": 20,
      "z": -7,
      "name": "Rock_Sandstone_Red"
    },
    {
      "x": -6,
      "y": 21,
      "z": -7,
      "name": "Soil_Clay_Smooth_Red"
    },
    {
      "x": -6,
      "y": 2,
      "z": -6,
      "name": "Rock_Sandstone_Red"
    },
    {
      "x": -6,
      "y": 3,
      "z": -6,
      "name": "Rock_Sandstone_Red"
    },
    {
      "x": -6,
      "y": 4,
      "z": -6,
      "name": "Rock_Sandstone_Red"
    },
    {
      "x": -6,
      "y": 5,
      "z": -6,
      "name": "Rock_Sandstone_Red"
    },
    {
      "x": -6,
      "y": 6,
      "z": -6,
      "name": "Rock_Sandstone_Red"
    },
    {
      "x": -6,
      "y": 7,
      "z": -6,
      "name": "Rock_Sandstone_Red"
    },
    {
      "x": -6,
      "y": 8,
      "z": -6,
      "name": "Rock_Sandstone_Red"
    },
    {
      "x": -6,
      "y": 9,
      "z": -6,
      "name": "Rock_Sandstone_Red"
    },
    {
      "x": -6,
      "y": 10,
      "z": -6,
      "name": "Rock_Sandstone_Red"
    },
    {
      "x": -6,
      "y": 11,
      "z": -6,
      "name": "Rock_Sandstone_Red"
    },
    {
      "x": -6,
      "y": 12,
      "z": -6,
      "name": "Rock_Sandstone_Red"
    },
    {
      "x": -6,
      "y": 13,
      "z": -6,
      "name": "Rock_Sandstone_Red"
    },
    {
      "x": -6,
      "y": 14,
      "z": -6,
      "name": "Soil_Clay_Orange"
    },
    {
      "x": -6,
      "y": 15,
      "z": -6,
      "name": "Soil_Clay_Smooth_Red"
    },
    {
      "x": -6,
      "y": 19,
      "z": -6,
      "name": "Soil_Clay_Orange"
    },
    {
      "x": -6,
      "y": 20,
      "z": -6,
      "name": "Rock_Sandstone_Red"
    },
    {
      "x": -6,
      "y": 21,
      "z": -6,
      "name": "Soil_Clay_Smooth_Red"
    },
    {
      "x": -6,
      "y": 2,
      "z": -5,
      "name": "Rock_Sandstone_Red"
    },
    {
      "x": -6,
      "y": 3,
      "z": -5,
      "name": "Rock_Sandstone_Red"
    },
    {
      "x": -6,
      "y": 4,
      "z": -5,
      "name": "Rock_Sandstone_Red"
    },
    {
      "x": -6,
      "y": 5,
      "z": -5,
      "name": "Rock_Sandstone_Red"
    },
    {
      "x": -6,
      "y": 6,
      "z": -5,
      "name": "Rock_Sandstone_Red"
    },
    {
      "x": -6,
      "y": 7,
      "z": -5,
      "name": "Rock_Sandstone_Red"
    },
    {
      "x": -6,
      "y": 8,
      "z": -5,
      "name": "Rock_Sandstone_Red"
    },
    {
      "x": -6,
      "y": 9,
      "z": -5,
      "name": "Rock_Sandstone_Red"
    },
    {
      "x": -6,
      "y": 10,
      "z": -5,
      "name": "Rock_Sandstone_Red"
    },
    {
      "x": -6,
      "y": 11,
      "z": -5,
      "name": "Rock_Sandstone_Red"
    },
    {
      "x": -6,
      "y": 12,
      "z": -5,
      "name": "Rock_Sandstone_Red"
    },
    {
      "x": -6,
      "y": 13,
      "z": -5,
      "name": "Rock_Sandstone_Red"
    },
    {
      "x": -6,
      "y": 14,
      "z": -5,
      "name": "Soil_Clay_Orange"
    },
    {
      "x": -6,
      "y": 15,
      "z": -5,
      "name": "Soil_Clay_Smooth_Red"
    },
    {
      "x": -6,
      "y": 19,
      "z": -5,
      "name": "Rock_Sandstone_Red"
    },
    {
      "x": -6,
      "y": 20,
      "z": -5,
      "name": "Rock_Sandstone_Red"
    },
    {
      "x": -6,
      "y": 21,
      "z": -5,
      "name": "Soil_Clay_Smooth_Red"
    },
    {
      "x": -6,
      "y": 1,
      "z": -4,
      "name": "Soil_Clay_Orange"
    },
    {
      "x": -6,
      "y": 2,
      "z": -4,
      "name": "Rock_Sandstone_Red"
    },
    {
      "x": -6,
      "y": 3,
      "z": -4,
      "name": "Rock_Sandstone_Red"
    },
    {
      "x": -6,
      "y": 4,
      "z": -4,
      "name": "Rock_Sandstone_Red"
    },
    {
      "x": -6,
      "y": 5,
      "z": -4,
      "name": "Rock_Sandstone_Red"
    },
    {
      "x": -6,
      "y": 6,
      "z": -4,
      "name": "Rock_Sandstone_Red"
    },
    {
      "x": -6,
      "y": 7,
      "z": -4,
      "name": "Rock_Sandstone_Red"
    },
    {
      "x": -6,
      "y": 8,
      "z": -4,
      "name": "Rock_Sandstone_Red"
    },
    {
      "x": -6,
      "y": 9,
      "z": -4,
      "name": "Rock_Sandstone_Red"
    },
    {
      "x": -6,
      "y": 10,
      "z": -4,
      "name": "Rock_Sandstone_Red"
    },
    {
      "x": -6,
      "y": 11,
      "z": -4,
      "name": "Rock_Sandstone_Red"
    },
    {
      "x": -6,
      "y": 12,
      "z": -4,
      "name": "Rock_Sandstone_Red"
    },
    {
      "x": -6,
      "y": 13,
      "z": -4,
      "name": "Rock_Sandstone_Red"
    },
    {
      "x": -6,
      "y": 14,
      "z": -4,
      "name": "Soil_Clay_Orange"
    },
    {
      "x": -6,
      "y": 15,
      "z": -4,
      "name": "Soil_Clay_Smooth_Red"
    },
    {
      "x": -6,
      "y": 19,
      "z": -4,
      "name": "Rock_Sandstone_Red"
    },
    {
      "x": -6,
      "y": 20,
      "z": -4,
      "name": "Rock_Sandstone_Red"
    },
    {
      "x": -6,
      "y": 21,
      "z": -4,
      "name": "Soil_Clay_Smooth_Red"
    },
    {
      "x": -6,
      "y": 1,
      "z": -3,
      "name": "Soil_Clay_Orange"
    },
    {
      "x": -6,
      "y": 2,
      "z": -3,
      "name": "Rock_Sandstone_Red"
    },
    {
      "x": -6,
      "y": 3,
      "z": -3,
      "name": "Rock_Sandstone_Red"
    },
    {
      "x": -6,
      "y": 4,
      "z": -3,
      "name": "Rock_Sandstone_Red"
    },
    {
      "x": -6,
      "y": 5,
      "z": -3,
      "name": "Rock_Sandstone_Red"
    },
    {
      "x": -6,
      "y": 6,
      "z": -3,
      "name": "Rock_Sandstone_Red"
    },
    {
      "x": -6,
      "y": 7,
      "z": -3,
      "name": "Rock_Sandstone_Red"
    },
    {
      "x": -6,
      "y": 8,
      "z": -3,
      "name": "Soil_Clay_Orange"
    },
    {
      "x": -6,
      "y": 9,
      "z": -3,
      "name": "Rock_Sandstone_Red"
    },
    {
      "x": -6,
      "y": 10,
      "z": -3,
      "name": "Rock_Sandstone_Red"
    },
    {
      "x": -6,
      "y": 11,
      "z": -3,
      "name": "Rock_Sandstone_Red"
    },
    {
      "x": -6,
      "y": 12,
      "z": -3,
      "name": "Rock_Sandstone_Red"
    },
    {
      "x": -6,
      "y": 13,
      "z": -3,
      "name": "Rock_Sandstone_Red"
    },
    {
      "x": -6,
      "y": 14,
      "z": -3,
      "name": "Soil_Clay_Orange"
    },
    {
      "x": -6,
      "y": 15,
      "z": -3,
      "name": "Soil_Clay_Smooth_Red"
    },
    {
      "x": -6,
      "y": 19,
      "z": -3,
      "name": "Rock_Sandstone_Red"
    },
    {
      "x": -6,
      "y": 20,
      "z": -3,
      "name": "Rock_Sandstone_Red"
    },
    {
      "x": -6,
      "y": 21,
      "z": -3,
      "name": "Soil_Clay_Smooth_Red"
    },
    {
      "x": -6,
      "y": 1,
      "z": -2,
      "name": "Soil_Clay_Orange"
    },
    {
      "x": -6,
      "y": 2,
      "z": -2,
      "name": "Rock_Sandstone_Red"
    },
    {
      "x": -6,
      "y": 3,
      "z": -2,
      "name": "Rock_Sandstone_Red"
    },
    {
      "x": -6,
      "y": 4,
      "z": -2,
      "name": "Rock_Sandstone_Red"
    },
    {
      "x": -6,
      "y": 5,
      "z": -2,
      "name": "Rock_Sandstone_Red"
    },
    {
      "x": -6,
      "y": 6,
      "z": -2,
      "name": "Rock_Sandstone_Red"
    },
    {
      "x": -6,
      "y": 7,
      "z": -2,
      "name": "Soil_Clay_Orange"
    },
    {
      "x": -6,
      "y": 8,
      "z": -2,
      "name": "Soil_Clay_Orange"
    },
    {
      "x": -6,
      "y": 9,
      "z": -2,
      "name": "Rock_Sandstone_Red"
    },
    {
      "x": -6,
      "y": 10,
      "z": -2,
      "name": "Rock_Sandstone_Red"
    },
    {
      "x": -6,
      "y": 11,
      "z": -2,
      "name": "Rock_Sandstone_Red"
    },
    {
      "x": -6,
      "y": 12,
      "z": -2,
      "name": "Rock_Sandstone_Red"
    },
    {
      "x": -6,
      "y": 13,
      "z": -2,
      "name": "Rock_Sandstone_Red"
    },
    {
      "x": -6,
      "y": 14,
      "z": -2,
      "name": "Soil_Clay_Orange"
    },
    {
      "x": -6,
      "y": 15,
      "z": -2,
      "name": "Soil_Clay_Smooth_Red"
    },
    {
      "x": -6,
      "y": 19,
      "z": -2,
      "name": "Rock_Sandstone_Red"
    },
    {
      "x": -6,
      "y": 20,
      "z": -2,
      "name": "Rock_Sandstone_Red"
    },
    {
      "x": -6,
      "y": 21,
      "z": -2,
      "name": "Soil_Clay_Smooth_Red"
    },
    {
      "x": -6,
      "y": 1,
      "z": -1,
      "name": "Soil_Clay_Orange"
    },
    {
      "x": -6,
      "y": 2,
      "z": -1,
      "name": "Rock_Sandstone_Red"
    },
    {
      "x": -6,
      "y": 3,
      "z": -1,
      "name": "Rock_Sandstone_Red"
    },
    {
      "x": -6,
      "y": 4,
      "z": -1,
      "name": "Rock_Sandstone_Red"
    },
    {
      "x": -6,
      "y": 5,
      "z": -1,
      "name": "Rock_Sandstone_Red"
    },
    {
      "x": -6,
      "y": 6,
      "z": -1,
      "name": "Rock_Sandstone_Red"
    },
    {
      "x": -6,
      "y": 7,
      "z": -1,
      "name": "Soil_Clay_Orange"
    },
    {
      "x": -6,
      "y": 8,
      "z": -1,
      "name": "Soil_Clay_Orange"
    },
    {
      "x": -6,
      "y": 9,
      "z": -1,
      "name": "Rock_Sandstone_Red"
    },
    {
      "x": -6,
      "y": 10,
      "z": -1,
      "name": "Rock_Sandstone_Red"
    },
    {
      "x": -6,
      "y": 11,
      "z": -1,
      "name": "Rock_Sandstone_Red"
    },
    {
      "x": -6,
      "y": 12,
      "z": -1,
      "name": "Rock_Sandstone_Red"
    },
    {
      "x": -6,
      "y": 13,
      "z": -1,
      "name": "Rock_Sandstone_Red"
    },
    {
      "x": -6,
      "y": 14,
      "z": -1,
      "name": "Soil_Clay_Orange"
    },
    {
      "x": -6,
      "y": 15,
      "z": -1,
      "name": "Soil_Clay_Smooth_Red"
    },
    {
      "x": -6,
      "y": 18,
      "z": -1,
      "name": "Soil_Clay_Orange"
    },
    {
      "x": -6,
      "y": 19,
      "z": -1,
      "name": "Soil_Clay_Orange"
    },
    {
      "x": -6,
      "y": 20,
      "z": -1,
      "name": "Rock_Sandstone_Red"
    },
    {
      "x": -6,
      "y": 21,
      "z": -1,
      "name": "Soil_Clay_Smooth_Red"
    },
    {
      "x": -6,
      "y": 1,
      "z": 0,
      "name": "Soil_Clay_Orange"
    },
    {
      "x": -6,
      "y": 2,
      "z": 0,
      "name": "Rock_Sandstone_Red"
    },
    {
      "x": -6,
      "y": 3,
      "z": 0,
      "name": "Rock_Sandstone_Red"
    },
    {
      "x": -6,
      "y": 4,
      "z": 0,
      "name": "Rock_Sandstone_Red"
    },
    {
      "x": -6,
      "y": 5,
      "z": 0,
      "name": "Rock_Sandstone_Red"
    },
    {
      "x": -6,
      "y": 6,
      "z": 0,
      "name": "Rock_Sandstone_Red"
    },
    {
      "x": -6,
      "y": 7,
      "z": 0,
      "name": "Soil_Clay_Orange"
    },
    {
      "x": -6,
      "y": 8,
      "z": 0,
      "name": "Soil_Clay_Orange"
    },
    {
      "x": -6,
      "y": 9,
      "z": 0,
      "name": "Rock_Sandstone_Red"
    },
    {
      "x": -6,
      "y": 10,
      "z": 0,
      "name": "Rock_Sandstone_Red"
    },
    {
      "x": -6,
      "y": 11,
      "z": 0,
      "name": "Rock_Sandstone_Red"
    },
    {
      "x": -6,
      "y": 12,
      "z": 0,
      "name": "Rock_Sandstone_Red"
    },
    {
      "x": -6,
      "y": 13,
      "z": 0,
      "name": "Rock_Sandstone_Red"
    },
    {
      "x": -6,
      "y": 14,
      "z": 0,
      "name": "Soil_Clay_Orange"
    },
    {
      "x": -6,
      "y": 15,
      "z": 0,
      "name": "Soil_Clay_Smooth_Red"
    },
    {
      "x": -6,
      "y": 17,
      "z": 0,
      "name": "Rock_Sandstone"
    },
    {
      "x": -6,
      "y": 18,
      "z": 0,
      "name": "Soil_Clay_Orange"
    },
    {
      "x": -6,
      "y": 19,
      "z": 0,
      "name": "Soil_Clay_Orange"
    },
    {
      "x": -6,
      "y": 20,
      "z": 0,
      "name": "Soil_Clay_Orange"
    },
    {
      "x": -6,
      "y": 21,
      "z": 0,
      "name": "Soil_Clay_Smooth_Red"
    },
    {
      "x": -6,
      "y": 1,
      "z": 1,
      "name": "Soil_Clay_Orange"
    },
    {
      "x": -6,
      "y": 2,
      "z": 1,
      "name": "Rock_Sandstone_Red"
    },
    {
      "x": -6,
      "y": 3,
      "z": 1,
      "name": "Rock_Sandstone_Red"
    },
    {
      "x": -6,
      "y": 4,
      "z": 1,
      "name": "Rock_Sandstone_Red"
    },
    {
      "x": -6,
      "y": 5,
      "z": 1,
      "name": "Rock_Sandstone_Red"
    },
    {
      "x": -6,
      "y": 6,
      "z": 1,
      "name": "Rock_Sandstone_Red"
    },
    {
      "x": -6,
      "y": 7,
      "z": 1,
      "name": "Soil_Clay_Orange"
    },
    {
      "x": -6,
      "y": 8,
      "z": 1,
      "name": "Soil_Clay_Orange"
    },
    {
      "x": -6,
      "y": 9,
      "z": 1,
      "name": "Rock_Sandstone_Red"
    },
    {
      "x": -6,
      "y": 10,
      "z": 1,
      "name": "Rock_Sandstone_Red"
    },
    {
      "x": -6,
      "y": 11,
      "z": 1,
      "name": "Rock_Sandstone_Red"
    },
    {
      "x": -6,
      "y": 12,
      "z": 1,
      "name": "Rock_Sandstone_Red"
    },
    {
      "x": -6,
      "y": 13,
      "z": 1,
      "name": "Rock_Sandstone_Red"
    },
    {
      "x": -6,
      "y": 14,
      "z": 1,
      "name": "Soil_Clay_Orange"
    },
    {
      "x": -6,
      "y": 15,
      "z": 1,
      "name": "Soil_Clay_Smooth_Red"
    },
    {
      "x": -6,
      "y": 17,
      "z": 1,
      "name": "Soil_Clay_Yellow"
    },
    {
      "x": -6,
      "y": 18,
      "z": 1,
      "name": "Soil_Clay_Orange"
    },
    {
      "x": -6,
      "y": 19,
      "z": 1,
      "name": "Soil_Clay_Orange"
    },
    {
      "x": -6,
      "y": 20,
      "z": 1,
      "name": "Soil_Clay_Orange"
    },
    {
      "x": -6,
      "y": 21,
      "z": 1,
      "name": "Soil_Clay_Smooth_Red"
    },
    {
      "x": -6,
      "y": 1,
      "z": 2,
      "name": "Soil_Clay_Orange"
    },
    {
      "x": -6,
      "y": 2,
      "z": 2,
      "name": "Soil_Clay_Orange"
    },
    {
      "x": -6,
      "y": 3,
      "z": 2,
      "name": "Rock_Sandstone_Red"
    },
    {
      "x": -6,
      "y": 4,
      "z": 2,
      "name": "Rock_Sandstone_Red"
    },
    {
      "x": -6,
      "y": 5,
      "z": 2,
      "name": "Rock_Sandstone_Red"
    },
    {
      "x": -6,
      "y": 6,
      "z": 2,
      "name": "Rock_Sandstone_Red"
    },
    {
      "x": -6,
      "y": 7,
      "z": 2,
      "name": "Soil_Clay_Orange"
    },
    {
      "x": -6,
      "y": 8,
      "z": 2,
      "name": "Soil_Clay_Orange"
    },
    {
      "x": -6,
      "y": 9,
      "z": 2,
      "name": "Soil_Clay_Orange"
    },
    {
      "x": -6,
      "y": 10,
      "z": 2,
      "name": "Rock_Sandstone_Red"
    },
    {
      "x": -6,
      "y": 11,
      "z": 2,
      "name": "Rock_Sandstone_Red"
    },
    {
      "x": -6,
      "y": 12,
      "z": 2,
      "name": "Rock_Sandstone_Red"
    },
    {
      "x": -6,
      "y": 13,
      "z": 2,
      "name": "Rock_Sandstone_Red"
    },
    {
      "x": -6,
      "y": 14,
      "z": 2,
      "name": "Soil_Clay_Orange"
    },
    {
      "x": -6,
      "y": 15,
      "z": 2,
      "name": "Soil_Clay_Smooth_Red"
    },
    {
      "x": -6,
      "y": 20,
      "z": 2,
      "name": "Soil_Clay_Orange"
    },
    {
      "x": -6,
      "y": 21,
      "z": 2,
      "name": "Soil_Clay_Smooth_Red"
    },
    {
      "x": -6,
      "y": 2,
      "z": 3,
      "name": "Soil_Clay_Orange"
    },
    {
      "x": -6,
      "y": 3,
      "z": 3,
      "name": "Rock_Sandstone_Red"
    },
    {
