{
  "version": 8,
  "blockIdVersion": 10,
  "anchorX": 0,
  "anchorY": 0,
  "anchorZ": 0,
  "blocks": [
    {
      "x": -9,
      "y": 9,
      "z": -5,
      "name": "Soil_Clay_Orange"
    },
    {
      "x": -9,
      "y": 10,
      "z": -5,
      "name": "Soil_Clay_Orange"
    },
    {
      "x": -9,
      "y": 11,
      "z": -5,
      "name": "Soil_Clay_Orange"
    },
    {
      "x": -9,
      "y": 12,
      "z": -5,
      "name": "Rock_Sandstone_Red"
    },
    {
      "x": -9,
      "y": 13,
      "z": -5,
      "name": "Rock_Sandstone_Red"
    },
    {
      "x": -9,
      "y": 9,
      "z": -4,
      "name": "Soil_Clay_Orange"
    },
    {
      "x": -9,
      "y": 10,
      "z": -4,
      "name": "Soil_Clay_Orange"
    },
    {
      "x": -9,
      "y": 11,
      "z": -4,
      "name": "Soil_Clay_Orange"
    },
    {
      "x": -9,
      "y": 12,
      "z": -4,
      "name": "Rock_Sandstone_Red"
    },
    {
      "x": -9,
      "y": 13,
      "z": -4,
      "name": "Rock_Sandstone_Red"
    },
    {
      "x": -9,
      "y": 9,
      "z": -3,
      "name": "Soil_Clay_Orange"
    },
    {
      "x": -9,
      "y": 10,
      "z": -3,
      "name": "Soil_Clay_Orange"
    },
    {
      "x": -9,
      "y": 11,
      "z": -3,
      "name": "Rock_Sandstone_Red"
    },
    {
      "x": -9,
      "y": 12,
      "z": -3,
      "name": "Rock_Sandstone_Red"
    },
    {
      "x": -9,
      "y": 13,
      "z": -3,
      "name": "Rock_Sandstone_Red"
    },
    {
      "x": -9,
      "y": 9,
      "z": -2,
      "name": "Soil_Clay_Orange"
    },
    {
      "x": -9,
      "y": 10,
      "z": -2,
      "name": "Rock_Sandstone"
    },
    {
      "x": -9,
      "y": 11,
      "z": -2,
      "name": "Rock_Sandstone_Red"
    },
    {
      "x": -9,
      "y": 12,
      "z": -2,
      "name": "Rock_Sandstone_Red"
    },
    {
      "x": -9,
      "y": 13,
      "z": -2,
      "name": "Rock_Sandstone_Red"
    },
    {
      "x": -9,
      "y": 14,
      "z": -2,
      "name": "Rock_Sandstone"
    },
    {
      "x": -9,
      "y": 9,
      "z": -1,
      "name": "Soil_Clay_Orange"
    },
    {
      "x": -9,
      "y": 10,
      "z": -1,
      "name": "Rock_Sandstone"
    },
    {
      "x": -9,
      "y": 11,
      "z": -1,
      "name": "Rock_Sandstone_Red"
    },
    {
      "x": -9,
      "y": 12,
      "z": -1,
      "name": "Rock_Sandstone_Red"
    },
    {
      "x": -9,
      "y": 13,
      "z": -1,
      "name": "Rock_Sandstone_Red"
    },
    {
      "x": -9,
      "y": 14,
      "z": -1,
      "name": "Rock_Sandstone"
    },
    {
      "x": -9,
      "y": 31,
      "z": 3,
      "name": "Rock_Sandstone_Red"
    },
    {
      "x": -9,
      "y": 32,
      "z": 3,
      "name": "Soil_Clay_Orange"
    },
    {
      "x": -9,
      "y": 33,
      "z": 3,
      "name": "Soil_Clay_Orange"
    },
    {
      "x": -9,
      "y": 34,
      "z": 3,
      "name": "Rock_Sandstone"
    },
    {
      "x": -9,
      "y": 35,
      "z": 3,
      "name": "Rock_Sandstone_Red"
    },
    {
      "x": -9,
      "y": 36,
      "z": 3,
      "name": "Rock_Sandstone_Red"
    },
    {
      "x": -9,
      "y": 37,
      "z": 3,
      "name": "Rock_Sandstone"
    },
    {
      "x": -9,
      "y": 38,
      "z": 3,
      "name": "Rock_Sandstone_Red"
    },
    {
      "x": -9,
      "y": 39,
      "z": 3,
      "name": "Rock_Sandstone_Red"
    },
    {
      "x": -9,
      "y": 40,
      "z": 3,
      "name": "Rock_Sandstone_Red"
    },
    {
      "x": -9,
      "y": 41,
      "z": 3,
      "name": "Rock_Sandstone_Red"
    },
    {
      "x": -9,
      "y": 42,
      "z": 3,
      "name": "Rock_Sandstone_Red"
    },
    {
      "x": -9,
      "y": 43,
      "z": 3,
      "name": "Rock_Sandstone_Red"
    },
    {
      "x": -9,
      "y": 44,
      "z": 3,
      "name": "Rock_Sandstone_Red"
    },
    {
      "x": -9,
      "y": 45,
      "z": 3,
      "name": "Rock_Sandstone_Red"
    },
    {
      "x": -9,
      "y": 46,
      "z": 3,
      "name": "Rock_Sandstone_Red"
    },
    {
      "x": -9,
      "y": 47,
      "z": 3,
      "name": "Rock_Sandstone_Red"
    },
    {
      "x": -9,
      "y": 48,
      "z": 3,
      "name": "Rock_Sandstone_Red"
    },
    {
      "x": -9,
      "y": 30,
      "z": 4,
      "name": "Rock_Sandstone_Red"
    },
    {
      "x": -9,
      "y": 31,
      "z": 4,
      "name": "Rock_Sandstone_Red"
    },
    {
      "x": -9,
      "y": 32,
      "z": 4,
      "name": "Soil_Clay_Orange"
    },
    {
      "x": -9,
      "y": 33,
      "z": 4,
      "name": "Soil_Clay_Orange"
    },
    {
      "x": -9,
      "y": 34,
      "z": 4,
      "name": "Rock_Sandstone"
    },
    {
      "x": -9,
      "y": 35,
      "z": 4,
      "name": "Rock_Sandstone_Red"
    },
    {
      "x": -9,
      "y": 36,
      "z": 4,
      "name": "Rock_Sandstone_Red"
    },
    {
      "x": -9,
      "y": 37,
      "z": 4,
      "name": "Rock_Sandstone"
    },
    {
      "x": -9,
      "y": 38,
      "z": 4,
      "name": "Soil_Clay_Orange"
    },
    {
      "x": -9,
      "y": 39,
      "z": 4,
      "name": "Rock_Sandstone_Red"
    },
    {
      "x": -9,
      "y": 40,
      "z": 4,
      "name": "Soil_Clay_Orange"
    },
    {
      "x": -9,
      "y": 41,
      "z": 4,
      "name": "Rock_Sandstone_Red"
    },
    {
      "x": -9,
      "y": 42,
      "z": 4,
      "name": "Rock_Sandstone_Red"
    },
    {
      "x": -9,
      "y": 43,
      "z": 4,
      "name": "Rock_Sandstone_Red"
    },
    {
      "x": -9,
      "y": 44,
      "z": 4,
      "name": "Rock_Sandstone_Red"
    },
    {
      "x": -9,
      "y": 45,
      "z": 4,
      "name": "Rock_Sandstone_Red"
    },
    {
      "x": -9,
      "y": 46,
      "z": 4,
      "name": "Rock_Sandstone_Red"
    },
    {
      "x": -9,
      "y": 47,
      "z": 4,
      "name": "Rock_Sandstone_Red"
    },
    {
      "x": -9,
      "y": 48,
      "z": 4,
      "name": "Rock_Sandstone_Red"
    },
    {
      "x": -9,
      "y": 31,
      "z": 5,
      "name": "Rock_Sandstone_Red"
    },
    {
      "x": -9,
      "y": 32,
      "z": 5,
      "name": "Soil_Clay_Orange"
    },
    {
      "x": -9,
      "y": 33,
      "z": 5,
      "name": "Soil_Clay_Orange"
    },
    {
      "x": -9,
      "y": 34,
      "z": 5,
      "name": "Rock_Sandstone"
    },
    {
      "x": -9,
      "y": 35,
      "z": 5,
      "name": "Rock_Sandstone_Red"
    },
    {
      "x": -9,
      "y": 36,
      "z": 5,
      "name": "Rock_Sandstone_Red"
    },
    {
      "x": -9,
      "y": 37,
      "z": 5,
      "name": "Rock_Sandstone"
    },
    {
      "x": -9,
      "y": 38,
      "z": 5,
      "name": "Soil_Clay_Orange"
    },
    {
      "x": -9,
      "y": 39,
      "z": 5,
      "name": "Soil_Clay_Orange"
    },
    {
      "x": -9,
      "y": 40,
      "z": 5,
      "name": "Soil_Clay_Orange"
    },
    {
      "x": -9,
      "y": 41,
      "z": 5,
      "name": "Rock_Sandstone_Red"
    },
    {
      "x": -9,
      "y": 42,
      "z": 5,
      "name": "Rock_Sandstone_Red"
    },
    {
      "x": -9,
      "y": 43,
      "z": 5,
      "name": "Rock_Sandstone_Red"
    },
    {
      "x": -9,
      "y": 44,
      "z": 5,
      "name": "Rock_Sandstone_Red"
    },
    {
      "x": -9,
      "y": 45,
      "z": 5,
      "name": "Rock_Sandstone_Red"
    },
    {
      "x": -9,
      "y": 46,
      "z": 5,
      "name": "Rock_Sandstone_Red"
    },
    {
      "x": -9,
      "y": 47,
      "z": 5,
      "name": "Rock_Sandstone_Red"
    },
    {
      "x": -9,
      "y": 48,
      "z": 5,
      "name": "Rock_Sandstone_Red"
    },
    {
      "x": -9,
      "y": 49,
      "z": 5,
      "name": "Soil_Clay_Smooth_Red"
    },
    {
      "x": -9,
      "y": 31,
      "z": 6,
      "name": "Soil_Clay_Orange"
    },
    {
      "x": -9,
      "y": 32,
      "z": 6,
      "name": "Soil_Clay_Orange"
    },
    {
      "x": -9,
      "y": 33,
      "z": 6,
      "name": "Soil_Clay_Orange"
    },
    {
      "x": -9,
      "y": 34,
      "z": 6,
      "name": "Rock_Sandstone"
    },
    {
      "x": -9,
      "y": 35,
      "z": 6,
      "name": "Rock_Sandstone_Red"
    },
    {
      "x": -9,
      "y": 36,
      "z": 6,
      "name": "Rock_Sandstone_Red"
    },
    {
      "x": -9,
      "y": 37,
      "z": 6,
      "name": "Rock_Sandstone"
    },
    {
      "x": -9,
      "y": 38,
      "z": 6,
      "name": "Soil_Clay_Orange"
    },
    {
      "x": -9,
      "y": 39,
      "z": 6,
      "name": "Soil_Clay_Orange"
    },
    {
      "x": -9,
      "y": 40,
      "z": 6,
      "name": "Soil_Clay_Orange"
    },
    {
      "x": -9,
      "y": 41,
      "z": 6,
      "name": "Soil_Clay_Orange"
    },
    {
      "x": -9,
      "y": 42,
      "z": 6,
      "name": "Rock_Sandstone_Red"
    },
    {
      "x": -9,
      "y": 43,
      "z": 6,
      "name": "Rock_Sandstone_Red"
    },
    {
      "x": -9,
      "y": 44,
      "z": 6,
      "name": "Rock_Sandstone_Red"
    },
    {
      "x": -9,
      "y": 45,
      "z": 6,
      "name": "Rock_Sandstone_Red"
    },
    {
      "x": -9,
      "y": 46,
      "z": 6,
      "name": "Rock_Sandstone_Red"
    },
    {
      "x": -9,
      "y": 47,
      "z": 6,
      "name": "Rock_Sandstone_Red"
    },
    {
      "x": -9,
      "y": 48,
      "z": 6,
      "name": "Soil_Clay_Smooth_Red"
    },
    {
      "x": -9,
      "y": 32,
      "z": 7,
      "name": "Soil_Clay_Orange"
    },
    {
      "x": -9,
      "y": 33,
      "z": 7,
      "name": "Soil_Clay_Orange"
    },
    {
      "x": -9,
      "y": 34,
      "z": 7,
      "name": "Rock_Sandstone"
    },
    {
      "x": -9,
      "y": 35,
      "z": 7,
      "name": "Rock_Sandstone_Red"
    },
    {
      "x": -9,
      "y": 36,
      "z": 7,
      "name": "Rock_Sandstone_Red"
    },
    {
      "x": -9,
      "y": 37,
      "z": 7,
      "name": "Rock_Sandstone"
    },
    {
      "x": -9,
      "y": 38,
      "z": 7,
      "name": "Soil_Clay_Orange"
    },
    {
      "x": -9,
      "y": 39,
      "z": 7,
      "name": "Soil_Clay_Orange"
    },
    {
      "x": -9,
      "y": 41,
      "z": 7,
      "name": "Soil_Clay_Orange"
    },
    {
      "x": -9,
      "y": 42,
      "z": 7,
      "name": "Soil_Clay_Orange"
    },
    {
      "x": -9,
      "y": 43,
      "z": 7,
      "name": "Soil_Clay_Orange"
    },
    {
      "x": -9,
      "y": 44,
      "z": 7,
      "name": "Rock_Sandstone_Red"
    },
    {
      "x": -9,
      "y": 45,
      "z": 7,
      "name": "Rock_Sandstone_Red"
    },
    {
      "x": -9,
      "y": 46,
      "z": 7,
      "name": "Rock_Sandstone_Red"
    },
    {
      "x": -9,
      "y": 47,
      "z": 7,
      "name": "Rock_Sandstone_Red"
    },
    {
      "x": -9,
      "y": 48,
      "z": 7,
      "name": "Rock_Sandstone_Red"
    },
    {
      "x": -8,
      "y": 9,
      "z": -6,
      "name": "Rock_Sandstone"
    },
    {
      "x": -8,
      "y": 10,
      "z": -6,
      "name": "Soil_Clay_Orange"
    },
    {
      "x": -8,
      "y": 11,
      "z": -6,
      "name": "Soil_Clay_Orange"
    },
    {
      "x": -8,
      "y": 12,
      "z": -6,
      "name": "Soil_Clay_Orange"
    },
    {
      "x": -8,
      "y": 13,
      "z": -6,
      "name": "Soil_Clay_Orange"
    },
    {
      "x": -8,
      "y": 9,
      "z": -5,
      "name": "Soil_Clay_Orange"
    },
    {
      "x": -8,
      "y": 10,
      "z": -5,
      "name": "Soil_Clay_Orange"
    },
    {
      "x": -8,
      "y": 11,
      "z": -5,
      "name": "Soil_Clay_Orange"
    },
    {
      "x": -8,
      "y": 12,
      "z": -5,
      "name": "Soil_Clay_Orange"
    },
    {
      "x": -8,
      "y": 13,
      "z": -5,
      "name": "Rock_Sandstone_Red"
    },
    {
      "x": -8,
      "y": 14,
      "z": -5,
      "name": "Rock_Sandstone"
    },
    {
      "x": -8,
      "y": 9,
      "z": -4,
      "name": "Soil_Clay_Orange"
    },
    {
      "x": -8,
      "y": 10,
      "z": -4,
      "name": "Soil_Clay_Orange"
    },
    {
      "x": -8,
      "y": 11,
      "z": -4,
      "name": "Soil_Clay_Orange"
    },
    {
      "x": -8,
      "y": 12,
      "z": -4,
      "name": "Soil_Clay_Orange"
    },
    {
      "x": -8,
      "y": 13,
      "z": -4,
      "name": "Rock_Sandstone_Red"
    },
    {
      "x": -8,
      "y": 14,
      "z": -4,
      "name": "Rock_Sandstone"
    },
    {
      "x": -8,
      "y": 15,
      "z": -4,
      "name": "Rock_Sandstone"
    },
    {
      "x": -8,
      "y": 9,
      "z": -3,
      "name": "Soil_Clay_Orange"
    },
    {
      "x": -8,
      "y": 10,
      "z": -3,
      "name": "Soil_Clay_Orange"
    },
    {
      "x": -8,
      "y": 11,
      "z": -3,
      "name": "Soil_Clay_Orange"
    },
    {
      "x": -8,
      "y": 12,
      "z": -3,
      "name": "Rock_Sandstone_Red"
    },
    {
      "x": -8,
      "y": 13,
      "z": -3,
      "name": "Rock_Sandstone_Red"
    },
    {
      "x": -8,
      "y": 14,
      "z": -3,
      "name": "Rock_Sandstone"
    },
    {
      "x": -8,
      "y": 15,
      "z": -3,
      "name": "Rock_Sandstone"
    },
    {
      "x": -8,
      "y": 9,
      "z": -2,
      "name": "Soil_Clay_Orange"
    },
    {
      "x": -8,
      "y": 10,
      "z": -2,
      "name": "Soil_Clay_Orange"
    },
    {
      "x": -8,
      "y": 11,
      "z": -2,
      "name": "Soil_Clay_Orange"
    },
    {
      "x": -8,
      "y": 12,
      "z": -2,
      "name": "Rock_Sandstone_Red"
    },
    {
      "x": -8,
      "y": 13,
      "z": -2,
      "name": "Rock_Sandstone_Red"
    },
    {
      "x": -8,
      "y": 14,
      "z": -2,
      "name": "Rock_Sandstone"
    },
    {
      "x": -8,
      "y": 15,
      "z": -2,
      "name": "Rock_Sandstone"
    },
    {
      "x": -8,
      "y": 9,
      "z": -1,
      "name": "Soil_Clay_Orange"
    },
    {
      "x": -8,
      "y": 10,
      "z": -1,
      "name": "Soil_Clay_Orange"
    },
    {
      "x": -8,
      "y": 11,
      "z": -1,
      "name": "Soil_Clay_Orange"
    },
    {
      "x": -8,
      "y": 12,
      "z": -1,
      "name": "Rock_Sandstone_Red"
    },
    {
      "x": -8,
      "y": 13,
      "z": -1,
      "name": "Rock_Sandstone_Red"
    },
    {
      "x": -8,
      "y": 14,
      "z": -1,
      "name": "Rock_Sandstone"
    },
    {
      "x": -8,
      "y": 15,
      "z": -1,
      "name": "Rock_Sandstone"
    },
    {
      "x": -8,
      "y": 10,
      "z": 0,
      "name": "Soil_Clay_Orange"
    },
    {
      "x": -8,
      "y": 11,
      "z": 0,
      "name": "Rock_Sandstone"
    },
    {
      "x": -8,
      "y": 12,
      "z": 0,
      "name": "Rock_Sandstone_Red"
    },
    {
      "x": -8,
      "y": 13,
      "z": 0,
      "name": "Rock_Sandstone_Red"
    },
    {
      "x": -8,
      "y": 14,
      "z": 0,
      "name": "Rock_Sandstone"
    },
    {
      "x": -8,
      "y": 15,
      "z": 0,
      "name": "Rock_Sandstone"
    },
    {
      "x": -8,
      "y": 10,
      "z": 1,
      "name": "Rock_Sandstone"
    },
    {
      "x": -8,
      "y": 11,
      "z": 1,
      "name": "Rock_Sandstone"
    },
    {
      "x": -8,
      "y": 12,
      "z": 1,
      "name": "Rock_Sandstone_Red"
    },
    {
      "x": -8,
      "y": 13,
      "z": 1,
      "name": "Rock_Sandstone_Red"
    },
    {
      "x": -8,
      "y": 14,
      "z": 1,
      "name": "Rock_Sandstone"
    },
    {
      "x": -8,
      "y": 15,
      "z": 1,
      "name": "Rock_Sandstone"
    },
    {
      "x": -8,
      "y": 12,
      "z": 2,
      "name": "Rock_Sandstone_Red"
    },
    {
      "x": -8,
      "y": 13,
      "z": 2,
      "name": "Rock_Sandstone_Red"
    },
    {
      "x": -8,
      "y": 14,
      "z": 2,
      "name": "Rock_Sandstone"
    },
    {
      "x": -8,
      "y": 30,
      "z": 2,
      "name": "Rock_Sandstone_Red"
    },
    {
      "x": -8,
      "y": 31,
      "z": 2,
      "name": "Rock_Sandstone_Red"
    },
    {
      "x": -8,
      "y": 32,
      "z": 2,
      "name": "Soil_Clay_Orange"
    },
    {
      "x": -8,
      "y": 33,
      "z": 2,
      "name": "Soil_Clay_Orange"
    },
    {
      "x": -8,
      "y": 34,
      "z": 2,
      "name": "Rock_Sandstone"
    },
    {
      "x": -8,
      "y": 35,
      "z": 2,
      "name": "Rock_Sandstone_Red"
    },
    {
      "x": -8,
      "y": 36,
      "z": 2,
      "name": "Rock_Sandstone_Red"
    },
    {
      "x": -8,
      "y": 37,
      "z": 2,
      "name": "Rock_Sandstone"
    },
    {
      "x": -8,
      "y": 38,
      "z": 2,
      "name": "Rock_Sandstone_Red"
    },
    {
      "x": -8,
      "y": 39,
      "z": 2,
      "name": "Rock_Sandstone_Red"
    },
    {
      "x": -8,
      "y": 40,
      "z": 2,
      "name": "Rock_Sandstone_Red"
    },
    {
      "x": -8,
      "y": 41,
      "z": 2,
      "name": "Rock_Sandstone_Red"
    },
    {
      "x": -8,
      "y": 42,
      "z": 2,
      "name": "Rock_Sandstone_Red"
    },
    {
      "x": -8,
      "y": 43,
      "z": 2,
      "name": "Rock_Sandstone_Red"
    },
    {
      "x": -8,
      "y": 44,
      "z": 2,
      "name": "Rock_Sandstone_Red"
    },
    {
      "x": -8,
      "y": 45,
      "z": 2,
      "name": "Rock_Sandstone_Red"
    },
    {
      "x": -8,
      "y": 46,
      "z": 2,
      "name": "Soil_Clay_Orange"
    },
    {
      "x": -8,
      "y": 47,
      "z": 2,
      "name": "Soil_Clay_Orange"
    },
    {
      "x": -8,
      "y": 48,
      "z": 2,
      "name": "Soil_Clay_Orange"
    },
    {
      "x": -8,
      "y": 30,
      "z": 3,
      "name": "Rock_Sandstone_Red"
    },
    {
      "x": -8,
      "y": 31,
      "z": 3,
      "name": "Rock_Sandstone_Red"
    },
    {
      "x": -8,
      "y": 32,
      "z": 3,
      "name": "Soil_Clay_Orange"
    },
    {
      "x": -8,
      "y": 33,
      "z": 3,
      "name": "Soil_Clay_Orange"
    },
    {
      "x": -8,
      "y": 34,
      "z": 3,
      "name": "Rock_Sandstone"
    },
    {
      "x": -8,
      "y": 35,
      "z": 3,
      "name": "Rock_Sandstone_Red"
    },
    {
      "x": -8,
      "y": 36,
      "z": 3,
      "name": "Rock_Sandstone_Red"
    },
    {
      "x": -8,
      "y": 37,
      "z": 3,
      "name": "Rock_Sandstone"
    },
    {
      "x": -8,
      "y": 38,
      "z": 3,
      "name": "Rock_Sandstone_Red"
    },
    {
      "x": -8,
      "y": 39,
      "z": 3,
      "name": "Rock_Sandstone_Red"
    },
    {
      "x": -8,
      "y": 40,
      "z": 3,
      "name": "Rock_Sandstone_Red"
    },
    {
      "x": -8,
      "y": 41,
      "z": 3,
      "name": "Rock_Sandstone_Red"
    },
    {
      "x": -8,
      "y": 42,
      "z": 3,
      "name": "Rock_Sandstone_Red"
    },
    {
      "x": -8,
      "y": 43,
      "z": 3,
      "name": "Rock_Sandstone_Red"
    },
    {
      "x": -8,
      "y": 44,
      "z": 3,
      "name": "Rock_Sandstone_Red"
    },
    {
      "x": -8,
      "y": 45,
      "z": 3,
      "name": "Rock_Sandstone_Red"
    },
    {
      "x": -8,
      "y": 46,
      "z": 3,
      "name": "Rock_Sandstone_Red"
    },
    {
      "x": -8,
      "y": 47,
      "z": 3,
      "name": "Soil_Clay_Orange"
    },
    {
      "x": -8,
      "y": 48,
      "z": 3,
      "name": "Rock_Sandstone_Red"
    },
    {
      "x": -8,
      "y": 49,
      "z": 3,
      "name": "Soil_Clay_Smooth_Red"
    },
    {
      "x": -8,
      "y": 30,
      "z": 4,
      "name": "Rock_Sandstone_Red"
    },
    {
      "x": -8,
      "y": 31,
      "z": 4,
      "name": "Rock_Sandstone_Red"
    },
    {
      "x": -8,
      "y": 32,
      "z": 4,
      "name": "Soil_Clay_Orange"
    },
    {
      "x": -8,
      "y": 33,
      "z": 4,
      "name": "Soil_Clay_Orange"
    },
    {
      "x": -8,
      "y": 34,
      "z": 4,
      "name": "Rock_Sandstone"
    },
    {
      "x": -8,
      "y": 35,
      "z": 4,
      "name": "Rock_Sandstone_Red"
    },
    {
      "x": -8,
      "y": 36,
      "z": 4,
      "name": "Rock_Sandstone_Red"
    },
    {
      "x": -8,
      "y": 37,
      "z": 4,
      "name": "Rock_Sandstone"
    },
    {
      "x": -8,
      "y": 38,
      "z": 4,
      "name": "Soil_Clay_Orange"
    },
    {
      "x": -8,
      "y": 39,
      "z": 4,
      "name": "Rock_Sandstone_Red"
    },
    {
      "x": -8,
      "y": 40,
      "z": 4,
      "name": "Soil_Clay_Orange"
    },
    {
      "x": -8,
      "y": 41,
      "z": 4,
      "name": "Rock_Sandstone_Red"
    },
    {
      "x": -8,
      "y": 42,
      "z": 4,
      "name": "Rock_Sandstone_Red"
    },
    {
      "x": -8,
      "y": 43,
      "z": 4,
      "name": "Rock_Sandstone_Red"
    },
    {
      "x": -8,
      "y": 44,
      "z": 4,
      "name": "Rock_Sandstone_Red"
    },
    {
      "x": -8,
      "y": 45,
      "z": 4,
      "name": "Rock_Sandstone_Red"
    },
    {
      "x": -8,
      "y": 46,
      "z": 4,
      "name": "Rock_Sandstone_Red"
    },
    {
      "x": -8,
      "y": 47,
      "z": 4,
      "name": "Rock_Sandstone_Red"
    },
    {
      "x": -8,
      "y": 48,
      "z": 4,
      "name": "Rock_Sandstone_Red"
    },
    {
      "x": -8,
      "y": 49,
      "z": 4,
      "name": "Soil_Clay_Smooth_Red"
    },
    {
      "x": -8,
      "y": 30,
      "z": 5,
      "name": "Rock_Sandstone_Red"
    },
    {
      "x": -8,
      "y": 31,
      "z": 5,
      "name": "Rock_Sandstone_Red"
    },
    {
      "x": -8,
      "y": 32,
      "z": 5,
      "name": "Soil_Clay_Orange"
    },
    {
      "x": -8,
      "y": 33,
      "z": 5,
      "name": "Soil_Clay_Orange"
    },
    {
      "x": -8,
      "y": 34,
      "z": 5,
      "name": "Rock_Sandstone"
    },
    {
      "x": -8,
      "y": 35,
      "z": 5,
      "name": "Rock_Sandstone_Red"
    },
    {
      "x": -8,
      "y": 36,
      "z": 5,
      "name": "Rock_Sandstone_Red"
    },
    {
      "x": -8,
      "y": 37,
      "z": 5,
      "name": "Rock_Sandstone"
    },
    {
      "x": -8,
      "y": 38,
      "z": 5,
      "name": "Soil_Clay_Orange"
    },
    {
      "x": -8,
      "y": 39,
      "z": 5,
      "name": "Soil_Clay_Orange"
    },
    {
      "x": -8,
      "y": 40,
      "z": 5,
      "name": "Soil_Clay_Orange"
    },
    {
      "x": -8,
      "y": 41,
      "z": 5,
      "name": "Soil_Clay_Orange"
    },
    {
      "x": -8,
      "y": 42,
      "z": 5,
      "name": "Rock_Sandstone_Red"
    },
    {
      "x": -8,
      "y": 43,
      "z": 5,
      "name": "Rock_Sandstone_Red"
    },
    {
      "x": -8,
      "y": 44,
      "z": 5,
      "name": "Rock_Sandstone_Red"
    },
    {
      "x": -8,
      "y": 45,
      "z": 5,
      "name": "Rock_Sandstone_Red"
    },
    {
      "x": -8,
      "y": 46,
      "z": 5,
      "name": "Rock_Sandstone_Red"
    },
    {
      "x": -8,
      "y": 47,
      "z": 5,
      "name": "Rock_Sandstone_Red"
    },
    {
      "x": -8,
      "y": 48,
      "z": 5,
      "name": "Rock_Sandstone_Red"
    },
    {
      "x": -8,
      "y": 49,
      "z": 5,
      "name": "Soil_Clay_Smooth_Red"
    },
    {
      "x": -8,
      "y": 31,
      "z": 6,
      "name": "Soil_Clay_Orange"
    },
    {
      "x": -8,
      "y": 32,
      "z": 6,
      "name": "Soil_Clay_Orange"
    },
    {
      "x": -8,
      "y": 33,
      "z": 6,
      "name": "Soil_Clay_Orange"
    },
    {
      "x": -8,
      "y": 34,
      "z": 6,
      "name": "Rock_Sandstone"
    },
    {
      "x": -8,
      "y": 35,
      "z": 6,
      "name": "Rock_Sandstone_Red"
    },
    {
      "x": -8,
      "y": 36,
      "z": 6,
      "name": "Rock_Sandstone_Red"
    },
    {
      "x": -8,
      "y": 37,
      "z": 6,
      "name": "Rock_Sandstone"
    },
    {
      "x": -8,
      "y": 38,
      "z": 6,
      "name": "Soil_Clay_Orange"
    },
    {
      "x": -8,
      "y": 39,
      "z": 6,
      "name": "Soil_Clay_Orange"
    },
    {
      "x": -8,
      "y": 40,
      "z": 6,
      "name": "Soil_Clay_Orange"
    },
    {
      "x": -8,
      "y": 41,
      "z": 6,
      "name": "Soil_Clay_Orange"
    },
    {
      "x": -8,
      "y": 42,
      "z": 6,
      "name": "Soil_Clay_Orange"
    },
    {
      "x": -8,
      "y": 43,
      "z": 6,
      "name": "Rock_Sandstone_Red"
    },
    {
      "x": -8,
      "y": 44,
      "z": 6,
      "name": "Rock_Sandstone_Red"
    },
    {
      "x": -8,
      "y": 45,
      "z": 6,
      "name": "Rock_Sandstone_Red"
    },
    {
      "x": -8,
      "y": 46,
      "z": 6,
      "name": "Rock_Sandstone_Red"
    },
    {
      "x": -8,
      "y": 47,
      "z": 6,
      "name": "Rock_Sandstone_Red"
    },
    {
      "x": -8,
      "y": 48,
      "z": 6,
      "name": "Rock_Sandstone_Red"
    },
    {
      "x": -8,
      "y": 49,
      "z": 6,
      "name": "Soil_Clay_Smooth_Red"
    },
    {
      "x": -8,
      "y": 32,
      "z": 7,
      "name": "Soil_Clay_Orange"
    },
    {
      "x": -8,
      "y": 33,
      "z": 7,
      "name": "Soil_Clay_Orange"
    },
    {
      "x": -8,
      "y": 34,
      "z": 7,
      "name": "Rock_Sandstone"
    },
    {
      "x": -8,
      "y": 35,
      "z": 7,
      "name": "Rock_Sandstone_Red"
    },
    {
      "x": -8,
      "y": 36,
      "z": 7,
      "name": "Rock_Sandstone_Red"
    },
    {
      "x": -8,
      "y": 37,
      "z": 7,
      "name": "Rock_Sandstone"
    },
    {
      "x": -8,
      "y": 38,
      "z": 7,
      "name": "Soil_Clay_Orange"
    },
    {
      "x": -8,
      "y": 39,
      "z": 7,
      "name": "Soil_Clay_Orange"
    },
    {
      "x": -8,
      "y": 40,
      "z": 7,
      "name": "Soil_Clay_Orange"
    },
    {
      "x": -8,
      "y": 41,
      "z": 7,
      "name": "Soil_Clay_Orange"
    },
    {
      "x": -8,
      "y": 42,
      "z": 7,
      "name": "Soil_Clay_Orange"
    },
    {
      "x": -8,
      "y": 43,
      "z": 7,
      "name": "Soil_Clay_Orange"
    },
    {
      "x": -8,
      "y": 44,
      "z": 7,
      "name": "Rock_Sandstone_Red"
    },
    {
      "x": -8,
      "y": 45,
      "z": 7,
      "name": "Rock_Sandstone_Red"
    },
    {
      "x": -8,
      "y": 46,
      "z": 7,
      "name": "Rock_Sandstone_Red"
    },
    {
      "x": -8,
      "y": 47,
      "z": 7,
      "name": "Rock_Sandstone_Red"
    },
    {
      "x": -8,
      "y": 48,
      "z": 7,
      "name": "Rock_Sandstone_Red"
    },
    {
      "x": -8,
      "y": 49,
      "z": 7,
      "name": "Soil_Clay_Smooth_Red"
    },
    {
      "x": -8,
      "y": 32,
      "z": 8,
      "name": "Soil_Clay_Orange"
    },
    {
      "x": -8,
      "y": 33,
      "z": 8,
      "name": "Soil_Clay_Orange"
    },
    {
      "x": -8,
      "y": 34,
      "z": 8,
      "name": "Rock_Sandstone"
    },
    {
      "x": -8,
      "y": 35,
      "z": 8,
      "name": "Rock_Sandstone_Red"
    },
    {
      "x": -8,
      "y": 36,
      "z": 8,
      "name": "Soil_Clay_Orange"
    },
    {
      "x": -8,
      "y": 37,
      "z": 8,
      "name": "Rock_Sandstone"
    },
    {
      "x": -8,
      "y": 38,
      "z": 8,
      "name": "Soil_Clay_Orange"
    },
    {
      "x": -8,
      "y": 39,
      "z": 8,
      "name": "Soil_Clay_Orange"
    },
    {
      "x": -8,
      "y": 40,
      "z": 8,
      "name": "Soil_Clay_Orange"
    },
    {
      "x": -8,
      "y": 41,
      "z": 8,
      "name": "Soil_Clay_Orange"
    },
    {
      "x": -8,
      "y": 42,
      "z": 8,
      "name": "Soil_Clay_Orange"
    },
    {
      "x": -8,
      "y": 44,
      "z": 8,
      "name": "Rock_Sandstone_Red"
    },
    {
      "x": -8,
      "y": 45,
      "z": 8,
      "name": "Rock_Sandstone_Red"
    },
    {
      "x": -8,
      "y": 46,
      "z": 8,
      "name": "Rock_Sandstone_Red"
    },
    {
      "x": -8,
      "y": 47,
      "z": 8,
      "name": "Rock_Sandstone_Red"
    },
    {
      "x": -8,
      "y": 48,
      "z": 8,
      "name": "Rock_Sandstone_Red"
    },
    {
      "x": -7,
      "y": 9,
      "z": -6,
      "name": "Rock_Sandstone"
    },
    {
      "x": -7,
      "y": 10,
      "z": -6,
      "name": "Soil_Clay_Orange"
    },
    {
      "x": -7,
      "y": 11,
      "z": -6,
      "name": "Soil_Clay_Orange"
    },
    {
      "x": -7,
      "y": 12,
      "z": -6,
      "name": "Soil_Clay_Orange"
    },
    {
      "x": -7,
      "y": 13,
      "z": -6,
      "name": "Soil_Clay_Orange"
    },
    {
      "x": -7,
      "y": 9,
      "z": -5,
      "name": "Rock_Sandstone"
    },
    {
      "x": -7,
      "y": 10,
      "z": -5,
      "name": "Soil_Clay_Orange"
    },
    {
      "x": -7,
      "y": 11,
      "z": -5,
      "name": "Soil_Clay_Orange"
    },
    {
      "x": -7,
      "y": 12,
      "z": -5,
      "name": "Soil_Clay_Orange"
    },
    {
      "x": -7,
      "y": 13,
      "z": -5,
      "name": "Soil_Clay_Orange"
    },
    {
      "x": -7,
      "y": 14,
      "z": -5,
      "name": "Rock_Sandstone"
    },
    {
      "x": -7,
      "y": 9,
      "z": -4,
      "name": "Rock_Sandstone"
    },
    {
      "x": -7,
      "y": 10,
      "z": -4,
      "name": "Soil_Clay_Orange"
    },
    {
      "x": -7,
      "y": 11,
      "z": -4,
      "name": "Soil_Clay_Orange"
    },
    {
      "x": -7,
      "y": 12,
      "z": -4,
      "name": "Soil_Clay_Orange"
    },
    {
      "x": -7,
      "y": 13,
      "z": -4,
      "name": "Soil_Clay_Orange"
    },
    {
      "x": -7,
      "y": 14,
      "z": -4,
      "name": "Rock_Sandstone"
    },
    {
      "x": -7,
      "y": 15,
      "z": -4,
      "name": "Rock_Sandstone"
    },
    {
      "x": -7,
      "y": 3,
      "z": -3,
      "name": "Rock_Sandstone_Red"
    },
    {
      "x": -7,
      "y": 4,
      "z": -3,
      "name": "Rock_Sandstone_Red"
    },
    {
      "x": -7,
      "y": 5,
      "z": -3,
      "name": "Rock_Sandstone"
    },
    {
      "x": -7,
      "y": 8,
      "z": -3,
      "name": "Soil_Clay_Orange"
    },
    {
      "x": -7,
      "y": 9,
      "z": -3,
      "name": "Soil_Clay_Orange"
    },
    {
      "x": -7,
      "y": 10,
      "z": -3,
      "name": "Soil_Clay_Orange"
    },
    {
      "x": -7,
      "y": 11,
      "z": -3,
      "name": "Soil_Clay_Orange"
    },
    {
      "x": -7,
      "y": 12,
      "z": -3,
      "name": "Soil_Clay_Orange"
    },
    {
      "x": -7,
      "y": 13,
      "z": -3,
      "name": "Rock_Sandstone_Red"
    },
    {
      "x": -7,
      "y": 14,
      "z": -3,
      "name": "Rock_Sandstone"
    },
    {
      "x": -7,
      "y": 15,
      "z": -3,
      "name": "Rock_Sandstone"
    },
    {
      "x": -7,
      "y": 16,
      "z": -3,
      "name": "Rock_Sandstone_Red"
    },
    {
      "x": -7,
      "y": 22,
      "z": -3,
      "name": "Soil_Clay_Yellow"
    },
    {
      "x": -7,
      "y": 23,
      "z": -3,
      "name": "Rock_Sandstone"
    },
    {
      "x": -7,
      "y": 24,
      "z": -3,
      "name": "Rock_Sandstone_Red"
    },
    {
      "x": -7,
      "y": 25,
      "z": -3,
      "name": "Rock_Sandstone_Red"
    },
    {
      "x": -7,
      "y": 29,
      "z": -3,
      "name": "Rock_Sandstone_Red"
    },
    {
      "x": -7,
      "y": 30,
      "z": -3,
      "name": "Rock_Sandstone_Red"
    },
    {
      "x": -7,
      "y": 31,
      "z": -3,
      "name": "Rock_Sandstone_Red"
    },
    {
      "x": -7,
      "y": 32,
      "z": -3,
      "name": "Rock_Sandstone"
    },
    {
      "x": -7,
      "y": 33,
      "z": -3,
      "name": "Rock_Sandstone"
    },
    {
      "x": -7,
      "y": 34,
      "z": -3,
      "name": "Soil_Clay_Orange"
    },
    {
      "x": -7,
      "y": 38,
      "z": -3,
      "name": "Rock_Sandstone_Red"
    },
    {
      "x": -7,
      "y": 39,
      "z": -3,
      "name": "Rock_Sandstone_Red"
    },
    {
      "x": -7,
      "y": 40,
      "z": -3,
      "name": "Soil_Clay_Orange"
    },
    {
      "x": -7,
      "y": 41,
      "z": -3,
      "name": "Rock_Sandstone_Red"
    },
    {
      "x": -7,
      "y": 42,
      "z": -3,
      "name": "Rock_Sandstone_Red"
    },
    {
      "x": -7,
      "y": 43,
      "z": -3,
      "name": "Rock_Sandstone_Red"
    },
    {
      "x": -7,
      "y": 44,
      "z": -3,
      "name": "Rock_Sandstone_Red"
    },
    {
      "x": -7,
      "y": 45,
      "z": -3,
      "name": "Soil_Clay_Orange"
    },
    {
      "x": -7,
      "y": 46,
      "z": -3,
      "name": "Soil_Clay_Orange"
    },
    {
      "x": -7,
      "y": 47,
      "z": -3,
      "name": "Soil_Clay_Orange"
    },
    {
      "x": -7,
      "y": 48,
      "z": -3,
      "name": "Rock_Sandstone_Red"
    },
    {
      "x": -7,
      "y": 1,
      "z": -2,
      "name": "Rock_Sandstone_Red"
    },
    {
      "x": -7,
      "y": 2,
      "z": -2,
      "name": "Rock_Sandstone_Red"
    },
    {
      "x": -7,
      "y": 3,
      "z": -2,
      "name": "Rock_Sandstone_Red"
    },
    {
      "x": -7,
      "y": 4,
      "z": -2,
      "name": "Rock_Sandstone_Red"
    },
    {
      "x": -7,
      "y": 5,
      "z": -2,
      "name": "Rock_Sandstone"
    },
    {
      "x": -7,
      "y": 8,
      "z": -2,
      "name": "Soil_Clay_Orange"
    },
    {
      "x": -7,
      "y": 9,
      "z": -2,
      "name": "Soil_Clay_Orange"
    },
    {
      "x": -7,
      "y": 10,
      "z": -2,
      "name": "Soil_Clay_Orange"
    },
    {
      "x": -7,
      "y": 11,
      "z": -2,
      "name": "Soil_Clay_Orange"
    },
    {
      "x": -7,
      "y": 12,
      "z": -2,
      "name": "Rock_Sandstone_Red"
    },
    {
      "x": -7,
      "y": 13,
      "z": -2,
      "name": "Rock_Sandstone_Red"
    },
    {
      "x": -7,
      "y": 14,
      "z": -2,
      "name": "Rock_Sandstone"
    },
    {
      "x": -7,
      "y": 15,
      "z": -2,
      "name": "Rock_Sandstone"
    },
    {
      "x": -7,
      "y": 16,
      "z": -2,
      "name": "Rock_Sandstone_Red"
    },
    {
      "x": -7,
      "y": 17,
      "z": -2,
      "name": "Rock_Sandstone_Red"
    },
    {
      "x": -7,
      "y": 22,
      "z": -2,
      "name": "Soil_Clay_Yellow"
    },
    {
      "x": -7,
      "y": 23,
      "z": -2,
      "name": "Rock_Sandstone"
    },
    {
      "x": -7,
      "y": 24,
      "z": -2,
      "name": "Rock_Sandstone_Red"
    },
    {
      "x": -7,
      "y": 25,
      "z": -2,
      "name": "Rock_Sandstone_Red"
    },
    {
      "x": -7,
      "y": 26,
      "z": -2,
      "name": "Rock_Sandstone_Red"
    },
    {
      "x": -7,
      "y": 29,
      "z": -2,
      "name": "Rock_Sandstone_Red"
    },
    {
      "x": -7,
      "y": 30,
      "z": -2,
      "name": "Rock_Sandstone_Red"
    },
    {
      "x": -7,
      "y": 31,
      "z": -2,
      "name": "Rock_Sandstone_Red"
    },
    {
      "x": -7,
      "y": 34,
      "z": -2,
      "name": "Rock_Sandstone_Red"
    },
    {
      "x": -7,
      "y": 35,
      "z": -2,
      "name": "Rock_Sandstone_Red"
    },
    {
      "x": -7,
      "y": 40,
      "z": -2,
      "name": "Soil_Clay_Orange"
    },
    {
      "x": -7,
      "y": 41,
      "z": -2,
      "name": "Rock_Sandstone_Red"
    },
    {
      "x": -7,
      "y": 42,
      "z": -2,
      "name": "Rock_Sandstone_Red"
    },
    {
      "x": -7,
      "y": 43,
      "z": -2,
      "name": "Rock_Sandstone_Red"
    },
    {
      "x": -7,
      "y": 44,
      "z": -2,
      "name": "Rock_Sandstone_Red"
    },
    {
      "x": -7,
      "y": 45,
      "z": -2,
      "name": "Soil_Clay_Orange"
    },
    {
      "x": -7,
      "y": 46,
      "z": -2,
      "name": "Soil_Clay_Orange"
    },
    {
      "x": -7,
      "y": 47,
      "z": -2,
      "name": "Soil_Clay_Orange"
    },
    {
      "x": -7,
      "y": 48,
      "z": -2,
      "name": "Soil_Clay_Orange"
    },
    {
      "x": -7,
      "y": 1,
      "z": -1,
      "name": "Rock_Sandstone_Red"
    },
    {
      "x": -7,
      "y": 2,
      "z": -1,
      "name": "Rock_Sandstone_Red"
    },
    {
      "x": -7,
      "y": 3,
      "z": -1,
      "name": "Rock_Sandstone_Red"
    },
    {
      "x": -7,
      "y": 4,
      "z": -1,
      "name": "Rock_Sandstone_Red"
    },
    {
      "x": -7,
      "y": 5,
      "z": -1,
      "name": "Soil_Clay_Orange"
    },
    {
      "x": -7,
      "y": 6,
      "z": -1,
      "name": "Soil_Clay_Yellow"
    },
    {
      "x": -7,
      "y": 8,
      "z": -1,
      "name": "Soil_Clay_Orange"
    },
    {
      "x": -7,
      "y": 9,
      "z": -1,
      "name": "Soil_Clay_Orange"
    },
    {
      "x": -7,
      "y": 10,
      "z": -1,
      "name": "Soil_Clay_Orange"
    },
    {
      "x": -7,
      "y": 11,
      "z": -1,
      "name": "Soil_Clay_Orange"
    },
    {
      "x": -7,
      "y": 12,
      "z": -1,
      "name": "Rock_Sandstone_Red"
    },
    {
      "x": -7,
      "y": 13,
      "z": -1,
      "name": "Rock_Sandstone_Red"
    },
    {
      "x": -7,
      "y": 14,
      "z": -1,
      "name": "Rock_Sandstone"
    },
    {
      "x": -7,
      "y": 15,
      "z": -1,
      "name": "Rock_Sandstone"
    },
    {
      "x": -7,
      "y": 16,
      "z": -1,
      "name": "Rock_Sandstone_Red"
    },
    {
      "x": -7,
      "y": 17,
      "z": -1,
      "name": "Rock_Sandstone_Red"
    },
    {
      "x": -7,
      "y": 22,
      "z": -1,
      "name": "Soil_Clay_Yellow"
    },
    {
      "x": -7,
      "y": 23,
      "z": -1,
      "name": "Rock_Sandstone"
    },
    {
      "x": -7,
      "y": 24,
      "z": -1,
      "name": "Rock_Sandstone_Red"
    },
    {
      "x": -7,
      "y": 25,
      "z": -1,
      "name": "Rock_Sandstone_Red"
    },
    {
      "x": -7,
      "y": 26,
      "z": -1,
      "name": "Rock_Sandstone_Red"
    },
    {
      "x": -7,
      "y": 29,
      "z": -1,
      "name": "Rock_Sandstone_Red"
    },
    {
      "x": -7,
      "y": 30,
      "z": -1,
      "name": "Rock_Sandstone_Red"
    },
    {
      "x": -7,
      "y": 31,
      "z": -1,
      "name": "Rock_Sandstone_Red"
    },
    {
      "x": -7,
      "y": 32,
      "z": -1,
      "name": "Soil_Clay_Orange"
    },
    {
      "x": -7,
      "y": 33,
      "z": -1,
      "name": "Soil_Clay_Orange"
    },
    {
      "x": -7,
      "y": 34,
      "z": -1,
      "name": "Rock_Sandstone"
    },
    {
      "x": -7,
      "y": 35,
      "z": -1,
      "name": "Rock_Sandstone_Red"
    },
    {
      "x": -7,
      "y": 36,
      "z": -1,
      "name": "Rock_Sandstone_Red"
    },
    {
      "x": -7,
      "y": 37,
      "z": -1,
      "name": "Rock_Sandstone"
    },
    {
      "x": -7,
      "y": 44,
      "z": -1,
      "name": "Soil_Clay_Orange"
    },
    {
      "x": -7,
      "y": 45,
      "z": -1,
      "name": "Soil_Clay_Orange"
    },
    {
      "x": -7,
      "y": 46,
      "z": -1,
      "name": "Soil_Clay_Orange"
    },
    {
      "x": -7,
      "y": 47,
      "z": -1,
      "name": "Soil_Clay_Orange"
    },
    {
      "x": -7,
      "y": 48,
      "z": -1,
      "name": "Soil_Clay_Orange"
    },
    {
      "x": -7,
      "y": 2,
      "z": 0,
      "name": "Rock_Sandstone_Red"
    },
    {
      "x": -7,
      "y": 3,
      "z": 0,
      "name": "Rock_Sandstone_Red"
    },
    {
      "x": -7,
      "y": 4,
      "z": 0,
      "name": "Rock_Sandstone_Red"
    },
    {
      "x": -7,
      "y": 6,
      "z": 0,
      "name": "Soil_Clay_Yellow"
    },
    {
      "x": -7,
      "y": 9,
      "z": 0,
      "name": "Soil_Clay_Orange"
    },
    {
      "x": -7,
      "y": 10,
      "z": 0,
      "name": "Soil_Clay_Orange"
    },
    {
      "x": -7,
      "y": 11,
      "z": 0,
      "name": "Soil_Clay_Orange"
    },
    {
      "x": -7,
      "y": 12,
      "z": 0,
      "name": "Rock_Sandstone_Red"
    },
    {
      "x": -7,
      "y": 13,
      "z": 0,
      "name": "Rock_Sandstone_Red"
    },
    {
      "x": -7,
      "y": 14,
      "z": 0,
      "name": "Rock_Sandstone"
    },
    {
      "x": -7,
      "y": 15,
      "z": 0,
      "name": "Rock_Sandstone"
    },
    {
      "x": -7,
      "y": 16,
      "z": 0,
      "name": "Rock_Sandstone_Red"
    },
    {
      "x": -7,
      "y": 17,
      "z": 0,
      "name": "Rock_Sandstone_Red"
    },
    {
      "x": -7,
      "y": 22,
      "z": 0,
      "name": "Soil_Clay_Yellow"
    },
    {
      "x": -7,
      "y": 23,
      "z": 0,
      "name": "Rock_Sandstone"
    },
    {
      "x": -7,
      "y": 24,
      "z": 0,
      "name": "Rock_Sandstone_Red"
    },
    {
      "x": -7,
      "y": 25,
      "z": 0,
      "name": "Rock_Sandstone_Red"
    },
    {
      "x": -7,
      "y": 26,
      "z": 0,
      "name": "Rock_Sandstone_Red"
    },
    {
      "x": -7,
      "y": 30,
      "z": 0,
      "name": "Rock_Sandstone_Red"
    },
    {
      "x": -7,
      "y": 31,
      "z": 0,
      "name": "Rock_Sandstone_Red"
    },
    {
      "x": -7,
      "y": 32,
      "z": 0,
      "name": "Soil_Clay_Orange"
    },
    {
      "x": -7,
      "y": 33,
      "z": 0,
      "name": "Soil_Clay_Orange"
    },
    {
      "x": -7,
      "y": 35,
      "z": 0,
      "name": "Rock_Sandstone_Red"
    },
    {
      "x": -7,
      "y": 36,
      "z": 0,
      "name": "Rock_Sandstone_Red"
    },
    {
      "x": -7,
      "y": 37,
      "z": 0,
      "name": "Rock_Sandstone"
    },
    {
      "x": -7,
      "y": 38,
      "z": 0,
      "name": "Rock_Sandstone_Red"
    },
    {
      "x": -7,
      "y": 39,
      "z": 0,
      "name": "Rock_Sandstone_Red"
    },
    {
      "x": -7,
      "y": 40,
      "z": 0,
      "name": "Rock_Sandstone_Red"
    },
    {
      "x": -7,
      "y": 48,
      "z": 0,
      "name": "Soil_Clay_Orange"
    },
    {
      "x": -7,
      "y": 2,
      "z": 1,
      "name": "Rock_Sandstone_Red"
    },
    {
      "x": -7,
      "y": 4,
      "z": 1,
      "name": "Soil_Clay_Orange"
    },
    {
      "x": -7,
      "y": 5,
      "z": 1,
      "name": "Soil_Clay_Orange"
    },
    {
      "x": -7,
      "y": 9,
      "z": 1,
      "name": "Soil_Clay_Orange"
    },
    {
      "x": -7,
      "y": 10,
      "z": 1,
      "name": "Soil_Clay_Orange"
    },
    {
      "x": -7,
      "y": 11,
      "z": 1,
      "name": "Rock_Sandstone"
    },
    {
      "x": -7,
      "y": 12,
      "z": 1,
      "name": "Rock_Sandstone_Red"
    },
    {
      "x": -7,
      "y": 13,
      "z": 1,
      "name": "Rock_Sandstone_Red"
    },
    {
      "x": -7,
      "y": 14,
      "z": 1,
      "name": "Rock_Sandstone"
    },
    {
      "x": -7,
      "y": 15,
      "z": 1,
      "name": "Rock_Sandstone"
    },
    {
      "x": -7,
      "y": 16,
      "z": 1,
      "name": "Rock_Sandstone_Red"
    },
    {
      "x": -7,
      "y": 17,
      "z": 1,
      "name": "Rock_Sandstone_Red"
    },
    {
      "x": -7,
      "y": 22,
      "z": 1,
      "name": "Soil_Clay_Yellow"
    },
    {
      "x": -7,
      "y": 23,
      "z": 1,
      "name": "Rock_Sandstone"
    },
    {
      "x": -7,
      "y": 24,
      "z": 1,
      "name": "Rock_Sandstone_Red"
    },
    {
      "x": -7,
      "y": 25,
      "z": 1,
      "name": "Rock_Sandstone_Red"
    },
    {
      "x": -7,
      "y": 29,
      "z": 1,
      "name": "Rock_Sandstone_Red"
    },
    {
      "x": -7,
      "y": 30,
      "z": 1,
      "name": "Rock_Sandstone_Red"
    },
    {
      "x": -7,
      "y": 31,
      "z": 1,
      "name": "Rock_Sandstone_Red"
    },
    {
      "x": -7,
      "y": 32,
      "z": 1,
      "name": "Soil_Clay_Orange"
    },
    {
      "x": -7,
      "y": 33,
      "z": 1,
      "name": "Soil_Clay_Orange"
    },
    {
      "x": -7,
      "y": 34,
      "z": 1,
      "name": "Rock_Sandstone"
    },
    {
      "x": -7,
      "y": 35,
      "z": 1,
      "name": "Rock_Sandstone_Red"
    },
    {
      "x": -7,
      "y": 36,
      "z": 1,
      "name": "Rock_Sandstone_Red"
    },
    {
      "x": -7,
      "y": 37,
      "z": 1,
      "name": "Rock_Sandstone"
    },
    {
      "x": -7,
      "y": 38,
      "z": 1,
      "name": "Rock_Sandstone_Red"
    },
    {
      "x": -7,
      "y": 39,
      "z": 1,
      "name": "Rock_Sandstone_Red"
    },
    {
      "x": -7,
      "y": 40,
      "z": 1,
      "name": "Rock_Sandstone_Red"
    },
    {
      "x": -7,
      "y": 41,
      "z": 1,
      "name": "Rock_Sandstone_Red"
    },
    {
      "x": -7,
      "y": 42,
      "z": 1,
      "name": "Rock_Sandstone_Red"
    },
    {
      "x": -7,
      "y": 43,
      "z": 1,
      "name": "Rock_Sandstone_Red"
    },
    {
      "x": -7,
      "y": 44,
      "z": 1,
      "name": "Rock_Sandstone_Red"
    },
    {
      "x": -7,
      "y": 49,
      "z": 1,
      "name": "Soil_Clay_Smooth_Red"
    },
    {
      "x": -7,
      "y": 9,
      "z": 2,
      "name": "Soil_Clay_Orange"
    },
    {
      "x": -7,
      "y": 10,
      "z": 2,
      "name": "Soil_Clay_Orange"
    },
    {
      "x": -7,
      "y": 11,
      "z": 2,
      "name": "Rock_Sandstone"
    },
    {
      "x": -7,
      "y": 12,
      "z": 2,
      "name": "Rock_Sandstone_Red"
    },
    {
      "x": -7,
      "y": 13,
      "z": 2,
      "name": "Rock_Sandstone_Red"
    },
    {
      "x": -7,
      "y": 14,
      "z": 2,
      "name": "Rock_Sandstone"
    },
    {
      "x": -7,
      "y": 15,
      "z": 2,
      "name": "Rock_Sandstone"
    },
    {
      "x": -7,
      "y": 16,
      "z": 2,
      "name": "Rock_Sandstone_Red"
    },
    {
      "x": -7,
      "y": 29,
      "z": 2,
      "name": "Rock_Sandstone_Red"
    },
    {
      "x": -7,
      "y": 30,
      "z": 2,
      "name": "Rock_Sandstone_Red"
    },
    {
      "x": -7,
      "y": 31,
      "z": 2,
      "name": "Rock_Sandstone_Red"
    },
    {
      "x": -7,
      "y": 32,
      "z": 2,
      "name": "Soil_Clay_Orange"
    },
    {
      "x": -7,
      "y": 33,
      "z": 2,
      "name": "Soil_Clay_Orange"
    },
    {
      "x": -7,
      "y": 34,
      "z": 2,
      "name": "Rock_Sandstone"
    },
    {
      "x": -7,
      "y": 35,
      "z": 2,
      "name": "Rock_Sandstone_Red"
    },
    {
      "x": -7,
      "y": 36,
      "z": 2,
      "name": "Rock_Sandstone_Red"
    },
    {
      "x": -7,
      "y": 37,
      "z": 2,
      "name": "Rock_Sandstone"
    },
    {
      "x": -7,
      "y": 38,
      "z": 2,
      "name": "Rock_Sandstone_Red"
    },
    {
      "x": -7,
      "y": 39,
      "z": 2,
      "name": "Rock_Sandstone_Red"
    },
    {
      "x": -7,
      "y": 40,
      "z": 2,
      "name": "Rock_Sandstone_Red"
    },
    {
      "x": -7,
      "y": 41,
      "z": 2,
      "name": "Rock_Sandstone_Red"
    },
    {
      "x": -7,
      "y": 42,
      "z": 2,
      "name": "Rock_Sandstone_Red"
    },
    {
      "x": -7,
      "y": 43,
      "z": 2,
      "name": "Rock_Sandstone_Red"
    },
    {
      "x": -7,
      "y": 44,
      "z": 2,
      "name": "Rock_Sandstone_Red"
    },
    {
      "x": -7,
      "y": 45,
      "z": 2,
      "name": "Soil_Clay_Orange"
    },
    {
      "x": -7,
      "y": 46,
      "z": 2,
      "name": "Soil_Clay_Orange"
    },
    {
      "x": -7,
      "y": 47,
      "z": 2,
      "name": "Soil_Clay_Orange"
    },
    {
      "x": -7,
      "y": 48,
      "z": 2,
      "name": "Soil_Clay_Orange"
    },
    {
      "x": -7,
      "y": 49,
      "z": 2,
      "name": "Soil_Clay_Smooth_Red"
    },
    {
      "x": -7,
      "y": 9,
      "z": 3,
      "name": "Soil_Clay_Orange"
    },
    {
      "x": -7,
      "y": 10,
      "z": 3,
      "name": "Soil_Clay_Orange"
    },
    {
      "x": -7,
      "y": 11,
      "z": 3,
      "name": "Rock_Sandstone"
    },
    {
      "x": -7,
      "y": 12,
      "z": 3,
      "name": "Rock_Sandstone_Red"
    },
    {
      "x": -7,
      "y": 13,
      "z": 3,
      "name": "Rock_Sandstone_Red"
    },
    {
      "x": -7,
      "y": 14,
      "z": 3,
      "name": "Rock_Sandstone"
    },
    {
      "x": -7,
      "y": 15,
      "z": 3,
      "name": "Rock_Sandstone"
    },
    {
      "x": -7,
      "y": 16,
      "z": 3,
      "name": "Rock_Sandstone_Red"
    },
    {
      "x": -7,
      "y": 30,
      "z": 3,
      "name": "Rock_Sandstone_Red"
    },
    {
      "x": -7,
      "y": 31,
      "z": 3,
      "name": "Rock_Sandstone_Red"
    },
    {
      "x": -7,
      "y": 32,
      "z": 3,
      "name": "Soil_Clay_Orange"
    },
    {
      "x": -7,
      "y": 33,
      "z": 3,
      "name": "Soil_Clay_Orange"
    },
    {
      "x": -7,
      "y": 34,
      "z": 3,
      "name": "Rock_Sandstone"
    },
    {
      "x": -7,
      "y": 35,
      "z": 3,
      "name": "Rock_Sandstone_Red"
    },
    {
      "x": -7,
      "y": 36,
      "z": 3,
      "name": "Rock_Sandstone_Red"
    },
    {
      "x": -7,
      "y": 37,
      "z": 3,
      "name": "Rock_Sandstone"
    },
    {
      "x": -7,
      "y": 38,
      "z": 3,
      "name": "Rock_Sandstone_Red"
    },
    {
      "x": -7,
      "y": 39,
      "z": 3,
      "name": "Rock_Sandstone_Red"
    },
    {
      "x": -7,
      "y": 40,
      "z": 3,
      "name": "Rock_Sandstone_Red"
    },
    {
      "x": -7,
      "y": 41,
      "z": 3,
      "name": "Rock_Sandstone_Red"
    },
    {
      "x": -7,
      "y": 42,
      "z": 3,
      "name": "Rock_Sandstone_Red"
    },
    {
      "x": -7,
      "y": 43,
      "z": 3,
      "name": "Rock_Sandstone_Red"
    },
    {
      "x": -7,
      "y": 44,
      "z": 3,
      "name": "Rock_Sandstone_Red"
    },
    {
      "x": -7,
      "y": 45,
      "z": 3,
      "name": "Rock_Sandstone_Red"
    },
    {
      "x": -7,
      "y": 46,
      "z": 3,
      "name": "Soil_Clay_Orange"
    },
    {
      "x": -7,
      "y": 47,
      "z": 3,
      "name": "Soil_Clay_Orange"
    },
    {
      "x": -7,
      "y": 48,
      "z": 3,
      "name": "Rock_Sandstone_Red"
    },
    {
      "x": -7,
      "y": 49,
      "z": 3,
      "name": "Soil_Clay_Smooth_Red"
    },
    {
      "x": -7,
      "y": 9,
      "z": 4,
      "name": "Soil_Clay_Orange"
    },
    {
      "x": -7,
      "y": 10,
      "z": 4,
      "name": "Soil_Clay_Orange"
    },
    {
      "x": -7,
      "y": 11,
      "z": 4,
      "name": "Rock_Sandstone"
    },
    {
      "x": -7,
      "y": 12,
      "z": 4,
      "name": "Rock_Sandstone_Red"
    },
    {
      "x": -7,
      "y": 13,
      "z": 4,
      "name": "Rock_Sandstone_Red"
    },
    {
      "x": -7,
      "y": 14,
      "z": 4,
      "name": "Rock_Sandstone_Red"
    },
    {
      "x": -7,
      "y": 30,
      "z": 4,
      "name": "Rock_Sandstone_Red"
    },
    {
      "x": -7,
      "y": 31,
      "z": 4,
      "name": "Rock_Sandstone_Red"
    },
    {
      "x": -7,
      "y": 32,
      "z": 4,
      "name": "Soil_Clay_Orange"
    },
    {
      "x": -7,
      "y": 33,
      "z": 4,
      "name": "Soil_Clay_Orange"
    },
    {
      "x": -7,
      "y": 34,
      "z": 4,
      "name": "Rock_Sandstone"
    },
    {
      "x": -7,
      "y": 35,
      "z": 4,
      "name": "Rock_Sandstone_Red"
    },
    {
      "x": -7,
      "y": 36,
      "z": 4,
      "name": "Rock_Sandstone_Red"
    },
    {
      "x": -7,
      "y": 37,
      "z": 4,
      "name": "Rock_Sandstone"
    },
    {
      "x": -7,
      "y": 38,
      "z": 4,
      "name": "Rock_Sandstone_Red"
    },
    {
      "x": -7,
      "y": 39,
      "z": 4,
      "name": "Rock_Sandstone_Red"
    },
    {
      "x": -7,
      "y": 40,
      "z": 4,
      "name": "Rock_Sandstone_Red"
    },
    {
      "x": -7,
      "y": 41,
      "z": 4,
      "name": "Soil_Clay_Orange"
    },
    {
      "x": -7,
      "y": 42,
      "z": 4,
      "name": "Rock_Sandstone_Red"
    },
    {
      "x": -7,
      "y": 43,
      "z": 4,
      "name": "Rock_Sandstone_Red"
    },
    {
      "x": -7,
      "y": 44,
      "z": 4,
      "name": "Rock_Sandstone_Red"
    },
    {
      "x": -7,
      "y": 45,
      "z": 4,
      "name": "Rock_Sandstone_Red"
    },
    {
      "x": -7,
      "y": 46,
      "z": 4,
      "name": "Rock_Sandstone_Red"
    },
    {
      "x": -7,
      "y": 47,
      "z": 4,
      "name": "Soil_Clay_Orange"
    },
    {
      "x": -7,
      "y": 48,
      "z": 4,
      "name": "Soil_Clay_Orange"
    },
    {
      "x": -7,
      "y": 49,
      "z": 4,
      "name": "Soil_Clay_Smooth_Red"
    },
    {
      "x": -7,
      "y": 30,
      "z": 5,
      "name": "Rock_Sandstone_Red"
    },
    {
      "x": -7,
      "y": 31,
      "z": 5,
      "name": "Rock_Sandstone_Red"
    },
    {
      "x": -7,
      "y": 32,
      "z": 5,
      "name": "Soil_Clay_Orange"
    },
    {
      "x": -7,
      "y": 33,
      "z": 5,
      "name": "Soil_Clay_Orange"
    },
    {
      "x": -7,
      "y": 34,
      "z": 5,
      "name": "Rock_Sandstone"
    },
    {
      "x": -7,
      "y": 35,
      "z": 5,
      "name": "Rock_Sandstone_Red"
    },
    {
      "x": -7,
      "y": 36,
      "z": 5,
      "name": "Rock_Sandstone_Red"
    },
    {
      "x": -7,
      "y": 37,
      "z": 5,
      "name": "Rock_Sandstone"
    },
    {
      "x": -7,
      "y": 38,
      "z": 5,
      "name": "Soil_Clay_Orange"
    },
    {
      "x": -7,
      "y": 39,
      "z": 5,
      "name": "Rock_Sandstone_Red"
    },
    {
      "x": -7,
      "y": 40,
      "z": 5,
      "name": "Rock_Sandstone"
    },
    {
      "x": -7,
      "y": 41,
      "z": 5,
      "name": "Soil_Clay_Orange"
    },
    {
      "x": -7,
      "y": 42,
      "z": 5,
      "name": "Soil_Clay_Orange"
    },
    {
      "x": -7,
      "y": 43,
      "z": 5,
      "name": "Rock_Sandstone_Red"
    },
    {
      "x": -7,
      "y": 44,
      "z": 5,
      "name": "Rock_Sandstone_Red"
    },
    {
      "x": -7,
      "y": 45,
      "z": 5,
      "name": "Rock_Sandstone_Red"
    },
    {
      "x": -7,
      "y": 46,
      "z": 5,
      "name": "Rock_Sandstone_Red"
    },
    {
      "x": -7,
      "y": 47,
      "z": 5,
      "name": "Rock_Sandstone_Red"
    },
    {
      "x": -7,
      "y": 48,
      "z": 5,
      "name": "Soil_Clay_Orange"
    },
    {
      "x": -7,
      "y": 49,
      "z": 5,
      "name": "Soil_Clay_Smooth_Red"
    },
    {
      "x": -7,
      "y": 31,
      "z": 6,
      "name": "Soil_Clay_Orange"
    },
    {
      "x": -7,
      "y": 32,
      "z": 6,
      "name": "Soil_Clay_Orange"
    },
    {
      "x": -7,
      "y": 33,
      "z": 6,
      "name": "Soil_Clay_Orange"
    },
    {
      "x": -7,
      "y": 34,
      "z": 6,
      "name": "Rock_Sandstone"
    },
    {
      "x": -7,
      "y": 35,
      "z": 6,
      "name": "Rock_Sandstone_Red"
    },
    {
      "x": -7,
      "y": 36,
      "z": 6,
      "name": "Rock_Sandstone_Red"
    },
    {
      "x": -7,
      "y": 37,
      "z": 6,
      "name": "Rock_Sandstone"
    },
    {
      "x": -7,
      "y": 38,
      "z": 6,
      "name": "Soil_Clay_Orange"
    },
    {
      "x": -7,
      "y": 39,
      "z": 6,
      "name": "Soil_Clay_Orange"
    },
    {
      "x": -7,
      "y": 40,
      "z": 6,
      "name": "Rock_Sandstone"
    },
    {
      "x": -7,
      "y": 41,
      "z": 6,
      "name": "Soil_Clay_Orange"
    },
    {
      "x": -7,
      "y": 42,
      "z": 6,
      "name": "Soil_Clay_Orange"
    },
    {
      "x": -7,
      "y": 43,
      "z": 6,
      "name": "Rock_Sandstone_Red"
    },
    {
      "x": -7,
      "y": 44,
      "z": 6,
      "name": "Rock_Sandstone_Red"
    },
    {
      "x": -7,
      "y": 45,
      "z": 6,
      "name": "Rock_Sandstone_Red"
    },
    {
      "x": -7,
      "y": 46,
      "z": 6,
      "name": "Rock_Sandstone_Red"
    },
    {
      "x": -7,
      "y": 47,
      "z": 6,
      "name": "Rock_Sandstone_Red"
    },
    {
      "x": -7,
      "y": 48,
      "z": 6,
      "name": "Rock_Sandstone_Red"
    },
    {
      "x": -7,
      "y": 49,
      "z": 6,
      "name": "Soil_Clay_Smooth_Red"
    },
    {
      "x": -7,
      "y": 32,
      "z": 7,
      "name": "Soil_Clay_Orange"
    },
    {
      "x": -7,
      "y": 33,
      "z": 7,
      "name": "Soil_Clay_Orange"
    },
    {
      "x": -7,
      "y": 34,
      "z": 7,
      "name": "Rock_Sandstone"
    },
    {
      "x": -7,
      "y": 35,
      "z": 7,
      "name": "Rock_Sandstone_Red"
    },
    {
      "x": -7,
      "y": 36,
      "z": 7,
      "name": "Rock_Sandstone_Red"
    },
    {
      "x": -7,
      "y": 37,
      "z": 7,
      "name": "Rock_Sandstone"
    },
    {
      "x": -7,
      "y": 38,
      "z": 7,
      "name": "Soil_Clay_Orange"
    },
    {
      "x": -7,
      "y": 39,
      "z": 7,
      "name": "Soil_Clay_Orange"
    },
    {
      "x": -7,
      "y": 40,
      "z": 7,
      "name": "Soil_Clay_Orange"
    },
    {
      "x": -7,
      "y": 41,
      "z": 7,
      "name": "Soil_Clay_Orange"
    },
    {
      "x": -7,
      "y": 42,
      "z": 7,
      "name": "Soil_Clay_Orange"
    },
    {
      "x": -7,
      "y": 43,
      "z": 7,
      "name": "Soil_Clay_Orange"
    },
    {
      "x": -7,
      "y": 44,
      "z": 7,
      "name": "Rock_Sandstone_Red"
    },
    {
      "x": -7,
      "y": 45,
      "z": 7,
      "name": "Rock_Sandstone_Red"
    },
    {
      "x": -7,
      "y": 46,
      "z": 7,
      "name": "Rock_Sandstone_Red"
    },
    {
      "x": -7,
      "y": 47,
      "z": 7,
      "name": "Rock_Sandstone_Red"
    },
    {
      "x": -7,
      "y": 48,
      "z": 7,
      "name": "Rock_Sandstone_Red"
    },
    {
      "x": -7,
      "y": 49,
      "z": 7,
      "name": "Soil_Clay_Smooth_Red"
    },
    {
      "x": -7,
      "y": 32,
      "z": 8,
      "name": "Soil_Clay_Orange"
    },
    {
      "x": -7,
      "y": 33,
      "z": 8,
      "name": "Soil_Clay_Orange"
    },
    {
      "x": -7,
      "y": 34,
      "z": 8,
      "name": "Rock_Sandstone"
    },
    {
      "x": -7,
      "y": 35,
      "z": 8,
      "name": "Rock_Sandstone_Red"
    },
    {
      "x": -7,
      "y": 36,
      "z": 8,
      "name": "Soil_Clay_Orange"
    },
    {
      "x": -7,
      "y": 37,
      "z": 8,
      "name": "Rock_Sandstone"
    },
    {
      "x": -7,
      "y": 38,
      "z": 8,
      "name": "Soil_Clay_Orange"
    },
    {
      "x": -7,
      "y": 39,
      "z": 8,
      "name": "Soil_Clay_Orange"
    },
    {
      "x": -7,
      "y": 40,
      "z": 8,
      "name": "Soil_Clay_Orange"
    },
    {
      "x": -7,
      "y": 41,
      "z": 8,
      "name": "Rock_Sandstone_Red"
    },
    {
      "x": -7,
      "y": 42,
      "z": 8,
      "name": "Soil_Clay_Orange"
    },
    {
      "x": -7,
      "y": 43,
      "z": 8,
      "name": "Soil_Clay_Orange"
    },
    {
      "x": -7,
      "y": 44,
      "z": 8,
      "name": "Soil_Clay_Orange"
    },
    {
      "x": -7,
      "y": 47,
      "z": 8,
      "name": "Rock_Sandstone_Red"
    },
    {
      "x": -7,
      "y": 48,
      "z": 8,
      "name": "Rock_Sandstone_Red"
    },
    {
      "x": -6,
      "y": 2,
      "z": -5,
      "name": "Rock_Sandstone_Red"
    },
    {
      "x": -6,
      "y": 3,
      "z": -5,
      "name": "Rock_Sandstone_Red"
    },
    {
      "x": -6,
      "y": 4,
      "z": -5,
      "name": "Rock_Sandstone_Red"
    },
    {
      "x": -6,
      "y": 5,
      "z": -5,
      "name": "Rock_Sandstone"
    },
    {
      "x": -6,
      "y": 8,
      "z": -5,
      "name": "Soil_Clay_Orange"
    },
    {
      "x": -6,
      "y": 9,
      "z": -5,
      "name": "Rock_Sandstone"
    },
    {
      "x": -6,
      "y": 10,
      "z": -5,
      "name": "Soil_Clay_Orange"
    },
    {
      "x": -6,
      "y": 11,
      "z": -5,
      "name": "Soil_Clay_Orange"
    },
    {
      "x": -6,
      "y": 12,
      "z": -5,
      "name": "Soil_Clay_Orange"
    },
    {
      "x": -6,
      "y": 13,
      "z": -5,
      "name": "Rock_Sandstone_Red"
    },
    {
      "x": -6,
      "y": 14,
      "z": -5,
      "name": "Soil_Clay_Orange"
    },
    {
      "x": -6,
      "y": 15,
      "z": -5,
      "name": "Rock_Sandstone"
    },
    {
      "x": -6,
      "y": 22,
      "z": -5,
      "name": "Soil_Clay_Yellow"
    },
    {
      "x": -6,
      "y": 23,
      "z": -5,
      "name": "Rock_Sandstone"
    },
    {
      "x": -6,
      "y": 24,
      "z": -5,
      "name": "Rock_Sandstone_Red"
    },
    {
      "x": -6,
      "y": 25,
      "z": -5,
      "name": "Rock_Sandstone_Red"
    },
    {
      "x": -6,
      "y": 29,
      "z": -5,
      "name": "Rock_Sandstone_Red"
    },
    {
      "x": -6,
      "y": 30,
      "z": -5,
      "name": "Rock_Sandstone_Red"
    },
    {
      "x": -6,
      "y": 31,
      "z": -5,
      "name": "Rock_Sandstone_Red"
    },
    {
      "x": -6,
      "y": 32,
      "z": -5,
      "name": "Rock_Sandstone"
    },
    {
      "x": -6,
      "y": 33,
      "z": -5,
      "name": "Rock_Sandstone"
    },
    {
      "x": -6,
      "y": 34,
      "z": -5,
      "name": "Soil_Clay_Orange"
    },
    {
      "x": -6,
      "y": 35,
      "z": -5,
      "name": "Rock_Sandstone_Red"
    },
    {
      "x": -6,
      "y": 36,
      "z": -5,
      "name": "Soil_Clay_Orange"
    },
    {
      "x": -6,
      "y": 37,
      "z": -5,
      "name": "Rock_Sandstone"
    },
    {
      "x": -6,
      "y": 38,
      "z": -5,
      "name": "Rock_Sandstone_Red"
    },
    {
      "x": -6,
      "y": 39,
      "z": -5,
      "name": "Rock_Sandstone_Red"
    },
    {
      "x": -6,
      "y": 40,
      "z": -5,
      "name": "Soil_Clay_Orange"
    },
    {
      "x": -6,
      "y": 41,
      "z": -5,
      "name": "Soil_Clay_Orange"
    },
    {
      "x": -6,
      "y": 42,
      "z": -5,
      "name": "Rock_Sandstone_Red"
    },
    {
      "x": -6,
      "y": 43,
      "z": -5,
      "name": "Rock_Sandstone_Red"
    },
    {
      "x": -6,
      "y": 44,
      "z": -5,
      "name": "Rock_Sandstone_Red"
    },
    {
      "x": -6,
      "y": 45,
      "z": -5,
      "name": "Soil_Clay_Orange"
    },
    {
      "x": -6,
      "y": 46,
      "z": -5,
      "name": "Rock_Sandstone_Red"
    },
    {
      "x": -6,
      "y": 47,
      "z": -5,
      "name": "Rock_Sandstone_Red"
    },
    {
      "x": -6,
      "y": 48,
      "z": -5,
      "name": "Rock_Sandstone_Red"
    },
    {
      "x": -6,
      "y": 1,
      "z": -4,
      "name": "Rock_Sandstone_Red"
    },
    {
      "x": -6,
      "y": 2,
      "z": -4,
      "name": "Rock_Sandstone_Red"
    },
    {
      "x": -6,
      "y": 3,
      "z": -4,
      "name": "Rock_Sandstone_Red"
    },
    {
      "x": -6,
      "y": 4,
      "z": -4,
      "name": "Rock_Sandstone_Red"
    },
    {
      "x": -6,
      "y": 5,
      "z": -4,
      "name": "Rock_Sandstone"
    },
    {
      "x": -6,
      "y": 6,
      "z": -4,
      "name": "Soil_Clay_Yellow"
    },
    {
      "x": -6,
      "y": 8,
      "z": -4,
      "name": "Soil_Clay_Orange"
    },
    {
      "x": -6,
      "y": 9,
      "z": -4,
      "name": "Soil_Clay_Orange"
    },
    {
      "x": -6,
      "y": 10,
      "z": -4,
      "name": "Soil_Clay_Orange"
    },
    {
      "x": -6,
      "y": 11,
      "z": -4,
      "name": "Soil_Clay_Orange"
    },
    {
      "x": -6,
      "y": 12,
      "z": -4,
      "name": "Soil_Clay_Orange"
    },
    {
      "x": -6,
      "y": 13,
      "z": -4,
      "name": "Rock_Sandstone_Red"
    },
    {
      "x": -6,
      "y": 14,
      "z": -4,
      "name": "Soil_Clay_Orange"
    },
    {
      "x": -6,
      "y": 15,
      "z": -4,
      "name": "Rock_Sandstone"
    },
    {
      "x": -6,
      "y": 16,
      "z": -4,
      "name": "Rock_Sandstone_Red"
    },
    {
      "x": -6,
      "y": 17,
      "z": -4,
      "name": "Rock_Sandstone_Red"
    },
    {
      "x": -6,
      "y": 18,
      "z": -4,
      "name": "Soil_Clay_Orange"
    },
    {
      "x": -6,
      "y": 22,
      "z": -4,
      "name": "Soil_Clay_Yellow"
    },
    {
      "x": -6,
      "y": 23,
      "z": -4,
      "name": "Rock_Sandstone"
    },
    {
      "x": -6,
      "y": 24,
      "z": -4,
      "name": "Rock_Sandstone_Red"
    },
    {
      "x": -6,
      "y": 25,
      "z": -4,
      "name": "Rock_Sandstone_Red"
    },
    {
      "x": -6,
      "y": 26,
      "z": -4,
      "name": "Rock_Sandstone_Red"
    },
    {
      "x": -6,
      "y": 29,
      "z": -4,
      "name": "Rock_Sandstone_Red"
    },
    {
      "x": -6,
      "y": 30,
      "z": -4,
      "name": "Rock_Sandstone_Red"
    },
    {
      "x": -6,
      "y": 31,
      "z": -4,
      "name": "Rock_Sandstone_Red"
    },
    {
      "x": -6,
      "y": 32,
      "z": -4,
      "name": "Rock_Sandstone"
    },
    {
      "x": -6,
      "y": 33,
      "z": -4,
      "name": "Rock_Sandstone"
    },
    {
      "x": -6,
      "y": 34,
      "z": -4,
      "name": "Rock_Sandstone_Red"
    },
    {
      "x": -6,
      "y": 35,
      "z": -4,
      "name": "Rock_Sandstone_Red"
    },
    {
      "x": -6,
      "y": 36,
      "z": -4,
      "name": "Rock_Sandstone_Red"
    },
    {
      "x": -6,
      "y": 37,
      "z": -4,
      "name": "Rock_Sandstone"
    },
    {
      "x": -6,
      "y": 38,
      "z": -4,
      "name": "Rock_Sandstone_Red"
    },
    {
      "x": -6,
      "y": 39,
      "z": -4,
      "name": "Rock_Sandstone_Red"
    },
    {
      "x": -6,
      "y": 40,
      "z": -4,
      "name": "Soil_Clay_Orange"
    },
    {
      "x": -6,
      "y": 41,
      "z": -4,
      "name": "Rock_Sandstone_Red"
    },
    {
      "x": -6,
      "y": 42,
      "z": -4,
      "name": "Rock_Sandstone_Red"
    },
    {
      "x": -6,
      "y": 43,
      "z": -4,
      "name": "Rock_Sandstone_Red"
    },
    {
      "x": -6,
      "y": 44,
      "z": -4,
      "name": "Rock_Sandstone_Red"
    },
    {
      "x": -6,
      "y": 45,
      "z": -4,
      "name": "Soil_Clay_Orange"
    },
    {
      "x": -6,
      "y": 46,
      "z": -4,
      "name": "Soil_Clay_Orange"
    },
    {
      "x": -6,
      "y": 47,
      "z": -4,
      "name": "Rock_Sandstone_Red"
    },
    {
      "x": -6,
      "y": 48,
      "z": -4,
      "name": "Soil_Clay_Smooth_Red"
    },
    {
      "x": -6,
      "y": 1,
      "z": -3,
      "name": "Rock_Sandstone_Red"
    },
    {
      "x": -6,
      "y": 2,
      "z": -3,
      "name": "Rock_Sandstone_Red"
    },
    {
      "x": -6,
      "y": 3,
      "z": -3,
      "name": "Rock_Sandstone_Red"
    },
    {
      "x": -6,
      "y": 4,
      "z": -3,
      "name": "Rock_Sandstone_Red"
    },
    {
      "x": -6,
      "y": 5,
      "z": -3,
      "name": "Rock_Sandstone"
    },
    {
      "x": -6,
      "y": 6,
      "z": -3,
      "name": "Soil_Clay_Yellow"
    },
    {
      "x": -6,
      "y": 8,
      "z": -3,
      "name": "Soil_Clay_Orange"
    },
    {
      "x": -6,
      "y": 9,
      "z": -3,
      "name": "Soil_Clay_Orange"
    },
    {
      "x": -6,
      "y": 10,
      "z": -3,
      "name": "Soil_Clay_Orange"
    },
    {
      "x": -6,
      "y": 11,
      "z": -3,
      "name": "Soil_Clay_Orange"
    },
    {
      "x": -6,
      "y": 12,
      "z": -3,
      "name": "Soil_Clay_Orange"
    },
    {
      "x": -6,
      "y": 13,
      "z": -3,
      "name": "Soil_Clay_Orange"
    },
    {
      "x": -6,
      "y": 14,
      "z": -3,
      "name": "Soil_Clay_Orange"
    },
    {
      "x": -6,
      "y": 15,
      "z": -3,
      "name": "Rock_Sandstone"
    },
    {
      "x": -6,
      "y": 16,
      "z": -3,
      "name": "Rock_Sandstone_Red"
    },
    {
      "x": -6,
      "y": 17,
      "z": -3,
      "name": "Rock_Sandstone_Red"
    },
    {
      "x": -6,
      "y": 18,
      "z": -3,
      "name": "Soil_Clay_Orange"
    },
    {
      "x": -6,
      "y": 21,
      "z": -3,
      "name": "Rock_Sandstone"
    },
    {
      "x": -6,
      "y": 22,
      "z": -3,
      "name": "Soil_Clay_Yellow"
    },
    {
      "x": -6,
      "y": 23,
      "z": -3,
      "name": "Rock_Sandstone"
    },
    {
      "x": -6,
      "y": 24,
      "z": -3,
      "name": "Rock_Sandstone_Red"
    },
    {
      "x": -6,
      "y": 25,
      "z": -3,
      "name": "Rock_Sandstone_Red"
    },
    {
      "x": -6,
      "y": 26,
      "z": -3,
      "name": "Soil_Clay_Smooth_Red"
    },
    {
      "x": -6,
      "y": 27,
      "z": -3,
      "name": "Rock_Sandstone_Red"
    },
    {
      "x": -6,
      "y": 29,
      "z": -3,
      "name": "Rock_Sandstone_Red"
    },
    {
      "x": -6,
      "y": 30,
      "z": -3,
      "name": "Rock_Sandstone_Red"
    },
    {
      "x": -6,
      "y": 31,
      "z": -3,
      "name": "Rock_Sandstone_Red"
    },
    {
      "x": -6,
      "y": 32,
      "z": -3,
      "name": "Rock_Sandstone"
    },
    {
      "x": -6,
      "y": 33,
      "z": -3,
      "name": "Rock_Sandstone"
    },
    {
      "x": -6,
      "y": 34,
      "z": -3,
      "name": "Rock_Sandstone_Red"
    },
    {
      "x": -6,
      "y": 35,
      "z": -3,
      "name": "Rock_Sandstone_Red"
    },
    {
      "x": -6,
      "y": 36,
      "z": -3,
      "name": "Rock_Sandstone_Red"
    },
    {
      "x": -6,
      "y": 37,
      "z": -3,
      "name": "Rock_Sandstone"
    },
    {
      "x": -6,
      "y": 38,
      "z": -3,
      "name": "Rock_Sandstone_Red"
    },
    {
      "x": -6,
      "y": 39,
      "z": -3,
      "name": "Rock_Sandstone_Red"
    },
    {
      "x": -6,
      "y": 40,
      "z": -3,
      "name": "Soil_Clay_Orange"
    },
    {
      "x": -6,
      "y": 41,
      "z": -3,
      "name": "Rock_Sandstone_Red"
    },
    {
      "x": -6,
      "y": 42,
      "z": -3,
      "name": "Rock_Sandstone_Red"
    },
    {
      "x": -6,
      "y": 43,
      "z": -3,
      "name": "Rock_Sandstone_Red"
    },
    {
      "x": -6,
      "y": 44,
      "z": -3,
      "name": "Rock_Sandstone_Red"
    },
    {
      "x": -6,
      "y": 45,
      "z": -3,
      "name": "Soil_Clay_Orange"
    },
    {
      "x": -6,
      "y": 46,
      "z": -3,
      "name": "Soil_Clay_Orange"
    },
    {
      "x": -6,
      "y": 47,
      "z": -3,
      "name": "Rock_Sandstone_Red"
    },
    {
      "x": -6,
      "y": 48,
      "z": -3,
      "name": "Soil_Clay_Smooth_Red"
    },
    {
      "x": -6,
      "y": 1,
      "z": -2,
      "name": "Rock_Sandstone_Red"
    },
    {
      "x": -6,
      "y": 2,
      "z": -2,
      "name": "Rock_Sandstone_Red"
    },
    {
      "x": -6,
      "y": 3,
      "z": -2,
      "name": "Rock_Sandstone_Red"
    },
    {
      "x": -6,
      "y": 4,
      "z": -2,
      "name": "Rock_Sandstone_Red"
    },
    {
      "x": -6,
      "y": 5,
      "z": -2,
      "name": "Rock_Sandstone"
    },
    {
      "x": -6,
      "y": 6,
      "z": -2,
      "name": "Soil_Clay_Yellow"
    },
    {
      "x": -6,
      "y": 8,
      "z": -2,
      "name": "Soil_Clay_Orange"
    },
    {
      "x": -6,
      "y": 9,
      "z": -2,
      "name": "Soil_Clay_Orange"
    },
    {
      "x": -6,
      "y": 10,
      "z": -2,
      "name": "Soil_Clay_Orange"
    },
    {
      "x": -6,
      "y": 11,
      "z": -2,
      "name": "Soil_Clay_Orange"
    },
    {
      "x": -6,
      "y": 12,
      "z": -2,
      "name": "Soil_Clay_Orange"
    },
    {
      "x": -6,
      "y": 13,
      "z": -2,
      "name": "Rock_Sandstone_Red"
    },
    {
      "x": -6,
      "y": 14,
      "z": -2,
      "name": "Soil_Clay_Orange"
    },
    {
      "x": -6,
      "y": 15,
      "z": -2,
      "name": "Rock_Sandstone"
    },
    {
      "x": -6,
      "y": 16,
      "z": -2,
      "name": "Rock_Sandstone_Red"
    },
    {
      "x": -6,
      "y": 17,
      "z": -2,
      "name": "Rock_Sandstone_Red"
    },
    {
      "x": -6,
      "y": 18,
      "z": -2,
      "name": "Soil_Clay_Orange"
    },
    {
      "x": -6,
      "y": 21,
      "z": -2,
      "name": "Rock_Sandstone"
    },
    {
      "x": -6,
      "y": 22,
      "z": -2,
      "name": "Soil_Clay_Yellow"
    },
    {
      "x": -6,
      "y": 23,
      "z": -2,
      "name": "Rock_Sandstone"
    },
    {
      "x": -6,
      "y": 24,
      "z": -2,
      "name": "Rock_Sandstone_Red"
    },
    {
      "x": -6,
      "y": 25,
      "z": -2,
      "name": "Rock_Sandstone_Red"
    },
    {
      "x": -6,
      "y": 26,
      "z": -2,
      "name": "Rock_Sandstone_Red"
    },
    {
      "x": -6,
      "y": 27,
      "z": -2,
      "name": "Rock_Sandstone_Red"
    },
    {
      "x": -6,
      "y": 29,
      "z": -2,
      "name": "Rock_Sandstone_Red"
    },
    {
      "x": -6,
      "y": 30,
      "z": -2,
      "name": "Rock_Sandstone_Red"
    },
    {
      "x": -6,
      "y": 31,
      "z": -2,
      "name": "Rock_Sandstone_Red"
    },
    {
      "x": -6,
      "y": 32,
      "z": -2,
      "name": "Rock_Sandstone"
    },
    {
      "x": -6,
      "y": 33,
      "z": -2,
      "name": "Soil_Clay_Orange"
    },
    {
      "x": -6,
      "y": 34,
      "z": -2,
      "name": "Rock_Sandstone"
    },
    {
      "x": -6,
      "y": 35,
      "z": -2,
      "name": "Rock_Sandstone_Red"
    },
    {
      "x": -6,
      "y": 36,
      "z": -2,
      "name": "Rock_Sandstone_Red"
    },
    {
      "x": -6,
      "y": 37,
      "z": -2,
      "name": "Rock_Sandstone"
    },
    {
      "x": -6,
      "y": 38,
      "z": -2,
      "name": "Rock_Sandstone_Red"
    },
    {
      "x": -6,
      "y": 39,
      "z": -2,
      "name": "Rock_Sandstone_Red"
    },
    {
      "x": -6,
      "y": 40,
      "z": -2,
      "name": "Rock_Sandstone_Red"
    },
    {
      "x": -6,
      "y": 41,
      "z": -2,
      "name": "Rock_Sandstone_Red"
    },
    {
      "x": -6,
      "y": 42,
      "z": -2,
      "name": "Rock_Sandstone_Red"
    },
    {
      "x": -6,
      "y": 43,
      "z": -2,
      "name": "Rock_Sandstone_Red"
    },
    {
      "x": -6,
      "y": 44,
      "z": -2,
      "name": "Rock_Sandstone_Red"
    },
    {
      "x": -6,
      "y": 45,
      "z": -2,
      "name": "Soil_Clay_Orange"
    },
    {
      "x": -6,
      "y": 46,
      "z": -2,
      "name": "Soil_Clay_Orange"
    },
    {
      "x": -6,
      "y": 47,
      "z": -2,
      "name": "Soil_Clay_Orange"
    },
    {
      "x": -6,
      "y": 48,
      "z": -2,
      "name": "Rock_Sandstone_Red"
    },
    {
      "x": -6,
      "y": 1,
      "z": -1,
      "name": "Rock_Sandstone_Red"
    },
    {
      "x": -6,
      "y": 2,
      "z": -1,
      "name": "Rock_Sandstone_Red"
    },
    {
      "x": -6,
      "y": 3,
      "z": -1,
      "name": "Rock_Sandstone_Red"
    },
    {
      "x": -6,
      "y": 4,
      "z": -1,
      "name": "Rock_Sandstone_Red"
    },
    {
      "x": -6,
      "y": 5,
      "z": -1,
      "name": "Rock_Sandstone"
    },
    {
      "x": -6,
      "y": 6,
      "z": -1,
      "name": "Soil_Clay_Yellow"
    },
    {
      "x": -6,
      "y": 8,
      "z": -1,
      "name": "Soil_Clay_Orange"
    },
    {
      "x": -6,
      "y": 9,
      "z": -1,
      "name": "Soil_Clay_Orange"
    },
    {
      "x": -6,
      "y": 10,
      "z": -1,
      "name": "Soil_Clay_Orange"
    },
    {
      "x": -6,
      "y": 11,
      "z": -1,
      "name": "Soil_Clay_Orange"
    },
    {
      "x": -6,
      "y": 12,
      "z": -1,
      "name": "Rock_Sandstone_Red"
    },
    {
      "x": -6,
      "y": 13,
      "z": -1,
      "name": "Rock_Sandstone_Red"
    },
    {
      "x": -6,
      "y": 14,
      "z": -1,
      "name": "Rock_Sandstone_Red"
    },
    {
      "x": -6,
      "y": 15,
      "z": -1,
      "name": "Rock_Sandstone"
    },
    {
      "x": -6,
      "y": 16,
      "z": -1,
      "name": "Rock_Sandstone_Red"
    },
    {
      "x": -6,
      "y": 17,
      "z": -1,
      "name": "Rock_Sandstone_Red"
    },
    {
      "x": -6,
      "y": 18,
      "z": -1,
      "name": "Soil_Clay_Smooth_Red"
    },
    {
      "x": -6,
      "y": 22,
      "z": -1,
      "name": "Soil_Clay_Yellow"
    },
    {
      "x": -6,
      "y": 23,
      "z": -1,
      "name": "Rock_Sandstone"
    },
    {
      "x": -6,
      "y": 24,
      "z": -1,
      "name": "Rock_Sandstone_Red"
    },
    {
      "x": -6,
      "y": 25,
      "z": -1,
      "name": "Rock_Sandstone_Red"
    },
    {
      "x": -6,
      "y": 26,
      "z": -1,
      "name": "Rock_Sandstone_Red"
    },
    {
      "x": -6,
      "y": 27,
      "z": -1,
      "name": "Rock_Sandstone_Red"
    },
    {
      "x": -6,
      "y": 29,
      "z": -1,
      "name": "Rock_Sandstone_Red"
    },
    {
      "x": -6,
      "y": 30,
      "z": -1,
      "name": "Rock_Sandstone_Red"
    },
    {
      "x": -6,
      "y": 31,
      "z": -1,
      "name": "Rock_Sandstone_Red"
    },
    {
      "x": -6,
      "y": 32,
      "z": -1,
      "name": "Rock_Sandstone"
    },
    {
      "x": -6,
      "y": 33,
      "z": -1,
      "name": "Soil_Clay_Orange"
    },
    {
      "x": -6,
      "y": 34,
      "z": -1,
      "name": "Rock_Sandstone"
    },
    {
      "x": -6,
      "y": 35,
      "z": -1,
      "name": "Rock_Sandstone_Red"
    },
    {
      "x": -6,
      "y": 36,
      "z": -1,
      "name": "Rock_Sandstone_Red"
    },
    {
      "x": -6,
      "y": 37,
      "z": -1,
      "name": "Rock_Sandstone"
    },
    {
      "x": -6,
      "y": 38,
      "z": -1,
      "name": "Rock_Sandstone_Red"
    },
    {
      "x": -6,
      "y": 39,
      "z": -1,
      "name": "Rock_Sandstone_Red"
    },
    {
      "x": -6,
      "y": 40,
      "z": -1,
      "name": "Rock_Sandstone_Red"
    },
    {
      "x": -6,
      "y": 41,
      "z": -1,
      "name": "Rock_Sandstone_Red"
    },
    {
      "x": -6,
      "y": 42,
      "z": -1,
      "name": "Rock_Sandstone_Red"
    },
    {
      "x": -6,
      "y": 43,
      "z": -1,
      "name": "Rock_Sandstone_Red"
    },
    {
      "x": -6,
      "y": 44,
      "z": -1,
      "name": "Rock_Sandstone_Red"
    },
    {
      "x": -6,
      "y": 45,
      "z": -1,
      "name": "Soil_Clay_Orange"
    },
    {
      "x": -6,
      "y": 46,
      "z": -1,
      "name": "Soil_Clay_Orange"
    },
    {
      "x": -6,
      "y": 47,
      "z": -1,
      "name": "Soil_Clay_Orange"
    },
    {
      "x": -6,
      "y": 48,
      "z": -1,
      "name": "Soil_Clay_Orange"
    },
    {
      "x": -6,
      "y": 49,
      "z": -1,
      "name": "Soil_Clay_Smooth_Red"
    },
    {
      "x": -6,
      "y": 1,
      "z": 0,
      "name": "Rock_Sandstone_Red"
    },
    {
      "x": -6,
      "y": 2,
      "z": 0,
      "name": "Rock_Sandstone_Red"
    },
    {
      "x": -6,
      "y": 3,
      "z": 0,
      "name": "Rock_Sandstone_Red"
    },
    {
      "x": -6,
      "y": 4,
      "z": 0,
      "name": "Rock_Sandstone_Red"
    },
    {
      "x": -6,
      "y": 5,
      "z": 0,
      "name": "Soil_Clay_Orange"
    },
    {
      "x": -6,
      "y": 6,
      "z": 0,
      "name": "Soil_Clay_Yellow"
    },
    {
      "x": -6,
      "y": 8,
      "z": 0,
      "name": "Soil_Clay_Orange"
    },
    {
      "x": -6,
      "y": 9,
      "z": 0,
      "name": "Soil_Clay_Orange"
    },
    {
      "x": -6,
      "y": 10,
      "z": 0,
      "name": "Soil_Clay_Orange"
    },
    {
      "x": -6,
      "y": 11,
      "z": 0,
      "name": "Soil_Clay_Orange"
    },
    {
      "x": -6,
      "y": 12,
      "z": 0,
      "name": "Rock_Sandstone_Red"
    },
    {
      "x": -6,
      "y": 13,
      "z": 0,
      "name": "Rock_Sandstone_Red"
    },
    {
      "x": -6,
      "y": 14,
      "z": 0,
      "name": "Rock_Sandstone_Red"
    },
    {
      "x": -6,
      "y": 15,
      "z": 0,
      "name": "Rock_Sandstone"
    },
    {
      "x": -6,
      "y": 16,
      "z": 0,
      "name": "Rock_Sandstone_Red"
    },
    {
      "x": -6,
      "y": 17,
      "z": 0,
      "name": "Rock_Sandstone_Red"
    },
    {
      "x": -6,
      "y": 18,
      "z": 0,
      "name": "Soil_Clay_Smooth_Red"
    },
    {
      "x": -6,
      "y": 22,
      "z": 0,
      "name": "Soil_Clay_Yellow"
    },
    {
      "x": -6,
      "y": 23,
      "z": 0,
      "name": "Rock_Sandstone"
    },
    {
      "x": -6,
      "y": 24,
      "z": 0,
      "name": "Rock_Sandstone_Red"
    },
    {
      "x": -6,
      "y": 25,
      "z": 0,
      "name": "Rock_Sandstone_Red"
    },
    {
      "x": -6,
      "y": 26,
      "z": 0,
      "name": "Rock_Sandstone_Red"
    },
    {
      "x": -6,
      "y": 27,
      "z": 0,
      "name": "Rock_Sandstone_Red"
    },
    {
      "x": -6,
      "y": 29,
      "z": 0,
      "name": "Rock_Sandstone_Red"
    },
    {
      "x": -6,
      "y": 30,
      "z": 0,
      "name": "Rock_Sandstone_Red"
    },
    {
      "x": -6,
      "y": 31,
      "z": 0,
      "name": "Rock_Sandstone_Red"
    },
    {
      "x": -6,
      "y": 32,
      "z": 0,
      "name": "Soil_Clay_Orange"
    },
    {
      "x": -6,
      "y": 33,
      "z": 0,
      "name": "Soil_Clay_Orange"
    },
    {
      "x": -6,
      "y": 34,
      "z": 0,
      "name": "Rock_Sandstone"
    },
    {
      "x": -6,
      "y": 35,
      "z": 0,
      "name": "Rock_Sandstone_Red"
    },
    {
      "x": -6,
      "y": 36,
      "z": 0,
      "name": "Rock_Sandstone_Red"
    },
    {
      "x": -6,
      "y": 37,
      "z": 0,
      "name": "Rock_Sandstone"
    },
    {
      "x": -6,
      "y": 38,
      "z": 0,
      "name": "Rock_Sandstone_Red"
    },
    {
      "x": -6,
      "y": 39,
      "z": 0,
      "name": "Rock_Sandstone_Red"
    },
    {
      "x": -6,
      "y": 40,
      "z": 0,
      "name": "Rock_Sandstone_Red"
    },
    {
      "x": -6,
      "y": 41,
      "z": 0,
      "name": "Rock_Sandstone_Red"
    },
    {
      "x": -6,
      "y": 42,
      "z": 0,
      "name": "Rock_Sandstone_Red"
    },
    {
      "x": -6,
      "y": 43,
      "z": 0,
      "name": "Rock_Sandstone_Red"
    },
    {
      "x": -6,
      "y": 44,
      "z": 0,
      "name": "Rock_Sandstone_Red"
    },
    {
      "x": -6,
      "y": 45,
      "z": 0,
      "name": "Soil_Clay_Orange"
    },
    {
      "x": -6,
      "y": 46,
      "z": 0,
      "name": "Soil_Clay_Orange"
    },
    {
      "x": -6,
      "y": 47,
      "z": 0,
      "name": "Soil_Clay_Orange"
    },
    {
      "x": -6,
      "y": 48,
      "z": 0,
      "name": "Soil_Clay_Orange"
    },
    {
      "x": -6,
      "y": 49,
      "z": 0,
      "name": "Soil_Clay_Smooth_Red"
    },
    {
      "x": -6,
      "y": 1,
      "z": 1,
      "name": "Rock_Sandstone_Red"
    },
    {
      "x": -6,
      "y": 2,
      "z": 1,
      "name": "Rock_Sandstone_Red"
    },
    {
      "x": -6,
      "y": 3,
      "z": 1,
      "name": "Rock_Sandstone_Red"
    },
    {
      "x": -6,
      "y": 4,
      "z": 1,
      "name": "Rock_Sandstone_Red"
    },
    {
      "x": -6,
      "y": 5,
      "z": 1,
      "name": "Soil_Clay_Orange"
    },
    {
      "x": -6,
      "y": 6,
      "z": 1,
      "name": "Soil_Clay_Yellow"
    },
    {
      "x": -6,
      "y": 8,
      "z": 1,
      "name": "Soil_Clay_Orange"
    },
    {
      "x": -6,
      "y": 9,
      "z": 1,
      "name": "Soil_Clay_Orange"
    },
    {
      "x": -6,
      "y": 10,
      "z": 1,
      "name": "Soil_Clay_Orange"
    },
    {
      "x": -6,
      "y": 11,
      "z": 1,
      "name": "Soil_Clay_Orange"
    },
    {
      "x": -6,
      "y": 12,
      "z": 1,
      "name": "Rock_Sandstone_Red"
    },
    {
      "x": -6,
      "y": 13,
      "z": 1,
      "name": "Rock_Sandstone_Red"
    },
    {
      "x": -6,
      "y": 14,
      "z": 1,
      "name": "Rock_Sandstone_Red"
    },
    {
      "x": -6,
      "y": 15,
      "z": 1,
      "name": "Rock_Sandstone"
    },
    {
      "x": -6,
      "y": 16,
      "z": 1,
      "name": "Rock_Sandstone_Red"
    },
    {
      "x": -6,
      "y": 17,
      "z": 1,
      "name": "Rock_Sandstone_Red"
    },
    {
      "x": -6,
      "y": 18,
      "z": 1,
      "name": "Soil_Clay_Smooth_Red"
    },
    {
      "x": -6,
      "y": 22,
      "z": 1,
      "name": "Soil_Clay_Yellow"
    },
    {
      "x": -6,
      "y": 23,
      "z": 1,
      "name": "Rock_Sandstone"
    },
    {
      "x": -6,
      "y": 24,
      "z": 1,
      "name": "Rock_Sandstone_Red"
    },
    {
      "x": -6,
      "y": 25,
      "z": 1,
      "name": "Rock_Sandstone_Red"
    },
    {
      "x": -6,
      "y": 26,
      "z": 1,
      "name": "Rock_Sandstone_Red"
    },
    {
      "x": -6,
      "y": 27,
      "z": 1,
      "name": "Rock_Sandstone_Red"
    },
    {
      "x": -6,
      "y": 29,
      "z": 1,
      "name": "Rock_Sandstone_Red"
    },
    {
      "x": -6,
      "y": 30,
      "z": 1,
      "name": "Rock_Sandstone_Red"
    },
    {
      "x": -6,
      "y": 31,
      "z": 1,
      "name": "Rock_Sandstone_Red"
    },
    {
      "x": -6,
      "y": 32,
      "z": 1,
      "name": "Soil_Clay_Orange"
    },
    {
      "x": -6,
      "y": 33,
      "z": 1,
      "name": "Soil_Clay_Orange"
    },
    {
      "x": -6,
      "y": 34,
      "z": 1,
      "name": "Rock_Sandstone"
    },
    {
      "x": -6,
      "y": 35,
      "z": 1,
      "name": "Rock_Sandstone_Red"
    },
    {
      "x": -6,
      "y": 36,
      "z": 1,
      "name": "Rock_Sandstone_Red"
    },
    {
      "x": -6,
      "y": 37,
      "z": 1,
      "name": "Rock_Sandstone"
    },
    {
      "x": -6,
      "y": 38,
      "z": 1,
      "name": "Rock_Sandstone_Red"
    },
    {
      "x": -6,
      "y": 39,
      "z": 1,
      "name": "Rock_Sandstone_Red"
    },
    {
      "x": -6,
      "y": 40,
      "z": 1,
      "name": "Rock_Sandstone_Red"
    },
    {
      "x": -6,
      "y": 41,
      "z": 1,
      "name": "Rock_Sandstone_Red"
    },
    {
      "x": -6,
      "y": 42,
      "z": 1,
      "name": "Rock_Sandstone_Red"
    },
    {
      "x": -6,
      "y": 43,
      "z": 1,
      "name": "Rock_Sandstone_Red"
    },
    {
      "x": -6,
      "y": 44,
      "z": 1,
      "name": "Rock_Sandstone_Red"
    },
    {
      "x": -6,
      "y": 45,
      "z": 1,
      "name": "Soil_Clay_Orange"
    },
    {
      "x": -6,
      "y": 46,
      "z": 1,
      "name": "Soil_Clay_Orange"
    },
    {
      "x": -6,
      "y": 47,
      "z": 1,
      "name": "Soil_Clay_Orange"
    },
    {
      "x": -6,
      "y": 48,
      "z": 1,
      "name": "Soil_Clay_Orange"
    },
    {
      "x": -6,
      "y": 49,
      "z": 1,
      "name": "Soil_Clay_Smooth_Red"
    },
    {
      "x": -6,
      "y": 2,
      "z": 2,
      "name": "Rock_Sandstone_Red"
    },
    {
      "x": -6,
      "y": 3,
      "z": 2,
      "name": "Rock_Sandstone_Red"
    },
    {
      "x": -6,
      "y": 4,
      "z": 2,
      "name": "Rock_Sandstone_Red"
    },
    {
      "x": -6,
      "y": 5,
      "z": 2,
      "name": "Soil_Clay_Orange"
    },
    {
      "x": -6,
      "y": 6,
      "z": 2,
      "name": "Rock_Sandstone"
    },
    {
      "x": -6,
      "y": 9,
      "z": 2,
      "name": "Soil_Clay_Orange"
    },
    {
      "x": -6,
      "y": 10,
      "z": 2,
      "name": "Soil_Clay_Orange"
    },
    {
      "x": -6,
      "y": 11,
      "z": 2,
      "name": "Rock_Sandstone"
    },
    {
      "x": -6,
      "y": 12,
      "z": 2,
      "name": "Rock_Sandstone_Red"
    },
    {
      "x": -6,
      "y": 13,
      "z": 2,
      "name": "Rock_Sandstone_Red"
    },
    {
      "x": -6,
      "y": 14,
      "z": 2,
      "name": "Rock_Sandstone_Red"
    },
    {
      "x": -6,
      "y": 15,
      "z": 2,
      "name": "Rock_Sandstone"
    },
    {
      "x": -6,
      "y": 16,
      "z": 2,
      "name": "Rock_Sandstone_Red"
    },
    {
      "x": -6,
      "y": 17,
      "z": 2,
      "name": "Rock_Sandstone_Red"
    },
    {
      "x": -6,
      "y": 22,
      "z": 2,
      "name": "Soil_Clay_Yellow"
    },
    {
      "x": -6,
      "y": 23,
      "z": 2,
      "name": "Rock_Sandstone"
    },
    {
      "x": -6,
      "y": 24,
      "z": 2,
      "name": "Rock_Sandstone_Red"
    },
    {
      "x": -6,
      "y": 25,
      "z": 2,
      "name": "Rock_Sandstone_Red"
    },
    {
      "x": -6,
      "y": 26,
      "z": 2,
      "name": "Rock_Sandstone_Red"
    },
    {
      "x": -6,
      "y": 29,
      "z": 2,
      "name": "Rock_Sandstone_Red"
    },
    {
      "x": -6,
      "y": 30,
      "z": 2,
      "name": "Rock_Sandstone_Red"
    },
    {
      "x": -6,
      "y": 31,
      "z": 2,
      "name": "Rock_Sandstone_Red"
    },
    {
      "x": -6,
      "y": 32,
      "z": 2,
      "name": "Soil_Clay_Orange"
    },
    {
      "x": -6,
      "y": 33,
      "z": 2,
      "name": "Soil_Clay_Orange"
    },
    {
      "x": -6,
      "y": 34,
      "z": 2,
      "name": "Rock_Sandstone"
    },
    {
      "x": -6,
      "y": 35,
      "z": 2,
      "name": "Rock_Sandstone_Red"
    },
    {
      "x": -6,
      "y": 36,
      "z": 2,
      "name": "Rock_Sandstone_Red"
    },
    {
      "x": -6,
      "y": 37,
      "z": 2,
      "name": "Rock_Sandstone"
    },
    {
      "x": -6,
      "y": 38,
      "z": 2,
      "name": "Rock_Sandstone_Red"
    },
    {
      "x": -6,
      "y": 39,
      "z": 2,
      "name": "Rock_Sandstone_Red"
    },
    {
      "x": -6,
      "y": 40,
      "z": 2,
      "name": "Rock_Sandstone_Red"
    },
    {
      "x": -6,
      "y": 41,
      "z": 2,
      "name": "Rock_Sandstone_Red"
    },
    {
      "x": -6,
      "y": 42,
      "z": 2,
      "name": "Rock_Sandstone_Red"
    },
    {
      "x": -6,
      "y": 43,
      "z": 2,
      "name": "Rock_Sandstone_Red"
    },
    {
      "x": -6,
      "y": 44,
      "z": 2,
      "name": "Rock_Sandstone_Red"
    },
    {
      "x": -6,
      "y": 45,
      "z": 2,
      "name": "Soil_Clay_Orange"
    },
    {
      "x": -6,
      "y": 46,
      "z": 2,
      "name": "Soil_Clay_Orange"
    },
    {
      "x": -6,
      "y": 47,
      "z": 2,
      "name": "Soil_Clay_Orange"
    },
    {
      "x": -6,
      "y": 48,
      "z": 2,
      "name": "Soil_Clay_Orange"
    },
    {
      "x": -6,
      "y": 49,
      "z": 2,
      "name": "Soil_Clay_Smooth_Red"
    },
    {
      "x": -6,
      "y": 2,
      "z": 3,
      "name": "Rock_Sandstone_Red"
    },
    {
      "x": -6,
      "y": 3,
      "z": 3,
      "name": "Rock_Sandstone_Red"
    },
    {
      "x": -6,
      "y": 4,
      "z": 3,
      "name": "Rock_Sandstone_Red"
    },
    {
      "x": -6,
      "y": 5,
      "z": 3,
      "name": "Rock_Sandstone_Red"
    },
    {
      "x": -6,
      "y": 9,
      "z": 3,
      "name": "Soil_Clay_Orange"
    },
    {
      "x": -6,
      "y": 10,
      "z": 3,
      "name": "Soil_Clay_Orange"
    },
    {
      "x": -6,
      "y": 11,
      "z": 3,
      "name": "Rock_Sandstone"
    },
    {
      "x": -6,
      "y": 12,
      "z": 3,
      "name": "Rock_Sandstone_Red"
    },
    {
      "x": -6,
      "y": 13,
      "z": 3,
      "name": "Rock_Sandstone_Red"
    },
    {
      "x": -6,
      "y": 14,
      "z": 3,
      "name": "Rock_Sandstone_Red"
    },
    {
      "x": -6,
      "y": 15,
      "z": 3,
      "name": "Rock_Sandstone"
    },
    {
      "x": -6,
      "y": 16,
      "z": 3,
      "name": "Rock_Sandstone_Red"
    },
    {
      "x": -6,
      "y": 17,
      "z": 3,
      "name": "Soil_Clay_Orange"
    },
    {
      "x": -6,
      "y": 23,
      "z": 3,
      "name": "Rock_Sandstone"
    },
    {
      "x": -6,
      "y": 25,
      "z": 3,
      "name": "Rock_Sandstone_Red"
    },
    {
      "x": -6,
      "y": 29,
      "z": 3,
      "name": "Rock_Sandstone_Red"
    },
    {
      "x": -6,
      "y": 30,
      "z": 3,
      "name": "Rock_Sandstone_Red"
    },
    {
      "x": -6,
      "y": 31,
      "z": 3,
      "name": "Rock_Sandstone_Red"
    },
    {
      "x": -6,
      "y": 32,
      "z": 3,
      "name": "Soil_Clay_Orange"
    },
    {
      "x": -6,
      "y": 33,
      "z": 3,
      "name": "Soil_Clay_Orange"
    },
    {
      "x": -6,
      "y": 34,
      "z": 3,
      "name": "Rock_Sandstone"
    },
    {
      "x": -6,
      "y": 35,
      "z": 3,
      "name": "Rock_Sandstone_Red"
    },
    {
      "x": -6,
      "y": 36,
      "z": 3,
      "name": "Rock_Sandstone_Red"
    },
    {
      "x": -6,
      "y": 37,
      "z": 3,
      "name": "Rock_Sandstone"
    },
    {
      "x": -6,
      "y": 38,
      "z": 3,
      "name": "Rock_Sandstone_Red"
    },
    {
      "x": -6,
      "y": 39,
      "z": 3,
      "name": "Rock_Sandstone_Red"
    },
    {
      "x": -6,
      "y": 40,
      "z": 3,
      "name": "Rock_Sandstone_Red"
    },
    {
      "x": -6,
      "y": 41,
      "z": 3,
      "name": "Soil_Clay_Orange"
    },
    {
      "x": -6,
      "y": 42,
      "z": 3,
      "name": "Rock_Sandstone_Red"
    },
    {
      "x": -6,
      "y": 43,
      "z": 3,
      "name": "Rock_Sandstone_Red"
    },
    {
      "x": -6,
      "y": 44,
      "z": 3,
      "name": "Rock_Sandstone_Red"
    },
    {
      "x": -6,
      "y": 45,
      "z": 3,
      "name": "Rock_Sandstone_Red"
    },
    {
      "x": -6,
      "y": 46,
      "z": 3,
      "name": "Soil_Clay_Orange"
    },
    {
      "x": -6,
      "y": 47,
      "z": 3,
      "name": "Soil_Clay_Orange"
    },
    {
      "x": -6,
      "y": 48,
      "z": 3,
      "name": "Soil_Clay_Orange"
    },
    {
      "x": -6,
      "y": 49,
      "z": 3,
      "name": "Rock_Sandstone_Red"
    },
    {
      "x": -6,
      "y": 50,
      "z": 3,
      "name": "Soil_Clay_Smooth_Red"
    },
    {
      "x": -6,
      "y": 9,
      "z": 4,
      "name": "Soil_Clay_Orange"
    },
    {
      "x": -6,
      "y": 10,
      "z": 4,
      "name": "Soil_Clay_Orange"
    },
    {
      "x": -6,
      "y": 11,
      "z": 4,
      "name": "Rock_Sandstone"
    },
    {
      "x": -6,
      "y": 12,
      "z": 4,
      "name": "Rock_Sandstone_Red"
    },
    {
      "x": -6,
      "y": 13,
      "z": 4,
      "name": "Rock_Sandstone_Red"
    },
    {
      "x": -6,
      "y": 14,
      "z": 4,
      "name": "Rock_Sandstone_Red"
    },
    {
      "x": -6,
      "y": 15,
      "z": 4,
      "name": "Rock_Sandstone"
    },
    {
      "x": -6,
      "y": 29,
      "z": 4,
      "name": "Rock_Sandstone_Red"
    },
    {
      "x": -6,
      "y": 30,
      "z": 4,
      "name": "Rock_Sandstone_Red"
    },
    {
      "x": -6,
      "y": 31,
      "z": 4,
      "name": "Rock_Sandstone_Red"
    },
    {
      "x": -6,
      "y": 32,
      "z": 4,
      "name": "Soil_Clay_Orange"
    },
    {
      "x": -6,
      "y": 33,
      "z": 4,
      "name": "Soil_Clay_Orange"
    },
    {
      "x": -6,
      "y": 34,
      "z": 4,
      "name": "Rock_Sandstone"
    },
    {
      "x": -6,
      "y": 35,
      "z": 4,
      "name": "Rock_Sandstone_Red"
    },
    {
      "x": -6,
      "y": 36,
      "z": 4,
      "name": "Rock_Sandstone_Red"
    },
    {
      "x": -6,
      "y": 37,
      "z": 4,
      "name": "Rock_Sandstone"
    },
    {
      "x": -6,
      "y": 38,
      "z": 4,
      "name": "Rock_Sandstone_Red"
    },
    {
      "x": -6,
      "y": 39,
      "z": 4,
      "name": "Rock_Sandstone_Red"
    },
    {
      "x": -6,
      "y": 40,
      "z": 4,
      "name": "Rock_Sandstone"
    },
    {
      "x": -6,
      "y": 41,
      "z": 4,
      "name": "Soil_Clay_Orange"
    },
    {
      "x": -6,
      "y": 42,
      "z": 4,
      "name": "Soil_Clay_Orange"
    },
    {
      "x": -6,
      "y": 43,
      "z": 4,
      "name": "Rock_Sandstone_Red"
    },
    {
      "x": -6,
      "y": 44,
      "z": 4,
      "name": "Rock_Sandstone_Red"
    },
    {
      "x": -6,
      "y": 45,
      "z": 4,
      "name": "Rock_Sandstone_Red"
    },
    {
      "x": -6,
      "y": 46,
      "z": 4,
      "name": "Soil_Clay_Orange"
    },
    {
      "x": -6,
      "y": 47,
      "z": 4,
      "name": "Soil_Clay_Orange"
    },
    {
      "x": -6,
      "y": 48,
      "z": 4,
      "name": "Soil_Clay_Orange"
    },
    {
      "x": -6,
      "y": 49,
      "z": 4,
      "name": "Soil_Clay_Orange"
    },
    {
      "x": -6,
      "y": 50,
      "z": 4,
      "name": "Soil_Clay_Smooth_Red"
    },
    {
      "x": -6,
      "y": 30,
      "z": 5,
      "name": "Rock_Sandstone_Red"
    },
    {
      "x": -6,
      "y": 31,
      "z": 5,
      "name": "Rock_Sandstone_Red"
    },
    {
      "x": -6,
      "y": 32,
      "z": 5,
      "name": "Soil_Clay_Orange"
    },
    {
      "x": -6,
      "y": 33,
      "z": 5,
      "name": "Soil_Clay_Orange"
    },
    {
      "x": -6,
      "y": 34,
      "z": 5,
      "name": "Rock_Sandstone"
    },
    {
      "x": -6,
      "y": 35,
      "z": 5,
      "name": "Rock_Sandstone_Red"
    },
    {
      "x": -6,
      "y": 36,
      "z": 5,
      "name": "Rock_Sandstone_Red"
    },
    {
      "x": -6,
      "y": 37,
      "z": 5,
      "name": "Rock_Sandstone"
    },
    {
      "x": -6,
      "y": 38,
      "z": 5,
      "name": "Rock_Sandstone_Red"
    },
    {
      "x": -6,
      "y": 39,
      "z": 5,
      "name": "Rock_Sandstone_Red"
    },
    {
      "x": -6,
      "y": 40,
      "z": 5,
      "name": "Rock_Sandstone"
    },
    {
      "x": -6,
      "y": 41,
      "z": 5,
      "name": "Soil_Clay_Orange"
    },
    {
      "x": -6,
      "y": 42,
      "z": 5,
      "name": "Soil_Clay_Orange"
    },
    {
      "x": -6,
      "y": 43,
      "z": 5,
      "name": "Rock_Sandstone_Red"
    },
    {
      "x": -6,
      "y": 44,
      "z": 5,
      "name": "Rock_Sandstone_Red"
    },
    {
      "x": -6,
      "y": 45,
      "z": 5,
      "name": "Rock_Sandstone_Red"
    },
    {
      "x": -6,
      "y": 46,
      "z": 5,
      "name": "Rock_Sandstone_Red"
    },
    {
      "x": -6,
      "y": 47,
      "z": 5,
      "name": "Soil_Clay_Orange"
    },
    {
      "x": -6,
      "y": 48,
      "z": 5,
      "name": "Soil_Clay_Orange"
    },
    {
      "x": -6,
      "y": 49,
      "z": 5,
      "name": "Soil_Clay_Orange"
    },
    {
      "x": -6,
      "y": 50,
      "z": 5,
      "name": "Soil_Clay_Smooth_Red"
    },
    {
      "x": -6,
      "y": 30,
      "z": 6,
      "name": "Rock_Sandstone_Red"
    },
    {
      "x": -6,
      "y": 31,
      "z": 6,
      "name": "Rock_Sandstone_Red"
    },
    {
      "x": -6,
      "y": 32,
      "z": 6,
      "name": "Soil_Clay_Orange"
    },
    {
      "x": -6,
      "y": 33,
      "z": 6,
      "name": "Soil_Clay_Orange"
    },
    {
      "x": -6,
      "y": 34,
      "z": 6,
      "name": "Rock_Sandstone"
    },
    {
      "x": -6,
      "y": 35,
      "z": 6,
      "name": "Rock_Sandstone_Red"
    },
    {
      "x": -6,
      "y": 36,
      "z": 6,
      "name": "Rock_Sandstone_Red"
    },
    {
      "x": -6,
      "y": 37,
      "z": 6,
      "name": "Rock_Sandstone"
    },
    {
      "x": -6,
      "y": 38,
      "z": 6,
      "name": "Soil_Clay_Orange"
    },
    {
      "x": -6,
      "y": 39,
      "z": 6,
      "name": "Rock_Sandstone_Red"
    },
    {
      "x": -6,
      "y": 40,
      "z": 6,
      "name": "Rock_Sandstone"
    },
    {
      "x": -6,
      "y": 41,
      "z": 6,
      "name": "Soil_Clay_Orange"
    },
    {
      "x": -6,
      "y": 42,
      "z": 6,
      "name": "Soil_Clay_Orange"
    },
    {
      "x": -6,
      "y": 43,
      "z": 6,
      "name": "Rock_Sandstone_Red"
    },
    {
      "x": -6,
      "y": 44,
      "z": 6,
      "name": "Rock_Sandstone_Red"
    },
    {
      "x": -6,
      "y": 45,
      "z": 6,
      "name": "Rock_Sandstone_Red"
    },
    {
      "x": -6,
      "y": 46,
      "z": 6,
      "name": "Rock_Sandstone_Red"
    },
    {
      "x": -6,
      "y": 47,
      "z": 6,
      "name": "Rock_Sandstone_Red"
    },
    {
      "x": -6,
      "y": 48,
      "z": 6,
      "name": "Soil_Clay_Orange"
    },
    {
      "x": -6,
      "y": 49,
      "z": 6,
      "name": "Soil_Clay_Smooth_Red"
    },
    {
      "x": -6,
      "y": 31,
      "z": 7,
      "name": "Soil_Clay_Orange"
    },
    {
      "x": -6,
      "y": 32,
      "z": 7,
      "name": "Soil_Clay_Orange"
    },
    {
      "x": -6,
      "y": 33,
      "z": 7,
      "name": "Soil_Clay_Orange"
    },
    {
      "x": -6,
      "y": 34,
      "z": 7,
      "name": "Rock_Sandstone"
    },
    {
      "x": -6,
      "y": 35,
      "z": 7,
      "name": "Rock_Sandstone_Red"
    },
    {
      "x": -6,
      "y": 36,
      "z": 7,
      "name": "Rock_Sandstone_Red"
    },
    {
      "x": -6,
      "y": 37,
      "z": 7,
      "name": "Rock_Sandstone"
    },
    {
      "x": -6,
      "y": 38,
      "z": 7,
      "name": "Soil_Clay_Orange"
    },
    {
      "x": -6,
      "y": 39,
      "z": 7,
      "name": "Soil_Clay_Orange"
    },
    {
      "x": -6,
      "y": 40,
      "z": 7,
      "name": "Rock_Sandstone"
    },
    {
      "x": -6,
      "y": 41,
      "z": 7,
      "name": "Rock_Sandstone_Red"
    },
    {
      "x": -6,
      "y": 42,
      "z": 7,
