{
  "version": 8,
  "blockIdVersion": 10,
  "anchorX": 0,
  "anchorY": 17,
  "anchorZ": 0,
  "blocks": [
    {
      "x": -13,
      "y": 0,
      "z": -9,
      "name": "Soil_Sand"
    },
    {
      "x": -13,
      "y": 1,
      "z": -9,
      "name": "Soil_Sand"
    },
    {
      "x": -13,
      "y": 2,
      "z": -9,
      "name": "Soil_Sand"
    },
    {
      "x": -13,
      "y": 0,
      "z": -8,
      "name": "Soil_Sand"
    },
    {
      "x": -13,
      "y": 1,
      "z": -8,
      "name": "Soil_Sand"
    },
    {
      "x": -13,
      "y": 2,
      "z": -8,
      "name": "Soil_Sand"
    },
    {
      "x": -13,
      "y": 0,
      "z": -7,
      "name": "Soil_Sand"
    },
    {
      "x": -13,
      "y": 1,
      "z": -7,
      "name": "Soil_Sand"
    },
    {
      "x": -13,
      "y": 2,
      "z": -7,
      "name": "Soil_Sand"
    },
    {
      "x": -13,
      "y": 3,
      "z": -7,
      "name": "Soil_Sand"
    },
    {
      "x": -13,
      "y": 0,
      "z": -6,
      "name": "Soil_Sand"
    },
    {
      "x": -13,
      "y": 1,
      "z": -6,
      "name": "Soil_Sand"
    },
    {
      "x": -13,
      "y": 2,
      "z": -6,
      "name": "Soil_Sand"
    },
    {
      "x": -13,
      "y": 3,
      "z": -6,
      "name": "Soil_Sand"
    },
    {
      "x": -13,
      "y": 0,
      "z": -5,
      "name": "Soil_Sand"
    },
    {
      "x": -13,
      "y": 1,
      "z": -5,
      "name": "Soil_Sand"
    },
    {
      "x": -13,
      "y": 2,
      "z": -5,
      "name": "Soil_Sand"
    },
    {
      "x": -13,
      "y": 3,
      "z": -5,
      "name": "Soil_Sand"
    },
    {
      "x": -13,
      "y": 0,
      "z": -4,
      "name": "Soil_Sand"
    },
    {
      "x": -13,
      "y": 1,
      "z": -4,
      "name": "Soil_Sand"
    },
    {
      "x": -13,
      "y": 2,
      "z": -4,
      "name": "Soil_Sand"
    },
    {
      "x": -13,
      "y": 3,
      "z": -4,
      "name": "Soil_Sand"
    },
    {
      "x": -13,
      "y": 0,
      "z": -3,
      "name": "Soil_Sand"
    },
    {
      "x": -13,
      "y": 1,
      "z": -3,
      "name": "Soil_Sand"
    },
    {
      "x": -13,
      "y": 2,
      "z": -3,
      "name": "Soil_Sand"
    },
    {
      "x": -13,
      "y": 3,
      "z": -3,
      "name": "Soil_Sand"
    },
    {
      "x": -13,
      "y": 0,
      "z": -2,
      "name": "Soil_Sand"
    },
    {
      "x": -13,
      "y": 1,
      "z": -2,
      "name": "Soil_Sand"
    },
    {
      "x": -13,
      "y": 2,
      "z": -2,
      "name": "Soil_Sand"
    },
    {
      "x": -13,
      "y": 3,
      "z": -2,
      "name": "Soil_Sand"
    },
    {
      "x": -13,
      "y": 0,
      "z": -1,
      "name": "Soil_Sand"
    },
    {
      "x": -13,
      "y": 1,
      "z": -1,
      "name": "Soil_Clay_Lime"
    },
    {
      "x": -13,
      "y": 2,
      "z": -1,
      "name": "Soil_Sand"
    },
    {
      "x": -13,
      "y": 0,
      "z": 0,
      "name": "Soil_Sand"
    },
    {
      "x": -13,
      "y": 1,
      "z": 0,
      "name": "Soil_Sand"
    },
    {
      "x": -13,
      "y": 2,
      "z": 0,
      "name": "Plant_Flower_Bushy_Yellow"
    },
    {
      "x": -13,
      "y": 0,
      "z": 1,
      "name": "Soil_Sand"
    },
    {
      "x": -13,
      "y": 1,
      "z": 1,
      "name": "Soil_Sand"
    },
    {
      "x": -13,
      "y": 2,
      "z": 1,
      "name": "Plant_Flower_Bushy_Yellow"
    },
    {
      "x": -13,
      "y": 7,
      "z": 6,
      "name": "Rock_Stone_Mossy"
    },
    {
      "x": -13,
      "y": 8,
      "z": 6,
      "name": "Rock_Stone_Mossy"
    },
    {
      "x": -13,
      "y": 7,
      "z": 7,
      "name": "Rock_Stone_Mossy"
    },
    {
      "x": -13,
      "y": 8,
      "z": 7,
      "name": "Rock_Stone_Mossy"
    },
    {
      "x": -13,
      "y": 7,
      "z": 8,
      "name": "Rock_Stone_Mossy"
    },
    {
      "x": -13,
      "y": 8,
      "z": 8,
      "name": "Rock_Stone_Mossy"
    },
    {
      "x": -12,
      "y": 0,
      "z": -11,
      "name": "Soil_Sand"
    },
    {
      "x": -12,
      "y": 1,
      "z": -11,
      "name": "Soil_Sand"
    },
    {
      "x": -12,
      "y": 2,
      "z": -11,
      "name": "Soil_Sand"
    },
    {
      "x": -12,
      "y": 0,
      "z": -10,
      "name": "Soil_Sand"
    },
    {
      "x": -12,
      "y": 1,
      "z": -10,
      "name": "Soil_Sand"
    },
    {
      "x": -12,
      "y": 2,
      "z": -10,
      "name": "Soil_Sand"
    },
    {
      "x": -12,
      "y": 0,
      "z": -9,
      "name": "Soil_Sand"
    },
    {
      "x": -12,
      "y": 1,
      "z": -9,
      "name": "Soil_Sand"
    },
    {
      "x": -12,
      "y": 2,
      "z": -9,
      "name": "Soil_Sand"
    },
    {
      "x": -12,
      "y": 3,
      "z": -9,
      "name": "Soil_Sand"
    },
    {
      "x": -12,
      "y": 0,
      "z": -8,
      "name": "Soil_Sand"
    },
    {
      "x": -12,
      "y": 1,
      "z": -8,
      "name": "Soil_Sand"
    },
    {
      "x": -12,
      "y": 2,
      "z": -8,
      "name": "Soil_Sand"
    },
    {
      "x": -12,
      "y": 3,
      "z": -8,
      "name": "Soil_Sand"
    },
    {
      "x": -12,
      "y": 4,
      "z": -8,
      "name": "Soil_Sand"
    },
    {
      "x": -12,
      "y": 0,
      "z": -7,
      "name": "Soil_Sand"
    },
    {
      "x": -12,
      "y": 1,
      "z": -7,
      "name": "Soil_Sand"
    },
    {
      "x": -12,
      "y": 2,
      "z": -7,
      "name": "Soil_Sand"
    },
    {
      "x": -12,
      "y": 3,
      "z": -7,
      "name": "Soil_Sand"
    },
    {
      "x": -12,
      "y": 4,
      "z": -7,
      "name": "Soil_Sand"
    },
    {
      "x": -12,
      "y": 5,
      "z": -7,
      "name": "Soil_Sand"
    },
    {
      "x": -12,
      "y": 0,
      "z": -6,
      "name": "Soil_Sand"
    },
    {
      "x": -12,
      "y": 1,
      "z": -6,
      "name": "Soil_Sand"
    },
    {
      "x": -12,
      "y": 2,
      "z": -6,
      "name": "Soil_Sand"
    },
    {
      "x": -12,
      "y": 3,
      "z": -6,
      "name": "Soil_Sand"
    },
    {
      "x": -12,
      "y": 4,
      "z": -6,
      "name": "Soil_Sand"
    },
    {
      "x": -12,
      "y": 5,
      "z": -6,
      "name": "Soil_Sand"
    },
    {
      "x": -12,
      "y": 0,
      "z": -5,
      "name": "Soil_Sand"
    },
    {
      "x": -12,
      "y": 1,
      "z": -5,
      "name": "Soil_Sand"
    },
    {
      "x": -12,
      "y": 2,
      "z": -5,
      "name": "Soil_Sand"
    },
    {
      "x": -12,
      "y": 3,
      "z": -5,
      "name": "Soil_Sand"
    },
    {
      "x": -12,
      "y": 4,
      "z": -5,
      "name": "Soil_Sand"
    },
    {
      "x": -12,
      "y": 5,
      "z": -5,
      "name": "Soil_Sand"
    },
    {
      "x": -12,
      "y": 6,
      "z": -5,
      "name": "Soil_Sand"
    },
    {
      "x": -12,
      "y": 0,
      "z": -4,
      "name": "Soil_Sand"
    },
    {
      "x": -12,
      "y": 1,
      "z": -4,
      "name": "Soil_Sand"
    },
    {
      "x": -12,
      "y": 2,
      "z": -4,
      "name": "Soil_Sand"
    },
    {
      "x": -12,
      "y": 3,
      "z": -4,
      "name": "Soil_Sand"
    },
    {
      "x": -12,
      "y": 4,
      "z": -4,
      "name": "Soil_Sand"
    },
    {
      "x": -12,
      "y": 5,
      "z": -4,
      "name": "Soil_Sand"
    },
    {
      "x": -12,
      "y": 6,
      "z": -4,
      "name": "Soil_Sand"
    },
    {
      "x": -12,
      "y": 0,
      "z": -3,
      "name": "Soil_Sand"
    },
    {
      "x": -12,
      "y": 1,
      "z": -3,
      "name": "Soil_Sand"
    },
    {
      "x": -12,
      "y": 2,
      "z": -3,
      "name": "Soil_Sand"
    },
    {
      "x": -12,
      "y": 3,
      "z": -3,
      "name": "Soil_Sand"
    },
    {
      "x": -12,
      "y": 4,
      "z": -3,
      "name": "Soil_Sand"
    },
    {
      "x": -12,
      "y": 5,
      "z": -3,
      "name": "Soil_Sand"
    },
    {
      "x": -12,
      "y": 6,
      "z": -3,
      "name": "Soil_Sand"
    },
    {
      "x": -12,
      "y": 7,
      "z": -3,
      "name": "Soil_Sand"
    },
    {
      "x": -12,
      "y": 0,
      "z": -2,
      "name": "Soil_Sand"
    },
    {
      "x": -12,
      "y": 1,
      "z": -2,
      "name": "Soil_Sand"
    },
    {
      "x": -12,
      "y": 2,
      "z": -2,
      "name": "Soil_Sand"
    },
    {
      "x": -12,
      "y": 3,
      "z": -2,
      "name": "Soil_Sand"
    },
    {
      "x": -12,
      "y": 4,
      "z": -2,
      "name": "Soil_Sand"
    },
    {
      "x": -12,
      "y": 5,
      "z": -2,
      "name": "Soil_Sand"
    },
    {
      "x": -12,
      "y": 6,
      "z": -2,
      "name": "Soil_Sand"
    },
    {
      "x": -12,
      "y": 7,
      "z": -2,
      "name": "Soil_Sand"
    },
    {
      "x": -12,
      "y": 0,
      "z": -1,
      "name": "Soil_Sand"
    },
    {
      "x": -12,
      "y": 1,
      "z": -1,
      "name": "Soil_Sand"
    },
    {
      "x": -12,
      "y": 2,
      "z": -1,
      "name": "Soil_Sand"
    },
    {
      "x": -12,
      "y": 3,
      "z": -1,
      "name": "Soil_Sand"
    },
    {
      "x": -12,
      "y": 4,
      "z": -1,
      "name": "Soil_Sand"
    },
    {
      "x": -12,
      "y": 5,
      "z": -1,
      "name": "Soil_Sand"
    },
    {
      "x": -12,
      "y": 6,
      "z": -1,
      "name": "Soil_Sand"
    },
    {
      "x": -12,
      "y": 0,
      "z": 0,
      "name": "Soil_Sand"
    },
    {
      "x": -12,
      "y": 1,
      "z": 0,
      "name": "Soil_Sand"
    },
    {
      "x": -12,
      "y": 2,
      "z": 0,
      "name": "Soil_Sand"
    },
    {
      "x": -12,
      "y": 3,
      "z": 0,
      "name": "Soil_Sand"
    },
    {
      "x": -12,
      "y": 4,
      "z": 0,
      "name": "Soil_Sand"
    },
    {
      "x": -12,
      "y": 5,
      "z": 0,
      "name": "Soil_Sand"
    },
    {
      "x": -12,
      "y": 0,
      "z": 1,
      "name": "Soil_Sand"
    },
    {
      "x": -12,
      "y": 1,
      "z": 1,
      "name": "Soil_Sand"
    },
    {
      "x": -12,
      "y": 2,
      "z": 1,
      "name": "Soil_Sand"
    },
    {
      "x": -12,
      "y": 7,
      "z": 4,
      "name": "Rock_Stone_Mossy"
    },
    {
      "x": -12,
      "y": 8,
      "z": 4,
      "name": "Soil_Clay_Lime"
    },
    {
      "x": -12,
      "y": 0,
      "z": 5,
      "name": "Soil_Sand"
    },
    {
      "x": -12,
      "y": 1,
      "z": 5,
      "name": "Soil_Sand"
    },
    {
      "x": -12,
      "y": 2,
      "z": 5,
      "name": "Plant_Flower_Bushy_Yellow"
    },
    {
      "x": -12,
      "y": 6,
      "z": 5,
      "name": "Rock_Stone_Mossy"
    },
    {
      "x": -12,
      "y": 7,
      "z": 5,
      "name": "Rock_Stone_Mossy"
    },
    {
      "x": -12,
      "y": 8,
      "z": 5,
      "name": "Soil_Sand"
    },
    {
      "x": -12,
      "y": 9,
      "z": 5,
      "name": "Plant_Leaves_Palm_Arid"
    },
    {
      "x": -12,
      "y": 0,
      "z": 6,
      "name": "Soil_Sand"
    },
    {
      "x": -12,
      "y": 1,
      "z": 6,
      "name": "Soil_Sand"
    },
    {
      "x": -12,
      "y": 2,
      "z": 6,
      "name": "Plant_Flower_Bushy_Yellow"
    },
    {
      "x": -12,
      "y": 6,
      "z": 6,
      "name": "Rock_Stone_Mossy"
    },
    {
      "x": -12,
      "y": 7,
      "z": 6,
      "name": "Soil_Sand"
    },
    {
      "x": -12,
      "y": 8,
      "z": 6,
      "name": "Soil_Sand"
    },
    {
      "x": -12,
      "y": 9,
      "z": 6,
      "name": "Plant_Leaves_Palm_Arid"
    },
    {
      "x": -12,
      "y": 0,
      "z": 7,
      "name": "Soil_Sand"
    },
    {
      "x": -12,
      "y": 1,
      "z": 7,
      "name": "Soil_Sand"
    },
    {
      "x": -12,
      "y": 2,
      "z": 7,
      "name": "Plant_Leaves_Palm_Arid"
    },
    {
      "x": -12,
      "y": 6,
      "z": 7,
      "name": "Rock_Stone_Mossy"
    },
    {
      "x": -12,
      "y": 7,
      "z": 7,
      "name": "Soil_Sand"
    },
    {
      "x": -12,
      "y": 8,
      "z": 7,
      "name": "Soil_Sand"
    },
    {
      "x": -12,
      "y": 9,
      "z": 7,
      "name": "Plant_Flower_Bushy_Yellow"
    },
    {
      "x": -12,
      "y": 0,
      "z": 8,
      "name": "Soil_Sand"
    },
    {
      "x": -12,
      "y": 1,
      "z": 8,
      "name": "Soil_Sand"
    },
    {
      "x": -12,
      "y": 2,
      "z": 8,
      "name": "Plant_Leaves_Palm_Arid"
    },
    {
      "x": -12,
      "y": 7,
      "z": 8,
      "name": "Rock_Stone_Mossy"
    },
    {
      "x": -12,
      "y": 8,
      "z": 8,
      "name": "Soil_Sand"
    },
    {
      "x": -12,
      "y": 9,
      "z": 8,
      "name": "Plant_Flower_Bushy_Yellow"
    },
    {
      "x": -12,
      "y": 7,
      "z": 9,
      "name": "Rock_Stone_Mossy"
    },
    {
      "x": -12,
      "y": 8,
      "z": 9,
      "name": "Rock_Stone_Mossy"
    },
    {
      "x": -11,
      "y": 0,
      "z": -12,
      "name": "Soil_Sand"
    },
    {
      "x": -11,
      "y": 1,
      "z": -12,
      "name": "Soil_Sand"
    },
    {
      "x": -11,
      "y": 2,
      "z": -12,
      "name": "Soil_Sand"
    },
    {
      "x": -11,
      "y": 0,
      "z": -11,
      "name": "Soil_Sand"
    },
    {
      "x": -11,
      "y": 1,
      "z": -11,
      "name": "Soil_Sand"
    },
    {
      "x": -11,
      "y": 2,
      "z": -11,
      "name": "Soil_Sand"
    },
    {
      "x": -11,
      "y": 3,
      "z": -11,
      "name": "Soil_Sand"
    },
    {
      "x": -11,
      "y": 0,
      "z": -10,
      "name": "Soil_Sand"
    },
    {
      "x": -11,
      "y": 1,
      "z": -10,
      "name": "Soil_Sand"
    },
    {
      "x": -11,
      "y": 2,
      "z": -10,
      "name": "Soil_Sand"
    },
    {
      "x": -11,
      "y": 3,
      "z": -10,
      "name": "Soil_Sand"
    },
    {
      "x": -11,
      "y": 4,
      "z": -10,
      "name": "Soil_Sand"
    },
    {
      "x": -11,
      "y": 0,
      "z": -9,
      "name": "Soil_Sand"
    },
    {
      "x": -11,
      "y": 1,
      "z": -9,
      "name": "Soil_Sand"
    },
    {
      "x": -11,
      "y": 2,
      "z": -9,
      "name": "Soil_Sand"
    },
    {
      "x": -11,
      "y": 3,
      "z": -9,
      "name": "Soil_Sand"
    },
    {
      "x": -11,
      "y": 4,
      "z": -9,
      "name": "Soil_Sand"
    },
    {
      "x": -11,
      "y": 5,
      "z": -9,
      "name": "Soil_Sand"
    },
    {
      "x": -11,
      "y": 0,
      "z": -8,
      "name": "Soil_Sand"
    },
    {
      "x": -11,
      "y": 1,
      "z": -8,
      "name": "Soil_Sand"
    },
    {
      "x": -11,
      "y": 2,
      "z": -8,
      "name": "Soil_Sand"
    },
    {
      "x": -11,
      "y": 3,
      "z": -8,
      "name": "Soil_Sand"
    },
    {
      "x": -11,
      "y": 4,
      "z": -8,
      "name": "Soil_Sand"
    },
    {
      "x": -11,
      "y": 5,
      "z": -8,
      "name": "Soil_Sand"
    },
    {
      "x": -11,
      "y": 6,
      "z": -8,
      "name": "Soil_Sand"
    },
    {
      "x": -11,
      "y": 0,
      "z": -7,
      "name": "Soil_Sand"
    },
    {
      "x": -11,
      "y": 1,
      "z": -7,
      "name": "Soil_Sand"
    },
    {
      "x": -11,
      "y": 2,
      "z": -7,
      "name": "Soil_Sand"
    },
    {
      "x": -11,
      "y": 3,
      "z": -7,
      "name": "Soil_Sand"
    },
    {
      "x": -11,
      "y": 4,
      "z": -7,
      "name": "Soil_Sand"
    },
    {
      "x": -11,
      "y": 5,
      "z": -7,
      "name": "Soil_Sand"
    },
    {
      "x": -11,
      "y": 6,
      "z": -7,
      "name": "Soil_Sand"
    },
    {
      "x": -11,
      "y": 7,
      "z": -7,
      "name": "Soil_Sand"
    },
    {
      "x": -11,
      "y": 0,
      "z": -6,
      "name": "Soil_Sand"
    },
    {
      "x": -11,
      "y": 1,
      "z": -6,
      "name": "Soil_Sand"
    },
    {
      "x": -11,
      "y": 2,
      "z": -6,
      "name": "Soil_Sand"
    },
    {
      "x": -11,
      "y": 3,
      "z": -6,
      "name": "Soil_Sand"
    },
    {
      "x": -11,
      "y": 4,
      "z": -6,
      "name": "Soil_Sand"
    },
    {
      "x": -11,
      "y": 5,
      "z": -6,
      "name": "Soil_Sand"
    },
    {
      "x": -11,
      "y": 6,
      "z": -6,
      "name": "Soil_Sand"
    },
    {
      "x": -11,
      "y": 7,
      "z": -6,
      "name": "Soil_Sand"
    },
    {
      "x": -11,
      "y": 8,
      "z": -6,
      "name": "Soil_Sand"
    },
    {
      "x": -11,
      "y": 0,
      "z": -5,
      "name": "Soil_Sand"
    },
    {
      "x": -11,
      "y": 1,
      "z": -5,
      "name": "Soil_Sand"
    },
    {
      "x": -11,
      "y": 2,
      "z": -5,
      "name": "Soil_Sand"
    },
    {
      "x": -11,
      "y": 3,
      "z": -5,
      "name": "Soil_Sand"
    },
    {
      "x": -11,
      "y": 4,
      "z": -5,
      "name": "Soil_Sand"
    },
    {
      "x": -11,
      "y": 5,
      "z": -5,
      "name": "Soil_Sand"
    },
    {
      "x": -11,
      "y": 6,
      "z": -5,
      "name": "Soil_Sand"
    },
    {
      "x": -11,
      "y": 7,
      "z": -5,
      "name": "Soil_Sand"
    },
    {
      "x": -11,
      "y": 8,
      "z": -5,
      "name": "Soil_Sand"
    },
    {
      "x": -11,
      "y": 0,
      "z": -4,
      "name": "Soil_Sand"
    },
    {
      "x": -11,
      "y": 1,
      "z": -4,
      "name": "Soil_Sand"
    },
    {
      "x": -11,
      "y": 2,
      "z": -4,
      "name": "Soil_Sand"
    },
    {
      "x": -11,
      "y": 3,
      "z": -4,
      "name": "Soil_Sand"
    },
    {
      "x": -11,
      "y": 4,
      "z": -4,
      "name": "Soil_Sand"
    },
    {
      "x": -11,
      "y": 5,
      "z": -4,
      "name": "Soil_Sand"
    },
    {
      "x": -11,
      "y": 6,
      "z": -4,
      "name": "Soil_Sand"
    },
    {
      "x": -11,
      "y": 7,
      "z": -4,
      "name": "Soil_Sand"
    },
    {
      "x": -11,
      "y": 8,
      "z": -4,
      "name": "Soil_Sand"
    },
    {
      "x": -11,
      "y": 9,
      "z": -4,
      "name": "Soil_Sand"
    },
    {
      "x": -11,
      "y": 0,
      "z": -3,
      "name": "Soil_Sand"
    },
    {
      "x": -11,
      "y": 1,
      "z": -3,
      "name": "Soil_Sand"
    },
    {
      "x": -11,
      "y": 2,
      "z": -3,
      "name": "Soil_Sand"
    },
    {
      "x": -11,
      "y": 3,
      "z": -3,
      "name": "Soil_Sand"
    },
    {
      "x": -11,
      "y": 4,
      "z": -3,
      "name": "Soil_Sand"
    },
    {
      "x": -11,
      "y": 5,
      "z": -3,
      "name": "Soil_Sand"
    },
    {
      "x": -11,
      "y": 6,
      "z": -3,
      "name": "Soil_Sand"
    },
    {
      "x": -11,
      "y": 7,
      "z": -3,
      "name": "Soil_Sand"
    },
    {
      "x": -11,
      "y": 8,
      "z": -3,
      "name": "Soil_Sand"
    },
    {
      "x": -11,
      "y": 9,
      "z": -3,
      "name": "Soil_Sand"
    },
    {
      "x": -11,
      "y": 10,
      "z": -3,
      "name": "Soil_Sand"
    },
    {
      "x": -11,
      "y": 0,
      "z": -2,
      "name": "Soil_Sand"
    },
    {
      "x": -11,
      "y": 1,
      "z": -2,
      "name": "Soil_Sand"
    },
    {
      "x": -11,
      "y": 2,
      "z": -2,
      "name": "Soil_Sand"
    },
    {
      "x": -11,
      "y": 3,
      "z": -2,
      "name": "Soil_Sand"
    },
    {
      "x": -11,
      "y": 4,
      "z": -2,
      "name": "Soil_Sand"
    },
    {
      "x": -11,
      "y": 5,
      "z": -2,
      "name": "Soil_Sand"
    },
    {
      "x": -11,
      "y": 6,
      "z": -2,
      "name": "Soil_Sand"
    },
    {
      "x": -11,
      "y": 7,
      "z": -2,
      "name": "Soil_Sand"
    },
    {
      "x": -11,
      "y": 8,
      "z": -2,
      "name": "Soil_Sand"
    },
    {
      "x": -11,
      "y": 9,
      "z": -2,
      "name": "Soil_Sand"
    },
    {
      "x": -11,
      "y": 10,
      "z": -2,
      "name": "Soil_Sand"
    },
    {
      "x": -11,
      "y": 0,
      "z": -1,
      "name": "Soil_Sand"
    },
    {
      "x": -11,
      "y": 1,
      "z": -1,
      "name": "Soil_Sand"
    },
    {
      "x": -11,
      "y": 2,
      "z": -1,
      "name": "Soil_Sand"
    },
    {
      "x": -11,
      "y": 3,
      "z": -1,
      "name": "Soil_Sand"
    },
    {
      "x": -11,
      "y": 4,
      "z": -1,
      "name": "Soil_Sand"
    },
    {
      "x": -11,
      "y": 5,
      "z": -1,
      "name": "Soil_Sand"
    },
    {
      "x": -11,
      "y": 6,
      "z": -1,
      "name": "Soil_Sand"
    },
    {
      "x": -11,
      "y": 7,
      "z": -1,
      "name": "Soil_Sand"
    },
    {
      "x": -11,
      "y": 8,
      "z": -1,
      "name": "Soil_Sand"
    },
    {
      "x": -11,
      "y": 9,
      "z": -1,
      "name": "Soil_Sand"
    },
    {
      "x": -11,
      "y": 10,
      "z": -1,
      "name": "Soil_Sand"
    },
    {
      "x": -11,
      "y": 0,
      "z": 0,
      "name": "Soil_Sand"
    },
    {
      "x": -11,
      "y": 1,
      "z": 0,
      "name": "Soil_Sand"
    },
    {
      "x": -11,
      "y": 2,
      "z": 0,
      "name": "Soil_Sand"
    },
    {
      "x": -11,
      "y": 3,
      "z": 0,
      "name": "Soil_Sand"
    },
    {
      "x": -11,
      "y": 4,
      "z": 0,
      "name": "Soil_Sand"
    },
    {
      "x": -11,
      "y": 5,
      "z": 0,
      "name": "Soil_Sand"
    },
    {
      "x": -11,
      "y": 6,
      "z": 0,
      "name": "Soil_Sand"
    },
    {
      "x": -11,
      "y": 7,
      "z": 0,
      "name": "Soil_Sand"
    },
    {
      "x": -11,
      "y": 8,
      "z": 0,
      "name": "Soil_Sand"
    },
    {
      "x": -11,
      "y": 9,
      "z": 0,
      "name": "Soil_Sand"
    },
    {
      "x": -11,
      "y": 10,
      "z": 0,
      "name": "Soil_Sand"
    },
    {
      "x": -11,
      "y": 0,
      "z": 1,
      "name": "Soil_Sand"
    },
    {
      "x": -11,
      "y": 1,
      "z": 1,
      "name": "Soil_Sand"
    },
    {
      "x": -11,
      "y": 2,
      "z": 1,
      "name": "Soil_Sand"
    },
    {
      "x": -11,
      "y": 3,
      "z": 1,
      "name": "Soil_Sand"
    },
    {
      "x": -11,
      "y": 4,
      "z": 1,
      "name": "Soil_Sand"
    },
    {
      "x": -11,
      "y": 5,
      "z": 1,
      "name": "Soil_Sand"
    },
    {
      "x": -11,
      "y": 6,
      "z": 1,
      "name": "Soil_Sand"
    },
    {
      "x": -11,
      "y": 7,
      "z": 1,
      "name": "Soil_Sand"
    },
    {
      "x": -11,
      "y": 8,
      "z": 1,
      "name": "Soil_Sand"
    },
    {
      "x": -11,
      "y": 9,
      "z": 1,
      "name": "Soil_Sand"
    },
    {
      "x": -11,
      "y": 0,
      "z": 2,
      "name": "Soil_Sand"
    },
    {
      "x": -11,
      "y": 1,
      "z": 2,
      "name": "Soil_Sand"
    },
    {
      "x": -11,
      "y": 2,
      "z": 2,
      "name": "Soil_Sand"
    },
    {
      "x": -11,
      "y": 3,
      "z": 2,
      "name": "Soil_Sand"
    },
    {
      "x": -11,
      "y": 4,
      "z": 2,
      "name": "Soil_Sand"
    },
    {
      "x": -11,
      "y": 5,
      "z": 2,
      "name": "Soil_Sand"
    },
    {
      "x": -11,
      "y": 6,
      "z": 2,
      "name": "Soil_Sand"
    },
    {
      "x": -11,
      "y": 7,
      "z": 2,
      "name": "Soil_Sand"
    },
    {
      "x": -11,
      "y": 8,
      "z": 2,
      "name": "Soil_Sand"
    },
    {
      "x": -11,
      "y": 0,
      "z": 3,
      "name": "Soil_Sand"
    },
    {
      "x": -11,
      "y": 1,
      "z": 3,
      "name": "Soil_Sand"
    },
    {
      "x": -11,
      "y": 2,
      "z": 3,
      "name": "Soil_Sand"
    },
    {
      "x": -11,
      "y": 3,
      "z": 3,
      "name": "Soil_Sand"
    },
    {
      "x": -11,
      "y": 6,
      "z": 3,
      "name": "Soil_Clay_Lime"
    },
    {
      "x": -11,
      "y": 7,
      "z": 3,
      "name": "Soil_Clay_Lime"
    },
    {
      "x": -11,
      "y": 8,
      "z": 3,
      "name": "Plant_Moss_Block_Yellow"
    },
    {
      "x": -11,
      "y": 0,
      "z": 4,
      "name": "Soil_Sand"
    },
    {
      "x": -11,
      "y": 1,
      "z": 4,
      "name": "Soil_Sand"
    },
    {
      "x": -11,
      "y": 2,
      "z": 4,
      "name": "Soil_Sand"
    },
    {
      "x": -11,
      "y": 6,
      "z": 4,
      "name": "Rock_Stone_Mossy"
    },
    {
      "x": -11,
      "y": 7,
      "z": 4,
      "name": "Soil_Sand"
    },
    {
      "x": -11,
      "y": 8,
      "z": 4,
      "name": "Soil_Clay_Lime"
    },
    {
      "x": -11,
      "y": 0,
      "z": 5,
      "name": "Soil_Sand"
    },
    {
      "x": -11,
      "y": 1,
      "z": 5,
      "name": "Soil_Sand"
    },
    {
      "x": -11,
      "y": 2,
      "z": 5,
      "name": "Soil_Sand"
    },
    {
      "x": -11,
      "y": 6,
      "z": 5,
      "name": "Rock_Stone_Mossy"
    },
    {
      "x": -11,
      "y": 7,
      "z": 5,
      "name": "Soil_Sand"
    },
    {
      "x": -11,
      "y": 8,
      "z": 5,
      "name": "Soil_Sand"
    },
    {
      "x": -11,
      "y": 9,
      "z": 5,
      "name": "Plant_Leaves_Palm_Arid"
    },
    {
      "x": -11,
      "y": 0,
      "z": 6,
      "name": "Soil_Sand"
    },
    {
      "x": -11,
      "y": 1,
      "z": 6,
      "name": "Soil_Sand"
    },
    {
      "x": -11,
      "y": 2,
      "z": 6,
      "name": "Soil_Sand"
    },
    {
      "x": -11,
      "y": 3,
      "z": 6,
      "name": "Plant_Flower_Bushy_Yellow"
    },
    {
      "x": -11,
      "y": 6,
      "z": 6,
      "name": "Rock_Stone_Mossy"
    },
    {
      "x": -11,
      "y": 7,
      "z": 6,
      "name": "Soil_Sand"
    },
    {
      "x": -11,
      "y": 8,
      "z": 6,
      "name": "Soil_Sand"
    },
    {
      "x": -11,
      "y": 9,
      "z": 6,
      "name": "Plant_Leaves_Palm_Arid"
    },
    {
      "x": -11,
      "y": 0,
      "z": 7,
      "name": "Soil_Sand"
    },
    {
      "x": -11,
      "y": 1,
      "z": 7,
      "name": "Soil_Sand"
    },
    {
      "x": -11,
      "y": 2,
      "z": 7,
      "name": "Plant_Leaves_Palm_Arid"
    },
    {
      "x": -11,
      "y": 6,
      "z": 7,
      "name": "Rock_Stone_Mossy"
    },
    {
      "x": -11,
      "y": 7,
      "z": 7,
      "name": "Soil_Sand"
    },
    {
      "x": -11,
      "y": 8,
      "z": 7,
      "name": "Soil_Sand"
    },
    {
      "x": -11,
      "y": 9,
      "z": 7,
      "name": "Plant_Flower_Bushy_Yellow"
    },
    {
      "x": -11,
      "y": 0,
      "z": 8,
      "name": "Soil_Sand"
    },
    {
      "x": -11,
      "y": 1,
      "z": 8,
      "name": "Soil_Sand"
    },
    {
      "x": -11,
      "y": 2,
      "z": 8,
      "name": "Plant_Leaves_Palm_Arid"
    },
    {
      "x": -11,
      "y": 6,
      "z": 8,
      "name": "Rock_Stone_Mossy"
    },
    {
      "x": -11,
      "y": 7,
      "z": 8,
      "name": "Soil_Sand"
    },
    {
      "x": -11,
      "y": 8,
      "z": 8,
      "name": "Soil_Sand"
    },
    {
      "x": -11,
      "y": 9,
      "z": 8,
      "name": "Plant_Flower_Bushy_Yellow"
    },
    {
      "x": -11,
      "y": 0,
      "z": 9,
      "name": "Soil_Sand"
    },
    {
      "x": -11,
      "y": 1,
      "z": 9,
      "name": "Soil_Sand"
    },
    {
      "x": -11,
      "y": 2,
      "z": 9,
      "name": "Plant_Flower_Bushy_Yellow"
    },
    {
      "x": -11,
      "y": 7,
      "z": 9,
      "name": "Soil_Clay_Lime"
    },
    {
      "x": -11,
      "y": 8,
      "z": 9,
      "name": "Soil_Sand"
    },
    {
      "x": -11,
      "y": 9,
      "z": 9,
      "name": "Plant_Bush_Arid_Sharp"
    },
    {
      "x": -11,
      "y": 0,
      "z": 10,
      "name": "Soil_Sand"
    },
    {
      "x": -11,
      "y": 1,
      "z": 10,
      "name": "Soil_Sand"
    },
    {
      "x": -11,
      "y": 2,
      "z": 10,
      "name": "Plant_Flower_Bushy_Yellow"
    },
    {
      "x": -10,
      "y": 0,
      "z": -13,
      "name": "Soil_Sand"
    },
    {
      "x": -10,
      "y": 1,
      "z": -13,
      "name": "Soil_Sand"
    },
    {
      "x": -10,
      "y": 2,
      "z": -13,
      "name": "Soil_Sand"
    },
    {
      "x": -10,
      "y": 0,
      "z": -12,
      "name": "Soil_Sand"
    },
    {
      "x": -10,
      "y": 1,
      "z": -12,
      "name": "Soil_Sand"
    },
    {
      "x": -10,
      "y": 2,
      "z": -12,
      "name": "Soil_Sand"
    },
    {
      "x": -10,
      "y": 3,
      "z": -12,
      "name": "Soil_Sand"
    },
    {
      "x": -10,
      "y": 0,
      "z": -11,
      "name": "Soil_Sand"
    },
    {
      "x": -10,
      "y": 1,
      "z": -11,
      "name": "Soil_Sand"
    },
    {
      "x": -10,
      "y": 2,
      "z": -11,
      "name": "Soil_Sand"
    },
    {
      "x": -10,
      "y": 3,
      "z": -11,
      "name": "Soil_Sand"
    },
    {
      "x": -10,
      "y": 4,
      "z": -11,
      "name": "Soil_Sand"
    },
    {
      "x": -10,
      "y": 0,
      "z": -10,
      "name": "Soil_Sand"
    },
    {
      "x": -10,
      "y": 1,
      "z": -10,
      "name": "Soil_Sand"
    },
    {
      "x": -10,
      "y": 2,
      "z": -10,
      "name": "Soil_Sand"
    },
    {
      "x": -10,
      "y": 3,
      "z": -10,
      "name": "Soil_Sand"
    },
    {
      "x": -10,
      "y": 4,
      "z": -10,
      "name": "Soil_Sand"
    },
    {
      "x": -10,
      "y": 5,
      "z": -10,
      "name": "Soil_Sand"
    },
    {
      "x": -10,
      "y": 0,
      "z": -9,
      "name": "Soil_Sand"
    },
    {
      "x": -10,
      "y": 1,
      "z": -9,
      "name": "Soil_Sand"
    },
    {
      "x": -10,
      "y": 2,
      "z": -9,
      "name": "Soil_Sand"
    },
    {
      "x": -10,
      "y": 3,
      "z": -9,
      "name": "Soil_Sand"
    },
    {
      "x": -10,
      "y": 4,
      "z": -9,
      "name": "Soil_Sand"
    },
    {
      "x": -10,
      "y": 5,
      "z": -9,
      "name": "Soil_Sand"
    },
    {
      "x": -10,
      "y": 6,
      "z": -9,
      "name": "Soil_Sand"
    },
    {
      "x": -10,
      "y": 0,
      "z": -8,
      "name": "Soil_Sand"
    },
    {
      "x": -10,
      "y": 1,
      "z": -8,
      "name": "Soil_Sand"
    },
    {
      "x": -10,
      "y": 2,
      "z": -8,
      "name": "Soil_Sand"
    },
    {
      "x": -10,
      "y": 3,
      "z": -8,
      "name": "Soil_Sand"
    },
    {
      "x": -10,
      "y": 4,
      "z": -8,
      "name": "Soil_Sand"
    },
    {
      "x": -10,
      "y": 5,
      "z": -8,
      "name": "Soil_Sand"
    },
    {
      "x": -10,
      "y": 6,
      "z": -8,
      "name": "Soil_Sand"
    },
    {
      "x": -10,
      "y": 7,
      "z": -8,
      "name": "Soil_Sand"
    },
    {
      "x": -10,
      "y": 0,
      "z": -7,
      "name": "Soil_Sand"
    },
    {
      "x": -10,
      "y": 1,
      "z": -7,
      "name": "Soil_Sand"
    },
    {
      "x": -10,
      "y": 2,
      "z": -7,
      "name": "Soil_Sand"
    },
    {
      "x": -10,
      "y": 3,
      "z": -7,
      "name": "Soil_Sand"
    },
    {
      "x": -10,
      "y": 4,
      "z": -7,
      "name": "Soil_Sand"
    },
    {
      "x": -10,
      "y": 5,
      "z": -7,
      "name": "Soil_Sand"
    },
    {
      "x": -10,
      "y": 6,
      "z": -7,
      "name": "Soil_Sand"
    },
    {
      "x": -10,
      "y": 7,
      "z": -7,
      "name": "Soil_Sand"
    },
    {
      "x": -10,
      "y": 8,
      "z": -7,
      "name": "Soil_Sand"
    },
    {
      "x": -10,
      "y": 0,
      "z": -6,
      "name": "Soil_Sand"
    },
    {
      "x": -10,
      "y": 1,
      "z": -6,
      "name": "Soil_Sand"
    },
    {
      "x": -10,
      "y": 2,
      "z": -6,
      "name": "Soil_Sand"
    },
    {
      "x": -10,
      "y": 3,
      "z": -6,
      "name": "Soil_Sand"
    },
    {
      "x": -10,
      "y": 4,
      "z": -6,
      "name": "Soil_Sand"
    },
    {
      "x": -10,
      "y": 5,
      "z": -6,
      "name": "Soil_Sand"
    },
    {
      "x": -10,
      "y": 6,
      "z": -6,
      "name": "Soil_Sand"
    },
    {
      "x": -10,
      "y": 7,
      "z": -6,
      "name": "Soil_Sand"
    },
    {
      "x": -10,
      "y": 8,
      "z": -6,
      "name": "Soil_Sand"
    },
    {
      "x": -10,
      "y": 9,
      "z": -6,
      "name": "Soil_Sand"
    },
    {
      "x": -10,
      "y": 0,
      "z": -5,
      "name": "Soil_Sand"
    },
    {
      "x": -10,
      "y": 1,
      "z": -5,
      "name": "Soil_Sand"
    },
    {
      "x": -10,
      "y": 2,
      "z": -5,
      "name": "Soil_Sand"
    },
    {
      "x": -10,
      "y": 3,
      "z": -5,
      "name": "Soil_Sand"
    },
    {
      "x": -10,
      "y": 4,
      "z": -5,
      "name": "Soil_Sand"
    },
    {
      "x": -10,
      "y": 5,
      "z": -5,
      "name": "Soil_Sand"
    },
    {
      "x": -10,
      "y": 6,
      "z": -5,
      "name": "Soil_Sand"
    },
    {
      "x": -10,
      "y": 7,
      "z": -5,
      "name": "Soil_Sand"
    },
    {
      "x": -10,
      "y": 8,
      "z": -5,
      "name": "Soil_Sand"
    },
    {
      "x": -10,
      "y": 9,
      "z": -5,
      "name": "Soil_Sand"
    },
    {
      "x": -10,
      "y": 10,
      "z": -5,
      "name": "Soil_Sand"
    },
    {
      "x": -10,
      "y": 0,
      "z": -4,
      "name": "Soil_Sand"
    },
    {
      "x": -10,
      "y": 1,
      "z": -4,
      "name": "Soil_Sand"
    },
    {
      "x": -10,
      "y": 2,
      "z": -4,
      "name": "Soil_Sand"
    },
    {
      "x": -10,
      "y": 3,
      "z": -4,
      "name": "Soil_Sand"
    },
    {
      "x": -10,
      "y": 4,
      "z": -4,
      "name": "Soil_Sand"
    },
    {
      "x": -10,
      "y": 5,
      "z": -4,
      "name": "Soil_Sand"
    },
    {
      "x": -10,
      "y": 6,
      "z": -4,
      "name": "Soil_Sand"
    },
    {
      "x": -10,
      "y": 7,
      "z": -4,
      "name": "Soil_Sand"
    },
    {
      "x": -10,
      "y": 8,
      "z": -4,
      "name": "Soil_Sand"
    },
    {
      "x": -10,
      "y": 9,
      "z": -4,
      "name": "Soil_Sand"
    },
    {
      "x": -10,
      "y": 10,
      "z": -4,
      "name": "Soil_Sand"
    },
    {
      "x": -10,
      "y": 11,
      "z": -4,
      "name": "Soil_Sand"
    },
    {
      "x": -10,
      "y": 0,
      "z": -3,
      "name": "Soil_Sand"
    },
    {
      "x": -10,
      "y": 1,
      "z": -3,
      "name": "Soil_Sand"
    },
    {
      "x": -10,
      "y": 2,
      "z": -3,
      "name": "Soil_Sand"
    },
    {
      "x": -10,
      "y": 3,
      "z": -3,
      "name": "Soil_Sand"
    },
    {
      "x": -10,
      "y": 4,
      "z": -3,
      "name": "Soil_Sand"
    },
    {
      "x": -10,
      "y": 5,
      "z": -3,
      "name": "Soil_Sand"
    },
    {
      "x": -10,
      "y": 6,
      "z": -3,
      "name": "Soil_Sand"
    },
    {
      "x": -10,
      "y": 7,
      "z": -3,
      "name": "Soil_Sand"
    },
    {
      "x": -10,
      "y": 8,
      "z": -3,
      "name": "Soil_Sand"
    },
    {
      "x": -10,
      "y": 9,
      "z": -3,
      "name": "Soil_Sand"
    },
    {
      "x": -10,
      "y": 10,
      "z": -3,
      "name": "Soil_Sand"
    },
    {
      "x": -10,
      "y": 11,
      "z": -3,
      "name": "Soil_Sand"
    },
    {
      "x": -10,
      "y": 12,
      "z": -3,
      "name": "Soil_Sand"
    },
    {
      "x": -10,
      "y": 25,
      "z": -3,
      "name": "Soil_Clay_Lime"
    },
    {
      "x": -10,
      "y": 26,
      "z": -3,
      "name": "Soil_Clay_Lime"
    },
    {
      "x": -10,
      "y": 27,
      "z": -3,
      "name": "Plant_Moss_Block_Yellow"
    },
    {
      "x": -10,
      "y": 28,
      "z": -3,
      "name": "Plant_Moss_Block_Yellow"
    },
    {
      "x": -10,
      "y": 29,
      "z": -3,
      "name": "Plant_Moss_Block_Yellow"
    },
    {
      "x": -10,
      "y": 0,
      "z": -2,
      "name": "Soil_Sand"
    },
    {
      "x": -10,
      "y": 1,
      "z": -2,
      "name": "Soil_Sand"
    },
    {
      "x": -10,
      "y": 2,
      "z": -2,
      "name": "Soil_Sand"
    },
    {
      "x": -10,
      "y": 3,
      "z": -2,
      "name": "Soil_Sand"
    },
    {
      "x": -10,
      "y": 4,
      "z": -2,
      "name": "Soil_Sand"
    },
    {
      "x": -10,
      "y": 5,
      "z": -2,
      "name": "Soil_Sand"
    },
    {
      "x": -10,
      "y": 6,
      "z": -2,
      "name": "Soil_Sand"
    },
    {
      "x": -10,
      "y": 7,
      "z": -2,
      "name": "Soil_Sand"
    },
    {
      "x": -10,
      "y": 8,
      "z": -2,
      "name": "Soil_Sand"
    },
    {
      "x": -10,
      "y": 9,
      "z": -2,
      "name": "Soil_Sand"
    },
    {
      "x": -10,
      "y": 10,
      "z": -2,
      "name": "Soil_Sand"
    },
    {
      "x": -10,
      "y": 11,
      "z": -2,
      "name": "Soil_Sand"
    },
    {
      "x": -10,
      "y": 12,
      "z": -2,
      "name": "Soil_Sand"
    },
    {
      "x": -10,
      "y": 26,
      "z": -2,
      "name": "Soil_Clay_Lime"
    },
    {
      "x": -10,
      "y": 27,
      "z": -2,
      "name": "Plant_Moss_Block_Yellow"
    },
    {
      "x": -10,
      "y": 28,
      "z": -2,
      "name": "Plant_Moss_Block_Yellow"
    },
    {
      "x": -10,
      "y": 29,
      "z": -2,
      "name": "Plant_Moss_Block_Yellow"
    },
    {
      "x": -10,
      "y": 30,
      "z": -2,
      "name": "Soil_Clay_Lime"
    },
    {
      "x": -10,
      "y": 0,
      "z": -1,
      "name": "Soil_Sand"
    },
    {
      "x": -10,
      "y": 1,
      "z": -1,
      "name": "Soil_Sand"
    },
    {
      "x": -10,
      "y": 2,
      "z": -1,
      "name": "Soil_Sand"
    },
    {
      "x": -10,
      "y": 3,
      "z": -1,
      "name": "Soil_Sand"
    },
    {
      "x": -10,
      "y": 4,
      "z": -1,
      "name": "Soil_Sand"
    },
    {
      "x": -10,
      "y": 5,
      "z": -1,
      "name": "Soil_Sand"
    },
    {
      "x": -10,
      "y": 6,
      "z": -1,
      "name": "Soil_Sand"
    },
    {
      "x": -10,
      "y": 7,
      "z": -1,
      "name": "Soil_Sand"
    },
    {
      "x": -10,
      "y": 8,
      "z": -1,
      "name": "Soil_Sand"
    },
    {
      "x": -10,
      "y": 9,
      "z": -1,
      "name": "Soil_Sand"
    },
    {
      "x": -10,
      "y": 10,
      "z": -1,
      "name": "Soil_Sand"
    },
    {
      "x": -10,
      "y": 11,
      "z": -1,
      "name": "Soil_Sand"
    },
    {
      "x": -10,
      "y": 12,
      "z": -1,
      "name": "Soil_Sand"
    },
    {
      "x": -10,
      "y": 13,
      "z": -1,
      "name": "Soil_Sand"
    },
    {
      "x": -10,
      "y": 0,
      "z": 0,
      "name": "Soil_Sand"
    },
    {
      "x": -10,
      "y": 1,
      "z": 0,
      "name": "Soil_Sand"
    },
    {
      "x": -10,
      "y": 2,
      "z": 0,
      "name": "Soil_Sand"
    },
    {
      "x": -10,
      "y": 3,
      "z": 0,
      "name": "Soil_Sand"
    },
    {
      "x": -10,
      "y": 4,
      "z": 0,
      "name": "Soil_Sand"
    },
    {
      "x": -10,
      "y": 5,
      "z": 0,
      "name": "Soil_Sand"
    },
    {
      "x": -10,
      "y": 6,
      "z": 0,
      "name": "Soil_Sand"
    },
    {
      "x": -10,
      "y": 7,
      "z": 0,
      "name": "Soil_Sand"
    },
    {
      "x": -10,
      "y": 8,
      "z": 0,
      "name": "Soil_Sand"
    },
    {
      "x": -10,
      "y": 9,
      "z": 0,
      "name": "Soil_Sand"
    },
    {
      "x": -10,
      "y": 10,
      "z": 0,
      "name": "Soil_Sand"
    },
    {
      "x": -10,
      "y": 11,
      "z": 0,
      "name": "Soil_Sand"
    },
    {
      "x": -10,
      "y": 12,
      "z": 0,
      "name": "Soil_Sand"
    },
    {
      "x": -10,
      "y": 0,
      "z": 1,
      "name": "Soil_Sand"
    },
    {
      "x": -10,
      "y": 1,
      "z": 1,
      "name": "Soil_Sand"
    },
    {
      "x": -10,
      "y": 2,
      "z": 1,
      "name": "Soil_Sand"
    },
    {
      "x": -10,
      "y": 3,
      "z": 1,
      "name": "Soil_Sand"
    },
    {
      "x": -10,
      "y": 4,
      "z": 1,
      "name": "Soil_Sand"
    },
    {
      "x": -10,
      "y": 5,
      "z": 1,
      "name": "Soil_Sand"
    },
    {
      "x": -10,
      "y": 6,
      "z": 1,
      "name": "Soil_Sand"
    },
    {
      "x": -10,
      "y": 7,
      "z": 1,
      "name": "Soil_Sand"
    },
    {
      "x": -10,
      "y": 8,
      "z": 1,
      "name": "Soil_Sand"
    },
    {
      "x": -10,
      "y": 9,
      "z": 1,
      "name": "Soil_Sand"
    },
    {
      "x": -10,
      "y": 10,
      "z": 1,
      "name": "Soil_Sand"
    },
    {
      "x": -10,
      "y": 11,
      "z": 1,
      "name": "Soil_Sand"
    },
    {
      "x": -10,
      "y": 12,
      "z": 1,
      "name": "Soil_Sand"
    },
    {
      "x": -10,
      "y": 0,
      "z": 2,
      "name": "Soil_Sand"
    },
    {
      "x": -10,
      "y": 1,
      "z": 2,
      "name": "Soil_Sand"
    },
    {
      "x": -10,
      "y": 2,
      "z": 2,
      "name": "Soil_Sand"
    },
    {
      "x": -10,
      "y": 3,
      "z": 2,
      "name": "Soil_Sand"
    },
    {
      "x": -10,
      "y": 4,
      "z": 2,
      "name": "Soil_Sand"
    },
    {
      "x": -10,
      "y": 5,
      "z": 2,
      "name": "Soil_Sand"
    },
    {
      "x": -10,
      "y": 6,
      "z": 2,
      "name": "Soil_Sand"
    },
    {
      "x": -10,
      "y": 7,
      "z": 2,
      "name": "Soil_Sand"
    },
    {
      "x": -10,
      "y": 8,
      "z": 2,
      "name": "Soil_Sand"
    },
    {
      "x": -10,
      "y": 9,
      "z": 2,
      "name": "Soil_Sand"
    },
    {
      "x": -10,
      "y": 10,
      "z": 2,
      "name": "Soil_Sand"
    },
    {
      "x": -10,
      "y": 11,
      "z": 2,
      "name": "Soil_Sand"
    },
    {
      "x": -10,
      "y": 0,
      "z": 3,
      "name": "Soil_Sand"
    },
    {
      "x": -10,
      "y": 1,
      "z": 3,
      "name": "Soil_Sand"
    },
    {
      "x": -10,
      "y": 2,
      "z": 3,
      "name": "Soil_Sand"
    },
    {
      "x": -10,
      "y": 3,
      "z": 3,
      "name": "Soil_Sand"
    },
    {
      "x": -10,
      "y": 4,
      "z": 3,
      "name": "Soil_Sand"
    },
    {
      "x": -10,
      "y": 5,
      "z": 3,
      "name": "Soil_Clay_Lime"
    },
    {
      "x": -10,
      "y": 6,
      "z": 3,
      "name": "Soil_Sand"
    },
    {
      "x": -10,
      "y": 7,
      "z": 3,
      "name": "Soil_Sand"
    },
    {
      "x": -10,
      "y": 8,
      "z": 3,
      "name": "Soil_Sand"
    },
    {
      "x": -10,
      "y": 9,
      "z": 3,
      "name": "Soil_Sand"
    },
    {
      "x": -10,
      "y": 10,
      "z": 3,
      "name": "Soil_Sand"
    },
    {
      "x": -10,
      "y": 0,
      "z": 4,
      "name": "Soil_Sand"
    },
    {
      "x": -10,
      "y": 1,
      "z": 4,
      "name": "Soil_Sand"
    },
    {
      "x": -10,
      "y": 2,
      "z": 4,
      "name": "Soil_Sand"
    },
    {
      "x": -10,
      "y": 3,
      "z": 4,
      "name": "Soil_Sand"
    },
    {
      "x": -10,
      "y": 4,
      "z": 4,
      "name": "Soil_Sand"
    },
    {
      "x": -10,
      "y": 5,
      "z": 4,
      "name": "Soil_Clay_Lime"
    },
    {
      "x": -10,
      "y": 6,
      "z": 4,
      "name": "Soil_Sand"
    },
    {
      "x": -10,
      "y": 7,
      "z": 4,
      "name": "Soil_Sand"
    },
    {
      "x": -10,
      "y": 8,
      "z": 4,
      "name": "Soil_Sand"
    },
    {
      "x": -10,
      "y": 9,
      "z": 4,
      "name": "Plant_Leaves_Palm_Arid"
    },
    {
      "x": -10,
      "y": 0,
      "z": 5,
      "name": "Soil_Sand"
    },
    {
      "x": -10,
      "y": 1,
      "z": 5,
      "name": "Soil_Sand"
    },
    {
      "x": -10,
      "y": 2,
      "z": 5,
      "name": "Soil_Sand"
    },
    {
      "x": -10,
      "y": 3,
      "z": 5,
      "name": "Soil_Sand"
    },
    {
      "x": -10,
      "y": 4,
      "z": 5,
      "name": "Soil_Sand"
    },
    {
      "x": -10,
      "y": 5,
      "z": 5,
      "name": "Soil_Clay_Lime"
    },
    {
      "x": -10,
      "y": 6,
      "z": 5,
      "name": "Soil_Sand"
    },
    {
      "x": -10,
      "y": 7,
      "z": 5,
      "name": "Soil_Sand"
    },
    {
      "x": -10,
      "y": 8,
      "z": 5,
      "name": "Soil_Sand"
    },
    {
      "x": -10,
      "y": 9,
      "z": 5,
      "name": "Plant_Leaves_Palm_Arid"
    },
    {
      "x": -10,
      "y": 0,
      "z": 6,
      "name": "Soil_Sand"
    },
    {
      "x": -10,
      "y": 1,
      "z": 6,
      "name": "Soil_Sand"
    },
    {
      "x": -10,
      "y": 2,
      "z": 6,
      "name": "Soil_Sand"
    },
    {
      "x": -10,
      "y": 3,
      "z": 6,
      "name": "Soil_Sand"
    },
    {
      "x": -10,
      "y": 6,
      "z": 6,
      "name": "Rock_Stone_Mossy"
    },
    {
      "x": -10,
      "y": 7,
      "z": 6,
      "name": "Soil_Sand"
    },
    {
      "x": -10,
      "y": 8,
      "z": 6,
      "name": "Soil_Sand"
    },
    {
      "x": -10,
      "y": 9,
      "z": 6,
      "name": "Plant_Flower_Bushy_Yellow"
    },
    {
      "x": -10,
      "y": 0,
      "z": 7,
      "name": "Soil_Sand"
    },
    {
      "x": -10,
      "y": 1,
      "z": 7,
      "name": "Soil_Sand"
    },
    {
      "x": -10,
      "y": 2,
      "z": 7,
      "name": "Soil_Sand"
    },
    {
      "x": -10,
      "y": 3,
      "z": 7,
      "name": "Plant_Flower_Bushy_Yellow"
    },
    {
      "x": -10,
      "y": 6,
      "z": 7,
      "name": "Rock_Stone_Mossy"
    },
    {
      "x": -10,
      "y": 7,
      "z": 7,
      "name": "Soil_Sand"
    },
    {
      "x": -10,
      "y": 8,
      "z": 7,
      "name": "Soil_Sand"
    },
    {
      "x": -10,
      "y": 9,
      "z": 7,
      "name": "Plant_Flower_Bushy_Yellow"
    },
    {
      "x": -10,
      "y": 0,
      "z": 8,
      "name": "Soil_Sand"
    },
    {
      "x": -10,
      "y": 1,
      "z": 8,
      "name": "Soil_Sand"
    },
    {
      "x": -10,
      "y": 2,
      "z": 8,
      "name": "Soil_Sand"
    },
    {
      "x": -10,
      "y": 3,
      "z": 8,
      "name": "Plant_Flower_Bushy_Yellow"
    },
    {
      "x": -10,
      "y": 6,
      "z": 8,
      "name": "Soil_Clay_Lime"
    },
    {
      "x": -10,
      "y": 7,
      "z": 8,
      "name": "Soil_Sand"
    },
    {
      "x": -10,
      "y": 8,
      "z": 8,
      "name": "Soil_Sand"
    },
    {
      "x": -10,
      "y": 9,
      "z": 8,
      "name": "Plant_Flower_Bushy_Yellow"
    },
    {
      "x": -10,
      "y": 0,
      "z": 9,
      "name": "Soil_Sand"
    },
    {
      "x": -10,
      "y": 1,
      "z": 9,
      "name": "Soil_Sand"
    },
    {
      "x": -10,
      "y": 2,
      "z": 9,
      "name": "Plant_Flower_Bushy_Yellow"
    },
    {
      "x": -10,
      "y": 7,
      "z": 9,
      "name": "Soil_Clay_Lime"
    },
    {
      "x": -10,
      "y": 8,
      "z": 9,
      "name": "Soil_Sand"
    },
    {
      "x": -10,
      "y": 9,
      "z": 9,
      "name": "Plant_Flower_Bushy_Yellow"
    },
    {
      "x": -10,
      "y": 0,
      "z": 10,
      "name": "Soil_Sand"
    },
    {
      "x": -10,
      "y": 1,
      "z": 10,
      "name": "Soil_Sand"
    },
    {
      "x": -10,
      "y": 2,
      "z": 10,
      "name": "Plant_Flower_Bushy_Yellow"
    },
    {
      "x": -10,
      "y": 7,
      "z": 10,
      "name": "Plant_Moss_Block_Yellow"
    },
    {
      "x": -10,
      "y": 8,
      "z": 10,
      "name": "Plant_Moss_Block_Yellow"
    },
    {
      "x": -9,
      "y": 0,
      "z": -14,
      "name": "Soil_Sand"
    },
    {
      "x": -9,
      "y": 1,
      "z": -14,
      "name": "Soil_Sand"
    },
    {
      "x": -9,
      "y": 2,
      "z": -14,
      "name": "Soil_Sand"
    },
    {
      "x": -9,
      "y": 0,
      "z": -13,
      "name": "Soil_Sand"
    },
    {
      "x": -9,
      "y": 1,
      "z": -13,
      "name": "Soil_Sand"
    },
    {
      "x": -9,
      "y": 2,
      "z": -13,
      "name": "Soil_Sand"
    },
    {
      "x": -9,
      "y": 3,
      "z": -13,
      "name": "Soil_Sand"
    },
    {
      "x": -9,
      "y": 0,
      "z": -12,
      "name": "Soil_Sand"
    },
    {
      "x": -9,
      "y": 1,
      "z": -12,
      "name": "Soil_Sand"
    },
    {
      "x": -9,
      "y": 2,
      "z": -12,
      "name": "Soil_Sand"
    },
    {
      "x": -9,
      "y": 3,
      "z": -12,
      "name": "Soil_Sand"
    },
    {
      "x": -9,
      "y": 4,
      "z": -12,
      "name": "Soil_Sand"
    },
    {
      "x": -9,
      "y": 0,
      "z": -11,
      "name": "Soil_Sand"
    },
    {
      "x": -9,
      "y": 1,
      "z": -11,
      "name": "Soil_Sand"
    },
    {
      "x": -9,
      "y": 2,
      "z": -11,
      "name": "Soil_Sand"
    },
    {
      "x": -9,
      "y": 3,
      "z": -11,
      "name": "Soil_Sand"
    },
    {
      "x": -9,
      "y": 4,
      "z": -11,
      "name": "Soil_Sand"
    },
    {
      "x": -9,
      "y": 5,
      "z": -11,
      "name": "Soil_Sand"
    },
    {
      "x": -9,
      "y": 0,
      "z": -10,
      "name": "Soil_Sand"
    },
    {
      "x": -9,
      "y": 1,
      "z": -10,
      "name": "Soil_Sand"
    },
    {
      "x": -9,
      "y": 2,
      "z": -10,
      "name": "Soil_Sand"
    },
    {
      "x": -9,
      "y": 3,
      "z": -10,
      "name": "Soil_Sand"
    },
    {
      "x": -9,
      "y": 4,
      "z": -10,
      "name": "Soil_Sand"
    },
    {
      "x": -9,
      "y": 5,
      "z": -10,
      "name": "Soil_Sand"
    },
    {
      "x": -9,
      "y": 6,
      "z": -10,
      "name": "Soil_Sand"
    },
    {
      "x": -9,
      "y": 0,
      "z": -9,
      "name": "Soil_Sand"
    },
    {
      "x": -9,
      "y": 1,
      "z": -9,
      "name": "Soil_Sand"
    },
    {
      "x": -9,
      "y": 2,
      "z": -9,
      "name": "Soil_Sand"
    },
    {
      "x": -9,
      "y": 3,
      "z": -9,
      "name": "Soil_Sand"
    },
    {
      "x": -9,
      "y": 4,
      "z": -9,
      "name": "Soil_Sand"
    },
    {
      "x": -9,
      "y": 5,
      "z": -9,
      "name": "Soil_Sand"
    },
    {
      "x": -9,
      "y": 6,
      "z": -9,
      "name": "Soil_Sand"
    },
    {
      "x": -9,
      "y": 7,
      "z": -9,
      "name": "Soil_Sand"
    },
    {
      "x": -9,
      "y": 0,
      "z": -8,
      "name": "Soil_Sand"
    },
    {
      "x": -9,
      "y": 1,
      "z": -8,
      "name": "Soil_Sand"
    },
    {
      "x": -9,
      "y": 2,
      "z": -8,
      "name": "Soil_Sand"
    },
    {
      "x": -9,
      "y": 3,
      "z": -8,
      "name": "Soil_Sand"
    },
    {
      "x": -9,
      "y": 4,
      "z": -8,
      "name": "Soil_Sand"
    },
    {
      "x": -9,
      "y": 5,
      "z": -8,
      "name": "Soil_Sand"
    },
    {
      "x": -9,
      "y": 6,
      "z": -8,
      "name": "Soil_Sand"
    },
    {
      "x": -9,
      "y": 7,
      "z": -8,
      "name": "Soil_Sand"
    },
    {
      "x": -9,
      "y": 8,
      "z": -8,
      "name": "Soil_Sand"
    },
    {
      "x": -9,
      "y": 0,
      "z": -7,
      "name": "Soil_Sand"
    },
    {
      "x": -9,
      "y": 1,
      "z": -7,
      "name": "Soil_Sand"
    },
    {
      "x": -9,
      "y": 2,
      "z": -7,
      "name": "Soil_Sand"
    },
    {
      "x": -9,
      "y": 3,
      "z": -7,
      "name": "Soil_Sand"
    },
    {
      "x": -9,
      "y": 4,
      "z": -7,
      "name": "Soil_Sand"
    },
    {
      "x": -9,
      "y": 5,
      "z": -7,
      "name": "Soil_Sand"
    },
    {
      "x": -9,
      "y": 6,
      "z": -7,
      "name": "Soil_Sand"
    },
    {
      "x": -9,
      "y": 7,
      "z": -7,
      "name": "Soil_Sand"
    },
    {
      "x": -9,
      "y": 8,
      "z": -7,
      "name": "Soil_Sand"
    },
    {
      "x": -9,
      "y": 9,
      "z": -7,
      "name": "Soil_Sand"
    },
    {
      "x": -9,
      "y": 10,
      "z": -7,
      "name": "Soil_Sand"
    },
    {
      "x": -9,
      "y": 0,
      "z": -6,
      "name": "Soil_Sand"
    },
    {
      "x": -9,
      "y": 1,
      "z": -6,
      "name": "Soil_Sand"
    },
    {
      "x": -9,
      "y": 2,
      "z": -6,
      "name": "Soil_Sand"
    },
    {
      "x": -9,
      "y": 3,
      "z": -6,
      "name": "Soil_Sand"
    },
    {
      "x": -9,
      "y": 4,
      "z": -6,
      "name": "Soil_Sand"
    },
    {
      "x": -9,
      "y": 5,
      "z": -6,
      "name": "Soil_Sand"
    },
    {
      "x": -9,
      "y": 6,
      "z": -6,
      "name": "Soil_Sand"
    },
    {
      "x": -9,
      "y": 7,
      "z": -6,
      "name": "Soil_Sand"
    },
    {
      "x": -9,
      "y": 8,
      "z": -6,
      "name": "Soil_Sand"
    },
    {
      "x": -9,
      "y": 9,
      "z": -6,
      "name": "Soil_Sand"
    },
    {
      "x": -9,
      "y": 10,
      "z": -6,
      "name": "Soil_Sand"
    },
    {
      "x": -9,
      "y": 11,
      "z": -6,
      "name": "Soil_Sand"
    },
    {
      "x": -9,
      "y": 0,
      "z": -5,
      "name": "Soil_Sand"
    },
    {
      "x": -9,
      "y": 1,
      "z": -5,
      "name": "Soil_Sand"
    },
    {
      "x": -9,
      "y": 2,
      "z": -5,
      "name": "Soil_Sand"
    },
    {
      "x": -9,
      "y": 3,
      "z": -5,
      "name": "Soil_Sand"
    },
    {
      "x": -9,
      "y": 4,
      "z": -5,
      "name": "Soil_Sand"
    },
    {
      "x": -9,
      "y": 5,
      "z": -5,
      "name": "Soil_Sand"
    },
    {
      "x": -9,
      "y": 6,
      "z": -5,
      "name": "Soil_Sand"
    },
    {
      "x": -9,
      "y": 7,
      "z": -5,
      "name": "Soil_Sand"
    },
    {
      "x": -9,
      "y": 8,
      "z": -5,
      "name": "Soil_Sand"
    },
    {
      "x": -9,
      "y": 9,
      "z": -5,
      "name": "Soil_Sand"
    },
    {
      "x": -9,
      "y": 10,
      "z": -5,
      "name": "Soil_Sand"
    },
    {
      "x": -9,
      "y": 11,
      "z": -5,
      "name": "Soil_Sand"
    },
    {
      "x": -9,
      "y": 12,
      "z": -5,
      "name": "Soil_Sand"
    },
    {
      "x": -9,
      "y": 0,
      "z": -4,
      "name": "Soil_Sand"
    },
    {
      "x": -9,
      "y": 1,
      "z": -4,
      "name": "Soil_Sand"
    },
    {
      "x": -9,
      "y": 2,
      "z": -4,
      "name": "Soil_Sand"
    },
    {
      "x": -9,
      "y": 3,
      "z": -4,
      "name": "Soil_Sand"
    },
    {
      "x": -9,
      "y": 4,
      "z": -4,
      "name": "Soil_Sand"
    },
    {
      "x": -9,
      "y": 5,
      "z": -4,
      "name": "Soil_Sand"
    },
    {
      "x": -9,
      "y": 6,
      "z": -4,
      "name": "Soil_Sand"
    },
    {
      "x": -9,
      "y": 7,
      "z": -4,
      "name": "Soil_Sand"
    },
    {
      "x": -9,
      "y": 8,
      "z": -4,
      "name": "Soil_Sand"
    },
    {
      "x": -9,
      "y": 9,
      "z": -4,
      "name": "Soil_Sand"
    },
    {
      "x": -9,
      "y": 10,
      "z": -4,
      "name": "Soil_Sand"
    },
    {
      "x": -9,
      "y": 11,
      "z": -4,
      "name": "Soil_Sand"
    },
    {
      "x": -9,
      "y": 12,
      "z": -4,
      "name": "Soil_Sand"
    },
    {
      "x": -9,
      "y": 13,
      "z": -4,
      "name": "Soil_Sand"
    },
    {
      "x": -9,
      "y": 22,
      "z": -4,
      "name": "Rock_Stone_Mossy"
    },
    {
      "x": -9,
      "y": 23,
      "z": -4,
      "name": "Rock_Stone_Mossy"
    },
    {
      "x": -9,
      "y": 24,
      "z": -4,
      "name": "Rock_Stone_Mossy"
    },
    {
      "x": -9,
      "y": 25,
      "z": -4,
      "name": "Soil_Clay_Lime"
    },
    {
      "x": -9,
      "y": 26,
      "z": -4,
      "name": "Plant_Moss_Block_Yellow"
    },
    {
      "x": -9,
      "y": 27,
      "z": -4,
      "name": "Plant_Moss_Block_Yellow"
    },
    {
      "x": -9,
      "y": 28,
      "z": -4,
      "name": "Plant_Moss_Block_Yellow"
    },
    {
      "x": -9,
      "y": 29,
      "z": -4,
      "name": "Plant_Moss_Block_Yellow"
    },
    {
      "x": -9,
      "y": 30,
      "z": -4,
      "name": "Plant_Moss_Block_Yellow"
    },
    {
      "x": -9,
      "y": 36,
      "z": -4,
      "name": "Soil_Clay_Lime"
    },
    {
      "x": -9,
      "y": 37,
      "z": -4,
      "name": "Soil_Clay_Lime"
    },
    {
      "x": -9,
      "y": 38,
      "z": -4,
      "name": "Soil_Clay_Lime"
    },
    {
      "x": -9,
      "y": 0,
      "z": -3,
      "name": "Soil_Sand"
    },
    {
      "x": -9,
      "y": 1,
      "z": -3,
      "name": "Soil_Sand"
    },
    {
      "x": -9,
      "y": 2,
      "z": -3,
      "name": "Soil_Sand"
    },
    {
      "x": -9,
      "y": 3,
      "z": -3,
      "name": "Soil_Sand"
    },
    {
      "x": -9,
      "y": 4,
      "z": -3,
      "name": "Soil_Sand"
    },
    {
      "x": -9,
      "y": 5,
      "z": -3,
      "name": "Soil_Sand"
    },
    {
      "x": -9,
      "y": 6,
      "z": -3,
      "name": "Soil_Sand"
    },
    {
      "x": -9,
      "y": 7,
      "z": -3,
      "name": "Soil_Sand"
    },
    {
      "x": -9,
      "y": 8,
      "z": -3,
      "name": "Soil_Sand"
    },
    {
      "x": -9,
      "y": 9,
      "z": -3,
      "name": "Soil_Sand"
    },
    {
      "x": -9,
      "y": 10,
      "z": -3,
      "name": "Soil_Sand"
    },
    {
      "x": -9,
      "y": 11,
      "z": -3,
      "name": "Soil_Sand"
    },
    {
      "x": -9,
      "y": 12,
      "z": -3,
      "name": "Soil_Sand"
    },
    {
      "x": -9,
      "y": 13,
      "z": -3,
      "name": "Soil_Sand"
    },
    {
      "x": -9,
      "y": 14,
      "z": -3,
      "name": "Soil_Sand"
    },
    {
      "x": -9,
      "y": 22,
      "z": -3,
      "name": "Soil_Clay_Lime"
    },
    {
      "x": -9,
      "y": 23,
      "z": -3,
      "name": "Rock_Stone_Mossy"
    },
    {
      "x": -9,
      "y": 24,
      "z": -3,
      "name": "Rock_Stone_Mossy"
    },
    {
      "x": -9,
      "y": 25,
      "z": -3,
      "name": "Soil_Sand"
    },
    {
      "x": -9,
      "y": 26,
      "z": -3,
      "name": "Soil_Sand"
    },
    {
      "x": -9,
      "y": 27,
      "z": -3,
      "name": "Soil_Sand"
    },
    {
      "x": -9,
      "y": 28,
      "z": -3,
      "name": "Soil_Sand"
    },
    {
      "x": -9,
      "y": 29,
      "z": -3,
      "name": "Soil_Sand"
    },
    {
      "x": -9,
      "y": 30,
      "z": -3,
      "name": "Soil_Sand"
    },
    {
      "x": -9,
      "y": 31,
      "z": -3,
      "name": "Soil_Sand"
    },
    {
      "x": -9,
      "y": 32,
      "z": -3,
      "name": "Plant_Flower_Bushy_Yellow"
    },
    {
      "x": -9,
      "y": 36,
      "z": -3,
      "name": "Soil_Clay_Lime"
    },
    {
      "x": -9,
      "y": 37,
      "z": -3,
      "name": "Soil_Clay_Lime"
    },
    {
      "x": -9,
      "y": 38,
      "z": -3,
      "name": "Soil_Clay_Lime"
    },
    {
      "x": -9,
      "y": 0,
      "z": -2,
      "name": "Soil_Sand"
    },
    {
      "x": -9,
      "y": 1,
      "z": -2,
      "name": "Soil_Sand"
    },
    {
      "x": -9,
      "y": 2,
      "z": -2,
      "name": "Soil_Sand"
    },
    {
      "x": -9,
      "y": 3,
      "z": -2,
      "name": "Soil_Sand"
    },
    {
      "x": -9,
      "y": 4,
      "z": -2,
      "name": "Soil_Sand"
    },
    {
      "x": -9,
      "y": 5,
      "z": -2,
      "name": "Soil_Sand"
    },
    {
      "x": -9,
      "y": 6,
      "z": -2,
      "name": "Soil_Sand"
    },
    {
      "x": -9,
      "y": 7,
      "z": -2,
      "name": "Soil_Sand"
    },
    {
      "x": -9,
      "y": 8,
      "z": -2,
      "name": "Soil_Sand"
    },
    {
      "x": -9,
      "y": 9,
      "z": -2,
      "name": "Soil_Sand"
    },
    {
      "x": -9,
      "y": 10,
      "z": -2,
      "name": "Soil_Sand"
    },
    {
      "x": -9,
      "y": 11,
      "z": -2,
      "name": "Soil_Sand"
    },
    {
      "x": -9,
      "y": 12,
      "z": -2,
      "name": "Soil_Sand"
    },
    {
      "x": -9,
      "y": 13,
      "z": -2,
      "name": "Soil_Sand"
    },
    {
      "x": -9,
      "y": 14,
      "z": -2,
      "name": "Soil_Sand"
    },
    {
      "x": -9,
      "y": 22,
      "z": -2,
      "name": "Soil_Clay_Lime"
    },
    {
      "x": -9,
      "y": 23,
      "z": -2,
      "name": "Rock_Stone_Mossy"
    },
    {
      "x": -9,
      "y": 24,
      "z": -2,
      "name": "Rock_Stone_Mossy"
    },
    {
      "x": -9,
      "y": 25,
      "z": -2,
      "name": "Rock_Stone_Mossy"
    },
    {
      "x": -9,
      "y": 26,
      "z": -2,
      "name": "Soil_Sand"
    },
    {
      "x": -9,
      "y": 27,
      "z": -2,
      "name": "Soil_Sand"
    },
    {
      "x": -9,
      "y": 28,
      "z": -2,
      "name": "Soil_Sand"
    },
    {
      "x": -9,
      "y": 29,
      "z": -2,
      "name": "Soil_Sand"
    },
    {
      "x": -9,
      "y": 30,
      "z": -2,
      "name": "Soil_Sand"
    },
    {
      "x": -9,
      "y": 31,
      "z": -2,
      "name": "Soil_Sand"
    },
    {
      "x": -9,
      "y": 32,
      "z": -2,
      "name": "Plant_Flower_Bushy_Yellow"
    },
    {
      "x": -9,
      "y": 36,
      "z": -2,
      "name": "Soil_Clay_Lime"
    },
    {
      "x": -9,
      "y": 37,
      "z": -2,
      "name": "Soil_Clay_Lime"
    },
    {
      "x": -9,
      "y": 38,
      "z": -2,
      "name": "Soil_Clay_Lime"
    },
    {
      "x": -9,
      "y": 0,
      "z": -1,
      "name": "Soil_Sand"
    },
    {
      "x": -9,
      "y": 1,
      "z": -1,
      "name": "Soil_Sand"
    },
    {
      "x": -9,
      "y": 2,
      "z": -1,
      "name": "Soil_Sand"
    },
    {
      "x": -9,
      "y": 3,
      "z": -1,
      "name": "Soil_Sand"
    },
    {
      "x": -9,
      "y": 4,
      "z": -1,
      "name": "Soil_Sand"
    },
    {
      "x": -9,
      "y": 5,
      "z": -1,
      "name": "Soil_Sand"
    },
    {
      "x": -9,
      "y": 6,
      "z": -1,
      "name": "Soil_Sand"
    },
    {
      "x": -9,
      "y": 7,
      "z": -1,
      "name": "Soil_Sand"
    },
    {
      "x": -9,
      "y": 8,
      "z": -1,
      "name": "Soil_Sand"
    },
    {
      "x": -9,
      "y": 9,
      "z": -1,
      "name": "Soil_Sand"
    },
    {
      "x": -9,
      "y": 10,
      "z": -1,
      "name": "Soil_Sand"
    },
    {
      "x": -9,
      "y": 11,
      "z": -1,
      "name": "Soil_Sand"
    },
    {
      "x": -9,
      "y": 12,
      "z": -1,
      "name": "Soil_Sand"
    },
    {
      "x": -9,
      "y": 13,
      "z": -1,
      "name": "Soil_Sand"
    },
    {
      "x": -9,
      "y": 14,
      "z": -1,
      "name": "Soil_Sand"
    },
    {
      "x": -9,
      "y": 25,
      "z": -1,
      "name": "Rock_Stone_Mossy"
    },
    {
      "x": -9,
      "y": 26,
      "z": -1,
      "name": "Rock_Stone_Mossy"
    },
    {
      "x": -9,
      "y": 27,
      "z": -1,
      "name": "Soil_Clay_Lime"
    },
    {
      "x": -9,
      "y": 28,
      "z": -1,
      "name": "Plant_Moss_Block_Yellow"
    },
    {
      "x": -9,
      "y": 29,
      "z": -1,
      "name": "Plant_Moss_Block_Yellow"
    },
    {
      "x": -9,
      "y": 30,
      "z": -1,
      "name": "Soil_Sand"
    },
    {
      "x": -9,
      "y": 31,
      "z": -1,
      "name": "Plant_Flower_Bushy_Yellow"
    },
    {
      "x": -9,
      "y": 0,
      "z": 0,
      "name": "Soil_Sand"
    },
    {
      "x": -9,
      "y": 1,
      "z": 0,
      "name": "Soil_Sand"
    },
    {
      "x": -9,
      "y": 2,
      "z": 0,
      "name": "Soil_Sand"
    },
    {
      "x": -9,
      "y": 3,
      "z": 0,
      "name": "Soil_Sand"
    },
    {
      "x": -9,
      "y": 4,
      "z": 0,
      "name": "Soil_Sand"
    },
    {
      "x": -9,
      "y": 5,
      "z": 0,
      "name": "Soil_Sand"
    },
    {
      "x": -9,
      "y": 6,
      "z": 0,
      "name": "Soil_Sand"
    },
    {
      "x": -9,
      "y": 7,
      "z": 0,
      "name": "Soil_Sand"
    },
    {
      "x": -9,
      "y": 8,
      "z": 0,
      "name": "Soil_Sand"
    },
    {
      "x": -9,
      "y": 9,
      "z": 0,
      "name": "Soil_Sand"
    },
    {
      "x": -9,
      "y": 10,
      "z": 0,
      "name": "Soil_Sand"
    },
    {
      "x": -9,
      "y": 11,
      "z": 0,
      "name": "Soil_Sand"
    },
    {
      "x": -9,
      "y": 12,
      "z": 0,
      "name": "Soil_Sand"
    },
    {
      "x": -9,
      "y": 13,
      "z": 0,
      "name": "Soil_Sand"
    },
    {
      "x": -9,
      "y": 14,
      "z": 0,
      "name": "Soil_Sand"
    },
    {
      "x": -9,
      "y": 0,
      "z": 1,
      "name": "Soil_Sand"
    },
    {
      "x": -9,
      "y": 1,
      "z": 1,
      "name": "Soil_Sand"
    },
    {
      "x": -9,
      "y": 2,
      "z": 1,
      "name": "Soil_Sand"
    },
    {
      "x": -9,
      "y": 3,
      "z": 1,
      "name": "Soil_Sand"
    },
    {
      "x": -9,
      "y": 4,
      "z": 1,
      "name": "Soil_Sand"
    },
    {
      "x": -9,
      "y": 5,
      "z": 1,
      "name": "Soil_Sand"
    },
    {
      "x": -9,
      "y": 6,
      "z": 1,
      "name": "Soil_Sand"
    },
    {
      "x": -9,
      "y": 7,
      "z": 1,
      "name": "Soil_Sand"
    },
    {
      "x": -9,
      "y": 8,
      "z": 1,
      "name": "Soil_Sand"
    },
    {
      "x": -9,
      "y": 9,
      "z": 1,
      "name": "Soil_Sand"
    },
    {
      "x": -9,
      "y": 10,
      "z": 1,
      "name": "Soil_Sand"
    },
    {
      "x": -9,
      "y": 11,
      "z": 1,
      "name": "Soil_Sand"
    },
    {
      "x": -9,
      "y": 12,
      "z": 1,
      "name": "Soil_Sand"
    },
    {
      "x": -9,
      "y": 13,
      "z": 1,
      "name": "Soil_Sand"
    },
    {
      "x": -9,
      "y": 14,
      "z": 1,
      "name": "Soil_Sand"
    },
    {
      "x": -9,
      "y": 0,
      "z": 2,
      "name": "Soil_Sand"
    },
    {
      "x": -9,
      "y": 1,
      "z": 2,
      "name": "Soil_Sand"
    },
    {
      "x": -9,
      "y": 2,
      "z": 2,
      "name": "Soil_Sand"
    },
    {
      "x": -9,
      "y": 3,
      "z": 2,
      "name": "Soil_Sand"
    },
    {
      "x": -9,
      "y": 4,
      "z": 2,
      "name": "Soil_Sand"
    },
    {
      "x": -9,
      "y": 5,
      "z": 2,
      "name": "Soil_Sand"
    },
    {
      "x": -9,
      "y": 6,
      "z": 2,
      "name": "Soil_Sand"
    },
    {
      "x": -9,
      "y": 7,
      "z": 2,
      "name": "Soil_Sand"
    },
    {
      "x": -9,
      "y": 8,
      "z": 2,
      "name": "Soil_Sand"
    },
    {
      "x": -9,
      "y": 9,
      "z": 2,
      "name": "Soil_Sand"
    },
    {
      "x": -9,
      "y": 10,
      "z": 2,
      "name": "Soil_Sand"
    },
    {
      "x": -9,
      "y": 11,
      "z": 2,
      "name": "Soil_Sand"
    },
    {
      "x": -9,
      "y": 12,
      "z": 2,
      "name": "Soil_Sand"
    },
    {
      "x": -9,
      "y": 13,
      "z": 2,
      "name": "Soil_Sand"
    },
    {
      "x": -9,
      "y": 14,
      "z": 2,
      "name": "Soil_Sand"
    },
    {
      "x": -9,
      "y": 0,
      "z": 3,
      "name": "Soil_Sand"
    },
    {
      "x": -9,
      "y": 1,
      "z": 3,
      "name": "Soil_Sand"
    },
    {
      "x": -9,
      "y": 2,
      "z": 3,
      "name": "Soil_Sand"
    },
    {
      "x": -9,
      "y": 3,
      "z": 3,
      "name": "Soil_Sand"
    },
    {
      "x": -9,
      "y": 4,
      "z": 3,
      "name": "Soil_Sand"
    },
    {
      "x": -9,
      "y": 5,
      "z": 3,
      "name": "Soil_Sand"
    },
    {
      "x": -9,
      "y": 6,
      "z": 3,
      "name": "Soil_Sand"
    },
    {
      "x": -9,
      "y": 7,
      "z": 3,
      "name": "Soil_Sand"
    },
    {
      "x": -9,
      "y": 8,
      "z": 3,
      "name": "Soil_Sand"
    },
    {
      "x": -9,
      "y": 9,
      "z": 3,
      "name": "Soil_Sand"
    },
    {
      "x": -9,
      "y": 10,
      "z": 3,
      "name": "Soil_Sand"
    },
    {
      "x": -9,
      "y": 11,
      "z": 3,
      "name": "Soil_Sand"
    },
    {
      "x": -9,
      "y": 12,
      "z": 3,
      "name": "Soil_Sand"
    },
    {
      "x": -9,
      "y": 13,
      "z": 3,
      "name": "Soil_Sand"
    },
    {
      "x": -9,
      "y": 0,
      "z": 4,
      "name": "Soil_Sand"
    },
    {
      "x": -9,
      "y": 1,
      "z": 4,
      "name": "Soil_Sand"
    },
    {
      "x": -9,
      "y": 2,
      "z": 4,
      "name": "Soil_Sand"
    },
    {
      "x": -9,
      "y": 3,
      "z": 4,
      "name": "Soil_Sand"
    },
    {
      "x": -9,
      "y": 4,
      "z": 4,
      "name": "Soil_Sand"
    },
    {
      "x": -9,
      "y": 5,
      "z": 4,
      "name": "Soil_Sand"
    },
    {
      "x": -9,
      "y": 6,
      "z": 4,
      "name": "Soil_Sand"
    },
    {
      "x": -9,
      "y": 7,
      "z": 4,
      "name": "Soil_Sand"
    },
    {
      "x": -9,
      "y": 8,
      "z": 4,
      "name": "Soil_Sand"
    },
    {
      "x": -9,
      "y": 9,
      "z": 4,
      "name": "Soil_Sand"
    },
    {
      "x": -9,
      "y": 10,
      "z": 4,
      "name": "Soil_Sand"
    },
    {
      "x": -9,
      "y": 11,
      "z": 4,
      "name": "Soil_Sand"
    },
    {
      "x": -9,
      "y": 0,
      "z": 5,
      "name": "Soil_Sand"
    },
    {
      "x": -9,
      "y": 1,
      "z": 5,
      "name": "Soil_Sand"
    },
    {
      "x": -9,
      "y": 2,
      "z": 5,
      "name": "Soil_Sand"
    },
    {
      "x": -9,
      "y": 3,
      "z": 5,
      "name": "Soil_Sand"
    },
    {
      "x": -9,
      "y": 4,
      "z": 5,
      "name": "Soil_Sand"
    },
    {
      "x": -9,
      "y": 5,
      "z": 5,
      "name": "Soil_Sand"
    },
    {
      "x": -9,
      "y": 6,
      "z": 5,
      "name": "Soil_Sand"
    },
    {
      "x": -9,
      "y": 7,
      "z": 5,
      "name": "Soil_Sand"
    },
    {
      "x": -9,
      "y": 8,
      "z": 5,
      "name": "Soil_Sand"
    },
    {
      "x": -9,
      "y": 9,
      "z": 5,
      "name": "Soil_Sand"
    },
    {
      "x": -9,
      "y": 0,
      "z": 6,
      "name": "Soil_Sand"
    },
    {
      "x": -9,
      "y": 1,
      "z": 6,
      "name": "Soil_Sand"
    },
    {
      "x": -9,
      "y": 2,
      "z": 6,
      "name": "Soil_Sand"
    },
    {
      "x": -9,
      "y": 3,
      "z": 6,
      "name": "Soil_Sand"
    },
    {
      "x": -9,
      "y": 4,
      "z": 6,
      "name": "Soil_Sand"
    },
    {
      "x": -9,
      "y": 5,
      "z": 6,
      "name": "Soil_Clay_Lime"
    },
    {
      "x": -9,
      "y": 6,
      "z": 6,
      "name": "Soil_Sand"
    },
    {
      "x": -9,
      "y": 7,
      "z": 6,
      "name": "Soil_Sand"
    },
    {
      "x": -9,
      "y": 8,
      "z": 6,
      "name": "Soil_Sand"
    },
    {
      "x": -9,
      "y": 9,
      "z": 6,
      "name": "Plant_Flower_Bushy_Yellow"
    },
    {
      "x": -9,
      "y": 0,
      "z": 7,
      "name": "Soil_Sand"
    },
    {
      "x": -9,
      "y": 1,
      "z": 7,
      "name": "Soil_Sand"
    },
    {
      "x": -9,
      "y": 2,
      "z": 7,
      "name": "Soil_Sand"
    },
    {
      "x": -9,
      "y": 3,
      "z": 7,
      "name": "Soil_Sand"
    },
    {
      "x": -9,
      "y": 4,
      "z": 7,
      "name": "Soil_Sand"
    },
    {
      "x": -9,
      "y": 5,
      "z": 7,
      "name": "Soil_Sand"
    },
    {
      "x": -9,
      "y": 6,
      "z": 7,
      "name": "Soil_Sand"
    },
    {
      "x": -9,
      "y": 7,
      "z": 7,
      "name": "Soil_Sand"
    },
    {
      "x": -9,
      "y": 8,
      "z": 7,
      "name": "Soil_Sand"
    },
    {
      "x": -9,
      "y": 9,
      "z": 7,
      "name": "Plant_Flower_Bushy_Yellow"
    },
    {
      "x": -9,
      "y": 0,
      "z": 8,
      "name": "Soil_Sand"
    },
    {
      "x": -9,
      "y": 1,
      "z": 8,
      "name": "Soil_Sand"
    },
    {
      "x": -9,
      "y": 2,
      "z": 8,
      "name": "Soil_Sand"
    },
    {
      "x": -9,
      "y": 3,
      "z": 8,
      "name": "Plant_Flower_Bushy_Yellow"
    },
    {
      "x": -9,
      "y": 6,
      "z": 8,
      "name": "Soil_Clay_Lime"
    },
    {
      "x": -9,
      "y": 7,
      "z": 8,
      "name": "Soil_Sand"
    },
    {
      "x": -9,
      "y": 8,
      "z": 8,
      "name": "Soil_Sand"
    },
    {
      "x": -9,
      "y": 9,
      "z": 8,
      "name": "Plant_Flower_Bushy_Yellow"
    },
    {
      "x": -9,
      "y": 0,
      "z": 9,
      "name": "Soil_Sand"
    },
    {
      "x": -9,
      "y": 1,
      "z": 9,
      "name": "Soil_Sand"
    },
    {
      "x": -9,
      "y": 2,
      "z": 9,
      "name": "Soil_Sand"
    },
    {
      "x": -9,
      "y": 3,
      "z": 9,
      "name": "Plant_Flower_Bushy_Yellow"
    },
    {
      "x": -9,
      "y": 6,
      "z": 9,
      "name": "Plant_Moss_Block_Yellow"
    },
    {
      "x": -9,
      "y": 7,
      "z": 9,
      "name": "Soil_Sand"
    },
    {
      "x": -9,
      "y": 8,
      "z": 9,
      "name": "Soil_Sand"
    },
    {
      "x": -9,
      "y": 9,
      "z": 9,
      "name": "Plant_Flower_Bushy_Yellow"
    },
    {
      "x": -9,
      "y": 0,
      "z": 10,
      "name": "Soil_Sand"
    },
    {
      "x": -9,
      "y": 1,
      "z": 10,
      "name": "Soil_Sand"
    },
    {
      "x": -9,
      "y": 2,
      "z": 10,
      "name": "Plant_Flower_Bushy_Yellow"
    },
    {
      "x": -9,
      "y": 7,
      "z": 10,
      "name": "Plant_Moss_Block_Yellow"
    },
    {
      "x": -9,
      "y": 8,
      "z": 10,
      "name": "Soil_Sand"
    },
    {
      "x": -9,
      "y": 9,
      "z": 10,
      "name": "Plant_Bush_Arid_Sharp"
    },
    {
      "x": -8,
      "y": 0,
      "z": -14,
      "name": "Soil_Sand"
    },
    {
      "x": -8,
      "y": 1,
      "z": -14,
      "name": "Soil_Sand"
    },
    {
      "x": -8,
      "y": 2,
      "z": -14,
      "name": "Soil_Sand"
    },
    {
      "x": -8,
      "y": 0,
      "z": -13,
      "name": "Soil_Sand"
    },
    {
      "x": -8,
      "y": 1,
      "z": -13,
      "name": "Soil_Sand"
    },
    {
      "x": -8,
      "y": 2,
      "z": -13,
      "name": "Soil_Sand"
    },
    {
      "x": -8,
      "y": 3,
      "z": -13,
      "name": "Soil_Sand"
    },
    {
      "x": -8,
      "y": 0,
      "z": -12,
      "name": "Soil_Sand"
    },
    {
      "x": -8,
      "y": 1,
      "z": -12,
      "name": "Soil_Sand"
    },
    {
      "x": -8,
      "y": 2,
      "z": -12,
      "name": "Soil_Sand"
    },
    {
      "x": -8,
      "y": 3,
      "z": -12,
      "name": "Soil_Sand"
    },
    {
      "x": -8,
      "y": 4,
      "z": -12,
      "name": "Soil_Sand"
    },
    {
      "x": -8,
      "y": 0,
      "z": -11,
      "name": "Soil_Sand"
    },
    {
      "x": -8,
      "y": 1,
      "z": -11,
      "name": "Soil_Sand"
    },
    {
      "x": -8,
      "y": 2,
      "z": -11,
      "name": "Soil_Sand"
    },
    {
      "x": -8,
      "y": 3,
      "z": -11,
      "name": "Soil_Sand"
    },
    {
      "x": -8,
      "y": 4,
      "z": -11,
      "name": "Soil_Sand"
    },
    {
      "x": -8,
      "y": 5,
      "z": -11,
      "name": "Soil_Sand"
    },
    {
      "x": -8,
      "y": 0,
      "z": -10,
      "name": "Soil_Sand"
    },
    {
      "x": -8,
      "y": 1,
      "z": -10,
      "name": "Soil_Sand"
    },
    {
      "x": -8,
      "y": 2,
      "z": -10,
      "name": "Soil_Sand"
    },
    {
      "x": -8,
      "y": 3,
      "z": -10,
      "name": "Soil_Sand"
    },
    {
      "x": -8,
      "y": 4,
      "z": -10,
      "name": "Soil_Sand"
    },
    {
      "x": -8,
      "y": 5,
      "z": -10,
      "name": "Soil_Sand"
    },
    {
      "x": -8,
      "y": 6,
      "z": -10,
      "name": "Soil_Sand"
    },
    {
      "x": -8,
      "y": 7,
      "z": -10,
      "name": "Soil_Sand"
    },
    {
      "x": -8,
      "y": 0,
      "z": -9,
      "name": "Soil_Sand"
    },
    {
      "x": -8,
      "y": 1,
      "z": -9,
      "name": "Soil_Sand"
    },
    {
      "x": -8,
      "y": 2,
      "z": -9,
      "name": "Soil_Sand"
    },
    {
      "x": -8,
      "y": 3,
      "z": -9,
      "name": "Soil_Sand"
    },
    {
      "x": -8,
      "y": 4,
      "z": -9,
      "name": "Soil_Sand"
    },
    {
      "x": -8,
      "y": 5,
      "z": -9,
      "name": "Soil_Sand"
    },
    {
      "x": -8,
      "y": 6,
      "z": -9,
      "name": "Soil_Sand"
    },
    {
      "x": -8,
      "y": 7,
      "z": -9,
      "name": "Soil_Sand"
    },
    {
      "x": -8,
      "y": 8,
      "z": -9,
      "name": "Soil_Sand"
    },
    {
      "x": -8,
      "y": 0,
      "z": -8,
      "name": "Soil_Sand"
    },
    {
      "x": -8,
      "y": 1,
      "z": -8,
      "name": "Soil_Sand"
    },
    {
      "x": -8,
      "y": 2,
      "z": -8,
      "name": "Soil_Sand"
    },
    {
      "x": -8,
      "y": 3,
      "z": -8,
      "name": "Soil_Sand"
    },
    {
      "x": -8,
      "y": 4,
      "z": -8,
      "name": "Soil_Sand"
    },
    {
      "x": -8,
      "y": 5,
      "z": -8,
      "name": "Soil_Sand"
    },
    {
      "x": -8,
      "y": 6,
      "z": -8,
      "name": "Soil_Sand"
    },
    {
      "x": -8,
      "y": 7,
      "z": -8,
      "name": "Soil_Sand"
    },
    {
      "x": -8,
      "y": 8,
      "z": -8,
      "name": "Soil_Sand"
    },
    {
      "x": -8,
      "y": 9,
      "z": -8,
      "name": "Soil_Sand"
    },
    {
      "x": -8,
      "y": 10,
      "z": -8,
      "name": "Soil_Sand"
    },
    {
      "x": -8,
      "y": 0,
      "z": -7,
      "name": "Soil_Sand"
    },
    {
      "x": -8,
      "y": 1,
      "z": -7,
      "name": "Soil_Sand"
    },
    {
      "x": -8,
      "y": 2,
      "z": -7,
      "name": "Soil_Sand"
    },
    {
      "x": -8,
      "y": 3,
      "z": -7,
      "name": "Soil_Sand"
    },
    {
      "x": -8,
      "y": 4,
      "z": -7,
      "name": "Soil_Sand"
    },
    {
      "x": -8,
      "y": 5,
      "z": -7,
      "name": "Soil_Sand"
    },
    {
      "x": -8,
      "y": 6,
      "z": -7,
      "name": "Soil_Sand"
    },
    {
      "x": -8,
      "y": 7,
      "z": -7,
      "name": "Soil_Sand"
    },
    {
      "x": -8,
      "y": 8,
      "z": -7,
      "name": "Soil_Sand"
    },
    {
      "x": -8,
      "y": 9,
      "z": -7,
      "name": "Soil_Sand"
    },
    {
      "x": -8,
      "y": 10,
      "z": -7,
      "name": "Soil_Sand"
    },
    {
      "x": -8,
      "y": 11,
      "z": -7,
      "name": "Soil_Sand"
    },
    {
      "x": -8,
      "y": 0,
      "z": -6,
      "name": "Soil_Sand"
    },
    {
      "x": -8,
      "y": 1,
      "z": -6,
      "name": "Soil_Sand"
    },
    {
      "x": -8,
      "y": 2,
      "z": -6,
      "name": "Soil_Sand"
    },
    {
      "x": -8,
      "y": 3,
      "z": -6,
      "name": "Soil_Sand"
    },
    {
      "x": -8,
      "y": 4,
      "z": -6,
      "name": "Soil_Sand"
    },
    {
      "x": -8,
      "y": 5,
      "z": -6,
      "name": "Soil_Sand"
    },
    {
      "x": -8,
      "y": 6,
      "z": -6,
      "name": "Soil_Sand"
    },
    {
      "x": -8,
      "y": 7,
      "z": -6,
      "name": "Soil_Sand"
    },
    {
      "x": -8,
      "y": 8,
      "z": -6,
      "name": "Soil_Sand"
    },
    {
      "x": -8,
      "y": 9,
      "z": -6,
      "name": "Soil_Sand"
    },
    {
      "x": -8,
      "y": 10,
      "z": -6,
      "name": "Soil_Sand"
    },
    {
      "x": -8,
      "y": 11,
      "z": -6,
      "name": "Soil_Sand"
    },
    {
      "x": -8,
      "y": 12,
      "z": -6,
      "name": "Soil_Sand"
    },
    {
      "x": -8,
      "y": 0,
      "z": -5,
      "name": "Soil_Sand"
    },
    {
      "x": -8,
      "y": 1,
      "z": -5,
      "name": "Soil_Sand"
    },
    {
      "x": -8,
      "y": 2,
      "z": -5,
      "name": "Soil_Sand"
    },
    {
      "x": -8,
      "y": 3,
      "z": -5,
      "name": "Soil_Sand"
    },
    {
      "x": -8,
      "y": 4,
      "z": -5,
      "name": "Soil_Sand"
    },
    {
      "x": -8,
      "y": 5,
      "z": -5,
      "name": "Soil_Sand"
    },
    {
      "x": -8,
      "y": 6,
      "z": -5,
      "name": "Soil_Sand"
    },
    {
      "x": -8,
      "y": 7,
      "z": -5,
      "name": "Soil_Sand"
    },
    {
      "x": -8,
      "y": 8,
      "z": -5,
      "name": "Soil_Sand"
    },
    {
      "x": -8,
      "y": 9,
      "z": -5,
      "name": "Soil_Sand"
    },
    {
      "x": -8,
      "y": 10,
      "z": -5,
      "name": "Soil_Sand"
    },
    {
      "x": -8,
      "y": 11,
      "z": -5,
      "name": "Soil_Sand"
    },
    {
      "x": -8,
      "y": 12,
      "z": -5,
      "name": "Soil_Sand"
    },
    {
      "x": -8,
      "y": 13,
      "z": -5,
      "name": "Soil_Sand"
    },
    {
      "x": -8,
      "y": 14,
      "z": -5,
      "name": "Soil_Sand"
    },
    {
      "x": -8,
      "y": 35,
      "z": -5,
      "name": "Plant_Moss_Block_Yellow"
    },
    {
      "x": -8,
      "y": 36,
      "z": -5,
      "name": "Plant_Moss_Block_Yellow"
    },
    {
      "x": -8,
      "y": 37,
      "z": -5,
      "name": "Soil_Clay_Lime"
    },
    {
      "x": -8,
      "y": 38,
      "z": -5,
      "name": "Plant_Moss_Block_Yellow"
    },
    {
      "x": -8,
      "y": 0,
      "z": -4,
      "name": "Soil_Sand"
    },
    {
      "x": -8,
      "y": 1,
      "z": -4,
      "name": "Soil_Sand"
    },
    {
      "x": -8,
      "y": 2,
      "z": -4,
      "name": "Soil_Sand"
    },
    {
      "x": -8,
      "y": 3,
      "z": -4,
      "name": "Soil_Sand"
    },
    {
      "x": -8,
      "y": 4,
      "z": -4,
      "name": "Soil_Sand"
    },
    {
      "x": -8,
      "y": 5,
      "z": -4,
      "name": "Soil_Sand"
    },
    {
      "x": -8,
      "y": 6,
      "z": -4,
      "name": "Soil_Sand"
    },
    {
      "x": -8,
      "y": 7,
      "z": -4,
      "name": "Soil_Sand"
    },
    {
      "x": -8,
      "y": 8,
      "z": -4,
      "name": "Soil_Sand"
    },
    {
      "x": -8,
      "y": 9,
      "z": -4,
      "name": "Soil_Sand"
    },
    {
      "x": -8,
      "y": 10,
      "z": -4,
      "name": "Soil_Sand"
    },
    {
      "x": -8,
      "y": 11,
      "z": -4,
      "name": "Soil_Sand"
    },
    {
      "x": -8,
      "y": 12,
      "z": -4,
      "name": "Soil_Sand"
    },
    {
      "x": -8,
      "y": 13,
      "z": -4,
      "name": "Soil_Sand"
    },
    {
      "x": -8,
      "y": 14,
      "z": -4,
      "name": "Soil_Sand"
    },
    {
      "x": -8,
      "y": 15,
      "z": -4,
      "name": "Soil_Sand"
    },
    {
      "x": -8,
      "y": 22,
      "z": -4,
      "name": "Rock_Stone_Mossy"
    },
    {
      "x": -8,
      "y": 23,
      "z": -4,
      "name": "Rock_Stone_Mossy"
    },
    {
      "x": -8,
      "y": 24,
      "z": -4,
      "name": "Soil_Clay_Lime"
    },
    {
      "x": -8,
      "y": 25,
      "z": -4,
      "name": "Soil_Clay_Lime"
    },
    {
      "x": -8,
      "y": 26,
      "z": -4,
      "name": "Plant_Moss_Block_Yellow"
    },
    {
      "x": -8,
      "y": 27,
      "z": -4,
      "name": "Plant_Moss_Block_Yellow"
    },
    {
      "x": -8,
      "y": 28,
      "z": -4,
      "name": "Plant_Moss_Block_Yellow"
    },
    {
      "x": -8,
      "y": 29,
      "z": -4,
      "name": "Plant_Moss_Block_Yellow"
    },
    {
      "x": -8,
      "y": 30,
      "z": -4,
      "name": "Soil_Sand"
    },
    {
      "x": -8,
      "y": 31,
      "z": -4,
      "name": "Soil_Sand"
    },
    {
      "x": -8,
      "y": 32,
      "z": -4,
      "name": "Plant_Flower_Bushy_Yellow"
    },
    {
      "x": -8,
      "y": 35,
      "z": -4,
      "name": "Plant_Moss_Block_Yellow"
    },
    {
      "x": -8,
      "y": 36,
      "z": -4,
      "name": "Soil_Sand"
    },
    {
      "x": -8,
      "y": 37,
      "z": -4,
      "name": "Soil_Sand"
    },
    {
      "x": -8,
      "y": 38,
      "z": -4,
      "name": "Soil_Clay_Lime"
    },
    {
      "x": -8,
      "y": 0,
      "z": -3,
      "name": "Soil_Sand"
    },
    {
      "x": -8,
      "y": 1,
      "z": -3,
      "name": "Soil_Sand"
    },
    {
      "x": -8,
      "y": 2,
      "z": -3,
      "name": "Soil_Sand"
    },
    {
      "x": -8,
      "y": 3,
      "z": -3,
      "name": "Soil_Sand"
    },
    {
      "x": -8,
      "y": 4,
      "z": -3,
      "name": "Soil_Sand"
    },
    {
      "x": -8,
      "y": 5,
      "z": -3,
      "name": "Soil_Sand"
    },
    {
      "x": -8,
      "y": 6,
      "z": -3,
      "name": "Soil_Sand"
    },
    {
      "x": -8,
      "y": 7,
      "z": -3,
      "name": "Soil_Sand"
    },
    {
      "x": -8,
      "y": 8,
      "z": -3,
      "name": "Soil_Sand"
    },
    {
      "x": -8,
      "y": 9,
      "z": -3,
      "name": "Soil_Sand"
    },
    {
      "x": -8,
      "y": 10,
      "z": -3,
      "name": "Soil_Sand"
    },
    {
      "x": -8,
      "y": 11,
      "z": -3,
      "name": "Soil_Sand"
    },
    {
      "x": -8,
      "y": 12,
      "z": -3,
      "name": "Soil_Sand"
    },
    {
      "x": -8,
      "y": 13,
      "z": -3,
      "name": "Soil_Sand"
    },
    {
      "x": -8,
      "y": 14,
      "z": -3,
      "name": "Soil_Sand"
    },
    {
      "x": -8,
      "y": 15,
      "z": -3,
      "name": "Soil_Sand"
    },
    {
      "x": -8,
      "y": 22,
      "z": -3,
      "name": "Soil_Clay_Lime"
    },
    {
      "x": -8,
      "y": 23,
      "z": -3,
      "name": "Soil_Sand"
    },
    {
      "x": -8,
      "y": 24,
      "z": -3,
      "name": "Soil_Sand"
    },
    {
      "x": -8,
      "y": 25,
      "z": -3,
      "name": "Soil_Sand"
    },
    {
      "x": -8,
      "y": 26,
      "z": -3,
      "name": "Soil_Sand"
    },
    {
      "x": -8,
      "y": 27,
      "z": -3,
      "name": "Soil_Sand"
    },
    {
      "x": -8,
      "y": 28,
      "z": -3,
      "name": "Soil_Sand"
    },
    {
      "x": -8,
      "y": 29,
      "z": -3,
      "name": "Soil_Sand"
    },
    {
      "x": -8,
      "y": 30,
      "z": -3,
      "name": "Soil_Sand"
    },
    {
      "x": -8,
      "y": 31,
      "z": -3,
      "name": "Soil_Sand"
    },
    {
      "x": -8,
      "y": 32,
      "z": -3,
      "name": "Plant_Flower_Bushy_Yellow"
    },
    {
      "x": -8,
      "y": 35,
      "z": -3,
      "name": "Plant_Moss_Block_Yellow"
    },
    {
      "x": -8,
      "y": 36,
      "z": -3,
      "name": "Soil_Sand"
    },
    {
      "x": -8,
      "y": 37,
      "z": -3,
      "name": "Soil_Sand"
    },
    {
      "x": -8,
      "y": 38,
      "z": -3,
      "name": "Soil_Sand"
    },
    {
      "x": -8,
      "y": 39,
      "z": -3,
      "name": "Plant_Leaves_Palm_Arid"
    },
    {
      "x": -8,
      "y": 0,
      "z": -2,
      "name": "Soil_Sand"
    },
    {
      "x": -8,
      "y": 1,
      "z": -2,
      "name": "Soil_Sand"
    },
    {
      "x": -8,
      "y": 2,
      "z": -2,
      "name": "Soil_Sand"
    },
    {
      "x": -8,
      "y": 3,
      "z": -2,
      "name": "Soil_Sand"
    },
    {
      "x": -8,
      "y": 4,
      "z": -2,
      "name": "Soil_Sand"
    },
    {
      "x": -8,
      "y": 5,
      "z": -2,
      "name": "Soil_Sand"
    },
    {
      "x": -8,
      "y": 6,
      "z": -2,
      "name": "Soil_Sand"
    },
    {
      "x": -8,
      "y": 7,
      "z": -2,
      "name": "Soil_Sand"
    },
    {
      "x": -8,
      "y": 8,
      "z": -2,
      "name": "Soil_Sand"
    },
    {
      "x": -8,
      "y": 9,
      "z": -2,
      "name": "Soil_Sand"
    },
    {
      "x": -8,
      "y": 10,
      "z": -2,
      "name": "Soil_Sand"
    },
    {
      "x": -8,
      "y": 11,
      "z": -2,
      "name": "Soil_Sand"
    },
    {
      "x": -8,
      "y": 12,
      "z": -2,
      "name": "Soil_Sand"
    },
    {
      "x": -8,
      "y": 13,
      "z": -2,
      "name": "Soil_Sand"
    },
    {
      "x": -8,
      "y": 14,
      "z": -2,
      "name": "Soil_Sand"
    },
    {
      "x": -8,
      "y": 15,
      "z": -2,
      "name": "Soil_Sand"
    },
    {
      "x": -8,
      "y": 16,
      "z": -2,
      "name": "Soil_Sand"
    },
    {
      "x": -8,
      "y": 21,
      "z": -2,
      "name": "Soil_Clay_Lime"
    },
    {
      "x": -8,
      "y": 22,
      "z": -2,
      "name": "Soil_Sand"
    },
    {
      "x": -8,
      "y": 23,
      "z": -2,
      "name": "Soil_Sand"
    },
    {
      "x": -8,
      "y": 24,
      "z": -2,
      "name": "Soil_Sand"
    },
    {
      "x": -8,
      "y": 25,
      "z": -2,
      "name": "Soil_Sand"
    },
    {
      "x": -8,
      "y": 26,
      "z": -2,
      "name": "Soil_Sand"
    },
    {
      "x": -8,
      "y": 27,
      "z": -2,
      "name": "Soil_Sand"
    },
    {
      "x": -8,
      "y": 28,
      "z": -2,
      "name": "Soil_Sand"
    },
    {
      "x": -8,
      "y": 29,
      "z": -2,
      "name": "Soil_Sand"
    },
    {
      "x": -8,
      "y": 30,
      "z": -2,
      "name": "Soil_Sand"
    },
    {
      "x": -8,
      "y": 31,
      "z": -2,
      "name": "Soil_Sand"
    },
    {
      "x": -8,
      "y": 32,
      "z": -2,
      "name": "Plant_Flower_Bushy_Yellow"
    },
    {
      "x": -8,
      "y": 35,
      "z": -2,
      "name": "Plant_Moss_Block_Yellow"
    },
    {
      "x": -8,
      "y": 36,
      "z": -2,
      "name": "Soil_Sand"
    },
    {
      "x": -8,
      "y": 37,
      "z": -2,
      "name": "Soil_Sand"
    },
    {
      "x": -8,
      "y": 38,
      "z": -2,
      "name": "Soil_Sand"
    },
    {
      "x": -8,
      "y": 39,
      "z": -2,
      "name": "Plant_Leaves_Palm_Arid"
    },
    {
      "x": -8,
      "y": 0,
      "z": -1,
      "name": "Soil_Sand"
    },
    {
      "x": -8,
      "y": 1,
      "z": -1,
      "name": "Soil_Sand"
    },
    {
      "x": -8,
      "y": 2,
      "z": -1,
      "name": "Soil_Sand"
    },
    {
      "x": -8,
      "y": 3,
      "z": -1,
      "name": "Soil_Sand"
    },
    {
      "x": -8,
      "y": 4,
      "z": -1,
      "name": "Soil_Sand"
    },
    {
      "x": -8,
      "y": 5,
      "z": -1,
      "name": "Soil_Sand"
    },
    {
      "x": -8,
      "y": 6,
      "z": -1,
      "name": "Soil_Sand"
    },
    {
      "x": -8,
      "y": 7,
      "z": -1,
      "name": "Soil_Sand"
    },
    {
      "x": -8,
      "y": 8,
      "z": -1,
      "name": "Soil_Sand"
    },
    {
      "x": -8,
      "y": 9,
      "z": -1,
      "name": "Soil_Sand"
    },
    {
      "x": -8,
      "y": 10,
      "z": -1,
      "name": "Soil_Sand"
    },
    {
      "x": -8,
      "y": 11,
      "z": -1,
      "name": "Soil_Sand"
    },
    {
      "x": -8,
      "y": 12,
      "z": -1,
      "name": "Soil_Sand"
    },
    {
      "x": -8,
      "y": 13,
      "z": -1,
      "name": "Soil_Sand"
    },
    {
      "x": -8,
      "y": 14,
      "z": -1,
      "name": "Soil_Sand"
    },
    {
      "x": -8,
      "y": 15,
      "z": -1,
      "name": "Soil_Sand"
    },
    {
      "x": -8,
      "y": 16,
      "z": -1,
      "name": "Soil_Sand"
    },
    {
      "x": -8,
      "y": 21,
      "z": -1,
      "name": "Soil_Clay_Lime"
    },
    {
      "x": -8,
      "y": 22,
      "z": -1,
      "name": "Rock_Stone_Mossy"
    },
    {
      "x": -8,
      "y": 23,
      "z": -1,
      "name": "Rock_Stone_Mossy"
    },
    {
      "x": -8,
      "y": 24,
      "z": -1,
      "name": "Rock_Stone_Mossy"
    },
    {
      "x": -8,
      "y": 25,
      "z": -1,
      "name": "Soil_Sand"
    },
    {
      "x": -8,
      "y": 26,
      "z": -1,
      "name": "Soil_Sand"
    },
    {
      "x": -8,
      "y": 27,
      "z": -1,
      "name": "Soil_Sand"
    },
    {
      "x": -8,
      "y": 28,
      "z": -1,
      "name": "Soil_Sand"
    },
    {
      "x": -8,
      "y": 29,
      "z": -1,
      "name": "Soil_Sand"
    },
    {
      "x": -8,
      "y": 30,
      "z": -1,
      "name": "Soil_Sand"
    },
    {
      "x": -8,
      "y": 31,
      "z": -1,
      "name": "Soil_Sand"
    },
    {
      "x": -8,
      "y": 32,
      "z": -1,
      "name": "Plant_Bush_Arid_Sharp"
    },
    {
      "x": -8,
      "y": 35,
      "z": -1,
      "name": "Soil_Clay_Lime"
    },
    {
      "x": -8,
      "y": 36,
      "z": -1,
      "name": "Plant_Moss_Block_Yellow"
    },
    {
      "x": -8,
      "y": 37,
      "z": -1,
      "name": "Plant_Moss_Block_Yellow"
    },
    {
      "x": -8,
      "y": 38,
      "z": -1,
      "name": "Soil_Clay_Lime"
    },
    {
      "x": -8,
      "y": 0,
      "z": 0,
      "name": "Soil_Sand"
    },
    {
      "x": -8,
      "y": 1,
      "z": 0,
      "name": "Soil_Sand"
    },
    {
      "x": -8,
      "y": 2,
      "z": 0,
      "name": "Soil_Sand"
    },
    {
      "x": -8,
      "y": 3,
      "z": 0,
      "name": "Soil_Sand"
    },
    {
      "x": -8,
      "y": 4,
      "z": 0,
      "name": "Soil_Sand"
    },
    {
      "x": -8,
      "y": 5,
      "z": 0,
      "name": "Soil_Sand"
    },
    {
      "x": -8,
      "y": 6,
      "z": 0,
      "name": "Soil_Sand"
    },
    {
      "x": -8,
      "y": 7,
      "z": 0,
      "name": "Soil_Sand"
    },
    {
      "x": -8,
      "y": 8,
      "z": 0,
      "name": "Soil_Sand"
    },
    {
      "x": -8,
      "y": 9,
      "z": 0,
      "name": "Soil_Sand"
    },
    {
      "x": -8,
      "y": 10,
      "z": 0,
      "name": "Soil_Sand"
    },
    {
      "x": -8,
      "y": 11,
      "z": 0,
      "name": "Soil_Sand"
    },
    {
      "x": -8,
      "y": 12,
      "z": 0,
      "name": "Soil_Sand"
    },
    {
      "x": -8,
      "y": 13,
      "z": 0,
      "name": "Soil_Sand"
    },
    {
      "x": -8,
      "y": 14,
      "z": 0,
      "name": "Soil_Sand"
    },
    {
      "x": -8,
      "y": 15,
      "z": 0,
      "name": "Soil_Sand"
    },
    {
      "x": -8,
      "y": 16,
      "z": 0,
      "name": "Soil_Sand"
    },
    {
      "x": -8,
      "y": 23,
      "z": 0,
      "name": "Rock_Stone_Mossy"
    },
    {
      "x": -8,
      "y": 24,
      "z": 0,
      "name": "Rock_Stone_Mossy"
    },
    {
      "x": -8,
      "y": 25,
      "z": 0,
      "name": "Rock_Stone_Mossy"
    },
    {
      "x": -8,
      "y": 26,
      "z": 0,
      "name": "Rock_Stone_Mossy"
    },
    {
      "x": -8,
      "y": 27,
      "z": 0,
      "name": "Rock_Stone_Mossy"
    },
    {
      "x": -8,
      "y": 28,
      "z": 0,
      "name": "Soil_Clay_Lime"
    },
    {
      "x": -8,
      "y": 29,
      "z": 0,
      "name": "Soil_Clay_Lime"
    },
    {
      "x": -8,
      "y": 30,
      "z": 0,
      "name": "Soil_Sand"
    },
    {
      "x": -8,
      "y": 31,
      "z": 0,
      "name": "Soil_Sand"
    },
    {
      "x": -8,
      "y": 32,
      "z": 0,
      "name": "Plant_Bush_Arid_Sharp"
    },
    {
      "x": -8,
      "y": 0,
      "z": 1,
      "name": "Soil_Sand"
    },
    {
      "x": -8,
      "y": 1,
      "z": 1,
      "name": "Soil_Sand"
    },
    {
      "x": -8,
      "y": 2,
      "z": 1,
      "name": "Soil_Sand"
    },
    {
      "x": -8,
      "y": 3,
      "z": 1,
      "name": "Soil_Sand"
    },
    {
      "x": -8,
      "y": 4,
      "z": 1,
      "name": "Soil_Sand"
    },
    {
      "x": -8,
      "y": 5,
      "z": 1,
      "name": "Soil_Sand"
    },
    {
      "x": -8,
      "y": 6,
      "z": 1,
      "name": "Soil_Sand"
    },
    {
      "x": -8,
      "y": 7,
      "z": 1,
      "name": "Soil_Sand"
    },
    {
      "x": -8,
      "y": 8,
      "z": 1,
      "name": "Soil_Sand"
    },
    {
      "x": -8,
      "y": 9,
      "z": 1,
      "name": "Soil_Sand"
    },
    {
      "x": -8,
      "y": 10,
      "z": 1,
      "name": "Soil_Sand"
    },
    {
      "x": -8,
      "y": 11,
      "z": 1,
      "name": "Soil_Sand"
    },
    {
      "x": -8,
      "y": 12,
      "z": 1,
      "name": "Soil_Sand"
    },
    {
      "x": -8,
      "y": 13,
      "z": 1,
      "name": "Soil_Sand"
    },
    {
      "x": -8,
      "y": 14,
      "z": 1,
      "name": "Soil_Sand"
    },
    {
      "x": -8,
      "y": 15,
      "z": 1,
      "name": "Soil_Sand"
    },
    {
      "x": -8,
      "y": 16,
      "z": 1,
      "name": "Soil_Sand"
    },
    {
      "x": -8,
      "y": 23,
      "z": 1,
      "name": "Rock_Stone_Mossy"
    },
    {
      "x": -8,
      "y": 24,
      "z": 1,
      "name": "Rock_Stone_Mossy"
    },
    {
      "x": -8,
      "y": 25,
      "z": 1,
      "name": "Rock_Stone_Mossy"
    },
    {
      "x": -8,
      "y": 26,
      "z": 1,
      "name": "Rock_Stone_Mossy"
    },
    {
      "x": -8,
      "y": 27,
      "z": 1,
      "name": "Rock_Stone_Mossy"
    },
    {
      "x": -8,
      "y": 28,
      "z": 1,
      "name": "Soil_Clay_Lime"
    },
    {
      "x": -8,
      "y": 29,
      "z": 1,
      "name": "Soil_Clay_Lime"
    },
    {
      "x": -8,
      "y": 0,
      "z": 2,
      "name": "Soil_Sand"
    },
    {
      "x": -8,
      "y": 1,
      "z": 2,
      "name": "Soil_Sand"
    },
    {
      "x": -8,
      "y": 2,
      "z": 2,
      "name": "Soil_Sand"
    },
    {
      "x": -8,
      "y": 3,
      "z": 2,
      "name": "Soil_Sand"
    },
    {
      "x": -8,
      "y": 4,
      "z": 2,
      "name": "Soil_Sand"
    },
    {
      "x": -8,
      "y": 5,
      "z": 2,
      "name": "Soil_Sand"
    },
    {
      "x": -8,
      "y": 6,
      "z": 2,
      "name": "Soil_Sand"
    },
    {
      "x": -8,
      "y": 7,
      "z": 2,
      "name": "Soil_Sand"
    },
    {
      "x": -8,
      "y": 8,
      "z": 2,
      "name": "Soil_Sand"
    },
    {
      "x": -8,
      "y": 9,
      "z": 2,
      "name": "Soil_Sand"
    },
    {
      "x": -8,
      "y": 10,
      "z": 2,
      "name": "Soil_Sand"
    },
    {
      "x": -8,
      "y": 11,
      "z": 2,
      "name": "Soil_Sand"
    },
    {
      "x": -8,
      "y": 12,
      "z": 2,
      "name": "Soil_Sand"
    },
    {
      "x": -8,
      "y": 13,
      "z": 2,
      "name": "Soil_Sand"
    },
    {
      "x": -8,
      "y": 14,
      "z": 2,
      "name": "Soil_Sand"
    },
    {
      "x": -8,
      "y": 15,
      "z": 2,
      "name": "Soil_Sand"
    },
    {
      "x": -8,
      "y": 16,
      "z": 2,
      "name": "Soil_Sand"
    },
    {
      "x": -8,
      "y": 26,
      "z": 2,
      "name": "Soil_Clay_Lime"
    },
    {
      "x": -8,
      "y": 27,
      "z": 2,
      "name": "Soil_Clay_Lime"
    },
    {
      "x": -8,
      "y": 28,
      "z": 2,
      "name": "Soil_Clay_Lime"
    },
    {
      "x": -8,
      "y": 0,
      "z": 3,
      "name": "Soil_Sand"
    },
    {
      "x": -8,
      "y": 1,
      "z": 3,
      "name": "Soil_Sand"
    },
    {
      "x": -8,
      "y": 2,
      "z": 3,
      "name": "Soil_Sand"
    },
    {
      "x": -8,
      "y": 3,
      "z": 3,
      "name": "Soil_Sand"
    },
    {
      "x": -8,
      "y": 4,
      "z": 3,
      "name": "Soil_Sand"
    },
    {
      "x": -8,
      "y": 5,
      "z": 3,
      "name": "Soil_Sand"
    },
    {
      "x": -8,
      "y": 6,
      "z": 3,
      "name": "Soil_Sand"
    },
    {
      "x": -8,
      "y": 7,
      "z": 3,
      "name": "Soil_Sand"
    },
    {
      "x": -8,
      "y": 8,
      "z": 3,
      "name": "Soil_Sand"
    },
    {
      "x": -8,
      "y": 9,
      "z": 3,
      "name": "Soil_Sand"
    },
    {
      "x": -8,
      "y": 10,
      "z": 3,
      "name": "Soil_Sand"
    },
    {
      "x": -8,
      "y": 11,
      "z": 3,
      "name": "Soil_Sand"
    },
    {
      "x": -8,
      "y": 12,
      "z": 3,
      "name": "Soil_Sand"
    },
    {
      "x": -8,
      "y": 13,
      "z": 3,
      "name": "Soil_Sand"
    },
    {
      "x": -8,
      "y": 14,
      "z": 3,
      "name": "Soil_Sand"
    },
    {
      "x": -8,
      "y": 15,
      "z": 3,
      "name": "Soil_Sand"
    },
    {
      "x": -8,
      "y": 0,
      "z": 4,
      "name": "Soil_Sand"
    },
    {
      "x": -8,
      "y": 1,
      "z": 4,
      "name": "Soil_Sand"
    },
    {
      "x": -8,
      "y": 2,
      "z": 4,
      "name": "Soil_Sand"
    },
    {
      "x": -8,
      "y": 3,
      "z": 4,
      "name": "Soil_Sand"
    },
    {
      "x": -8,
      "y": 4,
      "z": 4,
      "name": "Soil_Sand"
    },
    {
      "x": -8,
      "y": 5,
      "z": 4,
      "name": "Soil_Sand"
    },
    {
      "x": -8,
      "y": 6,
      "z": 4,
      "name": "Soil_Sand"
    },
    {
      "x": -8,
      "y": 7,
      "z": 4,
      "name": "Soil_Sand"
    },
    {
      "x": -8,
      "y": 8,
      "z": 4,
      "name": "Soil_Sand"
    },
    {
      "x": -8,
      "y": 9,
      "z": 4,
      "name": "Soil_Sand"
    },
    {
      "x": -8,
      "y": 10,
