{
  "version": 8,
  "blockIdVersion": 10,
  "anchorX": 0,
  "anchorY": 4,
  "anchorZ": 0,
  "blocks": [
    {
      "x": -14,
      "y": 15,
      "z": -1,
      "name": "Soil_Clay_Lime"
    },
    {
      "x": -14,
      "y": 16,
      "z": -1,
      "name": "Plant_Grass_Sharp"
    },
    {
      "x": -13,
      "y": 14,
      "z": -1,
      "name": "Soil_Seaweed_Block"
    },
    {
      "x": -13,
      "y": 15,
      "z": -1,
      "name": "Soil_Clay_Lime"
    },
    {
      "x": -13,
      "y": 16,
      "z": -1,
      "name": "Plant_Grass_Sharp"
    },
    {
      "x": -13,
      "y": 14,
      "z": 0,
      "name": "Soil_Seaweed_Block"
    },
    {
      "x": -12,
      "y": 13,
      "z": -1,
      "name": "Soil_Seaweed_Block"
    },
    {
      "x": -12,
      "y": 14,
      "z": -1,
      "name": "Soil_Clay_Lime"
    },
    {
      "x": -12,
      "y": 15,
      "z": -1,
      "name": "Plant_Grass_Sharp"
    },
    {
      "x": -12,
      "y": 13,
      "z": 0,
      "name": "Soil_Seaweed_Block"
    },
    {
      "x": -12,
      "y": 14,
      "z": 0,
      "name": "Soil_Clay_Lime"
    },
    {
      "x": -12,
      "y": 15,
      "z": 0,
      "name": "Plant_Grass_Sharp"
    },
    {
      "x": -11,
      "y": 12,
      "z": -1,
      "name": "Soil_Clay_Green"
    },
    {
      "x": -11,
      "y": 13,
      "z": -1,
      "name": "Soil_Seaweed_Block"
    },
    {
      "x": -11,
      "y": 14,
      "z": -1,
      "name": "Soil_Clay_Lime"
    },
    {
      "x": -11,
      "y": 15,
      "z": -1,
      "name": "Plant_Grass_Sharp"
    },
    {
      "x": -11,
      "y": 12,
      "z": 0,
      "name": "Soil_Clay_Green"
    },
    {
      "x": -11,
      "y": 13,
      "z": 0,
      "name": "Soil_Seaweed_Block"
    },
    {
      "x": -11,
      "y": 11,
      "z": 2,
      "name": "Soil_Clay_Green"
    },
    {
      "x": -11,
      "y": 12,
      "z": 2,
      "name": "Soil_Seaweed_Block"
    },
    {
      "x": -10,
      "y": 11,
      "z": -2,
      "name": "Soil_Clay_Green"
    },
    {
      "x": -10,
      "y": 12,
      "z": -2,
      "name": "Soil_Clay_Green"
    },
    {
      "x": -10,
      "y": 13,
      "z": -2,
      "name": "Soil_Seaweed_Block"
    },
    {
      "x": -10,
      "y": 11,
      "z": -1,
      "name": "Soil_Clay_Green"
    },
    {
      "x": -10,
      "y": 12,
      "z": -1,
      "name": "Soil_Clay_Green"
    },
    {
      "x": -10,
      "y": 13,
      "z": -1,
      "name": "Soil_Seaweed_Block"
    },
    {
      "x": -10,
      "y": 15,
      "z": -1,
      "name": "Plant_Grass_Sharp"
    },
    {
      "x": -10,
      "y": 10,
      "z": 0,
      "name": "Soil_Clay_Green"
    },
    {
      "x": -10,
      "y": 11,
      "z": 0,
      "name": "Soil_Seaweed_Block"
    },
    {
      "x": -10,
      "y": 12,
      "z": 0,
      "name": "Soil_Seaweed_Block"
    },
    {
      "x": -10,
      "y": 13,
      "z": 0,
      "name": "Soil_Seaweed_Block"
    },
    {
      "x": -10,
      "y": 14,
      "z": 0,
      "name": "Soil_Clay_Lime"
    },
    {
      "x": -10,
      "y": 15,
      "z": 0,
      "name": "Plant_Grass_Sharp"
    },
    {
      "x": -10,
      "y": 10,
      "z": 1,
      "name": "Soil_Clay_Green"
    },
    {
      "x": -10,
      "y": 11,
      "z": 1,
      "name": "Soil_Seaweed_Block"
    },
    {
      "x": -10,
      "y": 12,
      "z": 1,
      "name": "Soil_Seaweed_Block"
    },
    {
      "x": -10,
      "y": 13,
      "z": 1,
      "name": "Soil_Clay_Lime"
    },
    {
      "x": -10,
      "y": 14,
      "z": 1,
      "name": "Soil_Clay_Lime"
    },
    {
      "x": -10,
      "y": 15,
      "z": 1,
      "name": "Plant_Grass_Sharp"
    },
    {
      "x": -10,
      "y": 11,
      "z": 2,
      "name": "Soil_Clay_Green"
    },
    {
      "x": -10,
      "y": 12,
      "z": 2,
      "name": "Soil_Seaweed_Block"
    },
    {
      "x": -10,
      "y": 11,
      "z": 3,
      "name": "Soil_Clay_Green"
    },
    {
      "x": -10,
      "y": 12,
      "z": 3,
      "name": "Soil_Seaweed_Block"
    },
    {
      "x": -9,
      "y": 11,
      "z": -2,
      "name": "Soil_Clay_Green"
    },
    {
      "x": -9,
      "y": 12,
      "z": -2,
      "name": "Soil_Seaweed_Block"
    },
    {
      "x": -9,
      "y": 13,
      "z": -2,
      "name": "Soil_Clay_Lime"
    },
    {
      "x": -9,
      "y": 14,
      "z": -2,
      "name": "Plant_Grass_Sharp"
    },
    {
      "x": -9,
      "y": 10,
      "z": -1,
      "name": "Soil_Clay_Green"
    },
    {
      "x": -9,
      "y": 11,
      "z": -1,
      "name": "Soil_Seaweed_Block"
    },
    {
      "x": -9,
      "y": 12,
      "z": -1,
      "name": "Soil_Seaweed_Block"
    },
    {
      "x": -9,
      "y": 13,
      "z": -1,
      "name": "Soil_Seaweed_Block"
    },
    {
      "x": -9,
      "y": 14,
      "z": -1,
      "name": "Soil_Clay_Lime"
    },
    {
      "x": -9,
      "y": 15,
      "z": -1,
      "name": "Plant_Grass_Sharp"
    },
    {
      "x": -9,
      "y": 10,
      "z": 0,
      "name": "Soil_Clay_Green"
    },
    {
      "x": -9,
      "y": 11,
      "z": 0,
      "name": "Soil_Seaweed_Block"
    },
    {
      "x": -9,
      "y": 12,
      "z": 0,
      "name": "Soil_Seaweed_Block"
    },
    {
      "x": -9,
      "y": 13,
      "z": 0,
      "name": "Soil_Seaweed_Block"
    },
    {
      "x": -9,
      "y": 14,
      "z": 0,
      "name": "Soil_Clay_Lime"
    },
    {
      "x": -9,
      "y": 15,
      "z": 0,
      "name": "Soil_Clay_Lime"
    },
    {
      "x": -9,
      "y": 16,
      "z": 0,
      "name": "Soil_Seaweed_Block"
    },
    {
      "x": -9,
      "y": 8,
      "z": 1,
      "name": "Soil_Clay_Green"
    },
    {
      "x": -9,
      "y": 9,
      "z": 1,
      "name": "Soil_Clay_Green"
    },
    {
      "x": -9,
      "y": 10,
      "z": 1,
      "name": "Soil_Seaweed_Block"
    },
    {
      "x": -9,
      "y": 11,
      "z": 1,
      "name": "Soil_Seaweed_Block"
    },
    {
      "x": -9,
      "y": 12,
      "z": 1,
      "name": "Soil_Seaweed_Block"
    },
    {
      "x": -9,
      "y": 13,
      "z": 1,
      "name": "Soil_Clay_Lime"
    },
    {
      "x": -9,
      "y": 14,
      "z": 1,
      "name": "Soil_Clay_Lime"
    },
    {
      "x": -9,
      "y": 15,
      "z": 1,
      "name": "Soil_Seaweed_Block"
    },
    {
      "x": -9,
      "y": 16,
      "z": 1,
      "name": "Soil_Clay_Green"
    },
    {
      "x": -9,
      "y": 7,
      "z": 2,
      "name": "Soil_Clay_Green"
    },
    {
      "x": -9,
      "y": 8,
      "z": 2,
      "name": "Soil_Clay_Green"
    },
    {
      "x": -9,
      "y": 9,
      "z": 2,
      "name": "Soil_Clay_Green"
    },
    {
      "x": -9,
      "y": 10,
      "z": 2,
      "name": "Soil_Clay_Green"
    },
    {
      "x": -9,
      "y": 11,
      "z": 2,
      "name": "Soil_Seaweed_Block"
    },
    {
      "x": -9,
      "y": 12,
      "z": 2,
      "name": "Soil_Seaweed_Block"
    },
    {
      "x": -9,
      "y": 13,
      "z": 2,
      "name": "Soil_Clay_Lime"
    },
    {
      "x": -9,
      "y": 14,
      "z": 2,
      "name": "Soil_Seaweed_Block"
    },
    {
      "x": -9,
      "y": 7,
      "z": 3,
      "name": "Soil_Clay_Green"
    },
    {
      "x": -9,
      "y": 8,
      "z": 3,
      "name": "Soil_Clay_Green"
    },
    {
      "x": -9,
      "y": 11,
      "z": 3,
      "name": "Soil_Seaweed_Block"
    },
    {
      "x": -9,
      "y": 12,
      "z": 3,
      "name": "Soil_Seaweed_Block"
    },
    {
      "x": -9,
      "y": 10,
      "z": 4,
      "name": "Soil_Clay_Green"
    },
    {
      "x": -9,
      "y": 11,
      "z": 4,
      "name": "Soil_Clay_Green"
    },
    {
      "x": -9,
      "y": 12,
      "z": 4,
      "name": "Soil_Seaweed_Block"
    },
    {
      "x": -9,
      "y": 12,
      "z": 5,
      "name": "Soil_Seaweed_Block"
    },
    {
      "x": -9,
      "y": 12,
      "z": 6,
      "name": "Soil_Seaweed_Block"
    },
    {
      "x": -9,
      "y": 12,
      "z": 7,
      "name": "Soil_Seaweed_Block"
    },
    {
      "x": -8,
      "y": 11,
      "z": -5,
      "name": "Soil_Clay_Green"
    },
    {
      "x": -8,
      "y": 11,
      "z": -4,
      "name": "Soil_Clay_Green"
    },
    {
      "x": -8,
      "y": 12,
      "z": -4,
      "name": "Soil_Seaweed_Block"
    },
    {
      "x": -8,
      "y": 11,
      "z": -3,
      "name": "Soil_Clay_Green"
    },
    {
      "x": -8,
      "y": 12,
      "z": -3,
      "name": "Soil_Seaweed_Block"
    },
    {
      "x": -8,
      "y": 11,
      "z": -2,
      "name": "Soil_Clay_Green"
    },
    {
      "x": -8,
      "y": 12,
      "z": -2,
      "name": "Soil_Seaweed_Block"
    },
    {
      "x": -8,
      "y": 13,
      "z": -2,
      "name": "Soil_Clay_Lime"
    },
    {
      "x": -8,
      "y": 14,
      "z": -2,
      "name": "Plant_Grass_Sharp"
    },
    {
      "x": -8,
      "y": 10,
      "z": -1,
      "name": "Soil_Clay_Green"
    },
    {
      "x": -8,
      "y": 11,
      "z": -1,
      "name": "Soil_Seaweed_Block"
    },
    {
      "x": -8,
      "y": 12,
      "z": -1,
      "name": "Soil_Seaweed_Block"
    },
    {
      "x": -8,
      "y": 13,
      "z": -1,
      "name": "Soil_Seaweed_Block"
    },
    {
      "x": -8,
      "y": 14,
      "z": -1,
      "name": "Soil_Clay_Lime"
    },
    {
      "x": -8,
      "y": 17,
      "z": -1,
      "name": "Soil_Seaweed_Block"
    },
    {
      "x": -8,
      "y": 10,
      "z": 0,
      "name": "Soil_Clay_Green"
    },
    {
      "x": -8,
      "y": 11,
      "z": 0,
      "name": "Soil_Seaweed_Block"
    },
    {
      "x": -8,
      "y": 12,
      "z": 0,
      "name": "Soil_Seaweed_Block"
    },
    {
      "x": -8,
      "y": 13,
      "z": 0,
      "name": "Soil_Seaweed_Block"
    },
    {
      "x": -8,
      "y": 14,
      "z": 0,
      "name": "Soil_Clay_Lime"
    },
    {
      "x": -8,
      "y": 15,
      "z": 0,
      "name": "Soil_Clay_Lime"
    },
    {
      "x": -8,
      "y": 16,
      "z": 0,
      "name": "Soil_Seaweed_Block"
    },
    {
      "x": -8,
      "y": 17,
      "z": 0,
      "name": "Soil_Seaweed_Block"
    },
    {
      "x": -8,
      "y": 6,
      "z": 1,
      "name": "Soil_Clay_Green"
    },
    {
      "x": -8,
      "y": 7,
      "z": 1,
      "name": "Soil_Clay_Green"
    },
    {
      "x": -8,
      "y": 8,
      "z": 1,
      "name": "Soil_Clay_Green"
    },
    {
      "x": -8,
      "y": 9,
      "z": 1,
      "name": "Soil_Clay_Green"
    },
    {
      "x": -8,
      "y": 10,
      "z": 1,
      "name": "Soil_Clay_Green"
    },
    {
      "x": -8,
      "y": 11,
      "z": 1,
      "name": "Soil_Seaweed_Block"
    },
    {
      "x": -8,
      "y": 12,
      "z": 1,
      "name": "Soil_Seaweed_Block"
    },
    {
      "x": -8,
      "y": 13,
      "z": 1,
      "name": "Soil_Clay_Lime"
    },
    {
      "x": -8,
      "y": 14,
      "z": 1,
      "name": "Soil_Clay_Lime"
    },
    {
      "x": -8,
      "y": 15,
      "z": 1,
      "name": "Soil_Clay_Green"
    },
    {
      "x": -8,
      "y": 16,
      "z": 1,
      "name": "Soil_Seaweed_Block"
    },
    {
      "x": -8,
      "y": 17,
      "z": 1,
      "name": "Soil_Seaweed_Block"
    },
    {
      "x": -8,
      "y": 18,
      "z": 1,
      "name": "Soil_Clay_Lime"
    },
    {
      "x": -8,
      "y": 19,
      "z": 1,
      "name": "Plant_Grass_Sharp"
    },
    {
      "x": -8,
      "y": 7,
      "z": 2,
      "name": "Soil_Clay_Green"
    },
    {
      "x": -8,
      "y": 8,
      "z": 2,
      "name": "Soil_Clay_Green"
    },
    {
      "x": -8,
      "y": 9,
      "z": 2,
      "name": "Soil_Clay_Green"
    },
    {
      "x": -8,
      "y": 10,
      "z": 2,
      "name": "Soil_Seaweed_Block"
    },
    {
      "x": -8,
      "y": 11,
      "z": 2,
      "name": "Soil_Seaweed_Block"
    },
    {
      "x": -8,
      "y": 12,
      "z": 2,
      "name": "Soil_Clay_Lime"
    },
    {
      "x": -8,
      "y": 13,
      "z": 2,
      "name": "Plant_Grass_Sharp"
    },
    {
      "x": -8,
      "y": 16,
      "z": 2,
      "name": "Soil_Clay_Green"
    },
    {
      "x": -8,
      "y": 17,
      "z": 2,
      "name": "Soil_Clay_Green"
    },
    {
      "x": -8,
      "y": 7,
      "z": 3,
      "name": "Soil_Clay_Green"
    },
    {
      "x": -8,
      "y": 8,
      "z": 3,
      "name": "Soil_Clay_Green"
    },
    {
      "x": -8,
      "y": 9,
      "z": 3,
      "name": "Soil_Clay_Green"
    },
    {
      "x": -8,
      "y": 10,
      "z": 3,
      "name": "Soil_Seaweed_Block"
    },
    {
      "x": -8,
      "y": 11,
      "z": 3,
      "name": "Soil_Seaweed_Block"
    },
    {
      "x": -8,
      "y": 12,
      "z": 3,
      "name": "Soil_Clay_Lime"
    },
    {
      "x": -8,
      "y": 13,
      "z": 3,
      "name": "Plant_Grass_Sharp"
    },
    {
      "x": -8,
      "y": 10,
      "z": 4,
      "name": "Soil_Clay_Green"
    },
    {
      "x": -8,
      "y": 11,
      "z": 4,
      "name": "Soil_Clay_Green"
    },
    {
      "x": -8,
      "y": 12,
      "z": 4,
      "name": "Soil_Clay_Lime"
    },
    {
      "x": -8,
      "y": 13,
      "z": 4,
      "name": "Plant_Grass_Sharp"
    },
    {
      "x": -8,
      "y": 10,
      "z": 5,
      "name": "Soil_Clay_Green"
    },
    {
      "x": -8,
      "y": 11,
      "z": 5,
      "name": "Soil_Clay_Green"
    },
    {
      "x": -8,
      "y": 12,
      "z": 5,
      "name": "Soil_Seaweed_Block"
    },
    {
      "x": -8,
      "y": 13,
      "z": 5,
      "name": "Soil_Clay_Lime"
    },
    {
      "x": -8,
      "y": 14,
      "z": 5,
      "name": "Plant_Grass_Sharp"
    },
    {
      "x": -8,
      "y": 15,
      "z": 5,
      "name": "Plant_Grass_Sharp"
    },
    {
      "x": -8,
      "y": 11,
      "z": 6,
      "name": "Soil_Clay_Green"
    },
    {
      "x": -8,
      "y": 12,
      "z": 6,
      "name": "Soil_Seaweed_Block"
    },
    {
      "x": -8,
      "y": 13,
      "z": 6,
      "name": "Soil_Clay_Lime"
    },
    {
      "x": -8,
      "y": 14,
      "z": 6,
      "name": "Soil_Clay_Lime"
    },
    {
      "x": -8,
      "y": 15,
      "z": 6,
      "name": "Plant_Grass_Sharp"
    },
    {
      "x": -8,
      "y": 10,
      "z": 7,
      "name": "Soil_Clay_Green"
    },
    {
      "x": -8,
      "y": 11,
      "z": 7,
      "name": "Soil_Seaweed_Block"
    },
    {
      "x": -8,
      "y": 12,
      "z": 7,
      "name": "Soil_Seaweed_Block"
    },
    {
      "x": -8,
      "y": 13,
      "z": 7,
      "name": "Soil_Seaweed_Block"
    },
    {
      "x": -8,
      "y": 14,
      "z": 7,
      "name": "Soil_Clay_Lime"
    },
    {
      "x": -8,
      "y": 15,
      "z": 7,
      "name": "Plant_Grass_Sharp"
    },
    {
      "x": -8,
      "y": 11,
      "z": 8,
      "name": "Soil_Clay_Green"
    },
    {
      "x": -8,
      "y": 12,
      "z": 8,
      "name": "Soil_Seaweed_Block"
    },
    {
      "x": -8,
      "y": 13,
      "z": 8,
      "name": "Soil_Seaweed_Block"
    },
    {
      "x": -7,
      "y": 11,
      "z": -8,
      "name": "Soil_Clay_Green"
    },
    {
      "x": -7,
      "y": 12,
      "z": -8,
      "name": "Soil_Seaweed_Block"
    },
    {
      "x": -7,
      "y": 11,
      "z": -7,
      "name": "Soil_Clay_Green"
    },
    {
      "x": -7,
      "y": 12,
      "z": -7,
      "name": "Soil_Seaweed_Block"
    },
    {
      "x": -7,
      "y": 11,
      "z": -6,
      "name": "Soil_Clay_Green"
    },
    {
      "x": -7,
      "y": 12,
      "z": -6,
      "name": "Soil_Seaweed_Block"
    },
    {
      "x": -7,
      "y": 11,
      "z": -5,
      "name": "Soil_Clay_Green"
    },
    {
      "x": -7,
      "y": 12,
      "z": -5,
      "name": "Soil_Clay_Lime"
    },
    {
      "x": -7,
      "y": 13,
      "z": -5,
      "name": "Plant_Grass_Sharp"
    },
    {
      "x": -7,
      "y": 11,
      "z": -4,
      "name": "Soil_Clay_Green"
    },
    {
      "x": -7,
      "y": 12,
      "z": -4,
      "name": "Soil_Clay_Lime"
    },
    {
      "x": -7,
      "y": 13,
      "z": -4,
      "name": "Plant_Grass_Sharp"
    },
    {
      "x": -7,
      "y": 11,
      "z": -3,
      "name": "Soil_Clay_Green"
    },
    {
      "x": -7,
      "y": 12,
      "z": -3,
      "name": "Soil_Seaweed_Block"
    },
    {
      "x": -7,
      "y": 13,
      "z": -3,
      "name": "Plant_Grass_Sharp"
    },
    {
      "x": -7,
      "y": 14,
      "z": -3,
      "name": "Plant_Grass_Sharp"
    },
    {
      "x": -7,
      "y": 11,
      "z": -2,
      "name": "Soil_Clay_Green"
    },
    {
      "x": -7,
      "y": 12,
      "z": -2,
      "name": "Soil_Seaweed_Block"
    },
    {
      "x": -7,
      "y": 13,
      "z": -2,
      "name": "Soil_Clay_Lime"
    },
    {
      "x": -7,
      "y": 14,
      "z": -2,
      "name": "Plant_Grass_Sharp"
    },
    {
      "x": -7,
      "y": 4,
      "z": -1,
      "name": "Soil_Clay_Green"
    },
    {
      "x": -7,
      "y": 5,
      "z": -1,
      "name": "Soil_Seaweed_Block"
    },
    {
      "x": -7,
      "y": 11,
      "z": -1,
      "name": "Soil_Clay_Green"
    },
    {
      "x": -7,
      "y": 12,
      "z": -1,
      "name": "Soil_Seaweed_Block"
    },
    {
      "x": -7,
      "y": 13,
      "z": -1,
      "name": "Soil_Clay_Lime"
    },
    {
      "x": -7,
      "y": 14,
      "z": -1,
      "name": "Plant_Grass_Sharp"
    },
    {
      "x": -7,
      "y": 17,
      "z": -1,
      "name": "Soil_Seaweed_Block"
    },
    {
      "x": -7,
      "y": 5,
      "z": 0,
      "name": "Soil_Clay_Green"
    },
    {
      "x": -7,
      "y": 6,
      "z": 0,
      "name": "Soil_Seaweed_Block"
    },
    {
      "x": -7,
      "y": 7,
      "z": 0,
      "name": "Soil_Clay_Green"
    },
    {
      "x": -7,
      "y": 11,
      "z": 0,
      "name": "Soil_Clay_Green"
    },
    {
      "x": -7,
      "y": 12,
      "z": 0,
      "name": "Soil_Seaweed_Block"
    },
    {
      "x": -7,
      "y": 16,
      "z": 0,
      "name": "Soil_Clay_Green"
    },
    {
      "x": -7,
      "y": 17,
      "z": 0,
      "name": "Soil_Seaweed_Block"
    },
    {
      "x": -7,
      "y": 18,
      "z": 0,
      "name": "Soil_Seaweed_Block"
    },
    {
      "x": -7,
      "y": 7,
      "z": 1,
      "name": "Soil_Clay_Green"
    },
    {
      "x": -7,
      "y": 8,
      "z": 1,
      "name": "Soil_Clay_Green"
    },
    {
      "x": -7,
      "y": 10,
      "z": 1,
      "name": "Soil_Clay_Green"
    },
    {
      "x": -7,
      "y": 11,
      "z": 1,
      "name": "Soil_Clay_Green"
    },
    {
      "x": -7,
      "y": 12,
      "z": 1,
      "name": "Soil_Seaweed_Block"
    },
    {
      "x": -7,
      "y": 16,
      "z": 1,
      "name": "Soil_Clay_Green"
    },
    {
      "x": -7,
      "y": 17,
      "z": 1,
      "name": "Soil_Seaweed_Block"
    },
    {
      "x": -7,
      "y": 18,
      "z": 1,
      "name": "Soil_Clay_Lime"
    },
    {
      "x": -7,
      "y": 19,
      "z": 1,
      "name": "Plant_Grass_Sharp"
    },
    {
      "x": -7,
      "y": 10,
      "z": 2,
      "name": "Soil_Clay_Green"
    },
    {
      "x": -7,
      "y": 11,
      "z": 2,
      "name": "Soil_Clay_Green"
    },
    {
      "x": -7,
      "y": 17,
      "z": 2,
      "name": "Soil_Clay_Green"
    },
    {
      "x": -7,
      "y": 18,
      "z": 2,
      "name": "Soil_Clay_Lime"
    },
    {
      "x": -7,
      "y": 19,
      "z": 2,
      "name": "Plant_Grass_Sharp"
    },
    {
      "x": -7,
      "y": 20,
      "z": 2,
      "name": "Plant_Grass_Sharp"
    },
    {
      "x": -7,
      "y": 9,
      "z": 3,
      "name": "Soil_Clay_Green"
    },
    {
      "x": -7,
      "y": 10,
      "z": 3,
      "name": "Soil_Clay_Green"
    },
    {
      "x": -7,
      "y": 11,
      "z": 3,
      "name": "Soil_Clay_Green"
    },
    {
      "x": -7,
      "y": 17,
      "z": 3,
      "name": "Soil_Clay_Green"
    },
    {
      "x": -7,
      "y": 18,
      "z": 3,
      "name": "Soil_Clay_Lime"
    },
    {
      "x": -7,
      "y": 19,
      "z": 3,
      "name": "Plant_Grass_Sharp"
    },
    {
      "x": -7,
      "y": 10,
      "z": 4,
      "name": "Soil_Clay_Green"
    },
    {
      "x": -7,
      "y": 11,
      "z": 4,
      "name": "Soil_Clay_Green"
    },
    {
      "x": -7,
      "y": 12,
      "z": 4,
      "name": "Soil_Clay_Lime"
    },
    {
      "x": -7,
      "y": 13,
      "z": 4,
      "name": "Plant_Grass_Sharp"
    },
    {
      "x": -7,
      "y": 10,
      "z": 5,
      "name": "Soil_Clay_Green"
    },
    {
      "x": -7,
      "y": 11,
      "z": 5,
      "name": "Soil_Clay_Green"
    },
    {
      "x": -7,
      "y": 12,
      "z": 5,
      "name": "Soil_Seaweed_Block"
    },
    {
      "x": -7,
      "y": 13,
      "z": 5,
      "name": "Soil_Clay_Lime"
    },
    {
      "x": -7,
      "y": 14,
      "z": 5,
      "name": "Soil_Clay_Lime"
    },
    {
      "x": -7,
      "y": 15,
      "z": 5,
      "name": "Plant_Grass_Sharp"
    },
    {
      "x": -7,
      "y": 16,
      "z": 5,
      "name": "Soil_Clay_Green"
    },
    {
      "x": -7,
      "y": 17,
      "z": 5,
      "name": "Soil_Clay_Green"
    },
    {
      "x": -7,
      "y": 9,
      "z": 6,
      "name": "Soil_Clay_Green"
    },
    {
      "x": -7,
      "y": 10,
      "z": 6,
      "name": "Soil_Clay_Green"
    },
    {
      "x": -7,
      "y": 11,
      "z": 6,
      "name": "Soil_Seaweed_Block"
    },
    {
      "x": -7,
      "y": 12,
      "z": 6,
      "name": "Soil_Seaweed_Block"
    },
    {
      "x": -7,
      "y": 13,
      "z": 6,
      "name": "Soil_Seaweed_Block"
    },
    {
      "x": -7,
      "y": 14,
      "z": 6,
      "name": "Soil_Clay_Lime"
    },
    {
      "x": -7,
      "y": 15,
      "z": 6,
      "name": "Soil_Clay_Lime"
    },
    {
      "x": -7,
      "y": 9,
      "z": 7,
      "name": "Soil_Clay_Green"
    },
    {
      "x": -7,
      "y": 10,
      "z": 7,
      "name": "Soil_Seaweed_Block"
    },
    {
      "x": -7,
      "y": 11,
      "z": 7,
      "name": "Soil_Seaweed_Block"
    },
    {
      "x": -7,
      "y": 12,
      "z": 7,
      "name": "Soil_Seaweed_Block"
    },
    {
      "x": -7,
      "y": 13,
      "z": 7,
      "name": "Soil_Seaweed_Block"
    },
    {
      "x": -7,
      "y": 14,
      "z": 7,
      "name": "Soil_Clay_Lime"
    },
    {
      "x": -7,
      "y": 15,
      "z": 7,
      "name": "Plant_Grass_Sharp"
    },
    {
      "x": -7,
      "y": 9,
      "z": 8,
      "name": "Soil_Clay_Green"
    },
    {
      "x": -7,
      "y": 10,
      "z": 8,
      "name": "Soil_Clay_Green"
    },
    {
      "x": -7,
      "y": 11,
      "z": 8,
      "name": "Soil_Clay_Green"
    },
    {
      "x": -7,
      "y": 12,
      "z": 8,
      "name": "Soil_Seaweed_Block"
    },
    {
      "x": -7,
      "y": 13,
      "z": 8,
      "name": "Soil_Clay_Lime"
    },
    {
      "x": -7,
      "y": 14,
      "z": 8,
      "name": "Plant_Grass_Sharp"
    },
    {
      "x": -6,
      "y": 11,
      "z": -8,
      "name": "Soil_Clay_Green"
    },
    {
      "x": -6,
      "y": 12,
      "z": -8,
      "name": "Soil_Seaweed_Block"
    },
    {
      "x": -6,
      "y": 10,
      "z": -7,
      "name": "Soil_Clay_Green"
    },
    {
      "x": -6,
      "y": 11,
      "z": -7,
      "name": "Soil_Seaweed_Block"
    },
    {
      "x": -6,
      "y": 12,
      "z": -7,
      "name": "Soil_Seaweed_Block"
    },
    {
      "x": -6,
      "y": 13,
      "z": -7,
      "name": "Soil_Clay_Lime"
    },
    {
      "x": -6,
      "y": 14,
      "z": -7,
      "name": "Plant_Grass_Sharp"
    },
    {
      "x": -6,
      "y": 10,
      "z": -6,
      "name": "Soil_Clay_Green"
    },
    {
      "x": -6,
      "y": 11,
      "z": -6,
      "name": "Soil_Seaweed_Block"
    },
    {
      "x": -6,
      "y": 12,
      "z": -6,
      "name": "Soil_Clay_Lime"
    },
    {
      "x": -6,
      "y": 13,
      "z": -6,
      "name": "Plant_Grass_Sharp"
    },
    {
      "x": -6,
      "y": 11,
      "z": -5,
      "name": "Soil_Clay_Green"
    },
    {
      "x": -6,
      "y": 12,
      "z": -5,
      "name": "Soil_Clay_Lime"
    },
    {
      "x": -6,
      "y": 13,
      "z": -5,
      "name": "Plant_Grass_Sharp"
    },
    {
      "x": -6,
      "y": 11,
      "z": -4,
      "name": "Soil_Clay_Green"
    },
    {
      "x": -6,
      "y": 12,
      "z": -4,
      "name": "Soil_Clay_Lime"
    },
    {
      "x": -6,
      "y": 13,
      "z": -4,
      "name": "Plant_Grass_Sharp"
    },
    {
      "x": -6,
      "y": 4,
      "z": -2,
      "name": "Soil_Clay_Green"
    },
    {
      "x": -6,
      "y": 5,
      "z": -2,
      "name": "Soil_Clay_Lime"
    },
    {
      "x": -6,
      "y": 6,
      "z": -2,
      "name": "Plant_Grass_Sharp"
    },
    {
      "x": -6,
      "y": 4,
      "z": -1,
      "name": "Soil_Clay_Green"
    },
    {
      "x": -6,
      "y": 5,
      "z": -1,
      "name": "Soil_Seaweed_Block"
    },
    {
      "x": -6,
      "y": 6,
      "z": -1,
      "name": "Soil_Clay_Lime"
    },
    {
      "x": -6,
      "y": 7,
      "z": -1,
      "name": "Plant_Grass_Sharp"
    },
    {
      "x": -6,
      "y": 16,
      "z": 0,
      "name": "Soil_Clay_Green"
    },
    {
      "x": -6,
      "y": 17,
      "z": 0,
      "name": "Soil_Clay_Green"
    },
    {
      "x": -6,
      "y": 18,
      "z": 0,
      "name": "Soil_Seaweed_Block"
    },
    {
      "x": -6,
      "y": 19,
      "z": 0,
      "name": "Soil_Clay_Lime"
    },
    {
      "x": -6,
      "y": 20,
      "z": 0,
      "name": "Plant_Grass_Sharp"
    },
    {
      "x": -6,
      "y": 12,
      "z": 1,
      "name": "Soil_Seaweed_Block"
    },
    {
      "x": -6,
      "y": 16,
      "z": 1,
      "name": "Soil_Clay_Green"
    },
    {
      "x": -6,
      "y": 17,
      "z": 1,
      "name": "Soil_Seaweed_Block"
    },
    {
      "x": -6,
      "y": 18,
      "z": 1,
      "name": "Soil_Seaweed_Block"
    },
    {
      "x": -6,
      "y": 19,
      "z": 1,
      "name": "Soil_Clay_Lime"
    },
    {
      "x": -6,
      "y": 20,
      "z": 1,
      "name": "Plant_Grass_Sharp"
    },
    {
      "x": -6,
      "y": 17,
      "z": 2,
      "name": "Soil_Clay_Green"
    },
    {
      "x": -6,
      "y": 18,
      "z": 2,
      "name": "Soil_Seaweed_Block"
    },
    {
      "x": -6,
      "y": 19,
      "z": 2,
      "name": "Soil_Clay_Lime"
    },
    {
      "x": -6,
      "y": 20,
      "z": 2,
      "name": "Plant_Grass_Sharp"
    },
    {
      "x": -6,
      "y": 17,
      "z": 3,
      "name": "Soil_Clay_Green"
    },
    {
      "x": -6,
      "y": 18,
      "z": 3,
      "name": "Soil_Seaweed_Block"
    },
    {
      "x": -6,
      "y": 19,
      "z": 3,
      "name": "Soil_Clay_Lime"
    },
    {
      "x": -6,
      "y": 20,
      "z": 3,
      "name": "Plant_Grass_Sharp"
    },
    {
      "x": -6,
      "y": 17,
      "z": 4,
      "name": "Soil_Clay_Green"
    },
    {
      "x": -6,
      "y": 18,
      "z": 4,
      "name": "Soil_Clay_Lime"
    },
    {
      "x": -6,
      "y": 19,
      "z": 4,
      "name": "Plant_Grass_Sharp"
    },
    {
      "x": -6,
      "y": 11,
      "z": 5,
      "name": "Soil_Clay_Green"
    },
    {
      "x": -6,
      "y": 12,
      "z": 5,
      "name": "Soil_Seaweed_Block"
    },
    {
      "x": -6,
      "y": 13,
      "z": 5,
      "name": "Soil_Seaweed_Block"
    },
    {
      "x": -6,
      "y": 16,
      "z": 5,
      "name": "Soil_Clay_Green"
    },
    {
      "x": -6,
      "y": 17,
      "z": 5,
      "name": "Soil_Seaweed_Block"
    },
    {
      "x": -6,
      "y": 18,
      "z": 5,
      "name": "Soil_Seaweed_Block"
    },
    {
      "x": -6,
      "y": 9,
      "z": 6,
      "name": "Soil_Clay_Green"
    },
    {
      "x": -6,
      "y": 10,
      "z": 6,
      "name": "Soil_Clay_Green"
    },
    {
      "x": -6,
      "y": 11,
      "z": 6,
      "name": "Soil_Seaweed_Block"
    },
    {
      "x": -6,
      "y": 12,
      "z": 6,
      "name": "Soil_Seaweed_Block"
    },
    {
      "x": -6,
      "y": 13,
      "z": 6,
      "name": "Soil_Seaweed_Block"
    },
    {
      "x": -6,
      "y": 14,
      "z": 6,
      "name": "Soil_Clay_Lime"
    },
    {
      "x": -6,
      "y": 15,
      "z": 6,
      "name": "Soil_Clay_Lime"
    },
    {
      "x": -6,
      "y": 16,
      "z": 6,
      "name": "Soil_Clay_Green"
    },
    {
      "x": -6,
      "y": 17,
      "z": 6,
      "name": "Soil_Clay_Green"
    },
    {
      "x": -6,
      "y": 8,
      "z": 7,
      "name": "Soil_Clay_Green"
    },
    {
      "x": -6,
      "y": 9,
      "z": 7,
      "name": "Soil_Seaweed_Block"
    },
    {
      "x": -6,
      "y": 10,
      "z": 7,
      "name": "Soil_Seaweed_Block"
    },
    {
      "x": -6,
      "y": 11,
      "z": 7,
      "name": "Soil_Seaweed_Block"
    },
    {
      "x": -6,
      "y": 12,
      "z": 7,
      "name": "Soil_Seaweed_Block"
    },
    {
      "x": -6,
      "y": 13,
      "z": 7,
      "name": "Soil_Clay_Lime"
    },
    {
      "x": -6,
      "y": 14,
      "z": 7,
      "name": "Soil_Clay_Lime"
    },
    {
      "x": -6,
      "y": 15,
      "z": 7,
      "name": "Plant_Grass_Sharp"
    },
    {
      "x": -6,
      "y": 7,
      "z": 8,
      "name": "Soil_Clay_Green"
    },
    {
      "x": -6,
      "y": 8,
      "z": 8,
      "name": "Soil_Clay_Green"
    },
    {
      "x": -6,
      "y": 9,
      "z": 8,
      "name": "Soil_Seaweed_Block"
    },
    {
      "x": -6,
      "y": 10,
      "z": 8,
      "name": "Soil_Seaweed_Block"
    },
    {
      "x": -6,
      "y": 11,
      "z": 8,
      "name": "Soil_Seaweed_Block"
    },
    {
      "x": -6,
      "y": 12,
      "z": 8,
      "name": "Soil_Clay_Lime"
    },
    {
      "x": -6,
      "y": 13,
      "z": 8,
      "name": "Plant_Grass_Sharp"
    },
    {
      "x": -6,
      "y": 9,
      "z": 9,
      "name": "Soil_Clay_Green"
    },
    {
      "x": -6,
      "y": 10,
      "z": 9,
      "name": "Soil_Clay_Green"
    },
    {
      "x": -6,
      "y": 11,
      "z": 9,
      "name": "Soil_Seaweed_Block"
    },
    {
      "x": -6,
      "y": 10,
      "z": 10,
      "name": "Soil_Clay_Green"
    },
    {
      "x": -6,
      "y": 11,
      "z": 10,
      "name": "Soil_Seaweed_Block"
    },
    {
      "x": -5,
      "y": 10,
      "z": -8,
      "name": "Soil_Clay_Green"
    },
    {
      "x": -5,
      "y": 11,
      "z": -8,
      "name": "Soil_Clay_Green"
    },
    {
      "x": -5,
      "y": 12,
      "z": -8,
      "name": "Soil_Seaweed_Block"
    },
    {
      "x": -5,
      "y": 13,
      "z": -8,
      "name": "Soil_Clay_Lime"
    },
    {
      "x": -5,
      "y": 14,
      "z": -8,
      "name": "Plant_Grass_Sharp"
    },
    {
      "x": -5,
      "y": 10,
      "z": -7,
      "name": "Soil_Clay_Green"
    },
    {
      "x": -5,
      "y": 11,
      "z": -7,
      "name": "Soil_Seaweed_Block"
    },
    {
      "x": -5,
      "y": 12,
      "z": -7,
      "name": "Soil_Seaweed_Block"
    },
    {
      "x": -5,
      "y": 13,
      "z": -7,
      "name": "Soil_Clay_Lime"
    },
    {
      "x": -5,
      "y": 14,
      "z": -7,
      "name": "Plant_Grass_Sharp"
    },
    {
      "x": -5,
      "y": 10,
      "z": -6,
      "name": "Soil_Clay_Green"
    },
    {
      "x": -5,
      "y": 11,
      "z": -6,
      "name": "Soil_Seaweed_Block"
    },
    {
      "x": -5,
      "y": 12,
      "z": -6,
      "name": "Soil_Seaweed_Block"
    },
    {
      "x": -5,
      "y": 13,
      "z": -6,
      "name": "Soil_Clay_Lime"
    },
    {
      "x": -5,
      "y": 14,
      "z": -6,
      "name": "Plant_Grass_Sharp"
    },
    {
      "x": -5,
      "y": 11,
      "z": -5,
      "name": "Soil_Clay_Green"
    },
    {
      "x": -5,
      "y": 12,
      "z": -5,
      "name": "Soil_Clay_Lime"
    },
    {
      "x": -5,
      "y": 13,
      "z": -5,
      "name": "Plant_Grass_Sharp"
    },
    {
      "x": -5,
      "y": 12,
      "z": -4,
      "name": "Soil_Seaweed_Block"
    },
    {
      "x": -5,
      "y": 4,
      "z": -3,
      "name": "Soil_Seaweed_Block"
    },
    {
      "x": -5,
      "y": 3,
      "z": -2,
      "name": "Soil_Clay_Green"
    },
    {
      "x": -5,
      "y": 4,
      "z": -2,
      "name": "Soil_Seaweed_Block"
    },
    {
      "x": -5,
      "y": 3,
      "z": -1,
      "name": "Soil_Clay_Green"
    },
    {
      "x": -5,
      "y": 4,
      "z": -1,
      "name": "Soil_Clay_Green"
    },
    {
      "x": -5,
      "y": 5,
      "z": -1,
      "name": "Soil_Clay_Lime"
    },
    {
      "x": -5,
      "y": 6,
      "z": -1,
      "name": "Plant_Grass_Sharp"
    },
    {
      "x": -5,
      "y": 17,
      "z": 0,
      "name": "Soil_Clay_Green"
    },
    {
      "x": -5,
      "y": 18,
      "z": 0,
      "name": "Soil_Seaweed_Block"
    },
    {
      "x": -5,
      "y": 19,
      "z": 0,
      "name": "Soil_Clay_Lime"
    },
    {
      "x": -5,
      "y": 20,
      "z": 0,
      "name": "Plant_Grass_Sharp"
    },
    {
      "x": -5,
      "y": 17,
      "z": 1,
      "name": "Soil_Clay_Green"
    },
    {
      "x": -5,
      "y": 18,
      "z": 1,
      "name": "Soil_Clay_Green"
    },
    {
      "x": -5,
      "y": 19,
      "z": 1,
      "name": "Soil_Clay_Lime"
    },
    {
      "x": -5,
      "y": 20,
      "z": 1,
      "name": "Soil_Clay_Lime"
    },
    {
      "x": -5,
      "y": 21,
      "z": 1,
      "name": "Plant_Grass_Sharp"
    },
    {
      "x": -5,
      "y": 17,
      "z": 2,
      "name": "Soil_Clay_Green"
    },
    {
      "x": -5,
      "y": 18,
      "z": 2,
      "name": "Soil_Seaweed_Block"
    },
    {
      "x": -5,
      "y": 19,
      "z": 2,
      "name": "Soil_Clay_Lime"
    },
    {
      "x": -5,
      "y": 20,
      "z": 2,
      "name": "Plant_Grass_Sharp"
    },
    {
      "x": -5,
      "y": 17,
      "z": 3,
      "name": "Soil_Clay_Green"
    },
    {
      "x": -5,
      "y": 18,
      "z": 3,
      "name": "Soil_Seaweed_Block"
    },
    {
      "x": -5,
      "y": 17,
      "z": 4,
      "name": "Soil_Clay_Green"
    },
    {
      "x": -5,
      "y": 18,
      "z": 4,
      "name": "Soil_Clay_Lime"
    },
    {
      "x": -5,
      "y": 19,
      "z": 4,
      "name": "Plant_Grass_Sharp"
    },
    {
      "x": -5,
      "y": 20,
      "z": 4,
      "name": "Plant_Grass_Sharp"
    },
    {
      "x": -5,
      "y": 11,
      "z": 5,
      "name": "Soil_Clay_Green"
    },
    {
      "x": -5,
      "y": 12,
      "z": 5,
      "name": "Soil_Seaweed_Block"
    },
    {
      "x": -5,
      "y": 13,
      "z": 5,
      "name": "Soil_Seaweed_Block"
    },
    {
      "x": -5,
      "y": 16,
      "z": 5,
      "name": "Soil_Clay_Green"
    },
    {
      "x": -5,
      "y": 17,
      "z": 5,
      "name": "Soil_Seaweed_Block"
    },
    {
      "x": -5,
      "y": 18,
      "z": 5,
      "name": "Soil_Seaweed_Block"
    },
    {
      "x": -5,
      "y": 20,
      "z": 5,
      "name": "Plant_Grass_Sharp"
    },
    {
      "x": -5,
      "y": 12,
      "z": 6,
      "name": "Soil_Seaweed_Block"
    },
    {
      "x": -5,
      "y": 17,
      "z": 6,
      "name": "Soil_Clay_Green"
    },
    {
      "x": -5,
      "y": 18,
      "z": 6,
      "name": "Soil_Seaweed_Block"
    },
    {
      "x": -5,
      "y": 19,
      "z": 6,
      "name": "Soil_Clay_Lime"
    },
    {
      "x": -5,
      "y": 20,
      "z": 6,
      "name": "Plant_Grass_Sharp"
    },
    {
      "x": -5,
      "y": 7,
      "z": 7,
      "name": "Soil_Clay_Green"
    },
    {
      "x": -5,
      "y": 8,
      "z": 7,
      "name": "Soil_Clay_Green"
    },
    {
      "x": -5,
      "y": 9,
      "z": 7,
      "name": "Soil_Clay_Green"
    },
    {
      "x": -5,
      "y": 10,
      "z": 7,
      "name": "Soil_Clay_Green"
    },
    {
      "x": -5,
      "y": 11,
      "z": 7,
      "name": "Soil_Seaweed_Block"
    },
    {
      "x": -5,
      "y": 12,
      "z": 7,
      "name": "Soil_Seaweed_Block"
    },
    {
      "x": -5,
      "y": 6,
      "z": 8,
      "name": "Soil_Clay_Green"
    },
    {
      "x": -5,
      "y": 7,
      "z": 8,
      "name": "Soil_Clay_Green"
    },
    {
      "x": -5,
      "y": 8,
      "z": 8,
      "name": "Soil_Clay_Green"
    },
    {
      "x": -5,
      "y": 9,
      "z": 8,
      "name": "Soil_Clay_Green"
    },
    {
      "x": -5,
      "y": 10,
      "z": 8,
      "name": "Soil_Clay_Green"
    },
    {
      "x": -5,
      "y": 11,
      "z": 8,
      "name": "Soil_Seaweed_Block"
    },
    {
      "x": -5,
      "y": 12,
      "z": 8,
      "name": "Soil_Clay_Lime"
    },
    {
      "x": -5,
      "y": 13,
      "z": 8,
      "name": "Plant_Grass_Sharp"
    },
    {
      "x": -5,
      "y": 6,
      "z": 9,
      "name": "Soil_Clay_Green"
    },
    {
      "x": -5,
      "y": 7,
      "z": 9,
      "name": "Soil_Clay_Green"
    },
    {
      "x": -5,
      "y": 8,
      "z": 9,
      "name": "Soil_Clay_Green"
    },
    {
      "x": -5,
      "y": 9,
      "z": 9,
      "name": "Soil_Seaweed_Block"
    },
    {
      "x": -5,
      "y": 10,
      "z": 9,
      "name": "Soil_Seaweed_Block"
    },
    {
      "x": -5,
      "y": 11,
      "z": 9,
      "name": "Soil_Seaweed_Block"
    },
    {
      "x": -5,
      "y": 12,
      "z": 9,
      "name": "Soil_Clay_Lime"
    },
    {
      "x": -5,
      "y": 13,
      "z": 9,
      "name": "Plant_Grass_Sharp"
    },
    {
      "x": -5,
      "y": 10,
      "z": 10,
      "name": "Soil_Clay_Green"
    },
    {
      "x": -5,
      "y": 11,
      "z": 10,
      "name": "Soil_Seaweed_Block"
    },
    {
      "x": -5,
      "y": 12,
      "z": 10,
      "name": "Soil_Seaweed_Block"
    },
    {
      "x": -5,
      "y": 10,
      "z": 11,
      "name": "Soil_Clay_Green"
    },
    {
      "x": -5,
      "y": 11,
      "z": 11,
      "name": "Soil_Seaweed_Block"
    },
    {
      "x": -5,
      "y": 12,
      "z": 11,
      "name": "Soil_Seaweed_Block"
    },
    {
      "x": -4,
      "y": 12,
      "z": -9,
      "name": "Soil_Seaweed_Block"
    },
    {
      "x": -4,
      "y": 9,
      "z": -8,
      "name": "Soil_Clay_Green"
    },
    {
      "x": -4,
      "y": 10,
      "z": -8,
      "name": "Soil_Clay_Green"
    },
    {
      "x": -4,
      "y": 11,
      "z": -8,
      "name": "Soil_Clay_Green"
    },
    {
      "x": -4,
      "y": 12,
      "z": -8,
      "name": "Soil_Seaweed_Block"
    },
    {
      "x": -4,
      "y": 13,
      "z": -8,
      "name": "Soil_Clay_Lime"
    },
    {
      "x": -4,
      "y": 14,
      "z": -8,
      "name": "Plant_Grass_Sharp"
    },
    {
      "x": -4,
      "y": 10,
      "z": -7,
      "name": "Soil_Clay_Green"
    },
    {
      "x": -4,
      "y": 11,
      "z": -7,
      "name": "Soil_Seaweed_Block"
    },
    {
      "x": -4,
      "y": 12,
      "z": -7,
      "name": "Soil_Seaweed_Block"
    },
    {
      "x": -4,
      "y": 13,
      "z": -7,
      "name": "Soil_Clay_Lime"
    },
    {
      "x": -4,
      "y": 14,
      "z": -7,
      "name": "Plant_Grass_Sharp"
    },
    {
      "x": -4,
      "y": 10,
      "z": -6,
      "name": "Soil_Clay_Green"
    },
    {
      "x": -4,
      "y": 11,
      "z": -6,
      "name": "Soil_Clay_Green"
    },
    {
      "x": -4,
      "y": 12,
      "z": -6,
      "name": "Soil_Seaweed_Block"
    },
    {
      "x": -4,
      "y": 13,
      "z": -6,
      "name": "Soil_Clay_Lime"
    },
    {
      "x": -4,
      "y": 14,
      "z": -6,
      "name": "Plant_Grass_Sharp"
    },
    {
      "x": -4,
      "y": 11,
      "z": -5,
      "name": "Soil_Clay_Green"
    },
    {
      "x": -4,
      "y": 12,
      "z": -5,
      "name": "Soil_Seaweed_Block"
    },
    {
      "x": -4,
      "y": 0,
      "z": -2,
      "name": "Soil_Clay_Green"
    },
    {
      "x": -4,
      "y": 1,
      "z": -2,
      "name": "Soil_Clay_Green"
    },
    {
      "x": -4,
      "y": 0,
      "z": -1,
      "name": "Soil_Clay_Green"
    },
    {
      "x": -4,
      "y": 1,
      "z": -1,
      "name": "Soil_Clay_Green"
    },
    {
      "x": -4,
      "y": 2,
      "z": -1,
      "name": "Soil_Clay_Green"
    },
    {
      "x": -4,
      "y": 20,
      "z": -1,
      "name": "Soil_Clay_Green"
    },
    {
      "x": -4,
      "y": 21,
      "z": -1,
      "name": "Soil_Seaweed_Block"
    },
    {
      "x": -4,
      "y": 19,
      "z": 0,
      "name": "Soil_Clay_Green"
    },
    {
      "x": -4,
      "y": 20,
      "z": 0,
      "name": "Soil_Seaweed_Block"
    },
    {
      "x": -4,
      "y": 21,
      "z": 0,
      "name": "Soil_Clay_Lime"
    },
    {
      "x": -4,
      "y": 22,
      "z": 0,
      "name": "Plant_Grass_Sharp"
    },
    {
      "x": -4,
      "y": 20,
      "z": 1,
      "name": "Soil_Clay_Green"
    },
    {
      "x": -4,
      "y": 21,
      "z": 1,
      "name": "Soil_Seaweed_Block"
    },
    {
      "x": -4,
      "y": 22,
      "z": 1,
      "name": "Plant_Grass_Sharp"
    },
    {
      "x": -4,
      "y": 18,
      "z": 5,
      "name": "Soil_Seaweed_Block"
    },
    {
      "x": -4,
      "y": 19,
      "z": 5,
      "name": "Soil_Clay_Lime"
    },
    {
      "x": -4,
      "y": 20,
      "z": 5,
      "name": "Plant_Grass_Sharp"
    },
    {
      "x": -4,
      "y": 18,
      "z": 6,
      "name": "Soil_Seaweed_Block"
    },
    {
      "x": -4,
      "y": 19,
      "z": 6,
      "name": "Soil_Clay_Lime"
    },
    {
      "x": -4,
      "y": 20,
      "z": 6,
      "name": "Plant_Grass_Sharp"
    },
    {
      "x": -4,
      "y": 3,
      "z": 7,
      "name": "Soil_Clay_Green"
    },
    {
      "x": -4,
      "y": 4,
      "z": 7,
      "name": "Soil_Clay_Green"
    },
    {
      "x": -4,
      "y": 7,
      "z": 7,
      "name": "Soil_Clay_Green"
    },
    {
      "x": -4,
      "y": 18,
      "z": 7,
      "name": "Soil_Seaweed_Block"
    },
    {
      "x": -4,
      "y": 19,
      "z": 7,
      "name": "Soil_Clay_Lime"
    },
    {
      "x": -4,
      "y": 20,
      "z": 7,
      "name": "Plant_Grass_Sharp"
    },
    {
      "x": -4,
      "y": 3,
      "z": 8,
      "name": "Soil_Clay_Green"
    },
    {
      "x": -4,
      "y": 4,
      "z": 8,
      "name": "Soil_Clay_Green"
    },
    {
      "x": -4,
      "y": 5,
      "z": 8,
      "name": "Soil_Clay_Green"
    },
    {
      "x": -4,
      "y": 6,
      "z": 8,
      "name": "Soil_Seaweed_Block"
    },
    {
      "x": -4,
      "y": 7,
      "z": 8,
      "name": "Soil_Seaweed_Block"
    },
    {
      "x": -4,
      "y": 8,
      "z": 8,
      "name": "Soil_Seaweed_Block"
    },
    {
      "x": -4,
      "y": 9,
      "z": 8,
      "name": "Soil_Clay_Green"
    },
    {
      "x": -4,
      "y": 10,
      "z": 8,
      "name": "Soil_Clay_Green"
    },
    {
      "x": -4,
      "y": 11,
      "z": 8,
      "name": "Soil_Seaweed_Block"
    },
    {
      "x": -4,
      "y": 12,
      "z": 8,
      "name": "Soil_Clay_Lime"
    },
    {
      "x": -4,
      "y": 13,
      "z": 8,
      "name": "Plant_Grass_Sharp"
    },
    {
      "x": -4,
      "y": 5,
      "z": 9,
      "name": "Soil_Clay_Green"
    },
    {
      "x": -4,
      "y": 6,
      "z": 9,
      "name": "Soil_Clay_Green"
    },
    {
      "x": -4,
      "y": 7,
      "z": 9,
      "name": "Soil_Seaweed_Block"
    },
    {
      "x": -4,
      "y": 8,
      "z": 9,
      "name": "Soil_Seaweed_Block"
    },
    {
      "x": -4,
      "y": 9,
      "z": 9,
      "name": "Soil_Seaweed_Block"
    },
    {
      "x": -4,
      "y": 10,
      "z": 9,
      "name": "Soil_Seaweed_Block"
    },
    {
      "x": -4,
      "y": 11,
      "z": 9,
      "name": "Soil_Seaweed_Block"
    },
    {
      "x": -4,
      "y": 12,
      "z": 9,
      "name": "Soil_Seaweed_Block"
    },
    {
      "x": -4,
      "y": 13,
      "z": 9,
      "name": "Soil_Clay_Lime"
    },
    {
      "x": -4,
      "y": 14,
      "z": 9,
      "name": "Soil_Seaweed_Block"
    },
    {
      "x": -4,
      "y": 15,
      "z": 9,
      "name": "Soil_Seaweed_Block"
    },
    {
      "x": -4,
      "y": 16,
      "z": 9,
      "name": "Soil_Clay_Green"
    },
    {
      "x": -4,
      "y": 8,
      "z": 10,
      "name": "Soil_Clay_Green"
    },
    {
      "x": -4,
      "y": 9,
      "z": 10,
      "name": "Soil_Clay_Green"
    },
    {
      "x": -4,
      "y": 10,
      "z": 10,
      "name": "Soil_Seaweed_Block"
    },
    {
      "x": -4,
      "y": 11,
      "z": 10,
      "name": "Soil_Seaweed_Block"
    },
    {
      "x": -4,
      "y": 12,
      "z": 10,
      "name": "Soil_Seaweed_Block"
    },
    {
      "x": -4,
      "y": 13,
      "z": 10,
      "name": "Soil_Clay_Lime"
    },
    {
      "x": -4,
      "y": 14,
      "z": 10,
      "name": "Soil_Seaweed_Block"
    },
    {
      "x": -4,
      "y": 15,
      "z": 10,
      "name": "Soil_Seaweed_Block"
    },
    {
      "x": -4,
      "y": 9,
      "z": 11,
      "name": "Soil_Clay_Green"
    },
    {
      "x": -4,
      "y": 10,
      "z": 11,
      "name": "Soil_Clay_Green"
    },
    {
      "x": -4,
      "y": 11,
      "z": 11,
      "name": "Soil_Seaweed_Block"
    },
    {
      "x": -4,
      "y": 12,
      "z": 11,
      "name": "Soil_Seaweed_Block"
    },
    {
      "x": -4,
      "y": 13,
      "z": 11,
      "name": "Soil_Clay_Lime"
    },
    {
      "x": -4,
      "y": 14,
      "z": 11,
      "name": "Soil_Seaweed_Block"
    },
    {
      "x": -4,
      "y": 11,
      "z": 12,
      "name": "Soil_Clay_Green"
    },
    {
      "x": -4,
      "y": 12,
      "z": 12,
      "name": "Soil_Seaweed_Block"
    },
    {
      "x": -3,
      "y": 8,
      "z": -10,
      "name": "Soil_Clay_Green"
    },
    {
      "x": -3,
      "y": 8,
      "z": -9,
      "name": "Soil_Clay_Green"
    },
    {
      "x": -3,
      "y": 12,
      "z": -9,
      "name": "Soil_Seaweed_Block"
    },
    {
      "x": -3,
      "y": 7,
      "z": -8,
      "name": "Soil_Clay_Green"
    },
    {
      "x": -3,
      "y": 8,
      "z": -8,
      "name": "Soil_Clay_Green"
    },
    {
      "x": -3,
      "y": 9,
      "z": -8,
      "name": "Soil_Clay_Green"
    },
    {
      "x": -3,
      "y": 10,
      "z": -8,
      "name": "Soil_Clay_Green"
    },
    {
      "x": -3,
      "y": 11,
      "z": -8,
      "name": "Soil_Clay_Green"
    },
    {
      "x": -3,
      "y": 12,
      "z": -8,
      "name": "Soil_Seaweed_Block"
    },
    {
      "x": -3,
      "y": 13,
      "z": -8,
      "name": "Soil_Clay_Lime"
    },
    {
      "x": -3,
      "y": 14,
      "z": -8,
      "name": "Plant_Grass_Sharp"
    },
    {
      "x": -3,
      "y": 5,
      "z": -7,
      "name": "Soil_Clay_Green"
    },
    {
      "x": -3,
      "y": 6,
      "z": -7,
      "name": "Soil_Clay_Green"
    },
    {
      "x": -3,
      "y": 9,
      "z": -7,
      "name": "Soil_Clay_Green"
    },
    {
      "x": -3,
      "y": 10,
      "z": -7,
      "name": "Soil_Clay_Green"
    },
    {
      "x": -3,
      "y": 11,
      "z": -7,
      "name": "Soil_Clay_Green"
    },
    {
      "x": -3,
      "y": 12,
      "z": -7,
      "name": "Soil_Clay_Lime"
    },
    {
      "x": -3,
      "y": 13,
      "z": -7,
      "name": "Soil_Clay_Lime"
    },
    {
      "x": -3,
      "y": 14,
      "z": -7,
      "name": "Plant_Grass_Sharp"
    },
    {
      "x": -3,
      "y": 3,
      "z": -6,
      "name": "Soil_Clay_Green"
    },
    {
      "x": -3,
      "y": 4,
      "z": -6,
      "name": "Soil_Clay_Green"
    },
    {
      "x": -3,
      "y": 5,
      "z": -6,
      "name": "Soil_Seaweed_Block"
    },
    {
      "x": -3,
      "y": 6,
      "z": -6,
      "name": "Soil_Clay_Green"
    },
    {
      "x": -3,
      "y": 12,
      "z": -6,
      "name": "Soil_Seaweed_Block"
    },
    {
      "x": -3,
      "y": 1,
      "z": -5,
      "name": "Soil_Clay_Green"
    },
    {
      "x": -3,
      "y": 2,
      "z": -5,
      "name": "Soil_Clay_Green"
    },
    {
      "x": -3,
      "y": 3,
      "z": -5,
      "name": "Soil_Clay_Green"
    },
    {
      "x": -3,
      "y": 4,
      "z": -5,
      "name": "Soil_Clay_Green"
    },
    {
      "x": -3,
      "y": 5,
      "z": -5,
      "name": "Soil_Seaweed_Block"
    },
    {
      "x": -3,
      "y": 12,
      "z": -5,
      "name": "Soil_Seaweed_Block"
    },
    {
      "x": -3,
      "y": 18,
      "z": -4,
      "name": "Soil_Clay_Green"
    },
    {
      "x": -3,
      "y": 19,
      "z": -3,
      "name": "Soil_Clay_Green"
    },
    {
      "x": -3,
      "y": 20,
      "z": -3,
      "name": "Soil_Seaweed_Block"
    },
    {
      "x": -3,
      "y": 0,
      "z": -2,
      "name": "Soil_Clay_Green"
    },
    {
      "x": -3,
      "y": 1,
      "z": -2,
      "name": "Soil_Clay_Green"
    },
    {
      "x": -3,
      "y": 20,
      "z": -2,
      "name": "Soil_Clay_Green"
    },
    {
      "x": -3,
      "y": 21,
      "z": -2,
      "name": "Soil_Seaweed_Block"
    },
    {
      "x": -3,
      "y": 20,
      "z": -1,
      "name": "Soil_Clay_Green"
    },
    {
      "x": -3,
      "y": 21,
      "z": -1,
      "name": "Soil_Seaweed_Block"
    },
    {
      "x": -3,
      "y": 23,
      "z": -1,
      "name": "Plant_Grass_Sharp"
    },
    {
      "x": -3,
      "y": 19,
      "z": 0,
      "name": "Soil_Clay_Green"
    },
    {
      "x": -3,
      "y": 20,
      "z": 0,
      "name": "Soil_Seaweed_Block"
    },
    {
      "x": -3,
      "y": 21,
      "z": 0,
      "name": "Soil_Seaweed_Block"
    },
    {
      "x": -3,
      "y": 22,
      "z": 0,
      "name": "Soil_Clay_Lime"
    },
    {
      "x": -3,
      "y": 23,
      "z": 0,
      "name": "Plant_Grass_Sharp"
    },
    {
      "x": -3,
      "y": 20,
      "z": 1,
      "name": "Soil_Clay_Green"
    },
    {
      "x": -3,
      "y": 21,
      "z": 1,
      "name": "Soil_Seaweed_Block"
    },
    {
      "x": -3,
      "y": 22,
      "z": 1,
      "name": "Soil_Clay_Lime"
    },
    {
      "x": -3,
      "y": 23,
      "z": 1,
      "name": "Plant_Grass_Sharp"
    },
    {
      "x": -3,
      "y": 18,
      "z": 5,
      "name": "Soil_Clay_Green"
    },
    {
      "x": -3,
      "y": 19,
      "z": 5,
      "name": "Soil_Clay_Lime"
    },
    {
      "x": -3,
      "y": 20,
      "z": 5,
      "name": "Plant_Grass_Sharp"
    },
    {
      "x": -3,
      "y": 18,
      "z": 6,
      "name": "Soil_Seaweed_Block"
    },
    {
      "x": -3,
      "y": 19,
      "z": 6,
      "name": "Soil_Clay_Lime"
    },
    {
      "x": -3,
      "y": 20,
      "z": 6,
      "name": "Plant_Grass_Sharp"
    },
    {
      "x": -3,
      "y": 1,
      "z": 7,
      "name": "Soil_Clay_Green"
    },
    {
      "x": -3,
      "y": 2,
      "z": 7,
      "name": "Soil_Clay_Green"
    },
    {
      "x": -3,
      "y": 3,
      "z": 7,
      "name": "Soil_Clay_Green"
    },
    {
      "x": -3,
      "y": 4,
      "z": 7,
      "name": "Soil_Clay_Green"
    },
    {
      "x": -3,
      "y": 5,
      "z": 7,
      "name": "Soil_Clay_Green"
    },
    {
      "x": -3,
      "y": 6,
      "z": 7,
      "name": "Soil_Clay_Green"
    },
    {
      "x": -3,
      "y": 17,
      "z": 7,
      "name": "Soil_Clay_Green"
    },
    {
      "x": -3,
      "y": 18,
      "z": 7,
      "name": "Soil_Seaweed_Block"
    },
    {
      "x": -3,
      "y": 19,
      "z": 7,
      "name": "Soil_Clay_Lime"
    },
    {
      "x": -3,
      "y": 20,
      "z": 7,
      "name": "Plant_Grass_Sharp"
    },
    {
      "x": -3,
      "y": 4,
      "z": 8,
      "name": "Soil_Clay_Green"
    },
    {
      "x": -3,
      "y": 5,
      "z": 8,
      "name": "Soil_Clay_Green"
    },
    {
      "x": -3,
      "y": 6,
      "z": 8,
      "name": "Soil_Clay_Green"
    },
    {
      "x": -3,
      "y": 7,
      "z": 8,
      "name": "Soil_Clay_Green"
    },
    {
      "x": -3,
      "y": 8,
      "z": 8,
      "name": "Soil_Clay_Green"
    },
    {
      "x": -3,
      "y": 9,
      "z": 8,
      "name": "Soil_Clay_Green"
    },
    {
      "x": -3,
      "y": 10,
      "z": 8,
      "name": "Soil_Clay_Green"
    },
    {
      "x": -3,
      "y": 11,
      "z": 8,
      "name": "Soil_Seaweed_Block"
    },
    {
      "x": -3,
      "y": 12,
      "z": 8,
      "name": "Soil_Seaweed_Block"
    },
    {
      "x": -3,
      "y": 13,
      "z": 8,
      "name": "Soil_Seaweed_Block"
    },
    {
      "x": -3,
      "y": 14,
      "z": 8,
      "name": "Soil_Seaweed_Block"
    },
    {
      "x": -3,
      "y": 15,
      "z": 8,
      "name": "Soil_Clay_Green"
    },
    {
      "x": -3,
      "y": 16,
      "z": 8,
      "name": "Soil_Clay_Green"
    },
    {
      "x": -3,
      "y": 17,
      "z": 8,
      "name": "Soil_Clay_Green"
    },
    {
      "x": -3,
      "y": 18,
      "z": 8,
      "name": "Soil_Seaweed_Block"
    },
    {
      "x": -3,
      "y": 7,
      "z": 9,
      "name": "Soil_Clay_Green"
    },
    {
      "x": -3,
      "y": 8,
      "z": 9,
      "name": "Soil_Clay_Green"
    },
    {
      "x": -3,
      "y": 9,
      "z": 9,
      "name": "Soil_Clay_Green"
    },
    {
      "x": -3,
      "y": 10,
      "z": 9,
      "name": "Soil_Clay_Green"
    },
    {
      "x": -3,
      "y": 11,
      "z": 9,
      "name": "Soil_Seaweed_Block"
    },
    {
      "x": -3,
      "y": 12,
      "z": 9,
      "name": "Soil_Seaweed_Block"
    },
    {
      "x": -3,
      "y": 13,
      "z": 9,
      "name": "Soil_Seaweed_Block"
    },
    {
      "x": -3,
      "y": 14,
      "z": 9,
      "name": "Soil_Seaweed_Block"
    },
    {
      "x": -3,
      "y": 15,
      "z": 9,
      "name": "Soil_Seaweed_Block"
    },
    {
      "x": -3,
      "y": 16,
      "z": 9,
      "name": "Soil_Seaweed_Block"
    },
    {
      "x": -3,
      "y": 17,
      "z": 9,
      "name": "Soil_Clay_Green"
    },
    {
      "x": -3,
      "y": 18,
      "z": 9,
      "name": "Soil_Seaweed_Block"
    },
    {
      "x": -3,
      "y": 7,
      "z": 10,
      "name": "Soil_Clay_Green"
    },
    {
      "x": -3,
      "y": 8,
      "z": 10,
      "name": "Soil_Clay_Green"
    },
    {
      "x": -3,
      "y": 9,
      "z": 10,
      "name": "Soil_Seaweed_Block"
    },
    {
      "x": -3,
      "y": 10,
      "z": 10,
      "name": "Soil_Seaweed_Block"
    },
    {
      "x": -3,
      "y": 11,
      "z": 10,
      "name": "Soil_Seaweed_Block"
    },
    {
      "x": -3,
      "y": 12,
      "z": 10,
      "name": "Soil_Seaweed_Block"
    },
    {
      "x": -3,
      "y": 13,
      "z": 10,
      "name": "Soil_Seaweed_Block"
    },
    {
      "x": -3,
      "y": 14,
      "z": 10,
      "name": "Soil_Seaweed_Block"
    },
    {
      "x": -3,
      "y": 15,
      "z": 10,
      "name": "Soil_Seaweed_Block"
    },
    {
      "x": -3,
      "y": 16,
      "z": 10,
      "name": "Soil_Seaweed_Block"
    },
    {
      "x": -3,
      "y": 9,
      "z": 11,
      "name": "Soil_Clay_Green"
    },
    {
      "x": -3,
      "y": 10,
      "z": 11,
      "name": "Soil_Clay_Green"
    },
    {
      "x": -3,
      "y": 11,
      "z": 11,
      "name": "Soil_Seaweed_Block"
    },
    {
      "x": -3,
      "y": 12,
      "z": 11,
      "name": "Soil_Seaweed_Block"
    },
    {
      "x": -3,
      "y": 13,
      "z": 11,
      "name": "Soil_Seaweed_Block"
    },
    {
      "x": -3,
      "y": 14,
      "z": 11,
      "name": "Soil_Seaweed_Block"
    },
    {
      "x": -3,
      "y": 15,
      "z": 11,
      "name": "Soil_Seaweed_Block"
    },
    {
      "x": -3,
      "y": 16,
      "z": 11,
      "name": "Soil_Seaweed_Block"
    },
    {
      "x": -3,
      "y": 10,
      "z": 12,
      "name": "Soil_Clay_Green"
    },
    {
      "x": -3,
      "y": 11,
      "z": 12,
      "name": "Soil_Clay_Green"
    },
    {
      "x": -3,
      "y": 12,
      "z": 12,
      "name": "Soil_Seaweed_Block"
    },
    {
      "x": -3,
      "y": 13,
      "z": 12,
      "name": "Soil_Seaweed_Block"
    },
    {
      "x": -2,
      "y": 8,
      "z": -10,
      "name": "Soil_Clay_Green"
    },
    {
      "x": -2,
      "y": 9,
      "z": -10,
      "name": "Soil_Seaweed_Block"
    },
    {
      "x": -2,
      "y": 6,
      "z": -9,
      "name": "Soil_Clay_Green"
    },
    {
      "x": -2,
      "y": 7,
      "z": -9,
      "name": "Soil_Clay_Green"
    },
    {
      "x": -2,
      "y": 8,
      "z": -9,
      "name": "Soil_Seaweed_Block"
    },
    {
      "x": -2,
      "y": 9,
      "z": -9,
      "name": "Soil_Clay_Green"
    },
    {
      "x": -2,
      "y": 10,
      "z": -9,
      "name": "Soil_Clay_Green"
    },
    {
      "x": -2,
      "y": 11,
      "z": -9,
      "name": "Soil_Clay_Green"
    },
    {
      "x": -2,
      "y": 12,
      "z": -9,
      "name": "Soil_Seaweed_Block"
    },
    {
      "x": -2,
      "y": 13,
      "z": -9,
      "name": "Soil_Seaweed_Block"
    },
    {
      "x": -2,
      "y": 14,
      "z": -9,
      "name": "Soil_Seaweed_Block"
    },
    {
      "x": -2,
      "y": 15,
      "z": -9,
      "name": "Soil_Seaweed_Block"
    },
    {
      "x": -2,
      "y": 6,
      "z": -8,
      "name": "Soil_Clay_Green"
    },
    {
      "x": -2,
      "y": 7,
      "z": -8,
      "name": "Soil_Clay_Green"
    },
    {
      "x": -2,
      "y": 8,
      "z": -8,
      "name": "Soil_Seaweed_Block"
    },
    {
      "x": -2,
      "y": 9,
      "z": -8,
      "name": "Soil_Clay_Green"
    },
    {
      "x": -2,
      "y": 10,
      "z": -8,
      "name": "Soil_Clay_Green"
    },
    {
      "x": -2,
      "y": 11,
      "z": -8,
      "name": "Soil_Clay_Green"
    },
    {
      "x": -2,
      "y": 12,
      "z": -8,
      "name": "Soil_Seaweed_Block"
    },
    {
      "x": -2,
      "y": 13,
      "z": -8,
      "name": "Soil_Seaweed_Block"
    },
    {
      "x": -2,
      "y": 14,
      "z": -8,
      "name": "Soil_Seaweed_Block"
    },
    {
      "x": -2,
      "y": 15,
      "z": -8,
      "name": "Soil_Seaweed_Block"
    },
    {
      "x": -2,
      "y": 5,
      "z": -7,
      "name": "Soil_Clay_Green"
    },
    {
      "x": -2,
      "y": 6,
      "z": -7,
      "name": "Soil_Clay_Green"
    },
    {
      "x": -2,
      "y": 7,
      "z": -7,
      "name": "Soil_Seaweed_Block"
    },
    {
      "x": -2,
      "y": 8,
      "z": -7,
      "name": "Soil_Seaweed_Block"
    },
    {
      "x": -2,
      "y": 16,
      "z": -7,
      "name": "Soil_Seaweed_Block"
    },
    {
      "x": -2,
      "y": 17,
      "z": -7,
      "name": "Soil_Clay_Lime"
    },
    {
      "x": -2,
      "y": 18,
      "z": -7,
      "name": "Soil_Clay_Lime"
    },
    {
      "x": -2,
      "y": 19,
      "z": -7,
      "name": "Plant_Grass_Sharp"
    },
    {
      "x": -2,
      "y": 5,
      "z": -6,
      "name": "Soil_Clay_Green"
    },
    {
      "x": -2,
      "y": 6,
      "z": -6,
      "name": "Soil_Clay_Green"
    },
    {
      "x": -2,
      "y": 7,
      "z": -6,
      "name": "Soil_Seaweed_Block"
    },
    {
      "x": -2,
      "y": 8,
      "z": -6,
      "name": "Soil_Seaweed_Block"
    },
    {
      "x": -2,
      "y": 16,
      "z": -6,
      "name": "Soil_Seaweed_Block"
    },
    {
      "x": -2,
      "y": 17,
      "z": -6,
      "name": "Soil_Clay_Lime"
    },
    {
      "x": -2,
      "y": 18,
      "z": -6,
      "name": "Soil_Clay_Lime"
    },
    {
      "x": -2,
      "y": 19,
      "z": -6,
      "name": "Plant_Grass_Sharp"
    },
    {
      "x": -2,
      "y": 1,
      "z": -5,
      "name": "Soil_Clay_Green"
    },
    {
      "x": -2,
      "y": 2,
      "z": -5,
      "name": "Soil_Clay_Green"
    },
    {
      "x": -2,
      "y": 3,
      "z": -5,
      "name": "Soil_Clay_Green"
    },
    {
      "x": -2,
      "y": 4,
      "z": -5,
      "name": "Soil_Clay_Green"
    },
    {
      "x": -2,
      "y": 5,
      "z": -5,
      "name": "Soil_Clay_Green"
    },
    {
      "x": -2,
      "y": 18,
      "z": -5,
      "name": "Soil_Clay_Lime"
    },
    {
      "x": -2,
      "y": 19,
      "z": -5,
      "name": "Soil_Clay_Lime"
    },
    {
      "x": -2,
      "y": 20,
      "z": -5,
      "name": "Plant_Grass_Sharp"
    },
    {
      "x": -2,
      "y": 19,
      "z": -4,
      "name": "Soil_Clay_Green"
    },
    {
      "x": -2,
      "y": 20,
      "z": -1,
      "name": "Soil_Clay_Green"
    },
    {
      "x": -2,
      "y": 21,
      "z": -1,
      "name": "Soil_Seaweed_Block"
    },
    {
      "x": -2,
      "y": 22,
      "z": -1,
      "name": "Soil_Clay_Lime"
    },
    {
      "x": -2,
      "y": 23,
      "z": -1,
      "name": "Plant_Grass_Sharp"
    },
    {
      "x": -2,
      "y": 20,
      "z": 0,
      "name": "Soil_Clay_Green"
    },
    {
      "x": -2,
      "y": 21,
      "z": 0,
      "name": "Soil_Seaweed_Block"
    },
    {
      "x": -2,
      "y": 22,
      "z": 0,
      "name": "Soil_Clay_Lime"
    },
    {
      "x": -2,
      "y": 23,
      "z": 0,
      "name": "Plant_Grass_Sharp"
    },
    {
      "x": -2,
      "y": 21,
      "z": 1,
      "name": "Soil_Clay_Green"
    },
    {
      "x": -2,
      "y": 22,
      "z": 1,
      "name": "Soil_Seaweed_Block"
    },
    {
      "x": -2,
      "y": 23,
      "z": 1,
      "name": "Plant_Grass_Sharp"
    },
    {
      "x": -2,
      "y": 24,
      "z": 1,
      "name": "Plant_Grass_Sharp"
    },
    {
      "x": -2,
      "y": 18,
      "z": 5,
      "name": "Soil_Clay_Green"
    },
    {
      "x": -2,
      "y": 19,
      "z": 5,
      "name": "Soil_Clay_Lime"
    },
    {
      "x": -2,
      "y": 0,
      "z": 6,
      "name": "Soil_Clay_Green"
    },
    {
      "x": -2,
      "y": 1,
      "z": 6,
      "name": "Soil_Clay_Green"
    },
    {
      "x": -2,
      "y": 2,
      "z": 6,
      "name": "Soil_Clay_Green"
    },
    {
      "x": -2,
      "y": 18,
      "z": 6,
      "name": "Soil_Clay_Green"
    },
    {
      "x": -2,
      "y": 19,
      "z": 6,
      "name": "Soil_Clay_Lime"
    },
    {
      "x": -2,
      "y": 20,
      "z": 6,
      "name": "Plant_Grass_Sharp"
    },
    {
      "x": -2,
      "y": 0,
      "z": 7,
      "name": "Soil_Clay_Green"
    },
    {
      "x": -2,
      "y": 1,
      "z": 7,
      "name": "Soil_Clay_Green"
    },
    {
      "x": -2,
      "y": 2,
      "z": 7,
      "name": "Soil_Clay_Green"
    },
    {
      "x": -2,
      "y": 18,
      "z": 7,
      "name": "Soil_Clay_Green"
    },
    {
      "x": -2,
      "y": 19,
      "z": 7,
      "name": "Soil_Clay_Lime"
    },
    {
      "x": -2,
      "y": 20,
      "z": 7,
      "name": "Plant_Grass_Sharp"
    },
    {
      "x": -2,
      "y": 2,
      "z": 8,
      "name": "Soil_Clay_Green"
    },
    {
      "x": -2,
      "y": 3,
      "z": 8,
      "name": "Soil_Clay_Green"
    },
    {
      "x": -2,
      "y": 4,
      "z": 8,
      "name": "Soil_Clay_Green"
    },
    {
      "x": -2,
      "y": 16,
      "z": 8,
      "name": "Soil_Clay_Green"
    },
    {
      "x": -2,
      "y": 17,
      "z": 8,
      "name": "Soil_Clay_Green"
    },
    {
      "x": -2,
      "y": 18,
      "z": 8,
      "name": "Soil_Seaweed_Block"
    },
    {
      "x": -2,
      "y": 19,
      "z": 8,
      "name": "Soil_Clay_Lime"
    },
    {
      "x": -2,
      "y": 20,
      "z": 8,
      "name": "Plant_Grass_Sharp"
    },
    {
      "x": -2,
      "y": 7,
      "z": 9,
      "name": "Soil_Clay_Green"
    },
    {
      "x": -2,
      "y": 8,
      "z": 9,
      "name": "Soil_Clay_Green"
    },
    {
      "x": -2,
      "y": 9,
      "z": 9,
      "name": "Soil_Clay_Green"
    },
    {
      "x": -2,
      "y": 10,
      "z": 9,
      "name": "Soil_Clay_Green"
    },
    {
      "x": -2,
      "y": 11,
      "z": 9,
      "name": "Soil_Seaweed_Block"
    },
    {
      "x": -2,
      "y": 12,
      "z": 9,
      "name": "Soil_Seaweed_Block"
    },
    {
      "x": -2,
      "y": 13,
      "z": 9,
      "name": "Soil_Seaweed_Block"
    },
    {
      "x": -2,
      "y": 14,
      "z": 9,
      "name": "Soil_Seaweed_Block"
    },
    {
      "x": -2,
      "y": 15,
      "z": 9,
      "name": "Soil_Seaweed_Block"
    },
    {
      "x": -2,
      "y": 16,
      "z": 9,
      "name": "Soil_Seaweed_Block"
    },
    {
      "x": -2,
      "y": 17,
      "z": 9,
      "name": "Soil_Clay_Green"
    },
    {
      "x": -2,
      "y": 18,
      "z": 9,
      "name": "Soil_Seaweed_Block"
    },
    {
      "x": -2,
      "y": 19,
      "z": 9,
      "name": "Soil_Clay_Lime"
    },
    {
      "x": -2,
      "y": 20,
      "z": 9,
      "name": "Plant_Grass_Sharp"
    },
    {
      "x": -2,
      "y": 9,
      "z": 10,
      "name": "Soil_Clay_Green"
    },
    {
      "x": -2,
      "y": 10,
      "z": 10,
      "name": "Soil_Seaweed_Block"
    },
    {
      "x": -2,
      "y": 11,
      "z": 10,
      "name": "Soil_Seaweed_Block"
    },
    {
      "x": -2,
      "y": 12,
      "z": 10,
      "name": "Soil_Seaweed_Block"
    },
    {
      "x": -2,
      "y": 13,
      "z": 10,
      "name": "Soil_Clay_Lime"
    },
    {
      "x": -2,
      "y": 14,
      "z": 10,
      "name": "Soil_Seaweed_Block"
    },
    {
      "x": -2,
      "y": 15,
      "z": 10,
      "name": "Soil_Seaweed_Block"
    },
    {
      "x": -2,
      "y": 16,
      "z": 10,
      "name": "Soil_Seaweed_Block"
    },
    {
      "x": -2,
      "y": 17,
      "z": 10,
      "name": "Soil_Seaweed_Block"
    },
    {
      "x": -2,
      "y": 9,
      "z": 11,
      "name": "Soil_Clay_Green"
    },
    {
      "x": -2,
      "y": 10,
      "z": 11,
      "name": "Soil_Seaweed_Block"
    },
    {
      "x": -2,
      "y": 11,
      "z": 11,
      "name": "Soil_Seaweed_Block"
    },
    {
      "x": -2,
      "y": 12,
      "z": 11,
      "name": "Soil_Seaweed_Block"
    },
    {
      "x": -2,
      "y": 13,
      "z": 11,
      "name": "Soil_Clay_Lime"
    },
    {
      "x": -2,
      "y": 14,
      "z": 11,
      "name": "Plant_Grass_Sharp"
    },
    {
      "x": -2,
      "y": 15,
      "z": 11,
      "name": "Soil_Seaweed_Block"
    },
    {
      "x": -2,
      "y": 16,
      "z": 11,
      "name": "Soil_Seaweed_Block"
    },
    {
      "x": -2,
      "y": 10,
      "z": 12,
      "name": "Soil_Clay_Green"
    },
    {
      "x": -2,
      "y": 11,
      "z": 12,
      "name": "Soil_Clay_Green"
    },
    {
      "x": -2,
      "y": 12,
      "z": 12,
      "name": "Soil_Seaweed_Block"
    },
    {
      "x": -2,
      "y": 11,
      "z": 13,
      "name": "Soil_Clay_Green"
    },
    {
      "x": -1,
      "y": 19,
      "z": -12,
      "name": "Soil_Clay_Lime"
    },
    {
      "x": -1,
      "y": 20,
      "z": -12,
      "name": "Plant_Grass_Sharp"
    },
    {
      "x": -1,
      "y": 19,
      "z": -11,
      "name": "Soil_Clay_Lime"
    },
    {
      "x": -1,
      "y": 20,
      "z": -11,
      "name": "Plant_Grass_Sharp"
    },
    {
      "x": -1,
      "y": 7,
      "z": -10,
      "name": "Soil_Clay_Green"
    },
    {
      "x": -1,
      "y": 8,
      "z": -10,
      "name": "Soil_Seaweed_Block"
    },
    {
      "x": -1,
      "y": 9,
      "z": -10,
      "name": "Soil_Seaweed_Block"
    },
    {
      "x": -1,
      "y": 10,
      "z": -10,
      "name": "Soil_Seaweed_Block"
    },
    {
      "x": -1,
      "y": 11,
      "z": -10,
      "name": "Soil_Seaweed_Block"
    },
    {
      "x": -1,
      "y": 12,
      "z": -10,
      "name": "Soil_Clay_Green"
    },
    {
      "x": -1,
      "y": 13,
      "z": -10,
      "name": "Soil_Clay_Green"
    },
    {
      "x": -1,
      "y": 14,
      "z": -10,
      "name": "Soil_Clay_Green"
    },
    {
      "x": -1,
      "y": 15,
      "z": -10,
      "name": "Soil_Clay_Green"
    },
    {
      "x": -1,
      "y": 19,
      "z": -10,
      "name": "Plant_Grass_Sharp"
    },
    {
      "x": -1,
      "y": 6,
      "z": -9,
      "name": "Soil_Clay_Green"
    },
    {
      "x": -1,
      "y": 7,
      "z": -9,
      "name": "Soil_Seaweed_Block"
    },
    {
      "x": -1,
      "y": 8,
      "z": -9,
      "name": "Soil_Seaweed_Block"
    },
    {
      "x": -1,
      "y": 9,
      "z": -9,
      "name": "Soil_Seaweed_Block"
    },
    {
      "x": -1,
      "y": 10,
      "z": -9,
      "name": "Soil_Seaweed_Block"
    },
    {
      "x": -1,
      "y": 11,
      "z": -9,
      "name": "Soil_Seaweed_Block"
    },
    {
      "x": -1,
      "y": 12,
      "z": -9,
      "name": "Soil_Clay_Green"
    },
    {
      "x": -1,
      "y": 13,
      "z": -9,
      "name": "Soil_Seaweed_Block"
    },
    {
      "x": -1,
      "y": 14,
      "z": -9,
      "name": "Soil_Seaweed_Block"
    },
    {
      "x": -1,
      "y": 15,
      "z": -9,
      "name": "Soil_Seaweed_Block"
    },
    {
      "x": -1,
      "y": 16,
      "z": -9,
      "name": "Soil_Seaweed_Block"
    },
    {
      "x": -1,
      "y": 17,
      "z": -9,
      "name": "Soil_Clay_Lime"
    },
    {
      "x": -1,
      "y": 18,
      "z": -9,
      "name": "Plant_Grass_Sharp"
    },
    {
      "x": -1,
      "y": 6,
      "z": -8,
      "name": "Soil_Clay_Green"
    },
    {
      "x": -1,
      "y": 7,
      "z": -8,
      "name": "Soil_Seaweed_Block"
    },
    {
      "x": -1,
      "y": 8,
      "z": -8,
      "name": "Soil_Seaweed_Block"
    },
    {
      "x": -1,
      "y": 9,
      "z": -8,
      "name": "Soil_Seaweed_Block"
    },
    {
      "x": -1,
      "y": 10,
      "z": -8,
      "name": "Soil_Seaweed_Block"
    },
    {
      "x": -1,
      "y": 11,
      "z": -8,
      "name": "Soil_Seaweed_Block"
    },
    {
      "x": -1,
      "y": 12,
      "z": -8,
      "name": "Soil_Seaweed_Block"
    },
    {
      "x": -1,
      "y": 13,
      "z": -8,
      "name": "Soil_Seaweed_Block"
    },
    {
      "x": -1,
      "y": 14,
      "z": -8,
      "name": "Soil_Seaweed_Block"
    },
    {
      "x": -1,
      "y": 15,
      "z": -8,
      "name": "Soil_Seaweed_Block"
    },
    {
      "x": -1,
      "y": 16,
      "z": -8,
      "name": "Soil_Seaweed_Block"
    },
    {
      "x": -1,
      "y": 17,
      "z": -8,
      "name": "Soil_Clay_Lime"
    },
    {
      "x": -1,
      "y": 18,
      "z": -8,
      "name": "Plant_Grass_Sharp"
    },
    {
      "x": -1,
      "y": 5,
      "z": -7,
      "name": "Soil_Clay_Green"
    },
    {
      "x": -1,
      "y": 6,
      "z": -7,
      "name": "Soil_Clay_Green"
    },
    {
      "x": -1,
      "y": 7,
      "z": -7,
      "name": "Soil_Seaweed_Block"
    },
    {
      "x": -1,
      "y": 8,
      "z": -7,
      "name": "Soil_Seaweed_Block"
    },
    {
      "x": -1,
      "y": 9,
      "z": -7,
      "name": "Soil_Seaweed_Block"
    },
    {
      "x": -1,
      "y": 10,
      "z": -7,
      "name": "Soil_Seaweed_Block"
    },
    {
      "x": -1,
      "y": 14,
      "z": -7,
      "name": "Soil_Seaweed_Block"
    },
    {
      "x": -1,
      "y": 15,
      "z": -7,
      "name": "Soil_Seaweed_Block"
    },
    {
      "x": -1,
      "y": 16,
      "z": -7,
      "name": "Soil_Seaweed_Block"
    },
    {
      "x": -1,
      "y": 17,
      "z": -7,
      "name": "Soil_Clay_Lime"
    },
    {
      "x": -1,
      "y": 18,
      "z": -7,
      "name": "Plant_Grass_Sharp"
    },
    {
      "x": -1,
      "y": 7,
      "z": -6,
      "name": "Soil_Seaweed_Block"
    },
    {
      "x": -1,
      "y": 8,
      "z": -6,
      "name": "Soil_Seaweed_Block"
    },
    {
      "x": -1,
      "y": 15,
      "z": -6,
      "name": "Soil_Clay_Green"
    },
    {
      "x": -1,
      "y": 16,
      "z": -6,
      "name": "Soil_Seaweed_Block"
    },
    {
      "x": -1,
      "y": 21,
      "z": -1,
      "name": "Soil_Clay_Green"
    },
    {
      "x": -1,
      "y": 22,
      "z": -1,
      "name": "Soil_Seaweed_Block"
    },
    {
      "x": -1,
      "y": 23,
      "z": -1,
      "name": "Soil_Clay_Lime"
    },
    {
      "x": -1,
      "y": 24,
      "z": -1,
      "name": "Plant_Grass_Sharp"
    },
    {
      "x": -1,
      "y": 21,
      "z": 0,
      "name": "Soil_Clay_Green"
    },
    {
      "x": -1,
      "y": 22,
      "z": 0,
      "name": "Soil_Seaweed_Block"
    },
    {
      "x": -1,
      "y": 23,
      "z": 0,
      "name": "Soil_Clay_Lime"
    },
    {
      "x": -1,
      "y": 24,
      "z": 0,
      "name": "Plant_Grass_Sharp"
    },
    {
      "x": -1,
      "y": 21,
      "z": 1,
      "name": "Soil_Clay_Green"
    },
    {
      "x": -1,
      "y": 22,
      "z": 1,
      "name": "Soil_Seaweed_Block"
    },
    {
      "x": -1,
      "y": 23,
      "z": 1,
      "name": "Soil_Clay_Lime"
    },
    {
      "x": -1,
      "y": 24,
      "z": 1,
      "name": "Plant_Grass_Sharp"
    },
    {
      "x": -1,
      "y": 18,
      "z": 7,
      "name": "Soil_Clay_Green"
    },
    {
      "x": -1,
      "y": 19,
      "z": 7,
      "name": "Soil_Clay_Lime"
    },
    {
      "x": -1,
      "y": 20,
      "z": 7,
      "name": "Soil_Clay_Lime"
    },
    {
      "x": -1,
      "y": 21,
      "z": 7,
      "name": "Plant_Grass_Sharp"
    },
    {
      "x": -1,
      "y": 17,
      "z": 8,
      "name": "Soil_Clay_Green"
    },
    {
      "x": -1,
      "y": 18,
      "z": 8,
      "name": "Soil_Seaweed_Block"
    },
    {
      "x": -1,
      "y": 19,
      "z": 8,
      "name": "Soil_Seaweed_Block"
    },
    {
      "x": -1,
      "y": 20,
      "z": 8,
      "name": "Soil_Clay_Lime"
    },
    {
      "x": -1,
      "y": 21,
      "z": 8,
      "name": "Plant_Grass_Sharp"
    },
    {
      "x": -1,
      "y": 10,
      "z": 9,
      "name": "Soil_Clay_Green"
    },
    {
      "x": -1,
      "y": 11,
      "z": 9,
      "name": "Soil_Seaweed_Block"
    },
    {
      "x": -1,
      "y": 12,
      "z": 9,
      "name": "Soil_Seaweed_Block"
    },
    {
      "x": -1,
      "y": 16,
      "z": 9,
      "name": "Soil_Clay_Green"
    },
    {
      "x": -1,
      "y": 17,
      "z": 9,
      "name": "Soil_Clay_Green"
    },
    {
      "x": -1,
      "y": 18,
      "z": 9,
      "name": "Soil_Seaweed_Block"
    },
    {
      "x": -1,
      "y": 19,
      "z": 9,
      "name": "Soil_Clay_Lime"
    },
    {
      "x": -1,
      "y": 20,
      "z": 9,
      "name": "Plant_Grass_Sharp"
    },
    {
      "x": -1,
      "y": 9,
      "z": 10,
      "name": "Soil_Clay_Green"
    },
    {
      "x": -1,
      "y": 10,
      "z": 10,
      "name": "Soil_Seaweed_Block"
    },
    {
      "x": -1,
      "y": 11,
      "z": 10,
      "name": "Soil_Seaweed_Block"
    },
    {
      "x": -1,
      "y": 12,
      "z": 10,
      "name": "Soil_Seaweed_Block"
    },
    {
      "x": -1,
      "y": 13,
      "z": 10,
      "name": "Soil_Clay_Lime"
    },
    {
      "x": -1,
      "y": 16,
      "z": 10,
      "name": "Soil_Clay_Green"
    },
    {
      "x": -1,
      "y": 9,
      "z": 11,
      "name": "Soil_Clay_Green"
    },
    {
      "x": -1,
      "y": 10,
      "z": 11,
      "name": "Soil_Seaweed_Block"
    },
    {
      "x": -1,
      "y": 11,
      "z": 11,
      "name": "Soil_Seaweed_Block"
    },
    {
      "x": -1,
      "y": 12,
      "z": 11,
      "name": "Soil_Seaweed_Block"
    },
    {
      "x": -1,
      "y": 13,
      "z": 11,
      "name": "Soil_Clay_Lime"
    },
    {
      "x": -1,
      "y": 14,
      "z": 11,
      "name": "Plant_Grass_Sharp"
    },
    {
      "x": -1,
      "y": 10,
      "z": 12,
      "name": "Soil_Clay_Green"
    },
    {
      "x": -1,
      "y": 11,
      "z": 12,
      "name": "Soil_Clay_Green"
    },
    {
      "x": -1,
      "y": 12,
      "z": 12,
      "name": "Soil_Seaweed_Block"
    },
    {
      "x": 0,
      "y": 20,
      "z": -14,
      "name": "Soil_Clay_Lime"
    },
    {
      "x": 0,
      "y": 19,
      "z": -13,
      "name": "Soil_Seaweed_Block"
    },
    {
      "x": 0,
      "y": 20,
      "z": -13,
      "name": "Soil_Clay_Lime"
    },
    {
      "x": 0,
      "y": 21,
      "z": -13,
      "name": "Plant_Grass_Sharp"
    },
    {
      "x": 0,
      "y": 19,
      "z": -12,
      "name": "Soil_Seaweed_Block"
    },
    {
      "x": 0,
      "y": 20,
      "z": -12,
      "name": "Plant_Grass_Sharp"
    },
    {
      "x": 0,
      "y": 21,
      "z": -12,
      "name": "Plant_Grass_Sharp"
    },
    {
      "x": 0,
      "y": 18,
      "z": -11,
      "name": "Soil_Clay_Lime"
    },
    {
      "x": 0,
      "y": 19,
      "z": -11,
      "name": "Soil_Clay_Lime"
    },
    {
      "x": 0,
      "y": 20,
      "z": -11,
      "name": "Plant_Grass_Sharp"
    },
    {
      "x": 0,
      "y": 7,
      "z": -10,
      "name": "Soil_Clay_Green"
    },
    {
      "x": 0,
      "y": 8,
      "z": -10,
      "name": "Soil_Seaweed_Block"
    },
    {
      "x": 0,
      "y": 9,
      "z": -10,
      "name": "Soil_Seaweed_Block"
    },
    {
      "x": 0,
      "y": 13,
      "z": -10,
      "name": "Soil_Clay_Green"
    },
    {
      "x": 0,
      "y": 14,
      "z": -10,
      "name": "Soil_Clay_Green"
    },
    {
      "x": 0,
      "y": 15,
      "z": -10,
      "name": "Soil_Clay_Green"
    },
    {
      "x": 0,
      "y": 16,
      "z": -10,
      "name": "Soil_Seaweed_Block"
    },
    {
      "x": 0,
      "y": 17,
      "z": -10,
      "name": "Soil_Seaweed_Block"
    },
    {
      "x": 0,
      "y": 18,
      "z": -10,
      "name": "Soil_Clay_Lime"
    },
    {
      "x": 0,
      "y": 19,
      "z": -10,
      "name": "Plant_Grass_Sharp"
    },
    {
      "x": 0,
      "y": 6,
      "z": -9,
      "name": "Soil_Clay_Green"
    },
    {
      "x": 0,
      "y": 7,
      "z": -9,
      "name": "Soil_Seaweed_Block"
    },
    {
      "x": 0,
      "y": 8,
      "z": -9,
      "name": "Soil_Seaweed_Block"
    },
    {
      "x": 0,
      "y": 9,
      "z": -9,
      "name": "Soil_Seaweed_Block"
    },
    {
      "x": 0,
      "y": 10,
      "z": -9,
      "name": "Soil_Clay_Lime"
    },
    {
      "x": 0,
      "y": 11,
      "z": -9,
      "name": "Soil_Seaweed_Block"
    },
    {
      "x": 0,
      "y": 12,
      "z": -9,
      "name": "Soil_Clay_Green"
    },
    {
      "x": 0,
      "y": 13,
      "z": -9,
      "name": "Soil_Seaweed_Block"
    },
    {
      "x": 0,
      "y": 14,
      "z": -9,
      "name": "Soil_Seaweed_Block"
    },
    {
      "x": 0,
      "y": 15,
      "z": -9,
      "name": "Soil_Seaweed_Block"
    },
    {
      "x": 0,
      "y": 16,
      "z": -9,
      "name": "Soil_Seaweed_Block"
    },
    {
      "x": 0,
      "y": 17,
      "z": -9,
      "name": "Soil_Seaweed_Block"
    },
    {
      "x": 0,
      "y": 18,
      "z": -9,
      "name": "Soil_Clay_Lime"
    },
    {
      "x": 0,
      "y": 19,
      "z": -9,
      "name": "Plant_Grass_Sharp"
    },
    {
      "x": 0,
      "y": 5,
      "z": -8,
      "name": "Soil_Clay_Green"
    },
    {
      "x": 0,
      "y": 6,
      "z": -8,
      "name": "Soil_Seaweed_Block"
    },
    {
      "x": 0,
      "y": 7,
      "z": -8,
      "name": "Soil_Seaweed_Block"
    },
    {
      "x": 0,
      "y": 8,
      "z": -8,
      "name": "Soil_Seaweed_Block"
    },
    {
      "x": 0,
      "y": 9,
      "z": -8,
      "name": "Soil_Seaweed_Block"
    },
    {
      "x": 0,
      "y": 10,
      "z": -8,
      "name": "Soil_Seaweed_Block"
    },
    {
      "x": 0,
      "y": 11,
      "z": -8,
      "name": "Soil_Seaweed_Block"
    },
    {
      "x": 0,
      "y": 12,
      "z": -8,
      "name": "Soil_Clay_Green"
    },
    {
      "x": 0,
      "y": 13,
      "z": -8,
      "name": "Soil_Clay_Green"
    },
    {
      "x": 0,
      "y": 14,
      "z": -8,
      "name": "Soil_Seaweed_Block"
    },
    {
      "x": 0,
      "y": 15,
      "z": -8,
      "name": "Soil_Seaweed_Block"
    },
    {
      "x": 0,
      "y": 16,
      "z": -8,
      "name": "Soil_Seaweed_Block"
    },
    {
      "x": 0,
      "y": 17,
      "z": -8,
      "name": "Soil_Clay_Lime"
    },
    {
      "x": 0,
      "y": 18,
      "z": -8,
      "name": "Plant_Grass_Sharp"
    },
    {
      "x": 0,
      "y": 5,
      "z": -7,
      "name": "Soil_Clay_Green"
    },
    {
      "x": 0,
      "y": 6,
      "z": -7,
      "name": "Soil_Clay_Green"
    },
    {
      "x": 0,
      "y": 7,
      "z": -7,
      "name": "Soil_Seaweed_Block"
    },
    {
      "x": 0,
      "y": 8,
      "z": -7,
      "name": "Soil_Seaweed_Block"
    },
    {
      "x": 0,
      "y": 9,
      "z": -7,
      "name": "Soil_Seaweed_Block"
    },
    {
      "x": 0,
      "y": 14,
      "z": -7,
      "name": "Soil_Clay_Green"
    },
    {
      "x": 0,
      "y": 15,
      "z": -7,
      "name": "Soil_Clay_Green"
    },
    {
      "x": 0,
      "y": 16,
      "z": -7,
      "name": "Soil_Seaweed_Block"
    },
    {
      "x": 0,
      "y": 7,
      "z": -6,
      "name": "Soil_Seaweed_Block"
    },
    {
      "x": 0,
      "y": 8,
      "z": -6,
      "name": "Soil_Seaweed_Block"
    },
    {
      "x": 0,
      "y": 15,
      "z": -6,
      "name": "Soil_Clay_Green"
    },
    {
      "x": 0,
      "y": 16,
      "z": -6,
      "name": "Soil_Seaweed_Block"
    },
    {
      "x": 0,
      "y": 22,
      "z": -2,
      "name": "Soil_Clay_Green"
    },
    {
      "x": 0,
      "y": 23,
      "z": -2,
      "name": "Soil_Seaweed_Block"
    },
    {
      "x": 0,
      "y": 21,
      "z": -1,
      "name": "Soil_Clay_Green"
    },
    {
      "x": 0,
      "y": 22,
      "z": -1,
      "name": "Soil_Clay_Green"
    },
    {
      "x": 0,
      "y": 23,
      "z": -1,
      "name": "Soil_Clay_Lime"
    },
    {
      "x": 0,
      "y": 24,
      "z": -1,
      "name": "Plant_Grass_Sharp"
    },
    {
      "x": 0,
      "y": 21,
      "z": 0,
      "name": "Soil_Clay_Green"
    },
    {
      "x": 0,
      "y": 22,
      "z": 0,
      "name": "Soil_Seaweed_Block"
    },
    {
      "x": 0,
      "y": 23,
      "z": 0,
      "name": "Soil_Seaweed_Block"
    },
    {
      "x": 0,
      "y": 24,
      "z": 0,
      "name": "Soil_Clay_Lime"
    },
    {
      "x": 0,
      "y": 25,
      "z": 0,
      "name": "Plant_Grass_Sharp"
    },
    {
      "x": 0,
      "y": 22,
      "z": 1,
      "name": "Soil_Clay_Green"
    },
    {
      "x": 0,
      "y": 23,
      "z": 1,
      "name": "Soil_Seaweed_Block"
    },
    {
      "x": 0,
      "y": 24,
      "z": 1,
      "name": "Soil_Clay_Lime"
    },
    {
      "x": 0,
      "y": 25,
      "z": 1,
      "name": "Plant_Grass_Sharp"
    },
    {
      "x": 0,
      "y": 21,
      "z": 5,
      "name": "Soil_Seaweed_Block"
    },
    {
      "x": 0,
      "y": 20,
      "z": 6,
      "name": "Soil_Clay_Green"
    },
    {
      "x": 0,
      "y": 21,
      "z": 6,
      "name": "Soil_Seaweed_Block"
    },
    {
      "x": 0,
      "y": 18,
      "z": 7,
      "name": "Soil_Clay_Green"
    },
    {
      "x": 0,
      "y": 19,
      "z": 7,
      "name": "Soil_Seaweed_Block"
    },
    {
      "x": 0,
      "y": 20,
      "z": 7,
      "name": "Soil_Seaweed_Block"
    },
    {
      "x": 0,
      "y": 21,
      "z": 7,
      "name": "Soil_Clay_Lime"
    },
    {
      "x": 0,
      "y": 22,
      "z": 7,
      "name": "Plant_Grass_Sharp"
    },
    {
      "x": 0,
      "y": 18,
      "z": 8,
      "name": "Soil_Clay_Green"
    },
    {
      "x": 0,
      "y": 19,
      "z": 8,
      "name": "Soil_Seaweed_Block"
    },
    {
      "x": 0,
      "y": 20,
      "z": 8,
      "name": "Soil_Seaweed_Block"
    },
    {
      "x": 0,
      "y": 21,
      "z": 8,
      "name": "Soil_Clay_Lime"
    },
    {
      "x": 0,
      "y": 22,
      "z": 8,
      "name": "Plant_Grass_Sharp"
    },
    {
      "x": 0,
      "y": 17,
      "z": 9,
      "name": "Soil_Clay_Green"
    },
    {
      "x": 0,
      "y": 18,
      "z": 9,
      "name": "Soil_Clay_Green"
    },
    {
      "x": 0,
      "y": 19,
      "z": 9,
      "name": "Soil_Seaweed_Block"
    },
    {
      "x": 0,
      "y": 10,
      "z": 10,
      "name": "Soil_Clay_Green"
    },
    {
      "x": 0,
      "y": 11,
      "z": 10,
      "name": "Soil_Seaweed_Block"
    },
    {
      "x": 0,
      "y": 12,
      "z": 10,
      "name": "Soil_Clay_Lime"
    },
    {
      "x": 0,
      "y": 13,
      "z": 10,
      "name": "Plant_Grass_Sharp"
    },
    {
      "x": 0,
      "y": 16,
      "z": 10,
      "name": "Soil_Clay_Green"
    },
    {
      "x": 0,
      "y": 10,
      "z": 11,
      "name": "Soil_Clay_Green"
    },
    {
      "x": 0,
      "y": 11,
      "z": 11,
      "name": "Soil_Clay_Lime"
    },
    {
      "x": 0,
      "y": 12,
      "z": 11,
      "name": "Plant_Grass_Sharp"
    },
    {
      "x": 0,
      "y": 13,
      "z": 11,
      "name": "Plant_Grass_Sharp"
    },
    {
      "x": 0,
      "y": 10,
      "z": 12,
      "name": "Soil_Clay_Green"
    },
    {
      "x": 0,
      "y": 11,
      "z": 12,
      "name": "Soil_Clay_Lime"
    },
    {
      "x": 1,
      "y": 19,
      "z": -12,
      "name": "Soil_Seaweed_Block"
    },
    {
      "x": 1,
      "y": 17,
      "z": -11,
      "name": "Soil_Seaweed_Block"
    },
    {
      "x": 1,
      "y": 19,
      "z": -11,
      "name": "Soil_Clay_Lime"
    },
    {
      "x": 1,
      "y": 20,
      "z": -11,
      "name": "Plant_Grass_Sharp"
    },
    {
      "x": 1,
      "y": 5,
      "z": -10,
      "name": "Soil_Clay_Green"
    },
    {
      "x": 1,
      "y": 6,
      "z": -10,
      "name": "Soil_Clay_Green"
    },
    {
      "x": 1,
      "y": 7,
      "z": -10,
      "name": "Soil_Clay_Green"
    },
    {
      "x": 1,
      "y": 8,
      "z": -10,
      "name": "Soil_Seaweed_Block"
    },
    {
      "x": 1,
      "y": 9,
      "z": -10,
      "name": "Soil_Seaweed_Block"
    },
    {
      "x": 1,
      "y": 13,
      "z": -10,
      "name": "Soil_Clay_Green"
    },
    {
      "x": 1,
      "y": 14,
      "z": -10,
      "name": "Soil_Clay_Green"
    },
    {
      "x": 1,
      "y": 15,
      "z": -10,
      "name": "Soil_Clay_Green"
    },
    {
      "x": 1,
      "y": 16,
      "z": -10,
      "name": "Soil_Seaweed_Block"
    },
    {
      "x": 1,
      "y": 17,
      "z": -10,
      "name": "Soil_Seaweed_Block"
    },
    {
      "x": 1,
      "y": 18,
      "z": -10,
      "name": "Soil_Clay_Lime"
    },
    {
      "x": 1,
      "y": 19,
      "z": -10,
      "name": "Plant_Grass_Sharp"
    },
    {
      "x": 1,
      "y": 5,
      "z": -9,
      "name": "Soil_Clay_Green"
    },
    {
      "x": 1,
      "y": 6,
      "z": -9,
      "name": "Soil_Seaweed_Block"
    },
    {
      "x": 1,
      "y": 7,
      "z": -9,
      "name": "Soil_Seaweed_Block"
    },
    {
      "x": 1,
      "y": 8,
      "z": -9,
      "name": "Soil_Seaweed_Block"
    },
    {
      "x": 1,
      "y": 9,
      "z": -9,
      "name": "Soil_Clay_Lime"
    },
    {
      "x": 1,
      "y": 10,
      "z": -9,
      "name": "Soil_Seaweed_Block"
    },
    {
      "x": 1,
      "y": 11,
      "z": -9,
      "name": "Soil_Seaweed_Block"
    },
    {
      "x": 1,
      "y": 12,
      "z": -9,
      "name": "Soil_Clay_Green"
    },
    {
      "x": 1,
      "y": 13,
      "z": -9,
      "name": "Soil_Clay_Green"
    },
    {
      "x": 1,
      "y": 14,
      "z": -9,
      "name": "Soil_Seaweed_Block"
    },
    {
      "x": 1,
      "y": 15,
      "z": -9,
      "name": "Soil_Seaweed_Block"
    },
    {
      "x": 1,
      "y": 16,
      "z": -9,
      "name": "Soil_Seaweed_Block"
    },
    {
      "x": 1,
      "y": 17,
      "z": -9,
      "name": "Soil_Clay_Lime"
    },
    {
      "x": 1,
      "y": 18,
      "z": -9,
      "name": "Plant_Grass_Sharp"
    },
    {
      "x": 1,
      "y": 4,
      "z": -8,
      "name": "Soil_Clay_Green"
    },
    {
      "x": 1,
      "y": 5,
      "z": -8,
      "name": "Soil_Seaweed_Block"
    },
    {
      "x": 1,
      "y": 6,
      "z": -8,
      "name": "Soil_Seaweed_Block"
    },
    {
      "x": 1,
      "y": 7,
      "z": -8,
      "name": "Soil_Seaweed_Block"
    },
    {
      "x": 1,
      "y": 8,
      "z": -8,
      "name": "Soil_Clay_Lime"
    },
    {
      "x": 1,
      "y": 9,
      "z": -8,
      "name": "Plant_Grass_Sharp"
    },
    {
      "x": 1,
      "y": 10,
      "z": -8,
      "name": "Soil_Seaweed_Block"
    },
    {
      "x": 1,
      "y": 11,
      "z": -8,
      "name": "Soil_Seaweed_Block"
    },
    {
      "x": 1,
      "y": 12,
      "z": -8,
      "name": "Soil_Clay_Green"
    },
    {
      "x": 1,
      "y": 13,
      "z": -8,
      "name": "Soil_Clay_Green"
    },
    {
      "x": 1,
      "y": 14,
      "z": -8,
      "name": "Soil_Clay_Green"
    },
    {
      "x": 1,
      "y": 15,
      "z": -8,
      "name": "Soil_Seaweed_Block"
    },
    {
      "x": 1,
      "y": 16,
      "z": -8,
      "name": "Soil_Seaweed_Block"
    },
    {
      "x": 1,
      "y": 17,
      "z": -8,
      "name": "Soil_Clay_Lime"
    },
    {
      "x": 1,
      "y": 18,
      "z": -8,
      "name": "Plant_Grass_Sharp"
    },
    {
      "x": 1,
      "y": 4,
      "z": -7,
      "name": "Soil_Clay_Green"
    },
    {
      "x": 1,
      "y": 5,
      "z": -7,
      "name": "Soil_Seaweed_Block"
    },
    {
      "x": 1,
      "y": 6,
      "z": -7,
      "name": "Soil_Seaweed_Block"
    },
    {
      "x": 1,
      "y": 7,
      "z": -7,
      "name": "Soil_Seaweed_Block"
    },
    {
      "x": 1,
      "y": 8,
      "z": -7,
      "name": "Soil_Clay_Lime"
    },
    {
      "x": 1,
      "y": 9,
      "z": -7,
      "name": "Plant_Grass_Sharp"
    },
    {
      "x": 1,
      "y": 14,
      "z": -7,
      "name": "Soil_Clay_Green"
    },
    {
      "x": 1,
      "y": 15,
      "z": -7,
      "name": "Soil_Clay_Green"
    },
    {
      "x": 1,
      "y": 16,
      "z": -7,
      "name": "Soil_Seaweed_Block"
    },
    {
      "x": 1,
      "y": 18,
      "z": -7,
      "name": "Plant_Grass_Sharp"
    },
    {
      "x": 1,
      "y": 1,
      "z": -6,
      "name": "Soil_Clay_Green"
    },
    {
      "x": 1,
      "y": 2,
      "z": -6,
      "name": "Soil_Clay_Green"
    },
    {
      "x": 1,
      "y": 3,
      "z": -6,
      "name": "Soil_Clay_Green"
    },
    {
      "x": 1,
      "y": 4,
      "z": -6,
      "name": "Soil_Clay_Green"
    },
    {
      "x": 1,
      "y": 5,
      "z": -6,
      "name": "Soil_Clay_Green"
    },
    {
      "x": 1,
      "y": 6,
      "z": -6,
      "name": "Soil_Clay_Green"
    },
    {
      "x": 1,
      "y": 0,
      "z": -5,
      "name": "Soil_Clay_Green"
    },
    {
      "x": 1,
      "y": 1,
      "z": -5,
      "name": "Soil_Clay_Green"
    },
    {
      "x": 1,
      "y": 2,
      "z": -5,
      "name": "Soil_Clay_Green"
    },
    {
      "x": 1,
      "y": 3,
      "z": -5,
      "name": "Soil_Clay_Green"
    },
    {
      "x": 1,
      "y": 4,
      "z": -5,
      "name": "Soil_Clay_Green"
    },
    {
      "x": 1,
      "y": 22,
      "z": -2,
      "name": "Soil_Clay_Green"
    },
    {
      "x": 1,
      "y": 23,
      "z": -2,
      "name": "Soil_Seaweed_Block"
    },
    {
      "x": 1,
      "y": 21,
      "z": -1,
      "name": "Soil_Clay_Green"
    },
    {
      "x": 1,
      "y": 22,
      "z": -1,
      "name": "Soil_Seaweed_Block"
    },
    {
      "x": 1,
      "y": 23,
      "z": -1,
      "name": "Soil_Seaweed_Block"
    },
    {
      "x": 1,
      "y": 25,
      "z": -1,
      "name": "Plant_Grass_Sharp"
    },
    {
      "x": 1,
      "y": 22,
      "z": 0,
      "name": "Soil_Clay_Green"
    },
    {
      "x": 1,
      "y": 23,
      "z": 0,
      "name": "Soil_Seaweed_Block"
    },
    {
      "x": 1,
      "y": 24,
      "z": 0,
      "name": "Soil_Clay_Lime"
    },
    {
      "x": 1,
      "y": 25,
      "z": 0,
      "name": "Plant_Grass_Sharp"
    },
    {
      "x": 1,
      "y": 23,
      "z": 1,
      "name": "Soil_Clay_Green"
    },
    {
      "x": 1,
      "y": 24,
      "z": 1,
      "name": "Soil_Clay_Lime"
    },
    {
      "x": 1,
      "y": 25,
      "z": 1,
      "name": "Soil_Clay_Lime"
    },
    {
      "x": 1,
      "y": 26,
      "z": 1,
      "name": "Plant_Grass_Sharp"
    },
    {
      "x": 1,
      "y": 23,
      "z": 2,
      "name": "Soil_Clay_Green"
    },
    {
      "x": 1,
      "y": 24,
      "z": 2,
      "name": "Soil_Clay_Lime"
    },
    {
      "x": 1,
      "y": 25,
      "z": 2,
      "name": "Soil_Clay_Lime"
    },
    {
      "x": 1,
      "y": 26,
      "z": 2,
      "name": "Plant_Grass_Sharp"
    },
    {
      "x": 1,
      "y": 22,
      "z": 4,
      "name": "Soil_Clay_Green"
    },
    {
      "x": 1,
      "y": 20,
      "z": 5,
      "name": "Soil_Clay_Green"
    },
    {
      "x": 1,
      "y": 21,
      "z": 5,
      "name": "Soil_Seaweed_Block"
    },
    {
      "x": 1,
      "y": 22,
      "z": 5,
      "name": "Soil_Seaweed_Block"
    },
    {
      "x": 1,
      "y": 19,
      "z": 6,
      "name": "Soil_Clay_Green"
    },
    {
      "x": 1,
      "y": 20,
      "z": 6,
      "name": "Soil_Clay_Green"
    },
    {
      "x": 1,
      "y": 21,
      "z": 6,
      "name": "Soil_Seaweed_Block"
    },
    {
      "x": 1,
      "y": 22,
      "z": 6,
      "name": "Soil_Seaweed_Block"
    },
    {
      "x": 1,
      "y": 19,
      "z": 7,
      "name": "Soil_Clay_Green"
    },
    {
      "x": 1,
      "y": 20,
      "z": 7,
      "name": "Soil_Seaweed_Block"
    },
    {
      "x": 1,
      "y": 21,
      "z": 7,
      "name": "Soil_Seaweed_Block"
    },
    {
      "x": 1,
      "y": 22,
      "z": 7,
      "name": "Soil_Clay_Lime"
    },
    {
      "x": 1,
      "y": 23,
      "z": 7,
      "name": "Plant_Grass_Sharp"
    },
    {
      "x": 1,
      "y": 18,
      "z": 8,
      "name": "Soil_Clay_Green"
    },
    {
      "x": 1,
      "y": 19,
      "z": 8,
      "name": "Soil_Seaweed_Block"
    },
    {
      "x": 1,
      "y": 20,
      "z": 8,
      "name": "Soil_Seaweed_Block"
    },
    {
      "x": 1,
      "y": 21,
      "z": 8,
      "name": "Soil_Seaweed_Block"
    },
    {
      "x": 1,
      "y": 19,
      "z": 9,
      "name": "Soil_Clay_Green"
    },
    {
      "x": 1,
      "y": 20,
      "z": 9,
      "name": "Soil_Seaweed_Block"
    },
    {
      "x": 1,
      "y": 21,
      "z": 9,
      "name": "Soil_Seaweed_Block"
    },
    {
      "x": 1,
      "y": 10,
      "z": 10,
      "name": "Soil_Clay_Green"
    },
    {
      "x": 1,
      "y": 11,
      "z": 10,
      "name": "Soil_Clay_Lime"
    },
    {
      "x": 1,
      "y": 12,
      "z": 10,
      "name": "Plant_Grass_Sharp"
    },
    {
      "x": 1,
      "y": 10,
      "z": 11,
      "name": "Soil_Clay_Green"
    },
    {
      "x": 1,
      "y": 11,
      "z": 11,
      "name": "Soil_Clay_Lime"
    },
    {
      "x": 1,
      "y": 12,
      "z": 11,
      "name": "Plant_Grass_Sharp"
    },
    {
      "x": 1,
      "y": 10,
      "z": 12,
      "name": "Soil_Clay_Green"
    },
    {
      "x": 1,
      "y": 11,
      "z": 12,
      "name": "Soil_Clay_Lime"
    },
    {
      "x": 2,
      "y": 17,
      "z": -11,
      "name": "Soil_Seaweed_Block"
    },
    {
      "x": 2,
      "y": 5,
      "z": -10,
      "name": "Soil_Clay_Green"
    },
    {
      "x": 2,
      "y": 6,
      "z": -10,
      "name": "Soil_Clay_Green"
    },
    {
      "x": 2,
      "y": 7,
      "z": -10,
      "name": "Soil_Seaweed_Block"
    },
    {
      "x": 2,
      "y": 14,
      "z": -10,
      "name": "Soil_Clay_Green"
    },
    {
      "x": 2,
      "y": 15,
      "z": -10,
      "name": "Soil_Clay_Green"
    },
    {
      "x": 2,
      "y": 16,
      "z": -10,
      "name": "Soil_Seaweed_Block"
    },
    {
      "x": 2,
      "y": 5,
      "z": -9,
      "name": "Soil_Clay_Green"
    },
    {
      "x": 2,
      "y": 6,
      "z": -9,
      "name": "Soil_Seaweed_Block"
    },
    {
      "x": 2,
      "y": 7,
      "z": -9,
      "name": "Soil_Seaweed_Block"
    },
    {
      "x": 2,
      "y": 8,
      "z": -9,
      "name": "Soil_Clay_Lime"
    },
    {
      "x": 2,
      "y": 10,
      "z": -9,
      "name": "Plant_Grass_Sharp"
    },
    {
      "x": 2,
      "y": 14,
      "z": -9,
      "name": "Soil_Clay_Green"
    },
    {
      "x": 2,
      "y": 15,
      "z": -9,
      "name": "Soil_Clay_Green"
    },
    {
      "x": 2,
      "y": 16,
      "z": -9,
      "name": "Soil_Seaweed_Block"
    },
    {
      "x": 2,
      "y": 4,
      "z": -8,
      "name": "Soil_Clay_Green"
    },
    {
      "x": 2,
      "y": 5,
      "z": -8,
      "name": "Soil_Seaweed_Block"
    },
    {
      "x": 2,
      "y": 6,
      "z": -8,
      "name": "Soil_Seaweed_Block"
    },
    {
      "x": 2,
      "y": 7,
      "z": -8,
      "name": "Soil_Seaweed_Block"
    },
    {
      "x": 2,
      "y": 8,
      "z": -8,
      "name": "Soil_Clay_Lime"
    },
    {
      "x": 2,
      "y": 9,
      "z": -8,
      "name": "Plant_Grass_Sharp"
    },
    {
      "x": 2,
      "y": 14,
      "z": -8,
      "name": "Soil_Clay_Green"
    },
    {
      "x": 2,
      "y": 15,
      "z": -8,
      "name": "Soil_Seaweed_Block"
    },
    {
      "x": 2,
      "y": 16,
      "z": -8,
      "name": "Soil_Seaweed_Block"
    },
    {
      "x": 2,
      "y": 17,
      "z": -8,
      "name": "Soil_Clay_Lime"
    },
    {
      "x": 2,
      "y": 18,
      "z": -8,
      "name": "Plant_Grass_Sharp"
    },
    {
      "x": 2,
      "y": 2,
      "z": -7,
      "name": "Soil_Clay_Green"
    },
    {
      "x": 2,
      "y": 3,
      "z": -7,
      "name": "Soil_Clay_Green"
    },
    {
      "x": 2,
      "y": 4,
      "z": -7,
      "name": "Soil_Seaweed_Block"
    },
    {
      "x": 2,
      "y": 5,
      "z": -7,
      "name": "Soil_Seaweed_Block"
    },
    {
      "x": 2,
      "y": 6,
      "z": -7,
      "name": "Soil_Seaweed_Block"
    },
    {
      "x": 2,
      "y": 7,
      "z": -7,
      "name": "Soil_Seaweed_Block"
    },
    {
      "x": 2,
      "y": 9,
      "z": -7,
      "name": "Plant_Grass_Sharp"
    },
    {
      "x": 2,
      "y": 15,
      "z": -7,
      "name": "Soil_Clay_Green"
    },
    {
      "x": 2,
      "y": 16,
      "z": -7,
      "name": "Soil_Seaweed_Block"
    },
    {
      "x": 2,
      "y": 18,
      "z": -7,
      "name": "Plant_Grass_Sharp"
    },
    {
      "x": 2,
      "y": 1,
      "z": -6,
      "name": "Soil_Clay_Green"
    },
    {
      "x": 2,
      "y": 2,
      "z": -6,
      "name": "Soil_Clay_Green"
    },
    {
      "x": 2,
      "y": 3,
      "z": -6,
      "name": "Soil_Clay_Green"
    },
    {
      "x": 2,
      "y": 4,
      "z": -6,
      "name": "Soil_Clay_Green"
    },
    {
      "x": 2,
      "y": 5,
      "z": -6,
      "name": "Soil_Clay_Green"
    },
    {
      "x": 2,
      "y": 6,
      "z": -6,
      "name": "Soil_Clay_Green"
    },
    {
      "x": 2,
      "y": 0,
      "z": -5,
      "name": "Soil_Clay_Green"
    },
    {
      "x": 2,
      "y": 1,
      "z": -5,
      "name": "Soil_Clay_Green"
    },
    {
      "x": 2,
      "y": 2,
      "z": -5,
      "name": "Soil_Clay_Green"
    },
    {
      "x": 2,
      "y": 3,
      "z": -5,
      "name": "Soil_Clay_Green"
    },
    {
      "x": 2,
      "y": 4,
      "z": -5,
      "name": "Soil_Clay_Green"
    },
    {
      "x": 2,
      "y": 22,
      "z": -2,
      "name": "Soil_Clay_Green"
    },
    {
      "x": 2,
      "y": 23,
      "z": -2,
      "name": "Soil_Seaweed_Block"
    },
    {
      "x": 2,
      "y": 22,
      "z": -1,
      "name": "Soil_Clay_Green"
    },
    {
      "x": 2,
      "y": 23,
      "z": -1,
      "name": "Soil_Seaweed_Block"
    },
    {
      "x": 2,
      "y": 22,
      "z": 0,
      "name": "Soil_Clay_Green"
    },
    {
      "x": 2,
      "y": 23,
      "z": 0,
      "name": "Soil_Seaweed_Block"
    },
    {
      "x": 2,
      "y": 24,
      "z": 0,
      "name": "Soil_Seaweed_Block"
    },
    {
      "x": 2,
      "y": 25,
      "z": 0,
      "name": "Soil_Clay_Lime"
    },
    {
      "x": 2,
      "y": 26,
      "z": 0,
      "name": "Plant_Grass_Sharp"
    },
    {
      "x": 2,
      "y": 23,
      "z": 1,
      "name": "Soil_Clay_Green"
    },
    {
      "x": 2,
      "y": 24,
      "z": 1,
      "name": "Soil_Seaweed_Block"
    },
    {
      "x": 2,
      "y": 25,
      "z": 1,
      "name": "Soil_Clay_Lime"
    },
    {
      "x": 2,
      "y": 26,
      "z": 1,
      "name": "Plant_Grass_Sharp"
    },
    {
      "x": 2,
      "y": 23,
      "z": 2,
