{
  "version": 8,
  "blockIdVersion": 10,
  "anchorX": 0,
  "anchorY": 13,
  "anchorZ": 0,
  "blocks": [
    {
      "x": -31,
      "y": 20,
      "z": 16,
      "name": "Soil_Seaweed_Block"
    },
    {
      "x": -31,
      "y": 20,
      "z": 17,
      "name": "Soil_Seaweed_Block"
    },
    {
      "x": -30,
      "y": 20,
      "z": 15,
      "name": "Soil_Clay_Green"
    },
    {
      "x": -30,
      "y": 19,
      "z": 16,
      "name": "Soil_Clay_Green"
    },
    {
      "x": -30,
      "y": 20,
      "z": 16,
      "name": "Soil_Seaweed_Block"
    },
    {
      "x": -30,
      "y": 21,
      "z": 16,
      "name": "Soil_Seaweed_Block"
    },
    {
      "x": -30,
      "y": 20,
      "z": 17,
      "name": "Soil_Seaweed_Block"
    },
    {
      "x": -29,
      "y": 21,
      "z": 13,
      "name": "Soil_Seaweed_Block"
    },
    {
      "x": -29,
      "y": 20,
      "z": 14,
      "name": "Soil_Clay_Green"
    },
    {
      "x": -29,
      "y": 21,
      "z": 14,
      "name": "Soil_Seaweed_Block"
    },
    {
      "x": -29,
      "y": 19,
      "z": 15,
      "name": "Soil_Clay_Green"
    },
    {
      "x": -29,
      "y": 20,
      "z": 15,
      "name": "Soil_Seaweed_Block"
    },
    {
      "x": -29,
      "y": 21,
      "z": 15,
      "name": "Soil_Seaweed_Block"
    },
    {
      "x": -29,
      "y": 20,
      "z": 16,
      "name": "Soil_Clay_Green"
    },
    {
      "x": -28,
      "y": 32,
      "z": 0,
      "name": "Soil_Clay_Green"
    },
    {
      "x": -28,
      "y": 33,
      "z": 0,
      "name": "Soil_Seaweed_Block"
    },
    {
      "x": -28,
      "y": 34,
      "z": 0,
      "name": "Soil_Seaweed_Block"
    },
    {
      "x": -28,
      "y": 32,
      "z": 1,
      "name": "Soil_Clay_Green"
    },
    {
      "x": -28,
      "y": 33,
      "z": 1,
      "name": "Soil_Seaweed_Block"
    },
    {
      "x": -28,
      "y": 34,
      "z": 1,
      "name": "Soil_Seaweed_Block"
    },
    {
      "x": -28,
      "y": 32,
      "z": 2,
      "name": "Soil_Clay_Green"
    },
    {
      "x": -28,
      "y": 33,
      "z": 2,
      "name": "Soil_Seaweed_Block"
    },
    {
      "x": -28,
      "y": 34,
      "z": 2,
      "name": "Soil_Seaweed_Block"
    },
    {
      "x": -28,
      "y": 21,
      "z": 12,
      "name": "Soil_Clay_Green"
    },
    {
      "x": -28,
      "y": 20,
      "z": 13,
      "name": "Soil_Clay_Green"
    },
    {
      "x": -28,
      "y": 21,
      "z": 13,
      "name": "Soil_Seaweed_Block"
    },
    {
      "x": -28,
      "y": 22,
      "z": 13,
      "name": "Soil_Clay_Lime"
    },
    {
      "x": -28,
      "y": 23,
      "z": 13,
      "name": "Plant_Grass_Sharp"
    },
    {
      "x": -28,
      "y": 19,
      "z": 14,
      "name": "Soil_Clay_Green"
    },
    {
      "x": -28,
      "y": 20,
      "z": 14,
      "name": "Soil_Seaweed_Block"
    },
    {
      "x": -28,
      "y": 21,
      "z": 14,
      "name": "Soil_Seaweed_Block"
    },
    {
      "x": -28,
      "y": 22,
      "z": 14,
      "name": "Soil_Clay_Lime"
    },
    {
      "x": -28,
      "y": 23,
      "z": 14,
      "name": "Plant_Grass_Sharp"
    },
    {
      "x": -28,
      "y": 20,
      "z": 15,
      "name": "Soil_Clay_Green"
    },
    {
      "x": -28,
      "y": 21,
      "z": 15,
      "name": "Soil_Seaweed_Block"
    },
    {
      "x": -27,
      "y": 32,
      "z": -1,
      "name": "Soil_Clay_Green"
    },
    {
      "x": -27,
      "y": 33,
      "z": -1,
      "name": "Soil_Seaweed_Block"
    },
    {
      "x": -27,
      "y": 34,
      "z": -1,
      "name": "Soil_Seaweed_Block"
    },
    {
      "x": -27,
      "y": 31,
      "z": 0,
      "name": "Soil_Clay_Green"
    },
    {
      "x": -27,
      "y": 32,
      "z": 0,
      "name": "Soil_Seaweed_Block"
    },
    {
      "x": -27,
      "y": 33,
      "z": 0,
      "name": "Soil_Seaweed_Block"
    },
    {
      "x": -27,
      "y": 34,
      "z": 0,
      "name": "Soil_Seaweed_Block"
    },
    {
      "x": -27,
      "y": 35,
      "z": 0,
      "name": "Soil_Clay_Lime"
    },
    {
      "x": -27,
      "y": 36,
      "z": 0,
      "name": "Plant_Grass_Sharp"
    },
    {
      "x": -27,
      "y": 31,
      "z": 1,
      "name": "Soil_Clay_Green"
    },
    {
      "x": -27,
      "y": 32,
      "z": 1,
      "name": "Soil_Seaweed_Block"
    },
    {
      "x": -27,
      "y": 33,
      "z": 1,
      "name": "Soil_Seaweed_Block"
    },
    {
      "x": -27,
      "y": 34,
      "z": 1,
      "name": "Soil_Seaweed_Block"
    },
    {
      "x": -27,
      "y": 35,
      "z": 1,
      "name": "Soil_Clay_Lime"
    },
    {
      "x": -27,
      "y": 36,
      "z": 1,
      "name": "Plant_Grass_Sharp"
    },
    {
      "x": -27,
      "y": 31,
      "z": 2,
      "name": "Soil_Clay_Green"
    },
    {
      "x": -27,
      "y": 32,
      "z": 2,
      "name": "Soil_Seaweed_Block"
    },
    {
      "x": -27,
      "y": 33,
      "z": 2,
      "name": "Soil_Seaweed_Block"
    },
    {
      "x": -27,
      "y": 34,
      "z": 2,
      "name": "Soil_Seaweed_Block"
    },
    {
      "x": -27,
      "y": 35,
      "z": 2,
      "name": "Soil_Seaweed_Block"
    },
    {
      "x": -27,
      "y": 32,
      "z": 3,
      "name": "Soil_Seaweed_Block"
    },
    {
      "x": -27,
      "y": 33,
      "z": 3,
      "name": "Soil_Seaweed_Block"
    },
    {
      "x": -27,
      "y": 34,
      "z": 3,
      "name": "Soil_Seaweed_Block"
    },
    {
      "x": -27,
      "y": 22,
      "z": 11,
      "name": "Soil_Seaweed_Block"
    },
    {
      "x": -27,
      "y": 20,
      "z": 12,
      "name": "Soil_Clay_Green"
    },
    {
      "x": -27,
      "y": 21,
      "z": 12,
      "name": "Soil_Clay_Green"
    },
    {
      "x": -27,
      "y": 22,
      "z": 12,
      "name": "Soil_Seaweed_Block"
    },
    {
      "x": -27,
      "y": 20,
      "z": 13,
      "name": "Soil_Clay_Green"
    },
    {
      "x": -27,
      "y": 21,
      "z": 13,
      "name": "Soil_Seaweed_Block"
    },
    {
      "x": -27,
      "y": 22,
      "z": 13,
      "name": "Soil_Seaweed_Block"
    },
    {
      "x": -27,
      "y": 23,
      "z": 13,
      "name": "Soil_Clay_Lime"
    },
    {
      "x": -27,
      "y": 24,
      "z": 13,
      "name": "Plant_Grass_Sharp"
    },
    {
      "x": -27,
      "y": 20,
      "z": 14,
      "name": "Soil_Clay_Green"
    },
    {
      "x": -27,
      "y": 21,
      "z": 14,
      "name": "Soil_Seaweed_Block"
    },
    {
      "x": -27,
      "y": 22,
      "z": 14,
      "name": "Soil_Clay_Lime"
    },
    {
      "x": -27,
      "y": 23,
      "z": 14,
      "name": "Plant_Grass_Sharp"
    },
    {
      "x": -27,
      "y": 21,
      "z": 15,
      "name": "Soil_Seaweed_Block"
    },
    {
      "x": -26,
      "y": 24,
      "z": -9,
      "name": "Soil_Seaweed_Block"
    },
    {
      "x": -26,
      "y": 23,
      "z": -8,
      "name": "Soil_Clay_Green"
    },
    {
      "x": -26,
      "y": 24,
      "z": -8,
      "name": "Soil_Seaweed_Block"
    },
    {
      "x": -26,
      "y": 25,
      "z": -8,
      "name": "Soil_Seaweed_Block"
    },
    {
      "x": -26,
      "y": 23,
      "z": -7,
      "name": "Soil_Clay_Green"
    },
    {
      "x": -26,
      "y": 24,
      "z": -7,
      "name": "Soil_Seaweed_Block"
    },
    {
      "x": -26,
      "y": 25,
      "z": -7,
      "name": "Soil_Seaweed_Block"
    },
    {
      "x": -26,
      "y": 26,
      "z": -7,
      "name": "Soil_Seaweed_Block"
    },
    {
      "x": -26,
      "y": 23,
      "z": -6,
      "name": "Soil_Clay_Green"
    },
    {
      "x": -26,
      "y": 24,
      "z": -6,
      "name": "Soil_Seaweed_Block"
    },
    {
      "x": -26,
      "y": 25,
      "z": -6,
      "name": "Soil_Seaweed_Block"
    },
    {
      "x": -26,
      "y": 31,
      "z": -4,
      "name": "Soil_Seaweed_Block"
    },
    {
      "x": -26,
      "y": 32,
      "z": -4,
      "name": "Soil_Seaweed_Block"
    },
    {
      "x": -26,
      "y": 31,
      "z": -3,
      "name": "Soil_Clay_Green"
    },
    {
      "x": -26,
      "y": 32,
      "z": -3,
      "name": "Soil_Seaweed_Block"
    },
    {
      "x": -26,
      "y": 31,
      "z": -2,
      "name": "Soil_Clay_Green"
    },
    {
      "x": -26,
      "y": 32,
      "z": -2,
      "name": "Soil_Seaweed_Block"
    },
    {
      "x": -26,
      "y": 33,
      "z": -2,
      "name": "Soil_Seaweed_Block"
    },
    {
      "x": -26,
      "y": 31,
      "z": -1,
      "name": "Soil_Clay_Green"
    },
    {
      "x": -26,
      "y": 32,
      "z": -1,
      "name": "Soil_Seaweed_Block"
    },
    {
      "x": -26,
      "y": 33,
      "z": -1,
      "name": "Soil_Seaweed_Block"
    },
    {
      "x": -26,
      "y": 34,
      "z": -1,
      "name": "Soil_Clay_Lime"
    },
    {
      "x": -26,
      "y": 35,
      "z": -1,
      "name": "Plant_Grass_Sharp"
    },
    {
      "x": -26,
      "y": 31,
      "z": 0,
      "name": "Soil_Clay_Green"
    },
    {
      "x": -26,
      "y": 32,
      "z": 0,
      "name": "Soil_Seaweed_Block"
    },
    {
      "x": -26,
      "y": 33,
      "z": 0,
      "name": "Soil_Seaweed_Block"
    },
    {
      "x": -26,
      "y": 34,
      "z": 0,
      "name": "Soil_Seaweed_Block"
    },
    {
      "x": -26,
      "y": 35,
      "z": 0,
      "name": "Soil_Clay_Lime"
    },
    {
      "x": -26,
      "y": 36,
      "z": 0,
      "name": "Plant_Grass_Sharp"
    },
    {
      "x": -26,
      "y": 31,
      "z": 1,
      "name": "Soil_Clay_Green"
    },
    {
      "x": -26,
      "y": 32,
      "z": 1,
      "name": "Soil_Seaweed_Block"
    },
    {
      "x": -26,
      "y": 33,
      "z": 1,
      "name": "Soil_Seaweed_Block"
    },
    {
      "x": -26,
      "y": 34,
      "z": 1,
      "name": "Soil_Seaweed_Block"
    },
    {
      "x": -26,
      "y": 35,
      "z": 1,
      "name": "Soil_Seaweed_Block"
    },
    {
      "x": -26,
      "y": 36,
      "z": 1,
      "name": "Soil_Clay_Lime"
    },
    {
      "x": -26,
      "y": 37,
      "z": 1,
      "name": "Plant_Grass_Sharp"
    },
    {
      "x": -26,
      "y": 31,
      "z": 2,
      "name": "Soil_Clay_Green"
    },
    {
      "x": -26,
      "y": 32,
      "z": 2,
      "name": "Soil_Seaweed_Block"
    },
    {
      "x": -26,
      "y": 33,
      "z": 2,
      "name": "Soil_Seaweed_Block"
    },
    {
      "x": -26,
      "y": 34,
      "z": 2,
      "name": "Soil_Seaweed_Block"
    },
    {
      "x": -26,
      "y": 35,
      "z": 2,
      "name": "Soil_Seaweed_Block"
    },
    {
      "x": -26,
      "y": 36,
      "z": 2,
      "name": "Soil_Clay_Lime"
    },
    {
      "x": -26,
      "y": 37,
      "z": 2,
      "name": "Plant_Grass_Sharp"
    },
    {
      "x": -26,
      "y": 30,
      "z": 3,
      "name": "Soil_Clay_Green"
    },
    {
      "x": -26,
      "y": 31,
      "z": 3,
      "name": "Soil_Clay_Green"
    },
    {
      "x": -26,
      "y": 32,
      "z": 3,
      "name": "Soil_Seaweed_Block"
    },
    {
      "x": -26,
      "y": 33,
      "z": 3,
      "name": "Soil_Seaweed_Block"
    },
    {
      "x": -26,
      "y": 34,
      "z": 3,
      "name": "Soil_Seaweed_Block"
    },
    {
      "x": -26,
      "y": 35,
      "z": 3,
      "name": "Soil_Seaweed_Block"
    },
    {
      "x": -26,
      "y": 36,
      "z": 3,
      "name": "Soil_Seaweed_Block"
    },
    {
      "x": -26,
      "y": 31,
      "z": 4,
      "name": "Soil_Seaweed_Block"
    },
    {
      "x": -26,
      "y": 44,
      "z": 5,
      "name": "Soil_Seaweed_Block"
    },
    {
      "x": -26,
      "y": 43,
      "z": 6,
      "name": "Soil_Clay_Green"
    },
    {
      "x": -26,
      "y": 44,
      "z": 6,
      "name": "Soil_Seaweed_Block"
    },
    {
      "x": -26,
      "y": 45,
      "z": 6,
      "name": "Soil_Seaweed_Block"
    },
    {
      "x": -26,
      "y": 43,
      "z": 7,
      "name": "Soil_Clay_Green"
    },
    {
      "x": -26,
      "y": 44,
      "z": 7,
      "name": "Soil_Seaweed_Block"
    },
    {
      "x": -26,
      "y": 45,
      "z": 7,
      "name": "Soil_Seaweed_Block"
    },
    {
      "x": -26,
      "y": 23,
      "z": 10,
      "name": "Soil_Seaweed_Block"
    },
    {
      "x": -26,
      "y": 24,
      "z": 10,
      "name": "Soil_Seaweed_Block"
    },
    {
      "x": -26,
      "y": 22,
      "z": 11,
      "name": "Soil_Clay_Green"
    },
    {
      "x": -26,
      "y": 23,
      "z": 11,
      "name": "Soil_Seaweed_Block"
    },
    {
      "x": -26,
      "y": 24,
      "z": 11,
      "name": "Soil_Seaweed_Block"
    },
    {
      "x": -26,
      "y": 21,
      "z": 12,
      "name": "Soil_Clay_Green"
    },
    {
      "x": -26,
      "y": 22,
      "z": 12,
      "name": "Soil_Seaweed_Block"
    },
    {
      "x": -26,
      "y": 23,
      "z": 12,
      "name": "Soil_Clay_Lime"
    },
    {
      "x": -26,
      "y": 24,
      "z": 12,
      "name": "Plant_Grass_Sharp"
    },
    {
      "x": -26,
      "y": 20,
      "z": 13,
      "name": "Soil_Clay_Green"
    },
    {
      "x": -26,
      "y": 21,
      "z": 13,
      "name": "Soil_Seaweed_Block"
    },
    {
      "x": -26,
      "y": 22,
      "z": 13,
      "name": "Soil_Seaweed_Block"
    },
    {
      "x": -26,
      "y": 23,
      "z": 13,
      "name": "Soil_Clay_Lime"
    },
    {
      "x": -26,
      "y": 24,
      "z": 13,
      "name": "Plant_Grass_Sharp"
    },
    {
      "x": -26,
      "y": 21,
      "z": 14,
      "name": "Soil_Clay_Green"
    },
    {
      "x": -26,
      "y": 22,
      "z": 14,
      "name": "Soil_Seaweed_Block"
    },
    {
      "x": -25,
      "y": 30,
      "z": -16,
      "name": "Soil_Seaweed_Block"
    },
    {
      "x": -25,
      "y": 29,
      "z": -15,
      "name": "Soil_Clay_Green"
    },
    {
      "x": -25,
      "y": 30,
      "z": -15,
      "name": "Soil_Seaweed_Block"
    },
    {
      "x": -25,
      "y": 31,
      "z": -15,
      "name": "Soil_Seaweed_Block"
    },
    {
      "x": -25,
      "y": 36,
      "z": -15,
      "name": "Soil_Seaweed_Block"
    },
    {
      "x": -25,
      "y": 37,
      "z": -15,
      "name": "Soil_Seaweed_Block"
    },
    {
      "x": -25,
      "y": 29,
      "z": -14,
      "name": "Soil_Clay_Green"
    },
    {
      "x": -25,
      "y": 30,
      "z": -14,
      "name": "Soil_Seaweed_Block"
    },
    {
      "x": -25,
      "y": 31,
      "z": -14,
      "name": "Soil_Seaweed_Block"
    },
    {
      "x": -25,
      "y": 36,
      "z": -14,
      "name": "Soil_Seaweed_Block"
    },
    {
      "x": -25,
      "y": 37,
      "z": -14,
      "name": "Soil_Seaweed_Block"
    },
    {
      "x": -25,
      "y": 38,
      "z": -14,
      "name": "Soil_Seaweed_Block"
    },
    {
      "x": -25,
      "y": 30,
      "z": -13,
      "name": "Soil_Seaweed_Block"
    },
    {
      "x": -25,
      "y": 31,
      "z": -13,
      "name": "Soil_Seaweed_Block"
    },
    {
      "x": -25,
      "y": 36,
      "z": -13,
      "name": "Soil_Seaweed_Block"
    },
    {
      "x": -25,
      "y": 37,
      "z": -13,
      "name": "Soil_Seaweed_Block"
    },
    {
      "x": -25,
      "y": 38,
      "z": -13,
      "name": "Soil_Seaweed_Block"
    },
    {
      "x": -25,
      "y": 37,
      "z": -12,
      "name": "Soil_Seaweed_Block"
    },
    {
      "x": -25,
      "y": 43,
      "z": -11,
      "name": "Soil_Seaweed_Block"
    },
    {
      "x": -25,
      "y": 24,
      "z": -10,
      "name": "Soil_Clay_Green"
    },
    {
      "x": -25,
      "y": 25,
      "z": -10,
      "name": "Soil_Seaweed_Block"
    },
    {
      "x": -25,
      "y": 23,
      "z": -9,
      "name": "Soil_Clay_Green"
    },
    {
      "x": -25,
      "y": 24,
      "z": -9,
      "name": "Soil_Seaweed_Block"
    },
    {
      "x": -25,
      "y": 25,
      "z": -9,
      "name": "Soil_Seaweed_Block"
    },
    {
      "x": -25,
      "y": 26,
      "z": -9,
      "name": "Soil_Seaweed_Block"
    },
    {
      "x": -25,
      "y": 27,
      "z": -9,
      "name": "Soil_Seaweed_Block"
    },
    {
      "x": -25,
      "y": 28,
      "z": -9,
      "name": "Soil_Seaweed_Block"
    },
    {
      "x": -25,
      "y": 29,
      "z": -9,
      "name": "Soil_Seaweed_Block"
    },
    {
      "x": -25,
      "y": 30,
      "z": -9,
      "name": "Soil_Seaweed_Block"
    },
    {
      "x": -25,
      "y": 31,
      "z": -9,
      "name": "Soil_Seaweed_Block"
    },
    {
      "x": -25,
      "y": 32,
      "z": -9,
      "name": "Soil_Seaweed_Block"
    },
    {
      "x": -25,
      "y": 23,
      "z": -8,
      "name": "Soil_Clay_Green"
    },
    {
      "x": -25,
      "y": 24,
      "z": -8,
      "name": "Soil_Seaweed_Block"
    },
    {
      "x": -25,
      "y": 25,
      "z": -8,
      "name": "Soil_Seaweed_Block"
    },
    {
      "x": -25,
      "y": 26,
      "z": -8,
      "name": "Soil_Seaweed_Block"
    },
    {
      "x": -25,
      "y": 27,
      "z": -8,
      "name": "Soil_Seaweed_Block"
    },
    {
      "x": -25,
      "y": 28,
      "z": -8,
      "name": "Soil_Seaweed_Block"
    },
    {
      "x": -25,
      "y": 29,
      "z": -8,
      "name": "Soil_Seaweed_Block"
    },
    {
      "x": -25,
      "y": 30,
      "z": -8,
      "name": "Soil_Seaweed_Block"
    },
    {
      "x": -25,
      "y": 31,
      "z": -8,
      "name": "Soil_Seaweed_Block"
    },
    {
      "x": -25,
      "y": 32,
      "z": -8,
      "name": "Soil_Seaweed_Block"
    },
    {
      "x": -25,
      "y": 22,
      "z": -7,
      "name": "Soil_Clay_Green"
    },
    {
      "x": -25,
      "y": 23,
      "z": -7,
      "name": "Soil_Seaweed_Block"
    },
    {
      "x": -25,
      "y": 24,
      "z": -7,
      "name": "Soil_Seaweed_Block"
    },
    {
      "x": -25,
      "y": 25,
      "z": -7,
      "name": "Soil_Seaweed_Block"
    },
    {
      "x": -25,
      "y": 26,
      "z": -7,
      "name": "Soil_Seaweed_Block"
    },
    {
      "x": -25,
      "y": 27,
      "z": -7,
      "name": "Soil_Seaweed_Block"
    },
    {
      "x": -25,
      "y": 28,
      "z": -7,
      "name": "Soil_Seaweed_Block"
    },
    {
      "x": -25,
      "y": 29,
      "z": -7,
      "name": "Soil_Seaweed_Block"
    },
    {
      "x": -25,
      "y": 30,
      "z": -7,
      "name": "Soil_Seaweed_Block"
    },
    {
      "x": -25,
      "y": 31,
      "z": -7,
      "name": "Soil_Seaweed_Block"
    },
    {
      "x": -25,
      "y": 22,
      "z": -6,
      "name": "Soil_Clay_Green"
    },
    {
      "x": -25,
      "y": 23,
      "z": -6,
      "name": "Soil_Seaweed_Block"
    },
    {
      "x": -25,
      "y": 24,
      "z": -6,
      "name": "Soil_Seaweed_Block"
    },
    {
      "x": -25,
      "y": 25,
      "z": -6,
      "name": "Soil_Seaweed_Block"
    },
    {
      "x": -25,
      "y": 26,
      "z": -6,
      "name": "Soil_Seaweed_Block"
    },
    {
      "x": -25,
      "y": 27,
      "z": -6,
      "name": "Soil_Seaweed_Block"
    },
    {
      "x": -25,
      "y": 28,
      "z": -6,
      "name": "Soil_Seaweed_Block"
    },
    {
      "x": -25,
      "y": 29,
      "z": -6,
      "name": "Soil_Seaweed_Block"
    },
    {
      "x": -25,
      "y": 30,
      "z": -6,
      "name": "Soil_Seaweed_Block"
    },
    {
      "x": -25,
      "y": 31,
      "z": -6,
      "name": "Soil_Seaweed_Block"
    },
    {
      "x": -25,
      "y": 23,
      "z": -5,
      "name": "Soil_Clay_Green"
    },
    {
      "x": -25,
      "y": 24,
      "z": -5,
      "name": "Soil_Seaweed_Block"
    },
    {
      "x": -25,
      "y": 25,
      "z": -5,
      "name": "Soil_Seaweed_Block"
    },
    {
      "x": -25,
      "y": 29,
      "z": -5,
      "name": "Soil_Clay_Green"
    },
    {
      "x": -25,
      "y": 30,
      "z": -5,
      "name": "Soil_Clay_Green"
    },
    {
      "x": -25,
      "y": 31,
      "z": -5,
      "name": "Soil_Seaweed_Block"
    },
    {
      "x": -25,
      "y": 32,
      "z": -5,
      "name": "Soil_Clay_Lime"
    },
    {
      "x": -25,
      "y": 33,
      "z": -5,
      "name": "Plant_Grass_Sharp"
    },
    {
      "x": -25,
      "y": 13,
      "z": -4,
      "name": "Soil_Clay_Green"
    },
    {
      "x": -25,
      "y": 14,
      "z": -4,
      "name": "Soil_Seaweed_Block"
    },
    {
      "x": -25,
      "y": 15,
      "z": -4,
      "name": "Soil_Seaweed_Block"
    },
    {
      "x": -25,
      "y": 30,
      "z": -4,
      "name": "Soil_Clay_Green"
    },
    {
      "x": -25,
      "y": 31,
      "z": -4,
      "name": "Soil_Seaweed_Block"
    },
    {
      "x": -25,
      "y": 32,
      "z": -4,
      "name": "Soil_Clay_Lime"
    },
    {
      "x": -25,
      "y": 33,
      "z": -4,
      "name": "Plant_Grass_Sharp"
    },
    {
      "x": -25,
      "y": 13,
      "z": -3,
      "name": "Soil_Clay_Green"
    },
    {
      "x": -25,
      "y": 14,
      "z": -3,
      "name": "Soil_Clay_Green"
    },
    {
      "x": -25,
      "y": 15,
      "z": -3,
      "name": "Soil_Seaweed_Block"
    },
    {
      "x": -25,
      "y": 16,
      "z": -3,
      "name": "Soil_Seaweed_Block"
    },
    {
      "x": -25,
      "y": 30,
      "z": -3,
      "name": "Soil_Clay_Green"
    },
    {
      "x": -25,
      "y": 31,
      "z": -3,
      "name": "Soil_Seaweed_Block"
    },
    {
      "x": -25,
      "y": 32,
      "z": -3,
      "name": "Soil_Seaweed_Block"
    },
    {
      "x": -25,
      "y": 33,
      "z": -3,
      "name": "Soil_Clay_Lime"
    },
    {
      "x": -25,
      "y": 34,
      "z": -3,
      "name": "Plant_Grass_Sharp"
    },
    {
      "x": -25,
      "y": 13,
      "z": -2,
      "name": "Soil_Clay_Green"
    },
    {
      "x": -25,
      "y": 14,
      "z": -2,
      "name": "Soil_Seaweed_Block"
    },
    {
      "x": -25,
      "y": 15,
      "z": -2,
      "name": "Soil_Seaweed_Block"
    },
    {
      "x": -25,
      "y": 31,
      "z": -2,
      "name": "Soil_Clay_Green"
    },
    {
      "x": -25,
      "y": 32,
      "z": -2,
      "name": "Soil_Seaweed_Block"
    },
    {
      "x": -25,
      "y": 33,
      "z": -2,
      "name": "Soil_Clay_Lime"
    },
    {
      "x": -25,
      "y": 34,
      "z": -2,
      "name": "Plant_Grass_Sharp"
    },
    {
      "x": -25,
      "y": 31,
      "z": -1,
      "name": "Soil_Clay_Green"
    },
    {
      "x": -25,
      "y": 32,
      "z": -1,
      "name": "Soil_Seaweed_Block"
    },
    {
      "x": -25,
      "y": 33,
      "z": -1,
      "name": "Soil_Seaweed_Block"
    },
    {
      "x": -25,
      "y": 34,
      "z": -1,
      "name": "Soil_Clay_Lime"
    },
    {
      "x": -25,
      "y": 35,
      "z": -1,
      "name": "Plant_Grass_Sharp"
    },
    {
      "x": -25,
      "y": 31,
      "z": 0,
      "name": "Soil_Clay_Green"
    },
    {
      "x": -25,
      "y": 32,
      "z": 0,
      "name": "Soil_Seaweed_Block"
    },
    {
      "x": -25,
      "y": 33,
      "z": 0,
      "name": "Soil_Seaweed_Block"
    },
    {
      "x": -25,
      "y": 34,
      "z": 0,
      "name": "Soil_Seaweed_Block"
    },
    {
      "x": -25,
      "y": 35,
      "z": 0,
      "name": "Soil_Clay_Lime"
    },
    {
      "x": -25,
      "y": 36,
      "z": 0,
      "name": "Plant_Grass_Sharp"
    },
    {
      "x": -25,
      "y": 31,
      "z": 1,
      "name": "Soil_Clay_Green"
    },
    {
      "x": -25,
      "y": 32,
      "z": 1,
      "name": "Soil_Seaweed_Block"
    },
    {
      "x": -25,
      "y": 33,
      "z": 1,
      "name": "Soil_Seaweed_Block"
    },
    {
      "x": -25,
      "y": 34,
      "z": 1,
      "name": "Soil_Seaweed_Block"
    },
    {
      "x": -25,
      "y": 35,
      "z": 1,
      "name": "Soil_Seaweed_Block"
    },
    {
      "x": -25,
      "y": 36,
      "z": 1,
      "name": "Soil_Clay_Lime"
    },
    {
      "x": -25,
      "y": 37,
      "z": 1,
      "name": "Plant_Grass_Sharp"
    },
    {
      "x": -25,
      "y": 30,
      "z": 2,
      "name": "Soil_Clay_Green"
    },
    {
      "x": -25,
      "y": 31,
      "z": 2,
      "name": "Soil_Seaweed_Block"
    },
    {
      "x": -25,
      "y": 32,
      "z": 2,
      "name": "Soil_Seaweed_Block"
    },
    {
      "x": -25,
      "y": 33,
      "z": 2,
      "name": "Soil_Seaweed_Block"
    },
    {
      "x": -25,
      "y": 34,
      "z": 2,
      "name": "Soil_Seaweed_Block"
    },
    {
      "x": -25,
      "y": 35,
      "z": 2,
      "name": "Soil_Seaweed_Block"
    },
    {
      "x": -25,
      "y": 36,
      "z": 2,
      "name": "Soil_Seaweed_Block"
    },
    {
      "x": -25,
      "y": 37,
      "z": 2,
      "name": "Soil_Seaweed_Block"
    },
    {
      "x": -25,
      "y": 30,
      "z": 3,
      "name": "Soil_Clay_Green"
    },
    {
      "x": -25,
      "y": 31,
      "z": 3,
      "name": "Soil_Seaweed_Block"
    },
    {
      "x": -25,
      "y": 32,
      "z": 3,
      "name": "Soil_Seaweed_Block"
    },
    {
      "x": -25,
      "y": 33,
      "z": 3,
      "name": "Soil_Seaweed_Block"
    },
    {
      "x": -25,
      "y": 34,
      "z": 3,
      "name": "Soil_Seaweed_Block"
    },
    {
      "x": -25,
      "y": 35,
      "z": 3,
      "name": "Soil_Seaweed_Block"
    },
    {
      "x": -25,
      "y": 36,
      "z": 3,
      "name": "Soil_Seaweed_Block"
    },
    {
      "x": -25,
      "y": 37,
      "z": 3,
      "name": "Soil_Seaweed_Block"
    },
    {
      "x": -25,
      "y": 38,
      "z": 3,
      "name": "Soil_Seaweed_Block"
    },
    {
      "x": -25,
      "y": 39,
      "z": 3,
      "name": "Soil_Seaweed_Block"
    },
    {
      "x": -25,
      "y": 29,
      "z": 4,
      "name": "Soil_Clay_Green"
    },
    {
      "x": -25,
      "y": 30,
      "z": 4,
      "name": "Soil_Clay_Green"
    },
    {
      "x": -25,
      "y": 31,
      "z": 4,
      "name": "Soil_Seaweed_Block"
    },
    {
      "x": -25,
      "y": 32,
      "z": 4,
      "name": "Soil_Seaweed_Block"
    },
    {
      "x": -25,
      "y": 36,
      "z": 4,
      "name": "Soil_Seaweed_Block"
    },
    {
      "x": -25,
      "y": 37,
      "z": 4,
      "name": "Soil_Seaweed_Block"
    },
    {
      "x": -25,
      "y": 38,
      "z": 4,
      "name": "Soil_Seaweed_Block"
    },
    {
      "x": -25,
      "y": 39,
      "z": 4,
      "name": "Soil_Seaweed_Block"
    },
    {
      "x": -25,
      "y": 42,
      "z": 4,
      "name": "Soil_Clay_Green"
    },
    {
      "x": -25,
      "y": 43,
      "z": 4,
      "name": "Soil_Seaweed_Block"
    },
    {
      "x": -25,
      "y": 44,
      "z": 4,
      "name": "Soil_Seaweed_Block"
    },
    {
      "x": -25,
      "y": 29,
      "z": 5,
      "name": "Soil_Clay_Green"
    },
    {
      "x": -25,
      "y": 30,
      "z": 5,
      "name": "Soil_Seaweed_Block"
    },
    {
      "x": -25,
      "y": 31,
      "z": 5,
      "name": "Soil_Clay_Lime"
    },
    {
      "x": -25,
      "y": 32,
      "z": 5,
      "name": "Plant_Grass_Sharp"
    },
    {
      "x": -25,
      "y": 42,
      "z": 5,
      "name": "Soil_Clay_Green"
    },
    {
      "x": -25,
      "y": 43,
      "z": 5,
      "name": "Soil_Seaweed_Block"
    },
    {
      "x": -25,
      "y": 44,
      "z": 5,
      "name": "Soil_Seaweed_Block"
    },
    {
      "x": -25,
      "y": 45,
      "z": 5,
      "name": "Soil_Seaweed_Block"
    },
    {
      "x": -25,
      "y": 28,
      "z": 6,
      "name": "Soil_Clay_Green"
    },
    {
      "x": -25,
      "y": 29,
      "z": 6,
      "name": "Soil_Seaweed_Block"
    },
    {
      "x": -25,
      "y": 30,
      "z": 6,
      "name": "Soil_Seaweed_Block"
    },
    {
      "x": -25,
      "y": 42,
      "z": 6,
      "name": "Soil_Clay_Green"
    },
    {
      "x": -25,
      "y": 43,
      "z": 6,
      "name": "Soil_Seaweed_Block"
    },
    {
      "x": -25,
      "y": 44,
      "z": 6,
      "name": "Soil_Seaweed_Block"
    },
    {
      "x": -25,
      "y": 45,
      "z": 6,
      "name": "Soil_Seaweed_Block"
    },
    {
      "x": -25,
      "y": 46,
      "z": 6,
      "name": "Soil_Clay_Lime"
    },
    {
      "x": -25,
      "y": 47,
      "z": 6,
      "name": "Plant_Grass_Sharp"
    },
    {
      "x": -25,
      "y": 28,
      "z": 7,
      "name": "Soil_Clay_Green"
    },
    {
      "x": -25,
      "y": 29,
      "z": 7,
      "name": "Soil_Seaweed_Block"
    },
    {
      "x": -25,
      "y": 30,
      "z": 7,
      "name": "Soil_Seaweed_Block"
    },
    {
      "x": -25,
      "y": 42,
      "z": 7,
      "name": "Soil_Clay_Green"
    },
    {
      "x": -25,
      "y": 43,
      "z": 7,
      "name": "Soil_Seaweed_Block"
    },
    {
      "x": -25,
      "y": 44,
      "z": 7,
      "name": "Soil_Seaweed_Block"
    },
    {
      "x": -25,
      "y": 45,
      "z": 7,
      "name": "Soil_Seaweed_Block"
    },
    {
      "x": -25,
      "y": 46,
      "z": 7,
      "name": "Soil_Clay_Lime"
    },
    {
      "x": -25,
      "y": 47,
      "z": 7,
      "name": "Plant_Grass_Sharp"
    },
    {
      "x": -25,
      "y": 25,
      "z": 8,
      "name": "Soil_Seaweed_Block"
    },
    {
      "x": -25,
      "y": 44,
      "z": 8,
      "name": "Soil_Seaweed_Block"
    },
    {
      "x": -25,
      "y": 23,
      "z": 9,
      "name": "Soil_Clay_Green"
    },
    {
      "x": -25,
      "y": 24,
      "z": 9,
      "name": "Soil_Seaweed_Block"
    },
    {
      "x": -25,
      "y": 25,
      "z": 9,
      "name": "Soil_Seaweed_Block"
    },
    {
      "x": -25,
      "y": 26,
      "z": 9,
      "name": "Soil_Seaweed_Block"
    },
    {
      "x": -25,
      "y": 22,
      "z": 10,
      "name": "Soil_Clay_Green"
    },
    {
      "x": -25,
      "y": 23,
      "z": 10,
      "name": "Soil_Seaweed_Block"
    },
    {
      "x": -25,
      "y": 24,
      "z": 10,
      "name": "Soil_Seaweed_Block"
    },
    {
      "x": -25,
      "y": 25,
      "z": 10,
      "name": "Soil_Seaweed_Block"
    },
    {
      "x": -25,
      "y": 26,
      "z": 10,
      "name": "Soil_Seaweed_Block"
    },
    {
      "x": -25,
      "y": 21,
      "z": 11,
      "name": "Soil_Clay_Green"
    },
    {
      "x": -25,
      "y": 22,
      "z": 11,
      "name": "Soil_Seaweed_Block"
    },
    {
      "x": -25,
      "y": 23,
      "z": 11,
      "name": "Soil_Seaweed_Block"
    },
    {
      "x": -25,
      "y": 24,
      "z": 11,
      "name": "Soil_Seaweed_Block"
    },
    {
      "x": -25,
      "y": 25,
      "z": 11,
      "name": "Soil_Seaweed_Block"
    },
    {
      "x": -25,
      "y": 21,
      "z": 12,
      "name": "Soil_Clay_Green"
    },
    {
      "x": -25,
      "y": 22,
      "z": 12,
      "name": "Soil_Seaweed_Block"
    },
    {
      "x": -25,
      "y": 23,
      "z": 12,
      "name": "Soil_Seaweed_Block"
    },
    {
      "x": -25,
      "y": 24,
      "z": 12,
      "name": "Soil_Seaweed_Block"
    },
    {
      "x": -25,
      "y": 21,
      "z": 13,
      "name": "Soil_Clay_Green"
    },
    {
      "x": -25,
      "y": 22,
      "z": 13,
      "name": "Soil_Seaweed_Block"
    },
    {
      "x": -25,
      "y": 23,
      "z": 13,
      "name": "Soil_Seaweed_Block"
    },
    {
      "x": -24,
      "y": 29,
      "z": -16,
      "name": "Soil_Clay_Green"
    },
    {
      "x": -24,
      "y": 30,
      "z": -16,
      "name": "Soil_Seaweed_Block"
    },
    {
      "x": -24,
      "y": 31,
      "z": -16,
      "name": "Soil_Seaweed_Block"
    },
    {
      "x": -24,
      "y": 28,
      "z": -15,
      "name": "Soil_Clay_Green"
    },
    {
      "x": -24,
      "y": 29,
      "z": -15,
      "name": "Soil_Seaweed_Block"
    },
    {
      "x": -24,
      "y": 30,
      "z": -15,
      "name": "Soil_Seaweed_Block"
    },
    {
      "x": -24,
      "y": 31,
      "z": -15,
      "name": "Soil_Seaweed_Block"
    },
    {
      "x": -24,
      "y": 32,
      "z": -15,
      "name": "Soil_Seaweed_Block"
    },
    {
      "x": -24,
      "y": 36,
      "z": -15,
      "name": "Soil_Clay_Green"
    },
    {
      "x": -24,
      "y": 37,
      "z": -15,
      "name": "Soil_Seaweed_Block"
    },
    {
      "x": -24,
      "y": 38,
      "z": -15,
      "name": "Soil_Seaweed_Block"
    },
    {
      "x": -24,
      "y": 28,
      "z": -14,
      "name": "Soil_Clay_Green"
    },
    {
      "x": -24,
      "y": 29,
      "z": -14,
      "name": "Soil_Seaweed_Block"
    },
    {
      "x": -24,
      "y": 30,
      "z": -14,
      "name": "Soil_Seaweed_Block"
    },
    {
      "x": -24,
      "y": 31,
      "z": -14,
      "name": "Soil_Seaweed_Block"
    },
    {
      "x": -24,
      "y": 32,
      "z": -14,
      "name": "Soil_Seaweed_Block"
    },
    {
      "x": -24,
      "y": 33,
      "z": -14,
      "name": "Soil_Seaweed_Block"
    },
    {
      "x": -24,
      "y": 34,
      "z": -14,
      "name": "Soil_Seaweed_Block"
    },
    {
      "x": -24,
      "y": 35,
      "z": -14,
      "name": "Soil_Clay_Green"
    },
    {
      "x": -24,
      "y": 36,
      "z": -14,
      "name": "Soil_Seaweed_Block"
    },
    {
      "x": -24,
      "y": 37,
      "z": -14,
      "name": "Soil_Seaweed_Block"
    },
    {
      "x": -24,
      "y": 38,
      "z": -14,
      "name": "Soil_Seaweed_Block"
    },
    {
      "x": -24,
      "y": 39,
      "z": -14,
      "name": "Soil_Seaweed_Block"
    },
    {
      "x": -24,
      "y": 29,
      "z": -13,
      "name": "Soil_Clay_Green"
    },
    {
      "x": -24,
      "y": 30,
      "z": -13,
      "name": "Soil_Seaweed_Block"
    },
    {
      "x": -24,
      "y": 31,
      "z": -13,
      "name": "Soil_Seaweed_Block"
    },
    {
      "x": -24,
      "y": 32,
      "z": -13,
      "name": "Soil_Seaweed_Block"
    },
    {
      "x": -24,
      "y": 33,
      "z": -13,
      "name": "Soil_Seaweed_Block"
    },
    {
      "x": -24,
      "y": 34,
      "z": -13,
      "name": "Soil_Seaweed_Block"
    },
    {
      "x": -24,
      "y": 35,
      "z": -13,
      "name": "Soil_Clay_Green"
    },
    {
      "x": -24,
      "y": 36,
      "z": -13,
      "name": "Soil_Seaweed_Block"
    },
    {
      "x": -24,
      "y": 37,
      "z": -13,
      "name": "Soil_Seaweed_Block"
    },
    {
      "x": -24,
      "y": 38,
      "z": -13,
      "name": "Soil_Seaweed_Block"
    },
    {
      "x": -24,
      "y": 39,
      "z": -13,
      "name": "Soil_Seaweed_Block"
    },
    {
      "x": -24,
      "y": 43,
      "z": -13,
      "name": "Soil_Seaweed_Block"
    },
    {
      "x": -24,
      "y": 28,
      "z": -12,
      "name": "Soil_Clay_Green"
    },
    {
      "x": -24,
      "y": 29,
      "z": -12,
      "name": "Soil_Clay_Green"
    },
    {
      "x": -24,
      "y": 30,
      "z": -12,
      "name": "Soil_Seaweed_Block"
    },
    {
      "x": -24,
      "y": 31,
      "z": -12,
      "name": "Soil_Seaweed_Block"
    },
    {
      "x": -24,
      "y": 32,
      "z": -12,
      "name": "Soil_Seaweed_Block"
    },
    {
      "x": -24,
      "y": 33,
      "z": -12,
      "name": "Soil_Seaweed_Block"
    },
    {
      "x": -24,
      "y": 34,
      "z": -12,
      "name": "Soil_Seaweed_Block"
    },
    {
      "x": -24,
      "y": 35,
      "z": -12,
      "name": "Soil_Seaweed_Block"
    },
    {
      "x": -24,
      "y": 36,
      "z": -12,
      "name": "Soil_Seaweed_Block"
    },
    {
      "x": -24,
      "y": 37,
      "z": -12,
      "name": "Soil_Seaweed_Block"
    },
    {
      "x": -24,
      "y": 38,
      "z": -12,
      "name": "Soil_Seaweed_Block"
    },
    {
      "x": -24,
      "y": 39,
      "z": -12,
      "name": "Soil_Seaweed_Block"
    },
    {
      "x": -24,
      "y": 42,
      "z": -12,
      "name": "Soil_Seaweed_Block"
    },
    {
      "x": -24,
      "y": 43,
      "z": -12,
      "name": "Soil_Seaweed_Block"
    },
    {
      "x": -24,
      "y": 44,
      "z": -12,
      "name": "Soil_Seaweed_Block"
    },
    {
      "x": -24,
      "y": 28,
      "z": -11,
      "name": "Soil_Clay_Green"
    },
    {
      "x": -24,
      "y": 29,
      "z": -11,
      "name": "Soil_Seaweed_Block"
    },
    {
      "x": -24,
      "y": 30,
      "z": -11,
      "name": "Soil_Seaweed_Block"
    },
    {
      "x": -24,
      "y": 31,
      "z": -11,
      "name": "Soil_Seaweed_Block"
    },
    {
      "x": -24,
      "y": 32,
      "z": -11,
      "name": "Soil_Seaweed_Block"
    },
    {
      "x": -24,
      "y": 33,
      "z": -11,
      "name": "Soil_Seaweed_Block"
    },
    {
      "x": -24,
      "y": 34,
      "z": -11,
      "name": "Soil_Seaweed_Block"
    },
    {
      "x": -24,
      "y": 35,
      "z": -11,
      "name": "Soil_Seaweed_Block"
    },
    {
      "x": -24,
      "y": 36,
      "z": -11,
      "name": "Soil_Seaweed_Block"
    },
    {
      "x": -24,
      "y": 37,
      "z": -11,
      "name": "Soil_Seaweed_Block"
    },
    {
      "x": -24,
      "y": 38,
      "z": -11,
      "name": "Soil_Seaweed_Block"
    },
    {
      "x": -24,
      "y": 41,
      "z": -11,
      "name": "Soil_Clay_Green"
    },
    {
      "x": -24,
      "y": 42,
      "z": -11,
      "name": "Soil_Seaweed_Block"
    },
    {
      "x": -24,
      "y": 43,
      "z": -11,
      "name": "Soil_Seaweed_Block"
    },
    {
      "x": -24,
      "y": 44,
      "z": -11,
      "name": "Soil_Seaweed_Block"
    },
    {
      "x": -24,
      "y": 45,
      "z": -11,
      "name": "Soil_Clay_Lime"
    },
    {
      "x": -24,
      "y": 46,
      "z": -11,
      "name": "Plant_Grass_Sharp"
    },
    {
      "x": -24,
      "y": 24,
      "z": -10,
      "name": "Soil_Clay_Green"
    },
    {
      "x": -24,
      "y": 25,
      "z": -10,
      "name": "Soil_Seaweed_Block"
    },
    {
      "x": -24,
      "y": 26,
      "z": -10,
      "name": "Soil_Seaweed_Block"
    },
    {
      "x": -24,
      "y": 27,
      "z": -10,
      "name": "Soil_Seaweed_Block"
    },
    {
      "x": -24,
      "y": 28,
      "z": -10,
      "name": "Soil_Seaweed_Block"
    },
    {
      "x": -24,
      "y": 29,
      "z": -10,
      "name": "Soil_Seaweed_Block"
    },
    {
      "x": -24,
      "y": 30,
      "z": -10,
      "name": "Soil_Seaweed_Block"
    },
    {
      "x": -24,
      "y": 31,
      "z": -10,
      "name": "Soil_Seaweed_Block"
    },
    {
      "x": -24,
      "y": 32,
      "z": -10,
      "name": "Soil_Seaweed_Block"
    },
    {
      "x": -24,
      "y": 33,
      "z": -10,
      "name": "Soil_Seaweed_Block"
    },
    {
      "x": -24,
      "y": 41,
      "z": -10,
      "name": "Soil_Clay_Green"
    },
    {
      "x": -24,
      "y": 42,
      "z": -10,
      "name": "Soil_Seaweed_Block"
    },
    {
      "x": -24,
      "y": 43,
      "z": -10,
      "name": "Soil_Seaweed_Block"
    },
    {
      "x": -24,
      "y": 44,
      "z": -10,
      "name": "Soil_Seaweed_Block"
    },
    {
      "x": -24,
      "y": 23,
      "z": -9,
      "name": "Soil_Clay_Green"
    },
    {
      "x": -24,
      "y": 24,
      "z": -9,
      "name": "Soil_Seaweed_Block"
    },
    {
      "x": -24,
      "y": 25,
      "z": -9,
      "name": "Soil_Seaweed_Block"
    },
    {
      "x": -24,
      "y": 26,
      "z": -9,
      "name": "Soil_Seaweed_Block"
    },
    {
      "x": -24,
      "y": 27,
      "z": -9,
      "name": "Soil_Seaweed_Block"
    },
    {
      "x": -24,
      "y": 28,
      "z": -9,
      "name": "Soil_Seaweed_Block"
    },
    {
      "x": -24,
      "y": 29,
      "z": -9,
      "name": "Soil_Seaweed_Block"
    },
    {
      "x": -24,
      "y": 30,
      "z": -9,
      "name": "Soil_Seaweed_Block"
    },
    {
      "x": -24,
      "y": 31,
      "z": -9,
      "name": "Soil_Seaweed_Block"
    },
    {
      "x": -24,
      "y": 32,
      "z": -9,
      "name": "Soil_Seaweed_Block"
    },
    {
      "x": -24,
      "y": 33,
      "z": -9,
      "name": "Soil_Clay_Lime"
    },
    {
      "x": -24,
      "y": 34,
      "z": -9,
      "name": "Plant_Grass_Sharp"
    },
    {
      "x": -24,
      "y": 42,
      "z": -9,
      "name": "Soil_Clay_Green"
    },
    {
      "x": -24,
      "y": 43,
      "z": -9,
      "name": "Soil_Seaweed_Block"
    },
    {
      "x": -24,
      "y": 22,
      "z": -8,
      "name": "Soil_Clay_Green"
    },
    {
      "x": -24,
      "y": 23,
      "z": -8,
      "name": "Soil_Seaweed_Block"
    },
    {
      "x": -24,
      "y": 24,
      "z": -8,
      "name": "Soil_Seaweed_Block"
    },
    {
      "x": -24,
      "y": 25,
      "z": -8,
      "name": "Soil_Seaweed_Block"
    },
    {
      "x": -24,
      "y": 26,
      "z": -8,
      "name": "Soil_Seaweed_Block"
    },
    {
      "x": -24,
      "y": 27,
      "z": -8,
      "name": "Soil_Seaweed_Block"
    },
    {
      "x": -24,
      "y": 28,
      "z": -8,
      "name": "Soil_Seaweed_Block"
    },
    {
      "x": -24,
      "y": 29,
      "z": -8,
      "name": "Soil_Seaweed_Block"
    },
    {
      "x": -24,
      "y": 30,
      "z": -8,
      "name": "Soil_Seaweed_Block"
    },
    {
      "x": -24,
      "y": 31,
      "z": -8,
      "name": "Soil_Seaweed_Block"
    },
    {
      "x": -24,
      "y": 32,
      "z": -8,
      "name": "Soil_Clay_Lime"
    },
    {
      "x": -24,
      "y": 33,
      "z": -8,
      "name": "Plant_Grass_Sharp"
    },
    {
      "x": -24,
      "y": 22,
      "z": -7,
      "name": "Soil_Clay_Green"
    },
    {
      "x": -24,
      "y": 23,
      "z": -7,
      "name": "Soil_Seaweed_Block"
    },
    {
      "x": -24,
      "y": 24,
      "z": -7,
      "name": "Soil_Seaweed_Block"
    },
    {
      "x": -24,
      "y": 25,
      "z": -7,
      "name": "Soil_Seaweed_Block"
    },
    {
      "x": -24,
      "y": 26,
      "z": -7,
      "name": "Soil_Seaweed_Block"
    },
    {
      "x": -24,
      "y": 27,
      "z": -7,
      "name": "Soil_Seaweed_Block"
    },
    {
      "x": -24,
      "y": 28,
      "z": -7,
      "name": "Soil_Seaweed_Block"
    },
    {
      "x": -24,
      "y": 29,
      "z": -7,
      "name": "Soil_Seaweed_Block"
    },
    {
      "x": -24,
      "y": 30,
      "z": -7,
      "name": "Soil_Seaweed_Block"
    },
    {
      "x": -24,
      "y": 31,
      "z": -7,
      "name": "Soil_Seaweed_Block"
    },
    {
      "x": -24,
      "y": 32,
      "z": -7,
      "name": "Soil_Clay_Lime"
    },
    {
      "x": -24,
      "y": 33,
      "z": -7,
      "name": "Plant_Grass_Sharp"
    },
    {
      "x": -24,
      "y": 22,
      "z": -6,
      "name": "Soil_Clay_Green"
    },
    {
      "x": -24,
      "y": 23,
      "z": -6,
      "name": "Soil_Seaweed_Block"
    },
    {
      "x": -24,
      "y": 24,
      "z": -6,
      "name": "Soil_Seaweed_Block"
    },
    {
      "x": -24,
      "y": 25,
      "z": -6,
      "name": "Soil_Seaweed_Block"
    },
    {
      "x": -24,
      "y": 26,
      "z": -6,
      "name": "Soil_Seaweed_Block"
    },
    {
      "x": -24,
      "y": 27,
      "z": -6,
      "name": "Soil_Seaweed_Block"
    },
    {
      "x": -24,
      "y": 28,
      "z": -6,
      "name": "Soil_Seaweed_Block"
    },
    {
      "x": -24,
      "y": 29,
      "z": -6,
      "name": "Soil_Seaweed_Block"
    },
    {
      "x": -24,
      "y": 30,
      "z": -6,
      "name": "Soil_Seaweed_Block"
    },
    {
      "x": -24,
      "y": 31,
      "z": -6,
      "name": "Soil_Seaweed_Block"
    },
    {
      "x": -24,
      "y": 32,
      "z": -6,
      "name": "Soil_Clay_Lime"
    },
    {
      "x": -24,
      "y": 33,
      "z": -6,
      "name": "Plant_Grass_Sharp"
    },
    {
      "x": -24,
      "y": 14,
      "z": -5,
      "name": "Soil_Clay_Green"
    },
    {
      "x": -24,
      "y": 15,
      "z": -5,
      "name": "Soil_Seaweed_Block"
    },
    {
      "x": -24,
      "y": 22,
      "z": -5,
      "name": "Soil_Clay_Green"
    },
    {
      "x": -24,
      "y": 23,
      "z": -5,
      "name": "Soil_Clay_Green"
    },
    {
      "x": -24,
      "y": 24,
      "z": -5,
      "name": "Soil_Seaweed_Block"
    },
    {
      "x": -24,
      "y": 25,
      "z": -5,
      "name": "Soil_Seaweed_Block"
    },
    {
      "x": -24,
      "y": 26,
      "z": -5,
      "name": "Soil_Seaweed_Block"
    },
    {
      "x": -24,
      "y": 27,
      "z": -5,
      "name": "Soil_Seaweed_Block"
    },
    {
      "x": -24,
      "y": 28,
      "z": -5,
      "name": "Soil_Seaweed_Block"
    },
    {
      "x": -24,
      "y": 29,
      "z": -5,
      "name": "Soil_Clay_Green"
    },
    {
      "x": -24,
      "y": 30,
      "z": -5,
      "name": "Soil_Seaweed_Block"
    },
    {
      "x": -24,
      "y": 31,
      "z": -5,
      "name": "Soil_Clay_Lime"
    },
    {
      "x": -24,
      "y": 32,
      "z": -5,
      "name": "Soil_Clay_Lime"
    },
    {
      "x": -24,
      "y": 33,
      "z": -5,
      "name": "Plant_Grass_Sharp"
    },
    {
      "x": -24,
      "y": 44,
      "z": -5,
      "name": "Soil_Seaweed_Block"
    },
    {
      "x": -24,
      "y": 13,
      "z": -4,
      "name": "Soil_Clay_Green"
    },
    {
      "x": -24,
      "y": 14,
      "z": -4,
      "name": "Soil_Seaweed_Block"
    },
    {
      "x": -24,
      "y": 15,
      "z": -4,
      "name": "Soil_Seaweed_Block"
    },
    {
      "x": -24,
      "y": 16,
      "z": -4,
      "name": "Soil_Seaweed_Block"
    },
    {
      "x": -24,
      "y": 30,
      "z": -4,
      "name": "Soil_Clay_Green"
    },
    {
      "x": -24,
      "y": 31,
      "z": -4,
      "name": "Soil_Seaweed_Block"
    },
    {
      "x": -24,
      "y": 32,
      "z": -4,
      "name": "Soil_Clay_Lime"
    },
    {
      "x": -24,
      "y": 33,
      "z": -4,
      "name": "Plant_Grass_Sharp"
    },
    {
      "x": -24,
      "y": 43,
      "z": -4,
      "name": "Soil_Clay_Green"
    },
    {
      "x": -24,
      "y": 44,
      "z": -4,
      "name": "Soil_Seaweed_Block"
    },
    {
      "x": -24,
      "y": 45,
      "z": -4,
      "name": "Soil_Seaweed_Block"
    },
    {
      "x": -24,
      "y": 12,
      "z": -3,
      "name": "Soil_Clay_Green"
    },
    {
      "x": -24,
      "y": 13,
      "z": -3,
      "name": "Soil_Seaweed_Block"
    },
    {
      "x": -24,
      "y": 14,
      "z": -3,
      "name": "Soil_Seaweed_Block"
    },
    {
      "x": -24,
      "y": 15,
      "z": -3,
      "name": "Soil_Seaweed_Block"
    },
    {
      "x": -24,
      "y": 16,
      "z": -3,
      "name": "Soil_Seaweed_Block"
    },
    {
      "x": -24,
      "y": 17,
      "z": -3,
      "name": "Soil_Seaweed_Block"
    },
    {
      "x": -24,
      "y": 31,
      "z": -3,
      "name": "Soil_Clay_Green"
    },
    {
      "x": -24,
      "y": 32,
      "z": -3,
      "name": "Soil_Seaweed_Block"
    },
    {
      "x": -24,
      "y": 43,
      "z": -3,
      "name": "Soil_Clay_Green"
    },
    {
      "x": -24,
      "y": 44,
      "z": -3,
      "name": "Soil_Seaweed_Block"
    },
    {
      "x": -24,
      "y": 13,
      "z": -2,
      "name": "Soil_Clay_Green"
    },
    {
      "x": -24,
      "y": 14,
      "z": -2,
      "name": "Soil_Seaweed_Block"
    },
    {
      "x": -24,
      "y": 15,
      "z": -2,
      "name": "Soil_Seaweed_Block"
    },
    {
      "x": -24,
      "y": 16,
      "z": -2,
      "name": "Soil_Seaweed_Block"
    },
    {
      "x": -24,
      "y": 31,
      "z": -2,
      "name": "Soil_Clay_Green"
    },
    {
      "x": -24,
      "y": 32,
      "z": -2,
      "name": "Soil_Seaweed_Block"
    },
    {
      "x": -24,
      "y": 43,
      "z": -2,
      "name": "Soil_Clay_Green"
    },
    {
      "x": -24,
      "y": 44,
      "z": -2,
      "name": "Soil_Seaweed_Block"
    },
    {
      "x": -24,
      "y": 14,
      "z": -1,
      "name": "Soil_Seaweed_Block"
    },
    {
      "x": -24,
      "y": 15,
      "z": -1,
      "name": "Soil_Seaweed_Block"
    },
    {
      "x": -24,
      "y": 31,
      "z": -1,
      "name": "Soil_Clay_Green"
    },
    {
      "x": -24,
      "y": 32,
      "z": -1,
      "name": "Soil_Clay_Green"
    },
    {
      "x": -24,
      "y": 33,
      "z": -1,
      "name": "Soil_Seaweed_Block"
    },
    {
      "x": -24,
      "y": 43,
      "z": -1,
      "name": "Soil_Clay_Green"
    },
    {
      "x": -24,
      "y": 44,
      "z": -1,
      "name": "Soil_Seaweed_Block"
    },
    {
      "x": -24,
      "y": 31,
      "z": 0,
      "name": "Soil_Clay_Green"
    },
    {
      "x": -24,
      "y": 32,
      "z": 0,
      "name": "Soil_Clay_Green"
    },
    {
      "x": -24,
      "y": 33,
      "z": 0,
      "name": "Soil_Seaweed_Block"
    },
    {
      "x": -24,
      "y": 34,
      "z": 0,
      "name": "Soil_Seaweed_Block"
    },
    {
      "x": -24,
      "y": 43,
      "z": 0,
      "name": "Soil_Clay_Green"
    },
    {
      "x": -24,
      "y": 31,
      "z": 1,
      "name": "Soil_Clay_Green"
    },
    {
      "x": -24,
      "y": 32,
      "z": 1,
      "name": "Soil_Seaweed_Block"
    },
    {
      "x": -24,
      "y": 33,
      "z": 1,
      "name": "Soil_Seaweed_Block"
    },
    {
      "x": -24,
      "y": 34,
      "z": 1,
      "name": "Soil_Seaweed_Block"
    },
    {
      "x": -24,
      "y": 35,
      "z": 1,
      "name": "Soil_Seaweed_Block"
    },
    {
      "x": -24,
      "y": 36,
      "z": 1,
      "name": "Soil_Seaweed_Block"
    },
    {
      "x": -24,
      "y": 43,
      "z": 1,
      "name": "Soil_Clay_Green"
    },
    {
      "x": -24,
      "y": 31,
      "z": 2,
      "name": "Soil_Clay_Green"
    },
    {
      "x": -24,
      "y": 32,
      "z": 2,
      "name": "Soil_Clay_Green"
    },
    {
      "x": -24,
      "y": 33,
      "z": 2,
      "name": "Soil_Seaweed_Block"
    },
    {
      "x": -24,
      "y": 34,
      "z": 2,
      "name": "Soil_Seaweed_Block"
    },
    {
      "x": -24,
      "y": 35,
      "z": 2,
      "name": "Soil_Seaweed_Block"
    },
    {
      "x": -24,
      "y": 36,
      "z": 2,
      "name": "Soil_Seaweed_Block"
    },
    {
      "x": -24,
      "y": 37,
      "z": 2,
      "name": "Soil_Seaweed_Block"
    },
    {
      "x": -24,
      "y": 38,
      "z": 2,
      "name": "Soil_Seaweed_Block"
    },
    {
      "x": -24,
      "y": 42,
      "z": 2,
      "name": "Soil_Clay_Green"
    },
    {
      "x": -24,
      "y": 43,
      "z": 2,
      "name": "Soil_Seaweed_Block"
    },
    {
      "x": -24,
      "y": 44,
      "z": 2,
      "name": "Soil_Seaweed_Block"
    },
    {
      "x": -24,
      "y": 30,
      "z": 3,
      "name": "Soil_Clay_Green"
    },
    {
      "x": -24,
      "y": 31,
      "z": 3,
      "name": "Soil_Clay_Green"
    },
    {
      "x": -24,
      "y": 32,
      "z": 3,
      "name": "Soil_Seaweed_Block"
    },
    {
      "x": -24,
      "y": 33,
      "z": 3,
      "name": "Soil_Seaweed_Block"
    },
    {
      "x": -24,
      "y": 34,
      "z": 3,
      "name": "Soil_Seaweed_Block"
    },
    {
      "x": -24,
      "y": 35,
      "z": 3,
      "name": "Soil_Seaweed_Block"
    },
    {
      "x": -24,
      "y": 36,
      "z": 3,
      "name": "Soil_Seaweed_Block"
    },
    {
      "x": -24,
      "y": 37,
      "z": 3,
      "name": "Soil_Seaweed_Block"
    },
    {
      "x": -24,
      "y": 38,
      "z": 3,
      "name": "Soil_Seaweed_Block"
    },
    {
      "x": -24,
      "y": 39,
      "z": 3,
      "name": "Soil_Seaweed_Block"
    },
    {
      "x": -24,
      "y": 40,
      "z": 3,
      "name": "Soil_Clay_Green"
    },
    {
      "x": -24,
      "y": 41,
      "z": 3,
      "name": "Soil_Clay_Green"
    },
    {
      "x": -24,
      "y": 42,
      "z": 3,
      "name": "Soil_Clay_Green"
    },
    {
      "x": -24,
      "y": 43,
      "z": 3,
      "name": "Soil_Seaweed_Block"
    },
    {
      "x": -24,
      "y": 44,
      "z": 3,
      "name": "Soil_Seaweed_Block"
    },
    {
      "x": -24,
      "y": 29,
      "z": 4,
      "name": "Soil_Clay_Green"
    },
    {
      "x": -24,
      "y": 30,
      "z": 4,
      "name": "Soil_Clay_Green"
    },
    {
      "x": -24,
      "y": 31,
      "z": 4,
      "name": "Soil_Seaweed_Block"
    },
    {
      "x": -24,
      "y": 36,
      "z": 4,
      "name": "Soil_Seaweed_Block"
    },
    {
      "x": -24,
      "y": 37,
      "z": 4,
      "name": "Soil_Seaweed_Block"
    },
    {
      "x": -24,
      "y": 38,
      "z": 4,
      "name": "Soil_Seaweed_Block"
    },
    {
      "x": -24,
      "y": 39,
      "z": 4,
      "name": "Soil_Seaweed_Block"
    },
    {
      "x": -24,
      "y": 40,
      "z": 4,
      "name": "Soil_Clay_Green"
    },
    {
      "x": -24,
      "y": 41,
      "z": 4,
      "name": "Soil_Clay_Green"
    },
    {
      "x": -24,
      "y": 42,
      "z": 4,
      "name": "Soil_Seaweed_Block"
    },
    {
      "x": -24,
      "y": 43,
      "z": 4,
      "name": "Soil_Seaweed_Block"
    },
    {
      "x": -24,
      "y": 44,
      "z": 4,
      "name": "Soil_Seaweed_Block"
    },
    {
      "x": -24,
      "y": 45,
      "z": 4,
      "name": "Soil_Seaweed_Block"
    },
    {
      "x": -24,
      "y": 28,
      "z": 5,
      "name": "Soil_Clay_Green"
    },
    {
      "x": -24,
      "y": 29,
      "z": 5,
      "name": "Soil_Seaweed_Block"
    },
    {
      "x": -24,
      "y": 30,
      "z": 5,
      "name": "Soil_Seaweed_Block"
    },
    {
      "x": -24,
      "y": 31,
      "z": 5,
      "name": "Soil_Clay_Lime"
    },
    {
      "x": -24,
      "y": 32,
      "z": 5,
      "name": "Plant_Grass_Sharp"
    },
    {
      "x": -24,
      "y": 38,
      "z": 5,
      "name": "Soil_Clay_Green"
    },
    {
      "x": -24,
      "y": 39,
      "z": 5,
      "name": "Soil_Clay_Green"
    },
    {
      "x": -24,
      "y": 40,
      "z": 5,
      "name": "Soil_Clay_Green"
    },
    {
      "x": -24,
      "y": 41,
      "z": 5,
      "name": "Soil_Clay_Green"
    },
    {
      "x": -24,
      "y": 42,
      "z": 5,
      "name": "Soil_Seaweed_Block"
    },
    {
      "x": -24,
      "y": 43,
      "z": 5,
      "name": "Soil_Seaweed_Block"
    },
    {
      "x": -24,
      "y": 44,
      "z": 5,
      "name": "Soil_Seaweed_Block"
    },
    {
      "x": -24,
      "y": 45,
      "z": 5,
      "name": "Soil_Seaweed_Block"
    },
    {
      "x": -24,
      "y": 46,
      "z": 5,
      "name": "Soil_Clay_Lime"
    },
    {
      "x": -24,
      "y": 47,
      "z": 5,
      "name": "Plant_Grass_Sharp"
    },
    {
      "x": -24,
      "y": 27,
      "z": 6,
      "name": "Soil_Clay_Green"
    },
    {
      "x": -24,
      "y": 28,
      "z": 6,
      "name": "Soil_Seaweed_Block"
    },
    {
      "x": -24,
      "y": 29,
      "z": 6,
      "name": "Soil_Seaweed_Block"
    },
    {
      "x": -24,
      "y": 30,
      "z": 6,
      "name": "Soil_Seaweed_Block"
    },
    {
      "x": -24,
      "y": 31,
      "z": 6,
      "name": "Soil_Clay_Lime"
    },
    {
      "x": -24,
      "y": 32,
      "z": 6,
      "name": "Plant_Grass_Sharp"
    },
    {
      "x": -24,
      "y": 40,
      "z": 6,
      "name": "Soil_Clay_Green"
    },
    {
      "x": -24,
      "y": 41,
      "z": 6,
      "name": "Soil_Clay_Green"
    },
    {
      "x": -24,
      "y": 42,
      "z": 6,
      "name": "Soil_Seaweed_Block"
    },
    {
      "x": -24,
      "y": 43,
      "z": 6,
      "name": "Soil_Seaweed_Block"
    },
    {
      "x": -24,
      "y": 44,
      "z": 6,
      "name": "Soil_Seaweed_Block"
    },
    {
      "x": -24,
      "y": 45,
      "z": 6,
      "name": "Soil_Seaweed_Block"
    },
    {
      "x": -24,
      "y": 46,
      "z": 6,
      "name": "Soil_Clay_Lime"
    },
    {
      "x": -24,
      "y": 47,
      "z": 6,
      "name": "Plant_Grass_Sharp"
    },
    {
      "x": -24,
      "y": 24,
      "z": 7,
      "name": "Soil_Seaweed_Block"
    },
    {
      "x": -24,
      "y": 25,
      "z": 7,
      "name": "Soil_Seaweed_Block"
    },
    {
      "x": -24,
      "y": 26,
      "z": 7,
      "name": "Soil_Seaweed_Block"
    },
    {
      "x": -24,
      "y": 27,
      "z": 7,
      "name": "Soil_Seaweed_Block"
    },
    {
      "x": -24,
      "y": 28,
      "z": 7,
      "name": "Soil_Seaweed_Block"
    },
    {
      "x": -24,
      "y": 29,
      "z": 7,
      "name": "Soil_Seaweed_Block"
    },
    {
      "x": -24,
      "y": 30,
      "z": 7,
      "name": "Soil_Clay_Lime"
    },
    {
      "x": -24,
      "y": 31,
      "z": 7,
      "name": "Plant_Grass_Sharp"
    },
    {
      "x": -24,
      "y": 41,
      "z": 7,
      "name": "Soil_Clay_Green"
    },
    {
      "x": -24,
      "y": 42,
      "z": 7,
      "name": "Soil_Seaweed_Block"
    },
    {
      "x": -24,
      "y": 43,
      "z": 7,
      "name": "Soil_Seaweed_Block"
    },
    {
      "x": -24,
      "y": 44,
      "z": 7,
      "name": "Soil_Seaweed_Block"
    },
    {
      "x": -24,
      "y": 45,
      "z": 7,
      "name": "Soil_Seaweed_Block"
    },
    {
      "x": -24,
      "y": 46,
      "z": 7,
      "name": "Soil_Clay_Lime"
    },
    {
      "x": -24,
      "y": 47,
      "z": 7,
      "name": "Plant_Grass_Sharp"
    },
    {
      "x": -24,
      "y": 23,
      "z": 8,
      "name": "Soil_Clay_Green"
    },
    {
      "x": -24,
      "y": 24,
      "z": 8,
      "name": "Soil_Seaweed_Block"
    },
    {
      "x": -24,
      "y": 25,
      "z": 8,
      "name": "Soil_Seaweed_Block"
    },
    {
      "x": -24,
      "y": 26,
      "z": 8,
      "name": "Soil_Seaweed_Block"
    },
    {
      "x": -24,
      "y": 27,
      "z": 8,
      "name": "Soil_Seaweed_Block"
    },
    {
      "x": -24,
      "y": 28,
      "z": 8,
      "name": "Soil_Seaweed_Block"
    },
    {
      "x": -24,
      "y": 29,
      "z": 8,
      "name": "Soil_Seaweed_Block"
    },
    {
      "x": -24,
      "y": 30,
      "z": 8,
      "name": "Soil_Clay_Lime"
    },
    {
      "x": -24,
      "y": 31,
      "z": 8,
      "name": "Plant_Grass_Sharp"
    },
    {
      "x": -24,
      "y": 42,
      "z": 8,
      "name": "Soil_Seaweed_Block"
    },
    {
      "x": -24,
      "y": 43,
      "z": 8,
      "name": "Soil_Seaweed_Block"
    },
    {
      "x": -24,
      "y": 44,
      "z": 8,
      "name": "Soil_Seaweed_Block"
    },
    {
      "x": -24,
      "y": 45,
      "z": 8,
      "name": "Soil_Seaweed_Block"
    },
    {
      "x": -24,
      "y": 22,
      "z": 9,
      "name": "Soil_Clay_Green"
    },
    {
      "x": -24,
      "y": 23,
      "z": 9,
      "name": "Soil_Seaweed_Block"
    },
    {
      "x": -24,
      "y": 24,
      "z": 9,
      "name": "Soil_Seaweed_Block"
    },
    {
      "x": -24,
      "y": 25,
      "z": 9,
      "name": "Soil_Seaweed_Block"
    },
    {
      "x": -24,
      "y": 26,
      "z": 9,
      "name": "Soil_Seaweed_Block"
    },
    {
      "x": -24,
      "y": 27,
      "z": 9,
      "name": "Soil_Seaweed_Block"
    },
    {
      "x": -24,
      "y": 28,
      "z": 9,
      "name": "Soil_Seaweed_Block"
    },
    {
      "x": -24,
      "y": 29,
      "z": 9,
      "name": "Soil_Seaweed_Block"
    },
    {
      "x": -24,
      "y": 21,
      "z": 10,
      "name": "Soil_Clay_Green"
    },
    {
      "x": -24,
      "y": 22,
      "z": 10,
      "name": "Soil_Seaweed_Block"
    },
    {
      "x": -24,
      "y": 23,
      "z": 10,
      "name": "Soil_Seaweed_Block"
    },
    {
      "x": -24,
      "y": 24,
      "z": 10,
      "name": "Soil_Seaweed_Block"
    },
    {
      "x": -24,
      "y": 25,
      "z": 10,
      "name": "Soil_Seaweed_Block"
    },
    {
      "x": -24,
      "y": 26,
      "z": 10,
      "name": "Soil_Seaweed_Block"
    },
    {
      "x": -24,
      "y": 27,
      "z": 10,
      "name": "Soil_Seaweed_Block"
    },
    {
      "x": -24,
      "y": 21,
      "z": 11,
      "name": "Soil_Clay_Green"
    },
    {
      "x": -24,
      "y": 22,
      "z": 11,
      "name": "Soil_Seaweed_Block"
    },
    {
      "x": -24,
      "y": 23,
      "z": 11,
      "name": "Soil_Seaweed_Block"
    },
    {
      "x": -24,
      "y": 24,
      "z": 11,
      "name": "Soil_Seaweed_Block"
    },
    {
      "x": -24,
      "y": 25,
      "z": 11,
      "name": "Soil_Seaweed_Block"
    },
    {
      "x": -24,
      "y": 26,
      "z": 11,
      "name": "Soil_Clay_Lime"
    },
    {
      "x": -24,
      "y": 27,
      "z": 11,
      "name": "Plant_Grass_Sharp"
    },
    {
      "x": -24,
      "y": 21,
      "z": 12,
      "name": "Soil_Clay_Green"
    },
    {
      "x": -24,
      "y": 22,
      "z": 12,
      "name": "Soil_Seaweed_Block"
    },
    {
      "x": -24,
      "y": 23,
      "z": 12,
      "name": "Soil_Seaweed_Block"
    },
    {
      "x": -24,
      "y": 24,
      "z": 12,
      "name": "Soil_Seaweed_Block"
    },
    {
      "x": -24,
      "y": 25,
      "z": 12,
      "name": "Soil_Seaweed_Block"
    },
    {
      "x": -24,
      "y": 22,
      "z": 13,
      "name": "Soil_Clay_Green"
    },
    {
      "x": -24,
      "y": 23,
      "z": 13,
      "name": "Soil_Seaweed_Block"
    },
    {
      "x": -24,
      "y": 24,
      "z": 13,
      "name": "Soil_Seaweed_Block"
    },
    {
      "x": -23,
      "y": 29,
      "z": -16,
      "name": "Soil_Clay_Green"
    },
    {
      "x": -23,
      "y": 30,
      "z": -16,
      "name": "Soil_Seaweed_Block"
    },
    {
      "x": -23,
      "y": 31,
      "z": -16,
      "name": "Soil_Seaweed_Block"
    },
    {
      "x": -23,
      "y": 28,
      "z": -15,
      "name": "Soil_Clay_Green"
    },
    {
      "x": -23,
      "y": 29,
      "z": -15,
      "name": "Soil_Seaweed_Block"
    },
    {
      "x": -23,
      "y": 30,
      "z": -15,
      "name": "Soil_Seaweed_Block"
    },
    {
      "x": -23,
      "y": 31,
      "z": -15,
      "name": "Soil_Seaweed_Block"
    },
    {
      "x": -23,
      "y": 32,
      "z": -15,
      "name": "Soil_Seaweed_Block"
    },
    {
      "x": -23,
      "y": 35,
      "z": -15,
      "name": "Soil_Clay_Green"
    },
    {
      "x": -23,
      "y": 36,
      "z": -15,
      "name": "Soil_Clay_Green"
    },
    {
      "x": -23,
      "y": 37,
      "z": -15,
      "name": "Soil_Seaweed_Block"
    },
    {
      "x": -23,
      "y": 38,
      "z": -15,
      "name": "Soil_Seaweed_Block"
    },
    {
      "x": -23,
      "y": 28,
      "z": -14,
      "name": "Soil_Clay_Green"
    },
    {
      "x": -23,
      "y": 29,
      "z": -14,
      "name": "Soil_Seaweed_Block"
    },
    {
      "x": -23,
      "y": 30,
      "z": -14,
      "name": "Soil_Seaweed_Block"
    },
    {
      "x": -23,
      "y": 31,
      "z": -14,
      "name": "Soil_Seaweed_Block"
    },
    {
      "x": -23,
      "y": 32,
      "z": -14,
      "name": "Soil_Seaweed_Block"
    },
    {
      "x": -23,
      "y": 33,
      "z": -14,
      "name": "Soil_Seaweed_Block"
    },
    {
      "x": -23,
      "y": 34,
      "z": -14,
      "name": "Soil_Seaweed_Block"
    },
    {
      "x": -23,
      "y": 35,
      "z": -14,
      "name": "Soil_Seaweed_Block"
    },
    {
      "x": -23,
      "y": 36,
      "z": -14,
      "name": "Soil_Seaweed_Block"
    },
    {
      "x": -23,
      "y": 37,
      "z": -14,
      "name": "Soil_Seaweed_Block"
    },
    {
      "x": -23,
      "y": 38,
      "z": -14,
      "name": "Soil_Seaweed_Block"
    },
    {
      "x": -23,
      "y": 39,
      "z": -14,
      "name": "Soil_Clay_Lime"
    },
    {
      "x": -23,
      "y": 40,
      "z": -14,
      "name": "Plant_Grass_Sharp"
    },
    {
      "x": -23,
      "y": 28,
      "z": -13,
      "name": "Soil_Clay_Green"
    },
    {
      "x": -23,
      "y": 29,
      "z": -13,
      "name": "Soil_Seaweed_Block"
    },
    {
      "x": -23,
      "y": 30,
      "z": -13,
      "name": "Soil_Seaweed_Block"
    },
    {
      "x": -23,
      "y": 31,
      "z": -13,
      "name": "Soil_Seaweed_Block"
    },
    {
      "x": -23,
      "y": 32,
      "z": -13,
      "name": "Soil_Seaweed_Block"
    },
    {
      "x": -23,
      "y": 33,
      "z": -13,
      "name": "Soil_Seaweed_Block"
    },
    {
      "x": -23,
      "y": 34,
      "z": -13,
      "name": "Soil_Seaweed_Block"
    },
    {
      "x": -23,
      "y": 35,
      "z": -13,
      "name": "Soil_Seaweed_Block"
    },
    {
      "x": -23,
      "y": 36,
      "z": -13,
      "name": "Soil_Seaweed_Block"
    },
    {
      "x": -23,
      "y": 37,
      "z": -13,
      "name": "Soil_Seaweed_Block"
    },
    {
      "x": -23,
      "y": 38,
      "z": -13,
      "name": "Soil_Seaweed_Block"
    },
    {
      "x": -23,
      "y": 39,
      "z": -13,
      "name": "Soil_Seaweed_Block"
    },
    {
      "x": -23,
      "y": 40,
      "z": -13,
      "name": "Soil_Seaweed_Block"
    },
    {
      "x": -23,
      "y": 42,
      "z": -13,
      "name": "Soil_Seaweed_Block"
    },
    {
      "x": -23,
      "y": 43,
      "z": -13,
      "name": "Soil_Seaweed_Block"
    },
    {
      "x": -23,
      "y": 44,
      "z": -13,
      "name": "Soil_Seaweed_Block"
    },
    {
      "x": -23,
      "y": 27,
      "z": -12,
      "name": "Soil_Clay_Green"
    },
    {
      "x": -23,
      "y": 28,
      "z": -12,
      "name": "Soil_Seaweed_Block"
    },
    {
      "x": -23,
      "y": 29,
      "z": -12,
      "name": "Soil_Seaweed_Block"
    },
    {
      "x": -23,
      "y": 30,
      "z": -12,
      "name": "Soil_Seaweed_Block"
    },
    {
      "x": -23,
      "y": 31,
      "z": -12,
      "name": "Soil_Seaweed_Block"
    },
    {
      "x": -23,
      "y": 32,
      "z": -12,
      "name": "Soil_Seaweed_Block"
    },
    {
      "x": -23,
      "y": 33,
      "z": -12,
      "name": "Soil_Seaweed_Block"
    },
    {
      "x": -23,
      "y": 34,
      "z": -12,
      "name": "Soil_Seaweed_Block"
    },
    {
      "x": -23,
      "y": 35,
      "z": -12,
      "name": "Soil_Seaweed_Block"
    },
    {
      "x": -23,
      "y": 36,
      "z": -12,
      "name": "Soil_Seaweed_Block"
    },
    {
      "x": -23,
      "y": 37,
      "z": -12,
      "name": "Soil_Seaweed_Block"
    },
    {
      "x": -23,
      "y": 38,
      "z": -12,
      "name": "Soil_Seaweed_Block"
    },
    {
      "x": -23,
      "y": 39,
      "z": -12,
      "name": "Soil_Seaweed_Block"
    },
    {
      "x": -23,
      "y": 40,
      "z": -12,
      "name": "Soil_Seaweed_Block"
    },
    {
      "x": -23,
      "y": 41,
      "z": -12,
      "name": "Soil_Seaweed_Block"
    },
    {
      "x": -23,
      "y": 42,
      "z": -12,
      "name": "Soil_Seaweed_Block"
    },
    {
      "x": -23,
      "y": 43,
      "z": -12,
      "name": "Soil_Seaweed_Block"
    },
    {
      "x": -23,
      "y": 44,
      "z": -12,
      "name": "Soil_Seaweed_Block"
    },
    {
      "x": -23,
      "y": 45,
      "z": -12,
      "name": "Soil_Clay_Lime"
    },
    {
      "x": -23,
      "y": 46,
      "z": -12,
      "name": "Plant_Grass_Sharp"
    },
    {
      "x": -23,
      "y": 26,
      "z": -11,
      "name": "Soil_Clay_Green"
    },
    {
      "x": -23,
      "y": 27,
      "z": -11,
      "name": "Soil_Clay_Green"
    },
    {
      "x": -23,
      "y": 28,
      "z": -11,
      "name": "Soil_Seaweed_Block"
    },
    {
      "x": -23,
      "y": 29,
      "z": -11,
      "name": "Soil_Seaweed_Block"
    },
    {
      "x": -23,
      "y": 30,
      "z": -11,
      "name": "Soil_Seaweed_Block"
    },
    {
      "x": -23,
      "y": 31,
      "z": -11,
      "name": "Soil_Seaweed_Block"
    },
    {
      "x": -23,
      "y": 32,
      "z": -11,
      "name": "Soil_Seaweed_Block"
    },
    {
      "x": -23,
      "y": 33,
      "z": -11,
      "name": "Soil_Seaweed_Block"
    },
    {
      "x": -23,
      "y": 34,
      "z": -11,
      "name": "Soil_Seaweed_Block"
    },
    {
      "x": -23,
      "y": 35,
      "z": -11,
      "name": "Soil_Seaweed_Block"
    },
    {
      "x": -23,
      "y": 36,
      "z": -11,
      "name": "Soil_Seaweed_Block"
    },
    {
      "x": -23,
      "y": 37,
      "z": -11,
      "name": "Soil_Seaweed_Block"
    },
    {
      "x": -23,
      "y": 38,
      "z": -11,
      "name": "Soil_Seaweed_Block"
    },
    {
      "x": -23,
      "y": 39,
      "z": -11,
      "name": "Soil_Seaweed_Block"
    },
    {
      "x": -23,
      "y": 40,
      "z": -11,
      "name": "Soil_Seaweed_Block"
    },
    {
      "x": -23,
      "y": 41,
      "z": -11,
      "name": "Soil_Seaweed_Block"
    },
    {
      "x": -23,
      "y": 42,
      "z": -11,
      "name": "Soil_Seaweed_Block"
    },
    {
      "x": -23,
      "y": 43,
      "z": -11,
      "name": "Soil_Seaweed_Block"
    },
    {
      "x": -23,
      "y": 44,
      "z": -11,
      "name": "Soil_Seaweed_Block"
    },
    {
      "x": -23,
      "y": 45,
      "z": -11,
      "name": "Soil_Clay_Lime"
    },
    {
      "x": -23,
      "y": 46,
      "z": -11,
      "name": "Plant_Grass_Sharp"
    },
    {
      "x": -23,
      "y": 24,
      "z": -10,
      "name": "Soil_Clay_Green"
    },
    {
      "x": -23,
      "y": 25,
      "z": -10,
      "name": "Soil_Clay_Green"
    },
    {
      "x": -23,
      "y": 26,
      "z": -10,
      "name": "Soil_Seaweed_Block"
    },
    {
      "x": -23,
      "y": 27,
      "z": -10,
      "name": "Soil_Seaweed_Block"
    },
    {
      "x": -23,
      "y": 28,
      "z": -10,
      "name": "Soil_Seaweed_Block"
    },
    {
      "x": -23,
      "y": 29,
      "z": -10,
      "name": "Soil_Seaweed_Block"
    },
    {
      "x": -23,
      "y": 30,
      "z": -10,
      "name": "Soil_Seaweed_Block"
    },
    {
      "x": -23,
      "y": 31,
      "z": -10,
      "name": "Soil_Seaweed_Block"
    },
    {
      "x": -23,
      "y": 32,
      "z": -10,
      "name": "Soil_Seaweed_Block"
    },
    {
      "x": -23,
      "y": 33,
      "z": -10,
      "name": "Soil_Seaweed_Block"
    },
    {
      "x": -23,
      "y": 34,
      "z": -10,
      "name": "Soil_Seaweed_Block"
    },
    {
      "x": -23,
      "y": 37,
      "z": -10,
      "name": "Soil_Seaweed_Block"
    },
    {
      "x": -23,
      "y": 38,
      "z": -10,
      "name": "Soil_Seaweed_Block"
    },
    {
      "x": -23,
      "y": 39,
      "z": -10,
      "name": "Soil_Seaweed_Block"
    },
    {
      "x": -23,
      "y": 40,
      "z": -10,
      "name": "Soil_Clay_Green"
    },
    {
      "x": -23,
      "y": 41,
      "z": -10,
      "name": "Soil_Seaweed_Block"
    },
    {
      "x": -23,
      "y": 42,
      "z": -10,
      "name": "Soil_Seaweed_Block"
    },
    {
      "x": -23,
      "y": 43,
      "z": -10,
      "name": "Soil_Seaweed_Block"
    },
    {
      "x": -23,
      "y": 44,
      "z": -10,
      "name": "Soil_Seaweed_Block"
    },
    {
      "x": -23,
      "y": 45,
      "z": -10,
      "name": "Soil_Clay_Lime"
    },
    {
      "x": -23,
      "y": 46,
      "z": -10,
      "name": "Plant_Grass_Sharp"
    },
    {
      "x": -23,
      "y": 23,
      "z": -9,
      "name": "Soil_Clay_Green"
    },
    {
      "x": -23,
      "y": 24,
      "z": -9,
      "name": "Soil_Seaweed_Block"
    },
    {
      "x": -23,
      "y": 25,
      "z": -9,
      "name": "Soil_Seaweed_Block"
    },
    {
      "x": -23,
      "y": 26,
      "z": -9,
      "name": "Soil_Seaweed_Block"
    },
    {
      "x": -23,
      "y": 27,
      "z": -9,
      "name": "Soil_Seaweed_Block"
    },
    {
      "x": -23,
      "y": 28,
      "z": -9,
      "name": "Soil_Seaweed_Block"
    },
    {
      "x": -23,
      "y": 29,
      "z": -9,
      "name": "Soil_Seaweed_Block"
    },
    {
      "x": -23,
      "y": 30,
      "z": -9,
      "name": "Soil_Seaweed_Block"
    },
    {
      "x": -23,
      "y": 31,
      "z": -9,
      "name": "Soil_Seaweed_Block"
    },
    {
      "x": -23,
      "y": 32,
      "z": -9,
      "name": "Soil_Seaweed_Block"
    },
    {
      "x": -23,
      "y": 33,
      "z": -9,
      "name": "Soil_Clay_Lime"
    },
    {
      "x": -23,
      "y": 34,
      "z": -9,
      "name": "Plant_Grass_Sharp"
    },
    {
      "x": -23,
      "y": 41,
      "z": -9,
      "name": "Soil_Clay_Green"
    },
    {
      "x": -23,
      "y": 42,
      "z": -9,
      "name": "Soil_Seaweed_Block"
    },
    {
      "x": -23,
      "y": 43,
      "z": -9,
      "name": "Soil_Seaweed_Block"
    },
    {
      "x": -23,
      "y": 44,
      "z": -9,
      "name": "Soil_Clay_Lime"
    },
    {
      "x": -23,
      "y": 45,
      "z": -9,
      "name": "Plant_Grass_Sharp"
    },
    {
      "x": -23,
      "y": 22,
      "z": -8,
      "name": "Soil_Clay_Green"
    },
    {
      "x": -23,
      "y": 23,
      "z": -8,
      "name": "Soil_Seaweed_Block"
    },
    {
      "x": -23,
      "y": 24,
      "z": -8,
      "name": "Soil_Seaweed_Block"
    },
    {
      "x": -23,
      "y": 25,
      "z": -8,
      "name": "Soil_Seaweed_Block"
    },
    {
      "x": -23,
      "y": 26,
      "z": -8,
      "name": "Soil_Seaweed_Block"
    },
    {
      "x": -23,
      "y": 27,
      "z": -8,
      "name": "Soil_Seaweed_Block"
    },
    {
      "x": -23,
      "y": 28,
      "z": -8,
      "name": "Soil_Seaweed_Block"
    },
    {
      "x": -23,
      "y": 29,
      "z": -8,
      "name": "Soil_Seaweed_Block"
    },
    {
      "x": -23,
      "y": 30,
      "z": -8,
      "name": "Soil_Seaweed_Block"
    },
    {
      "x": -23,
      "y": 31,
      "z": -8,
      "name": "Soil_Seaweed_Block"
    },
    {
      "x": -23,
      "y": 32,
      "z": -8,
      "name": "Soil_Clay_Lime"
    },
    {
      "x": -23,
      "y": 33,
      "z": -8,
      "name": "Plant_Grass_Sharp"
    },
    {
      "x": -23,
      "y": 41,
      "z": -8,
      "name": "Soil_Clay_Green"
    },
    {
      "x": -23,
      "y": 42,
      "z": -8,
      "name": "Soil_Clay_Green"
    },
    {
      "x": -23,
      "y": 43,
      "z": -8,
      "name": "Soil_Seaweed_Block"
    },
    {
      "x": -23,
      "y": 44,
      "z": -8,
      "name": "Soil_Clay_Lime"
    },
    {
      "x": -23,
      "y": 45,
      "z": -8,
      "name": "Plant_Grass_Sharp"
    },
    {
      "x": -23,
      "y": 22,
      "z": -7,
      "name": "Soil_Clay_Green"
    },
    {
      "x": -23,
      "y": 23,
      "z": -7,
      "name": "Soil_Seaweed_Block"
    },
    {
      "x": -23,
      "y": 24,
      "z": -7,
      "name": "Soil_Seaweed_Block"
    },
    {
      "x": -23,
      "y": 25,
      "z": -7,
      "name": "Soil_Seaweed_Block"
    },
    {
      "x": -23,
      "y": 26,
      "z": -7,
      "name": "Soil_Seaweed_Block"
    },
    {
      "x": -23,
      "y": 27,
      "z": -7,
      "name": "Soil_Seaweed_Block"
    },
    {
      "x": -23,
      "y": 28,
      "z": -7,
      "name": "Soil_Seaweed_Block"
    },
    {
      "x": -23,
      "y": 29,
      "z": -7,
      "name": "Soil_Seaweed_Block"
    },
    {
      "x": -23,
      "y": 30,
      "z": -7,
      "name": "Soil_Seaweed_Block"
    },
    {
      "x": -23,
      "y": 31,
      "z": -7,
      "name": "Soil_Seaweed_Block"
    },
    {
      "x": -23,
      "y": 42,
      "z": -7,
      "name": "Soil_Clay_Green"
    },
    {
      "x": -23,
      "y": 43,
      "z": -7,
      "name": "Soil_Seaweed_Block"
    },
    {
      "x": -23,
      "y": 44,
      "z": -7,
      "name": "Soil_Clay_Lime"
    },
    {
      "x": -23,
      "y": 45,
      "z": -7,
      "name": "Plant_Grass_Sharp"
    },
    {
      "x": -23,
      "y": 21,
      "z": -6,
      "name": "Soil_Clay_Green"
    },
    {
      "x": -23,
      "y": 22,
      "z": -6,
      "name": "Soil_Seaweed_Block"
    },
    {
      "x": -23,
      "y": 23,
      "z": -6,
      "name": "Soil_Seaweed_Block"
    },
    {
      "x": -23,
      "y": 24,
      "z": -6,
      "name": "Soil_Seaweed_Block"
    },
    {
      "x": -23,
      "y": 25,
      "z": -6,
      "name": "Soil_Seaweed_Block"
    },
    {
      "x": -23,
      "y": 26,
      "z": -6,
      "name": "Soil_Seaweed_Block"
    },
    {
      "x": -23,
      "y": 27,
      "z": -6,
      "name": "Soil_Seaweed_Block"
    },
    {
      "x": -23,
      "y": 28,
      "z": -6,
      "name": "Soil_Seaweed_Block"
    },
    {
      "x": -23,
      "y": 29,
      "z": -6,
      "name": "Soil_Seaweed_Block"
    },
    {
      "x": -23,
      "y": 30,
      "z": -6,
      "name": "Soil_Seaweed_Block"
    },
    {
      "x": -23,
      "y": 31,
      "z": -6,
      "name": "Soil_Seaweed_Block"
    },
    {
      "x": -23,
      "y": 42,
      "z": -6,
      "name": "Soil_Clay_Green"
    },
    {
      "x": -23,
      "y": 43,
      "z": -6,
      "name": "Soil_Seaweed_Block"
    },
    {
      "x": -23,
      "y": 44,
      "z": -6,
      "name": "Soil_Seaweed_Block"
    },
    {
      "x": -23,
      "y": 14,
      "z": -5,
      "name": "Soil_Clay_Green"
    },
    {
      "x": -23,
      "y": 15,
      "z": -5,
      "name": "Soil_Seaweed_Block"
    },
    {
      "x": -23,
      "y": 16,
      "z": -5,
      "name": "Soil_Seaweed_Block"
    },
    {
      "x": -23,
      "y": 21,
      "z": -5,
      "name": "Soil_Clay_Green"
    },
    {
      "x": -23,
      "y": 22,
      "z": -5,
      "name": "Soil_Seaweed_Block"
    },
    {
      "x": -23,
      "y": 23,
      "z": -5,
      "name": "Soil_Seaweed_Block"
    },
    {
      "x": -23,
      "y": 24,
      "z": -5,
      "name": "Soil_Seaweed_Block"
    },
    {
      "x": -23,
      "y": 25,
      "z": -5,
      "name": "Soil_Seaweed_Block"
    },
    {
      "x": -23,
      "y": 26,
      "z": -5,
      "name": "Soil_Seaweed_Block"
    },
    {
      "x": -23,
      "y": 30,
      "z": -5,
      "name": "Soil_Seaweed_Block"
    },
    {
      "x": -23,
      "y": 42,
      "z": -5,
      "name": "Soil_Clay_Green"
    },
    {
      "x": -23,
      "y": 43,
      "z": -5,
      "name": "Soil_Clay_Green"
    },
    {
      "x": -23,
      "y": 44,
      "z": -5,
      "name": "Soil_Seaweed_Block"
    },
    {
      "x": -23,
      "y": 45,
      "z": -5,
      "name": "Soil_Clay_Lime"
    },
    {
      "x": -23,
      "y": 46,
      "z": -5,
      "name": "Plant_Grass_Sharp"
    },
    {
      "x": -23,
      "y": 13,
      "z": -4,
      "name": "Soil_Clay_Green"
    },
    {
      "x": -23,
      "y": 14,
      "z": -4,
      "name": "Soil_Seaweed_Block"
    },
    {
      "x": -23,
      "y": 15,
      "z": -4,
      "name": "Soil_Seaweed_Block"
    },
    {
      "x": -23,
      "y": 16,
      "z": -4,
      "name": "Soil_Seaweed_Block"
    },
    {
      "x": -23,
      "y": 17,
      "z": -4,
      "name": "Soil_Seaweed_Block"
    },
    {
      "x": -23,
      "y": 18,
      "z": -4,
      "name": "Soil_Seaweed_Block"
    },
    {
      "x": -23,
      "y": 21,
      "z": -4,
      "name": "Soil_Seaweed_Block"
    },
    {
      "x": -23,
      "y": 22,
      "z": -4,
      "name": "Soil_Seaweed_Block"
    },
    {
      "x": -23,
      "y": 23,
      "z": -4,
      "name": "Soil_Seaweed_Block"
    },
    {
      "x": -23,
      "y": 24,
      "z": -4,
      "name": "Soil_Seaweed_Block"
    },
    {
      "x": -23,
      "y": 42,
      "z": -4,
      "name": "Soil_Clay_Green"
    },
    {
      "x": -23,
      "y": 43,
      "z": -4,
      "name": "Soil_Seaweed_Block"
    },
    {
      "x": -23,
      "y": 44,
      "z": -4,
      "name": "Soil_Seaweed_Block"
    },
    {
      "x": -23,
      "y": 45,
      "z": -4,
      "name": "Soil_Clay_Lime"
    },
    {
      "x": -23,
      "y": 46,
      "z": -4,
      "name": "Plant_Grass_Sharp"
    },
    {
      "x": -23,
      "y": 12,
      "z": -3,
      "name": "Soil_Clay_Green"
    },
    {
      "x": -23,
      "y": 13,
      "z": -3,
      "name": "Soil_Seaweed_Block"
    },
    {
      "x": -23,
      "y": 14,
      "z": -3,
      "name": "Soil_Seaweed_Block"
    },
    {
      "x": -23,
      "y": 15,
      "z": -3,
      "name": "Soil_Seaweed_Block"
    },
    {
      "x": -23,
      "y": 16,
      "z": -3,
      "name": "Soil_Seaweed_Block"
    },
    {
      "x": -23,
      "y": 17,
      "z": -3,
      "name": "Soil_Seaweed_Block"
    },
    {
      "x": -23,
      "y": 18,
      "z": -3,
      "name": "Soil_Seaweed_Block"
    },
    {
      "x": -23,
      "y": 42,
      "z": -3,
      "name": "Soil_Clay_Green"
    },
    {
      "x": -23,
      "y": 43,
      "z": -3,
      "name": "Soil_Seaweed_Block"
    },
    {
      "x": -23,
      "y": 44,
      "z": -3,
      "name": "Soil_Seaweed_Block"
    },
    {
      "x": -23,
      "y": 45,
      "z": -3,
      "name": "Soil_Clay_Lime"
    },
    {
      "x": -23,
      "y": 46,
      "z": -3,
      "name": "Plant_Grass_Sharp"
    },
    {
      "x": -23,
      "y": 12,
      "z": -2,
      "name": "Soil_Clay_Green"
    },
    {
      "x": -23,
      "y": 13,
      "z": -2,
      "name": "Soil_Seaweed_Block"
    },
    {
      "x": -23,
      "y": 14,
      "z": -2,
      "name": "Soil_Seaweed_Block"
    },
    {
      "x": -23,
      "y": 15,
      "z": -2,
      "name": "Soil_Seaweed_Block"
    },
    {
      "x": -23,
      "y": 16,
      "z": -2,
      "name": "Soil_Seaweed_Block"
    },
    {
      "x": -23,
      "y": 17,
      "z": -2,
      "name": "Soil_Seaweed_Block"
    },
    {
      "x": -23,
      "y": 18,
      "z": -2,
      "name": "Soil_Seaweed_Block"
    },
    {
      "x": -23,
      "y": 42,
      "z": -2,
      "name": "Soil_Clay_Green"
    },
    {
      "x": -23,
      "y": 43,
      "z": -2,
      "name": "Soil_Seaweed_Block"
    },
    {
      "x": -23,
      "y": 44,
      "z": -2,
      "name": "Soil_Seaweed_Block"
    },
    {
      "x": -23,
      "y": 45,
      "z": -2,
      "name": "Soil_Clay_Lime"
    },
    {
      "x": -23,
      "y": 46,
      "z": -2,
      "name": "Plant_Grass_Sharp"
    },
    {
      "x": -23,
      "y": 13,
      "z": -1,
      "name": "Soil_Clay_Green"
    },
    {
      "x": -23,
      "y": 14,
      "z": -1,
      "name": "Soil_Seaweed_Block"
    },
    {
      "x": -23,
      "y": 15,
      "z": -1,
      "name": "Soil_Seaweed_Block"
    },
    {
      "x": -23,
      "y": 16,
      "z": -1,
      "name": "Soil_Seaweed_Block"
    },
    {
      "x": -23,
      "y": 42,
      "z": -1,
      "name": "Soil_Clay_Green"
    },
    {
      "x": -23,
      "y": 43,
      "z": -1,
      "name": "Soil_Seaweed_Block"
    },
    {
      "x": -23,
      "y": 44,
      "z": -1,
      "name": "Soil_Seaweed_Block"
    },
    {
      "x": -23,
      "y": 45,
      "z": -1,
      "name": "Soil_Clay_Lime"
    },
    {
      "x": -23,
      "y": 46,
      "z": -1,
      "name": "Plant_Grass_Sharp"
    },
    {
      "x": -23,
      "y": 20,
      "z": 0,
      "name": "Soil_Seaweed_Block"
    },
    {
      "x": -23,
      "y": 33,
      "z": 0,
      "name": "Soil_Seaweed_Block"
    },
    {
      "x": -23,
      "y": 42,
      "z": 0,
      "name": "Soil_Clay_Green"
    },
    {
      "x": -23,
      "y": 43,
      "z": 0,
      "name": "Soil_Seaweed_Block"
    },
    {
      "x": -23,
      "y": 44,
      "z": 0,
      "name": "Soil_Seaweed_Block"
    },
    {
      "x": -23,
      "y": 45,
      "z": 0,
      "name": "Soil_Clay_Lime"
    },
    {
      "x": -23,
      "y": 46,
      "z": 0,
      "name": "Plant_Grass_Sharp"
    },
    {
      "x": -23,
      "y": 20,
      "z": 1,
      "name": "Soil_Clay_Green"
    },
    {
      "x": -23,
      "y": 21,
      "z": 1,
      "name": "Soil_Seaweed_Block"
    },
    {
      "x": -23,
      "y": 32,
      "z": 1,
      "name": "Soil_Clay_Green"
    },
    {
      "x": -23,
      "y": 33,
      "z": 1,
      "name": "Soil_Seaweed_Block"
    },
    {
      "x": -23,
      "y": 34,
      "z": 1,
      "name": "Soil_Seaweed_Block"
    },
    {
      "x": -23,
      "y": 42,
      "z": 1,
      "name": "Soil_Clay_Green"
    },
    {
      "x": -23,
      "y": 43,
      "z": 1,
      "name": "Soil_Seaweed_Block"
    },
    {
      "x": -23,
      "y": 44,
      "z": 1,
      "name": "Soil_Seaweed_Block"
    },
    {
      "x": -23,
      "y": 45,
      "z": 1,
      "name": "Soil_Seaweed_Block"
    },
    {
      "x": -23,
      "y": 20,
      "z": 2,
      "name": "Soil_Clay_Green"
    },
    {
      "x": -23,
      "y": 21,
      "z": 2,
      "name": "Soil_Seaweed_Block"
    },
    {
      "x": -23,
      "y": 33,
      "z": 2,
      "name": "Soil_Seaweed_Block"
    },
    {
      "x": -23,
      "y": 42,
      "z": 2,
      "name": "Soil_Clay_Green"
    },
    {
      "x": -23,
      "y": 43,
      "z": 2,
      "name": "Soil_Seaweed_Block"
    },
    {
      "x": -23,
      "y": 44,
      "z": 2,
      "name": "Soil_Seaweed_Block"
    },
    {
      "x": -23,
      "y": 45,
      "z": 2,
      "name": "Soil_Seaweed_Block"
    },
    {
      "x": -23,
      "y": 21,
      "z": 3,
      "name": "Soil_Clay_Green"
    },
    {
      "x": -23,
      "y": 22,
      "z": 3,
      "name": "Soil_Seaweed_Block"
    },
    {
      "x": -23,
      "y": 37,
      "z": 3,
      "name": "Soil_Seaweed_Block"
    },
    {
      "x": -23,
      "y": 38,
      "z": 3,
      "name": "Soil_Seaweed_Block"
    },
    {
      "x": -23,
      "y": 39,
      "z": 3,
      "name": "Soil_Seaweed_Block"
    },
    {
      "x": -23,
      "y": 40,
      "z": 3,
      "name": "Soil_Clay_Green"
    },
    {
      "x": -23,
      "y": 41,
      "z": 3,
      "name": "Soil_Clay_Green"
    },
    {
      "x": -23,
      "y": 42,
      "z": 3,
      "name": "Soil_Seaweed_Block"
    },
    {
      "x": -23,
      "y": 43,
      "z": 3,
      "name": "Soil_Seaweed_Block"
    },
    {
      "x": -23,
      "y": 44,
      "z": 3,
      "name": "Soil_Seaweed_Block"
    },
    {
      "x": -23,
      "y": 45,
      "z": 3,
      "name": "Soil_Seaweed_Block"
    },
    {
      "x": -23,
      "y": 46,
      "z": 3,
      "name": "Soil_Clay_Lime"
    },
    {
      "x": -23,
      "y": 47,
      "z": 3,
      "name": "Plant_Grass_Sharp"
    },
    {
      "x": -23,
      "y": 21,
      "z": 4,
      "name": "Soil_Clay_Green"
    },
    {
      "x": -23,
      "y": 22,
      "z": 4,
      "name": "Soil_Seaweed_Block"
    },
    {
      "x": -23,
      "y": 37,
      "z": 4,
      "name": "Soil_Seaweed_Block"
    },
    {
      "x": -23,
      "y": 38,
      "z": 4,
      "name": "Soil_Clay_Green"
    },
    {
      "x": -23,
      "y": 39,
      "z": 4,
      "name": "Soil_Clay_Green"
    },
    {
      "x": -23,
      "y": 40,
      "z": 4,
      "name": "Soil_Seaweed_Block"
    },
    {
      "x": -23,
      "y": 41,
      "z": 4,
      "name": "Soil_Seaweed_Block"
    },
    {
      "x": -23,
      "y": 42,
      "z": 4,
      "name": "Soil_Seaweed_Block"
    },
    {
      "x": -23,
      "y": 43,
      "z": 4,
      "name": "Soil_Seaweed_Block"
    },
    {
      "x": -23,
      "y": 44,
      "z": 4,
      "name": "Soil_Seaweed_Block"
    },
    {
      "x": -23,
      "y": 45,
      "z": 4,
      "name": "Soil_Seaweed_Block"
    },
    {
      "x": -23,
      "y": 46,
      "z": 4,
      "name": "Soil_Clay_Lime"
    },
    {
      "x": -23,
      "y": 47,
      "z": 4,
      "name": "Plant_Grass_Sharp"
    },
    {
      "x": -23,
      "y": 22,
      "z": 5,
      "name": "Soil_Clay_Green"
    },
    {
      "x": -23,
      "y": 23,
      "z": 5,
      "name": "Soil_Seaweed_Block"
    },
    {
      "x": -23,
      "y": 29,
      "z": 5,
      "name": "Soil_Seaweed_Block"
    },
    {
      "x": -23,
      "y": 30,
      "z": 5,
      "name": "Soil_Seaweed_Block"
    },
    {
      "x": -23,
      "y": 39,
      "z": 5,
      "name": "Soil_Clay_Green"
    },
    {
      "x": -23,
      "y": 40,
      "z": 5,
      "name": "Soil_Seaweed_Block"
    },
    {
      "x": -23,
      "y": 41,
      "z": 5,
      "name": "Soil_Seaweed_Block"
    },
    {
      "x": -23,
      "y": 42,
      "z": 5,
      "name": "Soil_Seaweed_Block"
    },
    {
      "x": -23,
      "y": 43,
      "z": 5,
      "name": "Soil_Seaweed_Block"
    },
    {
      "x": -23,
      "y": 44,
      "z": 5,
      "name": "Soil_Seaweed_Block"
    },
    {
      "x": -23,
      "y": 45,
      "z": 5,
      "name": "Soil_Seaweed_Block"
    },
    {
      "x": -23,
      "y": 46,
      "z": 5,
      "name": "Soil_Clay_Lime"
    },
    {
      "x": -23,
      "y": 47,
      "z": 5,
      "name": "Plant_Grass_Sharp"
    },
    {
      "x": -23,
      "y": 23,
      "z": 6,
      "name": "Soil_Clay_Green"
    },
    {
      "x": -23,
      "y": 24,
      "z": 6,
      "name": "Soil_Seaweed_Block"
    },
    {
      "x": -23,
      "y": 25,
      "z": 6,
      "name": "Soil_Seaweed_Block"
    },
    {
      "x": -23,
      "y": 27,
      "z": 6,
      "name": "Soil_Clay_Green"
    },
    {
      "x": -23,
      "y": 28,
      "z": 6,
      "name": "Soil_Clay_Green"
    },
    {
      "x": -23,
      "y": 29,
      "z": 6,
      "name": "Soil_Seaweed_Block"
    },
    {
      "x": -23,
      "y": 30,
      "z": 6,
      "name": "Soil_Seaweed_Block"
    },
    {
      "x": -23,
      "y": 40,
      "z": 6,
      "name": "Soil_Clay_Green"
    },
    {
      "x": -23,
      "y": 41,
      "z": 6,
      "name": "Soil_Seaweed_Block"
    },
    {
      "x": -23,
      "y": 42,
      "z": 6,
      "name": "Soil_Seaweed_Block"
    },
    {
      "x": -23,
      "y": 43,
      "z": 6,
      "name": "Soil_Seaweed_Block"
    },
    {
      "x": -23,
      "y": 44,
      "z": 6,
      "name": "Soil_Seaweed_Block"
    },
    {
      "x": -23,
      "y": 45,
      "z": 6,
      "name": "Soil_Seaweed_Block"
    },
    {
      "x": -23,
      "y": 46,
      "z": 6,
      "name": "Soil_Clay_Lime"
    },
    {
      "x": -23,
      "y": 47,
      "z": 6,
      "name": "Plant_Grass_Sharp"
    },
    {
      "x": -23,
      "y": 23,
      "z": 7,
      "name": "Soil_Clay_Green"
    },
    {
      "x": -23,
      "y": 24,
      "z": 7,
      "name": "Soil_Seaweed_Block"
    },
    {
      "x": -23,
      "y": 25,
      "z": 7,
      "name": "Soil_Seaweed_Block"
    },
    {
      "x": -23,
      "y": 26,
      "z": 7,
      "name": "Soil_Seaweed_Block"
    },
    {
      "x": -23,
      "y": 27,
      "z": 7,
      "name": "Soil_Seaweed_Block"
    },
    {
      "x": -23,
      "y": 28,
      "z": 7,
      "name": "Soil_Seaweed_Block"
    },
    {
      "x": -23,
      "y": 29,
      "z": 7,
      "name": "Soil_Seaweed_Block"
    },
    {
      "x": -23,
      "y": 30,
      "z": 7,
      "name": "Soil_Clay_Lime"
    },
    {
      "x": -23,
      "y": 31,
      "z": 7,
      "name": "Plant_Grass_Sharp"
    },
    {
      "x": -23,
      "y": 40,
      "z": 7,
      "name": "Soil_Clay_Green"
    },
    {
      "x": -23,
      "y": 41,
      "z": 7,
      "name": "Soil_Seaweed_Block"
    },
    {
      "x": -23,
      "y": 42,
      "z": 7,
      "name": "Soil_Seaweed_Block"
    },
    {
      "x": -23,
      "y": 43,
      "z": 7,
      "name": "Soil_Seaweed_Block"
    },
    {
      "x": -23,
      "y": 44,
      "z": 7,
      "name": "Soil_Seaweed_Block"
    },
    {
      "x": -23,
      "y": 45,
      "z": 7,
      "name": "Soil_Seaweed_Block"
    },
    {
      "x": -23,
      "y": 46,
      "z": 7,
      "name": "Soil_Clay_Lime"
    },
    {
      "x": -23,
      "y": 47,
      "z": 7,
      "name": "Plant_Grass_Sharp"
    },
    {
      "x": -23,
      "y": 23,
      "z": 8,
      "name": "Soil_Clay_Green"
    },
    {
      "x": -23,
      "y": 24,
      "z": 8,
      "name": "Soil_Seaweed_Block"
    },
    {
      "x": -23,
      "y": 25,
      "z": 8,
      "name": "Soil_Seaweed_Block"
    },
    {
      "x": -23,
      "y": 26,
      "z": 8,
      "name": "Soil_Seaweed_Block"
    },
    {
      "x": -23,
      "y": 27,
      "z": 8,
      "name": "Soil_Seaweed_Block"
    },
    {
      "x": -23,
      "y": 28,
      "z": 8,
      "name": "Soil_Seaweed_Block"
    },
    {
      "x": -23,
      "y": 29,
      "z": 8,
      "name": "Soil_Seaweed_Block"
    },
    {
      "x": -23,
      "y": 30,
      "z": 8,
      "name": "Soil_Clay_Lime"
    },
    {
      "x": -23,
      "y": 31,
      "z": 8,
      "name": "Plant_Grass_Sharp"
    },
    {
      "x": -23,
      "y": 39,
      "z": 8,
      "name": "Soil_Clay_Green"
    },
    {
      "x": -23,
      "y": 40,
      "z": 8,
      "name": "Soil_Clay_Green"
    },
    {
      "x": -23,
      "y": 41,
      "z": 8,
      "name": "Soil_Clay_Green"
    },
    {
      "x": -23,
      "y": 42,
      "z": 8,
      "name": "Soil_Clay_Green"
    },
    {
      "x": -23,
      "y": 43,
      "z": 8,
      "name": "Soil_Seaweed_Block"
    },
    {
      "x": -23,
      "y": 44,
      "z": 8,
      "name": "Soil_Seaweed_Block"
    },
    {
      "x": -23,
      "y": 45,
      "z": 8,
      "name": "Soil_Seaweed_Block"
    },
    {
      "x": -23,
      "y": 22,
      "z": 9,
      "name": "Soil_Clay_Green"
    },
    {
      "x": -23,
      "y": 23,
      "z": 9,
      "name": "Soil_Seaweed_Block"
    },
    {
      "x": -23,
      "y": 24,
      "z": 9,
      "name": "Soil_Seaweed_Block"
    },
    {
      "x": -23,
      "y": 25,
      "z": 9,
      "name": "Soil_Seaweed_Block"
    },
    {
      "x": -23,
      "y": 26,
      "z": 9,
      "name": "Soil_Seaweed_Block"
    },
    {
      "x": -23,
      "y": 27,
      "z": 9,
      "name": "Soil_Seaweed_Block"
    },
    {
      "x": -23,
      "y": 28,
      "z": 9,
      "name": "Soil_Seaweed_Block"
    },
    {
      "x": -23,
      "y": 29,
      "z": 9,
      "name": "Soil_Seaweed_Block"
    },
    {
      "x": -23,
      "y": 30,
      "z": 9,
      "name": "Soil_Clay_Lime"
    },
    {
      "x": -23,
      "y": 31,
      "z": 9,
      "name": "Plant_Grass_Sharp"
    },
    {
      "x": -23,
      "y": 38,
      "z": 9,
      "name": "Soil_Seaweed_Block"
    },
    {
      "x": -23,
      "y": 39,
      "z": 9,
      "name": "Soil_Seaweed_Block"
    },
    {
      "x": -23,
      "y": 40,
      "z": 9,
      "name": "Soil_Seaweed_Block"
    },
    {
      "x": -23,
      "y": 41,
      "z": 9,
      "name": "Soil_Seaweed_Block"
    },
    {
      "x": -23,
      "y": 22,
      "z": 10,
      "name": "Soil_Clay_Green"
    },
    {
      "x": -23,
      "y": 23,
      "z": 10,
      "name": "Soil_Seaweed_Block"
    },
    {
      "x": -23,
      "y": 24,
      "z": 10,
      "name": "Soil_Seaweed_Block"
    },
    {
      "x": -23,
      "y": 25,
      "z": 10,
      "name": "Soil_Seaweed_Block"
    },
    {
      "x": -23,
      "y": 26,
      "z": 10,
      "name": "Soil_Seaweed_Block"
    },
    {
      "x": -23,
      "y": 27,
      "z": 10,
      "name": "Soil_Clay_Lime"
    },
    {
      "x": -23,
      "y": 28,
      "z": 10,
      "name": "Soil_Seaweed_Block"
    },
    {
      "x": -23,
      "y": 29,
      "z": 10,
      "name": "Soil_Seaweed_Block"
    },
    {
      "x": -23,
      "y": 30,
      "z": 10,
      "name": "Soil_Seaweed_Block"
    },
    {
      "x": -23,
      "y": 31,
      "z": 10,
      "name": "Soil_Seaweed_Block"
    },
    {
      "x": -23,
      "y": 32,
      "z": 10,
      "name": "Soil_Seaweed_Block"
    },
    {
      "x": -23,
      "y": 36,
      "z": 10,
      "name": "Soil_Seaweed_Block"
    },
    {
      "x": -23,
      "y": 37,
      "z": 10,
      "name": "Soil_Seaweed_Block"
    },
    {
      "x": -23,
      "y": 38,
      "z": 10,
      "name": "Soil_Seaweed_Block"
    },
    {
      "x": -23,
      "y": 39,
      "z": 10,
      "name": "Soil_Seaweed_Block"
    },
    {
      "x": -23,
      "y": 21,
      "z": 11,
      "name": "Soil_Clay_Green"
    },
    {
      "x": -23,
      "y": 22,
      "z": 11,
      "name": "Soil_Seaweed_Block"
    },
    {
      "x": -23,
      "y": 23,
      "z": 11,
      "name": "Soil_Seaweed_Block"
    },
    {
      "x": -23,
      "y": 24,
      "z": 11,
      "name": "Soil_Seaweed_Block"
    },
    {
      "x": -23,
      "y": 25,
      "z": 11,
      "name": "Soil_Seaweed_Block"
    },
    {
      "x": -23,
      "y": 26,
      "z": 11,
      "name": "Soil_Clay_Lime"
    },
    {
      "x": -23,
      "y": 27,
      "z": 11,
      "name": "Plant_Grass_Sharp"
    },
    {
      "x": -23,
      "y": 30,
      "z": 11,
      "name": "Soil_Clay_Green"
    },
    {
      "x": -23,
      "y": 31,
      "z": 11,
      "name": "Soil_Clay_Green"
    },
    {
      "x": -23,
      "y": 32,
      "z": 11,
      "name": "Soil_Clay_Green"
    },
    {
      "x": -23,
      "y": 33,
      "z": 11,
      "name": "Soil_Seaweed_Block"
    },
    {
      "x": -23,
      "y": 34,
      "z": 11,
      "name": "Soil_Seaweed_Block"
    },
    {
      "x": -23,
      "y": 35,
      "z": 11,
      "name": "Soil_Seaweed_Block"
    },
    {
      "x": -23,
      "y": 36,
      "z": 11,
      "name": "Soil_Seaweed_Block"
    },
    {
      "x": -23,
      "y": 37,
      "z": 11,
      "name": "Soil_Seaweed_Block"
    },
    {
      "x": -23,
      "y": 38,
      "z": 11,
      "name": "Soil_Seaweed_Block"
    },
    {
      "x": -23,
      "y": 21,
      "z": 12,
      "name": "Soil_Clay_Green"
    },
    {
      "x": -23,
      "y": 22,
      "z": 12,
      "name": "Soil_Clay_Green"
    },
    {
      "x": -23,
      "y": 23,
      "z": 12,
      "name": "Soil_Seaweed_Block"
    },
    {
      "x": -23,
      "y": 24,
      "z": 12,
      "name": "Soil_Seaweed_Block"
    },
    {
      "x": -23,
      "y": 25,
      "z": 12,
      "name": "Soil_Seaweed_Block"
    },
    {
      "x": -23,
      "y": 26,
      "z": 12,
      "name": "Soil_Clay_Lime"
    },
    {
      "x": -23,
      "y": 27,
      "z": 12,
      "name": "Plant_Grass_Sharp"
    },
    {
      "x": -23,
      "y": 32,
      "z": 12,
      "name": "Soil_Clay_Green"
    },
    {
      "x": -23,
      "y": 33,
      "z": 12,
      "name": "Soil_Clay_Green"
    },
    {
      "x": -23,
      "y": 34,
      "z": 12,
      "name": "Soil_Seaweed_Block"
    },
    {
      "x": -23,
      "y": 35,
      "z": 12,
      "name": "Soil_Seaweed_Block"
    },
    {
      "x": -23,
      "y": 23,
      "z": 13,
      "name": "Soil_Seaweed_Block"
    },
    {
      "x": -23,
      "y": 24,
      "z": 13,
      "name": "Soil_Seaweed_Block"
    },
    {
      "x": -23,
      "y": 25,
      "z": 13,
      "name": "Soil_Seaweed_Block"
    },
    {
      "x": -22,
      "y": 29,
      "z": -16,
      "name": "Soil_Clay_Green"
    },
    {
      "x": -22,
      "y": 30,
      "z": -16,
      "name": "Soil_Seaweed_Block"
    },
    {
      "x": -22,
      "y": 31,
      "z": -16,
      "name": "Soil_Seaweed_Block"
    },
    {
      "x": -22,
      "y": 28,
      "z": -15,
      "name": "Soil_Clay_Green"
    },
    {
      "x": -22,
      "y": 29,
      "z": -15,
      "name": "Soil_Seaweed_Block"
    },
    {
      "x": -22,
      "y": 30,
      "z": -15,
      "name": "Soil_Seaweed_Block"
    },
    {
      "x": -22,
      "y": 31,
      "z": -15,
      "name": "Soil_Seaweed_Block"
    },
    {
      "x": -22,
      "y": 32,
      "z": -15,
      "name": "Soil_Seaweed_Block"
    },
    {
      "x": -22,
      "y": 36,
      "z": -15,
      "name": "Soil_Clay_Green"
    },
    {
      "x": -22,
      "y": 37,
      "z": -15,
      "name": "Soil_Seaweed_Block"
    },
    {
      "x": -22,
      "y": 38,
      "z": -15,
      "name": "Soil_Seaweed_Block"
    },
    {
      "x": -22,
      "y": 28,
      "z": -14,
      "name": "Soil_Clay_Green"
    },
    {
      "x": -22,
      "y": 29,
      "z": -14,
      "name": "Soil_Seaweed_Block"
    },
    {
      "x": -22,
      "y": 30,
      "z": -14,
      "name": "Soil_Seaweed_Block"
    },
    {
      "x": -22,
      "y": 31,
      "z": -14,
      "name": "Soil_Seaweed_Block"
    },
    {
      "x": -22,
      "y": 32,
      "z": -14,
      "name": "Soil_Seaweed_Block"
    },
    {
      "x": -22,
      "y": 33,
      "z": -14,
      "name": "Soil_Seaweed_Block"
    },
    {
      "x": -22,
      "y": 34,
      "z": -14,
      "name": "Soil_Seaweed_Block"
    },
    {
      "x": -22,
      "y": 35,
      "z": -14,
      "name": "Soil_Clay_Green"
    },
    {
      "x": -22,
      "y": 36,
      "z": -14,
      "name": "Soil_Seaweed_Block"
    },
    {
      "x": -22,
      "y": 37,
      "z": -14,
      "name": "Soil_Seaweed_Block"
    },
    {
      "x": -22,
      "y": 38,
      "z": -14,
      "name": "Soil_Seaweed_Block"
    },
    {
      "x": -22,
      "y": 39,
      "z": -14,
      "name": "Soil_Clay_Lime"
    },
    {
      "x": -22,
      "y": 40,
