{
  "version": 8,
  "blockIdVersion": 10,
  "anchorX": 0,
  "anchorY": 12,
  "anchorZ": 0,
  "blocks": [
    {
      "x": -30,
      "y": 46,
      "z": 13,
      "name": "Soil_Seaweed_Block"
    },
    {
      "x": -29,
      "y": 45,
      "z": 11,
      "name": "Soil_Seaweed_Block"
    },
    {
      "x": -29,
      "y": 45,
      "z": 12,
      "name": "Soil_Seaweed_Block"
    },
    {
      "x": -29,
      "y": 46,
      "z": 12,
      "name": "Soil_Seaweed_Block"
    },
    {
      "x": -28,
      "y": 44,
      "z": 10,
      "name": "Plant_Moss_Block_Green"
    },
    {
      "x": -28,
      "y": 45,
      "z": 10,
      "name": "Soil_Seaweed_Block"
    },
    {
      "x": -28,
      "y": 44,
      "z": 11,
      "name": "Plant_Moss_Block_Green"
    },
    {
      "x": -28,
      "y": 45,
      "z": 11,
      "name": "Soil_Seaweed_Block"
    },
    {
      "x": -28,
      "y": 46,
      "z": 11,
      "name": "Soil_Clay_Lime"
    },
    {
      "x": -28,
      "y": 47,
      "z": 11,
      "name": "Plant_Grass_Sharp"
    },
    {
      "x": -28,
      "y": 45,
      "z": 12,
      "name": "Soil_Seaweed_Block"
    },
    {
      "x": -27,
      "y": 44,
      "z": 9,
      "name": "Soil_Seaweed_Block"
    },
    {
      "x": -27,
      "y": 43,
      "z": 10,
      "name": "Plant_Moss_Block_Green"
    },
    {
      "x": -27,
      "y": 44,
      "z": 10,
      "name": "Soil_Seaweed_Block"
    },
    {
      "x": -27,
      "y": 45,
      "z": 10,
      "name": "Soil_Clay_Lime"
    },
    {
      "x": -27,
      "y": 46,
      "z": 10,
      "name": "Plant_Grass_Sharp"
    },
    {
      "x": -27,
      "y": 43,
      "z": 11,
      "name": "Plant_Moss_Block_Green"
    },
    {
      "x": -27,
      "y": 44,
      "z": 11,
      "name": "Soil_Seaweed_Block"
    },
    {
      "x": -27,
      "y": 45,
      "z": 11,
      "name": "Soil_Seaweed_Block"
    },
    {
      "x": -27,
      "y": 46,
      "z": 11,
      "name": "Soil_Clay_Lime"
    },
    {
      "x": -27,
      "y": 47,
      "z": 11,
      "name": "Plant_Grass_Sharp"
    },
    {
      "x": -27,
      "y": 45,
      "z": 12,
      "name": "Soil_Seaweed_Block"
    },
    {
      "x": -26,
      "y": 44,
      "z": 8,
      "name": "Soil_Seaweed_Block"
    },
    {
      "x": -26,
      "y": 43,
      "z": 9,
      "name": "Plant_Moss_Block_Green"
    },
    {
      "x": -26,
      "y": 44,
      "z": 9,
      "name": "Soil_Seaweed_Block"
    },
    {
      "x": -26,
      "y": 45,
      "z": 9,
      "name": "Soil_Clay_Lime"
    },
    {
      "x": -26,
      "y": 46,
      "z": 9,
      "name": "Plant_Grass_Sharp"
    },
    {
      "x": -26,
      "y": 42,
      "z": 10,
      "name": "Plant_Moss_Block_Green"
    },
    {
      "x": -26,
      "y": 43,
      "z": 10,
      "name": "Soil_Seaweed_Block"
    },
    {
      "x": -26,
      "y": 44,
      "z": 10,
      "name": "Soil_Seaweed_Block"
    },
    {
      "x": -26,
      "y": 45,
      "z": 10,
      "name": "Soil_Seaweed_Block"
    },
    {
      "x": -26,
      "y": 46,
      "z": 10,
      "name": "Soil_Clay_Lime"
    },
    {
      "x": -26,
      "y": 47,
      "z": 10,
      "name": "Plant_Grass_Sharp"
    },
    {
      "x": -26,
      "y": 43,
      "z": 11,
      "name": "Plant_Moss_Block_Green"
    },
    {
      "x": -26,
      "y": 44,
      "z": 11,
      "name": "Soil_Seaweed_Block"
    },
    {
      "x": -26,
      "y": 45,
      "z": 11,
      "name": "Soil_Clay_Lime"
    },
    {
      "x": -26,
      "y": 46,
      "z": 11,
      "name": "Plant_Grass_Sharp"
    },
    {
      "x": -25,
      "y": 22,
      "z": -6,
      "name": "Plant_Moss_Cave_Green",
      "support": 15,
      "rotation": 8
    },
    {
      "x": -25,
      "y": 23,
      "z": -6,
      "name": "Plant_Moss_Block_Green"
    },
    {
      "x": -25,
      "y": 24,
      "z": -6,
      "name": "Soil_Seaweed_Block"
    },
    {
      "x": -25,
      "y": 25,
      "z": -6,
      "name": "Soil_Seaweed_Block"
    },
    {
      "x": -25,
      "y": 23,
      "z": -5,
      "name": "Plant_Moss_Block_Green"
    },
    {
      "x": -25,
      "y": 24,
      "z": -5,
      "name": "Soil_Seaweed_Block"
    },
    {
      "x": -25,
      "y": 25,
      "z": -5,
      "name": "Soil_Seaweed_Block"
    },
    {
      "x": -25,
      "y": 23,
      "z": -4,
      "name": "Plant_Moss_Block_Green"
    },
    {
      "x": -25,
      "y": 24,
      "z": -4,
      "name": "Soil_Seaweed_Block"
    },
    {
      "x": -25,
      "y": 25,
      "z": -4,
      "name": "Soil_Seaweed_Block"
    },
    {
      "x": -25,
      "y": 43,
      "z": 8,
      "name": "Soil_Seaweed_Block"
    },
    {
      "x": -25,
      "y": 44,
      "z": 8,
      "name": "Soil_Seaweed_Block"
    },
    {
      "x": -25,
      "y": 42,
      "z": 9,
      "name": "Plant_Moss_Block_Green"
    },
    {
      "x": -25,
      "y": 43,
      "z": 9,
      "name": "Soil_Seaweed_Block"
    },
    {
      "x": -25,
      "y": 44,
      "z": 9,
      "name": "Soil_Seaweed_Block"
    },
    {
      "x": -25,
      "y": 45,
      "z": 9,
      "name": "Soil_Clay_Lime"
    },
    {
      "x": -25,
      "y": 46,
      "z": 9,
      "name": "Plant_Grass_Sharp"
    },
    {
      "x": -25,
      "y": 42,
      "z": 10,
      "name": "Plant_Moss_Block_Green"
    },
    {
      "x": -25,
      "y": 43,
      "z": 10,
      "name": "Soil_Seaweed_Block"
    },
    {
      "x": -25,
      "y": 44,
      "z": 10,
      "name": "Soil_Seaweed_Block"
    },
    {
      "x": -25,
      "y": 45,
      "z": 10,
      "name": "Soil_Clay_Lime"
    },
    {
      "x": -25,
      "y": 46,
      "z": 10,
      "name": "Plant_Grass_Sharp"
    },
    {
      "x": -25,
      "y": 43,
      "z": 11,
      "name": "Plant_Moss_Block_Green"
    },
    {
      "x": -25,
      "y": 44,
      "z": 11,
      "name": "Soil_Seaweed_Block"
    },
    {
      "x": -24,
      "y": 23,
      "z": -7,
      "name": "Plant_Moss_Block_Green"
    },
    {
      "x": -24,
      "y": 24,
      "z": -7,
      "name": "Soil_Seaweed_Block"
    },
    {
      "x": -24,
      "y": 25,
      "z": -7,
      "name": "Soil_Seaweed_Block"
    },
    {
      "x": -24,
      "y": 21,
      "z": -6,
      "name": "Plant_Moss_Cave_Green",
      "support": 15,
      "rotation": 8
    },
    {
      "x": -24,
      "y": 22,
      "z": -6,
      "name": "Plant_Moss_Block_Green"
    },
    {
      "x": -24,
      "y": 23,
      "z": -6,
      "name": "Soil_Seaweed_Block"
    },
    {
      "x": -24,
      "y": 24,
      "z": -6,
      "name": "Soil_Seaweed_Block"
    },
    {
      "x": -24,
      "y": 25,
      "z": -6,
      "name": "Soil_Seaweed_Block"
    },
    {
      "x": -24,
      "y": 26,
      "z": -6,
      "name": "Soil_Seaweed_Block"
    },
    {
      "x": -24,
      "y": 21,
      "z": -5,
      "name": "Plant_Moss_Cave_Green",
      "support": 15,
      "rotation": 8
    },
    {
      "x": -24,
      "y": 22,
      "z": -5,
      "name": "Plant_Moss_Block_Green"
    },
    {
      "x": -24,
      "y": 23,
      "z": -5,
      "name": "Soil_Seaweed_Block"
    },
    {
      "x": -24,
      "y": 24,
      "z": -5,
      "name": "Soil_Seaweed_Block"
    },
    {
      "x": -24,
      "y": 25,
      "z": -5,
      "name": "Soil_Seaweed_Block"
    },
    {
      "x": -24,
      "y": 26,
      "z": -5,
      "name": "Soil_Seaweed_Block"
    },
    {
      "x": -24,
      "y": 22,
      "z": -4,
      "name": "Plant_Moss_Block_Green"
    },
    {
      "x": -24,
      "y": 23,
      "z": -4,
      "name": "Soil_Seaweed_Block"
    },
    {
      "x": -24,
      "y": 24,
      "z": -4,
      "name": "Soil_Seaweed_Block"
    },
    {
      "x": -24,
      "y": 25,
      "z": -4,
      "name": "Soil_Seaweed_Block"
    },
    {
      "x": -24,
      "y": 26,
      "z": -4,
      "name": "Soil_Seaweed_Block"
    },
    {
      "x": -24,
      "y": 23,
      "z": -3,
      "name": "Plant_Moss_Block_Green"
    },
    {
      "x": -24,
      "y": 24,
      "z": -3,
      "name": "Soil_Seaweed_Block"
    },
    {
      "x": -24,
      "y": 25,
      "z": -3,
      "name": "Soil_Seaweed_Block"
    },
    {
      "x": -24,
      "y": 37,
      "z": 6,
      "name": "Soil_Seaweed_Block"
    },
    {
      "x": -24,
      "y": 33,
      "z": 7,
      "name": "Soil_Seaweed_Block"
    },
    {
      "x": -24,
      "y": 34,
      "z": 7,
      "name": "Soil_Seaweed_Block"
    },
    {
      "x": -24,
      "y": 35,
      "z": 7,
      "name": "Soil_Seaweed_Block"
    },
    {
      "x": -24,
      "y": 36,
      "z": 7,
      "name": "Soil_Seaweed_Block"
    },
    {
      "x": -24,
      "y": 37,
      "z": 7,
      "name": "Soil_Seaweed_Block"
    },
    {
      "x": -24,
      "y": 38,
      "z": 7,
      "name": "Soil_Seaweed_Block"
    },
    {
      "x": -24,
      "y": 43,
      "z": 7,
      "name": "Soil_Seaweed_Block"
    },
    {
      "x": -24,
      "y": 32,
      "z": 8,
      "name": "Plant_Moss_Block_Green"
    },
    {
      "x": -24,
      "y": 33,
      "z": 8,
      "name": "Soil_Seaweed_Block"
    },
    {
      "x": -24,
      "y": 34,
      "z": 8,
      "name": "Soil_Seaweed_Block"
    },
    {
      "x": -24,
      "y": 35,
      "z": 8,
      "name": "Soil_Seaweed_Block"
    },
    {
      "x": -24,
      "y": 36,
      "z": 8,
      "name": "Soil_Seaweed_Block"
    },
    {
      "x": -24,
      "y": 37,
      "z": 8,
      "name": "Soil_Seaweed_Block"
    },
    {
      "x": -24,
      "y": 38,
      "z": 8,
      "name": "Soil_Seaweed_Block"
    },
    {
      "x": -24,
      "y": 39,
      "z": 8,
      "name": "Soil_Seaweed_Block"
    },
    {
      "x": -24,
      "y": 41,
      "z": 8,
      "name": "Plant_Moss_Block_Green"
    },
    {
      "x": -24,
      "y": 42,
      "z": 8,
      "name": "Soil_Seaweed_Block"
    },
    {
      "x": -24,
      "y": 43,
      "z": 8,
      "name": "Soil_Seaweed_Block"
    },
    {
      "x": -24,
      "y": 44,
      "z": 8,
      "name": "Soil_Clay_Lime"
    },
    {
      "x": -24,
      "y": 45,
      "z": 8,
      "name": "Plant_Grass_Sharp"
    },
    {
      "x": -24,
      "y": 32,
      "z": 9,
      "name": "Plant_Moss_Block_Green"
    },
    {
      "x": -24,
      "y": 33,
      "z": 9,
      "name": "Soil_Seaweed_Block"
    },
    {
      "x": -24,
      "y": 34,
      "z": 9,
      "name": "Soil_Seaweed_Block"
    },
    {
      "x": -24,
      "y": 35,
      "z": 9,
      "name": "Soil_Seaweed_Block"
    },
    {
      "x": -24,
      "y": 36,
      "z": 9,
      "name": "Soil_Seaweed_Block"
    },
    {
      "x": -24,
      "y": 37,
      "z": 9,
      "name": "Soil_Seaweed_Block"
    },
    {
      "x": -24,
      "y": 38,
      "z": 9,
      "name": "Soil_Seaweed_Block"
    },
    {
      "x": -24,
      "y": 40,
      "z": 9,
      "name": "Soil_Seaweed_Block"
    },
    {
      "x": -24,
      "y": 41,
      "z": 9,
      "name": "Plant_Moss_Block_Green"
    },
    {
      "x": -24,
      "y": 42,
      "z": 9,
      "name": "Soil_Seaweed_Block"
    },
    {
      "x": -24,
      "y": 43,
      "z": 9,
      "name": "Soil_Seaweed_Block"
    },
    {
      "x": -24,
      "y": 44,
      "z": 9,
      "name": "Soil_Seaweed_Block"
    },
    {
      "x": -24,
      "y": 45,
      "z": 9,
      "name": "Soil_Clay_Lime"
    },
    {
      "x": -24,
      "y": 46,
      "z": 9,
      "name": "Plant_Grass_Sharp"
    },
    {
      "x": -24,
      "y": 32,
      "z": 10,
      "name": "Soil_Seaweed_Block"
    },
    {
      "x": -24,
      "y": 33,
      "z": 10,
      "name": "Soil_Seaweed_Block"
    },
    {
      "x": -24,
      "y": 34,
      "z": 10,
      "name": "Soil_Seaweed_Block"
    },
    {
      "x": -24,
      "y": 35,
      "z": 10,
      "name": "Soil_Seaweed_Block"
    },
    {
      "x": -24,
      "y": 41,
      "z": 10,
      "name": "Plant_Moss_Block_Green"
    },
    {
      "x": -24,
      "y": 42,
      "z": 10,
      "name": "Plant_Moss_Block_Green"
    },
    {
      "x": -24,
      "y": 43,
      "z": 10,
      "name": "Soil_Seaweed_Block"
    },
    {
      "x": -24,
      "y": 44,
      "z": 10,
      "name": "Soil_Clay_Lime"
    },
    {
      "x": -24,
      "y": 45,
      "z": 10,
      "name": "Plant_Grass_Sharp"
    },
    {
      "x": -24,
      "y": 43,
      "z": 11,
      "name": "Soil_Seaweed_Block"
    },
    {
      "x": -23,
      "y": 32,
      "z": -13,
      "name": "Plant_Moss_Block_Green"
    },
    {
      "x": -23,
      "y": 33,
      "z": -13,
      "name": "Soil_Seaweed_Block"
    },
    {
      "x": -23,
      "y": 34,
      "z": -13,
      "name": "Soil_Seaweed_Block"
    },
    {
      "x": -23,
      "y": 32,
      "z": -12,
      "name": "Plant_Moss_Block_Green"
    },
    {
      "x": -23,
      "y": 33,
      "z": -12,
      "name": "Soil_Seaweed_Block"
    },
    {
      "x": -23,
      "y": 34,
      "z": -12,
      "name": "Soil_Seaweed_Block"
    },
    {
      "x": -23,
      "y": 32,
      "z": -11,
      "name": "Plant_Moss_Block_Green"
    },
    {
      "x": -23,
      "y": 33,
      "z": -11,
      "name": "Soil_Seaweed_Block"
    },
    {
      "x": -23,
      "y": 34,
      "z": -11,
      "name": "Soil_Seaweed_Block"
    },
    {
      "x": -23,
      "y": 33,
      "z": -10,
      "name": "Soil_Seaweed_Block"
    },
    {
      "x": -23,
      "y": 23,
      "z": -7,
      "name": "Plant_Moss_Block_Green"
    },
    {
      "x": -23,
      "y": 24,
      "z": -7,
      "name": "Soil_Seaweed_Block"
    },
    {
      "x": -23,
      "y": 25,
      "z": -7,
      "name": "Soil_Seaweed_Block"
    },
    {
      "x": -23,
      "y": 26,
      "z": -7,
      "name": "Soil_Seaweed_Block"
    },
    {
      "x": -23,
      "y": 22,
      "z": -6,
      "name": "Plant_Moss_Block_Green"
    },
    {
      "x": -23,
      "y": 23,
      "z": -6,
      "name": "Soil_Seaweed_Block"
    },
    {
      "x": -23,
      "y": 24,
      "z": -6,
      "name": "Soil_Seaweed_Block"
    },
    {
      "x": -23,
      "y": 25,
      "z": -6,
      "name": "Soil_Seaweed_Block"
    },
    {
      "x": -23,
      "y": 26,
      "z": -6,
      "name": "Soil_Seaweed_Block"
    },
    {
      "x": -23,
      "y": 27,
      "z": -6,
      "name": "Soil_Seaweed_Block"
    },
    {
      "x": -23,
      "y": 21,
      "z": -5,
      "name": "Plant_Moss_Cave_Green",
      "support": 15,
      "rotation": 8
    },
    {
      "x": -23,
      "y": 22,
      "z": -5,
      "name": "Plant_Moss_Block_Green"
    },
    {
      "x": -23,
      "y": 23,
      "z": -5,
      "name": "Soil_Seaweed_Block"
    },
    {
      "x": -23,
      "y": 24,
      "z": -5,
      "name": "Soil_Seaweed_Block"
    },
    {
      "x": -23,
      "y": 25,
      "z": -5,
      "name": "Soil_Seaweed_Block"
    },
    {
      "x": -23,
      "y": 26,
      "z": -5,
      "name": "Soil_Seaweed_Block"
    },
    {
      "x": -23,
      "y": 27,
      "z": -5,
      "name": "Soil_Clay_Lime"
    },
    {
      "x": -23,
      "y": 28,
      "z": -5,
      "name": "Plant_Grass_Sharp"
    },
    {
      "x": -23,
      "y": 22,
      "z": -4,
      "name": "Plant_Moss_Block_Green"
    },
    {
      "x": -23,
      "y": 23,
      "z": -4,
      "name": "Soil_Seaweed_Block"
    },
    {
      "x": -23,
      "y": 24,
      "z": -4,
      "name": "Soil_Seaweed_Block"
    },
    {
      "x": -23,
      "y": 25,
      "z": -4,
      "name": "Soil_Seaweed_Block"
    },
    {
      "x": -23,
      "y": 26,
      "z": -4,
      "name": "Soil_Clay_Lime"
    },
    {
      "x": -23,
      "y": 27,
      "z": -4,
      "name": "Plant_Grass_Sharp"
    },
    {
      "x": -23,
      "y": 35,
      "z": -4,
      "name": "Plant_Moss_Block_Green"
    },
    {
      "x": -23,
      "y": 36,
      "z": -4,
      "name": "Soil_Seaweed_Block"
    },
    {
      "x": -23,
      "y": 23,
      "z": -3,
      "name": "Plant_Moss_Block_Green"
    },
    {
      "x": -23,
      "y": 24,
      "z": -3,
      "name": "Soil_Seaweed_Block"
    },
    {
      "x": -23,
      "y": 25,
      "z": -3,
      "name": "Soil_Seaweed_Block"
    },
    {
      "x": -23,
      "y": 26,
      "z": -3,
      "name": "Soil_Seaweed_Block"
    },
    {
      "x": -23,
      "y": 35,
      "z": -3,
      "name": "Plant_Moss_Block_Green"
    },
    {
      "x": -23,
      "y": 36,
      "z": -3,
      "name": "Soil_Seaweed_Block"
    },
    {
      "x": -23,
      "y": 24,
      "z": -2,
      "name": "Soil_Seaweed_Block"
    },
    {
      "x": -23,
      "y": 25,
      "z": -2,
      "name": "Soil_Seaweed_Block"
    },
    {
      "x": -23,
      "y": 26,
      "z": -2,
      "name": "Soil_Seaweed_Block"
    },
    {
      "x": -23,
      "y": 35,
      "z": -2,
      "name": "Plant_Moss_Block_Green"
    },
    {
      "x": -23,
      "y": 36,
      "z": -2,
      "name": "Soil_Seaweed_Block"
    },
    {
      "x": -23,
      "y": 35,
      "z": -1,
      "name": "Plant_Moss_Block_Green"
    },
    {
      "x": -23,
      "y": 36,
      "z": -1,
      "name": "Soil_Seaweed_Block"
    },
    {
      "x": -23,
      "y": 37,
      "z": -1,
      "name": "Soil_Clay_Lime"
    },
    {
      "x": -23,
      "y": 38,
      "z": -1,
      "name": "Plant_Grass_Sharp"
    },
    {
      "x": -23,
      "y": 28,
      "z": 0,
      "name": "Soil_Seaweed_Block"
    },
    {
      "x": -23,
      "y": 29,
      "z": 0,
      "name": "Soil_Seaweed_Block"
    },
    {
      "x": -23,
      "y": 35,
      "z": 0,
      "name": "Plant_Moss_Block_Green"
    },
    {
      "x": -23,
      "y": 36,
      "z": 0,
      "name": "Soil_Seaweed_Block"
    },
    {
      "x": -23,
      "y": 37,
      "z": 0,
      "name": "Soil_Clay_Lime"
    },
    {
      "x": -23,
      "y": 38,
      "z": 0,
      "name": "Plant_Grass_Sharp"
    },
    {
      "x": -23,
      "y": 28,
      "z": 1,
      "name": "Plant_Moss_Block_Green"
    },
    {
      "x": -23,
      "y": 29,
      "z": 1,
      "name": "Soil_Seaweed_Block"
    },
    {
      "x": -23,
      "y": 30,
      "z": 1,
      "name": "Soil_Seaweed_Block"
    },
    {
      "x": -23,
      "y": 35,
      "z": 1,
      "name": "Plant_Moss_Block_Green"
    },
    {
      "x": -23,
      "y": 36,
      "z": 1,
      "name": "Soil_Seaweed_Block"
    },
    {
      "x": -23,
      "y": 37,
      "z": 1,
      "name": "Soil_Seaweed_Block"
    },
    {
      "x": -23,
      "y": 29,
      "z": 2,
      "name": "Soil_Seaweed_Block"
    },
    {
      "x": -23,
      "y": 30,
      "z": 2,
      "name": "Soil_Seaweed_Block"
    },
    {
      "x": -23,
      "y": 36,
      "z": 2,
      "name": "Soil_Seaweed_Block"
    },
    {
      "x": -23,
      "y": 29,
      "z": 3,
      "name": "Plant_Moss_Block_Green"
    },
    {
      "x": -23,
      "y": 30,
      "z": 3,
      "name": "Soil_Seaweed_Block"
    },
    {
      "x": -23,
      "y": 31,
      "z": 3,
      "name": "Soil_Seaweed_Block"
    },
    {
      "x": -23,
      "y": 31,
      "z": 4,
      "name": "Soil_Seaweed_Block"
    },
    {
      "x": -23,
      "y": 36,
      "z": 5,
      "name": "Soil_Seaweed_Block"
    },
    {
      "x": -23,
      "y": 37,
      "z": 5,
      "name": "Soil_Seaweed_Block"
    },
    {
      "x": -23,
      "y": 38,
      "z": 5,
      "name": "Soil_Seaweed_Block"
    },
    {
      "x": -23,
      "y": 32,
      "z": 6,
      "name": "Plant_Moss_Block_Green"
    },
    {
      "x": -23,
      "y": 33,
      "z": 6,
      "name": "Soil_Seaweed_Block"
    },
    {
      "x": -23,
      "y": 34,
      "z": 6,
      "name": "Soil_Seaweed_Block"
    },
    {
      "x": -23,
      "y": 35,
      "z": 6,
      "name": "Soil_Seaweed_Block"
    },
    {
      "x": -23,
      "y": 36,
      "z": 6,
      "name": "Soil_Seaweed_Block"
    },
    {
      "x": -23,
      "y": 37,
      "z": 6,
      "name": "Soil_Seaweed_Block"
    },
    {
      "x": -23,
      "y": 38,
      "z": 6,
      "name": "Soil_Seaweed_Block"
    },
    {
      "x": -23,
      "y": 39,
      "z": 6,
      "name": "Soil_Seaweed_Block"
    },
    {
      "x": -23,
      "y": 32,
      "z": 7,
      "name": "Plant_Moss_Block_Green"
    },
    {
      "x": -23,
      "y": 33,
      "z": 7,
      "name": "Soil_Seaweed_Block"
    },
    {
      "x": -23,
      "y": 34,
      "z": 7,
      "name": "Soil_Seaweed_Block"
    },
    {
      "x": -23,
      "y": 35,
      "z": 7,
      "name": "Soil_Seaweed_Block"
    },
    {
      "x": -23,
      "y": 36,
      "z": 7,
      "name": "Soil_Seaweed_Block"
    },
    {
      "x": -23,
      "y": 37,
      "z": 7,
      "name": "Soil_Seaweed_Block"
    },
    {
      "x": -23,
      "y": 38,
      "z": 7,
      "name": "Soil_Seaweed_Block"
    },
    {
      "x": -23,
      "y": 39,
      "z": 7,
      "name": "Soil_Seaweed_Block"
    },
    {
      "x": -23,
      "y": 40,
      "z": 7,
      "name": "Soil_Seaweed_Block"
    },
    {
      "x": -23,
      "y": 41,
      "z": 7,
      "name": "Soil_Seaweed_Block"
    },
    {
      "x": -23,
      "y": 42,
      "z": 7,
      "name": "Soil_Seaweed_Block"
    },
    {
      "x": -23,
      "y": 43,
      "z": 7,
      "name": "Soil_Seaweed_Block"
    },
    {
      "x": -23,
      "y": 31,
      "z": 8,
      "name": "Plant_Moss_Block_Green"
    },
    {
      "x": -23,
      "y": 32,
      "z": 8,
      "name": "Soil_Seaweed_Block"
    },
    {
      "x": -23,
      "y": 33,
      "z": 8,
      "name": "Soil_Seaweed_Block"
    },
    {
      "x": -23,
      "y": 34,
      "z": 8,
      "name": "Soil_Seaweed_Block"
    },
    {
      "x": -23,
      "y": 35,
      "z": 8,
      "name": "Soil_Seaweed_Block"
    },
    {
      "x": -23,
      "y": 36,
      "z": 8,
      "name": "Soil_Seaweed_Block"
    },
    {
      "x": -23,
      "y": 37,
      "z": 8,
      "name": "Soil_Seaweed_Block"
    },
    {
      "x": -23,
      "y": 38,
      "z": 8,
      "name": "Soil_Seaweed_Block"
    },
    {
      "x": -23,
      "y": 39,
      "z": 8,
      "name": "Soil_Seaweed_Block"
    },
    {
      "x": -23,
      "y": 40,
      "z": 8,
      "name": "Soil_Seaweed_Block"
    },
    {
      "x": -23,
      "y": 41,
      "z": 8,
      "name": "Soil_Seaweed_Block"
    },
    {
      "x": -23,
      "y": 42,
      "z": 8,
      "name": "Soil_Seaweed_Block"
    },
    {
      "x": -23,
      "y": 43,
      "z": 8,
      "name": "Soil_Seaweed_Block"
    },
    {
      "x": -23,
      "y": 44,
      "z": 8,
      "name": "Soil_Clay_Lime"
    },
    {
      "x": -23,
      "y": 45,
      "z": 8,
      "name": "Plant_Grass_Sharp"
    },
    {
      "x": -23,
      "y": 31,
      "z": 9,
      "name": "Plant_Moss_Block_Green"
    },
    {
      "x": -23,
      "y": 32,
      "z": 9,
      "name": "Soil_Seaweed_Block"
    },
    {
      "x": -23,
      "y": 33,
      "z": 9,
      "name": "Soil_Seaweed_Block"
    },
    {
      "x": -23,
      "y": 34,
      "z": 9,
      "name": "Soil_Seaweed_Block"
    },
    {
      "x": -23,
      "y": 35,
      "z": 9,
      "name": "Soil_Seaweed_Block"
    },
    {
      "x": -23,
      "y": 36,
      "z": 9,
      "name": "Soil_Seaweed_Block"
    },
    {
      "x": -23,
      "y": 37,
      "z": 9,
      "name": "Soil_Seaweed_Block"
    },
    {
      "x": -23,
      "y": 38,
      "z": 9,
      "name": "Soil_Seaweed_Block"
    },
    {
      "x": -23,
      "y": 39,
      "z": 9,
      "name": "Soil_Seaweed_Block"
    },
    {
      "x": -23,
      "y": 40,
      "z": 9,
      "name": "Soil_Seaweed_Block"
    },
    {
      "x": -23,
      "y": 41,
      "z": 9,
      "name": "Soil_Seaweed_Block"
    },
    {
      "x": -23,
      "y": 42,
      "z": 9,
      "name": "Soil_Seaweed_Block"
    },
    {
      "x": -23,
      "y": 43,
      "z": 9,
      "name": "Soil_Seaweed_Block"
    },
    {
      "x": -23,
      "y": 44,
      "z": 9,
      "name": "Soil_Clay_Lime"
    },
    {
      "x": -23,
      "y": 45,
      "z": 9,
      "name": "Plant_Grass_Sharp"
    },
    {
      "x": -23,
      "y": 31,
      "z": 10,
      "name": "Plant_Moss_Block_Green"
    },
    {
      "x": -23,
      "y": 32,
      "z": 10,
      "name": "Soil_Seaweed_Block"
    },
    {
      "x": -23,
      "y": 33,
      "z": 10,
      "name": "Soil_Seaweed_Block"
    },
    {
      "x": -23,
      "y": 34,
      "z": 10,
      "name": "Soil_Seaweed_Block"
    },
    {
      "x": -23,
      "y": 35,
      "z": 10,
      "name": "Soil_Seaweed_Block"
    },
    {
      "x": -23,
      "y": 36,
      "z": 10,
      "name": "Soil_Seaweed_Block"
    },
    {
      "x": -23,
      "y": 37,
      "z": 10,
      "name": "Soil_Seaweed_Block"
    },
    {
      "x": -23,
      "y": 38,
      "z": 10,
      "name": "Soil_Seaweed_Block"
    },
    {
      "x": -23,
      "y": 40,
      "z": 10,
      "name": "Soil_Seaweed_Block"
    },
    {
      "x": -23,
      "y": 41,
      "z": 10,
      "name": "Plant_Moss_Block_Green"
    },
    {
      "x": -23,
      "y": 42,
      "z": 10,
      "name": "Soil_Seaweed_Block"
    },
    {
      "x": -23,
      "y": 43,
      "z": 10,
      "name": "Soil_Seaweed_Block"
    },
    {
      "x": -23,
      "y": 44,
      "z": 10,
      "name": "Soil_Clay_Lime"
    },
    {
      "x": -23,
      "y": 45,
      "z": 10,
      "name": "Plant_Grass_Sharp"
    },
    {
      "x": -23,
      "y": 31,
      "z": 11,
      "name": "Soil_Seaweed_Block"
    },
    {
      "x": -23,
      "y": 32,
      "z": 11,
      "name": "Soil_Seaweed_Block"
    },
    {
      "x": -23,
      "y": 33,
      "z": 11,
      "name": "Soil_Seaweed_Block"
    },
    {
      "x": -23,
      "y": 34,
      "z": 11,
      "name": "Soil_Seaweed_Block"
    },
    {
      "x": -23,
      "y": 30,
      "z": 12,
      "name": "Plant_Moss_Block_Green"
    },
    {
      "x": -23,
      "y": 31,
      "z": 12,
      "name": "Soil_Seaweed_Block"
    },
    {
      "x": -23,
      "y": 32,
      "z": 12,
      "name": "Soil_Seaweed_Block"
    },
    {
      "x": -23,
      "y": 29,
      "z": 13,
      "name": "Plant_Moss_Block_Green"
    },
    {
      "x": -23,
      "y": 30,
      "z": 13,
      "name": "Soil_Seaweed_Block"
    },
    {
      "x": -23,
      "y": 31,
      "z": 13,
      "name": "Soil_Seaweed_Block"
    },
    {
      "x": -23,
      "y": 29,
      "z": 14,
      "name": "Plant_Moss_Block_Green"
    },
    {
      "x": -23,
      "y": 30,
      "z": 14,
      "name": "Soil_Seaweed_Block"
    },
    {
      "x": -23,
      "y": 31,
      "z": 14,
      "name": "Soil_Seaweed_Block"
    },
    {
      "x": -23,
      "y": 29,
      "z": 15,
      "name": "Plant_Moss_Block_Green"
    },
    {
      "x": -23,
      "y": 30,
      "z": 15,
      "name": "Soil_Seaweed_Block"
    },
    {
      "x": -23,
      "y": 31,
      "z": 15,
      "name": "Soil_Seaweed_Block"
    },
    {
      "x": -22,
      "y": 21,
      "z": -14,
      "name": "Plant_Moss_Cave_Green",
      "support": 15,
      "rotation": 8
    },
    {
      "x": -22,
      "y": 22,
      "z": -14,
      "name": "Plant_Moss_Block_Green"
    },
    {
      "x": -22,
      "y": 23,
      "z": -14,
      "name": "Soil_Seaweed_Block"
    },
    {
      "x": -22,
      "y": 32,
      "z": -14,
      "name": "Plant_Moss_Block_Green"
    },
    {
      "x": -22,
      "y": 33,
      "z": -14,
      "name": "Soil_Seaweed_Block"
    },
    {
      "x": -22,
      "y": 34,
      "z": -14,
      "name": "Soil_Seaweed_Block"
    },
    {
      "x": -22,
      "y": 21,
      "z": -13,
      "name": "Plant_Moss_Cave_Green",
      "support": 15,
      "rotation": 8
    },
    {
      "x": -22,
      "y": 22,
      "z": -13,
      "name": "Plant_Moss_Block_Green"
    },
    {
      "x": -22,
      "y": 23,
      "z": -13,
      "name": "Soil_Seaweed_Block"
    },
    {
      "x": -22,
      "y": 24,
      "z": -13,
      "name": "Soil_Seaweed_Block"
    },
    {
      "x": -22,
      "y": 31,
      "z": -13,
      "name": "Plant_Moss_Block_Green"
    },
    {
      "x": -22,
      "y": 32,
      "z": -13,
      "name": "Soil_Seaweed_Block"
    },
    {
      "x": -22,
      "y": 33,
      "z": -13,
      "name": "Soil_Seaweed_Block"
    },
    {
      "x": -22,
      "y": 34,
      "z": -13,
      "name": "Soil_Seaweed_Block"
    },
    {
      "x": -22,
      "y": 35,
      "z": -13,
      "name": "Soil_Clay_Lime"
    },
    {
      "x": -22,
      "y": 36,
      "z": -13,
      "name": "Plant_Grass_Sharp"
    },
    {
      "x": -22,
      "y": 22,
      "z": -12,
      "name": "Plant_Moss_Block_Green"
    },
    {
      "x": -22,
      "y": 23,
      "z": -12,
      "name": "Soil_Seaweed_Block"
    },
    {
      "x": -22,
      "y": 31,
      "z": -12,
      "name": "Plant_Moss_Block_Green"
    },
    {
      "x": -22,
      "y": 32,
      "z": -12,
      "name": "Soil_Seaweed_Block"
    },
    {
      "x": -22,
      "y": 33,
      "z": -12,
      "name": "Soil_Seaweed_Block"
    },
    {
      "x": -22,
      "y": 34,
      "z": -12,
      "name": "Soil_Seaweed_Block"
    },
    {
      "x": -22,
      "y": 35,
      "z": -12,
      "name": "Soil_Clay_Lime"
    },
    {
      "x": -22,
      "y": 36,
      "z": -12,
      "name": "Plant_Grass_Sharp"
    },
    {
      "x": -22,
      "y": 31,
      "z": -11,
      "name": "Plant_Moss_Block_Green"
    },
    {
      "x": -22,
      "y": 32,
      "z": -11,
      "name": "Soil_Seaweed_Block"
    },
    {
      "x": -22,
      "y": 33,
      "z": -11,
      "name": "Soil_Seaweed_Block"
    },
    {
      "x": -22,
      "y": 34,
      "z": -11,
      "name": "Soil_Seaweed_Block"
    },
    {
      "x": -22,
      "y": 35,
      "z": -11,
      "name": "Soil_Clay_Lime"
    },
    {
      "x": -22,
      "y": 36,
      "z": -11,
      "name": "Plant_Grass_Sharp"
    },
    {
      "x": -22,
      "y": 31,
      "z": -10,
      "name": "Plant_Moss_Block_Green"
    },
    {
      "x": -22,
      "y": 32,
      "z": -10,
      "name": "Soil_Seaweed_Block"
    },
    {
      "x": -22,
      "y": 33,
      "z": -10,
      "name": "Soil_Seaweed_Block"
    },
    {
      "x": -22,
      "y": 34,
      "z": -10,
      "name": "Soil_Seaweed_Block"
    },
    {
      "x": -22,
      "y": 35,
      "z": -10,
      "name": "Soil_Clay_Lime"
    },
    {
      "x": -22,
      "y": 36,
      "z": -10,
      "name": "Plant_Grass_Sharp"
    },
    {
      "x": -22,
      "y": 30,
      "z": -9,
      "name": "Soil_Seaweed_Block"
    },
    {
      "x": -22,
      "y": 31,
      "z": -9,
      "name": "Soil_Seaweed_Block"
    },
    {
      "x": -22,
      "y": 32,
      "z": -9,
      "name": "Soil_Seaweed_Block"
    },
    {
      "x": -22,
      "y": 33,
      "z": -9,
      "name": "Soil_Seaweed_Block"
    },
    {
      "x": -22,
      "y": 34,
      "z": -9,
      "name": "Soil_Seaweed_Block"
    },
    {
      "x": -22,
      "y": 35,
      "z": -9,
      "name": "Soil_Seaweed_Block"
    },
    {
      "x": -22,
      "y": 27,
      "z": -8,
      "name": "Soil_Seaweed_Block"
    },
    {
      "x": -22,
      "y": 28,
      "z": -8,
      "name": "Soil_Seaweed_Block"
    },
    {
      "x": -22,
      "y": 29,
      "z": -8,
      "name": "Soil_Seaweed_Block"
    },
    {
      "x": -22,
      "y": 30,
      "z": -8,
      "name": "Soil_Seaweed_Block"
    },
    {
      "x": -22,
      "y": 31,
      "z": -8,
      "name": "Soil_Seaweed_Block"
    },
    {
      "x": -22,
      "y": 32,
      "z": -8,
      "name": "Soil_Seaweed_Block"
    },
    {
      "x": -22,
      "y": 33,
      "z": -8,
      "name": "Soil_Seaweed_Block"
    },
    {
      "x": -22,
      "y": 34,
      "z": -8,
      "name": "Soil_Seaweed_Block"
    },
    {
      "x": -22,
      "y": 35,
      "z": -8,
      "name": "Soil_Seaweed_Block"
    },
    {
      "x": -22,
      "y": 23,
      "z": -7,
      "name": "Plant_Moss_Block_Green"
    },
    {
      "x": -22,
      "y": 24,
      "z": -7,
      "name": "Plant_Moss_Block_Green"
    },
    {
      "x": -22,
      "y": 25,
      "z": -7,
      "name": "Soil_Seaweed_Block"
    },
    {
      "x": -22,
      "y": 26,
      "z": -7,
      "name": "Soil_Seaweed_Block"
    },
    {
      "x": -22,
      "y": 27,
      "z": -7,
      "name": "Soil_Seaweed_Block"
    },
    {
      "x": -22,
      "y": 28,
      "z": -7,
      "name": "Soil_Seaweed_Block"
    },
    {
      "x": -22,
      "y": 29,
      "z": -7,
      "name": "Soil_Seaweed_Block"
    },
    {
      "x": -22,
      "y": 30,
      "z": -7,
      "name": "Soil_Seaweed_Block"
    },
    {
      "x": -22,
      "y": 34,
      "z": -7,
      "name": "Soil_Seaweed_Block"
    },
    {
      "x": -22,
      "y": 35,
      "z": -7,
      "name": "Soil_Seaweed_Block"
    },
    {
      "x": -22,
      "y": 22,
      "z": -6,
      "name": "Plant_Moss_Cave_Green",
      "support": 15,
      "rotation": 8
    },
    {
      "x": -22,
      "y": 23,
      "z": -6,
      "name": "Plant_Moss_Block_Green"
    },
    {
      "x": -22,
      "y": 24,
      "z": -6,
      "name": "Soil_Seaweed_Block"
    },
    {
      "x": -22,
      "y": 25,
      "z": -6,
      "name": "Soil_Seaweed_Block"
    },
    {
      "x": -22,
      "y": 26,
      "z": -6,
      "name": "Soil_Seaweed_Block"
    },
    {
      "x": -22,
      "y": 27,
      "z": -6,
      "name": "Soil_Seaweed_Block"
    },
    {
      "x": -22,
      "y": 28,
      "z": -6,
      "name": "Soil_Seaweed_Block"
    },
    {
      "x": -22,
      "y": 29,
      "z": -6,
      "name": "Soil_Seaweed_Block"
    },
    {
      "x": -22,
      "y": 34,
      "z": -6,
      "name": "Plant_Moss_Block_Green"
    },
    {
      "x": -22,
      "y": 35,
      "z": -6,
      "name": "Soil_Seaweed_Block"
    },
    {
      "x": -22,
      "y": 36,
      "z": -6,
      "name": "Soil_Clay_Lime"
    },
    {
      "x": -22,
      "y": 37,
      "z": -6,
      "name": "Plant_Grass_Sharp"
    },
    {
      "x": -22,
      "y": 22,
      "z": -5,
      "name": "Plant_Moss_Block_Green"
    },
    {
      "x": -22,
      "y": 23,
      "z": -5,
      "name": "Soil_Seaweed_Block"
    },
    {
      "x": -22,
      "y": 24,
      "z": -5,
      "name": "Soil_Seaweed_Block"
    },
    {
      "x": -22,
      "y": 25,
      "z": -5,
      "name": "Soil_Seaweed_Block"
    },
    {
      "x": -22,
      "y": 26,
      "z": -5,
      "name": "Soil_Seaweed_Block"
    },
    {
      "x": -22,
      "y": 27,
      "z": -5,
      "name": "Soil_Seaweed_Block"
    },
    {
      "x": -22,
      "y": 28,
      "z": -5,
      "name": "Soil_Clay_Lime"
    },
    {
      "x": -22,
      "y": 29,
      "z": -5,
      "name": "Plant_Grass_Sharp"
    },
    {
      "x": -22,
      "y": 34,
      "z": -5,
      "name": "Plant_Moss_Block_Green"
    },
    {
      "x": -22,
      "y": 35,
      "z": -5,
      "name": "Soil_Seaweed_Block"
    },
    {
      "x": -22,
      "y": 36,
      "z": -5,
      "name": "Soil_Clay_Lime"
    },
    {
      "x": -22,
      "y": 37,
      "z": -5,
      "name": "Plant_Grass_Sharp"
    },
    {
      "x": -22,
      "y": 22,
      "z": -4,
      "name": "Plant_Moss_Block_Green"
    },
    {
      "x": -22,
      "y": 23,
      "z": -4,
      "name": "Soil_Seaweed_Block"
    },
    {
      "x": -22,
      "y": 24,
      "z": -4,
      "name": "Soil_Seaweed_Block"
    },
    {
      "x": -22,
      "y": 25,
      "z": -4,
      "name": "Soil_Seaweed_Block"
    },
    {
      "x": -22,
      "y": 26,
      "z": -4,
      "name": "Soil_Seaweed_Block"
    },
    {
      "x": -22,
      "y": 27,
      "z": -4,
      "name": "Soil_Clay_Lime"
    },
    {
      "x": -22,
      "y": 28,
      "z": -4,
      "name": "Plant_Grass_Sharp"
    },
    {
      "x": -22,
      "y": 34,
      "z": -4,
      "name": "Plant_Moss_Block_Green"
    },
    {
      "x": -22,
      "y": 35,
      "z": -4,
      "name": "Soil_Seaweed_Block"
    },
    {
      "x": -22,
      "y": 36,
      "z": -4,
      "name": "Soil_Seaweed_Block"
    },
    {
      "x": -22,
      "y": 37,
      "z": -4,
      "name": "Soil_Clay_Lime"
    },
    {
      "x": -22,
      "y": 38,
      "z": -4,
      "name": "Plant_Grass_Sharp"
    },
    {
      "x": -22,
      "y": 21,
      "z": -3,
      "name": "Plant_Moss_Cave_Green",
      "support": 15,
      "rotation": 8
    },
    {
      "x": -22,
      "y": 22,
      "z": -3,
      "name": "Plant_Moss_Block_Green"
    },
    {
      "x": -22,
      "y": 23,
      "z": -3,
      "name": "Soil_Seaweed_Block"
    },
    {
      "x": -22,
      "y": 24,
      "z": -3,
      "name": "Soil_Seaweed_Block"
    },
    {
      "x": -22,
      "y": 25,
      "z": -3,
      "name": "Soil_Seaweed_Block"
    },
    {
      "x": -22,
      "y": 26,
      "z": -3,
      "name": "Soil_Seaweed_Block"
    },
    {
      "x": -22,
      "y": 27,
      "z": -3,
      "name": "Soil_Clay_Lime"
    },
    {
      "x": -22,
      "y": 28,
      "z": -3,
      "name": "Plant_Grass_Sharp"
    },
    {
      "x": -22,
      "y": 34,
      "z": -3,
      "name": "Plant_Moss_Block_Green"
    },
    {
      "x": -22,
      "y": 35,
      "z": -3,
      "name": "Soil_Seaweed_Block"
    },
    {
      "x": -22,
      "y": 36,
      "z": -3,
      "name": "Soil_Seaweed_Block"
    },
    {
      "x": -22,
      "y": 37,
      "z": -3,
      "name": "Soil_Clay_Lime"
    },
    {
      "x": -22,
      "y": 38,
      "z": -3,
      "name": "Plant_Grass_Sharp"
    },
    {
      "x": -22,
      "y": 23,
      "z": -2,
      "name": "Plant_Moss_Block_Green"
    },
    {
      "x": -22,
      "y": 24,
      "z": -2,
      "name": "Soil_Seaweed_Block"
    },
    {
      "x": -22,
      "y": 25,
      "z": -2,
      "name": "Soil_Seaweed_Block"
    },
    {
      "x": -22,
      "y": 26,
      "z": -2,
      "name": "Soil_Seaweed_Block"
    },
    {
      "x": -22,
      "y": 27,
      "z": -2,
      "name": "Soil_Clay_Lime"
    },
    {
      "x": -22,
      "y": 28,
      "z": -2,
      "name": "Soil_Clay_Lime"
    },
    {
      "x": -22,
      "y": 29,
      "z": -2,
      "name": "Plant_Grass_Sharp"
    },
    {
      "x": -22,
      "y": 34,
      "z": -2,
      "name": "Plant_Moss_Block_Green"
    },
    {
      "x": -22,
      "y": 35,
      "z": -2,
      "name": "Soil_Seaweed_Block"
    },
    {
      "x": -22,
      "y": 36,
      "z": -2,
      "name": "Soil_Seaweed_Block"
    },
    {
      "x": -22,
      "y": 37,
      "z": -2,
      "name": "Soil_Clay_Lime"
    },
    {
      "x": -22,
      "y": 38,
      "z": -2,
      "name": "Plant_Grass_Sharp"
    },
    {
      "x": -22,
      "y": 24,
      "z": -1,
      "name": "Soil_Seaweed_Block"
    },
    {
      "x": -22,
      "y": 25,
      "z": -1,
      "name": "Soil_Seaweed_Block"
    },
    {
      "x": -22,
      "y": 26,
      "z": -1,
      "name": "Soil_Seaweed_Block"
    },
    {
      "x": -22,
      "y": 27,
      "z": -1,
      "name": "Soil_Seaweed_Block"
    },
    {
      "x": -22,
      "y": 28,
      "z": -1,
      "name": "Soil_Seaweed_Block"
    },
    {
      "x": -22,
      "y": 29,
      "z": -1,
      "name": "Soil_Clay_Lime"
    },
    {
      "x": -22,
      "y": 30,
      "z": -1,
      "name": "Plant_Grass_Sharp"
    },
    {
      "x": -22,
      "y": 34,
      "z": -1,
      "name": "Plant_Moss_Block_Green"
    },
    {
      "x": -22,
      "y": 35,
      "z": -1,
      "name": "Soil_Seaweed_Block"
    },
    {
      "x": -22,
      "y": 36,
      "z": -1,
      "name": "Soil_Seaweed_Block"
    },
    {
      "x": -22,
      "y": 37,
      "z": -1,
      "name": "Soil_Clay_Lime"
    },
    {
      "x": -22,
      "y": 38,
      "z": -1,
      "name": "Plant_Grass_Sharp"
    },
    {
      "x": -22,
      "y": 27,
      "z": 0,
      "name": "Plant_Moss_Block_Green"
    },
    {
      "x": -22,
      "y": 28,
      "z": 0,
      "name": "Plant_Moss_Block_Green"
    },
    {
      "x": -22,
      "y": 29,
      "z": 0,
      "name": "Soil_Seaweed_Block"
    },
    {
      "x": -22,
      "y": 30,
      "z": 0,
      "name": "Soil_Clay_Lime"
    },
    {
      "x": -22,
      "y": 31,
      "z": 0,
      "name": "Plant_Grass_Sharp"
    },
    {
      "x": -22,
      "y": 35,
      "z": 0,
      "name": "Plant_Moss_Block_Green"
    },
    {
      "x": -22,
      "y": 36,
      "z": 0,
      "name": "Soil_Seaweed_Block"
    },
    {
      "x": -22,
      "y": 37,
      "z": 0,
      "name": "Soil_Clay_Lime"
    },
    {
      "x": -22,
      "y": 38,
      "z": 0,
      "name": "Plant_Grass_Sharp"
    },
    {
      "x": -22,
      "y": 27,
      "z": 1,
      "name": "Plant_Moss_Block_Green"
    },
    {
      "x": -22,
      "y": 28,
      "z": 1,
      "name": "Soil_Seaweed_Block"
    },
    {
      "x": -22,
      "y": 29,
      "z": 1,
      "name": "Soil_Seaweed_Block"
    },
    {
      "x": -22,
      "y": 30,
      "z": 1,
      "name": "Soil_Clay_Lime"
    },
    {
      "x": -22,
      "y": 31,
      "z": 1,
      "name": "Plant_Grass_Sharp"
    },
    {
      "x": -22,
      "y": 35,
      "z": 1,
      "name": "Plant_Moss_Block_Green"
    },
    {
      "x": -22,
      "y": 36,
      "z": 1,
      "name": "Soil_Seaweed_Block"
    },
    {
      "x": -22,
      "y": 37,
      "z": 1,
      "name": "Soil_Clay_Lime"
    },
    {
      "x": -22,
      "y": 38,
      "z": 1,
      "name": "Plant_Grass_Sharp"
    },
    {
      "x": -22,
      "y": 28,
      "z": 2,
      "name": "Plant_Moss_Block_Green"
    },
    {
      "x": -22,
      "y": 29,
      "z": 2,
      "name": "Soil_Seaweed_Block"
    },
    {
      "x": -22,
      "y": 30,
      "z": 2,
      "name": "Soil_Seaweed_Block"
    },
    {
      "x": -22,
      "y": 31,
      "z": 2,
      "name": "Soil_Clay_Lime"
    },
    {
      "x": -22,
      "y": 32,
      "z": 2,
      "name": "Plant_Grass_Sharp"
    },
    {
      "x": -22,
      "y": 35,
      "z": 2,
      "name": "Plant_Moss_Block_Green"
    },
    {
      "x": -22,
      "y": 36,
      "z": 2,
      "name": "Soil_Seaweed_Block"
    },
    {
      "x": -22,
      "y": 37,
      "z": 2,
      "name": "Soil_Clay_Lime"
    },
    {
      "x": -22,
      "y": 38,
      "z": 2,
      "name": "Plant_Grass_Sharp"
    },
    {
      "x": -22,
      "y": 28,
      "z": 3,
      "name": "Plant_Moss_Block_Green"
    },
    {
      "x": -22,
      "y": 29,
      "z": 3,
      "name": "Soil_Seaweed_Block"
    },
    {
      "x": -22,
      "y": 30,
      "z": 3,
      "name": "Soil_Seaweed_Block"
    },
    {
      "x": -22,
      "y": 31,
      "z": 3,
      "name": "Soil_Seaweed_Block"
    },
    {
      "x": -22,
      "y": 32,
      "z": 3,
      "name": "Soil_Seaweed_Block"
    },
    {
      "x": -22,
      "y": 36,
      "z": 3,
      "name": "Plant_Moss_Block_Green"
    },
    {
      "x": -22,
      "y": 37,
      "z": 3,
      "name": "Soil_Seaweed_Block"
    },
    {
      "x": -22,
      "y": 28,
      "z": 4,
      "name": "Plant_Moss_Cave_Green",
      "support": 15,
      "rotation": 8
    },
    {
      "x": -22,
      "y": 29,
      "z": 4,
      "name": "Plant_Moss_Block_Green"
    },
    {
      "x": -22,
      "y": 30,
      "z": 4,
      "name": "Plant_Moss_Block_Green"
    },
    {
      "x": -22,
      "y": 31,
      "z": 4,
      "name": "Soil_Seaweed_Block"
    },
    {
      "x": -22,
      "y": 32,
      "z": 4,
      "name": "Soil_Seaweed_Block"
    },
    {
      "x": -22,
      "y": 33,
      "z": 4,
      "name": "Soil_Seaweed_Block"
    },
    {
      "x": -22,
      "y": 35,
      "z": 4,
      "name": "Plant_Moss_Block_Green"
    },
    {
      "x": -22,
      "y": 36,
      "z": 4,
      "name": "Plant_Moss_Block_Green"
    },
    {
      "x": -22,
      "y": 37,
      "z": 4,
      "name": "Soil_Seaweed_Block"
    },
    {
      "x": -22,
      "y": 38,
      "z": 4,
      "name": "Soil_Seaweed_Block"
    },
    {
      "x": -22,
      "y": 15,
      "z": 5,
      "name": "Plant_Moss_Cave_Green",
      "support": 15,
      "rotation": 8
    },
    {
      "x": -22,
      "y": 16,
      "z": 5,
      "name": "Plant_Moss_Block_Green"
    },
    {
      "x": -22,
      "y": 17,
      "z": 5,
      "name": "Soil_Seaweed_Block"
    },
    {
      "x": -22,
      "y": 18,
      "z": 5,
      "name": "Soil_Seaweed_Block"
    },
    {
      "x": -22,
      "y": 30,
      "z": 5,
      "name": "Plant_Moss_Cave_Green",
      "support": 15,
      "rotation": 8
    },
    {
      "x": -22,
      "y": 31,
      "z": 5,
      "name": "Plant_Moss_Block_Green"
    },
    {
      "x": -22,
      "y": 32,
      "z": 5,
      "name": "Plant_Moss_Block_Green"
    },
    {
      "x": -22,
      "y": 33,
      "z": 5,
      "name": "Soil_Seaweed_Block"
    },
    {
      "x": -22,
      "y": 34,
      "z": 5,
      "name": "Soil_Seaweed_Block"
    },
    {
      "x": -22,
      "y": 35,
      "z": 5,
      "name": "Plant_Moss_Block_Green"
    },
    {
      "x": -22,
      "y": 36,
      "z": 5,
      "name": "Soil_Seaweed_Block"
    },
    {
      "x": -22,
      "y": 37,
      "z": 5,
      "name": "Soil_Seaweed_Block"
    },
    {
      "x": -22,
      "y": 38,
      "z": 5,
      "name": "Soil_Seaweed_Block"
    },
    {
      "x": -22,
      "y": 39,
      "z": 5,
      "name": "Soil_Seaweed_Block"
    },
    {
      "x": -22,
      "y": 15,
      "z": 6,
      "name": "Plant_Moss_Cave_Green",
      "support": 15,
      "rotation": 8
    },
    {
      "x": -22,
      "y": 16,
      "z": 6,
      "name": "Plant_Moss_Block_Green"
    },
    {
      "x": -22,
      "y": 17,
      "z": 6,
      "name": "Soil_Seaweed_Block"
    },
    {
      "x": -22,
      "y": 18,
      "z": 6,
      "name": "Soil_Seaweed_Block"
    },
    {
      "x": -22,
      "y": 30,
      "z": 6,
      "name": "Plant_Moss_Cave_Green",
      "support": 15,
      "rotation": 8
    },
    {
      "x": -22,
      "y": 31,
      "z": 6,
      "name": "Plant_Moss_Block_Green"
    },
    {
      "x": -22,
      "y": 32,
      "z": 6,
      "name": "Soil_Seaweed_Block"
    },
    {
      "x": -22,
      "y": 33,
      "z": 6,
      "name": "Soil_Seaweed_Block"
    },
    {
      "x": -22,
      "y": 34,
      "z": 6,
      "name": "Soil_Seaweed_Block"
    },
    {
      "x": -22,
      "y": 35,
      "z": 6,
      "name": "Soil_Seaweed_Block"
    },
    {
      "x": -22,
      "y": 36,
      "z": 6,
      "name": "Soil_Seaweed_Block"
    },
    {
      "x": -22,
      "y": 37,
      "z": 6,
      "name": "Soil_Seaweed_Block"
    },
    {
      "x": -22,
      "y": 38,
      "z": 6,
      "name": "Soil_Seaweed_Block"
    },
    {
      "x": -22,
      "y": 39,
      "z": 6,
      "name": "Soil_Seaweed_Block"
    },
    {
      "x": -22,
      "y": 40,
      "z": 6,
      "name": "Soil_Seaweed_Block"
    },
    {
      "x": -22,
      "y": 41,
      "z": 6,
      "name": "Soil_Seaweed_Block"
    },
    {
      "x": -22,
      "y": 15,
      "z": 7,
      "name": "Plant_Moss_Cave_Green",
      "support": 15,
      "rotation": 8
    },
    {
      "x": -22,
      "y": 16,
      "z": 7,
      "name": "Plant_Moss_Block_Green"
    },
    {
      "x": -22,
      "y": 17,
      "z": 7,
      "name": "Soil_Seaweed_Block"
    },
    {
      "x": -22,
      "y": 18,
      "z": 7,
      "name": "Soil_Seaweed_Block"
    },
    {
      "x": -22,
      "y": 30,
      "z": 7,
      "name": "Plant_Moss_Cave_Green",
      "support": 15,
      "rotation": 8
    },
    {
      "x": -22,
      "y": 31,
      "z": 7,
      "name": "Plant_Moss_Block_Green"
    },
    {
      "x": -22,
      "y": 32,
      "z": 7,
      "name": "Soil_Seaweed_Block"
    },
    {
      "x": -22,
      "y": 33,
      "z": 7,
      "name": "Soil_Seaweed_Block"
    },
    {
      "x": -22,
      "y": 34,
      "z": 7,
      "name": "Soil_Seaweed_Block"
    },
    {
      "x": -22,
      "y": 35,
      "z": 7,
      "name": "Soil_Seaweed_Block"
    },
    {
      "x": -22,
      "y": 36,
      "z": 7,
      "name": "Soil_Seaweed_Block"
    },
    {
      "x": -22,
      "y": 37,
      "z": 7,
      "name": "Soil_Seaweed_Block"
    },
    {
      "x": -22,
      "y": 38,
      "z": 7,
      "name": "Soil_Seaweed_Block"
    },
    {
      "x": -22,
      "y": 39,
      "z": 7,
      "name": "Soil_Seaweed_Block"
    },
    {
      "x": -22,
      "y": 40,
      "z": 7,
      "name": "Soil_Seaweed_Block"
    },
    {
      "x": -22,
      "y": 41,
      "z": 7,
      "name": "Soil_Seaweed_Block"
    },
    {
      "x": -22,
      "y": 42,
      "z": 7,
      "name": "Soil_Seaweed_Block"
    },
    {
      "x": -22,
      "y": 30,
      "z": 8,
      "name": "Plant_Moss_Cave_Green",
      "support": 15,
      "rotation": 8
    },
    {
      "x": -22,
      "y": 31,
      "z": 8,
      "name": "Plant_Moss_Block_Green"
    },
    {
      "x": -22,
      "y": 32,
      "z": 8,
      "name": "Soil_Seaweed_Block"
    },
    {
      "x": -22,
      "y": 33,
      "z": 8,
      "name": "Soil_Seaweed_Block"
    },
    {
      "x": -22,
      "y": 34,
      "z": 8,
      "name": "Soil_Seaweed_Block"
    },
    {
      "x": -22,
      "y": 35,
      "z": 8,
      "name": "Soil_Seaweed_Block"
    },
    {
      "x": -22,
      "y": 36,
      "z": 8,
      "name": "Soil_Seaweed_Block"
    },
    {
      "x": -22,
      "y": 37,
      "z": 8,
      "name": "Soil_Seaweed_Block"
    },
    {
      "x": -22,
      "y": 38,
      "z": 8,
      "name": "Soil_Seaweed_Block"
    },
    {
      "x": -22,
      "y": 39,
      "z": 8,
      "name": "Soil_Seaweed_Block"
    },
    {
      "x": -22,
      "y": 40,
      "z": 8,
      "name": "Soil_Seaweed_Block"
    },
    {
      "x": -22,
      "y": 41,
      "z": 8,
      "name": "Soil_Seaweed_Block"
    },
    {
      "x": -22,
      "y": 42,
      "z": 8,
      "name": "Soil_Seaweed_Block"
    },
    {
      "x": -22,
      "y": 43,
      "z": 8,
      "name": "Soil_Clay_Lime"
    },
    {
      "x": -22,
      "y": 44,
      "z": 8,
      "name": "Plant_Grass_Sharp"
    },
    {
      "x": -22,
      "y": 29,
      "z": 9,
      "name": "Plant_Moss_Cave_Green",
      "support": 15,
      "rotation": 8
    },
    {
      "x": -22,
      "y": 30,
      "z": 9,
      "name": "Plant_Moss_Block_Green"
    },
    {
      "x": -22,
      "y": 31,
      "z": 9,
      "name": "Soil_Seaweed_Block"
    },
    {
      "x": -22,
      "y": 32,
      "z": 9,
      "name": "Soil_Seaweed_Block"
    },
    {
      "x": -22,
      "y": 33,
      "z": 9,
      "name": "Soil_Seaweed_Block"
    },
    {
      "x": -22,
      "y": 34,
      "z": 9,
      "name": "Soil_Seaweed_Block"
    },
    {
      "x": -22,
      "y": 35,
      "z": 9,
      "name": "Soil_Seaweed_Block"
    },
    {
      "x": -22,
      "y": 36,
      "z": 9,
      "name": "Soil_Seaweed_Block"
    },
    {
      "x": -22,
      "y": 37,
      "z": 9,
      "name": "Soil_Seaweed_Block"
    },
    {
      "x": -22,
      "y": 38,
      "z": 9,
      "name": "Soil_Seaweed_Block"
    },
    {
      "x": -22,
      "y": 39,
      "z": 9,
      "name": "Soil_Seaweed_Block"
    },
    {
      "x": -22,
      "y": 40,
      "z": 9,
      "name": "Soil_Seaweed_Block"
    },
    {
      "x": -22,
      "y": 41,
      "z": 9,
      "name": "Soil_Seaweed_Block"
    },
    {
      "x": -22,
      "y": 42,
      "z": 9,
      "name": "Soil_Seaweed_Block"
    },
    {
      "x": -22,
      "y": 43,
      "z": 9,
      "name": "Soil_Seaweed_Block"
    },
    {
      "x": -22,
      "y": 44,
      "z": 9,
      "name": "Soil_Clay_Lime"
    },
    {
      "x": -22,
      "y": 45,
      "z": 9,
      "name": "Plant_Grass_Sharp"
    },
    {
      "x": -22,
      "y": 29,
      "z": 10,
      "name": "Plant_Moss_Block_Green"
    },
    {
      "x": -22,
      "y": 30,
      "z": 10,
      "name": "Plant_Moss_Block_Green"
    },
    {
      "x": -22,
      "y": 31,
      "z": 10,
      "name": "Soil_Seaweed_Block"
    },
    {
      "x": -22,
      "y": 32,
      "z": 10,
      "name": "Soil_Seaweed_Block"
    },
    {
      "x": -22,
      "y": 33,
      "z": 10,
      "name": "Soil_Seaweed_Block"
    },
    {
      "x": -22,
      "y": 34,
      "z": 10,
      "name": "Soil_Seaweed_Block"
    },
    {
      "x": -22,
      "y": 35,
      "z": 10,
      "name": "Soil_Seaweed_Block"
    },
    {
      "x": -22,
      "y": 36,
      "z": 10,
      "name": "Soil_Seaweed_Block"
    },
    {
      "x": -22,
      "y": 37,
      "z": 10,
      "name": "Soil_Seaweed_Block"
    },
    {
      "x": -22,
      "y": 38,
      "z": 10,
      "name": "Soil_Seaweed_Block"
    },
    {
      "x": -22,
      "y": 39,
      "z": 10,
      "name": "Soil_Seaweed_Block"
    },
    {
      "x": -22,
      "y": 40,
      "z": 10,
      "name": "Soil_Seaweed_Block"
    },
    {
      "x": -22,
      "y": 41,
      "z": 10,
      "name": "Soil_Seaweed_Block"
    },
    {
      "x": -22,
      "y": 42,
      "z": 10,
      "name": "Soil_Seaweed_Block"
    },
    {
      "x": -22,
      "y": 43,
      "z": 10,
      "name": "Soil_Seaweed_Block"
    },
    {
      "x": -22,
      "y": 29,
      "z": 11,
      "name": "Plant_Moss_Block_Green"
    },
    {
      "x": -22,
      "y": 30,
      "z": 11,
      "name": "Plant_Moss_Block_Green"
    },
    {
      "x": -22,
      "y": 31,
      "z": 11,
      "name": "Soil_Seaweed_Block"
    },
    {
      "x": -22,
      "y": 32,
      "z": 11,
      "name": "Soil_Seaweed_Block"
    },
    {
      "x": -22,
      "y": 33,
      "z": 11,
      "name": "Soil_Seaweed_Block"
    },
    {
      "x": -22,
      "y": 34,
      "z": 11,
      "name": "Soil_Seaweed_Block"
    },
    {
      "x": -22,
      "y": 29,
      "z": 12,
      "name": "Plant_Moss_Block_Green"
    },
    {
      "x": -22,
      "y": 30,
      "z": 12,
      "name": "Soil_Seaweed_Block"
    },
    {
      "x": -22,
      "y": 31,
      "z": 12,
      "name": "Soil_Seaweed_Block"
    },
    {
      "x": -22,
      "y": 32,
      "z": 12,
      "name": "Soil_Seaweed_Block"
    },
    {
      "x": -22,
      "y": 33,
      "z": 12,
      "name": "Soil_Seaweed_Block"
    },
    {
      "x": -22,
      "y": 28,
      "z": 13,
      "name": "Plant_Moss_Block_Green"
    },
    {
      "x": -22,
      "y": 29,
      "z": 13,
      "name": "Soil_Seaweed_Block"
    },
    {
      "x": -22,
      "y": 30,
      "z": 13,
      "name": "Soil_Seaweed_Block"
    },
    {
      "x": -22,
      "y": 31,
      "z": 13,
      "name": "Soil_Seaweed_Block"
    },
    {
      "x": -22,
      "y": 32,
      "z": 13,
      "name": "Soil_Seaweed_Block"
    },
    {
      "x": -22,
      "y": 28,
      "z": 14,
      "name": "Plant_Moss_Block_Green"
    },
    {
      "x": -22,
      "y": 29,
      "z": 14,
      "name": "Soil_Seaweed_Block"
    },
    {
      "x": -22,
      "y": 30,
      "z": 14,
      "name": "Soil_Seaweed_Block"
    },
    {
      "x": -22,
      "y": 31,
      "z": 14,
      "name": "Soil_Seaweed_Block"
    },
    {
      "x": -22,
      "y": 32,
      "z": 14,
      "name": "Soil_Clay_Lime"
    },
    {
      "x": -22,
      "y": 33,
      "z": 14,
      "name": "Plant_Grass_Sharp"
    },
    {
      "x": -22,
      "y": 29,
      "z": 15,
      "name": "Plant_Moss_Block_Green"
    },
    {
      "x": -22,
      "y": 30,
      "z": 15,
      "name": "Soil_Seaweed_Block"
    },
    {
      "x": -22,
      "y": 31,
      "z": 15,
      "name": "Soil_Seaweed_Block"
    },
    {
      "x": -22,
      "y": 29,
      "z": 16,
      "name": "Plant_Moss_Block_Green"
    },
    {
      "x": -22,
      "y": 30,
      "z": 16,
      "name": "Soil_Seaweed_Block"
    },
    {
      "x": -21,
      "y": 21,
      "z": -15,
      "name": "Plant_Moss_Cave_Green",
      "support": 15,
      "rotation": 8
    },
    {
      "x": -21,
      "y": 22,
      "z": -15,
      "name": "Plant_Moss_Block_Green"
    },
    {
      "x": -21,
      "y": 23,
      "z": -15,
      "name": "Soil_Seaweed_Block"
    },
    {
      "x": -21,
      "y": 20,
      "z": -14,
      "name": "Plant_Moss_Cave_Green",
      "support": 15,
      "rotation": 8
    },
    {
      "x": -21,
      "y": 21,
      "z": -14,
      "name": "Plant_Moss_Block_Green"
    },
    {
      "x": -21,
      "y": 22,
      "z": -14,
      "name": "Soil_Seaweed_Block"
    },
    {
      "x": -21,
      "y": 23,
      "z": -14,
      "name": "Soil_Seaweed_Block"
    },
    {
      "x": -21,
      "y": 24,
      "z": -14,
      "name": "Soil_Seaweed_Block"
    },
    {
      "x": -21,
      "y": 32,
      "z": -14,
      "name": "Plant_Moss_Block_Green"
    },
    {
      "x": -21,
      "y": 33,
      "z": -14,
      "name": "Soil_Seaweed_Block"
    },
    {
      "x": -21,
      "y": 34,
      "z": -14,
      "name": "Soil_Seaweed_Block"
    },
    {
      "x": -21,
      "y": 20,
      "z": -13,
      "name": "Plant_Moss_Cave_Green",
      "support": 15,
      "rotation": 8
    },
    {
      "x": -21,
      "y": 21,
      "z": -13,
      "name": "Plant_Moss_Block_Green"
    },
    {
      "x": -21,
      "y": 22,
      "z": -13,
      "name": "Soil_Seaweed_Block"
    },
    {
      "x": -21,
      "y": 23,
      "z": -13,
      "name": "Soil_Seaweed_Block"
    },
    {
      "x": -21,
      "y": 24,
      "z": -13,
      "name": "Soil_Seaweed_Block"
    },
    {
      "x": -21,
      "y": 25,
      "z": -13,
      "name": "Soil_Seaweed_Block"
    },
    {
      "x": -21,
      "y": 31,
      "z": -13,
      "name": "Plant_Moss_Block_Green"
    },
    {
      "x": -21,
      "y": 32,
      "z": -13,
      "name": "Soil_Seaweed_Block"
    },
    {
      "x": -21,
      "y": 33,
      "z": -13,
      "name": "Soil_Seaweed_Block"
    },
    {
      "x": -21,
      "y": 34,
      "z": -13,
      "name": "Soil_Seaweed_Block"
    },
    {
      "x": -21,
      "y": 35,
      "z": -13,
      "name": "Soil_Clay_Lime"
    },
    {
      "x": -21,
      "y": 36,
      "z": -13,
      "name": "Plant_Grass_Sharp"
    },
    {
      "x": -21,
      "y": 20,
      "z": -12,
      "name": "Plant_Moss_Cave_Green",
      "support": 15,
      "rotation": 8
    },
    {
      "x": -21,
      "y": 21,
      "z": -12,
      "name": "Plant_Moss_Block_Green"
    },
    {
      "x": -21,
      "y": 22,
      "z": -12,
      "name": "Soil_Seaweed_Block"
    },
    {
      "x": -21,
      "y": 23,
      "z": -12,
      "name": "Soil_Seaweed_Block"
    },
    {
      "x": -21,
      "y": 24,
      "z": -12,
      "name": "Soil_Seaweed_Block"
    },
    {
      "x": -21,
      "y": 25,
      "z": -12,
      "name": "Soil_Seaweed_Block"
    },
    {
      "x": -21,
      "y": 30,
      "z": -12,
      "name": "Plant_Moss_Block_Green"
    },
    {
      "x": -21,
      "y": 31,
      "z": -12,
      "name": "Soil_Seaweed_Block"
    },
    {
      "x": -21,
      "y": 32,
      "z": -12,
      "name": "Soil_Seaweed_Block"
    },
    {
      "x": -21,
      "y": 33,
      "z": -12,
      "name": "Soil_Seaweed_Block"
    },
    {
      "x": -21,
      "y": 34,
      "z": -12,
      "name": "Soil_Seaweed_Block"
    },
    {
      "x": -21,
      "y": 35,
      "z": -12,
      "name": "Soil_Seaweed_Block"
    },
    {
      "x": -21,
      "y": 36,
      "z": -12,
      "name": "Soil_Clay_Lime"
    },
    {
      "x": -21,
      "y": 37,
      "z": -12,
      "name": "Plant_Grass_Sharp"
    },
    {
      "x": -21,
      "y": 22,
      "z": -11,
      "name": "Plant_Moss_Block_Green"
    },
    {
      "x": -21,
      "y": 23,
      "z": -11,
      "name": "Soil_Seaweed_Block"
    },
    {
      "x": -21,
      "y": 24,
      "z": -11,
      "name": "Soil_Seaweed_Block"
    },
    {
      "x": -21,
      "y": 29,
      "z": -11,
      "name": "Plant_Moss_Block_Green"
    },
    {
      "x": -21,
      "y": 30,
      "z": -11,
      "name": "Plant_Moss_Block_Green"
    },
    {
      "x": -21,
      "y": 31,
      "z": -11,
      "name": "Soil_Seaweed_Block"
    },
    {
      "x": -21,
      "y": 32,
      "z": -11,
      "name": "Soil_Seaweed_Block"
    },
    {
      "x": -21,
      "y": 33,
      "z": -11,
      "name": "Soil_Seaweed_Block"
    },
    {
      "x": -21,
      "y": 34,
      "z": -11,
      "name": "Soil_Seaweed_Block"
    },
    {
      "x": -21,
      "y": 35,
      "z": -11,
      "name": "Soil_Clay_Lime"
    },
    {
      "x": -21,
      "y": 36,
      "z": -11,
      "name": "Plant_Grass_Sharp"
    },
    {
      "x": -21,
      "y": 29,
      "z": -10,
      "name": "Plant_Moss_Block_Green"
    },
    {
      "x": -21,
      "y": 30,
      "z": -10,
      "name": "Plant_Moss_Block_Green"
    },
    {
      "x": -21,
      "y": 31,
      "z": -10,
      "name": "Soil_Seaweed_Block"
    },
    {
      "x": -21,
      "y": 32,
      "z": -10,
      "name": "Soil_Seaweed_Block"
    },
    {
      "x": -21,
      "y": 33,
      "z": -10,
      "name": "Soil_Seaweed_Block"
    },
    {
      "x": -21,
      "y": 34,
      "z": -10,
      "name": "Soil_Seaweed_Block"
    },
    {
      "x": -21,
      "y": 35,
      "z": -10,
      "name": "Soil_Clay_Lime"
    },
    {
      "x": -21,
      "y": 36,
      "z": -10,
      "name": "Plant_Grass_Sharp"
    },
    {
      "x": -21,
      "y": 27,
      "z": -9,
      "name": "Soil_Seaweed_Block"
    },
    {
      "x": -21,
      "y": 28,
      "z": -9,
      "name": "Soil_Seaweed_Block"
    },
    {
      "x": -21,
      "y": 29,
      "z": -9,
      "name": "Soil_Seaweed_Block"
    },
    {
      "x": -21,
      "y": 30,
      "z": -9,
      "name": "Soil_Seaweed_Block"
    },
    {
      "x": -21,
      "y": 31,
      "z": -9,
      "name": "Soil_Seaweed_Block"
    },
    {
      "x": -21,
      "y": 32,
      "z": -9,
      "name": "Soil_Seaweed_Block"
    },
    {
      "x": -21,
      "y": 33,
      "z": -9,
      "name": "Soil_Seaweed_Block"
    },
    {
      "x": -21,
      "y": 34,
      "z": -9,
      "name": "Soil_Seaweed_Block"
    },
    {
      "x": -21,
      "y": 35,
      "z": -9,
      "name": "Soil_Clay_Lime"
    },
    {
      "x": -21,
      "y": 36,
      "z": -9,
      "name": "Plant_Grass_Sharp"
    },
    {
      "x": -21,
      "y": 24,
      "z": -8,
      "name": "Plant_Moss_Block_Green"
    },
    {
      "x": -21,
      "y": 25,
      "z": -8,
      "name": "Plant_Moss_Block_Green"
    },
    {
      "x": -21,
      "y": 26,
      "z": -8,
      "name": "Soil_Seaweed_Block"
    },
    {
      "x": -21,
      "y": 27,
      "z": -8,
      "name": "Soil_Seaweed_Block"
    },
    {
      "x": -21,
      "y": 28,
      "z": -8,
      "name": "Soil_Seaweed_Block"
    },
    {
      "x": -21,
      "y": 29,
      "z": -8,
      "name": "Soil_Seaweed_Block"
    },
    {
      "x": -21,
      "y": 30,
      "z": -8,
      "name": "Soil_Seaweed_Block"
    },
    {
      "x": -21,
      "y": 31,
      "z": -8,
      "name": "Soil_Seaweed_Block"
    },
    {
      "x": -21,
      "y": 32,
      "z": -8,
      "name": "Soil_Seaweed_Block"
    },
    {
      "x": -21,
      "y": 33,
      "z": -8,
      "name": "Soil_Seaweed_Block"
    },
    {
      "x": -21,
      "y": 34,
      "z": -8,
      "name": "Soil_Seaweed_Block"
    },
    {
      "x": -21,
      "y": 35,
      "z": -8,
      "name": "Soil_Seaweed_Block"
    },
    {
      "x": -21,
      "y": 36,
      "z": -8,
      "name": "Soil_Clay_Lime"
    },
    {
      "x": -21,
      "y": 37,
      "z": -8,
      "name": "Plant_Grass_Sharp"
    },
    {
      "x": -21,
      "y": 24,
      "z": -7,
      "name": "Plant_Moss_Block_Green"
    },
    {
      "x": -21,
      "y": 25,
      "z": -7,
      "name": "Soil_Seaweed_Block"
    },
    {
      "x": -21,
      "y": 26,
      "z": -7,
      "name": "Soil_Seaweed_Block"
    },
    {
      "x": -21,
      "y": 27,
      "z": -7,
      "name": "Soil_Seaweed_Block"
    },
    {
      "x": -21,
      "y": 28,
      "z": -7,
      "name": "Soil_Seaweed_Block"
    },
    {
      "x": -21,
      "y": 29,
      "z": -7,
      "name": "Soil_Seaweed_Block"
    },
    {
      "x": -21,
      "y": 30,
      "z": -7,
      "name": "Soil_Seaweed_Block"
    },
    {
      "x": -21,
      "y": 31,
      "z": -7,
      "name": "Soil_Seaweed_Block"
    },
    {
      "x": -21,
      "y": 32,
      "z": -7,
      "name": "Soil_Seaweed_Block"
    },
    {
      "x": -21,
      "y": 33,
      "z": -7,
      "name": "Plant_Moss_Block_Green"
    },
    {
      "x": -21,
      "y": 34,
      "z": -7,
      "name": "Soil_Seaweed_Block"
    },
    {
      "x": -21,
      "y": 35,
      "z": -7,
      "name": "Soil_Seaweed_Block"
    },
    {
      "x": -21,
      "y": 36,
      "z": -7,
      "name": "Soil_Clay_Lime"
    },
    {
      "x": -21,
      "y": 37,
      "z": -7,
      "name": "Plant_Grass_Sharp"
    },
    {
      "x": -21,
      "y": 22,
      "z": -6,
      "name": "Plant_Moss_Cave_Green",
      "support": 15,
      "rotation": 8
    },
    {
      "x": -21,
      "y": 23,
      "z": -6,
      "name": "Plant_Moss_Block_Green"
    },
    {
      "x": -21,
      "y": 24,
      "z": -6,
      "name": "Soil_Seaweed_Block"
    },
    {
      "x": -21,
      "y": 25,
      "z": -6,
      "name": "Soil_Seaweed_Block"
    },
    {
      "x": -21,
      "y": 26,
      "z": -6,
      "name": "Soil_Seaweed_Block"
    },
    {
      "x": -21,
      "y": 27,
      "z": -6,
      "name": "Soil_Seaweed_Block"
    },
    {
      "x": -21,
      "y": 28,
      "z": -6,
      "name": "Soil_Seaweed_Block"
    },
    {
      "x": -21,
      "y": 29,
      "z": -6,
      "name": "Soil_Seaweed_Block"
    },
    {
      "x": -21,
      "y": 30,
      "z": -6,
      "name": "Soil_Seaweed_Block"
    },
    {
      "x": -21,
      "y": 33,
      "z": -6,
      "name": "Plant_Moss_Block_Green"
    },
    {
      "x": -21,
      "y": 34,
      "z": -6,
      "name": "Soil_Seaweed_Block"
    },
    {
      "x": -21,
      "y": 35,
      "z": -6,
      "name": "Soil_Seaweed_Block"
    },
    {
      "x": -21,
      "y": 36,
      "z": -6,
      "name": "Soil_Clay_Lime"
    },
    {
      "x": -21,
      "y": 37,
      "z": -6,
      "name": "Plant_Grass_Sharp"
    },
    {
      "x": -21,
      "y": 22,
      "z": -5,
      "name": "Plant_Moss_Block_Green"
    },
    {
      "x": -21,
      "y": 23,
      "z": -5,
      "name": "Soil_Seaweed_Block"
    },
    {
      "x": -21,
      "y": 24,
      "z": -5,
      "name": "Soil_Seaweed_Block"
    },
    {
      "x": -21,
      "y": 25,
      "z": -5,
      "name": "Soil_Seaweed_Block"
    },
    {
      "x": -21,
      "y": 26,
      "z": -5,
      "name": "Soil_Seaweed_Block"
    },
    {
      "x": -21,
      "y": 27,
      "z": -5,
      "name": "Soil_Seaweed_Block"
    },
    {
      "x": -21,
      "y": 28,
      "z": -5,
      "name": "Soil_Seaweed_Block"
    },
    {
      "x": -21,
      "y": 29,
      "z": -5,
      "name": "Soil_Clay_Lime"
    },
    {
      "x": -21,
      "y": 30,
      "z": -5,
      "name": "Plant_Grass_Sharp"
    },
    {
      "x": -21,
      "y": 34,
      "z": -5,
      "name": "Plant_Moss_Block_Green"
    },
    {
      "x": -21,
      "y": 35,
      "z": -5,
      "name": "Soil_Seaweed_Block"
    },
    {
      "x": -21,
      "y": 36,
      "z": -5,
      "name": "Soil_Seaweed_Block"
    },
    {
      "x": -21,
      "y": 37,
      "z": -5,
      "name": "Soil_Clay_Lime"
    },
    {
      "x": -21,
      "y": 38,
      "z": -5,
      "name": "Plant_Grass_Sharp"
    },
    {
      "x": -21,
      "y": 21,
      "z": -4,
      "name": "Plant_Moss_Cave_Green",
      "support": 15,
      "rotation": 8
    },
    {
      "x": -21,
      "y": 22,
      "z": -4,
      "name": "Plant_Moss_Block_Green"
    },
    {
      "x": -21,
      "y": 23,
      "z": -4,
      "name": "Soil_Seaweed_Block"
    },
    {
      "x": -21,
      "y": 24,
      "z": -4,
      "name": "Soil_Seaweed_Block"
    },
    {
      "x": -21,
      "y": 25,
      "z": -4,
      "name": "Soil_Seaweed_Block"
    },
    {
      "x": -21,
      "y": 26,
      "z": -4,
      "name": "Soil_Seaweed_Block"
    },
    {
      "x": -21,
      "y": 27,
      "z": -4,
      "name": "Soil_Seaweed_Block"
    },
    {
      "x": -21,
      "y": 28,
      "z": -4,
      "name": "Soil_Clay_Lime"
    },
    {
      "x": -21,
      "y": 29,
      "z": -4,
      "name": "Plant_Grass_Sharp"
    },
    {
      "x": -21,
      "y": 34,
      "z": -4,
      "name": "Plant_Moss_Block_Green"
    },
    {
      "x": -21,
      "y": 35,
      "z": -4,
      "name": "Soil_Seaweed_Block"
    },
    {
      "x": -21,
      "y": 36,
      "z": -4,
      "name": "Soil_Seaweed_Block"
    },
    {
      "x": -21,
      "y": 37,
      "z": -4,
      "name": "Soil_Clay_Lime"
    },
    {
      "x": -21,
      "y": 38,
      "z": -4,
      "name": "Plant_Grass_Sharp"
    },
    {
      "x": -21,
      "y": 21,
      "z": -3,
      "name": "Plant_Moss_Cave_Green",
      "support": 15,
      "rotation": 8
    },
    {
      "x": -21,
      "y": 22,
      "z": -3,
      "name": "Plant_Moss_Block_Green"
    },
    {
      "x": -21,
      "y": 23,
      "z": -3,
      "name": "Soil_Seaweed_Block"
    },
    {
      "x": -21,
      "y": 24,
      "z": -3,
      "name": "Soil_Seaweed_Block"
    },
    {
      "x": -21,
      "y": 25,
      "z": -3,
      "name": "Soil_Seaweed_Block"
    },
    {
      "x": -21,
      "y": 26,
      "z": -3,
      "name": "Soil_Seaweed_Block"
    },
    {
      "x": -21,
      "y": 27,
      "z": -3,
      "name": "Soil_Clay_Lime"
    },
    {
      "x": -21,
      "y": 28,
      "z": -3,
      "name": "Plant_Grass_Sharp"
    },
    {
      "x": -21,
      "y": 34,
      "z": -3,
      "name": "Plant_Moss_Block_Green"
    },
    {
      "x": -21,
      "y": 35,
      "z": -3,
      "name": "Soil_Seaweed_Block"
    },
    {
      "x": -21,
      "y": 36,
      "z": -3,
      "name": "Soil_Seaweed_Block"
    },
    {
      "x": -21,
      "y": 37,
      "z": -3,
      "name": "Soil_Clay_Lime"
    },
    {
      "x": -21,
      "y": 38,
      "z": -3,
      "name": "Plant_Grass_Sharp"
    },
    {
      "x": -21,
      "y": 21,
      "z": -2,
      "name": "Plant_Moss_Cave_Green",
      "support": 15,
      "rotation": 8
    },
    {
      "x": -21,
      "y": 22,
      "z": -2,
      "name": "Plant_Moss_Block_Green"
    },
    {
      "x": -21,
      "y": 23,
      "z": -2,
      "name": "Soil_Seaweed_Block"
    },
    {
      "x": -21,
      "y": 24,
      "z": -2,
      "name": "Soil_Seaweed_Block"
    },
    {
      "x": -21,
      "y": 25,
      "z": -2,
      "name": "Soil_Seaweed_Block"
    },
    {
      "x": -21,
      "y": 26,
      "z": -2,
      "name": "Soil_Seaweed_Block"
    },
    {
      "x": -21,
      "y": 27,
      "z": -2,
      "name": "Soil_Seaweed_Block"
    },
    {
      "x": -21,
      "y": 28,
      "z": -2,
      "name": "Soil_Clay_Lime"
    },
    {
      "x": -21,
      "y": 29,
      "z": -2,
      "name": "Plant_Grass_Sharp"
    },
    {
      "x": -21,
      "y": 35,
      "z": -2,
      "name": "Plant_Moss_Block_Green"
    },
    {
      "x": -21,
      "y": 36,
      "z": -2,
      "name": "Soil_Seaweed_Block"
    },
    {
      "x": -21,
      "y": 37,
      "z": -2,
      "name": "Soil_Clay_Lime"
    },
    {
      "x": -21,
      "y": 38,
      "z": -2,
      "name": "Plant_Grass_Sharp"
    },
    {
      "x": -21,
      "y": 22,
      "z": -1,
      "name": "Plant_Moss_Block_Green"
    },
    {
      "x": -21,
      "y": 23,
      "z": -1,
      "name": "Plant_Moss_Block_Green"
    },
    {
      "x": -21,
      "y": 24,
      "z": -1,
      "name": "Soil_Seaweed_Block"
    },
    {
      "x": -21,
      "y": 25,
      "z": -1,
      "name": "Soil_Seaweed_Block"
    },
    {
      "x": -21,
      "y": 26,
      "z": -1,
      "name": "Soil_Seaweed_Block"
    },
    {
      "x": -21,
      "y": 27,
      "z": -1,
      "name": "Soil_Seaweed_Block"
    },
    {
      "x": -21,
      "y": 28,
      "z": -1,
      "name": "Soil_Seaweed_Block"
    },
    {
      "x": -21,
      "y": 29,
      "z": -1,
      "name": "Soil_Clay_Lime"
    },
    {
      "x": -21,
      "y": 30,
      "z": -1,
      "name": "Plant_Grass_Sharp"
    },
    {
      "x": -21,
      "y": 35,
      "z": -1,
      "name": "Plant_Moss_Block_Green"
    },
    {
      "x": -21,
      "y": 36,
      "z": -1,
      "name": "Soil_Seaweed_Block"
    },
    {
      "x": -21,
      "y": 37,
      "z": -1,
      "name": "Soil_Clay_Lime"
    },
    {
      "x": -21,
      "y": 38,
      "z": -1,
      "name": "Plant_Grass_Sharp"
    },
    {
      "x": -21,
      "y": 21,
      "z": 0,
      "name": "Plant_Moss_Block_Green"
    },
    {
      "x": -21,
      "y": 22,
      "z": 0,
      "name": "Soil_Seaweed_Block"
    },
    {
      "x": -21,
      "y": 23,
      "z": 0,
      "name": "Soil_Seaweed_Block"
    },
    {
      "x": -21,
      "y": 24,
      "z": 0,
      "name": "Soil_Seaweed_Block"
    },
    {
      "x": -21,
      "y": 26,
      "z": 0,
      "name": "Plant_Moss_Block_Green"
    },
    {
      "x": -21,
      "y": 27,
      "z": 0,
      "name": "Soil_Seaweed_Block"
    },
    {
      "x": -21,
      "y": 28,
      "z": 0,
      "name": "Soil_Seaweed_Block"
    },
    {
      "x": -21,
      "y": 29,
      "z": 0,
      "name": "Soil_Clay_Lime"
    },
    {
      "x": -21,
      "y": 30,
      "z": 0,
      "name": "Plant_Grass_Sharp"
    },
    {
      "x": -21,
      "y": 35,
      "z": 0,
      "name": "Plant_Moss_Block_Green"
    },
    {
      "x": -21,
      "y": 36,
      "z": 0,
      "name": "Soil_Seaweed_Block"
    },
    {
      "x": -21,
      "y": 37,
      "z": 0,
      "name": "Soil_Clay_Lime"
    },
    {
      "x": -21,
      "y": 38,
      "z": 0,
      "name": "Plant_Grass_Sharp"
    },
    {
      "x": -21,
      "y": 20,
      "z": 1,
      "name": "Plant_Moss_Block_Green"
    },
    {
      "x": -21,
      "y": 21,
      "z": 1,
      "name": "Soil_Seaweed_Block"
    },
    {
      "x": -21,
      "y": 22,
      "z": 1,
      "name": "Soil_Seaweed_Block"
    },
    {
      "x": -21,
      "y": 23,
      "z": 1,
      "name": "Soil_Seaweed_Block"
    },
    {
      "x": -21,
      "y": 27,
      "z": 1,
      "name": "Plant_Moss_Block_Green"
    },
    {
      "x": -21,
      "y": 28,
      "z": 1,
      "name": "Soil_Seaweed_Block"
    },
    {
      "x": -21,
      "y": 29,
      "z": 1,
      "name": "Soil_Seaweed_Block"
    },
    {
      "x": -21,
      "y": 30,
      "z": 1,
      "name": "Soil_Clay_Lime"
    },
    {
      "x": -21,
      "y": 31,
      "z": 1,
      "name": "Plant_Grass_Sharp"
    },
    {
      "x": -21,
      "y": 35,
      "z": 1,
      "name": "Plant_Moss_Block_Green"
    },
    {
      "x": -21,
      "y": 36,
      "z": 1,
      "name": "Soil_Seaweed_Block"
    },
    {
      "x": -21,
      "y": 37,
      "z": 1,
      "name": "Soil_Clay_Lime"
    },
    {
      "x": -21,
      "y": 38,
      "z": 1,
      "name": "Plant_Grass_Sharp"
    },
    {
      "x": -21,
      "y": 20,
      "z": 2,
      "name": "Soil_Seaweed_Block"
    },
    {
      "x": -21,
      "y": 21,
      "z": 2,
      "name": "Soil_Seaweed_Block"
    },
    {
      "x": -21,
      "y": 22,
      "z": 2,
      "name": "Soil_Seaweed_Block"
    },
    {
      "x": -21,
      "y": 28,
      "z": 2,
      "name": "Plant_Moss_Block_Green"
    },
    {
      "x": -21,
      "y": 29,
      "z": 2,
      "name": "Soil_Seaweed_Block"
    },
    {
      "x": -21,
      "y": 30,
      "z": 2,
      "name": "Soil_Seaweed_Block"
    },
    {
      "x": -21,
      "y": 36,
      "z": 2,
      "name": "Plant_Moss_Block_Green"
    },
    {
      "x": -21,
      "y": 37,
      "z": 2,
      "name": "Soil_Clay_Lime"
    },
    {
      "x": -21,
      "y": 38,
      "z": 2,
      "name": "Plant_Grass_Sharp"
    },
    {
      "x": -21,
      "y": 21,
      "z": 3,
      "name": "Soil_Seaweed_Block"
    },
    {
      "x": -21,
      "y": 29,
      "z": 3,
      "name": "Plant_Moss_Block_Green"
    },
    {
      "x": -21,
      "y": 30,
      "z": 3,
      "name": "Soil_Seaweed_Block"
    },
    {
      "x": -21,
      "y": 31,
      "z": 3,
      "name": "Soil_Seaweed_Block"
    },
    {
      "x": -21,
      "y": 36,
      "z": 3,
      "name": "Plant_Moss_Block_Green"
    },
    {
      "x": -21,
      "y": 37,
      "z": 3,
      "name": "Soil_Seaweed_Block"
    },
    {
      "x": -21,
      "y": 38,
      "z": 3,
      "name": "Soil_Clay_Lime"
    },
    {
      "x": -21,
      "y": 39,
      "z": 3,
      "name": "Plant_Grass_Sharp"
    },
    {
      "x": -21,
      "y": 15,
      "z": 4,
      "name": "Plant_Moss_Cave_Green",
      "support": 15,
      "rotation": 8
    },
    {
      "x": -21,
      "y": 16,
      "z": 4,
      "name": "Plant_Moss_Block_Green"
    },
    {
      "x": -21,
      "y": 17,
      "z": 4,
      "name": "Plant_Moss_Block_Green"
    },
    {
      "x": -21,
      "y": 18,
      "z": 4,
      "name": "Soil_Seaweed_Block"
    },
    {
      "x": -21,
      "y": 19,
      "z": 4,
      "name": "Soil_Seaweed_Block"
    },
    {
      "x": -21,
      "y": 28,
      "z": 4,
      "name": "Plant_Moss_Cave_Green",
      "support": 15,
      "rotation": 8
    },
    {
      "x": -21,
      "y": 29,
      "z": 4,
      "name": "Plant_Moss_Block_Green"
    },
    {
      "x": -21,
      "y": 30,
      "z": 4,
      "name": "Plant_Moss_Block_Green"
    },
    {
      "x": -21,
      "y": 31,
      "z": 4,
      "name": "Soil_Seaweed_Block"
    },
    {
      "x": -21,
      "y": 32,
      "z": 4,
      "name": "Soil_Seaweed_Block"
    },
    {
      "x": -21,
      "y": 33,
      "z": 4,
      "name": "Soil_Seaweed_Block"
    },
    {
      "x": -21,
      "y": 34,
      "z": 4,
      "name": "Plant_Moss_Block_Green"
    },
    {
      "x": -21,
      "y": 35,
      "z": 4,
      "name": "Plant_Moss_Block_Green"
    },
    {
      "x": -21,
      "y": 36,
      "z": 4,
      "name": "Soil_Seaweed_Block"
    },
    {
      "x": -21,
      "y": 37,
      "z": 4,
      "name": "Soil_Seaweed_Block"
    },
    {
      "x": -21,
      "y": 38,
      "z": 4,
      "name": "Soil_Seaweed_Block"
    },
    {
      "x": -21,
      "y": 14,
      "z": 5,
      "name": "Plant_Moss_Cave_Green",
      "support": 15,
      "rotation": 8
    },
    {
      "x": -21,
      "y": 15,
      "z": 5,
      "name": "Plant_Moss_Block_Green"
    },
    {
      "x": -21,
      "y": 16,
      "z": 5,
      "name": "Soil_Seaweed_Block"
    },
    {
      "x": -21,
      "y": 17,
      "z": 5,
      "name": "Soil_Seaweed_Block"
    },
    {
      "x": -21,
      "y": 18,
      "z": 5,
      "name": "Soil_Seaweed_Block"
    },
    {
      "x": -21,
      "y": 19,
      "z": 5,
      "name": "Soil_Seaweed_Block"
    },
    {
      "x": -21,
      "y": 29,
      "z": 5,
      "name": "Plant_Moss_Cave_Green",
      "support": 15,
      "rotation": 8
    },
    {
      "x": -21,
      "y": 30,
      "z": 5,
      "name": "Plant_Moss_Block_Green"
    },
    {
      "x": -21,
      "y": 31,
      "z": 5,
      "name": "Soil_Seaweed_Block"
    },
    {
      "x": -21,
      "y": 32,
      "z": 5,
      "name": "Soil_Seaweed_Block"
    },
    {
      "x": -21,
      "y": 33,
      "z": 5,
      "name": "Soil_Seaweed_Block"
    },
    {
      "x": -21,
      "y": 34,
      "z": 5,
      "name": "Soil_Seaweed_Block"
    },
    {
      "x": -21,
      "y": 35,
      "z": 5,
      "name": "Soil_Seaweed_Block"
    },
    {
      "x": -21,
      "y": 36,
      "z": 5,
      "name": "Soil_Seaweed_Block"
    },
    {
      "x": -21,
      "y": 37,
      "z": 5,
      "name": "Soil_Seaweed_Block"
    },
    {
      "x": -21,
      "y": 38,
      "z": 5,
      "name": "Soil_Seaweed_Block"
    },
    {
      "x": -21,
      "y": 39,
      "z": 5,
      "name": "Soil_Seaweed_Block"
    },
    {
      "x": -21,
      "y": 40,
      "z": 5,
      "name": "Soil_Seaweed_Block"
    },
    {
      "x": -21,
      "y": 41,
      "z": 5,
      "name": "Soil_Seaweed_Block"
    },
    {
      "x": -21,
      "y": 42,
      "z": 5,
      "name": "Soil_Seaweed_Block"
    },
    {
      "x": -21,
      "y": 14,
      "z": 6,
      "name": "Plant_Moss_Cave_Green",
      "support": 15,
      "rotation": 8
    },
    {
      "x": -21,
      "y": 15,
      "z": 6,
      "name": "Plant_Moss_Block_Green"
    },
    {
      "x": -21,
      "y": 16,
      "z": 6,
      "name": "Soil_Seaweed_Block"
    },
    {
      "x": -21,
      "y": 17,
      "z": 6,
      "name": "Soil_Seaweed_Block"
    },
    {
      "x": -21,
      "y": 18,
      "z": 6,
      "name": "Soil_Seaweed_Block"
    },
    {
      "x": -21,
      "y": 19,
      "z": 6,
      "name": "Soil_Seaweed_Block"
    },
    {
      "x": -21,
      "y": 30,
      "z": 6,
      "name": "Plant_Moss_Cave_Green",
      "support": 15,
      "rotation": 8
    },
    {
      "x": -21,
      "y": 31,
      "z": 6,
      "name": "Plant_Moss_Block_Green"
    },
    {
      "x": -21,
      "y": 32,
      "z": 6,
      "name": "Soil_Seaweed_Block"
    },
    {
      "x": -21,
      "y": 33,
      "z": 6,
      "name": "Soil_Seaweed_Block"
    },
    {
      "x": -21,
      "y": 34,
      "z": 6,
      "name": "Soil_Seaweed_Block"
    },
    {
      "x": -21,
      "y": 35,
      "z": 6,
      "name": "Soil_Seaweed_Block"
    },
    {
      "x": -21,
      "y": 36,
      "z": 6,
      "name": "Soil_Seaweed_Block"
    },
    {
      "x": -21,
      "y": 37,
      "z": 6,
      "name": "Soil_Seaweed_Block"
    },
    {
      "x": -21,
      "y": 38,
      "z": 6,
      "name": "Soil_Seaweed_Block"
    },
    {
      "x": -21,
      "y": 39,
      "z": 6,
      "name": "Soil_Seaweed_Block"
    },
    {
      "x": -21,
      "y": 40,
      "z": 6,
      "name": "Soil_Seaweed_Block"
    },
    {
      "x": -21,
      "y": 41,
      "z": 6,
      "name": "Soil_Seaweed_Block"
    },
    {
      "x": -21,
      "y": 42,
      "z": 6,
      "name": "Soil_Seaweed_Block"
    },
    {
      "x": -21,
      "y": 43,
      "z": 6,
      "name": "Soil_Seaweed_Block"
    },
    {
      "x": -21,
      "y": 14,
      "z": 7,
      "name": "Plant_Moss_Cave_Green",
      "support": 15,
      "rotation": 8
    },
    {
      "x": -21,
      "y": 15,
      "z": 7,
      "name": "Plant_Moss_Block_Green"
    },
    {
      "x": -21,
      "y": 16,
      "z": 7,
      "name": "Soil_Seaweed_Block"
    },
    {
      "x": -21,
      "y": 17,
      "z": 7,
      "name": "Soil_Seaweed_Block"
    },
    {
      "x": -21,
      "y": 18,
      "z": 7,
      "name": "Soil_Seaweed_Block"
    },
    {
      "x": -21,
      "y": 19,
      "z": 7,
      "name": "Soil_Seaweed_Block"
    },
    {
      "x": -21,
      "y": 30,
      "z": 7,
      "name": "Plant_Moss_Cave_Green",
      "support": 15,
      "rotation": 8
    },
    {
      "x": -21,
      "y": 31,
      "z": 7,
      "name": "Plant_Moss_Block_Green"
    },
    {
      "x": -21,
      "y": 32,
      "z": 7,
      "name": "Soil_Seaweed_Block"
    },
    {
      "x": -21,
      "y": 33,
      "z": 7,
      "name": "Soil_Seaweed_Block"
    },
    {
      "x": -21,
      "y": 34,
      "z": 7,
      "name": "Soil_Seaweed_Block"
    },
    {
      "x": -21,
      "y": 35,
      "z": 7,
      "name": "Soil_Seaweed_Block"
    },
    {
      "x": -21,
      "y": 36,
      "z": 7,
      "name": "Soil_Seaweed_Block"
    },
    {
      "x": -21,
      "y": 37,
      "z": 7,
      "name": "Soil_Seaweed_Block"
    },
    {
      "x": -21,
      "y": 38,
      "z": 7,
      "name": "Soil_Seaweed_Block"
    },
    {
      "x": -21,
      "y": 39,
      "z": 7,
      "name": "Soil_Seaweed_Block"
    },
    {
      "x": -21,
      "y": 40,
      "z": 7,
      "name": "Soil_Seaweed_Block"
    },
    {
      "x": -21,
      "y": 41,
      "z": 7,
      "name": "Soil_Seaweed_Block"
    },
    {
      "x": -21,
      "y": 42,
      "z": 7,
      "name": "Soil_Seaweed_Block"
    },
    {
      "x": -21,
      "y": 43,
      "z": 7,
      "name": "Soil_Clay_Lime"
    },
    {
      "x": -21,
      "y": 44,
      "z": 7,
      "name": "Plant_Grass_Sharp"
    },
    {
      "x": -21,
      "y": 15,
      "z": 8,
      "name": "Plant_Moss_Cave_Green",
      "support": 15,
      "rotation": 8
    },
    {
      "x": -21,
      "y": 16,
      "z": 8,
      "name": "Plant_Moss_Block_Green"
    },
    {
      "x": -21,
      "y": 17,
      "z": 8,
      "name": "Soil_Seaweed_Block"
    },
    {
      "x": -21,
      "y": 18,
      "z": 8,
      "name": "Soil_Seaweed_Block"
    },
    {
      "x": -21,
      "y": 25,
      "z": 8,
      "name": "Soil_Seaweed_Block"
    },
    {
      "x": -21,
      "y": 29,
      "z": 8,
      "name": "Plant_Moss_Cave_Green",
      "support": 15,
      "rotation": 8
    },
    {
      "x": -21,
      "y": 30,
      "z": 8,
      "name": "Plant_Moss_Block_Green"
    },
    {
      "x": -21,
      "y": 31,
      "z": 8,
      "name": "Soil_Seaweed_Block"
    },
    {
      "x": -21,
      "y": 32,
      "z": 8,
      "name": "Soil_Seaweed_Block"
    },
    {
      "x": -21,
      "y": 33,
      "z": 8,
      "name": "Soil_Seaweed_Block"
    },
    {
      "x": -21,
      "y": 34,
      "z": 8,
      "name": "Soil_Seaweed_Block"
    },
    {
      "x": -21,
      "y": 35,
      "z": 8,
      "name": "Soil_Seaweed_Block"
    },
    {
      "x": -21,
      "y": 36,
      "z": 8,
      "name": "Soil_Seaweed_Block"
    },
    {
      "x": -21,
      "y": 37,
      "z": 8,
      "name": "Soil_Seaweed_Block"
    },
    {
      "x": -21,
      "y": 38,
      "z": 8,
      "name": "Soil_Seaweed_Block"
    },
    {
      "x": -21,
      "y": 39,
      "z": 8,
      "name": "Soil_Seaweed_Block"
    },
    {
      "x": -21,
      "y": 40,
      "z": 8,
      "name": "Soil_Seaweed_Block"
    },
    {
      "x": -21,
      "y": 41,
      "z": 8,
      "name": "Soil_Seaweed_Block"
    },
    {
      "x": -21,
      "y": 42,
      "z": 8,
      "name": "Soil_Seaweed_Block"
    },
    {
      "x": -21,
      "y": 43,
      "z": 8,
      "name": "Soil_Clay_Lime"
    },
    {
      "x": -21,
      "y": 44,
      "z": 8,
      "name": "Plant_Grass_Sharp"
    },
    {
      "x": -21,
      "y": 25,
      "z": 9,
      "name": "Plant_Moss_Block_Green"
    },
    {
      "x": -21,
      "y": 26,
      "z": 9,
      "name": "Soil_Seaweed_Block"
    },
    {
      "x": -21,
      "y": 27,
      "z": 9,
      "name": "Soil_Seaweed_Block"
    },
    {
      "x": -21,
      "y": 28,
      "z": 9,
      "name": "Soil_Seaweed_Block"
    },
    {
      "x": -21,
      "y": 29,
      "z": 9,
      "name": "Plant_Moss_Block_Green"
    },
    {
      "x": -21,
      "y": 30,
      "z": 9,
      "name": "Soil_Seaweed_Block"
    },
    {
      "x": -21,
      "y": 31,
      "z": 9,
      "name": "Soil_Seaweed_Block"
    },
    {
      "x": -21,
      "y": 32,
      "z": 9,
      "name": "Soil_Seaweed_Block"
    },
    {
      "x": -21,
      "y": 33,
      "z": 9,
      "name": "Soil_Seaweed_Block"
    },
    {
      "x": -21,
      "y": 34,
      "z": 9,
      "name": "Soil_Seaweed_Block"
    },
    {
      "x": -21,
      "y": 35,
      "z": 9,
      "name": "Soil_Seaweed_Block"
    },
    {
      "x": -21,
      "y": 36,
      "z": 9,
      "name": "Soil_Seaweed_Block"
    },
    {
      "x": -21,
      "y": 37,
      "z": 9,
      "name": "Soil_Seaweed_Block"
    },
    {
      "x": -21,
      "y": 38,
      "z": 9,
      "name": "Soil_Seaweed_Block"
    },
    {
      "x": -21,
      "y": 39,
      "z": 9,
      "name": "Soil_Seaweed_Block"
    },
    {
      "x": -21,
      "y": 40,
      "z": 9,
      "name": "Soil_Seaweed_Block"
    },
    {
      "x": -21,
      "y": 41,
      "z": 9,
      "name": "Soil_Seaweed_Block"
    },
    {
      "x": -21,
      "y": 42,
      "z": 9,
      "name": "Soil_Seaweed_Block"
    },
    {
      "x": -21,
      "y": 43,
      "z": 9,
      "name": "Soil_Clay_Lime"
    },
    {
      "x": -21,
      "y": 44,
      "z": 9,
      "name": "Plant_Grass_Sharp"
    },
    {
      "x": -21,
      "y": 26,
      "z": 10,
      "name": "Plant_Moss_Block_Green"
    },
    {
      "x": -21,
      "y": 27,
      "z": 10,
      "name": "Plant_Moss_Block_Green"
    },
    {
      "x": -21,
      "y": 28,
      "z": 10,
      "name": "Plant_Moss_Block_Green"
    },
    {
      "x": -21,
      "y": 29,
      "z": 10,
      "name": "Soil_Seaweed_Block"
    },
    {
      "x": -21,
      "y": 30,
      "z": 10,
      "name": "Soil_Seaweed_Block"
    },
    {
      "x": -21,
      "y": 31,
      "z": 10,
      "name": "Soil_Seaweed_Block"
    },
    {
      "x": -21,
      "y": 32,
      "z": 10,
      "name": "Soil_Seaweed_Block"
    },
    {
      "x": -21,
      "y": 33,
      "z": 10,
      "name": "Soil_Seaweed_Block"
    },
    {
      "x": -21,
      "y": 34,
      "z": 10,
      "name": "Soil_Seaweed_Block"
    },
    {
      "x": -21,
      "y": 35,
      "z": 10,
      "name": "Soil_Seaweed_Block"
    },
    {
      "x": -21,
      "y": 36,
      "z": 10,
      "name": "Soil_Seaweed_Block"
    },
    {
      "x": -21,
      "y": 37,
      "z": 10,
      "name": "Soil_Seaweed_Block"
    },
    {
      "x": -21,
      "y": 38,
      "z": 10,
      "name": "Soil_Seaweed_Block"
    },
    {
      "x": -21,
      "y": 39,
      "z": 10,
      "name": "Soil_Seaweed_Block"
    },
    {
      "x": -21,
      "y": 40,
      "z": 10,
      "name": "Soil_Seaweed_Block"
    },
    {
      "x": -21,
      "y": 41,
      "z": 10,
      "name": "Soil_Seaweed_Block"
    },
    {
      "x": -21,
      "y": 42,
      "z": 10,
      "name": "Soil_Seaweed_Block"
    },
    {
      "x": -21,
      "y": 43,
      "z": 10,
      "name": "Soil_Clay_Lime"
    },
    {
      "x": -21,
      "y": 44,
      "z": 10,
      "name": "Plant_Grass_Sharp"
    },
    {
      "x": -21,
      "y": 28,
      "z": 11,
      "name": "Plant_Moss_Block_Green"
    },
    {
      "x": -21,
      "y": 29,
      "z": 11,
      "name": "Soil_Seaweed_Block"
    },
    {
      "x": -21,
      "y": 30,
      "z": 11,
      "name": "Soil_Seaweed_Block"
    },
    {
      "x": -21,
      "y": 31,
      "z": 11,
      "name": "Soil_Seaweed_Block"
    },
    {
      "x": -21,
      "y": 32,
      "z": 11,
      "name": "Soil_Seaweed_Block"
    },
    {
      "x": -21,
      "y": 33,
      "z": 11,
      "name": "Soil_Seaweed_Block"
    },
    {
      "x": -21,
      "y": 34,
      "z": 11,
      "name": "Soil_Seaweed_Block"
    },
    {
      "x": -21,
      "y": 35,
      "z": 11,
      "name": "Soil_Seaweed_Block"
    },
    {
      "x": -21,
      "y": 28,
      "z": 12,
      "name": "Plant_Moss_Block_Green"
    },
    {
      "x": -21,
      "y": 29,
      "z": 12,
      "name": "Soil_Seaweed_Block"
    },
    {
      "x": -21,
      "y": 30,
      "z": 12,
      "name": "Soil_Seaweed_Block"
    },
    {
      "x": -21,
      "y": 31,
      "z": 12,
      "name": "Soil_Seaweed_Block"
    },
    {
      "x": -21,
      "y": 32,
      "z": 12,
      "name": "Soil_Seaweed_Block"
    },
    {
      "x": -21,
      "y": 33,
      "z": 12,
      "name": "Soil_Seaweed_Block"
    },
    {
      "x": -21,
      "y": 34,
      "z": 12,
      "name": "Soil_Clay_Lime"
    },
    {
      "x": -21,
      "y": 35,
      "z": 12,
      "name": "Plant_Grass_Sharp"
    },
    {
      "x": -21,
      "y": 28,
      "z": 13,
      "name": "Plant_Moss_Block_Green"
    },
    {
      "x": -21,
      "y": 29,
      "z": 13,
      "name": "Soil_Seaweed_Block"
    },
    {
      "x": -21,
      "y": 30,
      "z": 13,
      "name": "Soil_Seaweed_Block"
    },
    {
      "x": -21,
      "y": 31,
      "z": 13,
      "name": "Soil_Seaweed_Block"
    },
    {
      "x": -21,
      "y": 32,
      "z": 13,
      "name": "Soil_Seaweed_Block"
    },
    {
      "x": -21,
      "y": 33,
      "z": 13,
      "name": "Soil_Clay_Lime"
    },
    {
      "x": -21,
      "y": 34,
      "z": 13,
      "name": "Plant_Grass_Sharp"
    },
    {
      "x": -21,
      "y": 28,
      "z": 14,
      "name": "Plant_Moss_Block_Green"
    },
    {
      "x": -21,
      "y": 29,
      "z": 14,
      "name": "Soil_Seaweed_Block"
    },
    {
      "x": -21,
      "y": 30,
      "z": 14,
      "name": "Soil_Seaweed_Block"
    },
    {
      "x": -21,
      "y": 31,
      "z": 14,
      "name": "Soil_Seaweed_Block"
    },
    {
      "x": -21,
      "y": 32,
      "z": 14,
      "name": "Soil_Clay_Lime"
    },
    {
      "x": -21,
      "y": 33,
      "z": 14,
      "name": "Plant_Grass_Sharp"
    },
    {
      "x": -21,
      "y": 29,
      "z": 15,
      "name": "Plant_Moss_Block_Green"
    },
    {
      "x": -21,
      "y": 30,
      "z": 15,
      "name": "Soil_Seaweed_Block"
    },
    {
      "x": -21,
      "y": 31,
      "z": 15,
      "name": "Soil_Seaweed_Block"
    },
    {
      "x": -21,
      "y": 30,
      "z": 16,
      "name": "Soil_Seaweed_Block"
    },
    {
      "x": -20,
      "y": 21,
      "z": -15,
      "name": "Plant_Moss_Cave_Green",
      "support": 15,
      "rotation": 8
    },
    {
      "x": -20,
      "y": 22,
      "z": -15,
      "name": "Plant_Moss_Block_Green"
    },
    {
      "x": -20,
      "y": 23,
      "z": -15,
      "name": "Soil_Seaweed_Block"
    },
    {
      "x": -20,
      "y": 24,
      "z": -15,
      "name": "Soil_Seaweed_Block"
    },
    {
      "x": -20,
      "y": 41,
      "z": -15,
      "name": "Soil_Seaweed_Block"
    },
    {
      "x": -20,
      "y": 42,
      "z": -15,
      "name": "Soil_Seaweed_Block"
    },
    {
      "x": -20,
      "y": 43,
      "z": -15,
      "name": "Soil_Seaweed_Block"
    },
    {
      "x": -20,
      "y": 20,
      "z": -14,
      "name": "Plant_Moss_Cave_Green",
      "support": 15,
      "rotation": 8
    },
    {
      "x": -20,
      "y": 21,
      "z": -14,
      "name": "Plant_Moss_Block_Green"
    },
    {
      "x": -20,
      "y": 22,
      "z": -14,
      "name": "Soil_Seaweed_Block"
    },
    {
      "x": -20,
      "y": 23,
      "z": -14,
      "name": "Soil_Seaweed_Block"
    },
    {
      "x": -20,
      "y": 24,
      "z": -14,
      "name": "Soil_Seaweed_Block"
    },
    {
      "x": -20,
      "y": 25,
      "z": -14,
      "name": "Soil_Seaweed_Block"
    },
    {
      "x": -20,
      "y": 31,
      "z": -14,
      "name": "Plant_Moss_Block_Green"
    },
    {
      "x": -20,
      "y": 32,
      "z": -14,
      "name": "Plant_Moss_Block_Green"
    },
    {
      "x": -20,
      "y": 33,
      "z": -14,
      "name": "Soil_Seaweed_Block"
    },
    {
      "x": -20,
      "y": 34,
      "z": -14,
      "name": "Soil_Seaweed_Block"
    },
    {
      "x": -20,
      "y": 35,
      "z": -14,
      "name": "Soil_Seaweed_Block"
    },
    {
      "x": -20,
      "y": 40,
      "z": -14,
      "name": "Plant_Moss_Block_Green"
    },
    {
      "x": -20,
      "y": 41,
      "z": -14,
      "name": "Soil_Seaweed_Block"
    },
    {
      "x": -20,
      "y": 42,
      "z": -14,
      "name": "Soil_Seaweed_Block"
    },
    {
      "x": -20,
      "y": 43,
      "z": -14,
      "name": "Soil_Seaweed_Block"
    },
    {
      "x": -20,
      "y": 20,
      "z": -13,
      "name": "Plant_Moss_Cave_Green",
      "support": 15,
      "rotation": 8
    },
    {
      "x": -20,
      "y": 21,
      "z": -13,
      "name": "Plant_Moss_Block_Green",
      "support": 15
    },
    {
      "x": -20,
      "y": 22,
      "z": -13,
      "name": "Soil_Seaweed_Block"
    },
    {
      "x": -20,
      "y": 23,
      "z": -13,
      "name": "Soil_Seaweed_Block"
    },
    {
      "x": -20,
      "y": 24,
      "z": -13,
      "name": "Soil_Seaweed_Block"
    },
    {
      "x": -20,
      "y": 25,
      "z": -13,
      "name": "Soil_Seaweed_Block"
    },
    {
      "x": -20,
      "y": 26,
      "z": -13,
      "name": "Soil_Seaweed_Block"
    },
    {
      "x": -20,
      "y": 29,
      "z": -13,
      "name": "Plant_Moss_Block_Green"
    },
    {
      "x": -20,
      "y": 30,
      "z": -13,
      "name": "Plant_Moss_Block_Green"
    },
    {
      "x": -20,
      "y": 31,
      "z": -13,
      "name": "Soil_Seaweed_Block"
    },
    {
      "x": -20,
      "y": 32,
      "z": -13,
      "name": "Soil_Seaweed_Block"
    },
    {
      "x": -20,
      "y": 33,
      "z": -13,
      "name": "Soil_Seaweed_Block"
    },
    {
      "x": -20,
      "y": 34,
      "z": -13,
      "name": "Soil_Seaweed_Block"
    },
    {
      "x": -20,
      "y": 35,
      "z": -13,
      "name": "Soil_Seaweed_Block"
    },
    {
      "x": -20,
      "y": 36,
      "z": -13,
      "name": "Soil_Clay_Lime"
    },
    {
      "x": -20,
      "y": 37,
      "z": -13,
      "name": "Plant_Grass_Sharp"
    },
    {
      "x": -20,
      "y": 40,
      "z": -13,
      "name": "Plant_Moss_Block_Green"
    },
    {
      "x": -20,
      "y": 41,
      "z": -13,
      "name": "Soil_Seaweed_Block"
    },
    {
      "x": -20,
      "y": 42,
      "z": -13,
      "name": "Soil_Seaweed_Block"
    },
    {
      "x": -20,
      "y": 43,
      "z": -13,
      "name": "Soil_Seaweed_Block"
    },
    {
      "x": -20,
      "y": 21,
      "z": -12,
      "name": "Plant_Moss_Block_Green"
    },
    {
      "x": -20,
      "y": 22,
      "z": -12,
      "name": "Soil_Seaweed_Block"
    },
    {
      "x": -20,
      "y": 23,
      "z": -12,
      "name": "Soil_Seaweed_Block"
    },
    {
      "x": -20,
      "y": 24,
      "z": -12,
      "name": "Soil_Seaweed_Block"
    },
    {
      "x": -20,
      "y": 25,
      "z": -12,
      "name": "Soil_Seaweed_Block"
    },
    {
      "x": -20,
      "y": 26,
      "z": -12,
      "name": "Soil_Seaweed_Block"
    },
    {
      "x": -20,
      "y": 27,
      "z": -12,
      "name": "Soil_Seaweed_Block"
    },
    {
      "x": -20,
      "y": 28,
      "z": -12,
      "name": "Soil_Seaweed_Block"
    },
    {
      "x": -20,
      "y": 29,
      "z": -12,
      "name": "Plant_Moss_Block_Green"
    },
    {
      "x": -20,
      "y": 30,
      "z": -12,
      "name": "Soil_Seaweed_Block"
    },
    {
      "x": -20,
      "y": 31,
      "z": -12,
      "name": "Soil_Seaweed_Block"
    },
    {
      "x": -20,
      "y": 32,
      "z": -12,
      "name": "Soil_Seaweed_Block"
    },
    {
      "x": -20,
      "y": 33,
      "z": -12,
      "name": "Soil_Seaweed_Block"
    },
    {
      "x": -20,
      "y": 34,
      "z": -12,
      "name": "Soil_Seaweed_Block"
    },
    {
      "x": -20,
      "y": 35,
      "z": -12,
      "name": "Soil_Seaweed_Block"
    },
    {
      "x": -20,
      "y": 36,
      "z": -12,
      "name": "Soil_Seaweed_Block"
    },
    {
      "x": -20,
      "y": 37,
      "z": -12,
      "name": "Soil_Clay_Lime"
    },
    {
      "x": -20,
      "y": 38,
      "z": -12,
      "name": "Plant_Grass_Sharp"
    },
    {
      "x": -20,
      "y": 41,
      "z": -12,
      "name": "Soil_Seaweed_Block"
    },
    {
      "x": -20,
      "y": 42,
      "z": -12,
      "name": "Soil_Seaweed_Block"
    },
    {
      "x": -20,
      "y": 21,
      "z": -11,
      "name": "Plant_Moss_Block_Green"
    },
    {
      "x": -20,
      "y": 22,
      "z": -11,
      "name": "Plant_Moss_Block_Green"
    },
    {
      "x": -20,
      "y": 23,
      "z": -11,
      "name": "Soil_Seaweed_Block"
    },
    {
      "x": -20,
      "y": 24,
      "z": -11,
      "name": "Soil_Seaweed_Block"
    },
    {
      "x": -20,
      "y": 25,
      "z": -11,
      "name": "Soil_Seaweed_Block"
    },
    {
      "x": -20,
      "y": 26,
      "z": -11,
      "name": "Soil_Seaweed_Block"
    },
    {
      "x": -20,
      "y": 27,
      "z": -11,
      "name": "Soil_Seaweed_Block"
    },
    {
      "x": -20,
      "y": 28,
      "z": -11,
      "name": "Plant_Moss_Block_Green"
    },
    {
      "x": -20,
      "y": 29,
      "z": -11,
      "name": "Soil_Seaweed_Block"
    },
    {
      "x": -20,
      "y": 30,
      "z": -11,
      "name": "Soil_Seaweed_Block"
    },
    {
      "x": -20,
      "y": 31,
      "z": -11,
      "name": "Soil_Seaweed_Block"
    },
    {
      "x": -20,
      "y": 32,
      "z": -11,
      "name": "Soil_Seaweed_Block"
    },
    {
