{
  "version": 8,
  "blockIdVersion": 10,
  "anchorX": 0,
  "anchorY": 5,
  "anchorZ": 0,
  "blocks": [
    {
      "x": -17,
      "y": 14,
      "z": 5,
      "name": "Soil_Clay_Green"
    },
    {
      "x": -17,
      "y": 15,
      "z": 5,
      "name": "Soil_Clay_Green"
    },
    {
      "x": -17,
      "y": 16,
      "z": 5,
      "name": "Soil_Seaweed_Block"
    },
    {
      "x": -17,
      "y": 15,
      "z": 6,
      "name": "Soil_Clay_Green"
    },
    {
      "x": -16,
      "y": 20,
      "z": -7,
      "name": "Soil_Seaweed_Block"
    },
    {
      "x": -16,
      "y": 19,
      "z": -6,
      "name": "Soil_Clay_Green"
    },
    {
      "x": -16,
      "y": 20,
      "z": -6,
      "name": "Soil_Seaweed_Block"
    },
    {
      "x": -16,
      "y": 21,
      "z": -6,
      "name": "Soil_Seaweed_Block"
    },
    {
      "x": -16,
      "y": 20,
      "z": -5,
      "name": "Soil_Seaweed_Block"
    },
    {
      "x": -16,
      "y": 20,
      "z": -4,
      "name": "Soil_Seaweed_Block"
    },
    {
      "x": -16,
      "y": 19,
      "z": -2,
      "name": "Soil_Clay_Green"
    },
    {
      "x": -16,
      "y": 19,
      "z": -1,
      "name": "Soil_Clay_Green"
    },
    {
      "x": -16,
      "y": 19,
      "z": 0,
      "name": "Soil_Seaweed_Block"
    },
    {
      "x": -16,
      "y": 19,
      "z": 1,
      "name": "Soil_Seaweed_Block"
    },
    {
      "x": -16,
      "y": 19,
      "z": 2,
      "name": "Soil_Clay_Lime"
    },
    {
      "x": -16,
      "y": 20,
      "z": 2,
      "name": "Plant_Grass_Sharp"
    },
    {
      "x": -16,
      "y": 15,
      "z": 3,
      "name": "Soil_Clay_Green"
    },
    {
      "x": -16,
      "y": 16,
      "z": 3,
      "name": "Soil_Seaweed_Block"
    },
    {
      "x": -16,
      "y": 19,
      "z": 3,
      "name": "Soil_Clay_Lime"
    },
    {
      "x": -16,
      "y": 20,
      "z": 3,
      "name": "Plant_Grass_Sharp"
    },
    {
      "x": -16,
      "y": 13,
      "z": 4,
      "name": "Soil_Clay_Green"
    },
    {
      "x": -16,
      "y": 14,
      "z": 4,
      "name": "Soil_Clay_Green"
    },
    {
      "x": -16,
      "y": 15,
      "z": 4,
      "name": "Soil_Seaweed_Block"
    },
    {
      "x": -16,
      "y": 16,
      "z": 4,
      "name": "Soil_Seaweed_Block"
    },
    {
      "x": -16,
      "y": 17,
      "z": 4,
      "name": "Soil_Clay_Lime"
    },
    {
      "x": -16,
      "y": 18,
      "z": 4,
      "name": "Plant_Grass_Sharp"
    },
    {
      "x": -16,
      "y": 14,
      "z": 5,
      "name": "Soil_Clay_Green"
    },
    {
      "x": -16,
      "y": 15,
      "z": 5,
      "name": "Soil_Seaweed_Block"
    },
    {
      "x": -16,
      "y": 16,
      "z": 5,
      "name": "Soil_Seaweed_Block"
    },
    {
      "x": -16,
      "y": 14,
      "z": 6,
      "name": "Soil_Clay_Green"
    },
    {
      "x": -16,
      "y": 15,
      "z": 6,
      "name": "Soil_Clay_Green"
    },
    {
      "x": -16,
      "y": 16,
      "z": 6,
      "name": "Soil_Seaweed_Block"
    },
    {
      "x": -15,
      "y": 18,
      "z": -7,
      "name": "Soil_Clay_Green"
    },
    {
      "x": -15,
      "y": 19,
      "z": -7,
      "name": "Soil_Clay_Green"
    },
    {
      "x": -15,
      "y": 20,
      "z": -7,
      "name": "Soil_Seaweed_Block"
    },
    {
      "x": -15,
      "y": 21,
      "z": -7,
      "name": "Soil_Seaweed_Block"
    },
    {
      "x": -15,
      "y": 18,
      "z": -6,
      "name": "Soil_Clay_Green"
    },
    {
      "x": -15,
      "y": 19,
      "z": -6,
      "name": "Soil_Clay_Green"
    },
    {
      "x": -15,
      "y": 20,
      "z": -6,
      "name": "Soil_Seaweed_Block"
    },
    {
      "x": -15,
      "y": 21,
      "z": -6,
      "name": "Soil_Seaweed_Block"
    },
    {
      "x": -15,
      "y": 18,
      "z": -5,
      "name": "Soil_Clay_Green"
    },
    {
      "x": -15,
      "y": 19,
      "z": -5,
      "name": "Soil_Clay_Green"
    },
    {
      "x": -15,
      "y": 20,
      "z": -5,
      "name": "Soil_Seaweed_Block"
    },
    {
      "x": -15,
      "y": 21,
      "z": -5,
      "name": "Soil_Clay_Lime"
    },
    {
      "x": -15,
      "y": 22,
      "z": -5,
      "name": "Plant_Grass_Sharp"
    },
    {
      "x": -15,
      "y": 18,
      "z": -4,
      "name": "Soil_Clay_Green"
    },
    {
      "x": -15,
      "y": 19,
      "z": -4,
      "name": "Soil_Clay_Green"
    },
    {
      "x": -15,
      "y": 20,
      "z": -4,
      "name": "Soil_Seaweed_Block"
    },
    {
      "x": -15,
      "y": 21,
      "z": -4,
      "name": "Soil_Clay_Lime"
    },
    {
      "x": -15,
      "y": 22,
      "z": -4,
      "name": "Plant_Grass_Sharp"
    },
    {
      "x": -15,
      "y": 19,
      "z": -3,
      "name": "Soil_Clay_Green"
    },
    {
      "x": -15,
      "y": 19,
      "z": -2,
      "name": "Soil_Clay_Green"
    },
    {
      "x": -15,
      "y": 19,
      "z": -1,
      "name": "Soil_Clay_Green"
    },
    {
      "x": -15,
      "y": 6,
      "z": 0,
      "name": "Soil_Clay_Green"
    },
    {
      "x": -15,
      "y": 7,
      "z": 0,
      "name": "Soil_Seaweed_Block"
    },
    {
      "x": -15,
      "y": 19,
      "z": 0,
      "name": "Soil_Seaweed_Block"
    },
    {
      "x": -15,
      "y": 6,
      "z": 1,
      "name": "Soil_Clay_Green"
    },
    {
      "x": -15,
      "y": 7,
      "z": 1,
      "name": "Soil_Seaweed_Block"
    },
    {
      "x": -15,
      "y": 19,
      "z": 1,
      "name": "Soil_Clay_Lime"
    },
    {
      "x": -15,
      "y": 15,
      "z": 2,
      "name": "Soil_Clay_Green"
    },
    {
      "x": -15,
      "y": 16,
      "z": 2,
      "name": "Soil_Seaweed_Block"
    },
    {
      "x": -15,
      "y": 17,
      "z": 2,
      "name": "Soil_Seaweed_Block"
    },
    {
      "x": -15,
      "y": 18,
      "z": 2,
      "name": "Soil_Clay_Lime"
    },
    {
      "x": -15,
      "y": 19,
      "z": 2,
      "name": "Soil_Clay_Lime"
    },
    {
      "x": -15,
      "y": 20,
      "z": 2,
      "name": "Plant_Grass_Sharp"
    },
    {
      "x": -15,
      "y": 13,
      "z": 3,
      "name": "Soil_Clay_Green"
    },
    {
      "x": -15,
      "y": 14,
      "z": 3,
      "name": "Soil_Clay_Green"
    },
    {
      "x": -15,
      "y": 15,
      "z": 3,
      "name": "Soil_Seaweed_Block"
    },
    {
      "x": -15,
      "y": 16,
      "z": 3,
      "name": "Soil_Seaweed_Block"
    },
    {
      "x": -15,
      "y": 17,
      "z": 3,
      "name": "Soil_Clay_Lime"
    },
    {
      "x": -15,
      "y": 18,
      "z": 3,
      "name": "Soil_Clay_Lime"
    },
    {
      "x": -15,
      "y": 19,
      "z": 3,
      "name": "Plant_Grass_Sharp"
    },
    {
      "x": -15,
      "y": 13,
      "z": 4,
      "name": "Soil_Clay_Green"
    },
    {
      "x": -15,
      "y": 14,
      "z": 4,
      "name": "Soil_Clay_Green"
    },
    {
      "x": -15,
      "y": 15,
      "z": 4,
      "name": "Soil_Seaweed_Block"
    },
    {
      "x": -15,
      "y": 16,
      "z": 4,
      "name": "Soil_Seaweed_Block"
    },
    {
      "x": -15,
      "y": 17,
      "z": 4,
      "name": "Soil_Clay_Lime"
    },
    {
      "x": -15,
      "y": 18,
      "z": 4,
      "name": "Plant_Grass_Sharp"
    },
    {
      "x": -15,
      "y": 13,
      "z": 5,
      "name": "Soil_Clay_Green"
    },
    {
      "x": -15,
      "y": 14,
      "z": 5,
      "name": "Soil_Seaweed_Block"
    },
    {
      "x": -15,
      "y": 15,
      "z": 5,
      "name": "Soil_Seaweed_Block"
    },
    {
      "x": -15,
      "y": 16,
      "z": 5,
      "name": "Soil_Seaweed_Block"
    },
    {
      "x": -15,
      "y": 17,
      "z": 5,
      "name": "Soil_Clay_Lime"
    },
    {
      "x": -15,
      "y": 18,
      "z": 5,
      "name": "Plant_Grass_Sharp"
    },
    {
      "x": -15,
      "y": 13,
      "z": 6,
      "name": "Soil_Clay_Green"
    },
    {
      "x": -15,
      "y": 14,
      "z": 6,
      "name": "Soil_Seaweed_Block"
    },
    {
      "x": -15,
      "y": 15,
      "z": 6,
      "name": "Soil_Seaweed_Block"
    },
    {
      "x": -15,
      "y": 16,
      "z": 6,
      "name": "Soil_Seaweed_Block"
    },
    {
      "x": -15,
      "y": 17,
      "z": 6,
      "name": "Soil_Seaweed_Block"
    },
    {
      "x": -15,
      "y": 18,
      "z": 6,
      "name": "Soil_Seaweed_Block"
    },
    {
      "x": -15,
      "y": 19,
      "z": 6,
      "name": "Soil_Seaweed_Block"
    },
    {
      "x": -15,
      "y": 20,
      "z": 6,
      "name": "Soil_Seaweed_Block"
    },
    {
      "x": -15,
      "y": 15,
      "z": 7,
      "name": "Soil_Clay_Green"
    },
    {
      "x": -15,
      "y": 16,
      "z": 7,
      "name": "Soil_Clay_Green"
    },
    {
      "x": -15,
      "y": 17,
      "z": 7,
      "name": "Soil_Clay_Green"
    },
    {
      "x": -15,
      "y": 18,
      "z": 7,
      "name": "Soil_Seaweed_Block"
    },
    {
      "x": -15,
      "y": 19,
      "z": 7,
      "name": "Soil_Seaweed_Block"
    },
    {
      "x": -15,
      "y": 20,
      "z": 7,
      "name": "Soil_Seaweed_Block"
    },
    {
      "x": -15,
      "y": 19,
      "z": 8,
      "name": "Soil_Seaweed_Block"
    },
    {
      "x": -14,
      "y": 11,
      "z": -8,
      "name": "Soil_Clay_Green"
    },
    {
      "x": -14,
      "y": 12,
      "z": -8,
      "name": "Soil_Clay_Green"
    },
    {
      "x": -14,
      "y": 13,
      "z": -8,
      "name": "Soil_Seaweed_Block"
    },
    {
      "x": -14,
      "y": 14,
      "z": -8,
      "name": "Soil_Seaweed_Block"
    },
    {
      "x": -14,
      "y": 19,
      "z": -8,
      "name": "Soil_Clay_Green"
    },
    {
      "x": -14,
      "y": 20,
      "z": -8,
      "name": "Soil_Clay_Green"
    },
    {
      "x": -14,
      "y": 21,
      "z": -8,
      "name": "Soil_Seaweed_Block"
    },
    {
      "x": -14,
      "y": 12,
      "z": -7,
      "name": "Soil_Clay_Green"
    },
    {
      "x": -14,
      "y": 18,
      "z": -7,
      "name": "Soil_Clay_Green"
    },
    {
      "x": -14,
      "y": 19,
      "z": -7,
      "name": "Soil_Clay_Green"
    },
    {
      "x": -14,
      "y": 20,
      "z": -7,
      "name": "Soil_Seaweed_Block"
    },
    {
      "x": -14,
      "y": 21,
      "z": -7,
      "name": "Soil_Seaweed_Block"
    },
    {
      "x": -14,
      "y": 12,
      "z": -6,
      "name": "Soil_Clay_Green"
    },
    {
      "x": -14,
      "y": 17,
      "z": -6,
      "name": "Soil_Clay_Green"
    },
    {
      "x": -14,
      "y": 18,
      "z": -6,
      "name": "Soil_Seaweed_Block"
    },
    {
      "x": -14,
      "y": 19,
      "z": -6,
      "name": "Soil_Seaweed_Block"
    },
    {
      "x": -14,
      "y": 20,
      "z": -6,
      "name": "Soil_Seaweed_Block"
    },
    {
      "x": -14,
      "y": 21,
      "z": -6,
      "name": "Soil_Seaweed_Block"
    },
    {
      "x": -14,
      "y": 22,
      "z": -6,
      "name": "Soil_Clay_Lime"
    },
    {
      "x": -14,
      "y": 23,
      "z": -6,
      "name": "Plant_Grass_Sharp"
    },
    {
      "x": -14,
      "y": 18,
      "z": -5,
      "name": "Soil_Clay_Green"
    },
    {
      "x": -14,
      "y": 19,
      "z": -5,
      "name": "Soil_Seaweed_Block"
    },
    {
      "x": -14,
      "y": 20,
      "z": -5,
      "name": "Soil_Seaweed_Block"
    },
    {
      "x": -14,
      "y": 21,
      "z": -5,
      "name": "Soil_Seaweed_Block"
    },
    {
      "x": -14,
      "y": 22,
      "z": -5,
      "name": "Soil_Clay_Lime"
    },
    {
      "x": -14,
      "y": 23,
      "z": -5,
      "name": "Plant_Grass_Sharp"
    },
    {
      "x": -14,
      "y": 18,
      "z": -4,
      "name": "Soil_Clay_Green"
    },
    {
      "x": -14,
      "y": 19,
      "z": -4,
      "name": "Soil_Clay_Green"
    },
    {
      "x": -14,
      "y": 20,
      "z": -4,
      "name": "Soil_Seaweed_Block"
    },
    {
      "x": -14,
      "y": 21,
      "z": -4,
      "name": "Soil_Seaweed_Block"
    },
    {
      "x": -14,
      "y": 19,
      "z": -3,
      "name": "Soil_Clay_Green"
    },
    {
      "x": -14,
      "y": 6,
      "z": -1,
      "name": "Soil_Clay_Green"
    },
    {
      "x": -14,
      "y": 7,
      "z": -1,
      "name": "Soil_Seaweed_Block"
    },
    {
      "x": -14,
      "y": 8,
      "z": -1,
      "name": "Soil_Clay_Lime"
    },
    {
      "x": -14,
      "y": 9,
      "z": -1,
      "name": "Plant_Grass_Sharp"
    },
    {
      "x": -14,
      "y": 5,
      "z": 0,
      "name": "Soil_Clay_Green"
    },
    {
      "x": -14,
      "y": 6,
      "z": 0,
      "name": "Soil_Seaweed_Block"
    },
    {
      "x": -14,
      "y": 7,
      "z": 0,
      "name": "Soil_Seaweed_Block"
    },
    {
      "x": -14,
      "y": 8,
      "z": 0,
      "name": "Soil_Seaweed_Block"
    },
    {
      "x": -14,
      "y": 6,
      "z": 1,
      "name": "Soil_Clay_Green"
    },
    {
      "x": -14,
      "y": 7,
      "z": 1,
      "name": "Soil_Seaweed_Block"
    },
    {
      "x": -14,
      "y": 8,
      "z": 1,
      "name": "Soil_Seaweed_Block"
    },
    {
      "x": -14,
      "y": 6,
      "z": 2,
      "name": "Soil_Clay_Green"
    },
    {
      "x": -14,
      "y": 7,
      "z": 2,
      "name": "Soil_Clay_Green"
    },
    {
      "x": -14,
      "y": 8,
      "z": 2,
      "name": "Soil_Seaweed_Block"
    },
    {
      "x": -14,
      "y": 15,
      "z": 2,
      "name": "Soil_Seaweed_Block"
    },
    {
      "x": -14,
      "y": 12,
      "z": 3,
      "name": "Soil_Clay_Green"
    },
    {
      "x": -14,
      "y": 13,
      "z": 3,
      "name": "Soil_Clay_Green"
    },
    {
      "x": -14,
      "y": 14,
      "z": 3,
      "name": "Soil_Clay_Green"
    },
    {
      "x": -14,
      "y": 15,
      "z": 3,
      "name": "Soil_Seaweed_Block"
    },
    {
      "x": -14,
      "y": 16,
      "z": 3,
      "name": "Soil_Seaweed_Block"
    },
    {
      "x": -14,
      "y": 17,
      "z": 3,
      "name": "Soil_Seaweed_Block"
    },
    {
      "x": -14,
      "y": 18,
      "z": 3,
      "name": "Soil_Clay_Lime"
    },
    {
      "x": -14,
      "y": 19,
      "z": 3,
      "name": "Plant_Grass_Sharp"
    },
    {
      "x": -14,
      "y": 10,
      "z": 4,
      "name": "Soil_Seaweed_Block"
    },
    {
      "x": -14,
      "y": 11,
      "z": 4,
      "name": "Soil_Clay_Green"
    },
    {
      "x": -14,
      "y": 12,
      "z": 4,
      "name": "Soil_Seaweed_Block"
    },
    {
      "x": -14,
      "y": 13,
      "z": 4,
      "name": "Soil_Seaweed_Block"
    },
    {
      "x": -14,
      "y": 14,
      "z": 4,
      "name": "Soil_Seaweed_Block"
    },
    {
      "x": -14,
      "y": 15,
      "z": 4,
      "name": "Soil_Seaweed_Block"
    },
    {
      "x": -14,
      "y": 16,
      "z": 4,
      "name": "Soil_Seaweed_Block"
    },
    {
      "x": -14,
      "y": 17,
      "z": 4,
      "name": "Soil_Clay_Lime"
    },
    {
      "x": -14,
      "y": 18,
      "z": 4,
      "name": "Plant_Grass_Sharp"
    },
    {
      "x": -14,
      "y": 11,
      "z": 5,
      "name": "Soil_Clay_Green"
    },
    {
      "x": -14,
      "y": 12,
      "z": 5,
      "name": "Soil_Clay_Green"
    },
    {
      "x": -14,
      "y": 13,
      "z": 5,
      "name": "Soil_Seaweed_Block"
    },
    {
      "x": -14,
      "y": 14,
      "z": 5,
      "name": "Soil_Seaweed_Block"
    },
    {
      "x": -14,
      "y": 15,
      "z": 5,
      "name": "Soil_Seaweed_Block"
    },
    {
      "x": -14,
      "y": 16,
      "z": 5,
      "name": "Soil_Seaweed_Block"
    },
    {
      "x": -14,
      "y": 17,
      "z": 5,
      "name": "Soil_Seaweed_Block"
    },
    {
      "x": -14,
      "y": 18,
      "z": 5,
      "name": "Soil_Clay_Lime"
    },
    {
      "x": -14,
      "y": 19,
      "z": 5,
      "name": "Soil_Seaweed_Block"
    },
    {
      "x": -14,
      "y": 20,
      "z": 5,
      "name": "Soil_Seaweed_Block"
    },
    {
      "x": -14,
      "y": 13,
      "z": 6,
      "name": "Soil_Clay_Green"
    },
    {
      "x": -14,
      "y": 14,
      "z": 6,
      "name": "Soil_Seaweed_Block"
    },
    {
      "x": -14,
      "y": 15,
      "z": 6,
      "name": "Soil_Seaweed_Block"
    },
    {
      "x": -14,
      "y": 16,
      "z": 6,
      "name": "Soil_Seaweed_Block"
    },
    {
      "x": -14,
      "y": 17,
      "z": 6,
      "name": "Soil_Seaweed_Block"
    },
    {
      "x": -14,
      "y": 18,
      "z": 6,
      "name": "Soil_Seaweed_Block"
    },
    {
      "x": -14,
      "y": 19,
      "z": 6,
      "name": "Soil_Seaweed_Block"
    },
    {
      "x": -14,
      "y": 20,
      "z": 6,
      "name": "Soil_Seaweed_Block"
    },
    {
      "x": -14,
      "y": 21,
      "z": 6,
      "name": "Soil_Clay_Lime"
    },
    {
      "x": -14,
      "y": 14,
      "z": 7,
      "name": "Soil_Clay_Green"
    },
    {
      "x": -14,
      "y": 15,
      "z": 7,
      "name": "Soil_Clay_Green"
    },
    {
      "x": -14,
      "y": 16,
      "z": 7,
      "name": "Soil_Clay_Green"
    },
    {
      "x": -14,
      "y": 17,
      "z": 7,
      "name": "Soil_Seaweed_Block"
    },
    {
      "x": -14,
      "y": 18,
      "z": 7,
      "name": "Soil_Seaweed_Block"
    },
    {
      "x": -14,
      "y": 19,
      "z": 7,
      "name": "Soil_Seaweed_Block"
    },
    {
      "x": -14,
      "y": 20,
      "z": 7,
      "name": "Soil_Seaweed_Block"
    },
    {
      "x": -14,
      "y": 21,
      "z": 7,
      "name": "Soil_Clay_Lime"
    },
    {
      "x": -14,
      "y": 22,
      "z": 7,
      "name": "Plant_Grass_Sharp"
    },
    {
      "x": -14,
      "y": 17,
      "z": 8,
      "name": "Soil_Clay_Green"
    },
    {
      "x": -14,
      "y": 18,
      "z": 8,
      "name": "Soil_Clay_Green"
    },
    {
      "x": -14,
      "y": 19,
      "z": 8,
      "name": "Soil_Seaweed_Block"
    },
    {
      "x": -14,
      "y": 20,
      "z": 8,
      "name": "Soil_Clay_Lime"
    },
    {
      "x": -14,
      "y": 21,
      "z": 8,
      "name": "Plant_Grass_Sharp"
    },
    {
      "x": -13,
      "y": 12,
      "z": -9,
      "name": "Soil_Clay_Green"
    },
    {
      "x": -13,
      "y": 11,
      "z": -8,
      "name": "Soil_Clay_Green"
    },
    {
      "x": -13,
      "y": 12,
      "z": -8,
      "name": "Soil_Seaweed_Block"
    },
    {
      "x": -13,
      "y": 13,
      "z": -8,
      "name": "Soil_Seaweed_Block"
    },
    {
      "x": -13,
      "y": 14,
      "z": -8,
      "name": "Soil_Clay_Lime"
    },
    {
      "x": -13,
      "y": 15,
      "z": -8,
      "name": "Soil_Clay_Lime"
    },
    {
      "x": -13,
      "y": 16,
      "z": -8,
      "name": "Plant_Grass_Sharp"
    },
    {
      "x": -13,
      "y": 21,
      "z": -8,
      "name": "Soil_Clay_Green"
    },
    {
      "x": -13,
      "y": 10,
      "z": -7,
      "name": "Soil_Clay_Green"
    },
    {
      "x": -13,
      "y": 11,
      "z": -7,
      "name": "Soil_Clay_Green"
    },
    {
      "x": -13,
      "y": 12,
      "z": -7,
      "name": "Soil_Seaweed_Block"
    },
    {
      "x": -13,
      "y": 13,
      "z": -7,
      "name": "Soil_Seaweed_Block"
    },
    {
      "x": -13,
      "y": 14,
      "z": -7,
      "name": "Soil_Clay_Lime"
    },
    {
      "x": -13,
      "y": 15,
      "z": -7,
      "name": "Soil_Clay_Lime"
    },
    {
      "x": -13,
      "y": 16,
      "z": -7,
      "name": "Soil_Seaweed_Block"
    },
    {
      "x": -13,
      "y": 17,
      "z": -7,
      "name": "Soil_Clay_Green"
    },
    {
      "x": -13,
      "y": 18,
      "z": -7,
      "name": "Soil_Clay_Green"
    },
    {
      "x": -13,
      "y": 19,
      "z": -7,
      "name": "Soil_Clay_Green"
    },
    {
      "x": -13,
      "y": 20,
      "z": -7,
      "name": "Soil_Seaweed_Block"
    },
    {
      "x": -13,
      "y": 21,
      "z": -7,
      "name": "Soil_Seaweed_Block"
    },
    {
      "x": -13,
      "y": 22,
      "z": -7,
      "name": "Soil_Clay_Lime"
    },
    {
      "x": -13,
      "y": 23,
      "z": -7,
      "name": "Soil_Clay_Lime"
    },
    {
      "x": -13,
      "y": 24,
      "z": -7,
      "name": "Plant_Grass_Sharp"
    },
    {
      "x": -13,
      "y": 12,
      "z": -6,
      "name": "Soil_Clay_Green"
    },
    {
      "x": -13,
      "y": 17,
      "z": -6,
      "name": "Soil_Clay_Green"
    },
    {
      "x": -13,
      "y": 18,
      "z": -6,
      "name": "Soil_Seaweed_Block"
    },
    {
      "x": -13,
      "y": 19,
      "z": -6,
      "name": "Soil_Seaweed_Block"
    },
    {
      "x": -13,
      "y": 20,
      "z": -6,
      "name": "Soil_Seaweed_Block"
    },
    {
      "x": -13,
      "y": 21,
      "z": -6,
      "name": "Soil_Seaweed_Block"
    },
    {
      "x": -13,
      "y": 22,
      "z": -6,
      "name": "Soil_Seaweed_Block"
    },
    {
      "x": -13,
      "y": 23,
      "z": -6,
      "name": "Soil_Clay_Lime"
    },
    {
      "x": -13,
      "y": 24,
      "z": -6,
      "name": "Plant_Grass_Sharp"
    },
    {
      "x": -13,
      "y": 17,
      "z": -5,
      "name": "Soil_Clay_Green"
    },
    {
      "x": -13,
      "y": 18,
      "z": -5,
      "name": "Soil_Seaweed_Block"
    },
    {
      "x": -13,
      "y": 19,
      "z": -5,
      "name": "Soil_Seaweed_Block"
    },
    {
      "x": -13,
      "y": 20,
      "z": -5,
      "name": "Soil_Seaweed_Block"
    },
    {
      "x": -13,
      "y": 21,
      "z": -5,
      "name": "Soil_Seaweed_Block"
    },
    {
      "x": -13,
      "y": 22,
      "z": -5,
      "name": "Soil_Seaweed_Block"
    },
    {
      "x": -13,
      "y": 23,
      "z": -5,
      "name": "Soil_Clay_Lime"
    },
    {
      "x": -13,
      "y": 24,
      "z": -5,
      "name": "Plant_Grass_Sharp"
    },
    {
      "x": -13,
      "y": 18,
      "z": -4,
      "name": "Soil_Clay_Green"
    },
    {
      "x": -13,
      "y": 19,
      "z": -4,
      "name": "Soil_Clay_Green"
    },
    {
      "x": -13,
      "y": 20,
      "z": -4,
      "name": "Soil_Seaweed_Block"
    },
    {
      "x": -13,
      "y": 21,
      "z": -4,
      "name": "Soil_Seaweed_Block"
    },
    {
      "x": -13,
      "y": 22,
      "z": -4,
      "name": "Soil_Clay_Lime"
    },
    {
      "x": -13,
      "y": 25,
      "z": -4,
      "name": "Soil_Clay_Green"
    },
    {
      "x": -13,
      "y": 20,
      "z": -3,
      "name": "Soil_Seaweed_Block"
    },
    {
      "x": -13,
      "y": 25,
      "z": -3,
      "name": "Soil_Clay_Green"
    },
    {
      "x": -13,
      "y": 26,
      "z": -3,
      "name": "Soil_Clay_Green"
    },
    {
      "x": -13,
      "y": 6,
      "z": -2,
      "name": "Soil_Clay_Green"
    },
    {
      "x": -13,
      "y": 7,
      "z": -2,
      "name": "Soil_Seaweed_Block"
    },
    {
      "x": -13,
      "y": 8,
      "z": -2,
      "name": "Soil_Clay_Lime"
    },
    {
      "x": -13,
      "y": 9,
      "z": -2,
      "name": "Plant_Grass_Sharp"
    },
    {
      "x": -13,
      "y": 5,
      "z": -1,
      "name": "Soil_Clay_Green"
    },
    {
      "x": -13,
      "y": 6,
      "z": -1,
      "name": "Soil_Seaweed_Block"
    },
    {
      "x": -13,
      "y": 7,
      "z": -1,
      "name": "Soil_Seaweed_Block"
    },
    {
      "x": -13,
      "y": 8,
      "z": -1,
      "name": "Soil_Seaweed_Block"
    },
    {
      "x": -13,
      "y": 9,
      "z": -1,
      "name": "Soil_Clay_Lime"
    },
    {
      "x": -13,
      "y": 10,
      "z": -1,
      "name": "Plant_Grass_Sharp"
    },
    {
      "x": -13,
      "y": 28,
      "z": -1,
      "name": "Plant_Grass_Sharp"
    },
    {
      "x": -13,
      "y": 5,
      "z": 0,
      "name": "Soil_Clay_Green"
    },
    {
      "x": -13,
      "y": 6,
      "z": 0,
      "name": "Soil_Seaweed_Block"
    },
    {
      "x": -13,
      "y": 7,
      "z": 0,
      "name": "Soil_Seaweed_Block"
    },
    {
      "x": -13,
      "y": 8,
      "z": 0,
      "name": "Soil_Seaweed_Block"
    },
    {
      "x": -13,
      "y": 9,
      "z": 0,
      "name": "Soil_Clay_Lime"
    },
    {
      "x": -13,
      "y": 10,
      "z": 0,
      "name": "Plant_Grass_Sharp"
    },
    {
      "x": -13,
      "y": 5,
      "z": 1,
      "name": "Soil_Clay_Green"
    },
    {
      "x": -13,
      "y": 6,
      "z": 1,
      "name": "Soil_Seaweed_Block"
    },
    {
      "x": -13,
      "y": 7,
      "z": 1,
      "name": "Soil_Seaweed_Block"
    },
    {
      "x": -13,
      "y": 8,
      "z": 1,
      "name": "Soil_Seaweed_Block"
    },
    {
      "x": -13,
      "y": 9,
      "z": 1,
      "name": "Soil_Clay_Lime"
    },
    {
      "x": -13,
      "y": 10,
      "z": 1,
      "name": "Plant_Grass_Sharp"
    },
    {
      "x": -13,
      "y": 5,
      "z": 2,
      "name": "Soil_Clay_Green"
    },
    {
      "x": -13,
      "y": 6,
      "z": 2,
      "name": "Soil_Seaweed_Block"
    },
    {
      "x": -13,
      "y": 7,
      "z": 2,
      "name": "Soil_Seaweed_Block"
    },
    {
      "x": -13,
      "y": 8,
      "z": 2,
      "name": "Soil_Seaweed_Block"
    },
    {
      "x": -13,
      "y": 9,
      "z": 2,
      "name": "Soil_Seaweed_Block"
    },
    {
      "x": -13,
      "y": 10,
      "z": 2,
      "name": "Soil_Clay_Lime"
    },
    {
      "x": -13,
      "y": 11,
      "z": 2,
      "name": "Soil_Clay_Lime"
    },
    {
      "x": -13,
      "y": 12,
      "z": 2,
      "name": "Plant_Grass_Sharp"
    },
    {
      "x": -13,
      "y": 7,
      "z": 3,
      "name": "Soil_Clay_Green"
    },
    {
      "x": -13,
      "y": 8,
      "z": 3,
      "name": "Soil_Seaweed_Block"
    },
    {
      "x": -13,
      "y": 9,
      "z": 3,
      "name": "Soil_Seaweed_Block"
    },
    {
      "x": -13,
      "y": 10,
      "z": 3,
      "name": "Soil_Seaweed_Block"
    },
    {
      "x": -13,
      "y": 11,
      "z": 3,
      "name": "Soil_Seaweed_Block"
    },
    {
      "x": -13,
      "y": 12,
      "z": 3,
      "name": "Soil_Seaweed_Block"
    },
    {
      "x": -13,
      "y": 13,
      "z": 3,
      "name": "Soil_Clay_Green"
    },
    {
      "x": -13,
      "y": 14,
      "z": 3,
      "name": "Soil_Clay_Green"
    },
    {
      "x": -13,
      "y": 15,
      "z": 3,
      "name": "Soil_Seaweed_Block"
    },
    {
      "x": -13,
      "y": 16,
      "z": 3,
      "name": "Soil_Seaweed_Block"
    },
    {
      "x": -13,
      "y": 8,
      "z": 4,
      "name": "Soil_Clay_Green"
    },
    {
      "x": -13,
      "y": 9,
      "z": 4,
      "name": "Soil_Clay_Green"
    },
    {
      "x": -13,
      "y": 10,
      "z": 4,
      "name": "Soil_Seaweed_Block"
    },
    {
      "x": -13,
      "y": 11,
      "z": 4,
      "name": "Soil_Seaweed_Block"
    },
    {
      "x": -13,
      "y": 12,
      "z": 4,
      "name": "Soil_Seaweed_Block"
    },
    {
      "x": -13,
      "y": 13,
      "z": 4,
      "name": "Soil_Seaweed_Block"
    },
    {
      "x": -13,
      "y": 14,
      "z": 4,
      "name": "Soil_Seaweed_Block"
    },
    {
      "x": -13,
      "y": 15,
      "z": 4,
      "name": "Soil_Seaweed_Block"
    },
    {
      "x": -13,
      "y": 16,
      "z": 4,
      "name": "Soil_Seaweed_Block"
    },
    {
      "x": -13,
      "y": 17,
      "z": 4,
      "name": "Soil_Seaweed_Block"
    },
    {
      "x": -13,
      "y": 8,
      "z": 5,
      "name": "Soil_Clay_Green"
    },
    {
      "x": -13,
      "y": 9,
      "z": 5,
      "name": "Soil_Clay_Green"
    },
    {
      "x": -13,
      "y": 10,
      "z": 5,
      "name": "Soil_Seaweed_Block"
    },
    {
      "x": -13,
      "y": 11,
      "z": 5,
      "name": "Soil_Seaweed_Block"
    },
    {
      "x": -13,
      "y": 12,
      "z": 5,
      "name": "Soil_Seaweed_Block"
    },
    {
      "x": -13,
      "y": 13,
      "z": 5,
      "name": "Soil_Seaweed_Block"
    },
    {
      "x": -13,
      "y": 14,
      "z": 5,
      "name": "Soil_Seaweed_Block"
    },
    {
      "x": -13,
      "y": 15,
      "z": 5,
      "name": "Soil_Seaweed_Block"
    },
    {
      "x": -13,
      "y": 16,
      "z": 5,
      "name": "Soil_Seaweed_Block"
    },
    {
      "x": -13,
      "y": 17,
      "z": 5,
      "name": "Soil_Seaweed_Block"
    },
    {
      "x": -13,
      "y": 19,
      "z": 5,
      "name": "Soil_Seaweed_Block"
    },
    {
      "x": -13,
      "y": 20,
      "z": 5,
      "name": "Soil_Seaweed_Block"
    },
    {
      "x": -13,
      "y": 10,
      "z": 6,
      "name": "Soil_Seaweed_Block"
    },
    {
      "x": -13,
      "y": 11,
      "z": 6,
      "name": "Soil_Seaweed_Block"
    },
    {
      "x": -13,
      "y": 12,
      "z": 6,
      "name": "Soil_Clay_Green"
    },
    {
      "x": -13,
      "y": 13,
      "z": 6,
      "name": "Soil_Clay_Green"
    },
    {
      "x": -13,
      "y": 14,
      "z": 6,
      "name": "Soil_Seaweed_Block"
    },
    {
      "x": -13,
      "y": 15,
      "z": 6,
      "name": "Soil_Seaweed_Block"
    },
    {
      "x": -13,
      "y": 16,
      "z": 6,
      "name": "Soil_Seaweed_Block"
    },
    {
      "x": -13,
      "y": 17,
      "z": 6,
      "name": "Soil_Seaweed_Block"
    },
    {
      "x": -13,
      "y": 18,
      "z": 6,
      "name": "Soil_Seaweed_Block"
    },
    {
      "x": -13,
      "y": 19,
      "z": 6,
      "name": "Soil_Seaweed_Block"
    },
    {
      "x": -13,
      "y": 20,
      "z": 6,
      "name": "Soil_Seaweed_Block"
    },
    {
      "x": -13,
      "y": 21,
      "z": 6,
      "name": "Soil_Clay_Lime"
    },
    {
      "x": -13,
      "y": 22,
      "z": 6,
      "name": "Soil_Clay_Lime"
    },
    {
      "x": -13,
      "y": 23,
      "z": 6,
      "name": "Soil_Clay_Green"
    },
    {
      "x": -13,
      "y": 15,
      "z": 7,
      "name": "Soil_Clay_Green"
    },
    {
      "x": -13,
      "y": 16,
      "z": 7,
      "name": "Soil_Clay_Green"
    },
    {
      "x": -13,
      "y": 17,
      "z": 7,
      "name": "Soil_Seaweed_Block"
    },
    {
      "x": -13,
      "y": 18,
      "z": 7,
      "name": "Soil_Seaweed_Block"
    },
    {
      "x": -13,
      "y": 19,
      "z": 7,
      "name": "Soil_Seaweed_Block"
    },
    {
      "x": -13,
      "y": 20,
      "z": 7,
      "name": "Soil_Seaweed_Block"
    },
    {
      "x": -13,
      "y": 21,
      "z": 7,
      "name": "Soil_Clay_Lime"
    },
    {
      "x": -13,
      "y": 22,
      "z": 7,
      "name": "Plant_Grass_Sharp"
    },
    {
      "x": -13,
      "y": 17,
      "z": 8,
      "name": "Soil_Clay_Green"
    },
    {
      "x": -13,
      "y": 18,
      "z": 8,
      "name": "Soil_Seaweed_Block"
    },
    {
      "x": -13,
      "y": 19,
      "z": 8,
      "name": "Soil_Seaweed_Block"
    },
    {
      "x": -13,
      "y": 20,
      "z": 8,
      "name": "Soil_Seaweed_Block"
    },
    {
      "x": -13,
      "y": 21,
      "z": 8,
      "name": "Soil_Clay_Lime"
    },
    {
      "x": -13,
      "y": 22,
      "z": 8,
      "name": "Plant_Grass_Sharp"
    },
    {
      "x": -13,
      "y": 17,
      "z": 9,
      "name": "Soil_Clay_Green"
    },
    {
      "x": -13,
      "y": 18,
      "z": 9,
      "name": "Soil_Clay_Green"
    },
    {
      "x": -13,
      "y": 19,
      "z": 9,
      "name": "Soil_Seaweed_Block"
    },
    {
      "x": -13,
      "y": 20,
      "z": 9,
      "name": "Soil_Clay_Lime"
    },
    {
      "x": -13,
      "y": 21,
      "z": 9,
      "name": "Plant_Grass_Sharp"
    },
    {
      "x": -13,
      "y": 18,
      "z": 10,
      "name": "Soil_Clay_Green"
    },
    {
      "x": -13,
      "y": 19,
      "z": 10,
      "name": "Soil_Seaweed_Block"
    },
    {
      "x": -12,
      "y": 11,
      "z": -9,
      "name": "Soil_Clay_Green"
    },
    {
      "x": -12,
      "y": 12,
      "z": -9,
      "name": "Soil_Clay_Green"
    },
    {
      "x": -12,
      "y": 13,
      "z": -9,
      "name": "Soil_Seaweed_Block"
    },
    {
      "x": -12,
      "y": 14,
      "z": -9,
      "name": "Soil_Clay_Lime"
    },
    {
      "x": -12,
      "y": 15,
      "z": -9,
      "name": "Soil_Clay_Lime"
    },
    {
      "x": -12,
      "y": 16,
      "z": -9,
      "name": "Plant_Grass_Sharp"
    },
    {
      "x": -12,
      "y": 21,
      "z": -9,
      "name": "Soil_Clay_Green"
    },
    {
      "x": -12,
      "y": 10,
      "z": -8,
      "name": "Soil_Clay_Green"
    },
    {
      "x": -12,
      "y": 11,
      "z": -8,
      "name": "Soil_Seaweed_Block"
    },
    {
      "x": -12,
      "y": 12,
      "z": -8,
      "name": "Soil_Seaweed_Block"
    },
    {
      "x": -12,
      "y": 13,
      "z": -8,
      "name": "Soil_Seaweed_Block"
    },
    {
      "x": -12,
      "y": 14,
      "z": -8,
      "name": "Soil_Seaweed_Block"
    },
    {
      "x": -12,
      "y": 15,
      "z": -8,
      "name": "Soil_Clay_Lime"
    },
    {
      "x": -12,
      "y": 16,
      "z": -8,
      "name": "Plant_Grass_Sharp"
    },
    {
      "x": -12,
      "y": 21,
      "z": -8,
      "name": "Soil_Clay_Green"
    },
    {
      "x": -12,
      "y": 22,
      "z": -8,
      "name": "Soil_Clay_Lime"
    },
    {
      "x": -12,
      "y": 23,
      "z": -8,
      "name": "Plant_Grass_Sharp"
    },
    {
      "x": -12,
      "y": 10,
      "z": -7,
      "name": "Soil_Clay_Green"
    },
    {
      "x": -12,
      "y": 11,
      "z": -7,
      "name": "Soil_Seaweed_Block"
    },
    {
      "x": -12,
      "y": 12,
      "z": -7,
      "name": "Soil_Seaweed_Block"
    },
    {
      "x": -12,
      "y": 13,
      "z": -7,
      "name": "Soil_Seaweed_Block"
    },
    {
      "x": -12,
      "y": 14,
      "z": -7,
      "name": "Soil_Clay_Lime"
    },
    {
      "x": -12,
      "y": 15,
      "z": -7,
      "name": "Soil_Clay_Lime"
    },
    {
      "x": -12,
      "y": 16,
      "z": -7,
      "name": "Plant_Grass_Sharp"
    },
    {
      "x": -12,
      "y": 20,
      "z": -7,
      "name": "Soil_Clay_Green"
    },
    {
      "x": -12,
      "y": 21,
      "z": -7,
      "name": "Soil_Clay_Green"
    },
    {
      "x": -12,
      "y": 22,
      "z": -7,
      "name": "Soil_Clay_Lime"
    },
    {
      "x": -12,
      "y": 23,
      "z": -7,
      "name": "Soil_Clay_Lime"
    },
    {
      "x": -12,
      "y": 24,
      "z": -7,
      "name": "Plant_Grass_Sharp"
    },
    {
      "x": -12,
      "y": 10,
      "z": -6,
      "name": "Soil_Clay_Green"
    },
    {
      "x": -12,
      "y": 11,
      "z": -6,
      "name": "Soil_Clay_Green"
    },
    {
      "x": -12,
      "y": 12,
      "z": -6,
      "name": "Soil_Clay_Green"
    },
    {
      "x": -12,
      "y": 13,
      "z": -6,
      "name": "Soil_Seaweed_Block"
    },
    {
      "x": -12,
      "y": 14,
      "z": -6,
      "name": "Soil_Seaweed_Block"
    },
    {
      "x": -12,
      "y": 19,
      "z": -6,
      "name": "Soil_Clay_Green"
    },
    {
      "x": -12,
      "y": 20,
      "z": -6,
      "name": "Soil_Clay_Green"
    },
    {
      "x": -12,
      "y": 21,
      "z": -6,
      "name": "Soil_Seaweed_Block"
    },
    {
      "x": -12,
      "y": 22,
      "z": -6,
      "name": "Soil_Seaweed_Block"
    },
    {
      "x": -12,
      "y": 23,
      "z": -6,
      "name": "Soil_Clay_Lime"
    },
    {
      "x": -12,
      "y": 24,
      "z": -6,
      "name": "Soil_Clay_Lime"
    },
    {
      "x": -12,
      "y": 25,
      "z": -6,
      "name": "Plant_Grass_Sharp"
    },
    {
      "x": -12,
      "y": 10,
      "z": -5,
      "name": "Soil_Clay_Green"
    },
    {
      "x": -12,
      "y": 11,
      "z": -5,
      "name": "Soil_Clay_Green"
    },
    {
      "x": -12,
      "y": 12,
      "z": -5,
      "name": "Soil_Seaweed_Block"
    },
    {
      "x": -12,
      "y": 19,
      "z": -5,
      "name": "Soil_Clay_Green"
    },
    {
      "x": -12,
      "y": 20,
      "z": -5,
      "name": "Soil_Clay_Green"
    },
    {
      "x": -12,
      "y": 21,
      "z": -5,
      "name": "Soil_Seaweed_Block"
    },
    {
      "x": -12,
      "y": 22,
      "z": -5,
      "name": "Soil_Seaweed_Block"
    },
    {
      "x": -12,
      "y": 23,
      "z": -5,
      "name": "Soil_Clay_Lime"
    },
    {
      "x": -12,
      "y": 24,
      "z": -5,
      "name": "Soil_Clay_Lime"
    },
    {
      "x": -12,
      "y": 25,
      "z": -5,
      "name": "Plant_Grass_Sharp"
    },
    {
      "x": -12,
      "y": 26,
      "z": -5,
      "name": "Plant_Grass_Sharp"
    },
    {
      "x": -12,
      "y": 8,
      "z": -4,
      "name": "Soil_Seaweed_Block"
    },
    {
      "x": -12,
      "y": 9,
      "z": -4,
      "name": "Soil_Clay_Lime"
    },
    {
      "x": -12,
      "y": 10,
      "z": -4,
      "name": "Plant_Grass_Sharp"
    },
    {
      "x": -12,
      "y": 20,
      "z": -4,
      "name": "Soil_Clay_Green"
    },
    {
      "x": -12,
      "y": 24,
      "z": -4,
      "name": "Soil_Seaweed_Block"
    },
    {
      "x": -12,
      "y": 25,
      "z": -4,
      "name": "Soil_Clay_Green"
    },
    {
      "x": -12,
      "y": 26,
      "z": -4,
      "name": "Soil_Clay_Green"
    },
    {
      "x": -12,
      "y": 7,
      "z": -3,
      "name": "Soil_Seaweed_Block"
    },
    {
      "x": -12,
      "y": 8,
      "z": -3,
      "name": "Soil_Seaweed_Block"
    },
    {
      "x": -12,
      "y": 26,
      "z": -3,
      "name": "Soil_Clay_Green"
    },
    {
      "x": -12,
      "y": 27,
      "z": -3,
      "name": "Soil_Clay_Lime"
    },
    {
      "x": -12,
      "y": 28,
      "z": -3,
      "name": "Plant_Grass_Sharp"
    },
    {
      "x": -12,
      "y": 6,
      "z": -2,
      "name": "Soil_Clay_Green"
    },
    {
      "x": -12,
      "y": 7,
      "z": -2,
      "name": "Soil_Seaweed_Block"
    },
    {
      "x": -12,
      "y": 8,
      "z": -2,
      "name": "Soil_Seaweed_Block"
    },
    {
      "x": -12,
      "y": 9,
      "z": -2,
      "name": "Soil_Clay_Lime"
    },
    {
      "x": -12,
      "y": 10,
      "z": -2,
      "name": "Plant_Grass_Sharp"
    },
    {
      "x": -12,
      "y": 26,
      "z": -2,
      "name": "Soil_Clay_Green"
    },
    {
      "x": -12,
      "y": 27,
      "z": -2,
      "name": "Soil_Clay_Lime"
    },
    {
      "x": -12,
      "y": 28,
      "z": -2,
      "name": "Plant_Grass_Sharp"
    },
    {
      "x": -12,
      "y": 5,
      "z": -1,
      "name": "Soil_Clay_Green"
    },
    {
      "x": -12,
      "y": 6,
      "z": -1,
      "name": "Soil_Seaweed_Block"
    },
    {
      "x": -12,
      "y": 7,
      "z": -1,
      "name": "Soil_Seaweed_Block"
    },
    {
      "x": -12,
      "y": 8,
      "z": -1,
      "name": "Soil_Seaweed_Block"
    },
    {
      "x": -12,
      "y": 9,
      "z": -1,
      "name": "Soil_Clay_Lime"
    },
    {
      "x": -12,
      "y": 10,
      "z": -1,
      "name": "Plant_Grass_Sharp"
    },
    {
      "x": -12,
      "y": 26,
      "z": -1,
      "name": "Soil_Clay_Green"
    },
    {
      "x": -12,
      "y": 27,
      "z": -1,
      "name": "Soil_Clay_Lime"
    },
    {
      "x": -12,
      "y": 28,
      "z": -1,
      "name": "Plant_Grass_Sharp"
    },
    {
      "x": -12,
      "y": 4,
      "z": 0,
      "name": "Soil_Clay_Green"
    },
    {
      "x": -12,
      "y": 5,
      "z": 0,
      "name": "Soil_Seaweed_Block"
    },
    {
      "x": -12,
      "y": 6,
      "z": 0,
      "name": "Soil_Seaweed_Block"
    },
    {
      "x": -12,
      "y": 7,
      "z": 0,
      "name": "Soil_Seaweed_Block"
    },
    {
      "x": -12,
      "y": 8,
      "z": 0,
      "name": "Soil_Seaweed_Block"
    },
    {
      "x": -12,
      "y": 9,
      "z": 0,
      "name": "Soil_Clay_Lime"
    },
    {
      "x": -12,
      "y": 10,
      "z": 0,
      "name": "Plant_Grass_Sharp"
    },
    {
      "x": -12,
      "y": 26,
      "z": 0,
      "name": "Soil_Clay_Green"
    },
    {
      "x": -12,
      "y": 27,
      "z": 0,
      "name": "Soil_Clay_Lime"
    },
    {
      "x": -12,
      "y": 28,
      "z": 0,
      "name": "Plant_Grass_Sharp"
    },
    {
      "x": -12,
      "y": 5,
      "z": 1,
      "name": "Soil_Clay_Green"
    },
    {
      "x": -12,
      "y": 6,
      "z": 1,
      "name": "Soil_Seaweed_Block"
    },
    {
      "x": -12,
      "y": 7,
      "z": 1,
      "name": "Soil_Seaweed_Block"
    },
    {
      "x": -12,
      "y": 8,
      "z": 1,
      "name": "Soil_Seaweed_Block"
    },
    {
      "x": -12,
      "y": 9,
      "z": 1,
      "name": "Soil_Clay_Lime"
    },
    {
      "x": -12,
      "y": 10,
      "z": 1,
      "name": "Plant_Grass_Sharp"
    },
    {
      "x": -12,
      "y": 26,
      "z": 1,
      "name": "Soil_Clay_Green"
    },
    {
      "x": -12,
      "y": 27,
      "z": 1,
      "name": "Soil_Clay_Lime"
    },
    {
      "x": -12,
      "y": 28,
      "z": 1,
      "name": "Plant_Grass_Sharp"
    },
    {
      "x": -12,
      "y": 5,
      "z": 2,
      "name": "Soil_Clay_Green"
    },
    {
      "x": -12,
      "y": 6,
      "z": 2,
      "name": "Soil_Seaweed_Block"
    },
    {
      "x": -12,
      "y": 7,
      "z": 2,
      "name": "Soil_Seaweed_Block"
    },
    {
      "x": -12,
      "y": 8,
      "z": 2,
      "name": "Soil_Seaweed_Block"
    },
    {
      "x": -12,
      "y": 9,
      "z": 2,
      "name": "Soil_Seaweed_Block"
    },
    {
      "x": -12,
      "y": 10,
      "z": 2,
      "name": "Soil_Clay_Lime"
    },
    {
      "x": -12,
      "y": 11,
      "z": 2,
      "name": "Soil_Clay_Lime"
    },
    {
      "x": -12,
      "y": 12,
      "z": 2,
      "name": "Plant_Grass_Sharp"
    },
    {
      "x": -12,
      "y": 26,
      "z": 2,
      "name": "Soil_Clay_Green"
    },
    {
      "x": -12,
      "y": 27,
      "z": 2,
      "name": "Soil_Clay_Lime"
    },
    {
      "x": -12,
      "y": 28,
      "z": 2,
      "name": "Plant_Grass_Sharp"
    },
    {
      "x": -12,
      "y": 6,
      "z": 3,
      "name": "Soil_Clay_Green"
    },
    {
      "x": -12,
      "y": 7,
      "z": 3,
      "name": "Soil_Seaweed_Block"
    },
    {
      "x": -12,
      "y": 8,
      "z": 3,
      "name": "Soil_Seaweed_Block"
    },
    {
      "x": -12,
      "y": 9,
      "z": 3,
      "name": "Soil_Seaweed_Block"
    },
    {
      "x": -12,
      "y": 10,
      "z": 3,
      "name": "Soil_Clay_Lime"
    },
    {
      "x": -12,
      "y": 11,
      "z": 3,
      "name": "Soil_Clay_Lime"
    },
    {
      "x": -12,
      "y": 12,
      "z": 3,
      "name": "Plant_Grass_Sharp"
    },
    {
      "x": -12,
      "y": 26,
      "z": 3,
      "name": "Soil_Clay_Green"
    },
    {
      "x": -12,
      "y": 27,
      "z": 3,
      "name": "Soil_Clay_Lime"
    },
    {
      "x": -12,
      "y": 28,
      "z": 3,
      "name": "Plant_Grass_Sharp"
    },
    {
      "x": -12,
      "y": 7,
      "z": 4,
      "name": "Soil_Clay_Green"
    },
    {
      "x": -12,
      "y": 8,
      "z": 4,
      "name": "Soil_Seaweed_Block"
    },
    {
      "x": -12,
      "y": 9,
      "z": 4,
      "name": "Soil_Seaweed_Block"
    },
    {
      "x": -12,
      "y": 10,
      "z": 4,
      "name": "Soil_Seaweed_Block"
    },
    {
      "x": -12,
      "y": 11,
      "z": 4,
      "name": "Soil_Clay_Lime"
    },
    {
      "x": -12,
      "y": 12,
      "z": 4,
      "name": "Soil_Seaweed_Block"
    },
    {
      "x": -12,
      "y": 13,
      "z": 4,
      "name": "Soil_Clay_Green"
    },
    {
      "x": -12,
      "y": 14,
      "z": 4,
      "name": "Soil_Clay_Green"
    },
    {
      "x": -12,
      "y": 15,
      "z": 4,
      "name": "Soil_Seaweed_Block"
    },
    {
      "x": -12,
      "y": 25,
      "z": 4,
      "name": "Soil_Clay_Green"
    },
    {
      "x": -12,
      "y": 26,
      "z": 4,
      "name": "Soil_Clay_Green"
    },
    {
      "x": -12,
      "y": 27,
      "z": 4,
      "name": "Soil_Clay_Lime"
    },
    {
      "x": -12,
      "y": 28,
      "z": 4,
      "name": "Plant_Grass_Sharp"
    },
    {
      "x": -12,
      "y": 7,
      "z": 5,
      "name": "Soil_Clay_Green"
    },
    {
      "x": -12,
      "y": 8,
      "z": 5,
      "name": "Soil_Clay_Green"
    },
    {
      "x": -12,
      "y": 9,
      "z": 5,
      "name": "Soil_Seaweed_Block"
    },
    {
      "x": -12,
      "y": 10,
      "z": 5,
      "name": "Soil_Seaweed_Block"
    },
    {
      "x": -12,
      "y": 11,
      "z": 5,
      "name": "Soil_Seaweed_Block"
    },
    {
      "x": -12,
      "y": 12,
      "z": 5,
      "name": "Soil_Seaweed_Block"
    },
    {
      "x": -12,
      "y": 13,
      "z": 5,
      "name": "Soil_Clay_Green"
    },
    {
      "x": -12,
      "y": 14,
      "z": 5,
      "name": "Soil_Clay_Green"
    },
    {
      "x": -12,
      "y": 15,
      "z": 5,
      "name": "Soil_Clay_Green"
    },
    {
      "x": -12,
      "y": 16,
      "z": 5,
      "name": "Soil_Seaweed_Block"
    },
    {
      "x": -12,
      "y": 17,
      "z": 5,
      "name": "Soil_Seaweed_Block"
    },
    {
      "x": -12,
      "y": 19,
      "z": 5,
      "name": "Soil_Seaweed_Block"
    },
    {
      "x": -12,
      "y": 20,
      "z": 5,
      "name": "Soil_Seaweed_Block"
    },
    {
      "x": -12,
      "y": 21,
      "z": 5,
      "name": "Soil_Seaweed_Block"
    },
    {
      "x": -12,
      "y": 22,
      "z": 5,
      "name": "Soil_Seaweed_Block"
    },
    {
      "x": -12,
      "y": 23,
      "z": 5,
      "name": "Soil_Clay_Green"
    },
    {
      "x": -12,
      "y": 24,
      "z": 5,
      "name": "Soil_Clay_Green"
    },
    {
      "x": -12,
      "y": 25,
      "z": 5,
      "name": "Soil_Clay_Green"
    },
    {
      "x": -12,
      "y": 26,
      "z": 5,
      "name": "Soil_Seaweed_Block"
    },
    {
      "x": -12,
      "y": 27,
      "z": 5,
      "name": "Soil_Clay_Lime"
    },
    {
      "x": -12,
      "y": 28,
      "z": 5,
      "name": "Plant_Grass_Sharp"
    },
    {
      "x": -12,
      "y": 7,
      "z": 6,
      "name": "Soil_Clay_Green"
    },
    {
      "x": -12,
      "y": 8,
      "z": 6,
      "name": "Soil_Seaweed_Block"
    },
    {
      "x": -12,
      "y": 9,
      "z": 6,
      "name": "Soil_Seaweed_Block"
    },
    {
      "x": -12,
      "y": 10,
      "z": 6,
      "name": "Soil_Clay_Lime"
    },
    {
      "x": -12,
      "y": 11,
      "z": 6,
      "name": "Soil_Clay_Lime"
    },
    {
      "x": -12,
      "y": 12,
      "z": 6,
      "name": "Plant_Grass_Sharp"
    },
    {
      "x": -12,
      "y": 18,
      "z": 6,
      "name": "Soil_Clay_Green"
    },
    {
      "x": -12,
      "y": 19,
      "z": 6,
      "name": "Soil_Seaweed_Block"
    },
    {
      "x": -12,
      "y": 20,
      "z": 6,
      "name": "Soil_Seaweed_Block"
    },
    {
      "x": -12,
      "y": 21,
      "z": 6,
      "name": "Soil_Seaweed_Block"
    },
    {
      "x": -12,
      "y": 22,
      "z": 6,
      "name": "Soil_Seaweed_Block"
    },
    {
      "x": -12,
      "y": 23,
      "z": 6,
      "name": "Soil_Clay_Green"
    },
    {
      "x": -12,
      "y": 24,
      "z": 6,
      "name": "Soil_Seaweed_Block"
    },
    {
      "x": -12,
      "y": 25,
      "z": 6,
      "name": "Soil_Seaweed_Block"
    },
    {
      "x": -12,
      "y": 26,
      "z": 6,
      "name": "Soil_Seaweed_Block"
    },
    {
      "x": -12,
      "y": 27,
      "z": 6,
      "name": "Soil_Clay_Lime"
    },
    {
      "x": -12,
      "y": 28,
      "z": 6,
      "name": "Plant_Grass_Sharp"
    },
    {
      "x": -12,
      "y": 8,
      "z": 7,
      "name": "Soil_Clay_Green"
    },
    {
      "x": -12,
      "y": 9,
      "z": 7,
      "name": "Soil_Seaweed_Block"
    },
    {
      "x": -12,
      "y": 17,
      "z": 7,
      "name": "Soil_Clay_Green"
    },
    {
      "x": -12,
      "y": 18,
      "z": 7,
      "name": "Soil_Clay_Green"
    },
    {
      "x": -12,
      "y": 19,
      "z": 7,
      "name": "Soil_Seaweed_Block"
    },
    {
      "x": -12,
      "y": 20,
      "z": 7,
      "name": "Soil_Clay_Lime"
    },
    {
      "x": -12,
      "y": 21,
      "z": 7,
      "name": "Soil_Clay_Lime"
    },
    {
      "x": -12,
      "y": 22,
      "z": 7,
      "name": "Plant_Grass_Sharp"
    },
    {
      "x": -12,
      "y": 24,
      "z": 7,
      "name": "Soil_Clay_Green"
    },
    {
      "x": -12,
      "y": 25,
      "z": 7,
      "name": "Soil_Clay_Green"
    },
    {
      "x": -12,
      "y": 26,
      "z": 7,
      "name": "Soil_Seaweed_Block"
    },
    {
      "x": -12,
      "y": 8,
      "z": 8,
      "name": "Soil_Clay_Green"
    },
    {
      "x": -12,
      "y": 9,
      "z": 8,
      "name": "Soil_Seaweed_Block"
    },
    {
      "x": -12,
      "y": 17,
      "z": 8,
      "name": "Soil_Clay_Green"
    },
    {
      "x": -12,
      "y": 18,
      "z": 8,
      "name": "Soil_Clay_Green"
    },
    {
      "x": -12,
      "y": 19,
      "z": 8,
      "name": "Soil_Seaweed_Block"
    },
    {
      "x": -12,
      "y": 20,
      "z": 8,
      "name": "Soil_Clay_Lime"
    },
    {
      "x": -12,
      "y": 21,
      "z": 8,
      "name": "Soil_Clay_Lime"
    },
    {
      "x": -12,
      "y": 22,
      "z": 8,
      "name": "Plant_Grass_Sharp"
    },
    {
      "x": -12,
      "y": 17,
      "z": 9,
      "name": "Soil_Clay_Green"
    },
    {
      "x": -12,
      "y": 18,
      "z": 9,
      "name": "Soil_Seaweed_Block"
    },
    {
      "x": -12,
      "y": 19,
      "z": 9,
      "name": "Soil_Seaweed_Block"
    },
    {
      "x": -12,
      "y": 20,
      "z": 9,
      "name": "Soil_Clay_Lime"
    },
    {
      "x": -12,
      "y": 21,
      "z": 9,
      "name": "Plant_Grass_Sharp"
    },
    {
      "x": -12,
      "y": 18,
      "z": 10,
      "name": "Soil_Clay_Green"
    },
    {
      "x": -12,
      "y": 19,
      "z": 10,
      "name": "Soil_Seaweed_Block"
    },
    {
      "x": -12,
      "y": 18,
      "z": 11,
      "name": "Soil_Clay_Green"
    },
    {
      "x": -12,
      "y": 19,
      "z": 11,
      "name": "Soil_Seaweed_Block"
    },
    {
      "x": -11,
      "y": 13,
      "z": -11,
      "name": "Soil_Clay_Green"
    },
    {
      "x": -11,
      "y": 14,
      "z": -11,
      "name": "Soil_Seaweed_Block"
    },
    {
      "x": -11,
      "y": 15,
      "z": -11,
      "name": "Soil_Clay_Lime"
    },
    {
      "x": -11,
      "y": 16,
      "z": -11,
      "name": "Plant_Grass_Sharp"
    },
    {
      "x": -11,
      "y": 12,
      "z": -10,
      "name": "Soil_Clay_Green"
    },
    {
      "x": -11,
      "y": 13,
      "z": -10,
      "name": "Soil_Clay_Green"
    },
    {
      "x": -11,
      "y": 14,
      "z": -10,
      "name": "Soil_Seaweed_Block"
    },
    {
      "x": -11,
      "y": 15,
      "z": -10,
      "name": "Soil_Clay_Lime"
    },
    {
      "x": -11,
      "y": 16,
      "z": -10,
      "name": "Plant_Grass_Sharp"
    },
    {
      "x": -11,
      "y": 21,
      "z": -10,
      "name": "Soil_Clay_Green"
    },
    {
      "x": -11,
      "y": 22,
      "z": -10,
      "name": "Soil_Seaweed_Block"
    },
    {
      "x": -11,
      "y": 11,
      "z": -9,
      "name": "Soil_Clay_Green"
    },
    {
      "x": -11,
      "y": 12,
      "z": -9,
      "name": "Soil_Seaweed_Block"
    },
    {
      "x": -11,
      "y": 13,
      "z": -9,
      "name": "Soil_Seaweed_Block"
    },
    {
      "x": -11,
      "y": 14,
      "z": -9,
      "name": "Soil_Clay_Lime"
    },
    {
      "x": -11,
      "y": 15,
      "z": -9,
      "name": "Plant_Grass_Sharp"
    },
    {
      "x": -11,
      "y": 16,
      "z": -9,
      "name": "Plant_Grass_Sharp"
    },
    {
      "x": -11,
      "y": 21,
      "z": -9,
      "name": "Soil_Clay_Green"
    },
    {
      "x": -11,
      "y": 22,
      "z": -9,
      "name": "Soil_Clay_Lime"
    },
    {
      "x": -11,
      "y": 23,
      "z": -9,
      "name": "Plant_Grass_Sharp"
    },
    {
      "x": -11,
      "y": 11,
      "z": -8,
      "name": "Soil_Clay_Green"
    },
    {
      "x": -11,
      "y": 12,
      "z": -8,
      "name": "Soil_Seaweed_Block"
    },
    {
      "x": -11,
      "y": 13,
      "z": -8,
      "name": "Soil_Seaweed_Block"
    },
    {
      "x": -11,
      "y": 14,
      "z": -8,
      "name": "Soil_Clay_Lime"
    },
    {
      "x": -11,
      "y": 15,
      "z": -8,
      "name": "Plant_Grass_Sharp"
    },
    {
      "x": -11,
      "y": 16,
      "z": -8,
      "name": "Plant_Grass_Sharp"
    },
    {
      "x": -11,
      "y": 21,
      "z": -8,
      "name": "Soil_Clay_Green"
    },
    {
      "x": -11,
      "y": 22,
      "z": -8,
      "name": "Soil_Clay_Lime"
    },
    {
      "x": -11,
      "y": 23,
      "z": -8,
      "name": "Plant_Grass_Sharp"
    },
    {
      "x": -11,
      "y": 11,
      "z": -7,
      "name": "Soil_Clay_Green"
    },
    {
      "x": -11,
      "y": 12,
      "z": -7,
      "name": "Soil_Clay_Green"
    },
    {
      "x": -11,
      "y": 13,
      "z": -7,
      "name": "Soil_Seaweed_Block"
    },
    {
      "x": -11,
      "y": 14,
      "z": -7,
      "name": "Soil_Clay_Lime"
    },
    {
      "x": -11,
      "y": 15,
      "z": -7,
      "name": "Plant_Grass_Sharp"
    },
    {
      "x": -11,
      "y": 16,
      "z": -7,
      "name": "Plant_Grass_Sharp"
    },
    {
      "x": -11,
      "y": 21,
      "z": -7,
      "name": "Soil_Clay_Green"
    },
    {
      "x": -11,
      "y": 22,
      "z": -7,
      "name": "Soil_Clay_Lime"
    },
    {
      "x": -11,
      "y": 23,
      "z": -7,
      "name": "Plant_Grass_Sharp"
    },
    {
      "x": -11,
      "y": 11,
      "z": -6,
      "name": "Soil_Clay_Green"
    },
    {
      "x": -11,
      "y": 12,
      "z": -6,
      "name": "Soil_Clay_Green"
    },
    {
      "x": -11,
      "y": 27,
      "z": -4,
      "name": "Soil_Clay_Green"
    },
    {
      "x": -11,
      "y": 29,
      "z": -4,
      "name": "Plant_Grass_Sharp"
    },
    {
      "x": -11,
      "y": 7,
      "z": -3,
      "name": "Soil_Seaweed_Block"
    },
    {
      "x": -11,
      "y": 8,
      "z": -3,
      "name": "Soil_Seaweed_Block"
    },
    {
      "x": -11,
      "y": 26,
      "z": -3,
      "name": "Soil_Clay_Green"
    },
    {
      "x": -11,
      "y": 27,
      "z": -3,
      "name": "Soil_Clay_Lime"
    },
    {
      "x": -11,
      "y": 28,
      "z": -3,
      "name": "Plant_Grass_Sharp"
    },
    {
      "x": -11,
      "y": 5,
      "z": -2,
      "name": "Soil_Clay_Green"
    },
    {
      "x": -11,
      "y": 6,
      "z": -2,
      "name": "Soil_Clay_Green"
    },
    {
      "x": -11,
      "y": 7,
      "z": -2,
      "name": "Soil_Seaweed_Block"
    },
    {
      "x": -11,
      "y": 8,
      "z": -2,
      "name": "Soil_Seaweed_Block"
    },
    {
      "x": -11,
      "y": 9,
      "z": -2,
      "name": "Soil_Clay_Lime"
    },
    {
      "x": -11,
      "y": 10,
      "z": -2,
      "name": "Plant_Grass_Sharp"
    },
    {
      "x": -11,
      "y": 27,
      "z": -2,
      "name": "Soil_Seaweed_Block"
    },
    {
      "x": -11,
      "y": 28,
      "z": -2,
      "name": "Plant_Grass_Sharp"
    },
    {
      "x": -11,
      "y": 5,
      "z": -1,
      "name": "Soil_Clay_Green"
    },
    {
      "x": -11,
      "y": 6,
      "z": -1,
      "name": "Soil_Seaweed_Block"
    },
    {
      "x": -11,
      "y": 7,
      "z": -1,
      "name": "Soil_Seaweed_Block"
    },
    {
      "x": -11,
      "y": 8,
      "z": -1,
      "name": "Soil_Clay_Lime"
    },
    {
      "x": -11,
      "y": 9,
      "z": -1,
      "name": "Soil_Clay_Lime"
    },
    {
      "x": -11,
      "y": 10,
      "z": -1,
      "name": "Plant_Grass_Sharp"
    },
    {
      "x": -11,
      "y": 5,
      "z": 0,
      "name": "Soil_Clay_Green"
    },
    {
      "x": -11,
      "y": 6,
      "z": 0,
      "name": "Soil_Seaweed_Block"
    },
    {
      "x": -11,
      "y": 7,
      "z": 0,
      "name": "Soil_Seaweed_Block"
    },
    {
      "x": -11,
      "y": 8,
      "z": 0,
      "name": "Soil_Seaweed_Block"
    },
    {
      "x": -11,
      "y": 9,
      "z": 0,
      "name": "Soil_Clay_Lime"
    },
    {
      "x": -11,
      "y": 10,
      "z": 0,
      "name": "Plant_Grass_Sharp"
    },
    {
      "x": -11,
      "y": 27,
      "z": 0,
      "name": "Soil_Clay_Lime"
    },
    {
      "x": -11,
      "y": 28,
      "z": 0,
      "name": "Plant_Grass_Sharp"
    },
    {
      "x": -11,
      "y": 5,
      "z": 1,
      "name": "Soil_Clay_Green"
    },
    {
      "x": -11,
      "y": 6,
      "z": 1,
      "name": "Soil_Seaweed_Block"
    },
    {
      "x": -11,
      "y": 7,
      "z": 1,
      "name": "Soil_Seaweed_Block"
    },
    {
      "x": -11,
      "y": 8,
      "z": 1,
      "name": "Soil_Seaweed_Block"
    },
    {
      "x": -11,
      "y": 9,
      "z": 1,
      "name": "Soil_Clay_Lime"
    },
    {
      "x": -11,
      "y": 10,
      "z": 1,
      "name": "Plant_Grass_Sharp"
    },
    {
      "x": -11,
      "y": 27,
      "z": 1,
      "name": "Soil_Clay_Lime"
    },
    {
      "x": -11,
      "y": 28,
      "z": 1,
      "name": "Plant_Grass_Sharp"
    },
    {
      "x": -11,
      "y": 5,
      "z": 2,
      "name": "Soil_Clay_Green"
    },
    {
      "x": -11,
      "y": 6,
      "z": 2,
      "name": "Soil_Seaweed_Block"
    },
    {
      "x": -11,
      "y": 7,
      "z": 2,
      "name": "Soil_Seaweed_Block"
    },
    {
      "x": -11,
      "y": 8,
      "z": 2,
      "name": "Soil_Seaweed_Block"
    },
    {
      "x": -11,
      "y": 9,
      "z": 2,
      "name": "Soil_Clay_Lime"
    },
    {
      "x": -11,
      "y": 10,
      "z": 2,
      "name": "Plant_Grass_Sharp"
    },
    {
      "x": -11,
      "y": 26,
      "z": 2,
      "name": "Soil_Clay_Green"
    },
    {
      "x": -11,
      "y": 27,
      "z": 2,
      "name": "Soil_Clay_Lime"
    },
    {
      "x": -11,
      "y": 28,
      "z": 2,
      "name": "Plant_Grass_Sharp"
    },
    {
      "x": -11,
      "y": 5,
      "z": 3,
      "name": "Soil_Clay_Green"
    },
    {
      "x": -11,
      "y": 6,
      "z": 3,
      "name": "Soil_Seaweed_Block"
    },
    {
      "x": -11,
      "y": 7,
      "z": 3,
      "name": "Soil_Seaweed_Block"
    },
    {
      "x": -11,
      "y": 8,
      "z": 3,
      "name": "Soil_Seaweed_Block"
    },
    {
      "x": -11,
      "y": 9,
      "z": 3,
      "name": "Soil_Clay_Lime"
    },
    {
      "x": -11,
      "y": 10,
      "z": 3,
      "name": "Plant_Grass_Sharp"
    },
    {
      "x": -11,
      "y": 11,
      "z": 3,
      "name": "Plant_Grass_Sharp"
    },
    {
      "x": -11,
      "y": 26,
      "z": 3,
      "name": "Soil_Clay_Green"
    },
    {
      "x": -11,
      "y": 27,
      "z": 3,
      "name": "Soil_Seaweed_Block"
    },
    {
      "x": -11,
      "y": 28,
      "z": 3,
      "name": "Plant_Grass_Sharp"
    },
    {
      "x": -11,
      "y": 6,
      "z": 4,
      "name": "Soil_Clay_Green"
    },
    {
      "x": -11,
      "y": 7,
      "z": 4,
      "name": "Soil_Seaweed_Block"
    },
    {
      "x": -11,
      "y": 8,
      "z": 4,
      "name": "Soil_Seaweed_Block"
    },
    {
      "x": -11,
      "y": 9,
      "z": 4,
      "name": "Soil_Clay_Lime"
    },
    {
      "x": -11,
      "y": 10,
      "z": 4,
      "name": "Soil_Clay_Lime"
    },
    {
      "x": -11,
      "y": 11,
      "z": 4,
      "name": "Plant_Grass_Sharp"
    },
    {
      "x": -11,
      "y": 25,
      "z": 4,
      "name": "Soil_Clay_Green"
    },
    {
      "x": -11,
      "y": 26,
      "z": 4,
      "name": "Soil_Seaweed_Block"
    },
    {
      "x": -11,
      "y": 27,
      "z": 4,
      "name": "Soil_Seaweed_Block"
    },
    {
      "x": -11,
      "y": 28,
      "z": 4,
      "name": "Soil_Clay_Lime"
    },
    {
      "x": -11,
      "y": 29,
      "z": 4,
      "name": "Plant_Grass_Sharp"
    },
    {
      "x": -11,
      "y": 6,
      "z": 5,
      "name": "Soil_Clay_Green"
    },
    {
      "x": -11,
      "y": 7,
      "z": 5,
      "name": "Soil_Seaweed_Block"
    },
    {
      "x": -11,
      "y": 8,
      "z": 5,
      "name": "Soil_Seaweed_Block"
    },
    {
      "x": -11,
      "y": 9,
      "z": 5,
      "name": "Soil_Seaweed_Block"
    },
    {
      "x": -11,
      "y": 10,
      "z": 5,
      "name": "Soil_Clay_Lime"
    },
    {
      "x": -11,
      "y": 11,
      "z": 5,
      "name": "Plant_Grass_Sharp"
    },
    {
      "x": -11,
      "y": 24,
      "z": 5,
      "name": "Soil_Clay_Green"
    },
    {
      "x": -11,
      "y": 25,
      "z": 5,
      "name": "Soil_Seaweed_Block"
    },
    {
      "x": -11,
      "y": 26,
      "z": 5,
      "name": "Soil_Seaweed_Block"
    },
    {
      "x": -11,
      "y": 27,
      "z": 5,
      "name": "Soil_Seaweed_Block"
    },
    {
      "x": -11,
      "y": 28,
      "z": 5,
      "name": "Soil_Clay_Lime"
    },
    {
      "x": -11,
      "y": 29,
      "z": 5,
      "name": "Plant_Grass_Sharp"
    },
    {
      "x": -11,
      "y": 7,
      "z": 6,
      "name": "Soil_Clay_Green"
    },
    {
      "x": -11,
      "y": 8,
      "z": 6,
      "name": "Soil_Seaweed_Block"
    },
    {
      "x": -11,
      "y": 9,
      "z": 6,
      "name": "Soil_Seaweed_Block"
    },
    {
      "x": -11,
      "y": 10,
      "z": 6,
      "name": "Soil_Clay_Lime"
    },
    {
      "x": -11,
      "y": 11,
      "z": 6,
      "name": "Plant_Grass_Sharp"
    },
    {
      "x": -11,
      "y": 24,
      "z": 6,
      "name": "Soil_Clay_Green"
    },
    {
      "x": -11,
      "y": 25,
      "z": 6,
      "name": "Soil_Seaweed_Block"
    },
    {
      "x": -11,
      "y": 26,
      "z": 6,
      "name": "Soil_Seaweed_Block"
    },
    {
      "x": -11,
      "y": 27,
      "z": 6,
      "name": "Soil_Seaweed_Block"
    },
    {
      "x": -11,
      "y": 28,
      "z": 6,
      "name": "Soil_Clay_Lime"
    },
    {
      "x": -11,
      "y": 29,
      "z": 6,
      "name": "Plant_Grass_Sharp"
    },
    {
      "x": -11,
      "y": 7,
      "z": 7,
      "name": "Soil_Clay_Green"
    },
    {
      "x": -11,
      "y": 8,
      "z": 7,
      "name": "Soil_Seaweed_Block"
    },
    {
      "x": -11,
      "y": 9,
      "z": 7,
      "name": "Soil_Seaweed_Block"
    },
    {
      "x": -11,
      "y": 10,
      "z": 7,
      "name": "Soil_Clay_Lime"
    },
    {
      "x": -11,
      "y": 11,
      "z": 7,
      "name": "Plant_Grass_Sharp"
    },
    {
      "x": -11,
      "y": 24,
      "z": 7,
      "name": "Soil_Clay_Green"
    },
    {
      "x": -11,
      "y": 25,
      "z": 7,
      "name": "Soil_Clay_Green"
    },
    {
      "x": -11,
      "y": 26,
      "z": 7,
      "name": "Soil_Clay_Green"
    },
    {
      "x": -11,
      "y": 27,
      "z": 7,
      "name": "Soil_Seaweed_Block"
    },
    {
      "x": -11,
      "y": 8,
      "z": 8,
      "name": "Soil_Clay_Green"
    },
    {
      "x": -11,
      "y": 9,
      "z": 8,
      "name": "Soil_Seaweed_Block"
    },
    {
      "x": -11,
      "y": 18,
      "z": 8,
      "name": "Soil_Clay_Green"
    },
    {
      "x": -11,
      "y": 19,
      "z": 8,
      "name": "Soil_Seaweed_Block"
    },
    {
      "x": -11,
      "y": 18,
      "z": 9,
      "name": "Soil_Clay_Green"
    },
    {
      "x": -11,
      "y": 19,
      "z": 9,
      "name": "Soil_Seaweed_Block"
    },
    {
      "x": -11,
      "y": 18,
      "z": 10,
      "name": "Soil_Clay_Green"
    },
    {
      "x": -11,
      "y": 19,
      "z": 10,
      "name": "Soil_Seaweed_Block"
    },
    {
      "x": -11,
      "y": 20,
      "z": 10,
      "name": "Soil_Clay_Lime"
    },
    {
      "x": -11,
      "y": 21,
      "z": 10,
      "name": "Plant_Grass_Sharp"
    },
    {
      "x": -11,
      "y": 18,
      "z": 11,
      "name": "Soil_Clay_Green"
    },
    {
      "x": -11,
      "y": 19,
      "z": 11,
      "name": "Soil_Seaweed_Block"
    },
    {
      "x": -11,
      "y": 20,
      "z": 11,
      "name": "Soil_Clay_Lime"
    },
    {
      "x": -11,
      "y": 21,
      "z": 11,
      "name": "Plant_Grass_Sharp"
    },
    {
      "x": -11,
      "y": 18,
      "z": 12,
      "name": "Soil_Clay_Green"
    },
    {
      "x": -11,
      "y": 19,
      "z": 12,
      "name": "Soil_Clay_Green"
    },
    {
      "x": -11,
      "y": 20,
      "z": 12,
      "name": "Soil_Clay_Lime"
    },
    {
      "x": -11,
      "y": 21,
      "z": 12,
      "name": "Plant_Grass_Sharp"
    },
    {
      "x": -11,
      "y": 19,
      "z": 13,
      "name": "Soil_Clay_Green"
    },
    {
      "x": -10,
      "y": 14,
      "z": -13,
      "name": "Soil_Seaweed_Block"
    },
    {
      "x": -10,
      "y": 13,
      "z": -12,
      "name": "Soil_Clay_Green"
    },
    {
      "x": -10,
      "y": 14,
      "z": -12,
      "name": "Soil_Seaweed_Block"
    },
    {
      "x": -10,
      "y": 15,
      "z": -12,
      "name": "Soil_Clay_Lime"
    },
    {
      "x": -10,
      "y": 16,
      "z": -12,
      "name": "Soil_Clay_Lime"
    },
    {
      "x": -10,
      "y": 17,
      "z": -12,
      "name": "Plant_Grass_Sharp"
    },
    {
      "x": -10,
      "y": 12,
      "z": -11,
      "name": "Soil_Clay_Green"
    },
    {
      "x": -10,
      "y": 13,
      "z": -11,
      "name": "Soil_Seaweed_Block"
    },
    {
      "x": -10,
      "y": 14,
      "z": -11,
      "name": "Soil_Seaweed_Block"
    },
    {
      "x": -10,
      "y": 15,
      "z": -11,
      "name": "Soil_Seaweed_Block"
    },
    {
      "x": -10,
      "y": 16,
      "z": -11,
      "name": "Soil_Clay_Lime"
    },
    {
      "x": -10,
      "y": 17,
      "z": -11,
      "name": "Plant_Grass_Sharp"
    },
    {
      "x": -10,
      "y": 19,
      "z": -11,
      "name": "Soil_Clay_Green"
    },
    {
      "x": -10,
      "y": 20,
      "z": -11,
      "name": "Soil_Clay_Green"
    },
    {
      "x": -10,
      "y": 21,
      "z": -11,
      "name": "Soil_Clay_Green"
    },
    {
      "x": -10,
      "y": 22,
      "z": -11,
      "name": "Soil_Seaweed_Block"
    },
    {
      "x": -10,
      "y": 12,
      "z": -10,
      "name": "Soil_Clay_Green"
    },
    {
      "x": -10,
      "y": 13,
      "z": -10,
      "name": "Soil_Seaweed_Block"
    },
    {
      "x": -10,
      "y": 14,
      "z": -10,
      "name": "Soil_Seaweed_Block"
    },
    {
      "x": -10,
      "y": 15,
      "z": -10,
      "name": "Soil_Clay_Lime"
    },
    {
      "x": -10,
      "y": 16,
      "z": -10,
      "name": "Plant_Grass_Sharp"
    },
    {
      "x": -10,
      "y": 20,
      "z": -10,
      "name": "Soil_Clay_Green"
    },
    {
      "x": -10,
      "y": 21,
      "z": -10,
      "name": "Soil_Clay_Green"
    },
    {
      "x": -10,
      "y": 22,
      "z": -10,
      "name": "Soil_Seaweed_Block"
    },
    {
      "x": -10,
      "y": 12,
      "z": -9,
      "name": "Soil_Clay_Green"
    },
    {
      "x": -10,
      "y": 13,
      "z": -9,
      "name": "Soil_Seaweed_Block"
    },
    {
      "x": -10,
      "y": 14,
      "z": -9,
      "name": "Soil_Seaweed_Block"
    },
    {
      "x": -10,
      "y": 16,
      "z": -9,
      "name": "Plant_Grass_Sharp"
    },
    {
      "x": -10,
      "y": 21,
      "z": -9,
      "name": "Soil_Clay_Green"
    },
    {
      "x": -10,
      "y": 22,
      "z": -9,
      "name": "Soil_Clay_Lime"
    },
    {
      "x": -10,
      "y": 23,
      "z": -9,
      "name": "Plant_Grass_Sharp"
    },
    {
      "x": -10,
      "y": 11,
      "z": -8,
      "name": "Soil_Clay_Green"
    },
    {
      "x": -10,
      "y": 12,
      "z": -8,
      "name": "Soil_Clay_Green"
    },
    {
      "x": -10,
      "y": 13,
      "z": -8,
      "name": "Soil_Seaweed_Block"
    },
    {
      "x": -10,
      "y": 21,
      "z": -8,
      "name": "Soil_Clay_Green"
    },
    {
      "x": -10,
      "y": 22,
      "z": -8,
      "name": "Soil_Clay_Lime"
    },
    {
      "x": -10,
      "y": 23,
      "z": -8,
      "name": "Plant_Grass_Sharp"
    },
    {
      "x": -10,
      "y": 28,
      "z": -4,
      "name": "Soil_Clay_Green"
    },
    {
      "x": -10,
      "y": 5,
      "z": -3,
      "name": "Soil_Clay_Green"
    },
    {
      "x": -10,
      "y": 27,
      "z": -3,
      "name": "Soil_Clay_Green"
    },
    {
      "x": -10,
      "y": 28,
      "z": -3,
      "name": "Soil_Clay_Lime"
    },
    {
      "x": -10,
      "y": 29,
      "z": -3,
      "name": "Plant_Grass_Sharp"
    },
    {
      "x": -10,
      "y": 5,
      "z": -2,
      "name": "Soil_Clay_Green"
    },
    {
      "x": -10,
      "y": 6,
      "z": -2,
      "name": "Soil_Clay_Green"
    },
    {
      "x": -10,
      "y": 7,
      "z": -2,
      "name": "Soil_Seaweed_Block"
    },
    {
      "x": -10,
      "y": 5,
      "z": -1,
      "name": "Soil_Clay_Green"
    },
    {
      "x": -10,
      "y": 6,
      "z": -1,
      "name": "Soil_Clay_Green"
    },
    {
      "x": -10,
      "y": 7,
      "z": -1,
      "name": "Soil_Seaweed_Block"
    },
    {
      "x": -10,
      "y": 5,
      "z": 0,
      "name": "Soil_Clay_Green"
    },
    {
      "x": -10,
      "y": 6,
      "z": 0,
      "name": "Soil_Seaweed_Block"
    },
    {
      "x": -10,
      "y": 7,
      "z": 0,
      "name": "Soil_Seaweed_Block"
    },
    {
      "x": -10,
      "y": 8,
      "z": 0,
      "name": "Soil_Clay_Lime"
    },
    {
      "x": -10,
      "y": 9,
      "z": 0,
      "name": "Plant_Grass_Sharp"
    },
    {
      "x": -10,
      "y": 5,
      "z": 1,
      "name": "Soil_Clay_Green"
    },
    {
      "x": -10,
      "y": 6,
      "z": 1,
      "name": "Soil_Clay_Green"
    },
    {
      "x": -10,
      "y": 7,
      "z": 1,
      "name": "Soil_Seaweed_Block"
    },
    {
      "x": -10,
      "y": 8,
      "z": 1,
      "name": "Soil_Clay_Lime"
    },
    {
      "x": -10,
      "y": 9,
      "z": 1,
      "name": "Plant_Grass_Sharp"
    },
    {
      "x": -10,
      "y": 5,
      "z": 2,
      "name": "Soil_Clay_Green"
    },
    {
      "x": -10,
      "y": 6,
      "z": 2,
      "name": "Soil_Seaweed_Block"
    },
    {
      "x": -10,
      "y": 7,
      "z": 2,
      "name": "Soil_Seaweed_Block"
    },
    {
      "x": -10,
      "y": 8,
      "z": 2,
      "name": "Soil_Seaweed_Block"
    },
    {
      "x": -10,
      "y": 10,
      "z": 2,
      "name": "Plant_Grass_Sharp"
    },
    {
      "x": -10,
      "y": 4,
      "z": 3,
      "name": "Soil_Clay_Green"
    },
    {
      "x": -10,
      "y": 5,
      "z": 3,
      "name": "Soil_Clay_Green"
    },
    {
      "x": -10,
      "y": 6,
      "z": 3,
      "name": "Soil_Seaweed_Block"
    },
    {
      "x": -10,
      "y": 7,
      "z": 3,
      "name": "Soil_Clay_Green"
    },
    {
      "x": -10,
      "y": 8,
      "z": 3,
      "name": "Soil_Seaweed_Block"
    },
    {
      "x": -10,
      "y": 26,
      "z": 3,
      "name": "Soil_Clay_Green"
    },
    {
      "x": -10,
      "y": 27,
      "z": 3,
      "name": "Soil_Seaweed_Block"
    },
    {
      "x": -10,
      "y": 4,
      "z": 4,
      "name": "Soil_Clay_Green"
    },
    {
      "x": -10,
      "y": 5,
      "z": 4,
      "name": "Soil_Clay_Green"
    },
    {
      "x": -10,
      "y": 6,
      "z": 4,
      "name": "Soil_Clay_Green"
    },
    {
      "x": -10,
      "y": 7,
      "z": 4,
      "name": "Soil_Clay_Green"
    },
    {
      "x": -10,
      "y": 8,
      "z": 4,
      "name": "Soil_Seaweed_Block"
    },
    {
      "x": -10,
      "y": 26,
      "z": 4,
      "name": "Soil_Clay_Green"
    },
    {
      "x": -10,
      "y": 27,
      "z": 4,
      "name": "Soil_Seaweed_Block"
    },
    {
      "x": -10,
      "y": 5,
      "z": 5,
      "name": "Soil_Clay_Green"
    },
    {
      "x": -10,
      "y": 6,
      "z": 5,
      "name": "Soil_Clay_Green"
    },
    {
      "x": -10,
      "y": 7,
      "z": 5,
      "name": "Soil_Seaweed_Block"
    },
    {
      "x": -10,
      "y": 8,
      "z": 5,
      "name": "Soil_Seaweed_Block"
    },
    {
      "x": -10,
      "y": 9,
      "z": 5,
      "name": "Soil_Seaweed_Block"
    },
    {
      "x": -10,
      "y": 10,
      "z": 5,
      "name": "Soil_Clay_Lime"
    },
    {
      "x": -10,
      "y": 11,
      "z": 5,
      "name": "Plant_Grass_Sharp"
    },
    {
      "x": -10,
      "y": 25,
      "z": 5,
      "name": "Soil_Clay_Green"
    },
    {
      "x": -10,
      "y": 26,
      "z": 5,
      "name": "Soil_Seaweed_Block"
    },
    {
      "x": -10,
      "y": 27,
      "z": 5,
      "name": "Soil_Seaweed_Block"
    },
    {
      "x": -10,
      "y": 28,
      "z": 5,
      "name": "Soil_Clay_Lime"
    },
    {
      "x": -10,
      "y": 29,
      "z": 5,
      "name": "Plant_Grass_Sharp"
    },
    {
      "x": -10,
      "y": 7,
      "z": 6,
      "name": "Soil_Clay_Green"
    },
    {
      "x": -10,
      "y": 8,
      "z": 6,
      "name": "Soil_Seaweed_Block"
    },
    {
      "x": -10,
      "y": 9,
      "z": 6,
      "name": "Soil_Seaweed_Block"
    },
    {
      "x": -10,
      "y": 10,
      "z": 6,
      "name": "Soil_Clay_Lime"
    },
    {
      "x": -10,
      "y": 11,
      "z": 6,
      "name": "Plant_Grass_Sharp"
    },
    {
      "x": -10,
      "y": 24,
      "z": 6,
      "name": "Soil_Clay_Green"
    },
    {
      "x": -10,
      "y": 25,
      "z": 6,
      "name": "Soil_Clay_Green"
    },
    {
      "x": -10,
      "y": 26,
      "z": 6,
      "name": "Soil_Seaweed_Block"
    },
    {
      "x": -10,
      "y": 27,
      "z": 6,
      "name": "Soil_Seaweed_Block"
    },
    {
      "x": -10,
      "y": 28,
      "z": 6,
      "name": "Soil_Clay_Lime"
    },
    {
      "x": -10,
      "y": 29,
      "z": 6,
      "name": "Plant_Grass_Sharp"
    },
    {
      "x": -10,
      "y": 7,
      "z": 7,
      "name": "Soil_Clay_Green"
    },
    {
      "x": -10,
      "y": 8,
      "z": 7,
      "name": "Soil_Seaweed_Block"
    },
    {
      "x": -10,
      "y": 9,
      "z": 7,
      "name": "Soil_Seaweed_Block"
    },
    {
      "x": -10,
      "y": 10,
      "z": 7,
      "name": "Plant_Grass_Sharp"
    },
    {
      "x": -10,
      "y": 26,
      "z": 7,
      "name": "Soil_Clay_Green"
    },
    {
      "x": -10,
      "y": 27,
      "z": 7,
      "name": "Soil_Seaweed_Block"
    },
    {
      "x": -10,
      "y": 8,
      "z": 8,
      "name": "Soil_Clay_Green"
    },
    {
      "x": -10,
      "y": 9,
      "z": 8,
      "name": "Soil_Seaweed_Block"
    },
    {
      "x": -10,
      "y": 8,
      "z": 9,
      "name": "Soil_Clay_Green"
    },
    {
      "x": -10,
      "y": 9,
      "z": 9,
      "name": "Soil_Seaweed_Block"
    },
    {
      "x": -10,
      "y": 18,
      "z": 10,
      "name": "Soil_Clay_Green"
    },
    {
      "x": -10,
      "y": 19,
      "z": 10,
      "name": "Soil_Seaweed_Block"
    },
    {
      "x": -10,
      "y": 17,
      "z": 11,
      "name": "Soil_Clay_Green"
    },
    {
      "x": -10,
      "y": 18,
      "z": 11,
      "name": "Soil_Seaweed_Block"
    },
    {
      "x": -10,
      "y": 19,
      "z": 11,
      "name": "Soil_Seaweed_Block"
    },
    {
      "x": -10,
      "y": 20,
      "z": 11,
      "name": "Soil_Seaweed_Block"
    },
    {
      "x": -10,
      "y": 21,
      "z": 11,
      "name": "Soil_Clay_Lime"
    },
    {
      "x": -10,
      "y": 22,
      "z": 11,
      "name": "Plant_Grass_Sharp"
    },
    {
      "x": -10,
      "y": 17,
      "z": 12,
      "name": "Soil_Clay_Green"
    },
    {
      "x": -10,
      "y": 18,
      "z": 12,
      "name": "Soil_Seaweed_Block"
    },
    {
      "x": -10,
      "y": 19,
      "z": 12,
      "name": "Soil_Seaweed_Block"
    },
    {
      "x": -10,
      "y": 20,
      "z": 12,
      "name": "Soil_Seaweed_Block"
    },
    {
      "x": -10,
      "y": 21,
      "z": 12,
      "name": "Soil_Clay_Lime"
    },
    {
      "x": -10,
      "y": 22,
      "z": 12,
      "name": "Plant_Grass_Sharp"
    },
    {
      "x": -10,
      "y": 18,
      "z": 13,
      "name": "Soil_Clay_Green"
    },
    {
      "x": -10,
      "y": 19,
      "z": 13,
      "name": "Soil_Clay_Green"
    },
    {
      "x": -10,
      "y": 20,
      "z": 13,
      "name": "Soil_Seaweed_Block"
    },
    {
      "x": -10,
      "y": 18,
      "z": 14,
      "name": "Soil_Clay_Green"
    },
    {
      "x": -10,
      "y": 19,
      "z": 14,
      "name": "Soil_Clay_Green"
    },
    {
      "x": -10,
      "y": 20,
      "z": 14,
      "name": "Soil_Seaweed_Block"
    },
    {
      "x": -9,
      "y": 13,
      "z": -13,
      "name": "Soil_Clay_Green"
    },
    {
      "x": -9,
      "y": 14,
      "z": -13,
      "name": "Soil_Seaweed_Block"
    },
    {
      "x": -9,
      "y": 15,
      "z": -13,
      "name": "Soil_Seaweed_Block"
    },
    {
      "x": -9,
      "y": 20,
      "z": -13,
      "name": "Soil_Clay_Green"
    },
    {
      "x": -9,
      "y": 21,
      "z": -13,
      "name": "Soil_Clay_Green"
    },
    {
      "x": -9,
      "y": 22,
      "z": -13,
      "name": "Soil_Seaweed_Block"
    },
    {
      "x": -9,
      "y": 13,
      "z": -12,
      "name": "Soil_Clay_Green"
    },
    {
      "x": -9,
      "y": 14,
      "z": -12,
      "name": "Soil_Seaweed_Block"
    },
    {
      "x": -9,
      "y": 15,
      "z": -12,
      "name": "Soil_Clay_Lime"
    },
    {
      "x": -9,
      "y": 16,
      "z": -12,
      "name": "Soil_Clay_Lime"
    },
    {
      "x": -9,
      "y": 17,
      "z": -12,
      "name": "Plant_Grass_Sharp"
    },
    {
      "x": -9,
      "y": 19,
      "z": -12,
      "name": "Soil_Clay_Green"
    },
    {
      "x": -9,
      "y": 20,
      "z": -12,
      "name": "Soil_Clay_Green"
    },
    {
      "x": -9,
      "y": 21,
      "z": -12,
      "name": "Soil_Clay_Green"
    },
    {
      "x": -9,
      "y": 22,
      "z": -12,
      "name": "Soil_Seaweed_Block"
    },
    {
      "x": -9,
      "y": 12,
      "z": -11,
      "name": "Soil_Clay_Green"
    },
    {
      "x": -9,
      "y": 13,
      "z": -11,
      "name": "Soil_Seaweed_Block"
    },
    {
      "x": -9,
      "y": 14,
      "z": -11,
      "name": "Soil_Seaweed_Block"
    },
    {
      "x": -9,
      "y": 15,
      "z": -11,
      "name": "Soil_Seaweed_Block"
    },
    {
      "x": -9,
      "y": 16,
      "z": -11,
      "name": "Soil_Clay_Lime"
    },
    {
      "x": -9,
      "y": 17,
      "z": -11,
      "name": "Plant_Grass_Sharp"
    },
    {
      "x": -9,
      "y": 19,
      "z": -11,
      "name": "Soil_Clay_Green"
    },
    {
      "x": -9,
      "y": 20,
      "z": -11,
      "name": "Soil_Clay_Green"
    },
    {
      "x": -9,
      "y": 21,
      "z": -11,
      "name": "Soil_Seaweed_Block"
    },
    {
      "x": -9,
      "y": 22,
      "z": -11,
      "name": "Soil_Seaweed_Block"
    },
    {
      "x": -9,
      "y": 23,
      "z": -11,
      "name": "Soil_Clay_Lime"
    },
    {
      "x": -9,
      "y": 24,
      "z": -11,
      "name": "Plant_Grass_Sharp"
    },
    {
      "x": -9,
      "y": 12,
      "z": -10,
      "name": "Soil_Clay_Green"
    },
    {
      "x": -9,
      "y": 13,
      "z": -10,
      "name": "Soil_Seaweed_Block"
    },
    {
      "x": -9,
      "y": 14,
      "z": -10,
      "name": "Soil_Seaweed_Block"
    },
    {
      "x": -9,
      "y": 15,
      "z": -10,
      "name": "Soil_Clay_Lime"
    },
    {
      "x": -9,
      "y": 16,
      "z": -10,
      "name": "Soil_Clay_Lime"
    },
    {
      "x": -9,
      "y": 17,
      "z": -10,
      "name": "Plant_Grass_Sharp"
    },
    {
      "x": -9,
      "y": 20,
      "z": -10,
      "name": "Soil_Clay_Green"
    },
    {
      "x": -9,
      "y": 21,
      "z": -10,
      "name": "Soil_Seaweed_Block"
    },
    {
      "x": -9,
      "y": 22,
      "z": -10,
      "name": "Soil_Seaweed_Block"
    },
    {
      "x": -9,
      "y": 23,
      "z": -10,
      "name": "Soil_Clay_Lime"
    },
    {
      "x": -9,
      "y": 24,
      "z": -10,
      "name": "Plant_Grass_Sharp"
    },
    {
      "x": -9,
      "y": 13,
      "z": -9,
      "name": "Soil_Clay_Green"
    },
    {
      "x": -9,
      "y": 14,
      "z": -9,
      "name": "Soil_Seaweed_Block"
    },
    {
      "x": -9,
      "y": 21,
      "z": -9,
      "name": "Soil_Clay_Green"
    },
    {
      "x": -9,
      "y": 22,
      "z": -9,
      "name": "Soil_Seaweed_Block"
    },
    {
      "x": -9,
      "y": 28,
      "z": -5,
      "name": "Soil_Clay_Green"
    },
    {
      "x": -9,
      "y": 28,
      "z": -4,
      "name": "Soil_Clay_Green"
    },
    {
      "x": -9,
      "y": 29,
      "z": -4,
      "name": "Soil_Clay_Lime"
    },
    {
      "x": -9,
      "y": 30,
      "z": -4,
      "name": "Plant_Grass_Sharp"
    },
    {
      "x": -9,
      "y": 4,
      "z": -3,
      "name": "Soil_Seaweed_Block"
    },
    {
      "x": -9,
      "y": 4,
      "z": -2,
      "name": "Soil_Clay_Green"
    },
    {
      "x": -9,
      "y": 5,
      "z": -2,
      "name": "Soil_Clay_Green"
    },
    {
      "x": -9,
      "y": 6,
      "z": 1,
      "name": "Soil_Clay_Green"
    },
    {
      "x": -9,
      "y": 7,
      "z": 1,
      "name": "Soil_Seaweed_Block"
    },
    {
      "x": -9,
      "y": 6,
      "z": 2,
      "name": "Soil_Clay_Green"
    },
    {
      "x": -9,
      "y": 7,
      "z": 2,
      "name": "Soil_Seaweed_Block"
    },
    {
      "x": -9,
      "y": 6,
      "z": 3,
      "name": "Soil_Clay_Green"
    },
    {
      "x": -9,
      "y": 3,
      "z": 4,
      "name": "Soil_Clay_Green"
    },
    {
      "x": -9,
      "y": 4,
      "z": 4,
      "name": "Soil_Clay_Green"
    },
    {
      "x": -9,
      "y": 5,
      "z": 4,
      "name": "Soil_Clay_Green"
    },
    {
      "x": -9,
      "y": 6,
      "z": 4,
      "name": "Soil_Clay_Green"
    },
    {
      "x": -9,
      "y": 7,
      "z": 4,
      "name": "Soil_Clay_Green"
    },
    {
      "x": -9,
      "y": 8,
      "z": 4,
      "name": "Soil_Seaweed_Block"
    },
    {
      "x": -9,
      "y": 26,
      "z": 4,
      "name": "Soil_Clay_Green"
    },
    {
      "x": -9,
      "y": 27,
      "z": 4,
      "name": "Soil_Seaweed_Block"
    },
    {
      "x": -9,
      "y": 3,
      "z": 5,
      "name": "Soil_Clay_Green"
    },
    {
      "x": -9,
      "y": 4,
      "z": 5,
      "name": "Soil_Clay_Green"
    },
    {
      "x": -9,
      "y": 5,
      "z": 5,
      "name": "Soil_Clay_Green"
    },
    {
      "x": -9,
      "y": 26,
      "z": 5,
      "name": "Soil_Clay_Green"
    },
    {
      "x": -9,
      "y": 27,
      "z": 5,
      "name": "Soil_Seaweed_Block"
    },
    {
      "x": -9,
      "y": 8,
      "z": 6,
      "name": "Soil_Clay_Green"
    },
    {
      "x": -9,
      "y": 26,
      "z": 6,
      "name": "Soil_Clay_Green"
    },
    {
      "x": -9,
      "y": 27,
      "z": 6,
      "name": "Soil_Seaweed_Block"
    },
    {
      "x": -9,
      "y": 8,
      "z": 7,
      "name": "Soil_Clay_Green"
    },
    {
      "x": -9,
      "y": 26,
      "z": 7,
      "name": "Soil_Clay_Green"
    },
    {
      "x": -9,
      "y": 27,
      "z": 7,
      "name": "Soil_Seaweed_Block"
    },
    {
      "x": -9,
      "y": 8,
      "z": 8,
      "name": "Soil_Clay_Green"
    },
    {
      "x": -9,
      "y": 9,
      "z": 8,
      "name": "Soil_Clay_Lime"
    },
    {
      "x": -9,
      "y": 10,
      "z": 8,
      "name": "Plant_Grass_Sharp"
    },
    {
      "x": -9,
      "y": 8,
      "z": 9,
      "name": "Soil_Clay_Green"
    },
    {
      "x": -9,
      "y": 9,
      "z": 9,
      "name": "Soil_Seaweed_Block"
    },
    {
      "x": -9,
      "y": 9,
      "z": 10,
      "name": "Soil_Clay_Green"
    },
    {
      "x": -9,
      "y": 18,
      "z": 11,
      "name": "Soil_Clay_Green"
    },
    {
      "x": -9,
      "y": 19,
      "z": 11,
      "name": "Soil_Seaweed_Block"
    },
    {
      "x": -9,
      "y": 20,
      "z": 11,
      "name": "Soil_Seaweed_Block"
    },
    {
      "x": -9,
      "y": 21,
      "z": 11,
      "name": "Soil_Seaweed_Block"
    },
    {
      "x": -9,
      "y": 22,
      "z": 11,
      "name": "Soil_Clay_Lime"
    },
    {
      "x": -9,
      "y": 23,
      "z": 11,
      "name": "Plant_Grass_Sharp"
    },
    {
      "x": -9,
      "y": 18,
      "z": 12,
      "name": "Soil_Clay_Green"
    },
    {
      "x": -9,
      "y": 19,
      "z": 12,
      "name": "Soil_Seaweed_Block"
    },
    {
      "x": -9,
      "y": 20,
      "z": 12,
      "name": "Soil_Seaweed_Block"
    },
    {
      "x": -9,
      "y": 21,
      "z": 12,
      "name": "Soil_Seaweed_Block"
    },
    {
      "x": -9,
      "y": 22,
      "z": 12,
      "name": "Soil_Clay_Lime"
    },
    {
      "x": -9,
      "y": 23,
      "z": 12,
      "name": "Plant_Grass_Sharp"
    },
    {
      "x": -9,
      "y": 18,
      "z": 13,
      "name": "Soil_Clay_Green"
    },
    {
      "x": -9,
      "y": 19,
      "z": 13,
      "name": "Soil_Seaweed_Block"
    },
    {
      "x": -9,
      "y": 20,
      "z": 13,
      "name": "Soil_Seaweed_Block"
    },
    {
      "x": -9,
      "y": 21,
      "z": 13,
      "name": "Soil_Clay_Lime"
    },
    {
      "x": -9,
      "y": 22,
      "z": 13,
      "name": "Plant_Grass_Sharp"
    },
    {
      "x": -9,
      "y": 18,
      "z": 14,
      "name": "Soil_Clay_Green"
    },
    {
      "x": -9,
      "y": 19,
      "z": 14,
      "name": "Soil_Clay_Green"
    },
    {
      "x": -9,
      "y": 20,
      "z": 14,
      "name": "Soil_Seaweed_Block"
    },
    {
      "x": -8,
      "y": 13,
      "z": -13,
      "name": "Soil_Clay_Green"
    },
    {
      "x": -8,
      "y": 14,
      "z": -13,
      "name": "Soil_Seaweed_Block"
    },
    {
      "x": -8,
      "y": 20,
      "z": -13,
      "name": "Soil_Clay_Green"
    },
    {
      "x": -8,
      "y": 21,
      "z": -13,
      "name": "Soil_Clay_Green"
    },
    {
      "x": -8,
      "y": 22,
      "z": -13,
      "name": "Soil_Seaweed_Block"
    },
    {
      "x": -8,
      "y": 12,
      "z": -12,
      "name": "Soil_Clay_Green"
    },
    {
      "x": -8,
      "y": 13,
      "z": -12,
      "name": "Soil_Seaweed_Block"
    },
    {
      "x": -8,
      "y": 14,
      "z": -12,
      "name": "Soil_Seaweed_Block"
    },
    {
      "x": -8,
      "y": 15,
      "z": -12,
      "name": "Soil_Clay_Lime"
    },
    {
      "x": -8,
      "y": 16,
      "z": -12,
      "name": "Soil_Clay_Lime"
    },
    {
      "x": -8,
      "y": 17,
      "z": -12,
      "name": "Soil_Seaweed_Block"
    },
    {
      "x": -8,
      "y": 18,
      "z": -12,
      "name": "Soil_Clay_Green"
    },
    {
      "x": -8,
      "y": 19,
      "z": -12,
      "name": "Soil_Clay_Green"
    },
    {
      "x": -8,
      "y": 20,
      "z": -12,
      "name": "Soil_Seaweed_Block"
    },
    {
      "x": -8,
      "y": 21,
      "z": -12,
      "name": "Soil_Seaweed_Block"
    },
    {
      "x": -8,
      "y": 22,
      "z": -12,
      "name": "Soil_Seaweed_Block"
    },
    {
      "x": -8,
      "y": 23,
      "z": -12,
      "name": "Soil_Clay_Lime"
    },
    {
      "x": -8,
      "y": 24,
      "z": -12,
      "name": "Plant_Grass_Sharp"
    },
    {
      "x": -8,
      "y": 12,
      "z": -11,
      "name": "Soil_Clay_Green"
    },
    {
      "x": -8,
      "y": 13,
      "z": -11,
      "name": "Soil_Seaweed_Block"
    },
    {
      "x": -8,
      "y": 14,
      "z": -11,
      "name": "Soil_Seaweed_Block"
    },
    {
      "x": -8,
      "y": 15,
      "z": -11,
      "name": "Soil_Clay_Lime"
    },
    {
      "x": -8,
      "y": 16,
      "z": -11,
      "name": "Soil_Clay_Lime"
    },
    {
      "x": -8,
      "y": 17,
      "z": -11,
      "name": "Plant_Grass_Sharp"
    },
    {
      "x": -8,
      "y": 19,
      "z": -11,
      "name": "Soil_Clay_Green"
    },
    {
      "x": -8,
      "y": 20,
      "z": -11,
      "name": "Soil_Clay_Green"
    },
    {
      "x": -8,
      "y": 21,
      "z": -11,
      "name": "Soil_Seaweed_Block"
    },
    {
      "x": -8,
      "y": 22,
      "z": -11,
      "name": "Soil_Seaweed_Block"
    },
    {
      "x": -8,
      "y": 23,
      "z": -11,
      "name": "Soil_Seaweed_Block"
    },
    {
      "x": -8,
      "y": 24,
      "z": -11,
      "name": "Soil_Clay_Lime"
    },
    {
      "x": -8,
      "y": 25,
      "z": -11,
      "name": "Plant_Grass_Sharp"
    },
    {
      "x": -8,
      "y": 13,
      "z": -10,
      "name": "Soil_Clay_Green"
    },
    {
      "x": -8,
      "y": 14,
      "z": -10,
      "name": "Soil_Seaweed_Block"
    },
    {
      "x": -8,
      "y": 21,
      "z": -10,
      "name": "Soil_Clay_Green"
    },
    {
      "x": -8,
      "y": 22,
      "z": -10,
      "name": "Soil_Seaweed_Block"
    },
    {
      "x": -8,
      "y": 23,
      "z": -10,
      "name": "Soil_Clay_Lime"
    },
    {
      "x": -8,
      "y": 24,
      "z": -10,
      "name": "Soil_Clay_Lime"
    },
    {
      "x": -8,
      "y": 25,
      "z": -10,
      "name": "Plant_Grass_Sharp"
    },
    {
      "x": -8,
      "y": 13,
      "z": -9,
      "name": "Soil_Clay_Green"
    },
    {
      "x": -8,
      "y": 14,
      "z": -9,
      "name": "Soil_Seaweed_Block"
    },
    {
      "x": -8,
      "y": 21,
      "z": -9,
      "name": "Soil_Clay_Green"
    },
    {
      "x": -8,
      "y": 22,
      "z": -9,
      "name": "Soil_Seaweed_Block"
    },
    {
      "x": -8,
      "y": 29,
      "z": -5,
      "name": "Soil_Clay_Green"
    },
    {
      "x": -8,
      "y": 31,
      "z": -5,
      "name": "Plant_Grass_Sharp"
    },
    {
      "x": -8,
      "y": 1,
      "z": -4,
      "name": "Soil_Clay_Green"
    },
    {
      "x": -8,
      "y": 2,
      "z": -4,
      "name": "Soil_Seaweed_Block"
    },
    {
      "x": -8,
      "y": 3,
      "z": -4,
      "name": "Soil_Seaweed_Block"
    },
    {
      "x": -8,
      "y": 29,
      "z": -4,
      "name": "Soil_Clay_Green"
    },
    {
      "x": -8,
      "y": 30,
      "z": -4,
      "name": "Soil_Clay_Lime"
    },
    {
      "x": -8,
      "y": 31,
      "z": -4,
      "name": "Plant_Grass_Sharp"
    },
    {
      "x": -8,
      "y": 1,
      "z": -3,
      "name": "Soil_Clay_Green"
    },
    {
      "x": -8,
      "y": 2,
      "z": -3,
      "name": "Soil_Clay_Green"
    },
    {
      "x": -8,
      "y": 3,
      "z": -3,
      "name": "Soil_Clay_Lime"
    },
    {
      "x": -8,
      "y": 4,
      "z": -3,
      "name": "Plant_Grass_Sharp"
    },
    {
      "x": -8,
      "y": 29,
      "z": -3,
      "name": "Soil_Clay_Green"
    },
    {
      "x": -8,
      "y": 30,
      "z": -3,
      "name": "Soil_Clay_Lime"
    },
    {
      "x": -8,
      "y": 31,
      "z": -3,
      "name": "Plant_Grass_Sharp"
    },
    {
      "x": -8,
      "y": 2,
      "z": 4,
      "name": "Soil_Clay_Green"
    },
    {
      "x": -8,
      "y": 2,
      "z": 5,
      "name": "Soil_Clay_Green"
    },
    {
      "x": -8,
      "y": 3,
      "z": 5,
      "name": "Soil_Clay_Green"
    },
    {
      "x": -8,
      "y": 27,
      "z": 7,
      "name": "Soil_Seaweed_Block"
    },
    {
      "x": -8,
      "y": 27,
      "z": 8,
      "name": "Soil_Clay_Green"
    },
    {
      "x": -8,
      "y": 9,
      "z": 9,
      "name": "Soil_Clay_Green"
    },
    {
      "x": -8,
      "y": 9,
      "z": 10,
      "name": "Soil_Clay_Green"
    },
    {
      "x": -8,
      "y": 9,
      "z": 11,
      "name": "Soil_Clay_Green"
    },
    {
      "x": -8,
      "y": 10,
      "z": 11,
      "name": "Soil_Seaweed_Block"
    },
    {
      "x": -8,
      "y": 11,
      "z": 11,
      "name": "Soil_Clay_Lime"
    },
    {
      "x": -8,
      "y": 12,
      "z": 11,
      "name": "Plant_Grass_Sharp"
    },
    {
      "x": -8,
      "y": 18,
      "z": 11,
      "name": "Soil_Clay_Green"
    },
    {
      "x": -8,
      "y": 19,
      "z": 11,
      "name": "Soil_Clay_Green"
    },
    {
      "x": -8,
      "y": 20,
      "z": 11,
      "name": "Soil_Seaweed_Block"
    },
    {
      "x": -8,
      "y": 21,
      "z": 11,
      "name": "Soil_Clay_Lime"
    },
    {
      "x": -8,
      "y": 22,
      "z": 11,
      "name": "Plant_Grass_Sharp"
    },
    {
      "x": -8,
      "y": 10,
      "z": 12,
      "name": "Soil_Clay_Green"
    },
    {
      "x": -8,
      "y": 11,
      "z": 12,
      "name": "Soil_Clay_Lime"
    },
    {
      "x": -8,
      "y": 12,
      "z": 12,
      "name": "Plant_Grass_Sharp"
    },
    {
      "x": -8,
      "y": 18,
      "z": 12,
      "name": "Soil_Clay_Green"
    },
    {
      "x": -8,
      "y": 19,
      "z": 12,
      "name": "Soil_Seaweed_Block"
    },
    {
      "x": -8,
      "y": 20,
      "z": 12,
      "name": "Soil_Seaweed_Block"
    },
    {
      "x": -8,
      "y": 21,
      "z": 12,
      "name": "Soil_Seaweed_Block"
    },
    {
      "x": -8,
      "y": 22,
      "z": 12,
      "name": "Soil_Clay_Lime"
    },
    {
      "x": -8,
      "y": 23,
      "z": 12,
      "name": "Soil_Clay_Lime"
    },
    {
      "x": -8,
      "y": 24,
      "z": 12,
      "name": "Plant_Grass_Sharp"
    },
    {
      "x": -8,
      "y": 10,
      "z": 13,
      "name": "Soil_Clay_Green"
    },
    {
      "x": -8,
      "y": 18,
      "z": 13,
      "name": "Soil_Clay_Green"
    },
    {
      "x": -8,
      "y": 19,
      "z": 13,
      "name": "Soil_Seaweed_Block"
    },
    {
      "x": -8,
      "y": 20,
      "z": 13,
      "name": "Soil_Seaweed_Block"
    },
    {
      "x": -8,
      "y": 21,
      "z": 13,
      "name": "Soil_Clay_Lime"
    },
    {
      "x": -8,
      "y": 22,
      "z": 13,
      "name": "Plant_Grass_Sharp"
    },
    {
      "x": -8,
      "y": 18,
      "z": 14,
      "name": "Soil_Clay_Green"
    },
    {
      "x": -8,
      "y": 19,
      "z": 14,
      "name": "Soil_Clay_Green"
    },
    {
      "x": -8,
      "y": 20,
      "z": 14,
      "name": "Soil_Seaweed_Block"
    },
    {
      "x": -7,
      "y": 22,
      "z": -13,
      "name": "Soil_Seaweed_Block"
    },
    {
      "x": -7,
      "y": 12,
      "z": -12,
      "name": "Soil_Clay_Green"
    },
    {
      "x": -7,
      "y": 13,
      "z": -12,
      "name": "Soil_Seaweed_Block"
    },
    {
      "x": -7,
      "y": 14,
      "z": -12,
      "name": "Soil_Seaweed_Block"
    },
    {
      "x": -7,
      "y": 20,
      "z": -12,
      "name": "Soil_Clay_Green"
    },
    {
      "x": -7,
      "y": 21,
      "z": -12,
      "name": "Soil_Seaweed_Block"
    },
    {
      "x": -7,
      "y": 22,
      "z": -12,
      "name": "Soil_Seaweed_Block"
    },
    {
      "x": -7,
      "y": 23,
      "z": -12,
      "name": "Soil_Seaweed_Block"
    },
    {
      "x": -7,
      "y": 24,
      "z": -12,
      "name": "Soil_Clay_Lime"
    },
    {
      "x": -7,
      "y": 25,
      "z": -12,
      "name": "Plant_Grass_Sharp"
    },
    {
      "x": -7,
      "y": 12,
      "z": -11,
      "name": "Soil_Clay_Green"
    },
    {
      "x": -7,
      "y": 13,
      "z": -11,
      "name": "Soil_Seaweed_Block"
    },
    {
      "x": -7,
      "y": 14,
      "z": -11,
      "name": "Soil_Seaweed_Block"
    },
    {
      "x": -7,
      "y": 20,
      "z": -11,
      "name": "Soil_Clay_Green"
    },
    {
      "x": -7,
      "y": 21,
      "z": -11,
      "name": "Soil_Seaweed_Block"
    },
    {
      "x": -7,
      "y": 22,
      "z": -11,
      "name": "Soil_Seaweed_Block"
    },
    {
      "x": -7,
      "y": 23,
      "z": -11,
      "name": "Soil_Seaweed_Block"
    },
    {
      "x": -7,
      "y": 24,
      "z": -11,
      "name": "Soil_Clay_Lime"
    },
    {
      "x": -7,
      "y": 25,
      "z": -11,
      "name": "Plant_Grass_Sharp"
    },
    {
      "x": -7,
      "y": 13,
      "z": -10,
      "name": "Soil_Clay_Green"
    },
    {
      "x": -7,
      "y": 14,
      "z": -10,
      "name": "Soil_Seaweed_Block"
    },
    {
      "x": -7,
      "y": 21,
      "z": -10,
      "name": "Soil_Clay_Green"
    },
    {
      "x": -7,
      "y": 22,
      "z": -10,
      "name": "Soil_Seaweed_Block"
    },
    {
      "x": -7,
      "y": 23,
      "z": -10,
      "name": "Soil_Seaweed_Block"
    },
    {
      "x": -7,
      "y": 24,
      "z": -10,
      "name": "Soil_Clay_Lime"
    },
    {
      "x": -7,
      "y": 25,
      "z": -10,
      "name": "Soil_Clay_Lime"
    },
    {
      "x": -7,
      "y": 30,
      "z": -9,
      "name": "Soil_Seaweed_Block"
    },
    {
      "x": -7,
      "y": 28,
      "z": -8,
      "name": "Soil_Clay_Green"
    },
    {
      "x": -7,
      "y": 29,
      "z": -8,
      "name": "Soil_Clay_Green"
    },
    {
      "x": -7,
      "y": 30,
      "z": -8,
      "name": "Soil_Seaweed_Block"
    },
    {
      "x": -7,
      "y": 31,
      "z": -8,
      "name": "Soil_Clay_Lime"
    },
    {
      "x": -7,
      "y": 32,
      "z": -8,
      "name": "Plant_Grass_Sharp"
    },
    {
      "x": -7,
      "y": 28,
      "z": -7,
      "name": "Soil_Clay_Green"
    },
    {
      "x": -7,
      "y": 29,
      "z": -7,
      "name": "Soil_Clay_Green"
    },
    {
      "x": -7,
      "y": 30,
      "z": -7,
      "name": "Soil_Seaweed_Block"
    },
    {
      "x": -7,
      "y": 31,
      "z": -7,
      "name": "Soil_Clay_Lime"
    },
    {
      "x": -7,
      "y": 32,
      "z": -7,
      "name": "Plant_Grass_Sharp"
    },
    {
      "x": -7,
      "y": 28,
      "z": -6,
      "name": "Soil_Clay_Green"
    },
    {
      "x": -7,
      "y": 29,
      "z": -6,
      "name": "Soil_Seaweed_Block"
    },
    {
      "x": -7,
      "y": 30,
      "z": -6,
      "name": "Soil_Seaweed_Block"
    },
    {
      "x": -7,
      "y": 31,
      "z": -6,
      "name": "Soil_Clay_Lime"
    },
    {
      "x": -7,
      "y": 32,
      "z": -6,
      "name": "Plant_Grass_Sharp"
    },
    {
      "x": -7,
      "y": 1,
      "z": -5,
      "name": "Soil_Clay_Green"
    },
    {
      "x": -7,
      "y": 2,
      "z": -5,
      "name": "Soil_Seaweed_Block"
    },
    {
      "x": -7,
      "y": 29,
      "z": -5,
      "name": "Soil_Clay_Green"
    },
    {
      "x": -7,
      "y": 30,
      "z": -5,
      "name": "Soil_Clay_Lime"
    },
    {
      "x": -7,
      "y": 31,
      "z": -5,
      "name": "Plant_Grass_Sharp"
    },
    {
      "x": -7,
      "y": 32,
      "z": -5,
      "name": "Plant_Grass_Sharp"
    },
    {
      "x": -7,
      "y": 0,
      "z": -4,
      "name": "Soil_Clay_Green"
    },
    {
      "x": -7,
      "y": 1,
      "z": -4,
      "name": "Soil_Seaweed_Block"
    },
    {
      "x": -7,
      "y": 2,
      "z": -4,
      "name": "Soil_Seaweed_Block"
    },
    {
      "x": -7,
      "y": 3,
      "z": -4,
      "name": "Soil_Clay_Lime"
    },
    {
      "x": -7,
      "y": 4,
      "z": -4,
      "name": "Plant_Grass_Sharp"
    },
    {
      "x": -7,
      "y": 29,
      "z": -4,
      "name": "Soil_Clay_Green"
    },
    {
      "x": -7,
      "y": 30,
      "z": -4,
      "name": "Soil_Clay_Lime"
    },
    {
      "x": -7,
      "y": 31,
      "z": -4,
      "name": "Plant_Grass_Sharp"
    },
    {
      "x": -7,
      "y": 1,
      "z": -3,
      "name": "Soil_Clay_Green"
    },
    {
      "x": -7,
      "y": 2,
      "z": -3,
      "name": "Soil_Seaweed_Block"
    },
    {
      "x": -7,
      "y": 30,
      "z": -3,
      "name": "Soil_Seaweed_Block"
    },
    {
      "x": -7,
      "y": 30,
      "z": -2,
      "name": "Soil_Clay_Green"
    },
    {
      "x": -7,
      "y": 31,
      "z": -2,
      "name": "Soil_Clay_Lime"
    },
    {
      "x": -7,
      "y": 32,
      "z": -2,
      "name": "Plant_Grass_Sharp"
    },
    {
      "x": -7,
      "y": 31,
      "z": -1,
      "name": "Soil_Clay_Lime"
    },
    {
      "x": -7,
      "y": 32,
      "z": -1,
      "name": "Plant_Grass_Sharp"
    },
    {
      "x": -7,
      "y": 31,
      "z": 0,
      "name": "Soil_Clay_Lime"
    },
    {
      "x": -7,
      "y": 31,
      "z": 1,
      "name": "Soil_Seaweed_Block"
    },
    {
      "x": -7,
      "y": 2,
      "z": 4,
      "name": "Soil_Clay_Green"
    },
    {
      "x": -7,
      "y": 2,
      "z": 5,
      "name": "Soil_Clay_Green"
    },
    {
      "x": -7,
      "y": 3,
      "z": 5,
      "name": "Soil_Clay_Lime"
    },
    {
      "x": -7,
      "y": 4,
      "z": 5,
      "name": "Plant_Grass_Sharp"
    },
    {
      "x": -7,
      "y": 1,
      "z": 6,
      "name": "Soil_Clay_Green"
    },
