{
  "version": 8,
  "blockIdVersion": 10,
  "anchorX": 0,
  "anchorY": 15,
  "anchorZ": 0,
  "blocks": [
    {
      "x": -28,
      "y": 28,
      "z": 8,
      "name": "Soil_Seaweed_Block"
    },
    {
      "x": -28,
      "y": 28,
      "z": 9,
      "name": "Soil_Seaweed_Block"
    },
    {
      "x": -27,
      "y": 23,
      "z": -6,
      "name": "Soil_Seaweed_Block"
    },
    {
      "x": -27,
      "y": 22,
      "z": -5,
      "name": "Soil_Clay_Green"
    },
    {
      "x": -27,
      "y": 23,
      "z": -5,
      "name": "Soil_Seaweed_Block"
    },
    {
      "x": -27,
      "y": 24,
      "z": -5,
      "name": "Soil_Seaweed_Block"
    },
    {
      "x": -27,
      "y": 22,
      "z": -4,
      "name": "Soil_Clay_Green"
    },
    {
      "x": -27,
      "y": 23,
      "z": -4,
      "name": "Soil_Seaweed_Block"
    },
    {
      "x": -27,
      "y": 24,
      "z": -4,
      "name": "Soil_Seaweed_Block"
    },
    {
      "x": -27,
      "y": 22,
      "z": -3,
      "name": "Soil_Clay_Green"
    },
    {
      "x": -27,
      "y": 23,
      "z": -3,
      "name": "Soil_Seaweed_Block"
    },
    {
      "x": -27,
      "y": 24,
      "z": -3,
      "name": "Soil_Seaweed_Block"
    },
    {
      "x": -27,
      "y": 18,
      "z": 4,
      "name": "Soil_Seaweed_Block"
    },
    {
      "x": -27,
      "y": 32,
      "z": 5,
      "name": "Soil_Seaweed_Block"
    },
    {
      "x": -27,
      "y": 33,
      "z": 5,
      "name": "Soil_Seaweed_Block"
    },
    {
      "x": -27,
      "y": 34,
      "z": 5,
      "name": "Soil_Seaweed_Block"
    },
    {
      "x": -27,
      "y": 31,
      "z": 6,
      "name": "Soil_Seaweed_Block"
    },
    {
      "x": -27,
      "y": 32,
      "z": 6,
      "name": "Soil_Seaweed_Block"
    },
    {
      "x": -27,
      "y": 33,
      "z": 6,
      "name": "Soil_Seaweed_Block"
    },
    {
      "x": -27,
      "y": 34,
      "z": 6,
      "name": "Soil_Seaweed_Block"
    },
    {
      "x": -27,
      "y": 27,
      "z": 7,
      "name": "Soil_Clay_Green"
    },
    {
      "x": -27,
      "y": 28,
      "z": 7,
      "name": "Soil_Seaweed_Block"
    },
    {
      "x": -27,
      "y": 29,
      "z": 7,
      "name": "Soil_Seaweed_Block"
    },
    {
      "x": -27,
      "y": 30,
      "z": 7,
      "name": "Soil_Seaweed_Block"
    },
    {
      "x": -27,
      "y": 31,
      "z": 7,
      "name": "Soil_Seaweed_Block"
    },
    {
      "x": -27,
      "y": 32,
      "z": 7,
      "name": "Soil_Seaweed_Block"
    },
    {
      "x": -27,
      "y": 33,
      "z": 7,
      "name": "Soil_Seaweed_Block"
    },
    {
      "x": -27,
      "y": 34,
      "z": 7,
      "name": "Soil_Seaweed_Block"
    },
    {
      "x": -27,
      "y": 26,
      "z": 8,
      "name": "Soil_Clay_Green"
    },
    {
      "x": -27,
      "y": 27,
      "z": 8,
      "name": "Soil_Clay_Green"
    },
    {
      "x": -27,
      "y": 28,
      "z": 8,
      "name": "Soil_Seaweed_Block"
    },
    {
      "x": -27,
      "y": 29,
      "z": 8,
      "name": "Soil_Seaweed_Block"
    },
    {
      "x": -27,
      "y": 30,
      "z": 8,
      "name": "Soil_Seaweed_Block"
    },
    {
      "x": -27,
      "y": 27,
      "z": 9,
      "name": "Soil_Clay_Green"
    },
    {
      "x": -27,
      "y": 28,
      "z": 9,
      "name": "Soil_Seaweed_Block"
    },
    {
      "x": -27,
      "y": 29,
      "z": 9,
      "name": "Soil_Seaweed_Block"
    },
    {
      "x": -27,
      "y": 27,
      "z": 10,
      "name": "Soil_Clay_Green"
    },
    {
      "x": -27,
      "y": 28,
      "z": 10,
      "name": "Soil_Seaweed_Block"
    },
    {
      "x": -27,
      "y": 29,
      "z": 10,
      "name": "Soil_Seaweed_Block"
    },
    {
      "x": -26,
      "y": 14,
      "z": -12,
      "name": "Soil_Clay_Green"
    },
    {
      "x": -26,
      "y": 15,
      "z": -12,
      "name": "Soil_Seaweed_Block"
    },
    {
      "x": -26,
      "y": 16,
      "z": -12,
      "name": "Soil_Seaweed_Block"
    },
    {
      "x": -26,
      "y": 14,
      "z": -11,
      "name": "Soil_Clay_Green"
    },
    {
      "x": -26,
      "y": 15,
      "z": -11,
      "name": "Soil_Seaweed_Block"
    },
    {
      "x": -26,
      "y": 16,
      "z": -11,
      "name": "Soil_Seaweed_Block"
    },
    {
      "x": -26,
      "y": 14,
      "z": -10,
      "name": "Soil_Clay_Green"
    },
    {
      "x": -26,
      "y": 15,
      "z": -10,
      "name": "Soil_Seaweed_Block"
    },
    {
      "x": -26,
      "y": 16,
      "z": -10,
      "name": "Soil_Seaweed_Block"
    },
    {
      "x": -26,
      "y": 23,
      "z": -7,
      "name": "Soil_Seaweed_Block"
    },
    {
      "x": -26,
      "y": 22,
      "z": -6,
      "name": "Soil_Clay_Green"
    },
    {
      "x": -26,
      "y": 23,
      "z": -6,
      "name": "Soil_Seaweed_Block"
    },
    {
      "x": -26,
      "y": 24,
      "z": -6,
      "name": "Soil_Seaweed_Block"
    },
    {
      "x": -26,
      "y": 21,
      "z": -5,
      "name": "Soil_Clay_Green"
    },
    {
      "x": -26,
      "y": 22,
      "z": -5,
      "name": "Soil_Seaweed_Block"
    },
    {
      "x": -26,
      "y": 23,
      "z": -5,
      "name": "Soil_Seaweed_Block"
    },
    {
      "x": -26,
      "y": 24,
      "z": -5,
      "name": "Soil_Seaweed_Block"
    },
    {
      "x": -26,
      "y": 25,
      "z": -5,
      "name": "Soil_Seaweed_Block"
    },
    {
      "x": -26,
      "y": 21,
      "z": -4,
      "name": "Soil_Clay_Green"
    },
    {
      "x": -26,
      "y": 22,
      "z": -4,
      "name": "Soil_Seaweed_Block"
    },
    {
      "x": -26,
      "y": 23,
      "z": -4,
      "name": "Soil_Seaweed_Block"
    },
    {
      "x": -26,
      "y": 24,
      "z": -4,
      "name": "Soil_Seaweed_Block"
    },
    {
      "x": -26,
      "y": 25,
      "z": -4,
      "name": "Soil_Clay_Lime"
    },
    {
      "x": -26,
      "y": 26,
      "z": -4,
      "name": "Plant_Grass_Sharp"
    },
    {
      "x": -26,
      "y": 21,
      "z": -3,
      "name": "Soil_Clay_Green"
    },
    {
      "x": -26,
      "y": 22,
      "z": -3,
      "name": "Soil_Seaweed_Block"
    },
    {
      "x": -26,
      "y": 23,
      "z": -3,
      "name": "Soil_Seaweed_Block"
    },
    {
      "x": -26,
      "y": 24,
      "z": -3,
      "name": "Soil_Seaweed_Block"
    },
    {
      "x": -26,
      "y": 25,
      "z": -3,
      "name": "Soil_Seaweed_Block"
    },
    {
      "x": -26,
      "y": 21,
      "z": -2,
      "name": "Soil_Clay_Green"
    },
    {
      "x": -26,
      "y": 22,
      "z": -2,
      "name": "Soil_Seaweed_Block"
    },
    {
      "x": -26,
      "y": 23,
      "z": -2,
      "name": "Soil_Seaweed_Block"
    },
    {
      "x": -26,
      "y": 24,
      "z": -2,
      "name": "Soil_Seaweed_Block"
    },
    {
      "x": -26,
      "y": 18,
      "z": 2,
      "name": "Soil_Clay_Green"
    },
    {
      "x": -26,
      "y": 19,
      "z": 2,
      "name": "Soil_Seaweed_Block"
    },
    {
      "x": -26,
      "y": 17,
      "z": 3,
      "name": "Soil_Clay_Green"
    },
    {
      "x": -26,
      "y": 18,
      "z": 3,
      "name": "Soil_Seaweed_Block"
    },
    {
      "x": -26,
      "y": 19,
      "z": 3,
      "name": "Soil_Seaweed_Block"
    },
    {
      "x": -26,
      "y": 20,
      "z": 3,
      "name": "Soil_Seaweed_Block"
    },
    {
      "x": -26,
      "y": 17,
      "z": 4,
      "name": "Soil_Clay_Green"
    },
    {
      "x": -26,
      "y": 18,
      "z": 4,
      "name": "Soil_Seaweed_Block"
    },
    {
      "x": -26,
      "y": 19,
      "z": 4,
      "name": "Soil_Seaweed_Block"
    },
    {
      "x": -26,
      "y": 20,
      "z": 4,
      "name": "Soil_Seaweed_Block"
    },
    {
      "x": -26,
      "y": 32,
      "z": 4,
      "name": "Soil_Seaweed_Block"
    },
    {
      "x": -26,
      "y": 33,
      "z": 4,
      "name": "Soil_Seaweed_Block"
    },
    {
      "x": -26,
      "y": 34,
      "z": 4,
      "name": "Soil_Seaweed_Block"
    },
    {
      "x": -26,
      "y": 17,
      "z": 5,
      "name": "Soil_Seaweed_Block"
    },
    {
      "x": -26,
      "y": 18,
      "z": 5,
      "name": "Soil_Seaweed_Block"
    },
    {
      "x": -26,
      "y": 19,
      "z": 5,
      "name": "Soil_Seaweed_Block"
    },
    {
      "x": -26,
      "y": 31,
      "z": 5,
      "name": "Soil_Clay_Green"
    },
    {
      "x": -26,
      "y": 32,
      "z": 5,
      "name": "Soil_Seaweed_Block"
    },
    {
      "x": -26,
      "y": 33,
      "z": 5,
      "name": "Soil_Seaweed_Block"
    },
    {
      "x": -26,
      "y": 34,
      "z": 5,
      "name": "Soil_Seaweed_Block"
    },
    {
      "x": -26,
      "y": 35,
      "z": 5,
      "name": "Soil_Clay_Lime"
    },
    {
      "x": -26,
      "y": 36,
      "z": 5,
      "name": "Plant_Grass_Sharp"
    },
    {
      "x": -26,
      "y": 27,
      "z": 6,
      "name": "Soil_Clay_Green"
    },
    {
      "x": -26,
      "y": 28,
      "z": 6,
      "name": "Soil_Seaweed_Block"
    },
    {
      "x": -26,
      "y": 29,
      "z": 6,
      "name": "Soil_Seaweed_Block"
    },
    {
      "x": -26,
      "y": 30,
      "z": 6,
      "name": "Soil_Clay_Green"
    },
    {
      "x": -26,
      "y": 31,
      "z": 6,
      "name": "Soil_Seaweed_Block"
    },
    {
      "x": -26,
      "y": 32,
      "z": 6,
      "name": "Soil_Seaweed_Block"
    },
    {
      "x": -26,
      "y": 33,
      "z": 6,
      "name": "Soil_Seaweed_Block"
    },
    {
      "x": -26,
      "y": 34,
      "z": 6,
      "name": "Soil_Seaweed_Block"
    },
    {
      "x": -26,
      "y": 35,
      "z": 6,
      "name": "Soil_Clay_Lime"
    },
    {
      "x": -26,
      "y": 36,
      "z": 6,
      "name": "Plant_Grass_Sharp"
    },
    {
      "x": -26,
      "y": 26,
      "z": 7,
      "name": "Soil_Clay_Green"
    },
    {
      "x": -26,
      "y": 27,
      "z": 7,
      "name": "Soil_Seaweed_Block"
    },
    {
      "x": -26,
      "y": 28,
      "z": 7,
      "name": "Soil_Seaweed_Block"
    },
    {
      "x": -26,
      "y": 29,
      "z": 7,
      "name": "Soil_Seaweed_Block"
    },
    {
      "x": -26,
      "y": 30,
      "z": 7,
      "name": "Soil_Seaweed_Block"
    },
    {
      "x": -26,
      "y": 31,
      "z": 7,
      "name": "Soil_Seaweed_Block"
    },
    {
      "x": -26,
      "y": 32,
      "z": 7,
      "name": "Soil_Seaweed_Block"
    },
    {
      "x": -26,
      "y": 33,
      "z": 7,
      "name": "Soil_Seaweed_Block"
    },
    {
      "x": -26,
      "y": 34,
      "z": 7,
      "name": "Soil_Seaweed_Block"
    },
    {
      "x": -26,
      "y": 35,
      "z": 7,
      "name": "Soil_Clay_Lime"
    },
    {
      "x": -26,
      "y": 36,
      "z": 7,
      "name": "Plant_Grass_Sharp"
    },
    {
      "x": -26,
      "y": 26,
      "z": 8,
      "name": "Soil_Clay_Green"
    },
    {
      "x": -26,
      "y": 27,
      "z": 8,
      "name": "Soil_Seaweed_Block"
    },
    {
      "x": -26,
      "y": 28,
      "z": 8,
      "name": "Soil_Seaweed_Block"
    },
    {
      "x": -26,
      "y": 29,
      "z": 8,
      "name": "Soil_Seaweed_Block"
    },
    {
      "x": -26,
      "y": 30,
      "z": 8,
      "name": "Soil_Seaweed_Block"
    },
    {
      "x": -26,
      "y": 31,
      "z": 8,
      "name": "Soil_Seaweed_Block"
    },
    {
      "x": -26,
      "y": 32,
      "z": 8,
      "name": "Soil_Seaweed_Block"
    },
    {
      "x": -26,
      "y": 33,
      "z": 8,
      "name": "Soil_Seaweed_Block"
    },
    {
      "x": -26,
      "y": 34,
      "z": 8,
      "name": "Soil_Seaweed_Block"
    },
    {
      "x": -26,
      "y": 26,
      "z": 9,
      "name": "Soil_Clay_Green"
    },
    {
      "x": -26,
      "y": 27,
      "z": 9,
      "name": "Soil_Seaweed_Block"
    },
    {
      "x": -26,
      "y": 28,
      "z": 9,
      "name": "Soil_Seaweed_Block"
    },
    {
      "x": -26,
      "y": 29,
      "z": 9,
      "name": "Soil_Seaweed_Block"
    },
    {
      "x": -26,
      "y": 30,
      "z": 9,
      "name": "Soil_Seaweed_Block"
    },
    {
      "x": -26,
      "y": 27,
      "z": 10,
      "name": "Soil_Clay_Green"
    },
    {
      "x": -26,
      "y": 28,
      "z": 10,
      "name": "Soil_Seaweed_Block"
    },
    {
      "x": -26,
      "y": 29,
      "z": 10,
      "name": "Soil_Seaweed_Block"
    },
    {
      "x": -26,
      "y": 30,
      "z": 10,
      "name": "Soil_Seaweed_Block"
    },
    {
      "x": -25,
      "y": 14,
      "z": -13,
      "name": "Soil_Clay_Green"
    },
    {
      "x": -25,
      "y": 15,
      "z": -13,
      "name": "Soil_Seaweed_Block"
    },
    {
      "x": -25,
      "y": 16,
      "z": -13,
      "name": "Soil_Seaweed_Block"
    },
    {
      "x": -25,
      "y": 13,
      "z": -12,
      "name": "Soil_Clay_Green"
    },
    {
      "x": -25,
      "y": 14,
      "z": -12,
      "name": "Soil_Seaweed_Block"
    },
    {
      "x": -25,
      "y": 15,
      "z": -12,
      "name": "Soil_Seaweed_Block"
    },
    {
      "x": -25,
      "y": 16,
      "z": -12,
      "name": "Soil_Seaweed_Block"
    },
    {
      "x": -25,
      "y": 17,
      "z": -12,
      "name": "Soil_Seaweed_Block"
    },
    {
      "x": -25,
      "y": 13,
      "z": -11,
      "name": "Soil_Clay_Green"
    },
    {
      "x": -25,
      "y": 14,
      "z": -11,
      "name": "Soil_Seaweed_Block"
    },
    {
      "x": -25,
      "y": 15,
      "z": -11,
      "name": "Soil_Seaweed_Block"
    },
    {
      "x": -25,
      "y": 16,
      "z": -11,
      "name": "Soil_Seaweed_Block"
    },
    {
      "x": -25,
      "y": 17,
      "z": -11,
      "name": "Soil_Clay_Lime"
    },
    {
      "x": -25,
      "y": 18,
      "z": -11,
      "name": "Plant_Grass_Sharp"
    },
    {
      "x": -25,
      "y": 13,
      "z": -10,
      "name": "Soil_Clay_Green"
    },
    {
      "x": -25,
      "y": 14,
      "z": -10,
      "name": "Soil_Seaweed_Block"
    },
    {
      "x": -25,
      "y": 15,
      "z": -10,
      "name": "Soil_Seaweed_Block"
    },
    {
      "x": -25,
      "y": 16,
      "z": -10,
      "name": "Soil_Seaweed_Block"
    },
    {
      "x": -25,
      "y": 17,
      "z": -10,
      "name": "Soil_Seaweed_Block"
    },
    {
      "x": -25,
      "y": 14,
      "z": -9,
      "name": "Soil_Clay_Green"
    },
    {
      "x": -25,
      "y": 15,
      "z": -9,
      "name": "Soil_Seaweed_Block"
    },
    {
      "x": -25,
      "y": 16,
      "z": -9,
      "name": "Soil_Seaweed_Block"
    },
    {
      "x": -25,
      "y": 22,
      "z": -7,
      "name": "Soil_Clay_Green"
    },
    {
      "x": -25,
      "y": 23,
      "z": -7,
      "name": "Soil_Seaweed_Block"
    },
    {
      "x": -25,
      "y": 24,
      "z": -7,
      "name": "Soil_Seaweed_Block"
    },
    {
      "x": -25,
      "y": 21,
      "z": -6,
      "name": "Soil_Clay_Green"
    },
    {
      "x": -25,
      "y": 22,
      "z": -6,
      "name": "Soil_Seaweed_Block"
    },
    {
      "x": -25,
      "y": 23,
      "z": -6,
      "name": "Soil_Seaweed_Block"
    },
    {
      "x": -25,
      "y": 24,
      "z": -6,
      "name": "Soil_Seaweed_Block"
    },
    {
      "x": -25,
      "y": 25,
      "z": -6,
      "name": "Soil_Seaweed_Block"
    },
    {
      "x": -25,
      "y": 21,
      "z": -5,
      "name": "Soil_Clay_Green"
    },
    {
      "x": -25,
      "y": 22,
      "z": -5,
      "name": "Soil_Seaweed_Block"
    },
    {
      "x": -25,
      "y": 23,
      "z": -5,
      "name": "Soil_Seaweed_Block"
    },
    {
      "x": -25,
      "y": 24,
      "z": -5,
      "name": "Soil_Seaweed_Block"
    },
    {
      "x": -25,
      "y": 25,
      "z": -5,
      "name": "Soil_Seaweed_Block"
    },
    {
      "x": -25,
      "y": 26,
      "z": -5,
      "name": "Soil_Seaweed_Block"
    },
    {
      "x": -25,
      "y": 21,
      "z": -4,
      "name": "Soil_Clay_Green"
    },
    {
      "x": -25,
      "y": 22,
      "z": -4,
      "name": "Soil_Seaweed_Block"
    },
    {
      "x": -25,
      "y": 23,
      "z": -4,
      "name": "Soil_Seaweed_Block"
    },
    {
      "x": -25,
      "y": 24,
      "z": -4,
      "name": "Soil_Seaweed_Block"
    },
    {
      "x": -25,
      "y": 25,
      "z": -4,
      "name": "Soil_Seaweed_Block"
    },
    {
      "x": -25,
      "y": 26,
      "z": -4,
      "name": "Soil_Seaweed_Block"
    },
    {
      "x": -25,
      "y": 21,
      "z": -3,
      "name": "Soil_Clay_Green"
    },
    {
      "x": -25,
      "y": 22,
      "z": -3,
      "name": "Soil_Seaweed_Block"
    },
    {
      "x": -25,
      "y": 23,
      "z": -3,
      "name": "Soil_Seaweed_Block"
    },
    {
      "x": -25,
      "y": 24,
      "z": -3,
      "name": "Soil_Seaweed_Block"
    },
    {
      "x": -25,
      "y": 25,
      "z": -3,
      "name": "Soil_Seaweed_Block"
    },
    {
      "x": -25,
      "y": 20,
      "z": -2,
      "name": "Soil_Clay_Green"
    },
    {
      "x": -25,
      "y": 21,
      "z": -2,
      "name": "Soil_Seaweed_Block"
    },
    {
      "x": -25,
      "y": 22,
      "z": -2,
      "name": "Soil_Seaweed_Block"
    },
    {
      "x": -25,
      "y": 23,
      "z": -2,
      "name": "Soil_Seaweed_Block"
    },
    {
      "x": -25,
      "y": 24,
      "z": -2,
      "name": "Soil_Seaweed_Block"
    },
    {
      "x": -25,
      "y": 20,
      "z": -1,
      "name": "Soil_Clay_Green"
    },
    {
      "x": -25,
      "y": 21,
      "z": -1,
      "name": "Soil_Seaweed_Block"
    },
    {
      "x": -25,
      "y": 22,
      "z": -1,
      "name": "Soil_Seaweed_Block"
    },
    {
      "x": -25,
      "y": 23,
      "z": -1,
      "name": "Soil_Seaweed_Block"
    },
    {
      "x": -25,
      "y": 19,
      "z": 0,
      "name": "Soil_Clay_Green"
    },
    {
      "x": -25,
      "y": 20,
      "z": 0,
      "name": "Soil_Seaweed_Block"
    },
    {
      "x": -25,
      "y": 21,
      "z": 0,
      "name": "Soil_Seaweed_Block"
    },
    {
      "x": -25,
      "y": 18,
      "z": 1,
      "name": "Soil_Clay_Green"
    },
    {
      "x": -25,
      "y": 19,
      "z": 1,
      "name": "Soil_Clay_Green"
    },
    {
      "x": -25,
      "y": 20,
      "z": 1,
      "name": "Soil_Seaweed_Block"
    },
    {
      "x": -25,
      "y": 21,
      "z": 1,
      "name": "Soil_Clay_Lime"
    },
    {
      "x": -25,
      "y": 22,
      "z": 1,
      "name": "Plant_Grass_Sharp"
    },
    {
      "x": -25,
      "y": 17,
      "z": 2,
      "name": "Soil_Clay_Green"
    },
    {
      "x": -25,
      "y": 18,
      "z": 2,
      "name": "Soil_Seaweed_Block"
    },
    {
      "x": -25,
      "y": 19,
      "z": 2,
      "name": "Soil_Seaweed_Block"
    },
    {
      "x": -25,
      "y": 20,
      "z": 2,
      "name": "Soil_Seaweed_Block"
    },
    {
      "x": -25,
      "y": 21,
      "z": 2,
      "name": "Soil_Clay_Lime"
    },
    {
      "x": -25,
      "y": 22,
      "z": 2,
      "name": "Plant_Grass_Sharp"
    },
    {
      "x": -25,
      "y": 16,
      "z": 3,
      "name": "Soil_Clay_Green"
    },
    {
      "x": -25,
      "y": 17,
      "z": 3,
      "name": "Soil_Seaweed_Block"
    },
    {
      "x": -25,
      "y": 18,
      "z": 3,
      "name": "Soil_Seaweed_Block"
    },
    {
      "x": -25,
      "y": 19,
      "z": 3,
      "name": "Soil_Seaweed_Block"
    },
    {
      "x": -25,
      "y": 20,
      "z": 3,
      "name": "Soil_Seaweed_Block"
    },
    {
      "x": -25,
      "y": 21,
      "z": 3,
      "name": "Soil_Clay_Lime"
    },
    {
      "x": -25,
      "y": 22,
      "z": 3,
      "name": "Plant_Grass_Sharp"
    },
    {
      "x": -25,
      "y": 33,
      "z": 3,
      "name": "Soil_Seaweed_Block"
    },
    {
      "x": -25,
      "y": 15,
      "z": 4,
      "name": "Soil_Clay_Green"
    },
    {
      "x": -25,
      "y": 16,
      "z": 4,
      "name": "Soil_Clay_Green"
    },
    {
      "x": -25,
      "y": 17,
      "z": 4,
      "name": "Soil_Seaweed_Block"
    },
    {
      "x": -25,
      "y": 18,
      "z": 4,
      "name": "Soil_Seaweed_Block"
    },
    {
      "x": -25,
      "y": 19,
      "z": 4,
      "name": "Soil_Seaweed_Block"
    },
    {
      "x": -25,
      "y": 20,
      "z": 4,
      "name": "Soil_Seaweed_Block"
    },
    {
      "x": -25,
      "y": 21,
      "z": 4,
      "name": "Soil_Seaweed_Block"
    },
    {
      "x": -25,
      "y": 22,
      "z": 4,
      "name": "Soil_Seaweed_Block"
    },
    {
      "x": -25,
      "y": 31,
      "z": 4,
      "name": "Soil_Clay_Green"
    },
    {
      "x": -25,
      "y": 32,
      "z": 4,
      "name": "Soil_Seaweed_Block"
    },
    {
      "x": -25,
      "y": 33,
      "z": 4,
      "name": "Soil_Seaweed_Block"
    },
    {
      "x": -25,
      "y": 34,
      "z": 4,
      "name": "Soil_Clay_Lime"
    },
    {
      "x": -25,
      "y": 35,
      "z": 4,
      "name": "Plant_Grass_Sharp"
    },
    {
      "x": -25,
      "y": 13,
      "z": 5,
      "name": "Soil_Clay_Green"
    },
    {
      "x": -25,
      "y": 14,
      "z": 5,
      "name": "Soil_Seaweed_Block"
    },
    {
      "x": -25,
      "y": 15,
      "z": 5,
      "name": "Soil_Seaweed_Block"
    },
    {
      "x": -25,
      "y": 16,
      "z": 5,
      "name": "Soil_Seaweed_Block"
    },
    {
      "x": -25,
      "y": 17,
      "z": 5,
      "name": "Soil_Seaweed_Block"
    },
    {
      "x": -25,
      "y": 18,
      "z": 5,
      "name": "Soil_Seaweed_Block"
    },
    {
      "x": -25,
      "y": 19,
      "z": 5,
      "name": "Soil_Seaweed_Block"
    },
    {
      "x": -25,
      "y": 20,
      "z": 5,
      "name": "Soil_Seaweed_Block"
    },
    {
      "x": -25,
      "y": 21,
      "z": 5,
      "name": "Soil_Seaweed_Block"
    },
    {
      "x": -25,
      "y": 22,
      "z": 5,
      "name": "Soil_Seaweed_Block"
    },
    {
      "x": -25,
      "y": 30,
      "z": 5,
      "name": "Soil_Clay_Green"
    },
    {
      "x": -25,
      "y": 31,
      "z": 5,
      "name": "Soil_Seaweed_Block"
    },
    {
      "x": -25,
      "y": 32,
      "z": 5,
      "name": "Soil_Seaweed_Block"
    },
    {
      "x": -25,
      "y": 33,
      "z": 5,
      "name": "Soil_Seaweed_Block"
    },
    {
      "x": -25,
      "y": 34,
      "z": 5,
      "name": "Soil_Seaweed_Block"
    },
    {
      "x": -25,
      "y": 35,
      "z": 5,
      "name": "Soil_Clay_Lime"
    },
    {
      "x": -25,
      "y": 36,
      "z": 5,
      "name": "Plant_Grass_Sharp"
    },
    {
      "x": -25,
      "y": 12,
      "z": 6,
      "name": "Soil_Clay_Green"
    },
    {
      "x": -25,
      "y": 13,
      "z": 6,
      "name": "Soil_Clay_Green"
    },
    {
      "x": -25,
      "y": 14,
      "z": 6,
      "name": "Soil_Seaweed_Block"
    },
    {
      "x": -25,
      "y": 15,
      "z": 6,
      "name": "Soil_Seaweed_Block"
    },
    {
      "x": -25,
      "y": 16,
      "z": 6,
      "name": "Soil_Seaweed_Block"
    },
    {
      "x": -25,
      "y": 17,
      "z": 6,
      "name": "Soil_Seaweed_Block"
    },
    {
      "x": -25,
      "y": 18,
      "z": 6,
      "name": "Soil_Seaweed_Block"
    },
    {
      "x": -25,
      "y": 19,
      "z": 6,
      "name": "Soil_Seaweed_Block"
    },
    {
      "x": -25,
      "y": 26,
      "z": 6,
      "name": "Soil_Clay_Green"
    },
    {
      "x": -25,
      "y": 27,
      "z": 6,
      "name": "Soil_Seaweed_Block"
    },
    {
      "x": -25,
      "y": 28,
      "z": 6,
      "name": "Soil_Seaweed_Block"
    },
    {
      "x": -25,
      "y": 29,
      "z": 6,
      "name": "Soil_Clay_Green"
    },
    {
      "x": -25,
      "y": 30,
      "z": 6,
      "name": "Soil_Seaweed_Block"
    },
    {
      "x": -25,
      "y": 31,
      "z": 6,
      "name": "Soil_Seaweed_Block"
    },
    {
      "x": -25,
      "y": 32,
      "z": 6,
      "name": "Soil_Seaweed_Block"
    },
    {
      "x": -25,
      "y": 33,
      "z": 6,
      "name": "Soil_Seaweed_Block"
    },
    {
      "x": -25,
      "y": 34,
      "z": 6,
      "name": "Soil_Seaweed_Block"
    },
    {
      "x": -25,
      "y": 35,
      "z": 6,
      "name": "Soil_Clay_Lime"
    },
    {
      "x": -25,
      "y": 36,
      "z": 6,
      "name": "Plant_Grass_Sharp"
    },
    {
      "x": -25,
      "y": 12,
      "z": 7,
      "name": "Soil_Clay_Green"
    },
    {
      "x": -25,
      "y": 13,
      "z": 7,
      "name": "Soil_Clay_Green"
    },
    {
      "x": -25,
      "y": 14,
      "z": 7,
      "name": "Soil_Seaweed_Block"
    },
    {
      "x": -25,
      "y": 15,
      "z": 7,
      "name": "Soil_Seaweed_Block"
    },
    {
      "x": -25,
      "y": 25,
      "z": 7,
      "name": "Soil_Clay_Green"
    },
    {
      "x": -25,
      "y": 26,
      "z": 7,
      "name": "Soil_Seaweed_Block"
    },
    {
      "x": -25,
      "y": 27,
      "z": 7,
      "name": "Soil_Seaweed_Block"
    },
    {
      "x": -25,
      "y": 28,
      "z": 7,
      "name": "Soil_Seaweed_Block"
    },
    {
      "x": -25,
      "y": 29,
      "z": 7,
      "name": "Soil_Seaweed_Block"
    },
    {
      "x": -25,
      "y": 30,
      "z": 7,
      "name": "Soil_Seaweed_Block"
    },
    {
      "x": -25,
      "y": 31,
      "z": 7,
      "name": "Soil_Seaweed_Block"
    },
    {
      "x": -25,
      "y": 32,
      "z": 7,
      "name": "Soil_Seaweed_Block"
    },
    {
      "x": -25,
      "y": 33,
      "z": 7,
      "name": "Soil_Seaweed_Block"
    },
    {
      "x": -25,
      "y": 34,
      "z": 7,
      "name": "Soil_Seaweed_Block"
    },
    {
      "x": -25,
      "y": 35,
      "z": 7,
      "name": "Soil_Clay_Lime"
    },
    {
      "x": -25,
      "y": 36,
      "z": 7,
      "name": "Plant_Grass_Sharp"
    },
    {
      "x": -25,
      "y": 12,
      "z": 8,
      "name": "Soil_Clay_Green"
    },
    {
      "x": -25,
      "y": 13,
      "z": 8,
      "name": "Soil_Seaweed_Block"
    },
    {
      "x": -25,
      "y": 14,
      "z": 8,
      "name": "Soil_Seaweed_Block"
    },
    {
      "x": -25,
      "y": 26,
      "z": 8,
      "name": "Soil_Clay_Green"
    },
    {
      "x": -25,
      "y": 27,
      "z": 8,
      "name": "Soil_Seaweed_Block"
    },
    {
      "x": -25,
      "y": 28,
      "z": 8,
      "name": "Soil_Seaweed_Block"
    },
    {
      "x": -25,
      "y": 29,
      "z": 8,
      "name": "Soil_Seaweed_Block"
    },
    {
      "x": -25,
      "y": 30,
      "z": 8,
      "name": "Soil_Seaweed_Block"
    },
    {
      "x": -25,
      "y": 31,
      "z": 8,
      "name": "Soil_Seaweed_Block"
    },
    {
      "x": -25,
      "y": 32,
      "z": 8,
      "name": "Soil_Seaweed_Block"
    },
    {
      "x": -25,
      "y": 33,
      "z": 8,
      "name": "Soil_Seaweed_Block"
    },
    {
      "x": -25,
      "y": 34,
      "z": 8,
      "name": "Soil_Seaweed_Block"
    },
    {
      "x": -25,
      "y": 26,
      "z": 9,
      "name": "Soil_Clay_Green"
    },
    {
      "x": -25,
      "y": 27,
      "z": 9,
      "name": "Soil_Seaweed_Block"
    },
    {
      "x": -25,
      "y": 28,
      "z": 9,
      "name": "Soil_Seaweed_Block"
    },
    {
      "x": -25,
      "y": 29,
      "z": 9,
      "name": "Soil_Seaweed_Block"
    },
    {
      "x": -25,
      "y": 30,
      "z": 9,
      "name": "Soil_Seaweed_Block"
    },
    {
      "x": -25,
      "y": 31,
      "z": 9,
      "name": "Soil_Seaweed_Block"
    },
    {
      "x": -25,
      "y": 26,
      "z": 10,
      "name": "Soil_Clay_Green"
    },
    {
      "x": -25,
      "y": 27,
      "z": 10,
      "name": "Soil_Clay_Green"
    },
    {
      "x": -25,
      "y": 28,
      "z": 10,
      "name": "Soil_Seaweed_Block"
    },
    {
      "x": -25,
      "y": 29,
      "z": 10,
      "name": "Soil_Seaweed_Block"
    },
    {
      "x": -25,
      "y": 30,
      "z": 10,
      "name": "Soil_Seaweed_Block"
    },
    {
      "x": -24,
      "y": 14,
      "z": -13,
      "name": "Soil_Clay_Green"
    },
    {
      "x": -24,
      "y": 15,
      "z": -13,
      "name": "Soil_Clay_Green"
    },
    {
      "x": -24,
      "y": 16,
      "z": -13,
      "name": "Soil_Seaweed_Block"
    },
    {
      "x": -24,
      "y": 17,
      "z": -13,
      "name": "Soil_Seaweed_Block"
    },
    {
      "x": -24,
      "y": 13,
      "z": -12,
      "name": "Soil_Clay_Green"
    },
    {
      "x": -24,
      "y": 14,
      "z": -12,
      "name": "Soil_Seaweed_Block"
    },
    {
      "x": -24,
      "y": 15,
      "z": -12,
      "name": "Soil_Seaweed_Block"
    },
    {
      "x": -24,
      "y": 16,
      "z": -12,
      "name": "Soil_Seaweed_Block"
    },
    {
      "x": -24,
      "y": 17,
      "z": -12,
      "name": "Soil_Clay_Lime"
    },
    {
      "x": -24,
      "y": 18,
      "z": -12,
      "name": "Plant_Grass_Sharp"
    },
    {
      "x": -24,
      "y": 13,
      "z": -11,
      "name": "Soil_Clay_Green"
    },
    {
      "x": -24,
      "y": 14,
      "z": -11,
      "name": "Soil_Seaweed_Block"
    },
    {
      "x": -24,
      "y": 15,
      "z": -11,
      "name": "Soil_Seaweed_Block"
    },
    {
      "x": -24,
      "y": 16,
      "z": -11,
      "name": "Soil_Seaweed_Block"
    },
    {
      "x": -24,
      "y": 17,
      "z": -11,
      "name": "Soil_Seaweed_Block"
    },
    {
      "x": -24,
      "y": 18,
      "z": -11,
      "name": "Soil_Clay_Lime"
    },
    {
      "x": -24,
      "y": 19,
      "z": -11,
      "name": "Plant_Grass_Sharp"
    },
    {
      "x": -24,
      "y": 13,
      "z": -10,
      "name": "Soil_Clay_Green"
    },
    {
      "x": -24,
      "y": 14,
      "z": -10,
      "name": "Soil_Seaweed_Block"
    },
    {
      "x": -24,
      "y": 15,
      "z": -10,
      "name": "Soil_Seaweed_Block"
    },
    {
      "x": -24,
      "y": 16,
      "z": -10,
      "name": "Soil_Seaweed_Block"
    },
    {
      "x": -24,
      "y": 17,
      "z": -10,
      "name": "Soil_Seaweed_Block"
    },
    {
      "x": -24,
      "y": 18,
      "z": -10,
      "name": "Soil_Clay_Lime"
    },
    {
      "x": -24,
      "y": 19,
      "z": -10,
      "name": "Plant_Grass_Sharp"
    },
    {
      "x": -24,
      "y": 29,
      "z": -10,
      "name": "Soil_Seaweed_Block"
    },
    {
      "x": -24,
      "y": 30,
      "z": -10,
      "name": "Soil_Seaweed_Block"
    },
    {
      "x": -24,
      "y": 31,
      "z": -10,
      "name": "Soil_Seaweed_Block"
    },
    {
      "x": -24,
      "y": 14,
      "z": -9,
      "name": "Soil_Clay_Green"
    },
    {
      "x": -24,
      "y": 15,
      "z": -9,
      "name": "Soil_Seaweed_Block"
    },
    {
      "x": -24,
      "y": 16,
      "z": -9,
      "name": "Soil_Seaweed_Block"
    },
    {
      "x": -24,
      "y": 17,
      "z": -9,
      "name": "Soil_Seaweed_Block"
    },
    {
      "x": -24,
      "y": 18,
      "z": -9,
      "name": "Soil_Seaweed_Block"
    },
    {
      "x": -24,
      "y": 28,
      "z": -9,
      "name": "Soil_Clay_Green"
    },
    {
      "x": -24,
      "y": 29,
      "z": -9,
      "name": "Soil_Seaweed_Block"
    },
    {
      "x": -24,
      "y": 30,
      "z": -9,
      "name": "Soil_Seaweed_Block"
    },
    {
      "x": -24,
      "y": 31,
      "z": -9,
      "name": "Soil_Seaweed_Block"
    },
    {
      "x": -24,
      "y": 28,
      "z": -8,
      "name": "Soil_Seaweed_Block"
    },
    {
      "x": -24,
      "y": 29,
      "z": -8,
      "name": "Soil_Seaweed_Block"
    },
    {
      "x": -24,
      "y": 30,
      "z": -8,
      "name": "Soil_Seaweed_Block"
    },
    {
      "x": -24,
      "y": 31,
      "z": -8,
      "name": "Soil_Seaweed_Block"
    },
    {
      "x": -24,
      "y": 20,
      "z": -7,
      "name": "Soil_Clay_Green"
    },
    {
      "x": -24,
      "y": 21,
      "z": -7,
      "name": "Soil_Clay_Green"
    },
    {
      "x": -24,
      "y": 22,
      "z": -7,
      "name": "Soil_Clay_Green"
    },
    {
      "x": -24,
      "y": 23,
      "z": -7,
      "name": "Soil_Seaweed_Block"
    },
    {
      "x": -24,
      "y": 24,
      "z": -7,
      "name": "Soil_Seaweed_Block"
    },
    {
      "x": -24,
      "y": 25,
      "z": -7,
      "name": "Soil_Seaweed_Block"
    },
    {
      "x": -24,
      "y": 26,
      "z": -7,
      "name": "Soil_Seaweed_Block"
    },
    {
      "x": -24,
      "y": 27,
      "z": -7,
      "name": "Soil_Seaweed_Block"
    },
    {
      "x": -24,
      "y": 28,
      "z": -7,
      "name": "Soil_Seaweed_Block"
    },
    {
      "x": -24,
      "y": 29,
      "z": -7,
      "name": "Soil_Seaweed_Block"
    },
    {
      "x": -24,
      "y": 30,
      "z": -7,
      "name": "Soil_Seaweed_Block"
    },
    {
      "x": -24,
      "y": 20,
      "z": -6,
      "name": "Soil_Clay_Green"
    },
    {
      "x": -24,
      "y": 21,
      "z": -6,
      "name": "Soil_Seaweed_Block"
    },
    {
      "x": -24,
      "y": 22,
      "z": -6,
      "name": "Soil_Seaweed_Block"
    },
    {
      "x": -24,
      "y": 23,
      "z": -6,
      "name": "Soil_Seaweed_Block"
    },
    {
      "x": -24,
      "y": 24,
      "z": -6,
      "name": "Soil_Seaweed_Block"
    },
    {
      "x": -24,
      "y": 25,
      "z": -6,
      "name": "Soil_Seaweed_Block"
    },
    {
      "x": -24,
      "y": 26,
      "z": -6,
      "name": "Soil_Seaweed_Block"
    },
    {
      "x": -24,
      "y": 27,
      "z": -6,
      "name": "Soil_Seaweed_Block"
    },
    {
      "x": -24,
      "y": 28,
      "z": -6,
      "name": "Soil_Seaweed_Block"
    },
    {
      "x": -24,
      "y": 29,
      "z": -6,
      "name": "Soil_Seaweed_Block"
    },
    {
      "x": -24,
      "y": 21,
      "z": -5,
      "name": "Soil_Clay_Green"
    },
    {
      "x": -24,
      "y": 22,
      "z": -5,
      "name": "Soil_Seaweed_Block"
    },
    {
      "x": -24,
      "y": 23,
      "z": -5,
      "name": "Soil_Seaweed_Block"
    },
    {
      "x": -24,
      "y": 24,
      "z": -5,
      "name": "Soil_Seaweed_Block"
    },
    {
      "x": -24,
      "y": 25,
      "z": -5,
      "name": "Soil_Seaweed_Block"
    },
    {
      "x": -24,
      "y": 26,
      "z": -5,
      "name": "Soil_Seaweed_Block"
    },
    {
      "x": -24,
      "y": 27,
      "z": -5,
      "name": "Soil_Seaweed_Block"
    },
    {
      "x": -24,
      "y": 28,
      "z": -5,
      "name": "Soil_Seaweed_Block"
    },
    {
      "x": -24,
      "y": 21,
      "z": -4,
      "name": "Soil_Clay_Green"
    },
    {
      "x": -24,
      "y": 22,
      "z": -4,
      "name": "Soil_Seaweed_Block"
    },
    {
      "x": -24,
      "y": 23,
      "z": -4,
      "name": "Soil_Seaweed_Block"
    },
    {
      "x": -24,
      "y": 24,
      "z": -4,
      "name": "Soil_Seaweed_Block"
    },
    {
      "x": -24,
      "y": 25,
      "z": -4,
      "name": "Soil_Seaweed_Block"
    },
    {
      "x": -24,
      "y": 26,
      "z": -4,
      "name": "Soil_Seaweed_Block"
    },
    {
      "x": -24,
      "y": 27,
      "z": -4,
      "name": "Soil_Seaweed_Block"
    },
    {
      "x": -24,
      "y": 28,
      "z": -4,
      "name": "Soil_Seaweed_Block"
    },
    {
      "x": -24,
      "y": 20,
      "z": -3,
      "name": "Soil_Clay_Green"
    },
    {
      "x": -24,
      "y": 21,
      "z": -3,
      "name": "Soil_Seaweed_Block"
    },
    {
      "x": -24,
      "y": 22,
      "z": -3,
      "name": "Soil_Seaweed_Block"
    },
    {
      "x": -24,
      "y": 23,
      "z": -3,
      "name": "Soil_Seaweed_Block"
    },
    {
      "x": -24,
      "y": 24,
      "z": -3,
      "name": "Soil_Seaweed_Block"
    },
    {
      "x": -24,
      "y": 25,
      "z": -3,
      "name": "Soil_Seaweed_Block"
    },
    {
      "x": -24,
      "y": 26,
      "z": -3,
      "name": "Soil_Seaweed_Block"
    },
    {
      "x": -24,
      "y": 27,
      "z": -3,
      "name": "Soil_Seaweed_Block"
    },
    {
      "x": -24,
      "y": 28,
      "z": -3,
      "name": "Soil_Seaweed_Block"
    },
    {
      "x": -24,
      "y": 29,
      "z": -3,
      "name": "Soil_Seaweed_Block"
    },
    {
      "x": -24,
      "y": 20,
      "z": -2,
      "name": "Soil_Clay_Green"
    },
    {
      "x": -24,
      "y": 21,
      "z": -2,
      "name": "Soil_Seaweed_Block"
    },
    {
      "x": -24,
      "y": 22,
      "z": -2,
      "name": "Soil_Seaweed_Block"
    },
    {
      "x": -24,
      "y": 23,
      "z": -2,
      "name": "Soil_Seaweed_Block"
    },
    {
      "x": -24,
      "y": 24,
      "z": -2,
      "name": "Soil_Seaweed_Block"
    },
    {
      "x": -24,
      "y": 28,
      "z": -2,
      "name": "Soil_Seaweed_Block"
    },
    {
      "x": -24,
      "y": 29,
      "z": -2,
      "name": "Soil_Seaweed_Block"
    },
    {
      "x": -24,
      "y": 19,
      "z": -1,
      "name": "Soil_Clay_Green"
    },
    {
      "x": -24,
      "y": 20,
      "z": -1,
      "name": "Soil_Seaweed_Block"
    },
    {
      "x": -24,
      "y": 21,
      "z": -1,
      "name": "Soil_Seaweed_Block"
    },
    {
      "x": -24,
      "y": 22,
      "z": -1,
      "name": "Soil_Seaweed_Block"
    },
    {
      "x": -24,
      "y": 23,
      "z": -1,
      "name": "Soil_Seaweed_Block"
    },
    {
      "x": -24,
      "y": 28,
      "z": -1,
      "name": "Soil_Clay_Green"
    },
    {
      "x": -24,
      "y": 29,
      "z": -1,
      "name": "Soil_Seaweed_Block"
    },
    {
      "x": -24,
      "y": 30,
      "z": -1,
      "name": "Soil_Seaweed_Block"
    },
    {
      "x": -24,
      "y": 19,
      "z": 0,
      "name": "Soil_Clay_Green"
    },
    {
      "x": -24,
      "y": 20,
      "z": 0,
      "name": "Soil_Seaweed_Block"
    },
    {
      "x": -24,
      "y": 21,
      "z": 0,
      "name": "Soil_Seaweed_Block"
    },
    {
      "x": -24,
      "y": 22,
      "z": 0,
      "name": "Soil_Clay_Lime"
    },
    {
      "x": -24,
      "y": 23,
      "z": 0,
      "name": "Plant_Grass_Sharp"
    },
    {
      "x": -24,
      "y": 29,
      "z": 0,
      "name": "Soil_Clay_Green"
    },
    {
      "x": -24,
      "y": 30,
      "z": 0,
      "name": "Soil_Seaweed_Block"
    },
    {
      "x": -24,
      "y": 18,
      "z": 1,
      "name": "Soil_Clay_Green"
    },
    {
      "x": -24,
      "y": 19,
      "z": 1,
      "name": "Soil_Seaweed_Block"
    },
    {
      "x": -24,
      "y": 20,
      "z": 1,
      "name": "Soil_Seaweed_Block"
    },
    {
      "x": -24,
      "y": 21,
      "z": 1,
      "name": "Soil_Clay_Lime"
    },
    {
      "x": -24,
      "y": 22,
      "z": 1,
      "name": "Plant_Grass_Sharp"
    },
    {
      "x": -24,
      "y": 30,
      "z": 1,
      "name": "Soil_Clay_Green"
    },
    {
      "x": -24,
      "y": 31,
      "z": 1,
      "name": "Soil_Seaweed_Block"
    },
    {
      "x": -24,
      "y": 16,
      "z": 2,
      "name": "Soil_Clay_Green"
    },
    {
      "x": -24,
      "y": 17,
      "z": 2,
      "name": "Soil_Clay_Green"
    },
    {
      "x": -24,
      "y": 18,
      "z": 2,
      "name": "Soil_Seaweed_Block"
    },
    {
      "x": -24,
      "y": 19,
      "z": 2,
      "name": "Soil_Seaweed_Block"
    },
    {
      "x": -24,
      "y": 20,
      "z": 2,
      "name": "Soil_Seaweed_Block"
    },
    {
      "x": -24,
      "y": 21,
      "z": 2,
      "name": "Soil_Clay_Lime"
    },
    {
      "x": -24,
      "y": 22,
      "z": 2,
      "name": "Plant_Grass_Sharp"
    },
    {
      "x": -24,
      "y": 31,
      "z": 2,
      "name": "Soil_Clay_Green"
    },
    {
      "x": -24,
      "y": 32,
      "z": 2,
      "name": "Soil_Seaweed_Block"
    },
    {
      "x": -24,
      "y": 14,
      "z": 3,
      "name": "Soil_Seaweed_Block"
    },
    {
      "x": -24,
      "y": 15,
      "z": 3,
      "name": "Soil_Seaweed_Block"
    },
    {
      "x": -24,
      "y": 16,
      "z": 3,
      "name": "Soil_Seaweed_Block"
    },
    {
      "x": -24,
      "y": 17,
      "z": 3,
      "name": "Soil_Seaweed_Block"
    },
    {
      "x": -24,
      "y": 18,
      "z": 3,
      "name": "Soil_Seaweed_Block"
    },
    {
      "x": -24,
      "y": 19,
      "z": 3,
      "name": "Soil_Seaweed_Block"
    },
    {
      "x": -24,
      "y": 20,
      "z": 3,
      "name": "Soil_Seaweed_Block"
    },
    {
      "x": -24,
      "y": 21,
      "z": 3,
      "name": "Soil_Seaweed_Block"
    },
    {
      "x": -24,
      "y": 22,
      "z": 3,
      "name": "Soil_Clay_Lime"
    },
    {
      "x": -24,
      "y": 23,
      "z": 3,
      "name": "Plant_Grass_Sharp"
    },
    {
      "x": -24,
      "y": 31,
      "z": 3,
      "name": "Soil_Clay_Green"
    },
    {
      "x": -24,
      "y": 32,
      "z": 3,
      "name": "Soil_Seaweed_Block"
    },
    {
      "x": -24,
      "y": 33,
      "z": 3,
      "name": "Soil_Seaweed_Block"
    },
    {
      "x": -24,
      "y": 34,
      "z": 3,
      "name": "Soil_Clay_Lime"
    },
    {
      "x": -24,
      "y": 35,
      "z": 3,
      "name": "Plant_Grass_Sharp"
    },
    {
      "x": -24,
      "y": 13,
      "z": 4,
      "name": "Soil_Clay_Green"
    },
    {
      "x": -24,
      "y": 14,
      "z": 4,
      "name": "Soil_Seaweed_Block"
    },
    {
      "x": -24,
      "y": 15,
      "z": 4,
      "name": "Soil_Seaweed_Block"
    },
    {
      "x": -24,
      "y": 16,
      "z": 4,
      "name": "Soil_Seaweed_Block"
    },
    {
      "x": -24,
      "y": 17,
      "z": 4,
      "name": "Soil_Seaweed_Block"
    },
    {
      "x": -24,
      "y": 18,
      "z": 4,
      "name": "Soil_Seaweed_Block"
    },
    {
      "x": -24,
      "y": 19,
      "z": 4,
      "name": "Soil_Seaweed_Block"
    },
    {
      "x": -24,
      "y": 20,
      "z": 4,
      "name": "Soil_Seaweed_Block"
    },
    {
      "x": -24,
      "y": 21,
      "z": 4,
      "name": "Soil_Seaweed_Block"
    },
    {
      "x": -24,
      "y": 22,
      "z": 4,
      "name": "Soil_Seaweed_Block"
    },
    {
      "x": -24,
      "y": 23,
      "z": 4,
      "name": "Soil_Seaweed_Block"
    },
    {
      "x": -24,
      "y": 30,
      "z": 4,
      "name": "Soil_Clay_Green"
    },
    {
      "x": -24,
      "y": 31,
      "z": 4,
      "name": "Soil_Seaweed_Block"
    },
    {
      "x": -24,
      "y": 32,
      "z": 4,
      "name": "Soil_Seaweed_Block"
    },
    {
      "x": -24,
      "y": 33,
      "z": 4,
      "name": "Soil_Seaweed_Block"
    },
    {
      "x": -24,
      "y": 34,
      "z": 4,
      "name": "Soil_Seaweed_Block"
    },
    {
      "x": -24,
      "y": 35,
      "z": 4,
      "name": "Soil_Clay_Lime"
    },
    {
      "x": -24,
      "y": 36,
      "z": 4,
      "name": "Plant_Grass_Sharp"
    },
    {
      "x": -24,
      "y": 12,
      "z": 5,
      "name": "Soil_Clay_Green"
    },
    {
      "x": -24,
      "y": 13,
      "z": 5,
      "name": "Soil_Seaweed_Block"
    },
    {
      "x": -24,
      "y": 14,
      "z": 5,
      "name": "Soil_Seaweed_Block"
    },
    {
      "x": -24,
      "y": 15,
      "z": 5,
      "name": "Soil_Seaweed_Block"
    },
    {
      "x": -24,
      "y": 16,
      "z": 5,
      "name": "Soil_Seaweed_Block"
    },
    {
      "x": -24,
      "y": 17,
      "z": 5,
      "name": "Soil_Seaweed_Block"
    },
    {
      "x": -24,
      "y": 18,
      "z": 5,
      "name": "Soil_Seaweed_Block"
    },
    {
      "x": -24,
      "y": 19,
      "z": 5,
      "name": "Soil_Seaweed_Block"
    },
    {
      "x": -24,
      "y": 20,
      "z": 5,
      "name": "Soil_Seaweed_Block"
    },
    {
      "x": -24,
      "y": 21,
      "z": 5,
      "name": "Soil_Seaweed_Block"
    },
    {
      "x": -24,
      "y": 22,
      "z": 5,
      "name": "Soil_Seaweed_Block"
    },
    {
      "x": -24,
      "y": 23,
      "z": 5,
      "name": "Soil_Seaweed_Block"
    },
    {
      "x": -24,
      "y": 24,
      "z": 5,
      "name": "Soil_Seaweed_Block"
    },
    {
      "x": -24,
      "y": 25,
      "z": 5,
      "name": "Soil_Seaweed_Block"
    },
    {
      "x": -24,
      "y": 30,
      "z": 5,
      "name": "Soil_Clay_Green"
    },
    {
      "x": -24,
      "y": 31,
      "z": 5,
      "name": "Soil_Seaweed_Block"
    },
    {
      "x": -24,
      "y": 32,
      "z": 5,
      "name": "Soil_Seaweed_Block"
    },
    {
      "x": -24,
      "y": 33,
      "z": 5,
      "name": "Soil_Seaweed_Block"
    },
    {
      "x": -24,
      "y": 34,
      "z": 5,
      "name": "Soil_Seaweed_Block"
    },
    {
      "x": -24,
      "y": 35,
      "z": 5,
      "name": "Soil_Clay_Lime"
    },
    {
      "x": -24,
      "y": 36,
      "z": 5,
      "name": "Plant_Grass_Sharp"
    },
    {
      "x": -24,
      "y": 11,
      "z": 6,
      "name": "Soil_Clay_Green"
    },
    {
      "x": -24,
      "y": 12,
      "z": 6,
      "name": "Soil_Seaweed_Block"
    },
    {
      "x": -24,
      "y": 13,
      "z": 6,
      "name": "Soil_Seaweed_Block"
    },
    {
      "x": -24,
      "y": 14,
      "z": 6,
      "name": "Soil_Seaweed_Block"
    },
    {
      "x": -24,
      "y": 15,
      "z": 6,
      "name": "Soil_Seaweed_Block"
    },
    {
      "x": -24,
      "y": 16,
      "z": 6,
      "name": "Soil_Seaweed_Block"
    },
    {
      "x": -24,
      "y": 17,
      "z": 6,
      "name": "Soil_Seaweed_Block"
    },
    {
      "x": -24,
      "y": 18,
      "z": 6,
      "name": "Soil_Seaweed_Block"
    },
    {
      "x": -24,
      "y": 19,
      "z": 6,
      "name": "Soil_Seaweed_Block"
    },
    {
      "x": -24,
      "y": 20,
      "z": 6,
      "name": "Soil_Seaweed_Block"
    },
    {
      "x": -24,
      "y": 21,
      "z": 6,
      "name": "Soil_Seaweed_Block"
    },
    {
      "x": -24,
      "y": 22,
      "z": 6,
      "name": "Soil_Seaweed_Block"
    },
    {
      "x": -24,
      "y": 23,
      "z": 6,
      "name": "Soil_Clay_Green"
    },
    {
      "x": -24,
      "y": 24,
      "z": 6,
      "name": "Soil_Clay_Green"
    },
    {
      "x": -24,
      "y": 25,
      "z": 6,
      "name": "Soil_Clay_Green"
    },
    {
      "x": -24,
      "y": 26,
      "z": 6,
      "name": "Soil_Clay_Green"
    },
    {
      "x": -24,
      "y": 27,
      "z": 6,
      "name": "Soil_Seaweed_Block"
    },
    {
      "x": -24,
      "y": 28,
      "z": 6,
      "name": "Soil_Clay_Green"
    },
    {
      "x": -24,
      "y": 29,
      "z": 6,
      "name": "Soil_Clay_Green"
    },
    {
      "x": -24,
      "y": 30,
      "z": 6,
      "name": "Soil_Seaweed_Block"
    },
    {
      "x": -24,
      "y": 31,
      "z": 6,
      "name": "Soil_Seaweed_Block"
    },
    {
      "x": -24,
      "y": 32,
      "z": 6,
      "name": "Soil_Seaweed_Block"
    },
    {
      "x": -24,
      "y": 33,
      "z": 6,
      "name": "Soil_Seaweed_Block"
    },
    {
      "x": -24,
      "y": 34,
      "z": 6,
      "name": "Soil_Seaweed_Block"
    },
    {
      "x": -24,
      "y": 35,
      "z": 6,
      "name": "Soil_Clay_Lime"
    },
    {
      "x": -24,
      "y": 36,
      "z": 6,
      "name": "Plant_Grass_Sharp"
    },
    {
      "x": -24,
      "y": 11,
      "z": 7,
      "name": "Soil_Clay_Green"
    },
    {
      "x": -24,
      "y": 12,
      "z": 7,
      "name": "Soil_Seaweed_Block"
    },
    {
      "x": -24,
      "y": 13,
      "z": 7,
      "name": "Soil_Seaweed_Block"
    },
    {
      "x": -24,
      "y": 14,
      "z": 7,
      "name": "Soil_Seaweed_Block"
    },
    {
      "x": -24,
      "y": 15,
      "z": 7,
      "name": "Soil_Seaweed_Block"
    },
    {
      "x": -24,
      "y": 16,
      "z": 7,
      "name": "Soil_Seaweed_Block"
    },
    {
      "x": -24,
      "y": 23,
      "z": 7,
      "name": "Soil_Clay_Green"
    },
    {
      "x": -24,
      "y": 24,
      "z": 7,
      "name": "Soil_Clay_Green"
    },
    {
      "x": -24,
      "y": 25,
      "z": 7,
      "name": "Soil_Seaweed_Block"
    },
    {
      "x": -24,
      "y": 26,
      "z": 7,
      "name": "Soil_Seaweed_Block"
    },
    {
      "x": -24,
      "y": 27,
      "z": 7,
      "name": "Soil_Seaweed_Block"
    },
    {
      "x": -24,
      "y": 28,
      "z": 7,
      "name": "Soil_Seaweed_Block"
    },
    {
      "x": -24,
      "y": 29,
      "z": 7,
      "name": "Soil_Seaweed_Block"
    },
    {
      "x": -24,
      "y": 30,
      "z": 7,
      "name": "Soil_Seaweed_Block"
    },
    {
      "x": -24,
      "y": 31,
      "z": 7,
      "name": "Soil_Seaweed_Block"
    },
    {
      "x": -24,
      "y": 32,
      "z": 7,
      "name": "Soil_Seaweed_Block"
    },
    {
      "x": -24,
      "y": 33,
      "z": 7,
      "name": "Soil_Seaweed_Block"
    },
    {
      "x": -24,
      "y": 34,
      "z": 7,
      "name": "Soil_Clay_Lime"
    },
    {
      "x": -24,
      "y": 35,
      "z": 7,
      "name": "Plant_Grass_Sharp"
    },
    {
      "x": -24,
      "y": 12,
      "z": 8,
      "name": "Soil_Clay_Green"
    },
    {
      "x": -24,
      "y": 13,
      "z": 8,
      "name": "Soil_Seaweed_Block"
    },
    {
      "x": -24,
      "y": 14,
      "z": 8,
      "name": "Soil_Seaweed_Block"
    },
    {
      "x": -24,
      "y": 15,
      "z": 8,
      "name": "Soil_Seaweed_Block"
    },
    {
      "x": -24,
      "y": 25,
      "z": 8,
      "name": "Soil_Clay_Green"
    },
    {
      "x": -24,
      "y": 26,
      "z": 8,
      "name": "Soil_Seaweed_Block"
    },
    {
      "x": -24,
      "y": 27,
      "z": 8,
      "name": "Soil_Seaweed_Block"
    },
    {
      "x": -24,
      "y": 28,
      "z": 8,
      "name": "Soil_Seaweed_Block"
    },
    {
      "x": -24,
      "y": 29,
      "z": 8,
      "name": "Soil_Seaweed_Block"
    },
    {
      "x": -24,
      "y": 30,
      "z": 8,
      "name": "Soil_Seaweed_Block"
    },
    {
      "x": -24,
      "y": 31,
      "z": 8,
      "name": "Soil_Seaweed_Block"
    },
    {
      "x": -24,
      "y": 32,
      "z": 8,
      "name": "Soil_Seaweed_Block"
    },
    {
      "x": -24,
      "y": 33,
      "z": 8,
      "name": "Soil_Seaweed_Block"
    },
    {
      "x": -24,
      "y": 12,
      "z": 9,
      "name": "Soil_Clay_Green"
    },
    {
      "x": -24,
      "y": 13,
      "z": 9,
      "name": "Soil_Seaweed_Block"
    },
    {
      "x": -24,
      "y": 14,
      "z": 9,
      "name": "Soil_Seaweed_Block"
    },
    {
      "x": -24,
      "y": 26,
      "z": 9,
      "name": "Soil_Clay_Green"
    },
    {
      "x": -24,
      "y": 27,
      "z": 9,
      "name": "Soil_Seaweed_Block"
    },
    {
      "x": -24,
      "y": 28,
      "z": 9,
      "name": "Soil_Seaweed_Block"
    },
    {
      "x": -24,
      "y": 29,
      "z": 9,
      "name": "Soil_Seaweed_Block"
    },
    {
      "x": -24,
      "y": 30,
      "z": 9,
      "name": "Soil_Seaweed_Block"
    },
    {
      "x": -24,
      "y": 31,
      "z": 9,
      "name": "Soil_Seaweed_Block"
    },
    {
      "x": -24,
      "y": 26,
      "z": 10,
      "name": "Soil_Clay_Green"
    },
    {
      "x": -24,
      "y": 27,
      "z": 10,
      "name": "Soil_Clay_Green"
    },
    {
      "x": -24,
      "y": 28,
      "z": 10,
      "name": "Soil_Seaweed_Block"
    },
    {
      "x": -24,
      "y": 29,
      "z": 10,
      "name": "Soil_Seaweed_Block"
    },
    {
      "x": -24,
      "y": 30,
      "z": 10,
      "name": "Soil_Seaweed_Block"
    },
    {
      "x": -23,
      "y": 17,
      "z": -16,
      "name": "Soil_Clay_Green"
    },
    {
      "x": -23,
      "y": 18,
      "z": -16,
      "name": "Soil_Seaweed_Block"
    },
    {
      "x": -23,
      "y": 28,
      "z": -16,
      "name": "Soil_Seaweed_Block"
    },
    {
      "x": -23,
      "y": 17,
      "z": -15,
      "name": "Soil_Seaweed_Block"
    },
    {
      "x": -23,
      "y": 18,
      "z": -15,
      "name": "Soil_Seaweed_Block"
    },
    {
      "x": -23,
      "y": 16,
      "z": -14,
      "name": "Soil_Clay_Green"
    },
    {
      "x": -23,
      "y": 17,
      "z": -14,
      "name": "Soil_Seaweed_Block"
    },
    {
      "x": -23,
      "y": 18,
      "z": -14,
      "name": "Soil_Seaweed_Block"
    },
    {
      "x": -23,
      "y": 15,
      "z": -13,
      "name": "Soil_Clay_Green"
    },
    {
      "x": -23,
      "y": 16,
      "z": -13,
      "name": "Soil_Seaweed_Block"
    },
    {
      "x": -23,
      "y": 17,
      "z": -13,
      "name": "Soil_Seaweed_Block"
    },
    {
      "x": -23,
      "y": 18,
      "z": -13,
      "name": "Soil_Clay_Lime"
    },
    {
      "x": -23,
      "y": 19,
      "z": -13,
      "name": "Plant_Grass_Sharp"
    },
    {
      "x": -23,
      "y": 13,
      "z": -12,
      "name": "Soil_Clay_Green"
    },
    {
      "x": -23,
      "y": 14,
      "z": -12,
      "name": "Soil_Clay_Green"
    },
    {
      "x": -23,
      "y": 15,
      "z": -12,
      "name": "Soil_Seaweed_Block"
    },
    {
      "x": -23,
      "y": 16,
      "z": -12,
      "name": "Soil_Seaweed_Block"
    },
    {
      "x": -23,
      "y": 17,
      "z": -12,
      "name": "Soil_Seaweed_Block"
    },
    {
      "x": -23,
      "y": 18,
      "z": -12,
      "name": "Soil_Clay_Lime"
    },
    {
      "x": -23,
      "y": 19,
      "z": -12,
      "name": "Plant_Grass_Sharp"
    },
    {
      "x": -23,
      "y": 12,
      "z": -11,
      "name": "Soil_Clay_Green"
    },
    {
      "x": -23,
      "y": 13,
      "z": -11,
      "name": "Soil_Seaweed_Block"
    },
    {
      "x": -23,
      "y": 14,
      "z": -11,
      "name": "Soil_Seaweed_Block"
    },
    {
      "x": -23,
      "y": 15,
      "z": -11,
      "name": "Soil_Seaweed_Block"
    },
    {
      "x": -23,
      "y": 16,
      "z": -11,
      "name": "Soil_Seaweed_Block"
    },
    {
      "x": -23,
      "y": 17,
      "z": -11,
      "name": "Soil_Seaweed_Block"
    },
    {
      "x": -23,
      "y": 18,
      "z": -11,
      "name": "Soil_Clay_Lime"
    },
    {
      "x": -23,
      "y": 19,
      "z": -11,
      "name": "Plant_Grass_Sharp"
    },
    {
      "x": -23,
      "y": 29,
      "z": -11,
      "name": "Soil_Seaweed_Block"
    },
    {
      "x": -23,
      "y": 30,
      "z": -11,
      "name": "Soil_Seaweed_Block"
    },
    {
      "x": -23,
      "y": 13,
      "z": -10,
      "name": "Soil_Clay_Green"
    },
    {
      "x": -23,
      "y": 14,
      "z": -10,
      "name": "Soil_Seaweed_Block"
    },
    {
      "x": -23,
      "y": 15,
      "z": -10,
      "name": "Soil_Seaweed_Block"
    },
    {
      "x": -23,
      "y": 16,
      "z": -10,
      "name": "Soil_Seaweed_Block"
    },
    {
      "x": -23,
      "y": 17,
      "z": -10,
      "name": "Soil_Seaweed_Block"
    },
    {
      "x": -23,
      "y": 18,
      "z": -10,
      "name": "Soil_Clay_Lime"
    },
    {
      "x": -23,
      "y": 19,
      "z": -10,
      "name": "Plant_Grass_Sharp"
    },
    {
      "x": -23,
      "y": 28,
      "z": -10,
      "name": "Soil_Clay_Green"
    },
    {
      "x": -23,
      "y": 29,
      "z": -10,
      "name": "Soil_Seaweed_Block"
    },
    {
      "x": -23,
      "y": 30,
      "z": -10,
      "name": "Soil_Seaweed_Block"
    },
    {
      "x": -23,
      "y": 31,
      "z": -10,
      "name": "Soil_Seaweed_Block"
    },
    {
      "x": -23,
      "y": 14,
      "z": -9,
      "name": "Soil_Clay_Green"
    },
    {
      "x": -23,
      "y": 15,
      "z": -9,
      "name": "Soil_Seaweed_Block"
    },
    {
      "x": -23,
      "y": 16,
      "z": -9,
      "name": "Soil_Seaweed_Block"
    },
    {
      "x": -23,
      "y": 17,
      "z": -9,
      "name": "Soil_Seaweed_Block"
    },
    {
      "x": -23,
      "y": 18,
      "z": -9,
      "name": "Soil_Seaweed_Block"
    },
    {
      "x": -23,
      "y": 19,
      "z": -9,
      "name": "Soil_Clay_Lime"
    },
    {
      "x": -23,
      "y": 20,
      "z": -9,
      "name": "Plant_Grass_Sharp"
    },
    {
      "x": -23,
      "y": 27,
      "z": -9,
      "name": "Soil_Clay_Green"
    },
    {
      "x": -23,
      "y": 28,
      "z": -9,
      "name": "Soil_Seaweed_Block"
    },
    {
      "x": -23,
      "y": 29,
      "z": -9,
      "name": "Soil_Seaweed_Block"
    },
    {
      "x": -23,
      "y": 30,
      "z": -9,
      "name": "Soil_Seaweed_Block"
    },
    {
      "x": -23,
      "y": 31,
      "z": -9,
      "name": "Soil_Seaweed_Block"
    },
    {
      "x": -23,
      "y": 32,
      "z": -9,
      "name": "Soil_Clay_Lime"
    },
    {
      "x": -23,
      "y": 33,
      "z": -9,
      "name": "Plant_Grass_Sharp"
    },
    {
      "x": -23,
      "y": 15,
      "z": -8,
      "name": "Soil_Seaweed_Block"
    },
    {
      "x": -23,
      "y": 16,
      "z": -8,
      "name": "Soil_Seaweed_Block"
    },
    {
      "x": -23,
      "y": 17,
      "z": -8,
      "name": "Soil_Seaweed_Block"
    },
    {
      "x": -23,
      "y": 18,
      "z": -8,
      "name": "Soil_Seaweed_Block"
    },
    {
      "x": -23,
      "y": 19,
      "z": -8,
      "name": "Soil_Seaweed_Block"
    },
    {
      "x": -23,
      "y": 20,
      "z": -8,
      "name": "Soil_Seaweed_Block"
    },
    {
      "x": -23,
      "y": 21,
      "z": -8,
      "name": "Soil_Seaweed_Block"
    },
    {
      "x": -23,
      "y": 22,
      "z": -8,
      "name": "Soil_Seaweed_Block"
    },
    {
      "x": -23,
      "y": 26,
      "z": -8,
      "name": "Soil_Clay_Green"
    },
    {
      "x": -23,
      "y": 27,
      "z": -8,
      "name": "Soil_Clay_Green"
    },
    {
      "x": -23,
      "y": 28,
      "z": -8,
      "name": "Soil_Seaweed_Block"
    },
    {
      "x": -23,
      "y": 29,
      "z": -8,
      "name": "Soil_Seaweed_Block"
    },
    {
      "x": -23,
      "y": 30,
      "z": -8,
      "name": "Soil_Seaweed_Block"
    },
    {
      "x": -23,
      "y": 31,
      "z": -8,
      "name": "Soil_Seaweed_Block"
    },
    {
      "x": -23,
      "y": 32,
      "z": -8,
      "name": "Soil_Clay_Lime"
    },
    {
      "x": -23,
      "y": 33,
      "z": -8,
      "name": "Plant_Grass_Sharp"
    },
    {
      "x": -23,
      "y": 19,
      "z": -7,
      "name": "Soil_Clay_Green"
    },
    {
      "x": -23,
      "y": 20,
      "z": -7,
      "name": "Soil_Seaweed_Block"
    },
    {
      "x": -23,
      "y": 21,
      "z": -7,
      "name": "Soil_Seaweed_Block"
    },
    {
      "x": -23,
      "y": 22,
      "z": -7,
      "name": "Soil_Seaweed_Block"
    },
    {
      "x": -23,
      "y": 23,
      "z": -7,
      "name": "Soil_Seaweed_Block"
    },
    {
      "x": -23,
      "y": 24,
      "z": -7,
      "name": "Soil_Seaweed_Block"
    },
    {
      "x": -23,
      "y": 25,
      "z": -7,
      "name": "Soil_Clay_Green"
    },
    {
      "x": -23,
      "y": 26,
      "z": -7,
      "name": "Soil_Seaweed_Block"
    },
    {
      "x": -23,
      "y": 27,
      "z": -7,
      "name": "Soil_Seaweed_Block"
    },
    {
      "x": -23,
      "y": 28,
      "z": -7,
      "name": "Soil_Seaweed_Block"
    },
    {
      "x": -23,
      "y": 29,
      "z": -7,
      "name": "Soil_Seaweed_Block"
    },
    {
      "x": -23,
      "y": 30,
      "z": -7,
      "name": "Soil_Seaweed_Block"
    },
    {
      "x": -23,
      "y": 31,
      "z": -7,
      "name": "Soil_Seaweed_Block"
    },
    {
      "x": -23,
      "y": 20,
      "z": -6,
      "name": "Soil_Clay_Green"
    },
    {
      "x": -23,
      "y": 21,
      "z": -6,
      "name": "Soil_Seaweed_Block"
    },
    {
      "x": -23,
      "y": 22,
      "z": -6,
      "name": "Soil_Seaweed_Block"
    },
    {
      "x": -23,
      "y": 23,
      "z": -6,
      "name": "Soil_Seaweed_Block"
    },
    {
      "x": -23,
      "y": 24,
      "z": -6,
      "name": "Soil_Seaweed_Block"
    },
    {
      "x": -23,
      "y": 25,
      "z": -6,
      "name": "Soil_Seaweed_Block"
    },
    {
      "x": -23,
      "y": 26,
      "z": -6,
      "name": "Soil_Seaweed_Block"
    },
    {
      "x": -23,
      "y": 27,
      "z": -6,
      "name": "Soil_Seaweed_Block"
    },
    {
      "x": -23,
      "y": 28,
      "z": -6,
      "name": "Soil_Seaweed_Block"
    },
    {
      "x": -23,
      "y": 29,
      "z": -6,
      "name": "Soil_Seaweed_Block"
    },
    {
      "x": -23,
      "y": 30,
      "z": -6,
      "name": "Soil_Seaweed_Block"
    },
    {
      "x": -23,
      "y": 21,
      "z": -5,
      "name": "Soil_Clay_Green"
    },
    {
      "x": -23,
      "y": 22,
      "z": -5,
      "name": "Soil_Seaweed_Block"
    },
    {
      "x": -23,
      "y": 23,
      "z": -5,
      "name": "Soil_Seaweed_Block"
    },
    {
      "x": -23,
      "y": 24,
      "z": -5,
      "name": "Soil_Seaweed_Block"
    },
    {
      "x": -23,
      "y": 25,
      "z": -5,
      "name": "Soil_Seaweed_Block"
    },
    {
      "x": -23,
      "y": 26,
      "z": -5,
      "name": "Soil_Seaweed_Block"
    },
    {
      "x": -23,
      "y": 27,
      "z": -5,
      "name": "Soil_Seaweed_Block"
    },
    {
      "x": -23,
      "y": 28,
      "z": -5,
      "name": "Soil_Seaweed_Block"
    },
    {
      "x": -23,
      "y": 29,
      "z": -5,
      "name": "Soil_Clay_Lime"
    },
    {
      "x": -23,
      "y": 30,
      "z": -5,
      "name": "Plant_Grass_Sharp"
    },
    {
      "x": -23,
      "y": 21,
      "z": -4,
      "name": "Soil_Clay_Green"
    },
    {
      "x": -23,
      "y": 22,
      "z": -4,
      "name": "Soil_Seaweed_Block"
    },
    {
      "x": -23,
      "y": 23,
      "z": -4,
      "name": "Soil_Seaweed_Block"
    },
    {
      "x": -23,
      "y": 24,
      "z": -4,
      "name": "Soil_Seaweed_Block"
    },
    {
      "x": -23,
      "y": 25,
      "z": -4,
      "name": "Soil_Seaweed_Block"
    },
    {
      "x": -23,
      "y": 26,
      "z": -4,
      "name": "Soil_Seaweed_Block"
    },
    {
      "x": -23,
      "y": 27,
      "z": -4,
      "name": "Soil_Seaweed_Block"
    },
    {
      "x": -23,
      "y": 28,
      "z": -4,
      "name": "Soil_Seaweed_Block"
    },
    {
      "x": -23,
      "y": 29,
      "z": -4,
      "name": "Soil_Clay_Lime"
    },
    {
      "x": -23,
      "y": 30,
      "z": -4,
      "name": "Plant_Grass_Sharp"
    },
    {
      "x": -23,
      "y": 21,
      "z": -3,
      "name": "Soil_Clay_Green"
    },
    {
      "x": -23,
      "y": 22,
      "z": -3,
      "name": "Soil_Clay_Green"
    },
    {
      "x": -23,
      "y": 23,
      "z": -3,
      "name": "Soil_Seaweed_Block"
    },
    {
      "x": -23,
      "y": 24,
      "z": -3,
      "name": "Soil_Seaweed_Block"
    },
    {
      "x": -23,
      "y": 25,
      "z": -3,
      "name": "Soil_Seaweed_Block"
    },
    {
      "x": -23,
      "y": 26,
      "z": -3,
      "name": "Soil_Seaweed_Block"
    },
    {
      "x": -23,
      "y": 27,
      "z": -3,
      "name": "Soil_Seaweed_Block"
    },
    {
      "x": -23,
      "y": 28,
      "z": -3,
      "name": "Soil_Seaweed_Block"
    },
    {
      "x": -23,
      "y": 29,
      "z": -3,
      "name": "Soil_Clay_Lime"
    },
    {
      "x": -23,
      "y": 30,
      "z": -3,
      "name": "Plant_Grass_Sharp"
    },
    {
      "x": -23,
      "y": 20,
      "z": -2,
      "name": "Soil_Clay_Green"
    },
    {
      "x": -23,
      "y": 21,
      "z": -2,
      "name": "Soil_Clay_Green"
    },
    {
      "x": -23,
      "y": 22,
      "z": -2,
      "name": "Soil_Seaweed_Block"
    },
    {
      "x": -23,
      "y": 23,
      "z": -2,
      "name": "Soil_Seaweed_Block"
    },
    {
      "x": -23,
      "y": 27,
      "z": -2,
      "name": "Soil_Clay_Green"
    },
    {
      "x": -23,
      "y": 28,
      "z": -2,
      "name": "Soil_Seaweed_Block"
    },
    {
      "x": -23,
      "y": 29,
      "z": -2,
      "name": "Soil_Seaweed_Block"
    },
    {
      "x": -23,
      "y": 30,
      "z": -2,
      "name": "Soil_Clay_Lime"
    },
    {
      "x": -23,
      "y": 31,
      "z": -2,
      "name": "Plant_Grass_Sharp"
    },
    {
      "x": -23,
      "y": 20,
      "z": -1,
      "name": "Soil_Clay_Green"
    },
    {
      "x": -23,
      "y": 21,
      "z": -1,
      "name": "Soil_Seaweed_Block"
    },
    {
      "x": -23,
      "y": 22,
      "z": -1,
      "name": "Soil_Seaweed_Block"
    },
    {
      "x": -23,
      "y": 28,
      "z": -1,
      "name": "Soil_Clay_Green"
    },
    {
      "x": -23,
      "y": 29,
      "z": -1,
      "name": "Soil_Seaweed_Block"
    },
    {
      "x": -23,
      "y": 30,
      "z": -1,
      "name": "Soil_Clay_Lime"
    },
    {
      "x": -23,
      "y": 31,
      "z": -1,
      "name": "Plant_Grass_Sharp"
    },
    {
      "x": -23,
      "y": 12,
      "z": 0,
      "name": "Soil_Clay_Green"
    },
    {
      "x": -23,
      "y": 13,
      "z": 0,
      "name": "Soil_Seaweed_Block"
    },
    {
      "x": -23,
      "y": 19,
      "z": 0,
      "name": "Soil_Clay_Green"
    },
    {
      "x": -23,
      "y": 20,
      "z": 0,
      "name": "Soil_Seaweed_Block"
    },
    {
      "x": -23,
      "y": 21,
      "z": 0,
      "name": "Soil_Seaweed_Block"
    },
    {
      "x": -23,
      "y": 29,
      "z": 0,
      "name": "Soil_Clay_Green"
    },
    {
      "x": -23,
      "y": 30,
      "z": 0,
      "name": "Soil_Seaweed_Block"
    },
    {
      "x": -23,
      "y": 31,
      "z": 0,
      "name": "Soil_Clay_Lime"
    },
    {
      "x": -23,
      "y": 32,
      "z": 0,
      "name": "Plant_Grass_Sharp"
    },
    {
      "x": -23,
      "y": 12,
      "z": 1,
      "name": "Soil_Clay_Green"
    },
    {
      "x": -23,
      "y": 13,
      "z": 1,
      "name": "Soil_Seaweed_Block"
    },
    {
      "x": -23,
      "y": 18,
      "z": 1,
      "name": "Soil_Clay_Green"
    },
    {
      "x": -23,
      "y": 19,
      "z": 1,
      "name": "Soil_Clay_Green"
    },
    {
      "x": -23,
      "y": 20,
      "z": 1,
      "name": "Soil_Seaweed_Block"
    },
    {
      "x": -23,
      "y": 21,
      "z": 1,
      "name": "Soil_Seaweed_Block"
    },
    {
      "x": -23,
      "y": 29,
      "z": 1,
      "name": "Soil_Clay_Green"
    },
    {
      "x": -23,
      "y": 30,
      "z": 1,
      "name": "Soil_Seaweed_Block"
    },
    {
      "x": -23,
      "y": 31,
      "z": 1,
      "name": "Soil_Seaweed_Block"
    },
    {
      "x": -23,
      "y": 32,
      "z": 1,
      "name": "Soil_Seaweed_Block"
    },
    {
      "x": -23,
      "y": 12,
      "z": 2,
      "name": "Soil_Clay_Green"
    },
    {
      "x": -23,
      "y": 13,
      "z": 2,
      "name": "Soil_Seaweed_Block"
    },
    {
      "x": -23,
      "y": 14,
      "z": 2,
      "name": "Soil_Seaweed_Block"
    },
    {
      "x": -23,
      "y": 15,
      "z": 2,
      "name": "Soil_Seaweed_Block"
    },
    {
      "x": -23,
      "y": 16,
      "z": 2,
      "name": "Soil_Seaweed_Block"
    },
    {
      "x": -23,
      "y": 17,
      "z": 2,
      "name": "Soil_Clay_Green"
    },
    {
      "x": -23,
      "y": 18,
      "z": 2,
      "name": "Soil_Seaweed_Block"
    },
    {
      "x": -23,
      "y": 19,
      "z": 2,
      "name": "Soil_Seaweed_Block"
    },
    {
      "x": -23,
      "y": 20,
      "z": 2,
      "name": "Soil_Seaweed_Block"
    },
    {
      "x": -23,
      "y": 21,
      "z": 2,
      "name": "Soil_Clay_Lime"
    },
    {
      "x": -23,
      "y": 22,
      "z": 2,
      "name": "Plant_Grass_Sharp"
    },
    {
      "x": -23,
      "y": 30,
      "z": 2,
      "name": "Soil_Clay_Green"
    },
    {
      "x": -23,
      "y": 31,
      "z": 2,
      "name": "Soil_Seaweed_Block"
    },
    {
      "x": -23,
      "y": 32,
      "z": 2,
      "name": "Soil_Seaweed_Block"
    },
    {
      "x": -23,
      "y": 33,
      "z": 2,
      "name": "Soil_Seaweed_Block"
    },
    {
      "x": -23,
      "y": 12,
      "z": 3,
      "name": "Soil_Clay_Green"
    },
    {
      "x": -23,
      "y": 13,
      "z": 3,
      "name": "Soil_Clay_Green"
    },
    {
      "x": -23,
      "y": 14,
      "z": 3,
      "name": "Soil_Seaweed_Block"
    },
    {
      "x": -23,
      "y": 15,
      "z": 3,
      "name": "Soil_Seaweed_Block"
    },
    {
      "x": -23,
      "y": 16,
      "z": 3,
      "name": "Soil_Seaweed_Block"
    },
    {
      "x": -23,
      "y": 17,
      "z": 3,
      "name": "Soil_Seaweed_Block"
    },
    {
      "x": -23,
      "y": 18,
      "z": 3,
      "name": "Soil_Seaweed_Block"
    },
    {
      "x": -23,
      "y": 19,
      "z": 3,
      "name": "Soil_Seaweed_Block"
    },
    {
      "x": -23,
      "y": 20,
      "z": 3,
      "name": "Soil_Seaweed_Block"
    },
    {
      "x": -23,
      "y": 21,
      "z": 3,
      "name": "Soil_Clay_Lime"
    },
    {
      "x": -23,
      "y": 22,
      "z": 3,
      "name": "Plant_Grass_Sharp"
    },
    {
      "x": -23,
      "y": 30,
      "z": 3,
      "name": "Soil_Clay_Green"
    },
    {
      "x": -23,
      "y": 31,
      "z": 3,
      "name": "Soil_Seaweed_Block"
    },
    {
      "x": -23,
      "y": 32,
      "z": 3,
      "name": "Soil_Seaweed_Block"
    },
    {
      "x": -23,
      "y": 33,
      "z": 3,
      "name": "Soil_Seaweed_Block"
    },
    {
      "x": -23,
      "y": 34,
      "z": 3,
      "name": "Soil_Clay_Lime"
    },
    {
      "x": -23,
      "y": 35,
      "z": 3,
      "name": "Plant_Grass_Sharp"
    },
    {
      "x": -23,
      "y": 12,
      "z": 4,
      "name": "Soil_Clay_Green"
    },
    {
      "x": -23,
      "y": 13,
      "z": 4,
      "name": "Soil_Seaweed_Block"
    },
    {
      "x": -23,
      "y": 14,
      "z": 4,
      "name": "Soil_Seaweed_Block"
    },
    {
      "x": -23,
      "y": 15,
      "z": 4,
      "name": "Soil_Seaweed_Block"
    },
    {
      "x": -23,
      "y": 16,
      "z": 4,
      "name": "Soil_Seaweed_Block"
    },
    {
      "x": -23,
      "y": 17,
      "z": 4,
      "name": "Soil_Seaweed_Block"
    },
    {
      "x": -23,
      "y": 18,
      "z": 4,
      "name": "Soil_Seaweed_Block"
    },
    {
      "x": -23,
      "y": 19,
      "z": 4,
      "name": "Soil_Seaweed_Block"
    },
    {
      "x": -23,
      "y": 20,
      "z": 4,
      "name": "Soil_Seaweed_Block"
    },
    {
      "x": -23,
      "y": 21,
      "z": 4,
      "name": "Soil_Seaweed_Block"
    },
    {
      "x": -23,
      "y": 22,
      "z": 4,
      "name": "Soil_Clay_Lime"
    },
    {
      "x": -23,
      "y": 23,
      "z": 4,
      "name": "Plant_Grass_Sharp"
    },
    {
      "x": -23,
      "y": 30,
      "z": 4,
      "name": "Soil_Clay_Green"
    },
    {
      "x": -23,
      "y": 31,
      "z": 4,
      "name": "Soil_Seaweed_Block"
    },
    {
      "x": -23,
      "y": 32,
      "z": 4,
      "name": "Soil_Seaweed_Block"
    },
    {
      "x": -23,
      "y": 33,
      "z": 4,
      "name": "Soil_Seaweed_Block"
    },
    {
      "x": -23,
      "y": 34,
      "z": 4,
      "name": "Soil_Seaweed_Block"
    },
    {
      "x": -23,
      "y": 35,
      "z": 4,
      "name": "Soil_Clay_Lime"
    },
    {
      "x": -23,
      "y": 36,
      "z": 4,
      "name": "Plant_Grass_Sharp"
    },
    {
      "x": -23,
      "y": 11,
      "z": 5,
      "name": "Soil_Clay_Green"
    },
    {
      "x": -23,
      "y": 12,
      "z": 5,
      "name": "Soil_Seaweed_Block"
    },
    {
      "x": -23,
      "y": 13,
      "z": 5,
      "name": "Soil_Seaweed_Block"
    },
    {
      "x": -23,
      "y": 14,
      "z": 5,
      "name": "Soil_Seaweed_Block"
    },
    {
      "x": -23,
      "y": 15,
      "z": 5,
      "name": "Soil_Seaweed_Block"
    },
    {
      "x": -23,
      "y": 16,
      "z": 5,
      "name": "Soil_Seaweed_Block"
    },
    {
      "x": -23,
      "y": 17,
      "z": 5,
      "name": "Soil_Seaweed_Block"
    },
    {
      "x": -23,
      "y": 18,
      "z": 5,
      "name": "Soil_Seaweed_Block"
    },
    {
      "x": -23,
      "y": 19,
      "z": 5,
      "name": "Soil_Seaweed_Block"
    },
    {
      "x": -23,
      "y": 20,
      "z": 5,
      "name": "Soil_Seaweed_Block"
    },
    {
      "x": -23,
      "y": 21,
      "z": 5,
      "name": "Soil_Seaweed_Block"
    },
    {
      "x": -23,
      "y": 22,
      "z": 5,
      "name": "Soil_Seaweed_Block"
    },
    {
      "x": -23,
      "y": 23,
      "z": 5,
      "name": "Soil_Seaweed_Block"
    },
    {
      "x": -23,
      "y": 24,
      "z": 5,
      "name": "Soil_Seaweed_Block"
    },
    {
      "x": -23,
      "y": 25,
      "z": 5,
      "name": "Soil_Seaweed_Block"
    },
    {
      "x": -23,
      "y": 26,
      "z": 5,
      "name": "Soil_Seaweed_Block"
    },
    {
      "x": -23,
      "y": 29,
      "z": 5,
      "name": "Soil_Clay_Green"
    },
    {
      "x": -23,
      "y": 30,
      "z": 5,
      "name": "Soil_Seaweed_Block"
    },
    {
      "x": -23,
      "y": 31,
      "z": 5,
      "name": "Soil_Seaweed_Block"
    },
    {
      "x": -23,
      "y": 32,
      "z": 5,
      "name": "Soil_Seaweed_Block"
    },
    {
      "x": -23,
      "y": 33,
      "z": 5,
      "name": "Soil_Seaweed_Block"
    },
    {
      "x": -23,
      "y": 34,
      "z": 5,
      "name": "Soil_Seaweed_Block"
    },
    {
      "x": -23,
      "y": 35,
      "z": 5,
      "name": "Soil_Clay_Lime"
    },
    {
      "x": -23,
      "y": 36,
      "z": 5,
      "name": "Plant_Grass_Sharp"
    },
    {
      "x": -23,
      "y": 11,
      "z": 6,
      "name": "Soil_Clay_Green"
    },
    {
      "x": -23,
      "y": 12,
      "z": 6,
      "name": "Soil_Seaweed_Block"
    },
    {
      "x": -23,
      "y": 13,
      "z": 6,
      "name": "Soil_Seaweed_Block"
    },
    {
      "x": -23,
      "y": 14,
      "z": 6,
      "name": "Soil_Seaweed_Block"
    },
    {
      "x": -23,
      "y": 15,
      "z": 6,
      "name": "Soil_Seaweed_Block"
    },
    {
      "x": -23,
      "y": 16,
      "z": 6,
      "name": "Soil_Seaweed_Block"
    },
    {
      "x": -23,
      "y": 17,
      "z": 6,
      "name": "Soil_Seaweed_Block"
    },
    {
      "x": -23,
      "y": 18,
      "z": 6,
      "name": "Soil_Seaweed_Block"
    },
    {
      "x": -23,
      "y": 19,
      "z": 6,
      "name": "Soil_Seaweed_Block"
    },
    {
      "x": -23,
      "y": 20,
      "z": 6,
      "name": "Soil_Seaweed_Block"
    },
    {
      "x": -23,
      "y": 21,
      "z": 6,
      "name": "Soil_Seaweed_Block"
    },
    {
      "x": -23,
      "y": 22,
      "z": 6,
      "name": "Soil_Seaweed_Block"
    },
    {
      "x": -23,
      "y": 23,
      "z": 6,
      "name": "Soil_Seaweed_Block"
    },
    {
      "x": -23,
      "y": 24,
      "z": 6,
      "name": "Soil_Seaweed_Block"
    },
    {
      "x": -23,
      "y": 25,
      "z": 6,
      "name": "Soil_Seaweed_Block"
    },
    {
      "x": -23,
      "y": 26,
      "z": 6,
      "name": "Soil_Seaweed_Block"
    },
    {
      "x": -23,
      "y": 27,
      "z": 6,
      "name": "Soil_Seaweed_Block"
    },
    {
      "x": -23,
      "y": 28,
      "z": 6,
      "name": "Soil_Clay_Green"
    },
    {
      "x": -23,
      "y": 29,
      "z": 6,
      "name": "Soil_Seaweed_Block"
    },
    {
      "x": -23,
      "y": 30,
      "z": 6,
      "name": "Soil_Seaweed_Block"
    },
    {
      "x": -23,
      "y": 31,
      "z": 6,
      "name": "Soil_Seaweed_Block"
    },
    {
      "x": -23,
      "y": 32,
      "z": 6,
      "name": "Soil_Seaweed_Block"
    },
    {
      "x": -23,
      "y": 33,
      "z": 6,
      "name": "Soil_Seaweed_Block"
    },
    {
      "x": -23,
      "y": 34,
      "z": 6,
      "name": "Soil_Seaweed_Block"
    },
    {
      "x": -23,
      "y": 35,
      "z": 6,
      "name": "Soil_Clay_Lime"
    },
    {
      "x": -23,
      "y": 36,
      "z": 6,
      "name": "Plant_Grass_Sharp"
    },
    {
      "x": -23,
      "y": 11,
      "z": 7,
      "name": "Soil_Clay_Green"
    },
    {
      "x": -23,
      "y": 12,
      "z": 7,
      "name": "Soil_Seaweed_Block"
    },
    {
      "x": -23,
      "y": 13,
      "z": 7,
      "name": "Soil_Seaweed_Block"
    },
    {
      "x": -23,
      "y": 14,
      "z": 7,
      "name": "Soil_Seaweed_Block"
    },
    {
      "x": -23,
      "y": 15,
      "z": 7,
      "name": "Soil_Seaweed_Block"
    },
    {
      "x": -23,
      "y": 16,
      "z": 7,
      "name": "Soil_Seaweed_Block"
    },
    {
      "x": -23,
      "y": 17,
      "z": 7,
      "name": "Soil_Clay_Lime"
    },
    {
      "x": -23,
      "y": 18,
      "z": 7,
      "name": "Plant_Grass_Sharp"
    },
    {
      "x": -23,
      "y": 22,
      "z": 7,
      "name": "Soil_Seaweed_Block"
    },
    {
      "x": -23,
      "y": 23,
      "z": 7,
      "name": "Soil_Clay_Green"
    },
    {
      "x": -23,
      "y": 24,
      "z": 7,
      "name": "Soil_Seaweed_Block"
    },
    {
      "x": -23,
      "y": 25,
      "z": 7,
      "name": "Soil_Seaweed_Block"
    },
    {
      "x": -23,
      "y": 26,
      "z": 7,
      "name": "Soil_Seaweed_Block"
    },
    {
      "x": -23,
      "y": 27,
      "z": 7,
      "name": "Soil_Seaweed_Block"
    },
    {
      "x": -23,
      "y": 28,
      "z": 7,
      "name": "Soil_Seaweed_Block"
    },
    {
      "x": -23,
      "y": 29,
      "z": 7,
      "name": "Soil_Seaweed_Block"
    },
    {
      "x": -23,
      "y": 30,
      "z": 7,
      "name": "Soil_Seaweed_Block"
    },
    {
      "x": -23,
      "y": 31,
      "z": 7,
      "name": "Soil_Seaweed_Block"
    },
    {
      "x": -23,
      "y": 32,
      "z": 7,
      "name": "Soil_Seaweed_Block"
    },
    {
      "x": -23,
      "y": 33,
      "z": 7,
      "name": "Soil_Seaweed_Block"
    },
    {
      "x": -23,
      "y": 34,
      "z": 7,
      "name": "Soil_Seaweed_Block"
    },
    {
      "x": -23,
      "y": 12,
      "z": 8,
      "name": "Soil_Clay_Green"
    },
    {
      "x": -23,
      "y": 13,
      "z": 8,
      "name": "Soil_Seaweed_Block"
    },
    {
      "x": -23,
      "y": 14,
      "z": 8,
      "name": "Soil_Seaweed_Block"
    },
    {
      "x": -23,
      "y": 15,
      "z": 8,
      "name": "Soil_Seaweed_Block"
    },
    {
      "x": -23,
      "y": 16,
      "z": 8,
      "name": "Soil_Clay_Lime"
    },
    {
      "x": -23,
      "y": 17,
      "z": 8,
      "name": "Plant_Grass_Sharp"
    },
    {
      "x": -23,
      "y": 24,
      "z": 8,
      "name": "Soil_Clay_Green"
    },
    {
      "x": -23,
      "y": 25,
      "z": 8,
      "name": "Soil_Seaweed_Block"
    },
    {
      "x": -23,
      "y": 26,
      "z": 8,
      "name": "Soil_Seaweed_Block"
    },
    {
      "x": -23,
      "y": 27,
      "z": 8,
      "name": "Soil_Seaweed_Block"
    },
    {
      "x": -23,
      "y": 28,
      "z": 8,
      "name": "Soil_Seaweed_Block"
    },
    {
      "x": -23,
      "y": 29,
      "z": 8,
      "name": "Soil_Seaweed_Block"
    },
    {
      "x": -23,
      "y": 30,
      "z": 8,
      "name": "Soil_Seaweed_Block"
    },
    {
      "x": -23,
      "y": 31,
      "z": 8,
      "name": "Soil_Seaweed_Block"
    },
    {
      "x": -23,
      "y": 32,
      "z": 8,
      "name": "Soil_Seaweed_Block"
    },
    {
      "x": -23,
      "y": 13,
      "z": 9,
      "name": "Soil_Clay_Green"
    },
    {
      "x": -23,
      "y": 14,
      "z": 9,
      "name": "Soil_Seaweed_Block"
    },
    {
      "x": -23,
      "y": 15,
      "z": 9,
      "name": "Soil_Seaweed_Block"
    },
    {
      "x": -23,
      "y": 16,
      "z": 9,
      "name": "Soil_Seaweed_Block"
    },
    {
      "x": -23,
      "y": 17,
      "z": 9,
      "name": "Soil_Seaweed_Block"
    },
    {
      "x": -23,
      "y": 25,
      "z": 9,
      "name": "Soil_Clay_Green"
    },
    {
      "x": -23,
      "y": 26,
      "z": 9,
      "name": "Soil_Seaweed_Block"
    },
    {
      "x": -23,
      "y": 27,
      "z": 9,
      "name": "Soil_Seaweed_Block"
    },
    {
      "x": -23,
      "y": 28,
      "z": 9,
      "name": "Soil_Seaweed_Block"
    },
    {
      "x": -23,
      "y": 29,
      "z": 9,
      "name": "Soil_Seaweed_Block"
    },
    {
      "x": -23,
      "y": 30,
      "z": 9,
      "name": "Soil_Seaweed_Block"
    },
    {
      "x": -23,
      "y": 31,
      "z": 9,
      "name": "Soil_Clay_Lime"
    },
    {
      "x": -23,
      "y": 32,
      "z": 9,
      "name": "Plant_Grass_Sharp"
    },
    {
      "x": -23,
      "y": 16,
      "z": 10,
      "name": "Soil_Seaweed_Block"
    },
    {
      "x": -23,
      "y": 17,
      "z": 10,
      "name": "Soil_Seaweed_Block"
    },
    {
      "x": -23,
      "y": 26,
      "z": 10,
      "name": "Soil_Clay_Green"
    },
    {
      "x": -23,
      "y": 27,
      "z": 10,
      "name": "Soil_Seaweed_Block"
    },
    {
      "x": -23,
      "y": 28,
      "z": 10,
      "name": "Soil_Seaweed_Block"
    },
    {
      "x": -23,
      "y": 29,
      "z": 10,
      "name": "Soil_Seaweed_Block"
    },
    {
      "x": -23,
      "y": 30,
      "z": 10,
      "name": "Soil_Clay_Lime"
    },
    {
      "x": -23,
      "y": 31,
      "z": 10,
      "name": "Plant_Grass_Sharp"
    },
    {
      "x": -23,
      "y": 27,
      "z": 11,
      "name": "Soil_Clay_Green"
    },
    {
      "x": -23,
      "y": 28,
      "z": 11,
      "name": "Soil_Seaweed_Block"
    },
    {
      "x": -23,
      "y": 29,
      "z": 11,
      "name": "Soil_Seaweed_Block"
    },
    {
      "x": -23,
      "y": 29,
      "z": 15,
      "name": "Soil_Seaweed_Block"
    },
    {
      "x": -23,
      "y": 28,
      "z": 16,
      "name": "Soil_Clay_Green"
    },
    {
      "x": -23,
      "y": 29,
      "z": 16,
      "name": "Soil_Seaweed_Block"
    },
    {
      "x": -23,
      "y": 30,
      "z": 16,
      "name": "Soil_Seaweed_Block"
    },
    {
      "x": -23,
      "y": 28,
      "z": 17,
      "name": "Soil_Clay_Green"
    },
    {
      "x": -23,
      "y": 29,
      "z": 17,
      "name": "Soil_Seaweed_Block"
    },
    {
      "x": -23,
      "y": 30,
      "z": 17,
      "name": "Soil_Seaweed_Block"
    },
    {
      "x": -23,
      "y": 29,
      "z": 18,
      "name": "Soil_Seaweed_Block"
    },
    {
      "x": -22,
      "y": 17,
      "z": -17,
      "name": "Soil_Clay_Green"
    },
    {
      "x": -22,
      "y": 18,
      "z": -17,
      "name": "Soil_Seaweed_Block"
    },
    {
      "x": -22,
      "y": 27,
      "z": -17,
      "name": "Soil_Clay_Green"
    },
    {
      "x": -22,
      "y": 28,
      "z": -17,
      "name": "Soil_Seaweed_Block"
    },
    {
      "x": -22,
      "y": 29,
      "z": -17,
      "name": "Soil_Seaweed_Block"
    },
    {
      "x": -22,
      "y": 16,
      "z": -16,
      "name": "Soil_Clay_Green"
    },
    {
      "x": -22,
      "y": 17,
      "z": -16,
      "name": "Soil_Seaweed_Block"
    },
    {
      "x": -22,
      "y": 18,
      "z": -16,
      "name": "Soil_Seaweed_Block"
    },
    {
      "x": -22,
      "y": 19,
      "z": -16,
      "name": "Soil_Seaweed_Block"
    },
    {
      "x": -22,
      "y": 26,
      "z": -16,
      "name": "Soil_Clay_Green"
    },
    {
      "x": -22,
      "y": 27,
      "z": -16,
      "name": "Soil_Clay_Green"
    },
    {
      "x": -22,
      "y": 28,
      "z": -16,
      "name": "Soil_Seaweed_Block"
    },
    {
      "x": -22,
      "y": 29,
      "z": -16,
      "name": "Soil_Seaweed_Block"
    },
    {
      "x": -22,
      "y": 16,
      "z": -15,
      "name": "Soil_Clay_Green"
    },
    {
      "x": -22,
      "y": 17,
      "z": -15,
      "name": "Soil_Seaweed_Block"
    },
    {
      "x": -22,
      "y": 18,
      "z": -15,
      "name": "Soil_Seaweed_Block"
    },
    {
      "x": -22,
      "y": 19,
      "z": -15,
      "name": "Soil_Seaweed_Block"
    },
    {
      "x": -22,
      "y": 26,
      "z": -15,
      "name": "Soil_Clay_Green"
    },
    {
      "x": -22,
      "y": 27,
      "z": -15,
      "name": "Soil_Clay_Green"
    },
    {
      "x": -22,
      "y": 28,
      "z": -15,
      "name": "Soil_Seaweed_Block"
    },
    {
      "x": -22,
      "y": 29,
      "z": -15,
      "name": "Soil_Seaweed_Block"
    },
    {
      "x": -22,
      "y": 16,
      "z": -14,
      "name": "Soil_Clay_Green"
    },
    {
      "x": -22,
      "y": 17,
      "z": -14,
      "name": "Soil_Seaweed_Block"
    },
    {
      "x": -22,
      "y": 18,
      "z": -14,
      "name": "Soil_Seaweed_Block"
    },
    {
      "x": -22,
      "y": 19,
      "z": -14,
      "name": "Soil_Clay_Lime"
    },
    {
      "x": -22,
      "y": 20,
      "z": -14,
      "name": "Plant_Grass_Sharp"
    },
    {
      "x": -22,
      "y": 27,
      "z": -14,
      "name": "Soil_Seaweed_Block"
    },
    {
      "x": -22,
      "y": 28,
      "z": -14,
      "name": "Soil_Seaweed_Block"
    },
    {
      "x": -22,
      "y": 15,
      "z": -13,
      "name": "Soil_Clay_Green"
    },
    {
      "x": -22,
      "y": 16,
      "z": -13,
      "name": "Soil_Seaweed_Block"
    },
    {
      "x": -22,
      "y": 17,
      "z": -13,
      "name": "Soil_Seaweed_Block"
    },
    {
      "x": -22,
      "y": 18,
      "z": -13,
      "name": "Soil_Seaweed_Block"
    },
    {
      "x": -22,
      "y": 19,
      "z": -13,
      "name": "Soil_Clay_Lime"
    },
    {
      "x": -22,
      "y": 20,
      "z": -13,
      "name": "Plant_Grass_Sharp"
    },
    {
      "x": -22,
      "y": 9,
      "z": -12,
      "name": "Soil_Clay_Green"
    },
    {
      "x": -22,
      "y": 10,
      "z": -12,
      "name": "Soil_Seaweed_Block"
    },
    {
      "x": -22,
      "y": 11,
      "z": -12,
      "name": "Soil_Seaweed_Block"
    },
    {
      "x": -22,
      "y": 12,
      "z": -12,
      "name": "Soil_Clay_Green"
    },
    {
      "x": -22,
      "y": 13,
      "z": -12,
      "name": "Soil_Clay_Green"
    },
    {
      "x": -22,
      "y": 14,
      "z": -12,
      "name": "Soil_Clay_Green"
    },
    {
      "x": -22,
      "y": 15,
      "z": -12,
      "name": "Soil_Seaweed_Block"
    },
    {
      "x": -22,
      "y": 16,
      "z": -12,
      "name": "Soil_Seaweed_Block"
    },
    {
      "x": -22,
      "y": 17,
      "z": -12,
      "name": "Soil_Seaweed_Block"
    },
    {
      "x": -22,
      "y": 18,
      "z": -12,
      "name": "Soil_Clay_Lime"
    },
    {
      "x": -22,
      "y": 19,
      "z": -12,
      "name": "Plant_Grass_Sharp"
    },
    {
      "x": -22,
      "y": 28,
      "z": -12,
      "name": "Soil_Seaweed_Block"
    },
    {
      "x": -22,
      "y": 9,
      "z": -11,
      "name": "Soil_Clay_Green"
    },
    {
      "x": -22,
      "y": 10,
      "z": -11,
      "name": "Soil_Clay_Green"
    },
    {
      "x": -22,
      "y": 11,
      "z": -11,
      "name": "Soil_Clay_Green"
    },
    {
      "x": -22,
      "y": 12,
      "z": -11,
      "name": "Soil_Seaweed_Block"
    },
    {
      "x": -22,
      "y": 13,
      "z": -11,
      "name": "Soil_Seaweed_Block"
    },
    {
      "x": -22,
      "y": 14,
      "z": -11,
      "name": "Soil_Seaweed_Block"
    },
    {
      "x": -22,
      "y": 15,
      "z": -11,
      "name": "Soil_Seaweed_Block"
    },
    {
      "x": -22,
      "y": 16,
      "z": -11,
      "name": "Soil_Seaweed_Block"
    },
    {
      "x": -22,
      "y": 17,
      "z": -11,
      "name": "Soil_Seaweed_Block"
    },
    {
      "x": -22,
      "y": 18,
      "z": -11,
      "name": "Soil_Clay_Lime"
    },
    {
      "x": -22,
      "y": 19,
      "z": -11,
      "name": "Plant_Grass_Sharp"
    },
    {
      "x": -22,
      "y": 27,
      "z": -11,
      "name": "Soil_Clay_Green"
    },
    {
      "x": -22,
      "y": 28,
      "z": -11,
      "name": "Soil_Seaweed_Block"
    },
    {
      "x": -22,
      "y": 29,
      "z": -11,
      "name": "Soil_Seaweed_Block"
    },
    {
      "x": -22,
      "y": 30,
      "z": -11,
      "name": "Soil_Seaweed_Block"
    },
    {
      "x": -22,
      "y": 9,
      "z": -10,
      "name": "Soil_Clay_Green"
    },
    {
      "x": -22,
      "y": 10,
      "z": -10,
      "name": "Soil_Clay_Green"
    },
    {
      "x": -22,
      "y": 11,
      "z": -10,
      "name": "Soil_Clay_Green"
    },
    {
      "x": -22,
      "y": 12,
      "z": -10,
      "name": "Soil_Clay_Green"
    },
    {
      "x": -22,
      "y": 13,
      "z": -10,
      "name": "Soil_Seaweed_Block"
    },
    {
      "x": -22,
      "y": 14,
      "z": -10,
      "name": "Soil_Seaweed_Block"
    },
    {
      "x": -22,
      "y": 15,
      "z": -10,
      "name": "Soil_Seaweed_Block"
    },
    {
      "x": -22,
      "y": 16,
      "z": -10,
      "name": "Soil_Seaweed_Block"
    },
    {
      "x": -22,
      "y": 17,
      "z": -10,
      "name": "Soil_Seaweed_Block"
    },
    {
      "x": -22,
      "y": 18,
      "z": -10,
      "name": "Soil_Seaweed_Block"
    },
    {
      "x": -22,
      "y": 19,
      "z": -10,
      "name": "Soil_Clay_Lime"
    },
    {
      "x": -22,
      "y": 20,
      "z": -10,
      "name": "Plant_Grass_Sharp"
    },
    {
      "x": -22,
      "y": 26,
      "z": -10,
      "name": "Soil_Clay_Green"
    },
    {
      "x": -22,
      "y": 27,
      "z": -10,
      "name": "Soil_Clay_Green"
    },
    {
      "x": -22,
      "y": 28,
      "z": -10,
      "name": "Soil_Seaweed_Block"
    },
    {
      "x": -22,
      "y": 29,
      "z": -10,
      "name": "Soil_Seaweed_Block"
    },
    {
      "x": -22,
      "y": 30,
      "z": -10,
      "name": "Soil_Seaweed_Block"
    },
    {
      "x": -22,
      "y": 31,
      "z": -10,
      "name": "Soil_Seaweed_Block"
    },
    {
      "x": -22,
      "y": 32,
      "z": -10,
      "name": "Soil_Seaweed_Block"
    },
    {
      "x": -22,
      "y": 10,
      "z": -9,
      "name": "Soil_Clay_Green"
    },
    {
      "x": -22,
      "y": 11,
      "z": -9,
      "name": "Soil_Clay_Green"
    },
    {
      "x": -22,
      "y": 12,
      "z": -9,
      "name": "Soil_Clay_Green"
    },
    {
      "x": -22,
      "y": 13,
      "z": -9,
      "name": "Soil_Clay_Green"
    },
    {
      "x": -22,
      "y": 14,
      "z": -9,
      "name": "Soil_Seaweed_Block"
    },
    {
      "x": -22,
      "y": 15,
      "z": -9,
      "name": "Soil_Seaweed_Block"
    },
    {
      "x": -22,
      "y": 16,
      "z": -9,
      "name": "Soil_Seaweed_Block"
    },
    {
      "x": -22,
      "y": 17,
      "z": -9,
      "name": "Soil_Seaweed_Block"
    },
    {
      "x": -22,
      "y": 18,
      "z": -9,
      "name": "Soil_Seaweed_Block"
    },
    {
      "x": -22,
      "y": 19,
      "z": -9,
      "name": "Soil_Seaweed_Block"
    },
    {
      "x": -22,
      "y": 20,
      "z": -9,
      "name": "Soil_Clay_Lime"
    },
    {
      "x": -22,
      "y": 21,
      "z": -9,
      "name": "Plant_Grass_Sharp"
    },
    {
      "x": -22,
      "y": 26,
      "z": -9,
      "name": "Soil_Clay_Green"
    },
    {
      "x": -22,
      "y": 27,
      "z": -9,
      "name": "Soil_Seaweed_Block"
    },
    {
      "x": -22,
      "y": 28,
      "z": -9,
      "name": "Soil_Seaweed_Block"
    },
    {
      "x": -22,
      "y": 29,
      "z": -9,
      "name": "Soil_Seaweed_Block"
    },
    {
      "x": -22,
      "y": 30,
      "z": -9,
      "name": "Soil_Seaweed_Block"
    },
    {
      "x": -22,
      "y": 31,
      "z": -9,
      "name": "Soil_Seaweed_Block"
    },
    {
      "x": -22,
      "y": 32,
      "z": -9,
      "name": "Soil_Clay_Lime"
    },
    {
      "x": -22,
      "y": 33,
      "z": -9,
      "name": "Plant_Grass_Sharp"
    },
    {
      "x": -22,
      "y": 14,
      "z": -8,
      "name": "Soil_Seaweed_Block"
    },
    {
      "x": -22,
      "y": 15,
      "z": -8,
      "name": "Soil_Seaweed_Block"
    },
    {
      "x": -22,
      "y": 16,
      "z": -8,
      "name": "Soil_Seaweed_Block"
    },
    {
      "x": -22,
      "y": 17,
      "z": -8,
      "name": "Soil_Seaweed_Block"
    },
    {
      "x": -22,
      "y": 18,
      "z": -8,
      "name": "Soil_Seaweed_Block"
    },
    {
      "x": -22,
      "y": 19,
      "z": -8,
      "name": "Soil_Seaweed_Block"
    },
    {
      "x": -22,
      "y": 20,
      "z": -8,
      "name": "Soil_Seaweed_Block"
    },
    {
      "x": -22,
      "y": 21,
      "z": -8,
      "name": "Soil_Seaweed_Block"
    },
    {
      "x": -22,
      "y": 26,
      "z": -8,
      "name": "Soil_Clay_Green"
    },
    {
      "x": -22,
      "y": 27,
      "z": -8,
      "name": "Soil_Seaweed_Block"
    },
    {
      "x": -22,
      "y": 28,
      "z": -8,
      "name": "Soil_Seaweed_Block"
    },
    {
      "x": -22,
      "y": 29,
      "z": -8,
      "name": "Soil_Seaweed_Block"
    },
    {
      "x": -22,
      "y": 30,
      "z": -8,
      "name": "Soil_Seaweed_Block"
    },
    {
      "x": -22,
      "y": 31,
      "z": -8,
      "name": "Soil_Seaweed_Block"
    },
    {
      "x": -22,
      "y": 32,
      "z": -8,
      "name": "Soil_Clay_Lime"
    },
    {
      "x": -22,
      "y": 33,
      "z": -8,
      "name": "Plant_Grass_Sharp"
    },
    {
      "x": -22,
      "y": 18,
      "z": -7,
      "name": "Soil_Seaweed_Block"
    },
    {
      "x": -22,
      "y": 19,
      "z": -7,
      "name": "Soil_Seaweed_Block"
    },
    {
      "x": -22,
      "y": 20,
      "z": -7,
      "name": "Soil_Seaweed_Block"
    },
    {
      "x": -22,
      "y": 21,
      "z": -7,
      "name": "Soil_Seaweed_Block"
    },
    {
      "x": -22,
      "y": 22,
      "z": -7,
      "name": "Soil_Seaweed_Block"
    },
    {
      "x": -22,
      "y": 23,
      "z": -7,
      "name": "Soil_Seaweed_Block"
    },
    {
      "x": -22,
      "y": 24,
      "z": -7,
      "name": "Soil_Seaweed_Block"
    },
    {
      "x": -22,
      "y": 25,
      "z": -7,
      "name": "Soil_Clay_Green"
    },
    {
      "x": -22,
      "y": 26,
      "z": -7,
      "name": "Soil_Clay_Green"
    },
    {
      "x": -22,
      "y": 27,
      "z": -7,
      "name": "Soil_Seaweed_Block"
    },
    {
      "x": -22,
      "y": 28,
      "z": -7,
      "name": "Soil_Seaweed_Block"
    },
    {
      "x": -22,
      "y": 29,
      "z": -7,
      "name": "Soil_Seaweed_Block"
    },
    {
      "x": -22,
      "y": 30,
      "z": -7,
      "name": "Soil_Seaweed_Block"
    },
    {
      "x": -22,
      "y": 31,
      "z": -7,
      "name": "Soil_Seaweed_Block"
    },
    {
      "x": -22,
      "y": 32,
      "z": -7,
      "name": "Soil_Clay_Lime"
    },
    {
      "x": -22,
      "y": 33,
      "z": -7,
      "name": "Plant_Grass_Sharp"
    },
    {
      "x": -22,
      "y": 21,
      "z": -6,
      "name": "Soil_Clay_Green"
    },
    {
      "x": -22,
      "y": 22,
      "z": -6,
      "name": "Soil_Seaweed_Block"
    },
    {
      "x": -22,
      "y": 23,
      "z": -6,
      "name": "Soil_Seaweed_Block"
    },
    {
      "x": -22,
      "y": 24,
      "z": -6,
      "name": "Soil_Seaweed_Block"
    },
    {
      "x": -22,
      "y": 25,
      "z": -6,
      "name": "Soil_Seaweed_Block"
    },
    {
      "x": -22,
      "y": 26,
      "z": -6,
      "name": "Soil_Clay_Green"
    },
    {
      "x": -22,
      "y": 27,
      "z": -6,
      "name": "Soil_Seaweed_Block"
    },
    {
      "x": -22,
      "y": 28,
      "z": -6,
      "name": "Soil_Seaweed_Block"
    },
    {
      "x": -22,
      "y": 29,
      "z": -6,
      "name": "Soil_Seaweed_Block"
    },
    {
      "x": -22,
      "y": 30,
      "z": -6,
      "name": "Soil_Seaweed_Block"
    },
    {
      "x": -22,
      "y": 31,
      "z": -6,
      "name": "Soil_Seaweed_Block"
    },
    {
      "x": -22,
      "y": 11,
      "z": -5,
      "name": "Soil_Clay_Green"
    },
    {
      "x": -22,
      "y": 12,
      "z": -5,
      "name": "Soil_Seaweed_Block"
    },
    {
      "x": -22,
      "y": 22,
      "z": -5,
      "name": "Soil_Clay_Green"
    },
    {
      "x": -22,
      "y": 23,
      "z": -5,
      "name": "Soil_Seaweed_Block"
    },
    {
      "x": -22,
      "y": 24,
      "z": -5,
      "name": "Soil_Seaweed_Block"
    },
    {
      "x": -22,
      "y": 25,
      "z": -5,
      "name": "Soil_Seaweed_Block"
    },
    {
      "x": -22,
      "y": 26,
      "z": -5,
      "name": "Soil_Seaweed_Block"
    },
    {
      "x": -22,
      "y": 27,
      "z": -5,
      "name": "Soil_Seaweed_Block"
    },
    {
      "x": -22,
      "y": 28,
      "z": -5,
      "name": "Soil_Seaweed_Block"
    },
    {
      "x": -22,
      "y": 29,
      "z": -5,
      "name": "Soil_Seaweed_Block"
    },
    {
      "x": -22,
      "y": 30,
      "z": -5,
      "name": "Soil_Clay_Lime"
    },
    {
      "x": -22,
      "y": 31,
      "z": -5,
      "name": "Plant_Grass_Sharp"
    },
    {
      "x": -22,
      "y": 11,
      "z": -4,
      "name": "Soil_Clay_Green"
    },
    {
      "x": -22,
      "y": 12,
      "z": -4,
      "name": "Soil_Seaweed_Block"
    },
    {
      "x": -22,
      "y": 22,
      "z": -4,
      "name": "Soil_Clay_Green"
    },
    {
      "x": -22,
      "y": 23,
      "z": -4,
      "name": "Soil_Seaweed_Block"
    },
    {
      "x": -22,
      "y": 24,
      "z": -4,
      "name": "Soil_Seaweed_Block"
    },
    {
      "x": -22,
      "y": 25,
      "z": -4,
      "name": "Soil_Seaweed_Block"
    },
    {
      "x": -22,
      "y": 26,
      "z": -4,
      "name": "Soil_Seaweed_Block"
    },
    {
      "x": -22,
      "y": 27,
      "z": -4,
      "name": "Soil_Seaweed_Block"
    },
    {
      "x": -22,
      "y": 28,
      "z": -4,
      "name": "Soil_Seaweed_Block"
    },
    {
      "x": -22,
      "y": 29,
      "z": -4,
      "name": "Soil_Clay_Lime"
    },
    {
      "x": -22,
      "y": 30,
      "z": -4,
      "name": "Plant_Grass_Sharp"
    },
    {
      "x": -22,
      "y": 11,
      "z": -3,
      "name": "Soil_Clay_Green"
    },
    {
      "x": -22,
      "y": 12,
      "z": -3,
      "name": "Soil_Seaweed_Block"
    },
    {
      "x": -22,
      "y": 23,
      "z": -3,
      "name": "Soil_Seaweed_Block"
    },
    {
      "x": -22,
      "y": 27,
      "z": -3,
      "name": "Soil_Clay_Green"
    },
    {
      "x": -22,
      "y": 28,
      "z": -3,
      "name": "Soil_Seaweed_Block"
    },
    {
      "x": -22,
      "y": 29,
      "z": -3,
      "name": "Soil_Seaweed_Block"
    },
    {
      "x": -22,
      "y": 11,
      "z": -2,
      "name": "Soil_Clay_Green"
    },
    {
      "x": -22,
      "y": 12,
      "z": -2,
      "name": "Soil_Seaweed_Block"
    },
    {
      "x": -22,
      "y": 28,
      "z": -2,
      "name": "Soil_Clay_Green"
    },
    {
      "x": -22,
      "y": 29,
      "z": -2,
      "name": "Soil_Seaweed_Block"
    },
    {
      "x": -22,
      "y": 11,
      "z": -1,
      "name": "Soil_Clay_Green"
    },
    {
      "x": -22,
      "y": 12,
      "z": -1,
      "name": "Soil_Seaweed_Block"
    },
    {
      "x": -22,
      "y": 13,
      "z": -1,
      "name": "Soil_Clay_Lime"
    },
    {
      "x": -22,
      "y": 14,
      "z": -1,
      "name": "Plant_Grass_Sharp"
    },
    {
      "x": -22,
      "y": 28,
      "z": -1,
      "name": "Soil_Clay_Green"
    },
    {
      "x": -22,
      "y": 29,
      "z": -1,
      "name": "Soil_Seaweed_Block"
    },
    {
      "x": -22,
      "y": 30,
      "z": -1,
      "name": "Soil_Seaweed_Block"
    },
    {
      "x": -22,
      "y": 11,
      "z": 0,
      "name": "Soil_Clay_Green"
    },
    {
      "x": -22,
      "y": 12,
      "z": 0,
      "name": "Soil_Seaweed_Block"
    },
    {
      "x": -22,
      "y": 13,
      "z": 0,
      "name": "Soil_Clay_Lime"
    },
    {
      "x": -22,
      "y": 14,
      "z": 0,
      "name": "Plant_Grass_Sharp"
    },
    {
      "x": -22,
      "y": 29,
      "z": 0,
      "name": "Soil_Clay_Green"
    },
    {
      "x": -22,
      "y": 30,
      "z": 0,
      "name": "Soil_Seaweed_Block"
    },
    {
      "x": -22,
      "y": 11,
      "z": 1,
      "name": "Soil_Clay_Green"
    },
    {
      "x": -22,
      "y": 12,
      "z": 1,
      "name": "Soil_Seaweed_Block"
    },
    {
      "x": -22,
      "y": 13,
      "z": 1,
      "name": "Soil_Seaweed_Block"
    },
    {
      "x": -22,
      "y": 14,
      "z": 1,
      "name": "Soil_Seaweed_Block"
    },
    {
      "x": -22,
      "y": 30,
      "z": 1,
      "name": "Soil_Clay_Green"
    },
    {
      "x": -22,
      "y": 31,
      "z": 1,
      "name": "Soil_Seaweed_Block"
    },
    {
      "x": -22,
      "y": 32,
      "z": 1,
      "name": "Soil_Seaweed_Block"
    },
    {
      "x": -22,
      "y": 12,
      "z": 2,
      "name": "Soil_Clay_Green"
    },
    {
