{
  "version": 8,
  "blockIdVersion": 10,
  "anchorX": 0,
  "anchorY": 12,
  "anchorZ": 0,
  "blocks": [
    {
      "x": -30,
      "y": 29,
      "z": 7,
      "name": "Soil_Clay_Green"
    },
    {
      "x": -30,
      "y": 30,
      "z": 7,
      "name": "Soil_Seaweed_Block"
    },
    {
      "x": -30,
      "y": 31,
      "z": 7,
      "name": "Soil_Seaweed_Block"
    },
    {
      "x": -30,
      "y": 29,
      "z": 8,
      "name": "Soil_Clay_Green"
    },
    {
      "x": -30,
      "y": 30,
      "z": 8,
      "name": "Soil_Seaweed_Block"
    },
    {
      "x": -30,
      "y": 31,
      "z": 8,
      "name": "Soil_Seaweed_Block"
    },
    {
      "x": -30,
      "y": 29,
      "z": 9,
      "name": "Soil_Clay_Green"
    },
    {
      "x": -30,
      "y": 30,
      "z": 9,
      "name": "Soil_Seaweed_Block"
    },
    {
      "x": -30,
      "y": 31,
      "z": 9,
      "name": "Soil_Seaweed_Block"
    },
    {
      "x": -30,
      "y": 36,
      "z": 9,
      "name": "Soil_Seaweed_Block"
    },
    {
      "x": -30,
      "y": 37,
      "z": 9,
      "name": "Soil_Seaweed_Block"
    },
    {
      "x": -29,
      "y": 32,
      "z": -9,
      "name": "Soil_Clay_Green"
    },
    {
      "x": -29,
      "y": 33,
      "z": -9,
      "name": "Soil_Seaweed_Block"
    },
    {
      "x": -29,
      "y": 34,
      "z": -9,
      "name": "Soil_Seaweed_Block"
    },
    {
      "x": -29,
      "y": 32,
      "z": -8,
      "name": "Soil_Clay_Green"
    },
    {
      "x": -29,
      "y": 33,
      "z": -8,
      "name": "Soil_Seaweed_Block"
    },
    {
      "x": -29,
      "y": 34,
      "z": -8,
      "name": "Soil_Seaweed_Block"
    },
    {
      "x": -29,
      "y": 35,
      "z": -8,
      "name": "Soil_Seaweed_Block"
    },
    {
      "x": -29,
      "y": 32,
      "z": -7,
      "name": "Soil_Clay_Green"
    },
    {
      "x": -29,
      "y": 33,
      "z": -7,
      "name": "Soil_Seaweed_Block"
    },
    {
      "x": -29,
      "y": 34,
      "z": -7,
      "name": "Soil_Seaweed_Block"
    },
    {
      "x": -29,
      "y": 35,
      "z": -7,
      "name": "Soil_Seaweed_Block"
    },
    {
      "x": -29,
      "y": 33,
      "z": -6,
      "name": "Soil_Seaweed_Block"
    },
    {
      "x": -29,
      "y": 34,
      "z": -6,
      "name": "Soil_Seaweed_Block"
    },
    {
      "x": -29,
      "y": 35,
      "z": -6,
      "name": "Soil_Seaweed_Block"
    },
    {
      "x": -29,
      "y": 36,
      "z": -6,
      "name": "Soil_Seaweed_Block"
    },
    {
      "x": -29,
      "y": 34,
      "z": -5,
      "name": "Soil_Seaweed_Block"
    },
    {
      "x": -29,
      "y": 35,
      "z": -5,
      "name": "Soil_Seaweed_Block"
    },
    {
      "x": -29,
      "y": 36,
      "z": -5,
      "name": "Soil_Seaweed_Block"
    },
    {
      "x": -29,
      "y": 29,
      "z": 6,
      "name": "Soil_Clay_Green"
    },
    {
      "x": -29,
      "y": 30,
      "z": 6,
      "name": "Soil_Seaweed_Block"
    },
    {
      "x": -29,
      "y": 31,
      "z": 6,
      "name": "Soil_Seaweed_Block"
    },
    {
      "x": -29,
      "y": 28,
      "z": 7,
      "name": "Soil_Clay_Green"
    },
    {
      "x": -29,
      "y": 29,
      "z": 7,
      "name": "Soil_Clay_Green"
    },
    {
      "x": -29,
      "y": 30,
      "z": 7,
      "name": "Soil_Seaweed_Block"
    },
    {
      "x": -29,
      "y": 31,
      "z": 7,
      "name": "Soil_Seaweed_Block"
    },
    {
      "x": -29,
      "y": 28,
      "z": 8,
      "name": "Soil_Clay_Green"
    },
    {
      "x": -29,
      "y": 29,
      "z": 8,
      "name": "Soil_Seaweed_Block"
    },
    {
      "x": -29,
      "y": 30,
      "z": 8,
      "name": "Soil_Seaweed_Block"
    },
    {
      "x": -29,
      "y": 31,
      "z": 8,
      "name": "Soil_Seaweed_Block"
    },
    {
      "x": -29,
      "y": 32,
      "z": 8,
      "name": "Soil_Seaweed_Block"
    },
    {
      "x": -29,
      "y": 36,
      "z": 8,
      "name": "Soil_Clay_Green"
    },
    {
      "x": -29,
      "y": 37,
      "z": 8,
      "name": "Soil_Seaweed_Block"
    },
    {
      "x": -29,
      "y": 38,
      "z": 8,
      "name": "Soil_Seaweed_Block"
    },
    {
      "x": -29,
      "y": 29,
      "z": 9,
      "name": "Soil_Clay_Green"
    },
    {
      "x": -29,
      "y": 30,
      "z": 9,
      "name": "Soil_Seaweed_Block"
    },
    {
      "x": -29,
      "y": 31,
      "z": 9,
      "name": "Soil_Seaweed_Block"
    },
    {
      "x": -29,
      "y": 36,
      "z": 9,
      "name": "Soil_Seaweed_Block"
    },
    {
      "x": -29,
      "y": 37,
      "z": 9,
      "name": "Soil_Seaweed_Block"
    },
    {
      "x": -29,
      "y": 38,
      "z": 9,
      "name": "Soil_Seaweed_Block"
    },
    {
      "x": -29,
      "y": 29,
      "z": 10,
      "name": "Soil_Clay_Green"
    },
    {
      "x": -29,
      "y": 30,
      "z": 10,
      "name": "Soil_Seaweed_Block"
    },
    {
      "x": -29,
      "y": 31,
      "z": 10,
      "name": "Soil_Seaweed_Block"
    },
    {
      "x": -29,
      "y": 36,
      "z": 10,
      "name": "Soil_Seaweed_Block"
    },
    {
      "x": -29,
      "y": 37,
      "z": 10,
      "name": "Soil_Seaweed_Block"
    },
    {
      "x": -29,
      "y": 38,
      "z": 10,
      "name": "Soil_Seaweed_Block"
    },
    {
      "x": -28,
      "y": 32,
      "z": -11,
      "name": "Soil_Clay_Green"
    },
    {
      "x": -28,
      "y": 33,
      "z": -11,
      "name": "Soil_Seaweed_Block"
    },
    {
      "x": -28,
      "y": 34,
      "z": -11,
      "name": "Soil_Seaweed_Block"
    },
    {
      "x": -28,
      "y": 32,
      "z": -10,
      "name": "Soil_Clay_Green"
    },
    {
      "x": -28,
      "y": 33,
      "z": -10,
      "name": "Soil_Seaweed_Block"
    },
    {
      "x": -28,
      "y": 34,
      "z": -10,
      "name": "Soil_Seaweed_Block"
    },
    {
      "x": -28,
      "y": 31,
      "z": -9,
      "name": "Soil_Clay_Green"
    },
    {
      "x": -28,
      "y": 32,
      "z": -9,
      "name": "Soil_Seaweed_Block"
    },
    {
      "x": -28,
      "y": 33,
      "z": -9,
      "name": "Soil_Seaweed_Block"
    },
    {
      "x": -28,
      "y": 34,
      "z": -9,
      "name": "Soil_Seaweed_Block"
    },
    {
      "x": -28,
      "y": 35,
      "z": -9,
      "name": "Soil_Seaweed_Block"
    },
    {
      "x": -28,
      "y": 31,
      "z": -8,
      "name": "Soil_Clay_Green"
    },
    {
      "x": -28,
      "y": 32,
      "z": -8,
      "name": "Soil_Seaweed_Block"
    },
    {
      "x": -28,
      "y": 33,
      "z": -8,
      "name": "Soil_Seaweed_Block"
    },
    {
      "x": -28,
      "y": 34,
      "z": -8,
      "name": "Soil_Seaweed_Block"
    },
    {
      "x": -28,
      "y": 35,
      "z": -8,
      "name": "Soil_Seaweed_Block"
    },
    {
      "x": -28,
      "y": 31,
      "z": -7,
      "name": "Soil_Clay_Green"
    },
    {
      "x": -28,
      "y": 32,
      "z": -7,
      "name": "Soil_Clay_Green"
    },
    {
      "x": -28,
      "y": 33,
      "z": -7,
      "name": "Soil_Seaweed_Block"
    },
    {
      "x": -28,
      "y": 34,
      "z": -7,
      "name": "Soil_Seaweed_Block"
    },
    {
      "x": -28,
      "y": 35,
      "z": -7,
      "name": "Soil_Seaweed_Block"
    },
    {
      "x": -28,
      "y": 36,
      "z": -7,
      "name": "Soil_Seaweed_Block"
    },
    {
      "x": -28,
      "y": 27,
      "z": -6,
      "name": "Soil_Seaweed_Block"
    },
    {
      "x": -28,
      "y": 28,
      "z": -6,
      "name": "Soil_Seaweed_Block"
    },
    {
      "x": -28,
      "y": 31,
      "z": -6,
      "name": "Soil_Clay_Green"
    },
    {
      "x": -28,
      "y": 32,
      "z": -6,
      "name": "Soil_Seaweed_Block"
    },
    {
      "x": -28,
      "y": 33,
      "z": -6,
      "name": "Soil_Seaweed_Block"
    },
    {
      "x": -28,
      "y": 34,
      "z": -6,
      "name": "Soil_Seaweed_Block"
    },
    {
      "x": -28,
      "y": 35,
      "z": -6,
      "name": "Soil_Seaweed_Block"
    },
    {
      "x": -28,
      "y": 36,
      "z": -6,
      "name": "Soil_Seaweed_Block"
    },
    {
      "x": -28,
      "y": 37,
      "z": -6,
      "name": "Soil_Seaweed_Block"
    },
    {
      "x": -28,
      "y": 38,
      "z": -6,
      "name": "Soil_Seaweed_Block"
    },
    {
      "x": -28,
      "y": 39,
      "z": -6,
      "name": "Soil_Seaweed_Block"
    },
    {
      "x": -28,
      "y": 26,
      "z": -5,
      "name": "Soil_Seaweed_Block"
    },
    {
      "x": -28,
      "y": 27,
      "z": -5,
      "name": "Soil_Seaweed_Block"
    },
    {
      "x": -28,
      "y": 28,
      "z": -5,
      "name": "Soil_Seaweed_Block"
    },
    {
      "x": -28,
      "y": 29,
      "z": -5,
      "name": "Soil_Seaweed_Block"
    },
    {
      "x": -28,
      "y": 30,
      "z": -5,
      "name": "Soil_Seaweed_Block"
    },
    {
      "x": -28,
      "y": 31,
      "z": -5,
      "name": "Soil_Seaweed_Block"
    },
    {
      "x": -28,
      "y": 32,
      "z": -5,
      "name": "Soil_Clay_Green"
    },
    {
      "x": -28,
      "y": 33,
      "z": -5,
      "name": "Soil_Seaweed_Block"
    },
    {
      "x": -28,
      "y": 34,
      "z": -5,
      "name": "Soil_Seaweed_Block"
    },
    {
      "x": -28,
      "y": 35,
      "z": -5,
      "name": "Soil_Seaweed_Block"
    },
    {
      "x": -28,
      "y": 36,
      "z": -5,
      "name": "Soil_Seaweed_Block"
    },
    {
      "x": -28,
      "y": 37,
      "z": -5,
      "name": "Soil_Seaweed_Block"
    },
    {
      "x": -28,
      "y": 38,
      "z": -5,
      "name": "Soil_Seaweed_Block"
    },
    {
      "x": -28,
      "y": 22,
      "z": -4,
      "name": "Soil_Clay_Green"
    },
    {
      "x": -28,
      "y": 23,
      "z": -4,
      "name": "Soil_Seaweed_Block"
    },
    {
      "x": -28,
      "y": 24,
      "z": -4,
      "name": "Soil_Seaweed_Block"
    },
    {
      "x": -28,
      "y": 25,
      "z": -4,
      "name": "Soil_Seaweed_Block"
    },
    {
      "x": -28,
      "y": 26,
      "z": -4,
      "name": "Soil_Seaweed_Block"
    },
    {
      "x": -28,
      "y": 27,
      "z": -4,
      "name": "Soil_Seaweed_Block"
    },
    {
      "x": -28,
      "y": 28,
      "z": -4,
      "name": "Soil_Seaweed_Block"
    },
    {
      "x": -28,
      "y": 29,
      "z": -4,
      "name": "Soil_Seaweed_Block"
    },
    {
      "x": -28,
      "y": 33,
      "z": -4,
      "name": "Soil_Clay_Green"
    },
    {
      "x": -28,
      "y": 34,
      "z": -4,
      "name": "Soil_Seaweed_Block"
    },
    {
      "x": -28,
      "y": 35,
      "z": -4,
      "name": "Soil_Seaweed_Block"
    },
    {
      "x": -28,
      "y": 36,
      "z": -4,
      "name": "Soil_Seaweed_Block"
    },
    {
      "x": -28,
      "y": 37,
      "z": -4,
      "name": "Soil_Seaweed_Block"
    },
    {
      "x": -28,
      "y": 22,
      "z": -3,
      "name": "Soil_Clay_Green"
    },
    {
      "x": -28,
      "y": 23,
      "z": -3,
      "name": "Soil_Seaweed_Block"
    },
    {
      "x": -28,
      "y": 24,
      "z": -3,
      "name": "Soil_Seaweed_Block"
    },
    {
      "x": -28,
      "y": 25,
      "z": -3,
      "name": "Soil_Seaweed_Block"
    },
    {
      "x": -28,
      "y": 26,
      "z": -3,
      "name": "Soil_Seaweed_Block"
    },
    {
      "x": -28,
      "y": 27,
      "z": -3,
      "name": "Soil_Seaweed_Block"
    },
    {
      "x": -28,
      "y": 28,
      "z": -3,
      "name": "Soil_Seaweed_Block"
    },
    {
      "x": -28,
      "y": 29,
      "z": -3,
      "name": "Soil_Seaweed_Block"
    },
    {
      "x": -28,
      "y": 35,
      "z": -3,
      "name": "Soil_Seaweed_Block"
    },
    {
      "x": -28,
      "y": 22,
      "z": -2,
      "name": "Soil_Clay_Green"
    },
    {
      "x": -28,
      "y": 23,
      "z": -2,
      "name": "Soil_Seaweed_Block"
    },
    {
      "x": -28,
      "y": 35,
      "z": -2,
      "name": "Soil_Clay_Green"
    },
    {
      "x": -28,
      "y": 29,
      "z": 5,
      "name": "Soil_Clay_Green"
    },
    {
      "x": -28,
      "y": 30,
      "z": 5,
      "name": "Soil_Seaweed_Block"
    },
    {
      "x": -28,
      "y": 31,
      "z": 5,
      "name": "Soil_Seaweed_Block"
    },
    {
      "x": -28,
      "y": 29,
      "z": 6,
      "name": "Soil_Clay_Green"
    },
    {
      "x": -28,
      "y": 30,
      "z": 6,
      "name": "Soil_Seaweed_Block"
    },
    {
      "x": -28,
      "y": 31,
      "z": 6,
      "name": "Soil_Seaweed_Block"
    },
    {
      "x": -28,
      "y": 28,
      "z": 7,
      "name": "Soil_Clay_Green"
    },
    {
      "x": -28,
      "y": 29,
      "z": 7,
      "name": "Soil_Seaweed_Block"
    },
    {
      "x": -28,
      "y": 30,
      "z": 7,
      "name": "Soil_Seaweed_Block"
    },
    {
      "x": -28,
      "y": 31,
      "z": 7,
      "name": "Soil_Seaweed_Block"
    },
    {
      "x": -28,
      "y": 32,
      "z": 7,
      "name": "Soil_Seaweed_Block"
    },
    {
      "x": -28,
      "y": 35,
      "z": 7,
      "name": "Soil_Clay_Green"
    },
    {
      "x": -28,
      "y": 36,
      "z": 7,
      "name": "Soil_Clay_Green"
    },
    {
      "x": -28,
      "y": 37,
      "z": 7,
      "name": "Soil_Seaweed_Block"
    },
    {
      "x": -28,
      "y": 38,
      "z": 7,
      "name": "Soil_Seaweed_Block"
    },
    {
      "x": -28,
      "y": 28,
      "z": 8,
      "name": "Soil_Clay_Green"
    },
    {
      "x": -28,
      "y": 29,
      "z": 8,
      "name": "Soil_Seaweed_Block"
    },
    {
      "x": -28,
      "y": 30,
      "z": 8,
      "name": "Soil_Seaweed_Block"
    },
    {
      "x": -28,
      "y": 31,
      "z": 8,
      "name": "Soil_Seaweed_Block"
    },
    {
      "x": -28,
      "y": 32,
      "z": 8,
      "name": "Soil_Seaweed_Block"
    },
    {
      "x": -28,
      "y": 33,
      "z": 8,
      "name": "Soil_Seaweed_Block"
    },
    {
      "x": -28,
      "y": 34,
      "z": 8,
      "name": "Soil_Seaweed_Block"
    },
    {
      "x": -28,
      "y": 35,
      "z": 8,
      "name": "Soil_Clay_Green"
    },
    {
      "x": -28,
      "y": 36,
      "z": 8,
      "name": "Soil_Seaweed_Block"
    },
    {
      "x": -28,
      "y": 37,
      "z": 8,
      "name": "Soil_Seaweed_Block"
    },
    {
      "x": -28,
      "y": 38,
      "z": 8,
      "name": "Soil_Seaweed_Block"
    },
    {
      "x": -28,
      "y": 39,
      "z": 8,
      "name": "Soil_Clay_Lime"
    },
    {
      "x": -28,
      "y": 28,
      "z": 9,
      "name": "Soil_Clay_Green"
    },
    {
      "x": -28,
      "y": 29,
      "z": 9,
      "name": "Soil_Seaweed_Block"
    },
    {
      "x": -28,
      "y": 30,
      "z": 9,
      "name": "Soil_Seaweed_Block"
    },
    {
      "x": -28,
      "y": 31,
      "z": 9,
      "name": "Soil_Seaweed_Block"
    },
    {
      "x": -28,
      "y": 32,
      "z": 9,
      "name": "Soil_Seaweed_Block"
    },
    {
      "x": -28,
      "y": 33,
      "z": 9,
      "name": "Soil_Seaweed_Block"
    },
    {
      "x": -28,
      "y": 34,
      "z": 9,
      "name": "Soil_Seaweed_Block"
    },
    {
      "x": -28,
      "y": 35,
      "z": 9,
      "name": "Soil_Clay_Green"
    },
    {
      "x": -28,
      "y": 36,
      "z": 9,
      "name": "Soil_Seaweed_Block"
    },
    {
      "x": -28,
      "y": 37,
      "z": 9,
      "name": "Soil_Seaweed_Block"
    },
    {
      "x": -28,
      "y": 38,
      "z": 9,
      "name": "Soil_Seaweed_Block"
    },
    {
      "x": -28,
      "y": 39,
      "z": 9,
      "name": "Soil_Seaweed_Block"
    },
    {
      "x": -28,
      "y": 29,
      "z": 10,
      "name": "Soil_Clay_Green"
    },
    {
      "x": -28,
      "y": 30,
      "z": 10,
      "name": "Soil_Seaweed_Block"
    },
    {
      "x": -28,
      "y": 31,
      "z": 10,
      "name": "Soil_Seaweed_Block"
    },
    {
      "x": -28,
      "y": 36,
      "z": 10,
      "name": "Soil_Seaweed_Block"
    },
    {
      "x": -28,
      "y": 37,
      "z": 10,
      "name": "Soil_Seaweed_Block"
    },
    {
      "x": -28,
      "y": 38,
      "z": 10,
      "name": "Soil_Seaweed_Block"
    },
    {
      "x": -28,
      "y": 37,
      "z": 11,
      "name": "Soil_Seaweed_Block"
    },
    {
      "x": -27,
      "y": 32,
      "z": -11,
      "name": "Soil_Clay_Green"
    },
    {
      "x": -27,
      "y": 33,
      "z": -11,
      "name": "Soil_Seaweed_Block"
    },
    {
      "x": -27,
      "y": 34,
      "z": -11,
      "name": "Soil_Seaweed_Block"
    },
    {
      "x": -27,
      "y": 31,
      "z": -10,
      "name": "Soil_Clay_Green"
    },
    {
      "x": -27,
      "y": 32,
      "z": -10,
      "name": "Soil_Seaweed_Block"
    },
    {
      "x": -27,
      "y": 33,
      "z": -10,
      "name": "Soil_Seaweed_Block"
    },
    {
      "x": -27,
      "y": 34,
      "z": -10,
      "name": "Soil_Seaweed_Block"
    },
    {
      "x": -27,
      "y": 35,
      "z": -10,
      "name": "Soil_Seaweed_Block"
    },
    {
      "x": -27,
      "y": 31,
      "z": -9,
      "name": "Soil_Clay_Green"
    },
    {
      "x": -27,
      "y": 32,
      "z": -9,
      "name": "Soil_Seaweed_Block"
    },
    {
      "x": -27,
      "y": 33,
      "z": -9,
      "name": "Soil_Seaweed_Block"
    },
    {
      "x": -27,
      "y": 34,
      "z": -9,
      "name": "Soil_Seaweed_Block"
    },
    {
      "x": -27,
      "y": 35,
      "z": -9,
      "name": "Soil_Seaweed_Block"
    },
    {
      "x": -27,
      "y": 30,
      "z": -8,
      "name": "Soil_Clay_Green"
    },
    {
      "x": -27,
      "y": 31,
      "z": -8,
      "name": "Soil_Seaweed_Block"
    },
    {
      "x": -27,
      "y": 32,
      "z": -8,
      "name": "Soil_Seaweed_Block"
    },
    {
      "x": -27,
      "y": 33,
      "z": -8,
      "name": "Soil_Seaweed_Block"
    },
    {
      "x": -27,
      "y": 34,
      "z": -8,
      "name": "Soil_Seaweed_Block"
    },
    {
      "x": -27,
      "y": 35,
      "z": -8,
      "name": "Soil_Seaweed_Block"
    },
    {
      "x": -27,
      "y": 36,
      "z": -8,
      "name": "Soil_Seaweed_Block"
    },
    {
      "x": -27,
      "y": 37,
      "z": -8,
      "name": "Soil_Seaweed_Block"
    },
    {
      "x": -27,
      "y": 38,
      "z": -8,
      "name": "Soil_Seaweed_Block"
    },
    {
      "x": -27,
      "y": 39,
      "z": -8,
      "name": "Soil_Seaweed_Block"
    },
    {
      "x": -27,
      "y": 40,
      "z": -8,
      "name": "Soil_Seaweed_Block"
    },
    {
      "x": -27,
      "y": 27,
      "z": -7,
      "name": "Soil_Clay_Green"
    },
    {
      "x": -27,
      "y": 28,
      "z": -7,
      "name": "Soil_Seaweed_Block"
    },
    {
      "x": -27,
      "y": 29,
      "z": -7,
      "name": "Soil_Clay_Green"
    },
    {
      "x": -27,
      "y": 30,
      "z": -7,
      "name": "Soil_Clay_Green"
    },
    {
      "x": -27,
      "y": 31,
      "z": -7,
      "name": "Soil_Seaweed_Block"
    },
    {
      "x": -27,
      "y": 32,
      "z": -7,
      "name": "Soil_Seaweed_Block"
    },
    {
      "x": -27,
      "y": 33,
      "z": -7,
      "name": "Soil_Seaweed_Block"
    },
    {
      "x": -27,
      "y": 34,
      "z": -7,
      "name": "Soil_Seaweed_Block"
    },
    {
      "x": -27,
      "y": 35,
      "z": -7,
      "name": "Soil_Seaweed_Block"
    },
    {
      "x": -27,
      "y": 36,
      "z": -7,
      "name": "Soil_Seaweed_Block"
    },
    {
      "x": -27,
      "y": 37,
      "z": -7,
      "name": "Soil_Seaweed_Block"
    },
    {
      "x": -27,
      "y": 38,
      "z": -7,
      "name": "Soil_Seaweed_Block"
    },
    {
      "x": -27,
      "y": 39,
      "z": -7,
      "name": "Soil_Seaweed_Block"
    },
    {
      "x": -27,
      "y": 40,
      "z": -7,
      "name": "Soil_Seaweed_Block"
    },
    {
      "x": -27,
      "y": 25,
      "z": -6,
      "name": "Soil_Seaweed_Block"
    },
    {
      "x": -27,
      "y": 26,
      "z": -6,
      "name": "Soil_Clay_Green"
    },
    {
      "x": -27,
      "y": 27,
      "z": -6,
      "name": "Soil_Seaweed_Block"
    },
    {
      "x": -27,
      "y": 28,
      "z": -6,
      "name": "Soil_Seaweed_Block"
    },
    {
      "x": -27,
      "y": 29,
      "z": -6,
      "name": "Soil_Seaweed_Block"
    },
    {
      "x": -27,
      "y": 30,
      "z": -6,
      "name": "Soil_Seaweed_Block"
    },
    {
      "x": -27,
      "y": 31,
      "z": -6,
      "name": "Soil_Seaweed_Block"
    },
    {
      "x": -27,
      "y": 32,
      "z": -6,
      "name": "Soil_Seaweed_Block"
    },
    {
      "x": -27,
      "y": 33,
      "z": -6,
      "name": "Soil_Seaweed_Block"
    },
    {
      "x": -27,
      "y": 34,
      "z": -6,
      "name": "Soil_Seaweed_Block"
    },
    {
      "x": -27,
      "y": 35,
      "z": -6,
      "name": "Soil_Seaweed_Block"
    },
    {
      "x": -27,
      "y": 36,
      "z": -6,
      "name": "Soil_Seaweed_Block"
    },
    {
      "x": -27,
      "y": 37,
      "z": -6,
      "name": "Soil_Seaweed_Block"
    },
    {
      "x": -27,
      "y": 38,
      "z": -6,
      "name": "Soil_Seaweed_Block"
    },
    {
      "x": -27,
      "y": 39,
      "z": -6,
      "name": "Soil_Seaweed_Block"
    },
    {
      "x": -27,
      "y": 40,
      "z": -6,
      "name": "Soil_Seaweed_Block"
    },
    {
      "x": -27,
      "y": 25,
      "z": -5,
      "name": "Soil_Seaweed_Block"
    },
    {
      "x": -27,
      "y": 26,
      "z": -5,
      "name": "Soil_Seaweed_Block"
    },
    {
      "x": -27,
      "y": 27,
      "z": -5,
      "name": "Soil_Seaweed_Block"
    },
    {
      "x": -27,
      "y": 28,
      "z": -5,
      "name": "Soil_Seaweed_Block"
    },
    {
      "x": -27,
      "y": 29,
      "z": -5,
      "name": "Soil_Seaweed_Block"
    },
    {
      "x": -27,
      "y": 30,
      "z": -5,
      "name": "Soil_Seaweed_Block"
    },
    {
      "x": -27,
      "y": 31,
      "z": -5,
      "name": "Soil_Seaweed_Block"
    },
    {
      "x": -27,
      "y": 32,
      "z": -5,
      "name": "Soil_Seaweed_Block"
    },
    {
      "x": -27,
      "y": 33,
      "z": -5,
      "name": "Soil_Seaweed_Block"
    },
    {
      "x": -27,
      "y": 34,
      "z": -5,
      "name": "Soil_Seaweed_Block"
    },
    {
      "x": -27,
      "y": 35,
      "z": -5,
      "name": "Soil_Seaweed_Block"
    },
    {
      "x": -27,
      "y": 36,
      "z": -5,
      "name": "Soil_Seaweed_Block"
    },
    {
      "x": -27,
      "y": 37,
      "z": -5,
      "name": "Soil_Seaweed_Block"
    },
    {
      "x": -27,
      "y": 38,
      "z": -5,
      "name": "Soil_Seaweed_Block"
    },
    {
      "x": -27,
      "y": 39,
      "z": -5,
      "name": "Soil_Seaweed_Block"
    },
    {
      "x": -27,
      "y": 40,
      "z": -5,
      "name": "Soil_Seaweed_Block"
    },
    {
      "x": -27,
      "y": 21,
      "z": -4,
      "name": "Soil_Clay_Green"
    },
    {
      "x": -27,
      "y": 22,
      "z": -4,
      "name": "Soil_Clay_Green"
    },
    {
      "x": -27,
      "y": 23,
      "z": -4,
      "name": "Soil_Seaweed_Block"
    },
    {
      "x": -27,
      "y": 24,
      "z": -4,
      "name": "Soil_Seaweed_Block"
    },
    {
      "x": -27,
      "y": 25,
      "z": -4,
      "name": "Soil_Seaweed_Block"
    },
    {
      "x": -27,
      "y": 26,
      "z": -4,
      "name": "Soil_Seaweed_Block"
    },
    {
      "x": -27,
      "y": 27,
      "z": -4,
      "name": "Soil_Seaweed_Block"
    },
    {
      "x": -27,
      "y": 28,
      "z": -4,
      "name": "Soil_Seaweed_Block"
    },
    {
      "x": -27,
      "y": 29,
      "z": -4,
      "name": "Soil_Seaweed_Block"
    },
    {
      "x": -27,
      "y": 30,
      "z": -4,
      "name": "Soil_Seaweed_Block"
    },
    {
      "x": -27,
      "y": 31,
      "z": -4,
      "name": "Soil_Seaweed_Block"
    },
    {
      "x": -27,
      "y": 32,
      "z": -4,
      "name": "Soil_Seaweed_Block"
    },
    {
      "x": -27,
      "y": 33,
      "z": -4,
      "name": "Soil_Seaweed_Block"
    },
    {
      "x": -27,
      "y": 34,
      "z": -4,
      "name": "Soil_Seaweed_Block"
    },
    {
      "x": -27,
      "y": 35,
      "z": -4,
      "name": "Soil_Seaweed_Block"
    },
    {
      "x": -27,
      "y": 36,
      "z": -4,
      "name": "Soil_Seaweed_Block"
    },
    {
      "x": -27,
      "y": 37,
      "z": -4,
      "name": "Soil_Seaweed_Block"
    },
    {
      "x": -27,
      "y": 38,
      "z": -4,
      "name": "Soil_Seaweed_Block"
    },
    {
      "x": -27,
      "y": 21,
      "z": -3,
      "name": "Soil_Clay_Green"
    },
    {
      "x": -27,
      "y": 22,
      "z": -3,
      "name": "Soil_Seaweed_Block"
    },
    {
      "x": -27,
      "y": 23,
      "z": -3,
      "name": "Soil_Seaweed_Block"
    },
    {
      "x": -27,
      "y": 24,
      "z": -3,
      "name": "Soil_Seaweed_Block"
    },
    {
      "x": -27,
      "y": 25,
      "z": -3,
      "name": "Soil_Seaweed_Block"
    },
    {
      "x": -27,
      "y": 26,
      "z": -3,
      "name": "Soil_Seaweed_Block"
    },
    {
      "x": -27,
      "y": 27,
      "z": -3,
      "name": "Soil_Seaweed_Block"
    },
    {
      "x": -27,
      "y": 28,
      "z": -3,
      "name": "Soil_Seaweed_Block"
    },
    {
      "x": -27,
      "y": 29,
      "z": -3,
      "name": "Soil_Seaweed_Block"
    },
    {
      "x": -27,
      "y": 30,
      "z": -3,
      "name": "Soil_Seaweed_Block"
    },
    {
      "x": -27,
      "y": 34,
      "z": -3,
      "name": "Soil_Clay_Green"
    },
    {
      "x": -27,
      "y": 35,
      "z": -3,
      "name": "Soil_Seaweed_Block"
    },
    {
      "x": -27,
      "y": 36,
      "z": -3,
      "name": "Soil_Seaweed_Block"
    },
    {
      "x": -27,
      "y": 37,
      "z": -3,
      "name": "Soil_Clay_Lime"
    },
    {
      "x": -27,
      "y": 38,
      "z": -3,
      "name": "Plant_Grass_Sharp"
    },
    {
      "x": -27,
      "y": 22,
      "z": -2,
      "name": "Soil_Clay_Green"
    },
    {
      "x": -27,
      "y": 23,
      "z": -2,
      "name": "Soil_Seaweed_Block"
    },
    {
      "x": -27,
      "y": 24,
      "z": -2,
      "name": "Soil_Seaweed_Block"
    },
    {
      "x": -27,
      "y": 25,
      "z": -2,
      "name": "Soil_Seaweed_Block"
    },
    {
      "x": -27,
      "y": 26,
      "z": -2,
      "name": "Soil_Seaweed_Block"
    },
    {
      "x": -27,
      "y": 27,
      "z": -2,
      "name": "Soil_Seaweed_Block"
    },
    {
      "x": -27,
      "y": 28,
      "z": -2,
      "name": "Soil_Seaweed_Block"
    },
    {
      "x": -27,
      "y": 29,
      "z": -2,
      "name": "Soil_Seaweed_Block"
    },
    {
      "x": -27,
      "y": 35,
      "z": -2,
      "name": "Soil_Clay_Green"
    },
    {
      "x": -27,
      "y": 36,
      "z": -2,
      "name": "Soil_Seaweed_Block"
    },
    {
      "x": -27,
      "y": 37,
      "z": -2,
      "name": "Soil_Clay_Lime"
    },
    {
      "x": -27,
      "y": 38,
      "z": -2,
      "name": "Plant_Grass_Sharp"
    },
    {
      "x": -27,
      "y": 22,
      "z": -1,
      "name": "Soil_Clay_Green"
    },
    {
      "x": -27,
      "y": 23,
      "z": -1,
      "name": "Soil_Seaweed_Block"
    },
    {
      "x": -27,
      "y": 24,
      "z": -1,
      "name": "Soil_Seaweed_Block"
    },
    {
      "x": -27,
      "y": 25,
      "z": -1,
      "name": "Soil_Seaweed_Block"
    },
    {
      "x": -27,
      "y": 26,
      "z": -1,
      "name": "Soil_Seaweed_Block"
    },
    {
      "x": -27,
      "y": 27,
      "z": -1,
      "name": "Soil_Seaweed_Block"
    },
    {
      "x": -27,
      "y": 28,
      "z": -1,
      "name": "Soil_Seaweed_Block"
    },
    {
      "x": -27,
      "y": 29,
      "z": -1,
      "name": "Soil_Clay_Lime"
    },
    {
      "x": -27,
      "y": 30,
      "z": -1,
      "name": "Plant_Grass_Sharp"
    },
    {
      "x": -27,
      "y": 35,
      "z": -1,
      "name": "Soil_Clay_Green"
    },
    {
      "x": -27,
      "y": 36,
      "z": -1,
      "name": "Soil_Seaweed_Block"
    },
    {
      "x": -27,
      "y": 37,
      "z": -1,
      "name": "Soil_Clay_Lime"
    },
    {
      "x": -27,
      "y": 38,
      "z": -1,
      "name": "Plant_Grass_Sharp"
    },
    {
      "x": -27,
      "y": 26,
      "z": 0,
      "name": "Soil_Clay_Green"
    },
    {
      "x": -27,
      "y": 27,
      "z": 0,
      "name": "Soil_Clay_Green"
    },
    {
      "x": -27,
      "y": 28,
      "z": 0,
      "name": "Soil_Seaweed_Block"
    },
    {
      "x": -27,
      "y": 29,
      "z": 0,
      "name": "Soil_Clay_Lime"
    },
    {
      "x": -27,
      "y": 30,
      "z": 0,
      "name": "Plant_Grass_Sharp"
    },
    {
      "x": -27,
      "y": 35,
      "z": 0,
      "name": "Soil_Clay_Green"
    },
    {
      "x": -27,
      "y": 36,
      "z": 0,
      "name": "Soil_Seaweed_Block"
    },
    {
      "x": -27,
      "y": 37,
      "z": 0,
      "name": "Soil_Clay_Lime"
    },
    {
      "x": -27,
      "y": 38,
      "z": 0,
      "name": "Plant_Grass_Sharp"
    },
    {
      "x": -27,
      "y": 27,
      "z": 1,
      "name": "Soil_Clay_Green"
    },
    {
      "x": -27,
      "y": 28,
      "z": 1,
      "name": "Soil_Seaweed_Block"
    },
    {
      "x": -27,
      "y": 29,
      "z": 1,
      "name": "Soil_Clay_Lime"
    },
    {
      "x": -27,
      "y": 30,
      "z": 1,
      "name": "Plant_Grass_Sharp"
    },
    {
      "x": -27,
      "y": 36,
      "z": 1,
      "name": "Soil_Seaweed_Block"
    },
    {
      "x": -27,
      "y": 37,
      "z": 1,
      "name": "Soil_Clay_Lime"
    },
    {
      "x": -27,
      "y": 38,
      "z": 1,
      "name": "Plant_Grass_Sharp"
    },
    {
      "x": -27,
      "y": 27,
      "z": 2,
      "name": "Soil_Clay_Green"
    },
    {
      "x": -27,
      "y": 28,
      "z": 2,
      "name": "Soil_Seaweed_Block"
    },
    {
      "x": -27,
      "y": 29,
      "z": 2,
      "name": "Soil_Clay_Lime"
    },
    {
      "x": -27,
      "y": 30,
      "z": 2,
      "name": "Plant_Grass_Sharp"
    },
    {
      "x": -27,
      "y": 36,
      "z": 2,
      "name": "Soil_Clay_Green"
    },
    {
      "x": -27,
      "y": 37,
      "z": 2,
      "name": "Soil_Clay_Lime"
    },
    {
      "x": -27,
      "y": 38,
      "z": 2,
      "name": "Plant_Grass_Sharp"
    },
    {
      "x": -27,
      "y": 28,
      "z": 3,
      "name": "Soil_Clay_Green"
    },
    {
      "x": -27,
      "y": 29,
      "z": 3,
      "name": "Soil_Seaweed_Block"
    },
    {
      "x": -27,
      "y": 30,
      "z": 3,
      "name": "Soil_Clay_Lime"
    },
    {
      "x": -27,
      "y": 31,
      "z": 3,
      "name": "Plant_Grass_Sharp"
    },
    {
      "x": -27,
      "y": 36,
      "z": 3,
      "name": "Soil_Clay_Green"
    },
    {
      "x": -27,
      "y": 28,
      "z": 4,
      "name": "Soil_Clay_Green"
    },
    {
      "x": -27,
      "y": 29,
      "z": 4,
      "name": "Soil_Clay_Green"
    },
    {
      "x": -27,
      "y": 30,
      "z": 4,
      "name": "Soil_Seaweed_Block"
    },
    {
      "x": -27,
      "y": 31,
      "z": 4,
      "name": "Soil_Clay_Lime"
    },
    {
      "x": -27,
      "y": 32,
      "z": 4,
      "name": "Plant_Grass_Sharp"
    },
    {
      "x": -27,
      "y": 36,
      "z": 4,
      "name": "Soil_Clay_Green"
    },
    {
      "x": -27,
      "y": 37,
      "z": 4,
      "name": "Soil_Seaweed_Block"
    },
    {
      "x": -27,
      "y": 28,
      "z": 5,
      "name": "Soil_Clay_Green"
    },
    {
      "x": -27,
      "y": 29,
      "z": 5,
      "name": "Soil_Clay_Green"
    },
    {
      "x": -27,
      "y": 30,
      "z": 5,
      "name": "Soil_Seaweed_Block"
    },
    {
      "x": -27,
      "y": 31,
      "z": 5,
      "name": "Soil_Seaweed_Block"
    },
    {
      "x": -27,
      "y": 36,
      "z": 5,
      "name": "Soil_Clay_Green"
    },
    {
      "x": -27,
      "y": 37,
      "z": 5,
      "name": "Soil_Seaweed_Block"
    },
    {
      "x": -27,
      "y": 28,
      "z": 6,
      "name": "Soil_Clay_Green"
    },
    {
      "x": -27,
      "y": 29,
      "z": 6,
      "name": "Soil_Seaweed_Block"
    },
    {
      "x": -27,
      "y": 30,
      "z": 6,
      "name": "Soil_Seaweed_Block"
    },
    {
      "x": -27,
      "y": 31,
      "z": 6,
      "name": "Soil_Seaweed_Block"
    },
    {
      "x": -27,
      "y": 32,
      "z": 6,
      "name": "Soil_Clay_Lime"
    },
    {
      "x": -27,
      "y": 33,
      "z": 6,
      "name": "Plant_Grass_Sharp"
    },
    {
      "x": -27,
      "y": 36,
      "z": 6,
      "name": "Soil_Clay_Green"
    },
    {
      "x": -27,
      "y": 37,
      "z": 6,
      "name": "Soil_Seaweed_Block"
    },
    {
      "x": -27,
      "y": 28,
      "z": 7,
      "name": "Soil_Clay_Green"
    },
    {
      "x": -27,
      "y": 29,
      "z": 7,
      "name": "Soil_Seaweed_Block"
    },
    {
      "x": -27,
      "y": 30,
      "z": 7,
      "name": "Soil_Seaweed_Block"
    },
    {
      "x": -27,
      "y": 31,
      "z": 7,
      "name": "Soil_Seaweed_Block"
    },
    {
      "x": -27,
      "y": 32,
      "z": 7,
      "name": "Soil_Seaweed_Block"
    },
    {
      "x": -27,
      "y": 33,
      "z": 7,
      "name": "Soil_Seaweed_Block"
    },
    {
      "x": -27,
      "y": 34,
      "z": 7,
      "name": "Soil_Seaweed_Block"
    },
    {
      "x": -27,
      "y": 35,
      "z": 7,
      "name": "Soil_Clay_Green"
    },
    {
      "x": -27,
      "y": 36,
      "z": 7,
      "name": "Soil_Seaweed_Block"
    },
    {
      "x": -27,
      "y": 37,
      "z": 7,
      "name": "Soil_Seaweed_Block"
    },
    {
      "x": -27,
      "y": 38,
      "z": 7,
      "name": "Soil_Seaweed_Block"
    },
    {
      "x": -27,
      "y": 39,
      "z": 7,
      "name": "Soil_Clay_Lime"
    },
    {
      "x": -27,
      "y": 40,
      "z": 7,
      "name": "Plant_Grass_Sharp"
    },
    {
      "x": -27,
      "y": 28,
      "z": 8,
      "name": "Soil_Clay_Green"
    },
    {
      "x": -27,
      "y": 29,
      "z": 8,
      "name": "Soil_Seaweed_Block"
    },
    {
      "x": -27,
      "y": 30,
      "z": 8,
      "name": "Soil_Seaweed_Block"
    },
    {
      "x": -27,
      "y": 31,
      "z": 8,
      "name": "Soil_Seaweed_Block"
    },
    {
      "x": -27,
      "y": 32,
      "z": 8,
      "name": "Soil_Seaweed_Block"
    },
    {
      "x": -27,
      "y": 33,
      "z": 8,
      "name": "Soil_Seaweed_Block"
    },
    {
      "x": -27,
      "y": 34,
      "z": 8,
      "name": "Soil_Seaweed_Block"
    },
    {
      "x": -27,
      "y": 35,
      "z": 8,
      "name": "Soil_Seaweed_Block"
    },
    {
      "x": -27,
      "y": 36,
      "z": 8,
      "name": "Soil_Seaweed_Block"
    },
    {
      "x": -27,
      "y": 37,
      "z": 8,
      "name": "Soil_Seaweed_Block"
    },
    {
      "x": -27,
      "y": 38,
      "z": 8,
      "name": "Soil_Seaweed_Block"
    },
    {
      "x": -27,
      "y": 39,
      "z": 8,
      "name": "Soil_Clay_Lime"
    },
    {
      "x": -27,
      "y": 40,
      "z": 8,
      "name": "Plant_Grass_Sharp"
    },
    {
      "x": -27,
      "y": 28,
      "z": 9,
      "name": "Soil_Clay_Green"
    },
    {
      "x": -27,
      "y": 29,
      "z": 9,
      "name": "Soil_Seaweed_Block"
    },
    {
      "x": -27,
      "y": 30,
      "z": 9,
      "name": "Soil_Seaweed_Block"
    },
    {
      "x": -27,
      "y": 31,
      "z": 9,
      "name": "Soil_Seaweed_Block"
    },
    {
      "x": -27,
      "y": 32,
      "z": 9,
      "name": "Soil_Seaweed_Block"
    },
    {
      "x": -27,
      "y": 33,
      "z": 9,
      "name": "Soil_Seaweed_Block"
    },
    {
      "x": -27,
      "y": 34,
      "z": 9,
      "name": "Soil_Seaweed_Block"
    },
    {
      "x": -27,
      "y": 35,
      "z": 9,
      "name": "Soil_Seaweed_Block"
    },
    {
      "x": -27,
      "y": 36,
      "z": 9,
      "name": "Soil_Seaweed_Block"
    },
    {
      "x": -27,
      "y": 37,
      "z": 9,
      "name": "Soil_Seaweed_Block"
    },
    {
      "x": -27,
      "y": 38,
      "z": 9,
      "name": "Soil_Seaweed_Block"
    },
    {
      "x": -27,
      "y": 39,
      "z": 9,
      "name": "Soil_Seaweed_Block"
    },
    {
      "x": -27,
      "y": 40,
      "z": 9,
      "name": "Soil_Seaweed_Block"
    },
    {
      "x": -27,
      "y": 42,
      "z": 9,
      "name": "Soil_Seaweed_Block"
    },
    {
      "x": -27,
      "y": 43,
      "z": 9,
      "name": "Soil_Seaweed_Block"
    },
    {
      "x": -27,
      "y": 44,
      "z": 9,
      "name": "Soil_Seaweed_Block"
    },
    {
      "x": -27,
      "y": 28,
      "z": 10,
      "name": "Soil_Clay_Green"
    },
    {
      "x": -27,
      "y": 29,
      "z": 10,
      "name": "Soil_Clay_Green"
    },
    {
      "x": -27,
      "y": 30,
      "z": 10,
      "name": "Soil_Seaweed_Block"
    },
    {
      "x": -27,
      "y": 31,
      "z": 10,
      "name": "Soil_Seaweed_Block"
    },
    {
      "x": -27,
      "y": 32,
      "z": 10,
      "name": "Soil_Seaweed_Block"
    },
    {
      "x": -27,
      "y": 33,
      "z": 10,
      "name": "Soil_Seaweed_Block"
    },
    {
      "x": -27,
      "y": 34,
      "z": 10,
      "name": "Soil_Seaweed_Block"
    },
    {
      "x": -27,
      "y": 35,
      "z": 10,
      "name": "Soil_Seaweed_Block"
    },
    {
      "x": -27,
      "y": 36,
      "z": 10,
      "name": "Soil_Seaweed_Block"
    },
    {
      "x": -27,
      "y": 37,
      "z": 10,
      "name": "Soil_Seaweed_Block"
    },
    {
      "x": -27,
      "y": 38,
      "z": 10,
      "name": "Soil_Seaweed_Block"
    },
    {
      "x": -27,
      "y": 39,
      "z": 10,
      "name": "Soil_Seaweed_Block"
    },
    {
      "x": -27,
      "y": 42,
      "z": 10,
      "name": "Soil_Seaweed_Block"
    },
    {
      "x": -27,
      "y": 43,
      "z": 10,
      "name": "Soil_Seaweed_Block"
    },
    {
      "x": -27,
      "y": 44,
      "z": 10,
      "name": "Soil_Seaweed_Block"
    },
    {
      "x": -27,
      "y": 37,
      "z": 11,
      "name": "Soil_Seaweed_Block"
    },
    {
      "x": -27,
      "y": 43,
      "z": 11,
      "name": "Soil_Seaweed_Block"
    },
    {
      "x": -26,
      "y": 38,
      "z": -11,
      "name": "Soil_Seaweed_Block"
    },
    {
      "x": -26,
      "y": 39,
      "z": -11,
      "name": "Soil_Seaweed_Block"
    },
    {
      "x": -26,
      "y": 31,
      "z": -10,
      "name": "Soil_Clay_Green"
    },
    {
      "x": -26,
      "y": 32,
      "z": -10,
      "name": "Soil_Clay_Green"
    },
    {
      "x": -26,
      "y": 33,
      "z": -10,
      "name": "Soil_Seaweed_Block"
    },
    {
      "x": -26,
      "y": 34,
      "z": -10,
      "name": "Soil_Seaweed_Block"
    },
    {
      "x": -26,
      "y": 35,
      "z": -10,
      "name": "Soil_Seaweed_Block"
    },
    {
      "x": -26,
      "y": 38,
      "z": -10,
      "name": "Soil_Seaweed_Block"
    },
    {
      "x": -26,
      "y": 39,
      "z": -10,
      "name": "Soil_Seaweed_Block"
    },
    {
      "x": -26,
      "y": 30,
      "z": -9,
      "name": "Soil_Clay_Green"
    },
    {
      "x": -26,
      "y": 31,
      "z": -9,
      "name": "Soil_Seaweed_Block"
    },
    {
      "x": -26,
      "y": 32,
      "z": -9,
      "name": "Soil_Seaweed_Block"
    },
    {
      "x": -26,
      "y": 33,
      "z": -9,
      "name": "Soil_Seaweed_Block"
    },
    {
      "x": -26,
      "y": 34,
      "z": -9,
      "name": "Soil_Seaweed_Block"
    },
    {
      "x": -26,
      "y": 35,
      "z": -9,
      "name": "Soil_Seaweed_Block"
    },
    {
      "x": -26,
      "y": 36,
      "z": -9,
      "name": "Soil_Seaweed_Block"
    },
    {
      "x": -26,
      "y": 37,
      "z": -9,
      "name": "Soil_Seaweed_Block"
    },
    {
      "x": -26,
      "y": 38,
      "z": -9,
      "name": "Soil_Seaweed_Block"
    },
    {
      "x": -26,
      "y": 39,
      "z": -9,
      "name": "Soil_Seaweed_Block"
    },
    {
      "x": -26,
      "y": 40,
      "z": -9,
      "name": "Soil_Seaweed_Block"
    },
    {
      "x": -26,
      "y": 28,
      "z": -8,
      "name": "Soil_Clay_Green"
    },
    {
      "x": -26,
      "y": 29,
      "z": -8,
      "name": "Soil_Clay_Green"
    },
    {
      "x": -26,
      "y": 30,
      "z": -8,
      "name": "Soil_Seaweed_Block"
    },
    {
      "x": -26,
      "y": 31,
      "z": -8,
      "name": "Soil_Seaweed_Block"
    },
    {
      "x": -26,
      "y": 32,
      "z": -8,
      "name": "Soil_Seaweed_Block"
    },
    {
      "x": -26,
      "y": 33,
      "z": -8,
      "name": "Soil_Seaweed_Block"
    },
    {
      "x": -26,
      "y": 34,
      "z": -8,
      "name": "Soil_Seaweed_Block"
    },
    {
      "x": -26,
      "y": 35,
      "z": -8,
      "name": "Soil_Seaweed_Block"
    },
    {
      "x": -26,
      "y": 36,
      "z": -8,
      "name": "Soil_Seaweed_Block"
    },
    {
      "x": -26,
      "y": 37,
      "z": -8,
      "name": "Soil_Seaweed_Block"
    },
    {
      "x": -26,
      "y": 38,
      "z": -8,
      "name": "Soil_Seaweed_Block"
    },
    {
      "x": -26,
      "y": 39,
      "z": -8,
      "name": "Soil_Seaweed_Block"
    },
    {
      "x": -26,
      "y": 40,
      "z": -8,
      "name": "Soil_Seaweed_Block"
    },
    {
      "x": -26,
      "y": 41,
      "z": -8,
      "name": "Soil_Clay_Lime"
    },
    {
      "x": -26,
      "y": 42,
      "z": -8,
      "name": "Plant_Grass_Sharp"
    },
    {
      "x": -26,
      "y": 26,
      "z": -7,
      "name": "Soil_Clay_Green"
    },
    {
      "x": -26,
      "y": 27,
      "z": -7,
      "name": "Soil_Clay_Green"
    },
    {
      "x": -26,
      "y": 28,
      "z": -7,
      "name": "Soil_Seaweed_Block"
    },
    {
      "x": -26,
      "y": 29,
      "z": -7,
      "name": "Soil_Seaweed_Block"
    },
    {
      "x": -26,
      "y": 30,
      "z": -7,
      "name": "Soil_Seaweed_Block"
    },
    {
      "x": -26,
      "y": 31,
      "z": -7,
      "name": "Soil_Seaweed_Block"
    },
    {
      "x": -26,
      "y": 32,
      "z": -7,
      "name": "Soil_Seaweed_Block"
    },
    {
      "x": -26,
      "y": 33,
      "z": -7,
      "name": "Soil_Seaweed_Block"
    },
    {
      "x": -26,
      "y": 34,
      "z": -7,
      "name": "Soil_Seaweed_Block"
    },
    {
      "x": -26,
      "y": 35,
      "z": -7,
      "name": "Soil_Seaweed_Block"
    },
    {
      "x": -26,
      "y": 36,
      "z": -7,
      "name": "Soil_Seaweed_Block"
    },
    {
      "x": -26,
      "y": 37,
      "z": -7,
      "name": "Soil_Seaweed_Block"
    },
    {
      "x": -26,
      "y": 38,
      "z": -7,
      "name": "Soil_Seaweed_Block"
    },
    {
      "x": -26,
      "y": 39,
      "z": -7,
      "name": "Soil_Seaweed_Block"
    },
    {
      "x": -26,
      "y": 40,
      "z": -7,
      "name": "Soil_Seaweed_Block"
    },
    {
      "x": -26,
      "y": 41,
      "z": -7,
      "name": "Soil_Clay_Lime"
    },
    {
      "x": -26,
      "y": 42,
      "z": -7,
      "name": "Plant_Grass_Sharp"
    },
    {
      "x": -26,
      "y": 25,
      "z": -6,
      "name": "Soil_Clay_Green"
    },
    {
      "x": -26,
      "y": 26,
      "z": -6,
      "name": "Soil_Clay_Green"
    },
    {
      "x": -26,
      "y": 27,
      "z": -6,
      "name": "Soil_Seaweed_Block"
    },
    {
      "x": -26,
      "y": 28,
      "z": -6,
      "name": "Soil_Seaweed_Block"
    },
    {
      "x": -26,
      "y": 29,
      "z": -6,
      "name": "Soil_Seaweed_Block"
    },
    {
      "x": -26,
      "y": 30,
      "z": -6,
      "name": "Soil_Seaweed_Block"
    },
    {
      "x": -26,
      "y": 31,
      "z": -6,
      "name": "Soil_Seaweed_Block"
    },
    {
      "x": -26,
      "y": 32,
      "z": -6,
      "name": "Soil_Seaweed_Block"
    },
    {
      "x": -26,
      "y": 33,
      "z": -6,
      "name": "Soil_Seaweed_Block"
    },
    {
      "x": -26,
      "y": 34,
      "z": -6,
      "name": "Soil_Seaweed_Block"
    },
    {
      "x": -26,
      "y": 35,
      "z": -6,
      "name": "Soil_Seaweed_Block"
    },
    {
      "x": -26,
      "y": 36,
      "z": -6,
      "name": "Soil_Seaweed_Block"
    },
    {
      "x": -26,
      "y": 37,
      "z": -6,
      "name": "Soil_Seaweed_Block"
    },
    {
      "x": -26,
      "y": 38,
      "z": -6,
      "name": "Soil_Seaweed_Block"
    },
    {
      "x": -26,
      "y": 39,
      "z": -6,
      "name": "Soil_Seaweed_Block"
    },
    {
      "x": -26,
      "y": 40,
      "z": -6,
      "name": "Soil_Seaweed_Block"
    },
    {
      "x": -26,
      "y": 41,
      "z": -6,
      "name": "Soil_Clay_Lime"
    },
    {
      "x": -26,
      "y": 42,
      "z": -6,
      "name": "Plant_Grass_Sharp"
    },
    {
      "x": -26,
      "y": 21,
      "z": -5,
      "name": "Soil_Clay_Green"
    },
    {
      "x": -26,
      "y": 22,
      "z": -5,
      "name": "Soil_Seaweed_Block"
    },
    {
      "x": -26,
      "y": 23,
      "z": -5,
      "name": "Soil_Seaweed_Block"
    },
    {
      "x": -26,
      "y": 24,
      "z": -5,
      "name": "Soil_Seaweed_Block"
    },
    {
      "x": -26,
      "y": 25,
      "z": -5,
      "name": "Soil_Seaweed_Block"
    },
    {
      "x": -26,
      "y": 26,
      "z": -5,
      "name": "Soil_Seaweed_Block"
    },
    {
      "x": -26,
      "y": 27,
      "z": -5,
      "name": "Soil_Seaweed_Block"
    },
    {
      "x": -26,
      "y": 28,
      "z": -5,
      "name": "Soil_Seaweed_Block"
    },
    {
      "x": -26,
      "y": 29,
      "z": -5,
      "name": "Soil_Seaweed_Block"
    },
    {
      "x": -26,
      "y": 30,
      "z": -5,
      "name": "Soil_Seaweed_Block"
    },
    {
      "x": -26,
      "y": 31,
      "z": -5,
      "name": "Soil_Seaweed_Block"
    },
    {
      "x": -26,
      "y": 32,
      "z": -5,
      "name": "Soil_Seaweed_Block"
    },
    {
      "x": -26,
      "y": 33,
      "z": -5,
      "name": "Soil_Seaweed_Block"
    },
    {
      "x": -26,
      "y": 34,
      "z": -5,
      "name": "Soil_Seaweed_Block"
    },
    {
      "x": -26,
      "y": 35,
      "z": -5,
      "name": "Soil_Seaweed_Block"
    },
    {
      "x": -26,
      "y": 36,
      "z": -5,
      "name": "Soil_Seaweed_Block"
    },
    {
      "x": -26,
      "y": 37,
      "z": -5,
      "name": "Soil_Seaweed_Block"
    },
    {
      "x": -26,
      "y": 38,
      "z": -5,
      "name": "Soil_Seaweed_Block"
    },
    {
      "x": -26,
      "y": 39,
      "z": -5,
      "name": "Soil_Seaweed_Block"
    },
    {
      "x": -26,
      "y": 40,
      "z": -5,
      "name": "Soil_Seaweed_Block"
    },
    {
      "x": -26,
      "y": 19,
      "z": -4,
      "name": "Soil_Clay_Green"
    },
    {
      "x": -26,
      "y": 20,
      "z": -4,
      "name": "Soil_Clay_Green"
    },
    {
      "x": -26,
      "y": 21,
      "z": -4,
      "name": "Soil_Seaweed_Block"
    },
    {
      "x": -26,
      "y": 22,
      "z": -4,
      "name": "Soil_Seaweed_Block"
    },
    {
      "x": -26,
      "y": 23,
      "z": -4,
      "name": "Soil_Seaweed_Block"
    },
    {
      "x": -26,
      "y": 24,
      "z": -4,
      "name": "Soil_Seaweed_Block"
    },
    {
      "x": -26,
      "y": 25,
      "z": -4,
      "name": "Soil_Seaweed_Block"
    },
    {
      "x": -26,
      "y": 26,
      "z": -4,
      "name": "Soil_Seaweed_Block"
    },
    {
      "x": -26,
      "y": 27,
      "z": -4,
      "name": "Soil_Seaweed_Block"
    },
    {
      "x": -26,
      "y": 28,
      "z": -4,
      "name": "Soil_Seaweed_Block"
    },
    {
      "x": -26,
      "y": 29,
      "z": -4,
      "name": "Soil_Seaweed_Block"
    },
    {
      "x": -26,
      "y": 30,
      "z": -4,
      "name": "Soil_Seaweed_Block"
    },
    {
      "x": -26,
      "y": 31,
      "z": -4,
      "name": "Soil_Seaweed_Block"
    },
    {
      "x": -26,
      "y": 32,
      "z": -4,
      "name": "Soil_Seaweed_Block"
    },
    {
      "x": -26,
      "y": 33,
      "z": -4,
      "name": "Soil_Clay_Green"
    },
    {
      "x": -26,
      "y": 34,
      "z": -4,
      "name": "Soil_Seaweed_Block"
    },
    {
      "x": -26,
      "y": 35,
      "z": -4,
      "name": "Soil_Seaweed_Block"
    },
    {
      "x": -26,
      "y": 36,
      "z": -4,
      "name": "Soil_Seaweed_Block"
    },
    {
      "x": -26,
      "y": 37,
      "z": -4,
      "name": "Soil_Seaweed_Block"
    },
    {
      "x": -26,
      "y": 38,
      "z": -4,
      "name": "Soil_Seaweed_Block"
    },
    {
      "x": -26,
      "y": 39,
      "z": -4,
      "name": "Soil_Seaweed_Block"
    },
    {
      "x": -26,
      "y": 40,
      "z": -4,
      "name": "Soil_Seaweed_Block"
    },
    {
      "x": -26,
      "y": 20,
      "z": -3,
      "name": "Soil_Clay_Green"
    },
    {
      "x": -26,
      "y": 21,
      "z": -3,
      "name": "Soil_Seaweed_Block"
    },
    {
      "x": -26,
      "y": 22,
      "z": -3,
      "name": "Soil_Seaweed_Block"
    },
    {
      "x": -26,
      "y": 23,
      "z": -3,
      "name": "Soil_Seaweed_Block"
    },
    {
      "x": -26,
      "y": 24,
      "z": -3,
      "name": "Soil_Seaweed_Block"
    },
    {
      "x": -26,
      "y": 25,
      "z": -3,
      "name": "Soil_Seaweed_Block"
    },
    {
      "x": -26,
      "y": 26,
      "z": -3,
      "name": "Soil_Seaweed_Block"
    },
    {
      "x": -26,
      "y": 27,
      "z": -3,
      "name": "Soil_Seaweed_Block"
    },
    {
      "x": -26,
      "y": 28,
      "z": -3,
      "name": "Soil_Seaweed_Block"
    },
    {
      "x": -26,
      "y": 29,
      "z": -3,
      "name": "Soil_Seaweed_Block"
    },
    {
      "x": -26,
      "y": 30,
      "z": -3,
      "name": "Soil_Seaweed_Block"
    },
    {
      "x": -26,
      "y": 31,
      "z": -3,
      "name": "Soil_Seaweed_Block"
    },
    {
      "x": -26,
      "y": 32,
      "z": -3,
      "name": "Soil_Seaweed_Block"
    },
    {
      "x": -26,
      "y": 33,
      "z": -3,
      "name": "Soil_Clay_Green"
    },
    {
      "x": -26,
      "y": 34,
      "z": -3,
      "name": "Soil_Seaweed_Block"
    },
    {
      "x": -26,
      "y": 35,
      "z": -3,
      "name": "Soil_Seaweed_Block"
    },
    {
      "x": -26,
      "y": 36,
      "z": -3,
      "name": "Soil_Seaweed_Block"
    },
    {
      "x": -26,
      "y": 37,
      "z": -3,
      "name": "Soil_Seaweed_Block"
    },
    {
      "x": -26,
      "y": 38,
      "z": -3,
      "name": "Soil_Clay_Lime"
    },
    {
      "x": -26,
      "y": 39,
      "z": -3,
      "name": "Plant_Grass_Sharp"
    },
    {
      "x": -26,
      "y": 21,
      "z": -2,
      "name": "Soil_Clay_Green"
    },
    {
      "x": -26,
      "y": 22,
      "z": -2,
      "name": "Soil_Seaweed_Block"
    },
    {
      "x": -26,
      "y": 23,
      "z": -2,
      "name": "Soil_Seaweed_Block"
    },
    {
      "x": -26,
      "y": 24,
      "z": -2,
      "name": "Soil_Seaweed_Block"
    },
    {
      "x": -26,
      "y": 25,
      "z": -2,
      "name": "Soil_Seaweed_Block"
    },
    {
      "x": -26,
      "y": 26,
      "z": -2,
      "name": "Soil_Seaweed_Block"
    },
    {
      "x": -26,
      "y": 27,
      "z": -2,
      "name": "Soil_Seaweed_Block"
    },
    {
      "x": -26,
      "y": 28,
      "z": -2,
      "name": "Soil_Seaweed_Block"
    },
    {
      "x": -26,
      "y": 29,
      "z": -2,
      "name": "Soil_Seaweed_Block"
    },
    {
      "x": -26,
      "y": 30,
      "z": -2,
      "name": "Soil_Clay_Lime"
    },
    {
      "x": -26,
      "y": 31,
      "z": -2,
      "name": "Plant_Grass_Sharp"
    },
    {
      "x": -26,
      "y": 35,
      "z": -2,
      "name": "Soil_Clay_Green"
    },
    {
      "x": -26,
      "y": 36,
      "z": -2,
      "name": "Soil_Seaweed_Block"
    },
    {
      "x": -26,
      "y": 37,
      "z": -2,
      "name": "Soil_Clay_Lime"
    },
    {
      "x": -26,
      "y": 38,
      "z": -2,
      "name": "Plant_Grass_Sharp"
    },
    {
      "x": -26,
      "y": 22,
      "z": -1,
      "name": "Soil_Clay_Green"
    },
    {
      "x": -26,
      "y": 23,
      "z": -1,
      "name": "Soil_Seaweed_Block"
    },
    {
      "x": -26,
      "y": 24,
      "z": -1,
      "name": "Soil_Seaweed_Block"
    },
    {
      "x": -26,
      "y": 25,
      "z": -1,
      "name": "Soil_Seaweed_Block"
    },
    {
      "x": -26,
      "y": 26,
      "z": -1,
      "name": "Soil_Seaweed_Block"
    },
    {
      "x": -26,
      "y": 27,
      "z": -1,
      "name": "Soil_Seaweed_Block"
    },
    {
      "x": -26,
      "y": 28,
      "z": -1,
      "name": "Soil_Seaweed_Block"
    },
    {
      "x": -26,
      "y": 29,
      "z": -1,
      "name": "Soil_Clay_Lime"
    },
    {
      "x": -26,
      "y": 30,
      "z": -1,
      "name": "Plant_Grass_Sharp"
    },
    {
      "x": -26,
      "y": 35,
      "z": -1,
      "name": "Soil_Clay_Green"
    },
    {
      "x": -26,
      "y": 36,
      "z": -1,
      "name": "Soil_Seaweed_Block"
    },
    {
      "x": -26,
      "y": 37,
      "z": -1,
      "name": "Soil_Clay_Lime"
    },
    {
      "x": -26,
      "y": 38,
      "z": -1,
      "name": "Plant_Grass_Sharp"
    },
    {
      "x": -26,
      "y": 23,
      "z": 0,
      "name": "Soil_Seaweed_Block"
    },
    {
      "x": -26,
      "y": 24,
      "z": 0,
      "name": "Soil_Seaweed_Block"
    },
    {
      "x": -26,
      "y": 25,
      "z": 0,
      "name": "Soil_Seaweed_Block"
    },
    {
      "x": -26,
      "y": 26,
      "z": 0,
      "name": "Soil_Clay_Green"
    },
    {
      "x": -26,
      "y": 27,
      "z": 0,
      "name": "Soil_Seaweed_Block"
    },
    {
      "x": -26,
      "y": 28,
      "z": 0,
      "name": "Soil_Seaweed_Block"
    },
    {
      "x": -26,
      "y": 29,
      "z": 0,
      "name": "Soil_Clay_Lime"
    },
    {
      "x": -26,
      "y": 30,
      "z": 0,
      "name": "Plant_Grass_Sharp"
    },
    {
      "x": -26,
      "y": 35,
      "z": 0,
      "name": "Soil_Clay_Green"
    },
    {
      "x": -26,
      "y": 36,
      "z": 0,
      "name": "Soil_Seaweed_Block"
    },
    {
      "x": -26,
      "y": 37,
      "z": 0,
      "name": "Soil_Clay_Lime"
    },
    {
      "x": -26,
      "y": 38,
      "z": 0,
      "name": "Plant_Grass_Sharp"
    },
    {
      "x": -26,
      "y": 26,
      "z": 1,
      "name": "Soil_Clay_Green"
    },
    {
      "x": -26,
      "y": 27,
      "z": 1,
      "name": "Soil_Seaweed_Block"
    },
    {
      "x": -26,
      "y": 28,
      "z": 1,
      "name": "Soil_Seaweed_Block"
    },
    {
      "x": -26,
      "y": 29,
      "z": 1,
      "name": "Soil_Clay_Lime"
    },
    {
      "x": -26,
      "y": 30,
      "z": 1,
      "name": "Plant_Grass_Sharp"
    },
    {
      "x": -26,
      "y": 35,
      "z": 1,
      "name": "Soil_Clay_Green"
    },
    {
      "x": -26,
      "y": 36,
      "z": 1,
      "name": "Soil_Seaweed_Block"
    },
    {
      "x": -26,
      "y": 37,
      "z": 1,
      "name": "Soil_Clay_Lime"
    },
    {
      "x": -26,
      "y": 38,
      "z": 1,
      "name": "Plant_Grass_Sharp"
    },
    {
      "x": -26,
      "y": 27,
      "z": 2,
      "name": "Soil_Clay_Green"
    },
    {
      "x": -26,
      "y": 28,
      "z": 2,
      "name": "Soil_Seaweed_Block"
    },
    {
      "x": -26,
      "y": 29,
      "z": 2,
      "name": "Soil_Seaweed_Block"
    },
    {
      "x": -26,
      "y": 30,
      "z": 2,
      "name": "Soil_Clay_Lime"
    },
    {
      "x": -26,
      "y": 31,
      "z": 2,
      "name": "Plant_Grass_Sharp"
    },
    {
      "x": -26,
      "y": 36,
      "z": 2,
      "name": "Soil_Clay_Green"
    },
    {
      "x": -26,
      "y": 37,
      "z": 2,
      "name": "Soil_Clay_Lime"
    },
    {
      "x": -26,
      "y": 38,
      "z": 2,
      "name": "Plant_Grass_Sharp"
    },
    {
      "x": -26,
      "y": 28,
      "z": 3,
      "name": "Soil_Clay_Green"
    },
    {
      "x": -26,
      "y": 29,
      "z": 3,
      "name": "Soil_Seaweed_Block"
    },
    {
      "x": -26,
      "y": 30,
      "z": 3,
      "name": "Soil_Clay_Lime"
    },
    {
      "x": -26,
      "y": 31,
      "z": 3,
      "name": "Plant_Grass_Sharp"
    },
    {
      "x": -26,
      "y": 36,
      "z": 3,
      "name": "Soil_Clay_Green"
    },
    {
      "x": -26,
      "y": 37,
      "z": 3,
      "name": "Soil_Clay_Lime"
    },
    {
      "x": -26,
      "y": 38,
      "z": 3,
      "name": "Plant_Grass_Sharp"
    },
    {
      "x": -26,
      "y": 28,
      "z": 4,
      "name": "Soil_Clay_Green"
    },
    {
      "x": -26,
      "y": 29,
      "z": 4,
      "name": "Soil_Seaweed_Block"
    },
    {
      "x": -26,
      "y": 30,
      "z": 4,
      "name": "Soil_Seaweed_Block"
    },
    {
      "x": -26,
      "y": 31,
      "z": 4,
      "name": "Soil_Clay_Lime"
    },
    {
      "x": -26,
      "y": 32,
      "z": 4,
      "name": "Plant_Grass_Sharp"
    },
    {
      "x": -26,
      "y": 36,
      "z": 4,
      "name": "Soil_Clay_Green"
    },
    {
      "x": -26,
      "y": 37,
      "z": 4,
      "name": "Soil_Clay_Lime"
    },
    {
      "x": -26,
      "y": 38,
      "z": 4,
      "name": "Plant_Grass_Sharp"
    },
    {
      "x": -26,
      "y": 28,
      "z": 5,
      "name": "Soil_Clay_Green"
    },
    {
      "x": -26,
      "y": 29,
      "z": 5,
      "name": "Soil_Seaweed_Block"
    },
    {
      "x": -26,
      "y": 30,
      "z": 5,
      "name": "Soil_Seaweed_Block"
    },
    {
      "x": -26,
      "y": 31,
      "z": 5,
      "name": "Soil_Seaweed_Block"
    },
    {
      "x": -26,
      "y": 32,
      "z": 5,
      "name": "Soil_Clay_Lime"
    },
    {
      "x": -26,
      "y": 33,
      "z": 5,
      "name": "Plant_Grass_Sharp"
    },
    {
      "x": -26,
      "y": 36,
      "z": 5,
      "name": "Soil_Clay_Green"
    },
    {
      "x": -26,
      "y": 37,
      "z": 5,
      "name": "Soil_Seaweed_Block"
    },
    {
      "x": -26,
      "y": 28,
      "z": 6,
      "name": "Soil_Clay_Green"
    },
    {
      "x": -26,
      "y": 29,
      "z": 6,
      "name": "Soil_Seaweed_Block"
    },
    {
      "x": -26,
      "y": 30,
      "z": 6,
      "name": "Soil_Seaweed_Block"
    },
    {
      "x": -26,
      "y": 31,
      "z": 6,
      "name": "Soil_Seaweed_Block"
    },
    {
      "x": -26,
      "y": 32,
      "z": 6,
      "name": "Soil_Seaweed_Block"
    },
    {
      "x": -26,
      "y": 36,
      "z": 6,
      "name": "Soil_Clay_Green"
    },
    {
      "x": -26,
      "y": 37,
      "z": 6,
      "name": "Soil_Seaweed_Block"
    },
    {
      "x": -26,
      "y": 38,
      "z": 6,
      "name": "Soil_Seaweed_Block"
    },
    {
      "x": -26,
      "y": 28,
      "z": 7,
      "name": "Soil_Clay_Green"
    },
    {
      "x": -26,
      "y": 29,
      "z": 7,
      "name": "Soil_Seaweed_Block"
    },
    {
      "x": -26,
      "y": 30,
      "z": 7,
      "name": "Soil_Seaweed_Block"
    },
    {
      "x": -26,
      "y": 31,
      "z": 7,
      "name": "Soil_Seaweed_Block"
    },
    {
      "x": -26,
      "y": 32,
      "z": 7,
      "name": "Soil_Seaweed_Block"
    },
    {
      "x": -26,
      "y": 33,
      "z": 7,
      "name": "Soil_Seaweed_Block"
    },
    {
      "x": -26,
      "y": 34,
      "z": 7,
      "name": "Soil_Seaweed_Block"
    },
    {
      "x": -26,
      "y": 35,
      "z": 7,
      "name": "Soil_Clay_Green"
    },
    {
      "x": -26,
      "y": 36,
      "z": 7,
      "name": "Soil_Seaweed_Block"
    },
    {
      "x": -26,
      "y": 37,
      "z": 7,
      "name": "Soil_Seaweed_Block"
    },
    {
      "x": -26,
      "y": 38,
      "z": 7,
      "name": "Soil_Seaweed_Block"
    },
    {
      "x": -26,
      "y": 39,
      "z": 7,
      "name": "Soil_Seaweed_Block"
    },
    {
      "x": -26,
      "y": 28,
      "z": 8,
      "name": "Soil_Clay_Green"
    },
    {
      "x": -26,
      "y": 29,
      "z": 8,
      "name": "Soil_Seaweed_Block"
    },
    {
      "x": -26,
      "y": 30,
      "z": 8,
      "name": "Soil_Seaweed_Block"
    },
    {
      "x": -26,
      "y": 31,
      "z": 8,
      "name": "Soil_Seaweed_Block"
    },
    {
      "x": -26,
      "y": 32,
      "z": 8,
      "name": "Soil_Seaweed_Block"
    },
    {
      "x": -26,
      "y": 33,
      "z": 8,
      "name": "Soil_Seaweed_Block"
    },
    {
      "x": -26,
      "y": 34,
      "z": 8,
      "name": "Soil_Seaweed_Block"
    },
    {
      "x": -26,
      "y": 35,
      "z": 8,
      "name": "Soil_Seaweed_Block"
    },
    {
      "x": -26,
      "y": 36,
      "z": 8,
      "name": "Soil_Seaweed_Block"
    },
    {
      "x": -26,
      "y": 37,
      "z": 8,
      "name": "Soil_Seaweed_Block"
    },
    {
      "x": -26,
      "y": 38,
      "z": 8,
      "name": "Soil_Seaweed_Block"
    },
    {
      "x": -26,
      "y": 39,
      "z": 8,
      "name": "Soil_Seaweed_Block"
    },
    {
      "x": -26,
      "y": 40,
      "z": 8,
      "name": "Soil_Seaweed_Block"
    },
    {
      "x": -26,
      "y": 41,
      "z": 8,
      "name": "Soil_Seaweed_Block"
    },
    {
      "x": -26,
      "y": 42,
      "z": 8,
      "name": "Soil_Seaweed_Block"
    },
    {
      "x": -26,
      "y": 43,
      "z": 8,
      "name": "Soil_Seaweed_Block"
    },
    {
      "x": -26,
      "y": 44,
      "z": 8,
      "name": "Soil_Seaweed_Block"
    },
    {
      "x": -26,
      "y": 27,
      "z": 9,
      "name": "Soil_Clay_Green"
    },
    {
      "x": -26,
      "y": 28,
      "z": 9,
      "name": "Soil_Seaweed_Block"
    },
    {
      "x": -26,
      "y": 29,
      "z": 9,
      "name": "Soil_Seaweed_Block"
    },
    {
      "x": -26,
      "y": 30,
      "z": 9,
      "name": "Soil_Seaweed_Block"
    },
    {
      "x": -26,
      "y": 31,
      "z": 9,
      "name": "Soil_Seaweed_Block"
    },
    {
      "x": -26,
      "y": 32,
      "z": 9,
      "name": "Soil_Seaweed_Block"
    },
    {
      "x": -26,
      "y": 33,
      "z": 9,
      "name": "Soil_Seaweed_Block"
    },
    {
      "x": -26,
      "y": 34,
      "z": 9,
      "name": "Soil_Seaweed_Block"
    },
    {
      "x": -26,
      "y": 35,
      "z": 9,
      "name": "Soil_Seaweed_Block"
    },
    {
      "x": -26,
      "y": 36,
      "z": 9,
      "name": "Soil_Seaweed_Block"
    },
    {
      "x": -26,
      "y": 37,
      "z": 9,
      "name": "Soil_Seaweed_Block"
    },
    {
      "x": -26,
      "y": 38,
      "z": 9,
      "name": "Soil_Seaweed_Block"
    },
    {
      "x": -26,
      "y": 39,
      "z": 9,
      "name": "Soil_Seaweed_Block"
    },
    {
      "x": -26,
      "y": 40,
      "z": 9,
      "name": "Soil_Seaweed_Block"
    },
    {
      "x": -26,
      "y": 41,
      "z": 9,
      "name": "Soil_Seaweed_Block"
    },
    {
      "x": -26,
      "y": 42,
      "z": 9,
      "name": "Soil_Seaweed_Block"
    },
    {
      "x": -26,
      "y": 43,
      "z": 9,
      "name": "Soil_Seaweed_Block"
    },
    {
      "x": -26,
      "y": 44,
      "z": 9,
      "name": "Soil_Seaweed_Block"
    },
    {
      "x": -26,
      "y": 45,
      "z": 9,
      "name": "Soil_Clay_Lime"
    },
    {
      "x": -26,
      "y": 46,
      "z": 9,
      "name": "Plant_Grass_Sharp"
    },
    {
      "x": -26,
      "y": 27,
      "z": 10,
      "name": "Soil_Clay_Green"
    },
    {
      "x": -26,
      "y": 28,
      "z": 10,
      "name": "Soil_Seaweed_Block"
    },
    {
      "x": -26,
      "y": 29,
      "z": 10,
      "name": "Soil_Seaweed_Block"
    },
    {
      "x": -26,
      "y": 30,
      "z": 10,
      "name": "Soil_Seaweed_Block"
    },
    {
      "x": -26,
      "y": 31,
      "z": 10,
      "name": "Soil_Seaweed_Block"
    },
    {
      "x": -26,
      "y": 32,
      "z": 10,
      "name": "Soil_Seaweed_Block"
    },
    {
      "x": -26,
      "y": 33,
      "z": 10,
      "name": "Soil_Seaweed_Block"
    },
    {
      "x": -26,
      "y": 34,
      "z": 10,
      "name": "Soil_Seaweed_Block"
    },
    {
      "x": -26,
      "y": 35,
      "z": 10,
      "name": "Soil_Seaweed_Block"
    },
    {
      "x": -26,
      "y": 36,
      "z": 10,
      "name": "Soil_Seaweed_Block"
    },
    {
      "x": -26,
      "y": 37,
      "z": 10,
      "name": "Soil_Seaweed_Block"
    },
    {
      "x": -26,
      "y": 38,
      "z": 10,
      "name": "Soil_Seaweed_Block"
    },
    {
      "x": -26,
      "y": 39,
      "z": 10,
      "name": "Soil_Seaweed_Block"
    },
    {
      "x": -26,
      "y": 40,
      "z": 10,
      "name": "Soil_Seaweed_Block"
    },
    {
      "x": -26,
      "y": 41,
      "z": 10,
      "name": "Soil_Seaweed_Block"
    },
    {
      "x": -26,
      "y": 42,
      "z": 10,
      "name": "Soil_Seaweed_Block"
    },
    {
      "x": -26,
      "y": 43,
      "z": 10,
      "name": "Soil_Seaweed_Block"
    },
    {
      "x": -26,
      "y": 44,
      "z": 10,
      "name": "Soil_Seaweed_Block"
    },
    {
      "x": -26,
      "y": 45,
      "z": 10,
      "name": "Soil_Clay_Lime"
    },
    {
      "x": -26,
      "y": 46,
      "z": 10,
      "name": "Plant_Grass_Sharp"
    },
    {
      "x": -26,
      "y": 26,
      "z": 11,
      "name": "Soil_Seaweed_Block"
    },
    {
      "x": -26,
      "y": 27,
      "z": 11,
      "name": "Soil_Seaweed_Block"
    },
    {
      "x": -26,
      "y": 28,
      "z": 11,
      "name": "Soil_Clay_Green"
    },
    {
      "x": -26,
      "y": 29,
      "z": 11,
      "name": "Soil_Seaweed_Block"
    },
    {
      "x": -26,
      "y": 30,
      "z": 11,
      "name": "Soil_Seaweed_Block"
    },
    {
      "x": -26,
      "y": 31,
      "z": 11,
      "name": "Soil_Seaweed_Block"
    },
    {
      "x": -26,
      "y": 32,
      "z": 11,
      "name": "Soil_Seaweed_Block"
    },
    {
      "x": -26,
      "y": 33,
      "z": 11,
      "name": "Soil_Seaweed_Block"
    },
    {
      "x": -26,
      "y": 34,
      "z": 11,
      "name": "Soil_Seaweed_Block"
    },
    {
      "x": -26,
      "y": 35,
      "z": 11,
      "name": "Soil_Seaweed_Block"
    },
    {
      "x": -26,
      "y": 36,
      "z": 11,
      "name": "Soil_Seaweed_Block"
    },
    {
      "x": -26,
      "y": 37,
      "z": 11,
      "name": "Soil_Seaweed_Block"
    },
    {
      "x": -26,
      "y": 38,
      "z": 11,
      "name": "Soil_Seaweed_Block"
    },
    {
      "x": -26,
      "y": 41,
      "z": 11,
      "name": "Soil_Clay_Green"
    },
    {
      "x": -26,
      "y": 42,
      "z": 11,
      "name": "Soil_Seaweed_Block"
    },
    {
      "x": -26,
      "y": 43,
      "z": 11,
      "name": "Soil_Seaweed_Block"
    },
    {
      "x": -26,
      "y": 44,
      "z": 11,
      "name": "Soil_Seaweed_Block"
    },
    {
      "x": -26,
      "y": 45,
      "z": 11,
      "name": "Soil_Clay_Lime"
    },
    {
      "x": -26,
      "y": 46,
      "z": 11,
      "name": "Plant_Grass_Sharp"
    },
    {
      "x": -26,
      "y": 24,
      "z": 12,
      "name": "Soil_Clay_Green"
    },
    {
      "x": -26,
      "y": 25,
      "z": 12,
      "name": "Soil_Seaweed_Block"
    },
    {
      "x": -26,
      "y": 26,
      "z": 12,
      "name": "Soil_Seaweed_Block"
    },
    {
      "x": -26,
      "y": 27,
      "z": 12,
      "name": "Soil_Seaweed_Block"
    },
    {
      "x": -26,
      "y": 28,
      "z": 12,
      "name": "Soil_Seaweed_Block"
    },
    {
      "x": -26,
      "y": 29,
      "z": 12,
      "name": "Soil_Seaweed_Block"
    },
    {
      "x": -26,
      "y": 30,
      "z": 12,
      "name": "Soil_Seaweed_Block"
    },
    {
      "x": -26,
      "y": 31,
      "z": 12,
      "name": "Soil_Seaweed_Block"
    },
    {
      "x": -26,
      "y": 32,
      "z": 12,
      "name": "Soil_Seaweed_Block"
    },
    {
      "x": -26,
      "y": 43,
      "z": 12,
      "name": "Soil_Seaweed_Block"
    },
    {
      "x": -26,
      "y": 44,
      "z": 12,
      "name": "Soil_Seaweed_Block"
    },
    {
      "x": -26,
      "y": 23,
      "z": 13,
      "name": "Soil_Clay_Green"
    },
    {
      "x": -26,
      "y": 24,
      "z": 13,
      "name": "Soil_Seaweed_Block"
    },
    {
      "x": -26,
      "y": 25,
      "z": 13,
      "name": "Soil_Seaweed_Block"
    },
    {
      "x": -26,
      "y": 26,
      "z": 13,
      "name": "Soil_Seaweed_Block"
    },
    {
      "x": -26,
      "y": 27,
      "z": 13,
      "name": "Soil_Seaweed_Block"
    },
    {
      "x": -26,
      "y": 28,
      "z": 13,
      "name": "Soil_Seaweed_Block"
    },
    {
      "x": -26,
      "y": 29,
      "z": 13,
      "name": "Soil_Seaweed_Block"
    },
    {
      "x": -26,
      "y": 30,
      "z": 13,
      "name": "Soil_Seaweed_Block"
    },
    {
      "x": -26,
      "y": 31,
      "z": 13,
      "name": "Soil_Seaweed_Block"
    },
    {
      "x": -26,
      "y": 32,
      "z": 13,
      "name": "Soil_Seaweed_Block"
    },
    {
      "x": -26,
      "y": 23,
      "z": 14,
      "name": "Soil_Clay_Green"
    },
    {
      "x": -26,
      "y": 24,
      "z": 14,
      "name": "Soil_Seaweed_Block"
    },
    {
      "x": -25,
      "y": 37,
      "z": -12,
      "name": "Soil_Clay_Green"
    },
    {
      "x": -25,
      "y": 38,
      "z": -12,
      "name": "Soil_Seaweed_Block"
    },
    {
      "x": -25,
      "y": 39,
      "z": -12,
      "name": "Soil_Seaweed_Block"
    },
    {
      "x": -25,
      "y": 40,
      "z": -12,
      "name": "Soil_Seaweed_Block"
    },
    {
      "x": -25,
      "y": 37,
      "z": -11,
      "name": "Soil_Seaweed_Block"
    },
    {
      "x": -25,
      "y": 38,
      "z": -11,
      "name": "Soil_Seaweed_Block"
    },
    {
      "x": -25,
      "y": 39,
      "z": -11,
      "name": "Soil_Seaweed_Block"
    },
    {
      "x": -25,
      "y": 40,
      "z": -11,
      "name": "Soil_Seaweed_Block"
    },
    {
      "x": -25,
      "y": 33,
      "z": -10,
      "name": "Soil_Clay_Green"
    },
    {
      "x": -25,
      "y": 34,
      "z": -10,
      "name": "Soil_Seaweed_Block"
    },
    {
      "x": -25,
      "y": 35,
      "z": -10,
      "name": "Soil_Clay_Green"
    },
    {
      "x": -25,
      "y": 36,
      "z": -10,
      "name": "Soil_Clay_Green"
    },
    {
      "x": -25,
      "y": 37,
      "z": -10,
      "name": "Soil_Seaweed_Block"
    },
    {
      "x": -25,
      "y": 38,
      "z": -10,
      "name": "Soil_Seaweed_Block"
    },
    {
      "x": -25,
      "y": 39,
      "z": -10,
      "name": "Soil_Seaweed_Block"
    },
    {
      "x": -25,
      "y": 40,
      "z": -10,
      "name": "Soil_Seaweed_Block"
    },
    {
      "x": -25,
      "y": 41,
      "z": -10,
      "name": "Soil_Clay_Lime"
    },
    {
      "x": -25,
      "y": 42,
      "z": -10,
      "name": "Plant_Grass_Sharp"
    },
    {
      "x": -25,
      "y": 31,
      "z": -9,
      "name": "Soil_Clay_Green"
    },
    {
      "x": -25,
      "y": 32,
      "z": -9,
      "name": "Soil_Seaweed_Block"
    },
    {
      "x": -25,
      "y": 33,
      "z": -9,
      "name": "Soil_Seaweed_Block"
    },
    {
      "x": -25,
      "y": 34,
      "z": -9,
      "name": "Soil_Seaweed_Block"
    },
    {
      "x": -25,
      "y": 35,
      "z": -9,
      "name": "Soil_Seaweed_Block"
    },
    {
      "x": -25,
      "y": 36,
      "z": -9,
      "name": "Soil_Seaweed_Block"
    },
    {
      "x": -25,
      "y": 37,
      "z": -9,
      "name": "Soil_Seaweed_Block"
    },
    {
      "x": -25,
      "y": 38,
      "z": -9,
      "name": "Soil_Seaweed_Block"
    },
    {
      "x": -25,
      "y": 39,
      "z": -9,
      "name": "Soil_Seaweed_Block"
    },
    {
      "x": -25,
      "y": 40,
      "z": -9,
      "name": "Soil_Seaweed_Block"
    },
    {
      "x": -25,
      "y": 41,
      "z": -9,
      "name": "Soil_Clay_Lime"
    },
    {
      "x": -25,
      "y": 42,
      "z": -9,
      "name": "Plant_Grass_Sharp"
    },
    {
      "x": -25,
      "y": 27,
      "z": -8,
      "name": "Soil_Seaweed_Block"
    },
    {
      "x": -25,
      "y": 28,
      "z": -8,
      "name": "Soil_Clay_Green"
    },
    {
      "x": -25,
      "y": 29,
      "z": -8,
      "name": "Soil_Clay_Green"
    },
    {
      "x": -25,
      "y": 30,
      "z": -8,
      "name": "Soil_Seaweed_Block"
    },
    {
      "x": -25,
      "y": 31,
      "z": -8,
      "name": "Soil_Seaweed_Block"
    },
    {
      "x": -25,
      "y": 32,
      "z": -8,
      "name": "Soil_Seaweed_Block"
    },
    {
      "x": -25,
      "y": 33,
      "z": -8,
      "name": "Soil_Seaweed_Block"
    },
    {
      "x": -25,
      "y": 34,
      "z": -8,
      "name": "Soil_Seaweed_Block"
    },
    {
      "x": -25,
      "y": 35,
      "z": -8,
      "name": "Soil_Seaweed_Block"
    },
    {
      "x": -25,
      "y": 36,
      "z": -8,
      "name": "Soil_Seaweed_Block"
    },
    {
      "x": -25,
      "y": 37,
      "z": -8,
      "name": "Soil_Seaweed_Block"
    },
    {
      "x": -25,
      "y": 38,
      "z": -8,
      "name": "Soil_Seaweed_Block"
    },
    {
      "x": -25,
      "y": 39,
      "z": -8,
      "name": "Soil_Seaweed_Block"
    },
    {
      "x": -25,
      "y": 40,
      "z": -8,
      "name": "Soil_Seaweed_Block"
    },
    {
      "x": -25,
      "y": 41,
      "z": -8,
      "name": "Soil_Clay_Lime"
    },
    {
      "x": -25,
      "y": 42,
      "z": -8,
      "name": "Plant_Grass_Sharp"
    },
    {
      "x": -25,
      "y": 26,
      "z": -7,
      "name": "Soil_Clay_Green"
    },
    {
      "x": -25,
      "y": 27,
      "z": -7,
      "name": "Soil_Seaweed_Block"
    },
    {
      "x": -25,
      "y": 28,
      "z": -7,
      "name": "Soil_Seaweed_Block"
    },
    {
      "x": -25,
      "y": 29,
      "z": -7,
      "name": "Soil_Seaweed_Block"
    },
    {
      "x": -25,
      "y": 30,
      "z": -7,
      "name": "Soil_Seaweed_Block"
    },
    {
      "x": -25,
      "y": 31,
      "z": -7,
      "name": "Soil_Seaweed_Block"
    },
    {
      "x": -25,
      "y": 32,
      "z": -7,
      "name": "Soil_Seaweed_Block"
    },
    {
      "x": -25,
      "y": 33,
      "z": -7,
      "name": "Soil_Seaweed_Block"
    },
    {
      "x": -25,
      "y": 34,
      "z": -7,
      "name": "Soil_Seaweed_Block"
    },
    {
      "x": -25,
      "y": 35,
      "z": -7,
      "name": "Soil_Seaweed_Block"
    },
    {
      "x": -25,
      "y": 36,
      "z": -7,
      "name": "Soil_Seaweed_Block"
    },
    {
      "x": -25,
      "y": 37,
      "z": -7,
      "name": "Soil_Seaweed_Block"
    },
    {
      "x": -25,
      "y": 38,
      "z": -7,
      "name": "Soil_Seaweed_Block"
    },
    {
      "x": -25,
      "y": 39,
      "z": -7,
      "name": "Soil_Seaweed_Block"
    },
    {
      "x": -25,
      "y": 40,
      "z": -7,
      "name": "Soil_Seaweed_Block"
    },
    {
      "x": -25,
      "y": 41,
      "z": -7,
      "name": "Soil_Clay_Lime"
    },
    {
      "x": -25,
      "y": 42,
      "z": -7,
      "name": "Plant_Grass_Sharp"
    },
    {
      "x": -25,
      "y": 22,
      "z": -6,
      "name": "Soil_Seaweed_Block"
    },
    {
      "x": -25,
      "y": 23,
      "z": -6,
      "name": "Soil_Seaweed_Block"
    },
    {
      "x": -25,
      "y": 24,
      "z": -6,
      "name": "Soil_Seaweed_Block"
    },
    {
      "x": -25,
      "y": 25,
      "z": -6,
      "name": "Soil_Seaweed_Block"
    },
    {
      "x": -25,
      "y": 26,
      "z": -6,
      "name": "Soil_Seaweed_Block"
    },
    {
      "x": -25,
      "y": 27,
      "z": -6,
      "name": "Soil_Seaweed_Block"
    },
    {
      "x": -25,
      "y": 28,
      "z": -6,
      "name": "Soil_Seaweed_Block"
    },
    {
      "x": -25,
      "y": 29,
      "z": -6,
      "name": "Soil_Seaweed_Block"
    },
    {
      "x": -25,
      "y": 30,
      "z": -6,
      "name": "Soil_Seaweed_Block"
    },
    {
      "x": -25,
      "y": 31,
      "z": -6,
      "name": "Soil_Seaweed_Block"
    },
    {
      "x": -25,
      "y": 32,
      "z": -6,
      "name": "Soil_Seaweed_Block"
    },
    {
      "x": -25,
      "y": 33,
      "z": -6,
      "name": "Soil_Seaweed_Block"
    },
    {
      "x": -25,
      "y": 34,
      "z": -6,
      "name": "Soil_Seaweed_Block"
    },
    {
      "x": -25,
      "y": 35,
      "z": -6,
      "name": "Soil_Seaweed_Block"
    },
    {
      "x": -25,
      "y": 36,
      "z": -6,
      "name": "Soil_Seaweed_Block"
    },
    {
      "x": -25,
      "y": 37,
      "z": -6,
      "name": "Soil_Seaweed_Block"
    },
    {
      "x": -25,
      "y": 38,
      "z": -6,
      "name": "Soil_Seaweed_Block"
    },
    {
      "x": -25,
      "y": 39,
      "z": -6,
      "name": "Soil_Seaweed_Block"
    },
    {
      "x": -25,
      "y": 40,
      "z": -6,
      "name": "Soil_Seaweed_Block"
    },
    {
      "x": -25,
      "y": 41,
      "z": -6,
      "name": "Soil_Seaweed_Block"
    },
    {
      "x": -25,
      "y": 42,
      "z": -6,
      "name": "Soil_Clay_Lime"
    },
    {
      "x": -25,
      "y": 43,
      "z": -6,
      "name": "Plant_Grass_Sharp"
    },
    {
      "x": -25,
      "y": 17,
      "z": -5,
      "name": "Soil_Clay_Green"
    },
    {
      "x": -25,
      "y": 18,
      "z": -5,
      "name": "Soil_Seaweed_Block"
    },
    {
      "x": -25,
      "y": 19,
      "z": -5,
      "name": "Soil_Clay_Green"
    },
    {
      "x": -25,
      "y": 20,
      "z": -5,
      "name": "Soil_Clay_Green"
    },
    {
      "x": -25,
      "y": 21,
      "z": -5,
      "name": "Soil_Seaweed_Block"
    },
    {
      "x": -25,
      "y": 22,
      "z": -5,
      "name": "Soil_Seaweed_Block"
    },
    {
      "x": -25,
      "y": 23,
      "z": -5,
      "name": "Soil_Seaweed_Block"
    },
    {
      "x": -25,
      "y": 24,
      "z": -5,
      "name": "Soil_Seaweed_Block"
    },
    {
      "x": -25,
      "y": 25,
      "z": -5,
      "name": "Soil_Seaweed_Block"
    },
    {
      "x": -25,
      "y": 26,
      "z": -5,
      "name": "Soil_Seaweed_Block"
    },
    {
      "x": -25,
      "y": 27,
      "z": -5,
      "name": "Soil_Seaweed_Block"
    },
    {
      "x": -25,
      "y": 28,
      "z": -5,
      "name": "Soil_Seaweed_Block"
    },
    {
      "x": -25,
      "y": 29,
      "z": -5,
      "name": "Soil_Seaweed_Block"
    },
    {
      "x": -25,
      "y": 30,
      "z": -5,
      "name": "Soil_Seaweed_Block"
    },
    {
      "x": -25,
      "y": 31,
      "z": -5,
      "name": "Soil_Seaweed_Block"
    },
    {
      "x": -25,
      "y": 32,
      "z": -5,
      "name": "Soil_Seaweed_Block"
    },
    {
      "x": -25,
      "y": 33,
      "z": -5,
      "name": "Soil_Seaweed_Block"
    },
    {
      "x": -25,
      "y": 34,
      "z": -5,
      "name": "Soil_Seaweed_Block"
    },
    {
      "x": -25,
      "y": 35,
      "z": -5,
      "name": "Soil_Seaweed_Block"
    },
    {
      "x": -25,
      "y": 36,
      "z": -5,
      "name": "Soil_Seaweed_Block"
    },
    {
      "x": -25,
      "y": 37,
      "z": -5,
      "name": "Soil_Seaweed_Block"
    },
    {
      "x": -25,
      "y": 38,
      "z": -5,
      "name": "Soil_Seaweed_Block"
    },
    {
      "x": -25,
      "y": 39,
      "z": -5,
      "name": "Soil_Seaweed_Block"
    },
    {
      "x": -25,
      "y": 40,
      "z": -5,
      "name": "Soil_Seaweed_Block"
    },
    {
      "x": -25,
      "y": 41,
      "z": -5,
      "name": "Soil_Seaweed_Block"
    },
    {
      "x": -25,
      "y": 42,
      "z": -5,
      "name": "Soil_Clay_Lime"
    },
    {
      "x": -25,
      "y": 43,
      "z": -5,
      "name": "Plant_Grass_Sharp"
    },
    {
      "x": -25,
      "y": 17,
      "z": -4,
      "name": "Soil_Clay_Green"
    },
    {
      "x": -25,
      "y": 19,
      "z": -4,
      "name": "Soil_Clay_Green"
    },
    {
      "x": -25,
      "y": 20,
      "z": -4,
      "name": "Soil_Clay_Green"
    },
    {
      "x": -25,
      "y": 21,
      "z": -4,
      "name": "Soil_Seaweed_Block"
    },
    {
      "x": -25,
      "y": 22,
      "z": -4,
      "name": "Soil_Seaweed_Block"
    },
    {
      "x": -25,
      "y": 23,
      "z": -4,
      "name": "Soil_Seaweed_Block"
    },
    {
      "x": -25,
      "y": 24,
      "z": -4,
      "name": "Soil_Seaweed_Block"
    },
    {
      "x": -25,
      "y": 25,
      "z": -4,
      "name": "Soil_Seaweed_Block"
    },
    {
      "x": -25,
      "y": 26,
      "z": -4,
      "name": "Soil_Seaweed_Block"
    },
    {
      "x": -25,
      "y": 27,
      "z": -4,
      "name": "Soil_Seaweed_Block"
    },
    {
      "x": -25,
      "y": 28,
      "z": -4,
      "name": "Soil_Seaweed_Block"
    },
    {
      "x": -25,
      "y": 29,
      "z": -4,
      "name": "Soil_Seaweed_Block"
    },
    {
      "x": -25,
      "y": 30,
      "z": -4,
      "name": "Soil_Seaweed_Block"
    },
    {
      "x": -25,
      "y": 31,
      "z": -4,
      "name": "Soil_Seaweed_Block"
    },
    {
      "x": -25,
      "y": 32,
      "z": -4,
      "name": "Soil_Seaweed_Block"
    },
    {
      "x": -25,
      "y": 33,
      "z": -4,
      "name": "Soil_Clay_Green"
    },
    {
      "x": -25,
      "y": 34,
      "z": -4,
      "name": "Soil_Seaweed_Block"
    },
    {
      "x": -25,
      "y": 35,
      "z": -4,
      "name": "Soil_Seaweed_Block"
    },
    {
      "x": -25,
      "y": 36,
      "z": -4,
      "name": "Soil_Seaweed_Block"
    },
    {
      "x": -25,
      "y": 37,
      "z": -4,
      "name": "Soil_Seaweed_Block"
    },
    {
      "x": -25,
      "y": 38,
      "z": -4,
      "name": "Soil_Seaweed_Block"
    },
    {
      "x": -25,
      "y": 39,
      "z": -4,
      "name": "Soil_Seaweed_Block"
    },
    {
      "x": -25,
      "y": 40,
      "z": -4,
      "name": "Soil_Seaweed_Block"
    },
    {
      "x": -25,
      "y": 41,
      "z": -4,
      "name": "Soil_Seaweed_Block"
    },
    {
      "x": -25,
      "y": 16,
      "z": -3,
      "name": "Soil_Clay_Green"
    },
    {
      "x": -25,
      "y": 17,
      "z": -3,
      "name": "Soil_Clay_Green"
    },
    {
      "x": -25,
      "y": 18,
      "z": -3,
      "name": "Soil_Clay_Green"
    },
    {
      "x": -25,
      "y": 19,
      "z": -3,
      "name": "Soil_Clay_Green"
    },
    {
      "x": -25,
      "y": 20,
      "z": -3,
      "name": "Soil_Seaweed_Block"
    },
    {
      "x": -25,
      "y": 21,
      "z": -3,
      "name": "Soil_Seaweed_Block"
    },
    {
      "x": -25,
      "y": 22,
      "z": -3,
      "name": "Soil_Seaweed_Block"
    },
    {
      "x": -25,
      "y": 23,
      "z": -3,
      "name": "Soil_Seaweed_Block"
    },
    {
      "x": -25,
      "y": 24,
      "z": -3,
      "name": "Soil_Seaweed_Block"
    },
    {
      "x": -25,
      "y": 25,
      "z": -3,
      "name": "Soil_Seaweed_Block"
    },
    {
      "x": -25,
      "y": 26,
      "z": -3,
      "name": "Soil_Seaweed_Block"
    },
    {
      "x": -25,
      "y": 27,
      "z": -3,
      "name": "Soil_Seaweed_Block"
    },
    {
      "x": -25,
      "y": 28,
      "z": -3,
      "name": "Soil_Seaweed_Block"
    },
    {
      "x": -25,
      "y": 29,
      "z": -3,
      "name": "Soil_Seaweed_Block"
    },
    {
      "x": -25,
      "y": 30,
      "z": -3,
      "name": "Soil_Seaweed_Block"
    },
    {
      "x": -25,
      "y": 34,
      "z": -3,
      "name": "Soil_Clay_Green"
    },
    {
      "x": -25,
      "y": 35,
      "z": -3,
      "name": "Soil_Clay_Green"
    },
    {
      "x": -25,
      "y": 36,
      "z": -3,
      "name": "Soil_Seaweed_Block"
    },
    {
      "x": -25,
      "y": 37,
      "z": -3,
      "name": "Soil_Seaweed_Block"
    },
    {
      "x": -25,
      "y": 38,
      "z": -3,
      "name": "Soil_Seaweed_Block"
    },
    {
      "x": -25,
      "y": 17,
      "z": -2,
      "name": "Soil_Clay_Green"
    },
    {
      "x": -25,
      "y": 18,
      "z": -2,
      "name": "Soil_Seaweed_Block"
    },
    {
      "x": -25,
      "y": 19,
      "z": -2,
      "name": "Soil_Clay_Green"
    },
    {
      "x": -25,
      "y": 20,
      "z": -2,
      "name": "Soil_Clay_Green"
    },
    {
      "x": -25,
      "y": 21,
      "z": -2,
      "name": "Soil_Seaweed_Block"
    },
    {
      "x": -25,
      "y": 22,
      "z": -2,
      "name": "Soil_Seaweed_Block"
    },
    {
      "x": -25,
      "y": 23,
      "z": -2,
      "name": "Soil_Seaweed_Block"
    },
    {
      "x": -25,
      "y": 24,
      "z": -2,
      "name": "Soil_Seaweed_Block"
    },
    {
      "x": -25,
      "y": 25,
      "z": -2,
      "name": "Soil_Seaweed_Block"
    },
    {
      "x": -25,
      "y": 26,
      "z": -2,
      "name": "Soil_Seaweed_Block"
    },
    {
      "x": -25,
      "y": 27,
      "z": -2,
      "name": "Soil_Seaweed_Block"
    },
    {
      "x": -25,
      "y": 28,
      "z": -2,
      "name": "Soil_Seaweed_Block"
    },
    {
      "x": -25,
      "y": 29,
      "z": -2,
      "name": "Soil_Seaweed_Block"
    },
    {
      "x": -25,
      "y": 21,
      "z": -1,
      "name": "Soil_Clay_Green"
    },
    {
      "x": -25,
      "y": 22,
      "z": -1,
      "name": "Soil_Seaweed_Block"
    },
    {
      "x": -25,
      "y": 23,
      "z": -1,
      "name": "Soil_Seaweed_Block"
    },
    {
      "x": -25,
      "y": 24,
      "z": -1,
      "name": "Soil_Seaweed_Block"
    },
    {
      "x": -25,
      "y": 25,
      "z": -1,
      "name": "Soil_Seaweed_Block"
    },
    {
      "x": -25,
      "y": 26,
      "z": -1,
      "name": "Soil_Seaweed_Block"
    },
    {
      "x": -25,
      "y": 27,
      "z": -1,
      "name": "Soil_Seaweed_Block"
    },
    {
      "x": -25,
      "y": 28,
      "z": -1,
      "name": "Soil_Seaweed_Block"
    },
    {
      "x": -25,
      "y": 29,
      "z": -1,
      "name": "Soil_Clay_Lime"
    },
    {
      "x": -25,
      "y": 30,
      "z": -1,
      "name": "Plant_Grass_Sharp"
    },
    {
      "x": -25,
      "y": 35,
      "z": -1,
      "name": "Soil_Clay_Green"
    },
    {
      "x": -25,
      "y": 36,
      "z": -1,
      "name": "Soil_Seaweed_Block"
    },
    {
      "x": -25,
      "y": 37,
      "z": -1,
      "name": "Soil_Clay_Lime"
    },
    {
      "x": -25,
      "y": 38,
      "z": -1,
      "name": "Plant_Grass_Sharp"
    },
    {
      "x": -25,
      "y": 23,
      "z": 0,
      "name": "Soil_Seaweed_Block"
    },
    {
      "x": -25,
      "y": 24,
      "z": 0,
      "name": "Soil_Seaweed_Block"
    },
    {
      "x": -25,
      "y": 25,
      "z": 0,
      "name": "Soil_Seaweed_Block"
    },
    {
      "x": -25,
      "y": 26,
      "z": 0,
      "name": "Soil_Clay_Green"
    },
    {
      "x": -25,
      "y": 27,
      "z": 0,
      "name": "Soil_Clay_Green"
    },
    {
      "x": -25,
      "y": 28,
      "z": 0,
      "name": "Soil_Seaweed_Block"
    },
    {
      "x": -25,
      "y": 30,
      "z": 0,
      "name": "Plant_Grass_Sharp"
    },
    {
      "x": -25,
      "y": 36,
      "z": 0,
      "name": "Soil_Seaweed_Block"
    },
    {
      "x": -25,
      "y": 37,
      "z": 0,
      "name": "Soil_Clay_Lime"
    },
    {
      "x": -25,
      "y": 38,
      "z": 0,
      "name": "Plant_Grass_Sharp"
    },
    {
      "x": -25,
      "y": 27,
      "z": 1,
      "name": "Soil_Clay_Green"
    },
    {
      "x": -25,
      "y": 28,
      "z": 1,
      "name": "Soil_Seaweed_Block"
    },
    {
      "x": -25,
      "y": 29,
      "z": 1,
      "name": "Soil_Clay_Lime"
    },
    {
      "x": -25,
      "y": 30,
      "z": 1,
      "name": "Plant_Grass_Sharp"
    },
    {
      "x": -25,
      "y": 36,
      "z": 1,
      "name": "Soil_Seaweed_Block"
    },
    {
      "x": -25,
      "y": 37,
      "z": 1,
      "name": "Soil_Clay_Lime"
    },
    {
      "x": -25,
      "y": 38,
      "z": 1,
      "name": "Plant_Grass_Sharp"
    },
    {
      "x": -25,
      "y": 27,
      "z": 2,
      "name": "Soil_Clay_Green"
    },
    {
      "x": -25,
      "y": 28,
      "z": 2,
      "name": "Soil_Seaweed_Block"
    },
    {
      "x": -25,
      "y": 29,
      "z": 2,
      "name": "Soil_Clay_Lime"
    },
    {
      "x": -25,
      "y": 36,
      "z": 2,
      "name": "Soil_Clay_Green"
    },
    {
      "x": -25,
      "y": 37,
      "z": 2,
      "name": "Soil_Clay_Lime"
    },
    {
      "x": -25,
      "y": 28,
      "z": 3,
      "name": "Soil_Clay_Green"
    },
    {
      "x": -25,
      "y": 29,
      "z": 3,
      "name": "Soil_Seaweed_Block"
    },
    {
      "x": -25,
      "y": 30,
      "z": 3,
      "name": "Soil_Clay_Lime"
    },
    {
      "x": -25,
      "y": 31,
      "z": 3,
      "name": "Plant_Grass_Sharp"
    },
    {
      "x": -25,
      "y": 36,
      "z": 3,
      "name": "Soil_Clay_Green"
    },
    {
      "x": -25,
      "y": 28,
      "z": 4,
      "name": "Soil_Clay_Green"
    },
    {
      "x": -25,
      "y": 29,
      "z": 4,
      "name": "Soil_Seaweed_Block"
    },
    {
      "x": -25,
      "y": 30,
      "z": 4,
      "name": "Soil_Seaweed_Block"
    },
    {
      "x": -25,
      "y": 31,
      "z": 4,
      "name": "Soil_Seaweed_Block"
    },
    {
      "x": -25,
      "y": 36,
      "z": 4,
      "name": "Soil_Clay_Green"
    },
    {
      "x": -25,
      "y": 37,
      "z": 4,
      "name": "Soil_Seaweed_Block"
    },
    {
      "x": -25,
      "y": 28,
      "z": 5,
      "name": "Soil_Clay_Green"
    },
    {
      "x": -25,
      "y": 29,
      "z": 5,
      "name": "Soil_Clay_Green"
    },
    {
      "x": -25,
      "y": 30,
      "z": 5,
      "name": "Soil_Seaweed_Block"
    },
    {
      "x": -25,
      "y": 31,
      "z": 5,
      "name": "Soil_Seaweed_Block"
    },
    {
      "x": -25,
      "y": 36,
      "z": 5,
      "name": "Soil_Clay_Green"
    },
    {
      "x": -25,
      "y": 37,
      "z": 5,
      "name": "Soil_Seaweed_Block"
    },
    {
      "x": -25,
      "y": 29,
      "z": 6,
      "name": "Soil_Clay_Green"
    },
    {
      "x": -25,
      "y": 30,
      "z": 6,
      "name": "Soil_Seaweed_Block"
    },
    {
      "x": -25,
      "y": 31,
      "z": 6,
      "name": "Soil_Seaweed_Block"
    },
    {
      "x": -25,
      "y": 32,
      "z": 6,
      "name": "Soil_Seaweed_Block"
    },
    {
      "x": -25,
      "y": 36,
      "z": 6,
      "name": "Soil_Clay_Green"
    },
    {
      "x": -25,
      "y": 37,
      "z": 6,
      "name": "Soil_Seaweed_Block"
    },
    {
      "x": -25,
      "y": 38,
      "z": 6,
      "name": "Soil_Seaweed_Block"
    },
    {
      "x": -25,
      "y": 28,
      "z": 7,
      "name": "Soil_Clay_Green"
    },
    {
      "x": -25,
      "y": 29,
      "z": 7,
      "name": "Soil_Seaweed_Block"
    },
    {
      "x": -25,
      "y": 30,
      "z": 7,
      "name": "Soil_Seaweed_Block"
    },
    {
      "x": -25,
      "y": 31,
      "z": 7,
      "name": "Soil_Seaweed_Block"
    },
    {
      "x": -25,
      "y": 32,
      "z": 7,
      "name": "Soil_Seaweed_Block"
    },
    {
      "x": -25,
      "y": 33,
      "z": 7,
      "name": "Soil_Seaweed_Block"
    },
    {
      "x": -25,
      "y": 34,
      "z": 7,
      "name": "Soil_Seaweed_Block"
    },
    {
      "x": -25,
      "y": 35,
      "z": 7,
      "name": "Soil_Clay_Green"
    },
    {
      "x": -25,
      "y": 36,
      "z": 7,
      "name": "Soil_Seaweed_Block"
    },
    {
      "x": -25,
      "y": 37,
      "z": 7,
      "name": "Soil_Seaweed_Block"
    },
    {
      "x": -25,
      "y": 38,
      "z": 7,
      "name": "Soil_Seaweed_Block"
    },
    {
      "x": -25,
      "y": 39,
      "z": 7,
      "name": "Soil_Seaweed_Block"
    },
    {
      "x": -25,
      "y": 40,
      "z": 7,
      "name": "Soil_Seaweed_Block"
    },
    {
      "x": -25,
      "y": 43,
      "z": 7,
      "name": "Soil_Seaweed_Block"
    },
    {
      "x": -25,
      "y": 28,
      "z": 8,
      "name": "Soil_Clay_Green"
    },
    {
      "x": -25,
      "y": 29,
      "z": 8,
      "name": "Soil_Clay_Green"
    },
    {
      "x": -25,
      "y": 30,
      "z": 8,
      "name": "Soil_Seaweed_Block"
    },
    {
      "x": -25,
      "y": 31,
      "z": 8,
      "name": "Soil_Seaweed_Block"
    },
    {
      "x": -25,
      "y": 32,
      "z": 8,
      "name": "Soil_Seaweed_Block"
    },
    {
      "x": -25,
      "y": 33,
      "z": 8,
      "name": "Soil_Seaweed_Block"
    },
    {
      "x": -25,
      "y": 34,
      "z": 8,
      "name": "Soil_Seaweed_Block"
    },
    {
      "x": -25,
      "y": 35,
      "z": 8,
      "name": "Soil_Seaweed_Block"
    },
    {
      "x": -25,
      "y": 36,
      "z": 8,
      "name": "Soil_Seaweed_Block"
    },
    {
      "x": -25,
      "y": 37,
      "z": 8,
      "name": "Soil_Seaweed_Block"
    },
    {
      "x": -25,
      "y": 38,
      "z": 8,
      "name": "Soil_Seaweed_Block"
    },
    {
      "x": -25,
      "y": 39,
      "z": 8,
      "name": "Soil_Seaweed_Block"
    },
    {
      "x": -25,
      "y": 40,
      "z": 8,
      "name": "Soil_Seaweed_Block"
    },
    {
      "x": -25,
      "y": 41,
      "z": 8,
      "name": "Soil_Seaweed_Block"
    },
    {
      "x": -25,
      "y": 42,
      "z": 8,
      "name": "Soil_Seaweed_Block"
    },
    {
      "x": -25,
      "y": 43,
      "z": 8,
      "name": "Soil_Seaweed_Block"
    },
    {
      "x": -25,
      "y": 44,
      "z": 8,
      "name": "Soil_Seaweed_Block"
    },
    {
      "x": -25,
      "y": 46,
      "z": 8,
      "name": "Plant_Grass_Sharp"
    },
    {
      "x": -25,
      "y": 26,
      "z": 9,
      "name": "Soil_Clay_Green"
    },
    {
      "x": -25,
      "y": 27,
      "z": 9,
      "name": "Soil_Seaweed_Block"
    },
    {
      "x": -25,
      "y": 28,
      "z": 9,
      "name": "Soil_Seaweed_Block"
    },
    {
      "x": -25,
      "y": 29,
      "z": 9,
      "name": "Soil_Seaweed_Block"
    },
    {
      "x": -25,
      "y": 30,
      "z": 9,
      "name": "Soil_Seaweed_Block"
    },
    {
      "x": -25,
      "y": 31,
      "z": 9,
      "name": "Soil_Seaweed_Block"
    },
    {
      "x": -25,
      "y": 32,
      "z": 9,
      "name": "Soil_Seaweed_Block"
    },
    {
      "x": -25,
      "y": 33,
      "z": 9,
      "name": "Soil_Seaweed_Block"
    },
    {
      "x": -25,
      "y": 34,
      "z": 9,
      "name": "Soil_Seaweed_Block"
    },
    {
      "x": -25,
      "y": 35,
      "z": 9,
      "name": "Soil_Seaweed_Block"
    },
    {
      "x": -25,
      "y": 36,
      "z": 9,
      "name": "Soil_Seaweed_Block"
    },
    {
      "x": -25,
      "y": 37,
      "z": 9,
      "name": "Soil_Seaweed_Block"
    },
    {
      "x": -25,
      "y": 38,
      "z": 9,
      "name": "Soil_Seaweed_Block"
    },
    {
      "x": -25,
      "y": 39,
      "z": 9,
      "name": "Soil_Seaweed_Block"
    },
    {
      "x": -25,
      "y": 40,
      "z": 9,
      "name": "Soil_Seaweed_Block"
    },
    {
      "x": -25,
      "y": 41,
      "z": 9,
      "name": "Soil_Seaweed_Block"
    },
    {
      "x": -25,
      "y": 42,
      "z": 9,
      "name": "Soil_Seaweed_Block"
    },
    {
      "x": -25,
      "y": 43,
      "z": 9,
      "name": "Soil_Seaweed_Block"
    },
    {
      "x": -25,
      "y": 44,
      "z": 9,
      "name": "Soil_Seaweed_Block"
    },
    {
      "x": -25,
      "y": 45,
      "z": 9,
      "name": "Soil_Clay_Lime"
    },
    {
      "x": -25,
      "y": 46,
      "z": 9,
      "name": "Plant_Grass_Sharp"
    },
    {
      "x": -25,
      "y": 26,
      "z": 10,
      "name": "Soil_Clay_Green"
    },
    {
      "x": -25,
      "y": 27,
      "z": 10,
      "name": "Soil_Seaweed_Block"
    },
    {
      "x": -25,
      "y": 28,
      "z": 10,
      "name": "Soil_Seaweed_Block"
    },
    {
      "x": -25,
      "y": 29,
      "z": 10,
      "name": "Soil_Seaweed_Block"
    },
    {
      "x": -25,
      "y": 30,
      "z": 10,
      "name": "Soil_Seaweed_Block"
    },
    {
      "x": -25,
      "y": 31,
      "z": 10,
      "name": "Soil_Seaweed_Block"
    },
    {
      "x": -25,
      "y": 32,
      "z": 10,
      "name": "Soil_Seaweed_Block"
    },
    {
      "x": -25,
      "y": 33,
      "z": 10,
      "name": "Soil_Seaweed_Block"
    },
    {
      "x": -25,
      "y": 34,
      "z": 10,
      "name": "Soil_Seaweed_Block"
    },
    {
      "x": -25,
      "y": 35,
      "z": 10,
      "name": "Soil_Seaweed_Block"
    },
    {
      "x": -25,
      "y": 36,
      "z": 10,
      "name": "Soil_Seaweed_Block"
    },
    {
      "x": -25,
      "y": 37,
      "z": 10,
      "name": "Soil_Seaweed_Block"
    },
    {
      "x": -25,
      "y": 38,
      "z": 10,
      "name": "Soil_Seaweed_Block"
    },
    {
      "x": -25,
      "y": 39,
      "z": 10,
      "name": "Soil_Seaweed_Block"
    },
    {
      "x": -25,
      "y": 40,
      "z": 10,
      "name": "Soil_Seaweed_Block"
    },
    {
      "x": -25,
      "y": 41,
      "z": 10,
      "name": "Soil_Seaweed_Block"
    },
    {
      "x": -25,
      "y": 42,
      "z": 10,
      "name": "Soil_Seaweed_Block"
    },
    {
      "x": -25,
      "y": 43,
      "z": 10,
      "name": "Soil_Seaweed_Block"
    },
    {
      "x": -25,
      "y": 44,
      "z": 10,
      "name": "Soil_Seaweed_Block"
    },
    {
      "x": -25,
      "y": 45,
      "z": 10,
      "name": "Soil_Clay_Lime"
    },
    {
      "x": -25,
      "y": 46,
      "z": 10,
      "name": "Plant_Grass_Sharp"
    },
    {
      "x": -25,
      "y": 24,
      "z": 11,
      "name": "Soil_Clay_Green"
    },
    {
      "x": -25,
      "y": 25,
      "z": 11,
      "name": "Soil_Clay_Green"
    },
    {
      "x": -25,
      "y": 26,
      "z": 11,
      "name": "Soil_Seaweed_Block"
    },
    {
      "x": -25,
      "y": 27,
      "z": 11,
      "name": "Soil_Seaweed_Block"
    },
    {
      "x": -25,
      "y": 28,
      "z": 11,
      "name": "Soil_Seaweed_Block"
    },
    {
      "x": -25,
      "y": 29,
      "z": 11,
      "name": "Soil_Seaweed_Block"
    },
    {
      "x": -25,
      "y": 30,
      "z": 11,
      "name": "Soil_Seaweed_Block"
    },
    {
      "x": -25,
      "y": 31,
      "z": 11,
      "name": "Soil_Seaweed_Block"
    },
    {
      "x": -25,
      "y": 32,
      "z": 11,
      "name": "Soil_Seaweed_Block"
    },
    {
      "x": -25,
      "y": 33,
      "z": 11,
      "name": "Soil_Seaweed_Block"
    },
    {
      "x": -25,
      "y": 34,
      "z": 11,
      "name": "Soil_Seaweed_Block"
    },
    {
      "x": -25,
      "y": 37,
      "z": 11,
      "name": "Soil_Seaweed_Block"
    },
    {
      "x": -25,
      "y": 38,
      "z": 11,
      "name": "Soil_Seaweed_Block"
    },
    {
      "x": -25,
      "y": 39,
      "z": 11,
      "name": "Soil_Seaweed_Block"
    },
    {
      "x": -25,
      "y": 40,
      "z": 11,
      "name": "Soil_Clay_Green"
    },
    {
      "x": -25,
      "y": 41,
      "z": 11,
      "name": "Soil_Seaweed_Block"
    },
    {
      "x": -25,
      "y": 42,
      "z": 11,
      "name": "Soil_Seaweed_Block"
    },
    {
      "x": -25,
      "y": 43,
      "z": 11,
      "name": "Soil_Seaweed_Block"
    },
    {
      "x": -25,
      "y": 44,
      "z": 11,
      "name": "Soil_Seaweed_Block"
    },
    {
      "x": -25,
      "y": 45,
      "z": 11,
      "name": "Soil_Clay_Lime"
    },
    {
      "x": -25,
      "y": 46,
      "z": 11,
      "name": "Plant_Grass_Sharp"
    },
    {
      "x": -25,
      "y": 23,
      "z": 12,
      "name": "Soil_Clay_Green"
    },
    {
      "x": -25,
      "y": 24,
      "z": 12,
      "name": "Soil_Seaweed_Block"
    },
    {
      "x": -25,
      "y": 25,
      "z": 12,
      "name": "Soil_Seaweed_Block"
    },
    {
      "x": -25,
      "y": 26,
      "z": 12,
      "name": "Soil_Seaweed_Block"
    },
    {
      "x": -25,
      "y": 27,
      "z": 12,
      "name": "Soil_Seaweed_Block"
    },
    {
      "x": -25,
      "y": 28,
      "z": 12,
      "name": "Soil_Seaweed_Block"
    },
    {
      "x": -25,
      "y": 29,
      "z": 12,
      "name": "Soil_Seaweed_Block"
    },
    {
      "x": -25,
      "y": 30,
      "z": 12,
      "name": "Soil_Seaweed_Block"
    },
    {
      "x": -25,
      "y": 31,
      "z": 12,
      "name": "Soil_Seaweed_Block"
    },
    {
      "x": -25,
      "y": 32,
      "z": 12,
      "name": "Soil_Seaweed_Block"
    },
    {
      "x": -25,
      "y": 33,
