{
  "version": 8,
  "blockIdVersion": 10,
  "anchorX": 0,
  "anchorY": 0,
  "anchorZ": 0,
  "blocks": [
    {
      "x": -11,
      "y": 96,
      "z": -5,
      "name": "Rock_Sandstone_Red"
    },
    {
      "x": -11,
      "y": 97,
      "z": -5,
      "name": "Rock_Sandstone_Red"
    },
    {
      "x": -11,
      "y": 97,
      "z": -4,
      "name": "Soil_Clay_Orange"
    },
    {
      "x": -11,
      "y": 93,
      "z": -1,
      "name": "Rock_Sandstone_Red"
    },
    {
      "x": -11,
      "y": 94,
      "z": -1,
      "name": "Soil_Clay_Yellow"
    },
    {
      "x": -11,
      "y": 97,
      "z": -1,
      "name": "Soil_Clay_Orange"
    },
    {
      "x": -11,
      "y": 92,
      "z": 0,
      "name": "Rock_Sandstone_Red"
    },
    {
      "x": -11,
      "y": 93,
      "z": 0,
      "name": "Rock_Sandstone_Red"
    },
    {
      "x": -11,
      "y": 94,
      "z": 0,
      "name": "Soil_Clay_Yellow"
    },
    {
      "x": -11,
      "y": 95,
      "z": 0,
      "name": "Rock_Sandstone_Red"
    },
    {
      "x": -11,
      "y": 96,
      "z": 0,
      "name": "Rock_Sandstone_Red"
    },
    {
      "x": -11,
      "y": 97,
      "z": 0,
      "name": "Rock_Sandstone_Red"
    },
    {
      "x": -11,
      "y": 93,
      "z": 1,
      "name": "Rock_Sandstone_Red"
    },
    {
      "x": -11,
      "y": 94,
      "z": 1,
      "name": "Soil_Clay_Yellow"
    },
    {
      "x": -11,
      "y": 95,
      "z": 1,
      "name": "Rock_Sandstone_Red"
    },
    {
      "x": -11,
      "y": 96,
      "z": 1,
      "name": "Rock_Sandstone_Red"
    },
    {
      "x": -11,
      "y": 97,
      "z": 1,
      "name": "Rock_Sandstone_Red"
    },
    {
      "x": -11,
      "y": 95,
      "z": 5,
      "name": "Rock_Sandstone"
    },
    {
      "x": -11,
      "y": 96,
      "z": 5,
      "name": "Rock_Sandstone_Red"
    },
    {
      "x": -11,
      "y": 97,
      "z": 5,
      "name": "Rock_Sandstone_Red"
    },
    {
      "x": -11,
      "y": 93,
      "z": 6,
      "name": "Rock_Sandstone"
    },
    {
      "x": -11,
      "y": 95,
      "z": 6,
      "name": "Rock_Sandstone"
    },
    {
      "x": -11,
      "y": 96,
      "z": 6,
      "name": "Rock_Sandstone_Red"
    },
    {
      "x": -11,
      "y": 97,
      "z": 6,
      "name": "Rock_Sandstone_Red"
    },
    {
      "x": -11,
      "y": 98,
      "z": 6,
      "name": "Soil_Clay_Smooth_Red"
    },
    {
      "x": -11,
      "y": 95,
      "z": 7,
      "name": "Rock_Sandstone"
    },
    {
      "x": -11,
      "y": 96,
      "z": 7,
      "name": "Rock_Sandstone_Red"
    },
    {
      "x": -11,
      "y": 97,
      "z": 7,
      "name": "Rock_Sandstone_Red"
    },
    {
      "x": -11,
      "y": 98,
      "z": 7,
      "name": "Soil_Clay_Smooth_Red"
    },
    {
      "x": -11,
      "y": 96,
      "z": 8,
      "name": "Rock_Sandstone_Red"
    },
    {
      "x": -11,
      "y": 97,
      "z": 8,
      "name": "Rock_Sandstone_Red"
    },
    {
      "x": -10,
      "y": 96,
      "z": -6,
      "name": "Rock_Sandstone_Red"
    },
    {
      "x": -10,
      "y": 97,
      "z": -6,
      "name": "Rock_Sandstone_Red"
    },
    {
      "x": -10,
      "y": 92,
      "z": -5,
      "name": "Rock_Sandstone_Red"
    },
    {
      "x": -10,
      "y": 93,
      "z": -5,
      "name": "Rock_Sandstone_Red"
    },
    {
      "x": -10,
      "y": 94,
      "z": -5,
      "name": "Rock_Sandstone"
    },
    {
      "x": -10,
      "y": 95,
      "z": -5,
      "name": "Rock_Sandstone_Red"
    },
    {
      "x": -10,
      "y": 96,
      "z": -5,
      "name": "Rock_Sandstone_Red"
    },
    {
      "x": -10,
      "y": 97,
      "z": -5,
      "name": "Rock_Sandstone_Red"
    },
    {
      "x": -10,
      "y": 98,
      "z": -5,
      "name": "Soil_Clay_Smooth_Red"
    },
    {
      "x": -10,
      "y": 91,
      "z": -4,
      "name": "Rock_Sandstone_Red"
    },
    {
      "x": -10,
      "y": 92,
      "z": -4,
      "name": "Rock_Sandstone_Red"
    },
    {
      "x": -10,
      "y": 93,
      "z": -4,
      "name": "Rock_Sandstone_Red"
    },
    {
      "x": -10,
      "y": 94,
      "z": -4,
      "name": "Rock_Sandstone"
    },
    {
      "x": -10,
      "y": 95,
      "z": -4,
      "name": "Rock_Sandstone_Red"
    },
    {
      "x": -10,
      "y": 96,
      "z": -4,
      "name": "Rock_Sandstone_Red"
    },
    {
      "x": -10,
      "y": 97,
      "z": -4,
      "name": "Rock_Sandstone_Red"
    },
    {
      "x": -10,
      "y": 98,
      "z": -4,
      "name": "Soil_Clay_Orange"
    },
    {
      "x": -10,
      "y": 103,
      "z": -4,
      "name": "Rock_Sandstone_Red"
    },
    {
      "x": -10,
      "y": 104,
      "z": -4,
      "name": "Rock_Sandstone_Red"
    },
    {
      "x": -10,
      "y": 105,
      "z": -4,
      "name": "Rock_Sandstone_Red"
    },
    {
      "x": -10,
      "y": 106,
      "z": -4,
      "name": "Rock_Sandstone_Red"
    },
    {
      "x": -10,
      "y": 107,
      "z": -4,
      "name": "Soil_Clay_Orange"
    },
    {
      "x": -10,
      "y": 92,
      "z": -3,
      "name": "Rock_Sandstone_Red"
    },
    {
      "x": -10,
      "y": 93,
      "z": -3,
      "name": "Rock_Sandstone_Red"
    },
    {
      "x": -10,
      "y": 94,
      "z": -3,
      "name": "Rock_Sandstone"
    },
    {
      "x": -10,
      "y": 95,
      "z": -3,
      "name": "Rock_Sandstone_Red"
    },
    {
      "x": -10,
      "y": 96,
      "z": -3,
      "name": "Rock_Sandstone_Red"
    },
    {
      "x": -10,
      "y": 97,
      "z": -3,
      "name": "Rock_Sandstone_Red"
    },
    {
      "x": -10,
      "y": 101,
      "z": -3,
      "name": "Rock_Sandstone_Red"
    },
    {
      "x": -10,
      "y": 103,
      "z": -3,
      "name": "Rock_Sandstone_Red"
    },
    {
      "x": -10,
      "y": 104,
      "z": -3,
      "name": "Rock_Sandstone_Red"
    },
    {
      "x": -10,
      "y": 105,
      "z": -3,
      "name": "Rock_Sandstone_Red"
    },
    {
      "x": -10,
      "y": 106,
      "z": -3,
      "name": "Rock_Sandstone_Red"
    },
    {
      "x": -10,
      "y": 107,
      "z": -3,
      "name": "Rock_Sandstone_Red"
    },
    {
      "x": -10,
      "y": 108,
      "z": -3,
      "name": "Rock_Sandstone_Red"
    },
    {
      "x": -10,
      "y": 91,
      "z": -2,
      "name": "Soil_Clay_Orange"
    },
    {
      "x": -10,
      "y": 93,
      "z": -2,
      "name": "Rock_Sandstone_Red"
    },
    {
      "x": -10,
      "y": 94,
      "z": -2,
      "name": "Soil_Clay_Yellow"
    },
    {
      "x": -10,
      "y": 95,
      "z": -2,
      "name": "Rock_Sandstone_Red"
    },
    {
      "x": -10,
      "y": 101,
      "z": -2,
      "name": "Rock_Sandstone_Red"
    },
    {
      "x": -10,
      "y": 102,
      "z": -2,
      "name": "Rock_Sandstone_Red"
    },
    {
      "x": -10,
      "y": 103,
      "z": -2,
      "name": "Rock_Sandstone_Red"
    },
    {
      "x": -10,
      "y": 104,
      "z": -2,
      "name": "Rock_Sandstone_Red"
    },
    {
      "x": -10,
      "y": 105,
      "z": -2,
      "name": "Rock_Sandstone_Red"
    },
    {
      "x": -10,
      "y": 106,
      "z": -2,
      "name": "Rock_Sandstone_Red"
    },
    {
      "x": -10,
      "y": 107,
      "z": -2,
      "name": "Rock_Sandstone_Red"
    },
    {
      "x": -10,
      "y": 108,
      "z": -2,
      "name": "Rock_Sandstone_Red"
    },
    {
      "x": -10,
      "y": 91,
      "z": -1,
      "name": "Rock_Sandstone_Red"
    },
    {
      "x": -10,
      "y": 92,
      "z": -1,
      "name": "Rock_Sandstone_Red"
    },
    {
      "x": -10,
      "y": 93,
      "z": -1,
      "name": "Rock_Sandstone_Red"
    },
    {
      "x": -10,
      "y": 94,
      "z": -1,
      "name": "Soil_Clay_Yellow"
    },
    {
      "x": -10,
      "y": 95,
      "z": -1,
      "name": "Rock_Sandstone_Red"
    },
    {
      "x": -10,
      "y": 96,
      "z": -1,
      "name": "Rock_Sandstone_Red"
    },
    {
      "x": -10,
      "y": 97,
      "z": -1,
      "name": "Rock_Sandstone_Red"
    },
    {
      "x": -10,
      "y": 98,
      "z": -1,
      "name": "Soil_Clay_Orange"
    },
    {
      "x": -10,
      "y": 101,
      "z": -1,
      "name": "Rock_Sandstone_Red"
    },
    {
      "x": -10,
      "y": 102,
      "z": -1,
      "name": "Rock_Sandstone"
    },
    {
      "x": -10,
      "y": 103,
      "z": -1,
      "name": "Rock_Sandstone_Red"
    },
    {
      "x": -10,
      "y": 104,
      "z": -1,
      "name": "Rock_Sandstone_Red"
    },
    {
      "x": -10,
      "y": 105,
      "z": -1,
      "name": "Rock_Sandstone_Red"
    },
    {
      "x": -10,
      "y": 106,
      "z": -1,
      "name": "Rock_Sandstone_Red"
    },
    {
      "x": -10,
      "y": 107,
      "z": -1,
      "name": "Rock_Sandstone_Red"
    },
    {
      "x": -10,
      "y": 108,
      "z": -1,
      "name": "Rock_Sandstone_Red"
    },
    {
      "x": -10,
      "y": 91,
      "z": 0,
      "name": "Rock_Sandstone_Red"
    },
    {
      "x": -10,
      "y": 92,
      "z": 0,
      "name": "Rock_Sandstone_Red"
    },
    {
      "x": -10,
      "y": 93,
      "z": 0,
      "name": "Rock_Sandstone_Red"
    },
    {
      "x": -10,
      "y": 94,
      "z": 0,
      "name": "Soil_Clay_Yellow"
    },
    {
      "x": -10,
      "y": 95,
      "z": 0,
      "name": "Rock_Sandstone_Red"
    },
    {
      "x": -10,
      "y": 96,
      "z": 0,
      "name": "Rock_Sandstone_Red"
    },
    {
      "x": -10,
      "y": 97,
      "z": 0,
      "name": "Rock_Sandstone_Red"
    },
    {
      "x": -10,
      "y": 98,
      "z": 0,
      "name": "Soil_Clay_Orange"
    },
    {
      "x": -10,
      "y": 101,
      "z": 0,
      "name": "Rock_Sandstone_Red"
    },
    {
      "x": -10,
      "y": 102,
      "z": 0,
      "name": "Rock_Sandstone"
    },
    {
      "x": -10,
      "y": 103,
      "z": 0,
      "name": "Rock_Sandstone_Red"
    },
    {
      "x": -10,
      "y": 104,
      "z": 0,
      "name": "Rock_Sandstone_Red"
    },
    {
      "x": -10,
      "y": 105,
      "z": 0,
      "name": "Rock_Sandstone_Red"
    },
    {
      "x": -10,
      "y": 106,
      "z": 0,
      "name": "Rock_Sandstone_Red"
    },
    {
      "x": -10,
      "y": 107,
      "z": 0,
      "name": "Rock_Sandstone_Red"
    },
    {
      "x": -10,
      "y": 108,
      "z": 0,
      "name": "Rock_Sandstone_Red"
    },
    {
      "x": -10,
      "y": 109,
      "z": 0,
      "name": "Soil_Clay_Smooth_Red"
    },
    {
      "x": -10,
      "y": 91,
      "z": 1,
      "name": "Rock_Sandstone_Red"
    },
    {
      "x": -10,
      "y": 92,
      "z": 1,
      "name": "Rock_Sandstone_Red"
    },
    {
      "x": -10,
      "y": 93,
      "z": 1,
      "name": "Rock_Sandstone_Red"
    },
    {
      "x": -10,
      "y": 94,
      "z": 1,
      "name": "Rock_Sandstone"
    },
    {
      "x": -10,
      "y": 95,
      "z": 1,
      "name": "Rock_Sandstone_Red"
    },
    {
      "x": -10,
      "y": 96,
      "z": 1,
      "name": "Rock_Sandstone_Red"
    },
    {
      "x": -10,
      "y": 97,
      "z": 1,
      "name": "Rock_Sandstone_Red"
    },
    {
      "x": -10,
      "y": 98,
      "z": 1,
      "name": "Soil_Clay_Orange"
    },
    {
      "x": -10,
      "y": 102,
      "z": 1,
      "name": "Rock_Sandstone"
    },
    {
      "x": -10,
      "y": 103,
      "z": 1,
      "name": "Rock_Sandstone_Red"
    },
    {
      "x": -10,
      "y": 104,
      "z": 1,
      "name": "Rock_Sandstone_Red"
    },
    {
      "x": -10,
      "y": 105,
      "z": 1,
      "name": "Rock_Sandstone_Red"
    },
    {
      "x": -10,
      "y": 106,
      "z": 1,
      "name": "Soil_Clay_Orange"
    },
    {
      "x": -10,
      "y": 107,
      "z": 1,
      "name": "Rock_Sandstone_Red"
    },
    {
      "x": -10,
      "y": 108,
      "z": 1,
      "name": "Rock_Sandstone_Red"
    },
    {
      "x": -10,
      "y": 92,
      "z": 2,
      "name": "Rock_Sandstone_Red"
    },
    {
      "x": -10,
      "y": 93,
      "z": 2,
      "name": "Rock_Sandstone_Red"
    },
    {
      "x": -10,
      "y": 94,
      "z": 2,
      "name": "Rock_Sandstone"
    },
    {
      "x": -10,
      "y": 95,
      "z": 2,
      "name": "Rock_Sandstone_Red"
    },
    {
      "x": -10,
      "y": 96,
      "z": 2,
      "name": "Rock_Sandstone_Red"
    },
    {
      "x": -10,
      "y": 97,
      "z": 2,
      "name": "Soil_Clay_Smooth_Red"
    },
    {
      "x": -10,
      "y": 104,
      "z": 2,
      "name": "Rock_Sandstone_Red"
    },
    {
      "x": -10,
      "y": 105,
      "z": 2,
      "name": "Soil_Clay_Orange"
    },
    {
      "x": -10,
      "y": 106,
      "z": 2,
      "name": "Soil_Clay_Orange"
    },
    {
      "x": -10,
      "y": 107,
      "z": 2,
      "name": "Rock_Sandstone_Red"
    },
    {
      "x": -10,
      "y": 108,
      "z": 2,
      "name": "Rock_Sandstone_Red"
    },
    {
      "x": -10,
      "y": 92,
      "z": 3,
      "name": "Rock_Sandstone_Red"
    },
    {
      "x": -10,
      "y": 94,
      "z": 3,
      "name": "Soil_Clay_Orange"
    },
    {
      "x": -10,
      "y": 102,
      "z": 3,
      "name": "Rock_Sandstone"
    },
    {
      "x": -10,
      "y": 103,
      "z": 3,
      "name": "Rock_Sandstone_Red"
    },
    {
      "x": -10,
      "y": 104,
      "z": 3,
      "name": "Rock_Sandstone_Red"
    },
    {
      "x": -10,
      "y": 105,
      "z": 3,
      "name": "Soil_Clay_Orange"
    },
    {
      "x": -10,
      "y": 106,
      "z": 3,
      "name": "Soil_Clay_Orange"
    },
    {
      "x": -10,
      "y": 107,
      "z": 3,
      "name": "Rock_Sandstone_Red"
    },
    {
      "x": -10,
      "y": 108,
      "z": 3,
      "name": "Rock_Sandstone_Red"
    },
    {
      "x": -10,
      "y": 92,
      "z": 4,
      "name": "Rock_Sandstone_Red"
    },
    {
      "x": -10,
      "y": 93,
      "z": 4,
      "name": "Rock_Sandstone_Red"
    },
    {
      "x": -10,
      "y": 94,
      "z": 4,
      "name": "Rock_Sandstone_Red"
    },
    {
      "x": -10,
      "y": 95,
      "z": 4,
      "name": "Rock_Sandstone"
    },
    {
      "x": -10,
      "y": 96,
      "z": 4,
      "name": "Rock_Sandstone_Red"
    },
    {
      "x": -10,
      "y": 97,
      "z": 4,
      "name": "Soil_Clay_Smooth_Red"
    },
    {
      "x": -10,
      "y": 102,
      "z": 4,
      "name": "Rock_Sandstone_Red"
    },
    {
      "x": -10,
      "y": 103,
      "z": 4,
      "name": "Rock_Sandstone_Red"
    },
    {
      "x": -10,
      "y": 104,
      "z": 4,
      "name": "Rock_Sandstone_Red"
    },
    {
      "x": -10,
      "y": 105,
      "z": 4,
      "name": "Soil_Clay_Orange"
    },
    {
      "x": -10,
      "y": 106,
      "z": 4,
      "name": "Soil_Clay_Orange"
    },
    {
      "x": -10,
      "y": 107,
      "z": 4,
      "name": "Rock_Sandstone_Red"
    },
    {
      "x": -10,
      "y": 108,
      "z": 4,
      "name": "Rock_Sandstone_Red"
    },
    {
      "x": -10,
      "y": 92,
      "z": 5,
      "name": "Rock_Sandstone_Red"
    },
    {
      "x": -10,
      "y": 93,
      "z": 5,
      "name": "Rock_Sandstone_Red"
    },
    {
      "x": -10,
      "y": 94,
      "z": 5,
      "name": "Rock_Sandstone_Red"
    },
    {
      "x": -10,
      "y": 95,
      "z": 5,
      "name": "Rock_Sandstone"
    },
    {
      "x": -10,
      "y": 96,
      "z": 5,
      "name": "Rock_Sandstone_Red"
    },
    {
      "x": -10,
      "y": 97,
      "z": 5,
      "name": "Rock_Sandstone_Red"
    },
    {
      "x": -10,
      "y": 98,
      "z": 5,
      "name": "Rock_Sandstone_Red"
    },
    {
      "x": -10,
      "y": 101,
      "z": 5,
      "name": "Rock_Sandstone_Red"
    },
    {
      "x": -10,
      "y": 102,
      "z": 5,
      "name": "Rock_Sandstone_Red"
    },
    {
      "x": -10,
      "y": 103,
      "z": 5,
      "name": "Rock_Sandstone_Red"
    },
    {
      "x": -10,
      "y": 104,
      "z": 5,
      "name": "Rock_Sandstone_Red"
    },
    {
      "x": -10,
      "y": 105,
      "z": 5,
      "name": "Soil_Clay_Orange"
    },
    {
      "x": -10,
      "y": 106,
      "z": 5,
      "name": "Soil_Clay_Orange"
    },
    {
      "x": -10,
      "y": 107,
      "z": 5,
      "name": "Soil_Clay_Orange"
    },
    {
      "x": -10,
      "y": 92,
      "z": 6,
      "name": "Rock_Sandstone_Red"
    },
    {
      "x": -10,
      "y": 93,
      "z": 6,
      "name": "Rock_Sandstone_Red"
    },
    {
      "x": -10,
      "y": 94,
      "z": 6,
      "name": "Rock_Sandstone_Red"
    },
    {
      "x": -10,
      "y": 95,
      "z": 6,
      "name": "Rock_Sandstone"
    },
    {
      "x": -10,
      "y": 96,
      "z": 6,
      "name": "Rock_Sandstone_Red"
    },
    {
      "x": -10,
      "y": 97,
      "z": 6,
      "name": "Rock_Sandstone_Red"
    },
    {
      "x": -10,
      "y": 98,
      "z": 6,
      "name": "Soil_Clay_Smooth_Red"
    },
    {
      "x": -10,
      "y": 101,
      "z": 6,
      "name": "Rock_Sandstone_Red"
    },
    {
      "x": -10,
      "y": 102,
      "z": 6,
      "name": "Rock_Sandstone_Red"
    },
    {
      "x": -10,
      "y": 103,
      "z": 6,
      "name": "Rock_Sandstone_Red"
    },
    {
      "x": -10,
      "y": 104,
      "z": 6,
      "name": "Rock_Sandstone_Red"
    },
    {
      "x": -10,
      "y": 105,
      "z": 6,
      "name": "Soil_Clay_Orange"
    },
    {
      "x": -10,
      "y": 107,
      "z": 6,
      "name": "Soil_Clay_Orange"
    },
    {
      "x": -10,
      "y": 93,
      "z": 7,
      "name": "Rock_Sandstone_Red"
    },
    {
      "x": -10,
      "y": 95,
      "z": 7,
      "name": "Rock_Sandstone"
    },
    {
      "x": -10,
      "y": 96,
      "z": 7,
      "name": "Rock_Sandstone_Red"
    },
    {
      "x": -10,
      "y": 97,
      "z": 7,
      "name": "Rock_Sandstone_Red"
    },
    {
      "x": -10,
      "y": 98,
      "z": 7,
      "name": "Soil_Clay_Smooth_Red"
    },
    {
      "x": -10,
      "y": 95,
      "z": 8,
      "name": "Rock_Sandstone"
    },
    {
      "x": -10,
      "y": 96,
      "z": 8,
      "name": "Rock_Sandstone_Red"
    },
    {
      "x": -10,
      "y": 97,
      "z": 8,
      "name": "Rock_Sandstone_Red"
    },
    {
      "x": -10,
      "y": 98,
      "z": 8,
      "name": "Rock_Sandstone_Red"
    },
    {
      "x": -10,
      "y": 96,
      "z": 9,
      "name": "Rock_Sandstone_Red"
    },
    {
      "x": -10,
      "y": 97,
      "z": 9,
      "name": "Rock_Sandstone_Red"
    },
    {
      "x": -9,
      "y": 95,
      "z": -6,
      "name": "Rock_Sandstone_Red"
    },
    {
      "x": -9,
      "y": 96,
      "z": -6,
      "name": "Rock_Sandstone_Red"
    },
    {
      "x": -9,
      "y": 97,
      "z": -6,
      "name": "Rock_Sandstone_Red"
    },
    {
      "x": -9,
      "y": 98,
      "z": -6,
      "name": "Soil_Clay_Orange"
    },
    {
      "x": -9,
      "y": 91,
      "z": -5,
      "name": "Rock_Sandstone_Red"
    },
    {
      "x": -9,
      "y": 92,
      "z": -5,
      "name": "Rock_Sandstone_Red"
    },
    {
      "x": -9,
      "y": 93,
      "z": -5,
      "name": "Rock_Sandstone_Red"
    },
    {
      "x": -9,
      "y": 94,
      "z": -5,
      "name": "Rock_Sandstone"
    },
    {
      "x": -9,
      "y": 95,
      "z": -5,
      "name": "Rock_Sandstone_Red"
    },
    {
      "x": -9,
      "y": 96,
      "z": -5,
      "name": "Rock_Sandstone_Red"
    },
    {
      "x": -9,
      "y": 97,
      "z": -5,
      "name": "Rock_Sandstone_Red"
    },
    {
      "x": -9,
      "y": 98,
      "z": -5,
      "name": "Soil_Clay_Smooth_Red"
    },
    {
      "x": -9,
      "y": 102,
      "z": -5,
      "name": "Rock_Sandstone_Red"
    },
    {
      "x": -9,
      "y": 103,
      "z": -5,
      "name": "Rock_Sandstone_Red"
    },
    {
      "x": -9,
      "y": 104,
      "z": -5,
      "name": "Rock_Sandstone_Red"
    },
    {
      "x": -9,
      "y": 105,
      "z": -5,
      "name": "Rock_Sandstone_Red"
    },
    {
      "x": -9,
      "y": 106,
      "z": -5,
      "name": "Rock_Sandstone_Red"
    },
    {
      "x": -9,
      "y": 107,
      "z": -5,
      "name": "Soil_Clay_Orange"
    },
    {
      "x": -9,
      "y": 91,
      "z": -4,
      "name": "Rock_Sandstone_Red"
    },
    {
      "x": -9,
      "y": 92,
      "z": -4,
      "name": "Rock_Sandstone_Red"
    },
    {
      "x": -9,
      "y": 93,
      "z": -4,
      "name": "Rock_Sandstone_Red"
    },
    {
      "x": -9,
      "y": 94,
      "z": -4,
      "name": "Rock_Sandstone"
    },
    {
      "x": -9,
      "y": 95,
      "z": -4,
      "name": "Rock_Sandstone_Red"
    },
    {
      "x": -9,
      "y": 96,
      "z": -4,
      "name": "Rock_Sandstone_Red"
    },
    {
      "x": -9,
      "y": 97,
      "z": -4,
      "name": "Soil_Clay_Smooth_Red"
    },
    {
      "x": -9,
      "y": 101,
      "z": -4,
      "name": "Rock_Sandstone_Red"
    },
    {
      "x": -9,
      "y": 102,
      "z": -4,
      "name": "Rock_Sandstone_Red"
    },
    {
      "x": -9,
      "y": 103,
      "z": -4,
      "name": "Rock_Sandstone_Red"
    },
    {
      "x": -9,
      "y": 104,
      "z": -4,
      "name": "Rock_Sandstone_Red"
    },
    {
      "x": -9,
      "y": 105,
      "z": -4,
      "name": "Rock_Sandstone_Red"
    },
    {
      "x": -9,
      "y": 106,
      "z": -4,
      "name": "Rock_Sandstone_Red"
    },
    {
      "x": -9,
      "y": 107,
      "z": -4,
      "name": "Soil_Clay_Orange"
    },
    {
      "x": -9,
      "y": 108,
      "z": -4,
      "name": "Soil_Clay_Smooth_Red"
    },
    {
      "x": -9,
      "y": 91,
      "z": -3,
      "name": "Rock_Sandstone_Red"
    },
    {
      "x": -9,
      "y": 92,
      "z": -3,
      "name": "Rock_Sandstone_Red"
    },
    {
      "x": -9,
      "y": 93,
      "z": -3,
      "name": "Rock_Sandstone_Red"
    },
    {
      "x": -9,
      "y": 94,
      "z": -3,
      "name": "Soil_Clay_Yellow"
    },
    {
      "x": -9,
      "y": 95,
      "z": -3,
      "name": "Rock_Sandstone_Red"
    },
    {
      "x": -9,
      "y": 96,
      "z": -3,
      "name": "Rock_Sandstone_Red"
    },
    {
      "x": -9,
      "y": 97,
      "z": -3,
      "name": "Soil_Clay_Smooth_Red"
    },
    {
      "x": -9,
      "y": 100,
      "z": -3,
      "name": "Rock_Sandstone_Red"
    },
    {
      "x": -9,
      "y": 101,
      "z": -3,
      "name": "Rock_Sandstone_Red"
    },
    {
      "x": -9,
      "y": 102,
      "z": -3,
      "name": "Rock_Sandstone_Red"
    },
    {
      "x": -9,
      "y": 103,
      "z": -3,
      "name": "Rock_Sandstone_Red"
    },
    {
      "x": -9,
      "y": 104,
      "z": -3,
      "name": "Rock_Sandstone_Red"
    },
    {
      "x": -9,
      "y": 105,
      "z": -3,
      "name": "Rock_Sandstone_Red"
    },
    {
      "x": -9,
      "y": 106,
      "z": -3,
      "name": "Rock_Sandstone_Red"
    },
    {
      "x": -9,
      "y": 107,
      "z": -3,
      "name": "Soil_Clay_Orange"
    },
    {
      "x": -9,
      "y": 108,
      "z": -3,
      "name": "Soil_Clay_Smooth_Red"
    },
    {
      "x": -9,
      "y": 90,
      "z": -2,
      "name": "Soil_Clay_Orange"
    },
    {
      "x": -9,
      "y": 91,
      "z": -2,
      "name": "Rock_Sandstone_Red"
    },
    {
      "x": -9,
      "y": 92,
      "z": -2,
      "name": "Rock_Sandstone_Red"
    },
    {
      "x": -9,
      "y": 93,
      "z": -2,
      "name": "Rock_Sandstone_Red"
    },
    {
      "x": -9,
      "y": 94,
      "z": -2,
      "name": "Soil_Clay_Yellow"
    },
    {
      "x": -9,
      "y": 95,
      "z": -2,
      "name": "Rock_Sandstone_Red"
    },
    {
      "x": -9,
      "y": 96,
      "z": -2,
      "name": "Soil_Clay_Smooth_Red"
    },
    {
      "x": -9,
      "y": 97,
      "z": -2,
      "name": "Soil_Clay_Smooth_Red"
    },
    {
      "x": -9,
      "y": 100,
      "z": -2,
      "name": "Rock_Sandstone_Red"
    },
    {
      "x": -9,
      "y": 101,
      "z": -2,
      "name": "Rock_Sandstone_Red"
    },
    {
      "x": -9,
      "y": 102,
      "z": -2,
      "name": "Rock_Sandstone_Red"
    },
    {
      "x": -9,
      "y": 103,
      "z": -2,
      "name": "Rock_Sandstone_Red"
    },
    {
      "x": -9,
      "y": 104,
      "z": -2,
      "name": "Rock_Sandstone_Red"
    },
    {
      "x": -9,
      "y": 105,
      "z": -2,
      "name": "Rock_Sandstone_Red"
    },
    {
      "x": -9,
      "y": 106,
      "z": -2,
      "name": "Rock_Sandstone_Red"
    },
    {
      "x": -9,
      "y": 107,
      "z": -2,
      "name": "Rock_Sandstone_Red"
    },
    {
      "x": -9,
      "y": 108,
      "z": -2,
      "name": "Soil_Clay_Smooth_Red"
    },
    {
      "x": -9,
      "y": 90,
      "z": -1,
      "name": "Soil_Clay_Orange"
    },
    {
      "x": -9,
      "y": 91,
      "z": -1,
      "name": "Rock_Sandstone_Red"
    },
    {
      "x": -9,
      "y": 92,
      "z": -1,
      "name": "Rock_Sandstone_Red"
    },
    {
      "x": -9,
      "y": 93,
      "z": -1,
      "name": "Rock_Sandstone_Red"
    },
    {
      "x": -9,
      "y": 94,
      "z": -1,
      "name": "Soil_Clay_Yellow"
    },
    {
      "x": -9,
      "y": 95,
      "z": -1,
      "name": "Rock_Sandstone_Red"
    },
    {
      "x": -9,
      "y": 96,
      "z": -1,
      "name": "Rock_Sandstone_Red"
    },
    {
      "x": -9,
      "y": 97,
      "z": -1,
      "name": "Soil_Clay_Smooth_Red"
    },
    {
      "x": -9,
      "y": 100,
      "z": -1,
      "name": "Rock_Sandstone_Red"
    },
    {
      "x": -9,
      "y": 101,
      "z": -1,
      "name": "Rock_Sandstone_Red"
    },
    {
      "x": -9,
      "y": 102,
      "z": -1,
      "name": "Rock_Sandstone_Red"
    },
    {
      "x": -9,
      "y": 103,
      "z": -1,
      "name": "Rock_Sandstone_Red"
    },
    {
      "x": -9,
      "y": 104,
      "z": -1,
      "name": "Rock_Sandstone_Red"
    },
    {
      "x": -9,
      "y": 105,
      "z": -1,
      "name": "Soil_Clay_Orange"
    },
    {
      "x": -9,
      "y": 106,
      "z": -1,
      "name": "Rock_Sandstone_Red"
    },
    {
      "x": -9,
      "y": 107,
      "z": -1,
      "name": "Rock_Sandstone_Red"
    },
    {
      "x": -9,
      "y": 108,
      "z": -1,
      "name": "Rock_Sandstone_Red"
    },
    {
      "x": -9,
      "y": 109,
      "z": -1,
      "name": "Soil_Clay_Smooth_Red"
    },
    {
      "x": -9,
      "y": 90,
      "z": 0,
      "name": "Soil_Clay_Orange"
    },
    {
      "x": -9,
      "y": 91,
      "z": 0,
      "name": "Rock_Sandstone_Red"
    },
    {
      "x": -9,
      "y": 92,
      "z": 0,
      "name": "Rock_Sandstone_Red"
    },
    {
      "x": -9,
      "y": 93,
      "z": 0,
      "name": "Rock_Sandstone_Red"
    },
    {
      "x": -9,
      "y": 94,
      "z": 0,
      "name": "Rock_Sandstone"
    },
    {
      "x": -9,
      "y": 95,
      "z": 0,
      "name": "Rock_Sandstone_Red"
    },
    {
      "x": -9,
      "y": 96,
      "z": 0,
      "name": "Rock_Sandstone_Red"
    },
    {
      "x": -9,
      "y": 97,
      "z": 0,
      "name": "Soil_Clay_Smooth_Red"
    },
    {
      "x": -9,
      "y": 100,
      "z": 0,
      "name": "Rock_Sandstone_Red"
    },
    {
      "x": -9,
      "y": 101,
      "z": 0,
      "name": "Rock_Sandstone_Red"
    },
    {
      "x": -9,
      "y": 102,
      "z": 0,
      "name": "Rock_Sandstone"
    },
    {
      "x": -9,
      "y": 103,
      "z": 0,
      "name": "Rock_Sandstone_Red"
    },
    {
      "x": -9,
      "y": 104,
      "z": 0,
      "name": "Rock_Sandstone_Red"
    },
    {
      "x": -9,
      "y": 105,
      "z": 0,
      "name": "Soil_Clay_Orange"
    },
    {
      "x": -9,
      "y": 106,
      "z": 0,
      "name": "Soil_Clay_Orange"
    },
    {
      "x": -9,
      "y": 107,
      "z": 0,
      "name": "Rock_Sandstone_Red"
    },
    {
      "x": -9,
      "y": 108,
      "z": 0,
      "name": "Rock_Sandstone_Red"
    },
    {
      "x": -9,
      "y": 109,
      "z": 0,
      "name": "Soil_Clay_Smooth_Red"
    },
    {
      "x": -9,
      "y": 90,
      "z": 1,
      "name": "Soil_Clay_Orange"
    },
    {
      "x": -9,
      "y": 91,
      "z": 1,
      "name": "Rock_Sandstone_Red"
    },
    {
      "x": -9,
      "y": 92,
      "z": 1,
      "name": "Rock_Sandstone_Red"
    },
    {
      "x": -9,
      "y": 93,
      "z": 1,
      "name": "Rock_Sandstone_Red"
    },
    {
      "x": -9,
      "y": 94,
      "z": 1,
      "name": "Rock_Sandstone"
    },
    {
      "x": -9,
      "y": 95,
      "z": 1,
      "name": "Rock_Sandstone_Red"
    },
    {
      "x": -9,
      "y": 96,
      "z": 1,
      "name": "Rock_Sandstone_Red"
    },
    {
      "x": -9,
      "y": 97,
      "z": 1,
      "name": "Soil_Clay_Smooth_Red"
    },
    {
      "x": -9,
      "y": 101,
      "z": 1,
      "name": "Rock_Sandstone_Red"
    },
    {
      "x": -9,
      "y": 102,
      "z": 1,
      "name": "Rock_Sandstone"
    },
    {
      "x": -9,
      "y": 103,
      "z": 1,
      "name": "Rock_Sandstone_Red"
    },
    {
      "x": -9,
      "y": 104,
      "z": 1,
      "name": "Rock_Sandstone_Red"
    },
    {
      "x": -9,
      "y": 105,
      "z": 1,
      "name": "Soil_Clay_Orange"
    },
    {
      "x": -9,
      "y": 106,
      "z": 1,
      "name": "Soil_Clay_Orange"
    },
    {
      "x": -9,
      "y": 107,
      "z": 1,
      "name": "Rock_Sandstone_Red"
    },
    {
      "x": -9,
      "y": 108,
      "z": 1,
      "name": "Rock_Sandstone_Red"
    },
    {
      "x": -9,
      "y": 109,
      "z": 1,
      "name": "Soil_Clay_Smooth_Red"
    },
    {
      "x": -9,
      "y": 91,
      "z": 2,
      "name": "Rock_Sandstone_Red"
    },
    {
      "x": -9,
      "y": 92,
      "z": 2,
      "name": "Rock_Sandstone_Red"
    },
    {
      "x": -9,
      "y": 93,
      "z": 2,
      "name": "Rock_Sandstone_Red"
    },
    {
      "x": -9,
      "y": 94,
      "z": 2,
      "name": "Rock_Sandstone_Red"
    },
    {
      "x": -9,
      "y": 95,
      "z": 2,
      "name": "Rock_Sandstone_Red"
    },
    {
      "x": -9,
      "y": 96,
      "z": 2,
      "name": "Rock_Sandstone_Red"
    },
    {
      "x": -9,
      "y": 97,
      "z": 2,
      "name": "Soil_Clay_Smooth_Red"
    },
    {
      "x": -9,
      "y": 102,
      "z": 2,
      "name": "Rock_Sandstone_Red"
    },
    {
      "x": -9,
      "y": 103,
      "z": 2,
      "name": "Rock_Sandstone_Red"
    },
    {
      "x": -9,
      "y": 104,
      "z": 2,
      "name": "Rock_Sandstone_Red"
    },
    {
      "x": -9,
      "y": 105,
      "z": 2,
      "name": "Soil_Clay_Orange"
    },
    {
      "x": -9,
      "y": 106,
      "z": 2,
      "name": "Soil_Clay_Orange"
    },
    {
      "x": -9,
      "y": 107,
      "z": 2,
      "name": "Rock_Sandstone_Red"
    },
    {
      "x": -9,
      "y": 108,
      "z": 2,
      "name": "Rock_Sandstone_Red"
    },
    {
      "x": -9,
      "y": 109,
      "z": 2,
      "name": "Soil_Clay_Smooth_Red"
    },
    {
      "x": -9,
      "y": 91,
      "z": 3,
      "name": "Soil_Clay_Orange"
    },
    {
      "x": -9,
      "y": 92,
      "z": 3,
      "name": "Rock_Sandstone_Red"
    },
    {
      "x": -9,
      "y": 93,
      "z": 3,
      "name": "Rock_Sandstone_Red"
    },
    {
      "x": -9,
      "y": 94,
      "z": 3,
      "name": "Rock_Sandstone_Red"
    },
    {
      "x": -9,
      "y": 95,
      "z": 3,
      "name": "Rock_Sandstone"
    },
    {
      "x": -9,
      "y": 96,
      "z": 3,
      "name": "Soil_Clay_Smooth_Red"
    },
    {
      "x": -9,
      "y": 101,
      "z": 3,
      "name": "Rock_Sandstone_Red"
    },
    {
      "x": -9,
      "y": 102,
      "z": 3,
      "name": "Rock_Sandstone_Red"
    },
    {
      "x": -9,
      "y": 103,
      "z": 3,
      "name": "Rock_Sandstone_Red"
    },
    {
      "x": -9,
      "y": 104,
      "z": 3,
      "name": "Rock_Sandstone_Red"
    },
    {
      "x": -9,
      "y": 105,
      "z": 3,
      "name": "Soil_Clay_Orange"
    },
    {
      "x": -9,
      "y": 106,
      "z": 3,
      "name": "Soil_Clay_Orange"
    },
    {
      "x": -9,
      "y": 107,
      "z": 3,
      "name": "Rock_Sandstone_Red"
    },
    {
      "x": -9,
      "y": 108,
      "z": 3,
      "name": "Rock_Sandstone_Red"
    },
    {
      "x": -9,
      "y": 109,
      "z": 3,
      "name": "Soil_Clay_Smooth_Red"
    },
    {
      "x": -9,
      "y": 91,
      "z": 4,
      "name": "Soil_Clay_Orange"
    },
    {
      "x": -9,
      "y": 92,
      "z": 4,
      "name": "Rock_Sandstone_Red"
    },
    {
      "x": -9,
      "y": 93,
      "z": 4,
      "name": "Rock_Sandstone_Red"
    },
    {
      "x": -9,
      "y": 94,
      "z": 4,
      "name": "Rock_Sandstone_Red"
    },
    {
      "x": -9,
      "y": 95,
      "z": 4,
      "name": "Rock_Sandstone"
    },
    {
      "x": -9,
      "y": 96,
      "z": 4,
      "name": "Rock_Sandstone_Red"
    },
    {
      "x": -9,
      "y": 97,
      "z": 4,
      "name": "Soil_Clay_Smooth_Red"
    },
    {
      "x": -9,
      "y": 100,
      "z": 4,
      "name": "Rock_Sandstone_Red"
    },
    {
      "x": -9,
      "y": 101,
      "z": 4,
      "name": "Rock_Sandstone_Red"
    },
    {
      "x": -9,
      "y": 102,
      "z": 4,
      "name": "Rock_Sandstone_Red"
    },
    {
      "x": -9,
      "y": 103,
      "z": 4,
      "name": "Rock_Sandstone_Red"
    },
    {
      "x": -9,
      "y": 104,
      "z": 4,
      "name": "Rock_Sandstone_Red"
    },
    {
      "x": -9,
      "y": 105,
      "z": 4,
      "name": "Soil_Clay_Orange"
    },
    {
      "x": -9,
      "y": 106,
      "z": 4,
      "name": "Soil_Clay_Orange"
    },
    {
      "x": -9,
      "y": 107,
      "z": 4,
      "name": "Rock_Sandstone_Red"
    },
    {
      "x": -9,
      "y": 108,
      "z": 4,
      "name": "Rock_Sandstone_Red"
    },
    {
      "x": -9,
      "y": 109,
      "z": 4,
      "name": "Soil_Clay_Smooth_Red"
    },
    {
      "x": -9,
      "y": 92,
      "z": 5,
      "name": "Rock_Sandstone_Red"
    },
    {
      "x": -9,
      "y": 93,
      "z": 5,
      "name": "Rock_Sandstone_Red"
    },
    {
      "x": -9,
      "y": 94,
      "z": 5,
      "name": "Rock_Sandstone_Red"
    },
    {
      "x": -9,
      "y": 95,
      "z": 5,
      "name": "Rock_Sandstone"
    },
    {
      "x": -9,
      "y": 96,
      "z": 5,
      "name": "Rock_Sandstone_Red"
    },
    {
      "x": -9,
      "y": 97,
      "z": 5,
      "name": "Soil_Clay_Smooth_Red"
    },
    {
      "x": -9,
      "y": 100,
      "z": 5,
      "name": "Rock_Sandstone_Red"
    },
    {
      "x": -9,
      "y": 101,
      "z": 5,
      "name": "Rock_Sandstone_Red"
    },
    {
      "x": -9,
      "y": 102,
      "z": 5,
      "name": "Rock_Sandstone_Red"
    },
    {
      "x": -9,
      "y": 103,
      "z": 5,
      "name": "Rock_Sandstone_Red"
    },
    {
      "x": -9,
      "y": 104,
      "z": 5,
      "name": "Rock_Sandstone_Red"
    },
    {
      "x": -9,
      "y": 105,
      "z": 5,
      "name": "Soil_Clay_Orange"
    },
    {
      "x": -9,
      "y": 106,
      "z": 5,
      "name": "Soil_Clay_Orange"
    },
    {
      "x": -9,
      "y": 107,
      "z": 5,
      "name": "Rock_Sandstone_Red"
    },
    {
      "x": -9,
      "y": 108,
      "z": 5,
      "name": "Rock_Sandstone_Red"
    },
    {
      "x": -9,
      "y": 92,
      "z": 6,
      "name": "Rock_Sandstone_Red"
    },
    {
      "x": -9,
      "y": 93,
      "z": 6,
      "name": "Rock_Sandstone_Red"
    },
    {
      "x": -9,
      "y": 94,
      "z": 6,
      "name": "Rock_Sandstone_Red"
    },
    {
      "x": -9,
      "y": 95,
      "z": 6,
      "name": "Rock_Sandstone"
    },
    {
      "x": -9,
      "y": 96,
      "z": 6,
      "name": "Rock_Sandstone_Red"
    },
    {
      "x": -9,
      "y": 97,
      "z": 6,
      "name": "Soil_Clay_Smooth_Red"
    },
    {
      "x": -9,
      "y": 100,
      "z": 6,
      "name": "Rock_Sandstone_Red"
    },
    {
      "x": -9,
      "y": 101,
      "z": 6,
      "name": "Rock_Sandstone_Red"
    },
    {
      "x": -9,
      "y": 102,
      "z": 6,
      "name": "Rock_Sandstone_Red"
    },
    {
      "x": -9,
      "y": 103,
      "z": 6,
      "name": "Rock_Sandstone_Red"
    },
    {
      "x": -9,
      "y": 104,
      "z": 6,
      "name": "Rock_Sandstone_Red"
    },
    {
      "x": -9,
      "y": 105,
      "z": 6,
      "name": "Soil_Clay_Orange"
    },
    {
      "x": -9,
      "y": 106,
      "z": 6,
      "name": "Rock_Sandstone"
    },
    {
      "x": -9,
      "y": 107,
      "z": 6,
      "name": "Soil_Clay_Orange"
    },
    {
      "x": -9,
      "y": 92,
      "z": 7,
      "name": "Rock_Sandstone_Red"
    },
    {
      "x": -9,
      "y": 93,
      "z": 7,
      "name": "Rock_Sandstone_Red"
    },
    {
      "x": -9,
      "y": 94,
      "z": 7,
      "name": "Rock_Sandstone_Red"
    },
    {
      "x": -9,
      "y": 95,
      "z": 7,
      "name": "Rock_Sandstone"
    },
    {
      "x": -9,
      "y": 96,
      "z": 7,
      "name": "Rock_Sandstone_Red"
    },
    {
      "x": -9,
      "y": 97,
      "z": 7,
      "name": "Soil_Clay_Smooth_Red"
    },
    {
      "x": -9,
      "y": 101,
      "z": 7,
      "name": "Rock_Sandstone_Red"
    },
    {
      "x": -9,
      "y": 102,
      "z": 7,
      "name": "Rock_Sandstone_Red"
    },
    {
      "x": -9,
      "y": 103,
      "z": 7,
      "name": "Rock_Sandstone_Red"
    },
    {
      "x": -9,
      "y": 104,
      "z": 7,
      "name": "Soil_Clay_Orange"
    },
    {
      "x": -9,
      "y": 105,
      "z": 7,
      "name": "Soil_Clay_Orange"
    },
    {
      "x": -9,
      "y": 106,
      "z": 7,
      "name": "Rock_Sandstone"
    },
    {
      "x": -9,
      "y": 107,
      "z": 7,
      "name": "Soil_Clay_Orange"
    },
    {
      "x": -9,
      "y": 93,
      "z": 8,
      "name": "Rock_Sandstone_Red"
    },
    {
      "x": -9,
      "y": 94,
      "z": 8,
      "name": "Rock_Sandstone_Red"
    },
    {
      "x": -9,
      "y": 95,
      "z": 8,
      "name": "Rock_Sandstone_Red"
    },
    {
      "x": -9,
      "y": 96,
      "z": 8,
      "name": "Rock_Sandstone_Red"
    },
    {
      "x": -9,
      "y": 97,
      "z": 8,
      "name": "Rock_Sandstone_Red"
    },
    {
      "x": -9,
      "y": 95,
      "z": 9,
      "name": "Soil_Clay_Orange"
    },
    {
      "x": -9,
      "y": 96,
      "z": 9,
      "name": "Rock_Sandstone_Red"
    },
    {
      "x": -9,
      "y": 97,
      "z": 9,
      "name": "Rock_Sandstone_Red"
    },
    {
      "x": -8,
      "y": 93,
      "z": -6,
      "name": "Soil_Clay_Orange"
    },
    {
      "x": -8,
      "y": 94,
      "z": -6,
      "name": "Rock_Sandstone"
    },
    {
      "x": -8,
      "y": 95,
      "z": -6,
      "name": "Rock_Sandstone_Red"
    },
    {
      "x": -8,
      "y": 96,
      "z": -6,
      "name": "Rock_Sandstone_Red"
    },
    {
      "x": -8,
      "y": 97,
      "z": -6,
      "name": "Rock_Sandstone_Red"
    },
    {
      "x": -8,
      "y": 98,
      "z": -6,
      "name": "Soil_Clay_Orange"
    },
    {
      "x": -8,
      "y": 91,
      "z": -5,
      "name": "Rock_Sandstone_Red"
    },
    {
      "x": -8,
      "y": 92,
      "z": -5,
      "name": "Rock_Sandstone_Red"
    },
    {
      "x": -8,
      "y": 93,
      "z": -5,
      "name": "Rock_Sandstone_Red"
    },
    {
      "x": -8,
      "y": 94,
      "z": -5,
      "name": "Rock_Sandstone"
    },
    {
      "x": -8,
      "y": 95,
      "z": -5,
      "name": "Rock_Sandstone_Red"
    },
    {
      "x": -8,
      "y": 96,
      "z": -5,
      "name": "Rock_Sandstone_Red"
    },
    {
      "x": -8,
      "y": 97,
      "z": -5,
      "name": "Rock_Sandstone_Red"
    },
    {
      "x": -8,
      "y": 98,
      "z": -5,
      "name": "Rock_Sandstone_Red"
    },
    {
      "x": -8,
      "y": 99,
      "z": -5,
      "name": "Rock_Sandstone_Red"
    },
    {
      "x": -8,
      "y": 101,
      "z": -5,
      "name": "Rock_Sandstone_Red"
    },
    {
      "x": -8,
      "y": 102,
      "z": -5,
      "name": "Rock_Sandstone_Red"
    },
    {
      "x": -8,
      "y": 103,
      "z": -5,
      "name": "Rock_Sandstone_Red"
    },
    {
      "x": -8,
      "y": 104,
      "z": -5,
      "name": "Rock_Sandstone_Red"
    },
    {
      "x": -8,
      "y": 105,
      "z": -5,
      "name": "Rock_Sandstone_Red"
    },
    {
      "x": -8,
      "y": 106,
      "z": -5,
      "name": "Rock_Sandstone_Red"
    },
    {
      "x": -8,
      "y": 107,
      "z": -5,
      "name": "Soil_Clay_Orange"
    },
    {
      "x": -8,
      "y": 108,
      "z": -5,
      "name": "Soil_Clay_Smooth_Red"
    },
    {
      "x": -8,
      "y": 90,
      "z": -4,
      "name": "Soil_Clay_Orange"
    },
    {
      "x": -8,
      "y": 91,
      "z": -4,
      "name": "Rock_Sandstone_Red"
    },
    {
      "x": -8,
      "y": 92,
      "z": -4,
      "name": "Rock_Sandstone_Red"
    },
    {
      "x": -8,
      "y": 93,
      "z": -4,
      "name": "Rock_Sandstone_Red"
    },
    {
      "x": -8,
      "y": 94,
      "z": -4,
      "name": "Soil_Clay_Yellow"
    },
    {
      "x": -8,
      "y": 95,
      "z": -4,
      "name": "Rock_Sandstone_Red"
    },
    {
      "x": -8,
      "y": 96,
      "z": -4,
      "name": "Rock_Sandstone_Red"
    },
    {
      "x": -8,
      "y": 97,
      "z": -4,
      "name": "Soil_Clay_Smooth_Red"
    },
    {
      "x": -8,
      "y": 100,
      "z": -4,
      "name": "Rock_Sandstone_Red"
    },
    {
      "x": -8,
      "y": 101,
      "z": -4,
      "name": "Rock_Sandstone_Red"
    },
    {
      "x": -8,
      "y": 102,
      "z": -4,
      "name": "Rock_Sandstone_Red"
    },
    {
      "x": -8,
      "y": 103,
      "z": -4,
      "name": "Rock_Sandstone_Red"
    },
    {
      "x": -8,
      "y": 104,
      "z": -4,
      "name": "Rock_Sandstone_Red"
    },
    {
      "x": -8,
      "y": 105,
      "z": -4,
      "name": "Rock_Sandstone_Red"
    },
    {
      "x": -8,
      "y": 106,
      "z": -4,
      "name": "Soil_Clay_Orange"
    },
    {
      "x": -8,
      "y": 107,
      "z": -4,
      "name": "Soil_Clay_Orange"
    },
    {
      "x": -8,
      "y": 108,
      "z": -4,
      "name": "Soil_Clay_Smooth_Red"
    },
    {
      "x": -8,
      "y": 91,
      "z": -3,
      "name": "Rock_Sandstone_Red"
    },
    {
      "x": -8,
      "y": 92,
      "z": -3,
      "name": "Rock_Sandstone_Red"
    },
    {
      "x": -8,
      "y": 93,
      "z": -3,
      "name": "Rock_Sandstone_Red"
    },
    {
      "x": -8,
      "y": 94,
      "z": -3,
      "name": "Soil_Clay_Yellow"
    },
    {
      "x": -8,
      "y": 95,
      "z": -3,
      "name": "Rock_Sandstone_Red"
    },
    {
      "x": -8,
      "y": 96,
      "z": -3,
      "name": "Rock_Sandstone_Red"
    },
    {
      "x": -8,
      "y": 97,
      "z": -3,
      "name": "Soil_Clay_Smooth_Red"
    },
    {
      "x": -8,
      "y": 99,
      "z": -3,
      "name": "Rock_Sandstone_Red"
    },
    {
      "x": -8,
      "y": 100,
      "z": -3,
      "name": "Rock_Sandstone_Red"
    },
    {
      "x": -8,
      "y": 101,
      "z": -3,
      "name": "Rock_Sandstone_Red"
    },
    {
      "x": -8,
      "y": 102,
      "z": -3,
      "name": "Rock_Sandstone_Red"
    },
    {
      "x": -8,
      "y": 103,
      "z": -3,
      "name": "Rock_Sandstone_Red"
    },
    {
      "x": -8,
      "y": 104,
      "z": -3,
      "name": "Rock_Sandstone_Red"
    },
    {
      "x": -8,
      "y": 105,
      "z": -3,
      "name": "Rock_Sandstone_Red"
    },
    {
      "x": -8,
      "y": 106,
      "z": -3,
      "name": "Soil_Clay_Orange"
    },
    {
      "x": -8,
      "y": 107,
      "z": -3,
      "name": "Soil_Clay_Orange"
    },
    {
      "x": -8,
      "y": 108,
      "z": -3,
      "name": "Soil_Clay_Smooth_Red"
    },
    {
      "x": -8,
      "y": 90,
      "z": -2,
      "name": "Soil_Clay_Orange"
    },
    {
      "x": -8,
      "y": 91,
      "z": -2,
      "name": "Rock_Sandstone_Red"
    },
    {
      "x": -8,
      "y": 92,
      "z": -2,
      "name": "Rock_Sandstone_Red"
    },
    {
      "x": -8,
      "y": 93,
      "z": -2,
      "name": "Rock_Sandstone_Red"
    },
    {
      "x": -8,
      "y": 94,
      "z": -2,
      "name": "Soil_Clay_Yellow"
    },
    {
      "x": -8,
      "y": 95,
      "z": -2,
      "name": "Rock_Sandstone_Red"
    },
    {
      "x": -8,
      "y": 96,
      "z": -2,
      "name": "Rock_Sandstone_Red"
    },
    {
      "x": -8,
      "y": 97,
      "z": -2,
      "name": "Soil_Clay_Smooth_Red"
    },
    {
      "x": -8,
      "y": 99,
      "z": -2,
      "name": "Rock_Sandstone_Red"
    },
    {
      "x": -8,
      "y": 100,
      "z": -2,
      "name": "Rock_Sandstone_Red"
    },
    {
      "x": -8,
      "y": 101,
      "z": -2,
      "name": "Rock_Sandstone_Red"
    },
    {
      "x": -8,
      "y": 102,
      "z": -2,
      "name": "Rock_Sandstone_Red"
    },
    {
      "x": -8,
      "y": 103,
      "z": -2,
      "name": "Rock_Sandstone_Red"
    },
    {
      "x": -8,
      "y": 104,
      "z": -2,
      "name": "Rock_Sandstone_Red"
    },
    {
      "x": -8,
      "y": 105,
      "z": -2,
      "name": "Soil_Clay_Orange"
    },
    {
      "x": -8,
      "y": 106,
      "z": -2,
      "name": "Soil_Clay_Orange"
    },
    {
      "x": -8,
      "y": 107,
      "z": -2,
      "name": "Soil_Clay_Orange"
    },
    {
      "x": -8,
      "y": 108,
      "z": -2,
      "name": "Rock_Sandstone_Red"
    },
    {
      "x": -8,
      "y": 109,
      "z": -2,
      "name": "Soil_Clay_Smooth_Red"
    },
    {
      "x": -8,
      "y": 90,
      "z": -1,
      "name": "Soil_Clay_Orange"
    },
    {
      "x": -8,
      "y": 91,
      "z": -1,
      "name": "Rock_Sandstone_Red"
    },
    {
      "x": -8,
      "y": 92,
      "z": -1,
      "name": "Rock_Sandstone_Red"
    },
    {
      "x": -8,
      "y": 93,
      "z": -1,
      "name": "Rock_Sandstone_Red"
    },
    {
      "x": -8,
      "y": 94,
      "z": -1,
      "name": "Rock_Sandstone"
    },
    {
      "x": -8,
      "y": 95,
      "z": -1,
      "name": "Rock_Sandstone_Red"
    },
    {
      "x": -8,
      "y": 96,
      "z": -1,
      "name": "Rock_Sandstone_Red"
    },
    {
      "x": -8,
      "y": 97,
      "z": -1,
      "name": "Soil_Clay_Smooth_Red"
    },
    {
      "x": -8,
      "y": 99,
      "z": -1,
      "name": "Rock_Sandstone_Red"
    },
    {
      "x": -8,
      "y": 100,
      "z": -1,
      "name": "Rock_Sandstone_Red"
    },
    {
      "x": -8,
      "y": 101,
      "z": -1,
      "name": "Rock_Sandstone_Red"
    },
    {
      "x": -8,
      "y": 102,
      "z": -1,
      "name": "Rock_Sandstone_Red"
    },
    {
      "x": -8,
      "y": 103,
      "z": -1,
      "name": "Rock_Sandstone_Red"
    },
    {
      "x": -8,
      "y": 104,
      "z": -1,
      "name": "Rock_Sandstone_Red"
    },
    {
      "x": -8,
      "y": 105,
      "z": -1,
      "name": "Soil_Clay_Orange"
    },
    {
      "x": -8,
      "y": 106,
      "z": -1,
      "name": "Soil_Clay_Orange"
    },
    {
      "x": -8,
      "y": 107,
      "z": -1,
      "name": "Soil_Clay_Orange"
    },
    {
      "x": -8,
      "y": 108,
      "z": -1,
      "name": "Rock_Sandstone_Red"
    },
    {
      "x": -8,
      "y": 109,
      "z": -1,
      "name": "Soil_Clay_Smooth_Red"
    },
    {
      "x": -8,
      "y": 90,
      "z": 0,
      "name": "Soil_Clay_Orange"
    },
    {
      "x": -8,
      "y": 91,
      "z": 0,
      "name": "Rock_Sandstone_Red"
    },
    {
      "x": -8,
      "y": 92,
      "z": 0,
      "name": "Rock_Sandstone_Red"
    },
    {
      "x": -8,
      "y": 93,
      "z": 0,
      "name": "Rock_Sandstone_Red"
    },
    {
      "x": -8,
      "y": 94,
      "z": 0,
      "name": "Rock_Sandstone"
    },
    {
      "x": -8,
      "y": 95,
      "z": 0,
      "name": "Rock_Sandstone_Red"
    },
    {
      "x": -8,
      "y": 96,
      "z": 0,
      "name": "Rock_Sandstone_Red"
    },
    {
      "x": -8,
      "y": 97,
      "z": 0,
      "name": "Soil_Clay_Smooth_Red"
    },
    {
      "x": -8,
      "y": 99,
      "z": 0,
      "name": "Rock_Sandstone_Red"
    },
    {
      "x": -8,
      "y": 100,
      "z": 0,
      "name": "Rock_Sandstone_Red"
    },
    {
      "x": -8,
      "y": 101,
      "z": 0,
      "name": "Rock_Sandstone_Red"
    },
    {
      "x": -8,
      "y": 102,
      "z": 0,
      "name": "Rock_Sandstone_Red"
    },
    {
      "x": -8,
      "y": 103,
      "z": 0,
      "name": "Rock_Sandstone_Red"
    },
    {
      "x": -8,
      "y": 104,
      "z": 0,
      "name": "Rock_Sandstone_Red"
    },
    {
      "x": -8,
      "y": 105,
      "z": 0,
      "name": "Soil_Clay_Orange"
    },
    {
      "x": -8,
      "y": 106,
      "z": 0,
      "name": "Soil_Clay_Orange"
    },
    {
      "x": -8,
      "y": 107,
      "z": 0,
      "name": "Soil_Clay_Orange"
    },
    {
      "x": -8,
      "y": 108,
      "z": 0,
      "name": "Rock_Sandstone_Red"
    },
    {
      "x": -8,
      "y": 109,
      "z": 0,
      "name": "Soil_Clay_Smooth_Red"
    },
    {
      "x": -8,
      "y": 90,
      "z": 1,
      "name": "Soil_Clay_Orange"
    },
    {
      "x": -8,
      "y": 91,
      "z": 1,
      "name": "Soil_Clay_Orange"
    },
    {
      "x": -8,
      "y": 92,
      "z": 1,
      "name": "Rock_Sandstone_Red"
    },
    {
      "x": -8,
      "y": 93,
      "z": 1,
      "name": "Rock_Sandstone_Red"
    },
    {
      "x": -8,
      "y": 94,
      "z": 1,
      "name": "Rock_Sandstone_Red"
    },
    {
      "x": -8,
      "y": 95,
      "z": 1,
      "name": "Rock_Sandstone_Red"
    },
    {
      "x": -8,
      "y": 96,
      "z": 1,
      "name": "Rock_Sandstone_Red"
    },
    {
      "x": -8,
      "y": 97,
      "z": 1,
      "name": "Soil_Clay_Smooth_Red"
    },
    {
      "x": -8,
      "y": 99,
      "z": 1,
      "name": "Rock_Sandstone_Red"
    },
    {
      "x": -8,
      "y": 100,
      "z": 1,
      "name": "Rock_Sandstone_Red"
    },
    {
      "x": -8,
      "y": 101,
      "z": 1,
      "name": "Rock_Sandstone_Red"
    },
    {
      "x": -8,
      "y": 102,
      "z": 1,
      "name": "Rock_Sandstone_Red"
    },
    {
      "x": -8,
      "y": 103,
      "z": 1,
      "name": "Rock_Sandstone_Red"
    },
    {
      "x": -8,
      "y": 104,
      "z": 1,
      "name": "Rock_Sandstone_Red"
    },
    {
      "x": -8,
      "y": 105,
      "z": 1,
      "name": "Soil_Clay_Orange"
    },
    {
      "x": -8,
      "y": 106,
      "z": 1,
      "name": "Soil_Clay_Orange"
    },
    {
      "x": -8,
      "y": 107,
      "z": 1,
      "name": "Rock_Sandstone_Red"
    },
    {
      "x": -8,
      "y": 108,
      "z": 1,
      "name": "Rock_Sandstone_Red"
    },
    {
      "x": -8,
      "y": 109,
      "z": 1,
      "name": "Soil_Clay_Smooth_Red"
    },
    {
      "x": -8,
      "y": 90,
      "z": 2,
      "name": "Soil_Clay_Orange"
    },
    {
      "x": -8,
      "y": 91,
      "z": 2,
      "name": "Soil_Clay_Orange"
    },
    {
      "x": -8,
      "y": 92,
      "z": 2,
      "name": "Rock_Sandstone_Red"
    },
    {
      "x": -8,
      "y": 93,
      "z": 2,
      "name": "Rock_Sandstone_Red"
    },
    {
      "x": -8,
      "y": 94,
      "z": 2,
      "name": "Rock_Sandstone_Red"
    },
    {
      "x": -8,
      "y": 95,
      "z": 2,
      "name": "Rock_Sandstone"
    },
    {
      "x": -8,
      "y": 96,
      "z": 2,
      "name": "Rock_Sandstone_Red"
    },
    {
      "x": -8,
      "y": 97,
      "z": 2,
      "name": "Soil_Clay_Smooth_Red"
    },
    {
      "x": -8,
      "y": 101,
      "z": 2,
      "name": "Rock_Sandstone_Red"
    },
    {
      "x": -8,
      "y": 102,
      "z": 2,
      "name": "Rock_Sandstone_Red"
    },
    {
      "x": -8,
      "y": 103,
      "z": 2,
      "name": "Rock_Sandstone_Red"
    },
    {
      "x": -8,
      "y": 104,
      "z": 2,
      "name": "Rock_Sandstone_Red"
    },
    {
      "x": -8,
      "y": 105,
      "z": 2,
      "name": "Soil_Clay_Orange"
    },
    {
      "x": -8,
      "y": 106,
      "z": 2,
      "name": "Rock_Sandstone"
    },
    {
      "x": -8,
      "y": 107,
      "z": 2,
      "name": "Rock_Sandstone_Red"
    },
    {
      "x": -8,
      "y": 108,
      "z": 2,
      "name": "Rock_Sandstone_Red"
    },
    {
      "x": -8,
      "y": 109,
      "z": 2,
      "name": "Soil_Clay_Smooth_Red"
    },
    {
      "x": -8,
      "y": 90,
      "z": 3,
      "name": "Soil_Clay_Orange"
    },
    {
      "x": -8,
      "y": 91,
      "z": 3,
      "name": "Soil_Clay_Orange"
    },
    {
      "x": -8,
      "y": 92,
      "z": 3,
      "name": "Rock_Sandstone_Red"
    },
    {
      "x": -8,
      "y": 93,
      "z": 3,
      "name": "Rock_Sandstone_Red"
    },
    {
      "x": -8,
      "y": 94,
      "z": 3,
      "name": "Rock_Sandstone_Red"
    },
    {
      "x": -8,
      "y": 95,
      "z": 3,
      "name": "Rock_Sandstone"
    },
    {
      "x": -8,
      "y": 96,
      "z": 3,
      "name": "Rock_Sandstone_Red"
    },
    {
      "x": -8,
      "y": 97,
      "z": 3,
      "name": "Soil_Clay_Smooth_Red"
    },
    {
      "x": -8,
      "y": 100,
      "z": 3,
      "name": "Rock_Sandstone_Red"
    },
    {
      "x": -8,
      "y": 101,
      "z": 3,
      "name": "Rock_Sandstone_Red"
    },
    {
      "x": -8,
      "y": 102,
      "z": 3,
      "name": "Rock_Sandstone_Red"
    },
    {
      "x": -8,
      "y": 103,
      "z": 3,
      "name": "Rock_Sandstone_Red"
    },
    {
      "x": -8,
      "y": 104,
      "z": 3,
      "name": "Rock_Sandstone_Red"
    },
    {
      "x": -8,
      "y": 105,
      "z": 3,
      "name": "Soil_Clay_Orange"
    },
    {
      "x": -8,
      "y": 106,
      "z": 3,
      "name": "Rock_Sandstone"
    },
    {
      "x": -8,
      "y": 107,
      "z": 3,
      "name": "Rock_Sandstone_Red"
    },
    {
      "x": -8,
      "y": 108,
      "z": 3,
      "name": "Rock_Sandstone_Red"
    },
    {
      "x": -8,
      "y": 109,
      "z": 3,
      "name": "Soil_Clay_Smooth_Red"
    },
    {
      "x": -8,
      "y": 91,
      "z": 4,
      "name": "Soil_Clay_Orange"
    },
    {
      "x": -8,
      "y": 92,
      "z": 4,
      "name": "Rock_Sandstone_Red"
    },
    {
      "x": -8,
      "y": 93,
      "z": 4,
      "name": "Rock_Sandstone_Red"
    },
    {
      "x": -8,
      "y": 94,
      "z": 4,
      "name": "Rock_Sandstone_Red"
    },
    {
      "x": -8,
      "y": 95,
      "z": 4,
      "name": "Rock_Sandstone"
    },
    {
      "x": -8,
      "y": 96,
      "z": 4,
      "name": "Rock_Sandstone_Red"
    },
    {
      "x": -8,
      "y": 97,
      "z": 4,
      "name": "Soil_Clay_Smooth_Red"
    },
    {
      "x": -8,
      "y": 99,
      "z": 4,
      "name": "Rock_Sandstone_Red"
    },
    {
      "x": -8,
      "y": 100,
      "z": 4,
      "name": "Rock_Sandstone_Red"
    },
    {
      "x": -8,
      "y": 101,
      "z": 4,
      "name": "Rock_Sandstone_Red"
    },
    {
      "x": -8,
      "y": 102,
      "z": 4,
      "name": "Rock_Sandstone_Red"
    },
    {
      "x": -8,
      "y": 103,
      "z": 4,
      "name": "Rock_Sandstone_Red"
    },
    {
      "x": -8,
      "y": 104,
      "z": 4,
      "name": "Rock_Sandstone_Red"
    },
    {
      "x": -8,
      "y": 105,
      "z": 4,
      "name": "Soil_Clay_Orange"
    },
    {
      "x": -8,
      "y": 106,
      "z": 4,
      "name": "Rock_Sandstone"
    },
    {
      "x": -8,
      "y": 107,
      "z": 4,
      "name": "Rock_Sandstone_Red"
    },
    {
      "x": -8,
      "y": 108,
      "z": 4,
      "name": "Rock_Sandstone_Red"
    },
    {
      "x": -8,
      "y": 109,
      "z": 4,
      "name": "Soil_Clay_Smooth_Red"
    },
    {
      "x": -8,
      "y": 91,
      "z": 5,
      "name": "Soil_Clay_Orange"
    },
    {
      "x": -8,
      "y": 92,
      "z": 5,
      "name": "Rock_Sandstone_Red"
    },
    {
      "x": -8,
      "y": 93,
      "z": 5,
      "name": "Rock_Sandstone_Red"
    },
    {
      "x": -8,
      "y": 94,
      "z": 5,
      "name": "Rock_Sandstone_Red"
    },
    {
      "x": -8,
      "y": 95,
      "z": 5,
      "name": "Rock_Sandstone"
    },
    {
      "x": -8,
      "y": 96,
      "z": 5,
      "name": "Rock_Sandstone_Red"
    },
    {
      "x": -8,
      "y": 97,
      "z": 5,
      "name": "Soil_Clay_Smooth_Red"
    },
    {
      "x": -8,
      "y": 99,
      "z": 5,
      "name": "Rock_Sandstone_Red"
    },
    {
      "x": -8,
      "y": 100,
      "z": 5,
      "name": "Rock_Sandstone_Red"
    },
    {
      "x": -8,
      "y": 101,
      "z": 5,
      "name": "Rock_Sandstone_Red"
    },
    {
      "x": -8,
      "y": 102,
      "z": 5,
      "name": "Rock_Sandstone_Red"
    },
    {
      "x": -8,
      "y": 103,
      "z": 5,
      "name": "Rock_Sandstone_Red"
    },
    {
      "x": -8,
      "y": 104,
      "z": 5,
      "name": "Soil_Clay_Orange"
    },
    {
      "x": -8,
      "y": 105,
      "z": 5,
      "name": "Soil_Clay_Orange"
    },
    {
      "x": -8,
      "y": 106,
      "z": 5,
      "name": "Rock_Sandstone"
    },
    {
      "x": -8,
      "y": 107,
      "z": 5,
      "name": "Rock_Sandstone_Red"
    },
    {
      "x": -8,
      "y": 108,
      "z": 5,
      "name": "Rock_Sandstone_Red"
    },
    {
      "x": -8,
      "y": 109,
      "z": 5,
      "name": "Soil_Clay_Smooth_Red"
    },
    {
      "x": -8,
      "y": 91,
      "z": 6,
      "name": "Soil_Clay_Orange"
    },
    {
      "x": -8,
      "y": 92,
      "z": 6,
      "name": "Rock_Sandstone_Red"
    },
    {
      "x": -8,
      "y": 93,
      "z": 6,
      "name": "Rock_Sandstone_Red"
    },
    {
      "x": -8,
      "y": 94,
      "z": 6,
      "name": "Rock_Sandstone_Red"
    },
    {
      "x": -8,
      "y": 95,
      "z": 6,
      "name": "Rock_Sandstone"
    },
    {
      "x": -8,
      "y": 96,
      "z": 6,
      "name": "Rock_Sandstone_Red"
    },
    {
      "x": -8,
      "y": 97,
      "z": 6,
      "name": "Soil_Clay_Smooth_Red"
    },
    {
      "x": -8,
      "y": 99,
      "z": 6,
      "name": "Rock_Sandstone_Red"
    },
    {
      "x": -8,
      "y": 100,
      "z": 6,
      "name": "Rock_Sandstone_Red"
    },
    {
      "x": -8,
      "y": 101,
      "z": 6,
      "name": "Rock_Sandstone_Red"
    },
    {
      "x": -8,
      "y": 102,
      "z": 6,
      "name": "Rock_Sandstone_Red"
    },
    {
      "x": -8,
      "y": 103,
      "z": 6,
      "name": "Rock_Sandstone_Red"
    },
    {
      "x": -8,
      "y": 104,
      "z": 6,
      "name": "Soil_Clay_Orange"
    },
    {
      "x": -8,
      "y": 105,
      "z": 6,
      "name": "Soil_Clay_Orange"
    },
    {
      "x": -8,
      "y": 106,
      "z": 6,
      "name": "Rock_Sandstone"
    },
    {
      "x": -8,
      "y": 107,
      "z": 6,
      "name": "Rock_Sandstone_Red"
    },
    {
      "x": -8,
      "y": 108,
      "z": 6,
      "name": "Soil_Clay_Smooth_Red"
    },
    {
      "x": -8,
      "y": 109,
      "z": 6,
      "name": "Soil_Clay_Smooth_Red"
    },
    {
      "x": -8,
      "y": 92,
      "z": 7,
      "name": "Rock_Sandstone_Red"
    },
    {
      "x": -8,
      "y": 93,
      "z": 7,
      "name": "Rock_Sandstone_Red"
    },
    {
      "x": -8,
      "y": 94,
      "z": 7,
      "name": "Rock_Sandstone_Red"
    },
    {
      "x": -8,
      "y": 95,
      "z": 7,
      "name": "Rock_Sandstone"
    },
    {
      "x": -8,
      "y": 96,
      "z": 7,
      "name": "Rock_Sandstone_Red"
    },
    {
      "x": -8,
      "y": 97,
      "z": 7,
      "name": "Soil_Clay_Smooth_Red"
    },
    {
      "x": -8,
      "y": 99,
      "z": 7,
      "name": "Rock_Sandstone_Red"
    },
    {
      "x": -8,
      "y": 100,
      "z": 7,
      "name": "Rock_Sandstone_Red"
    },
    {
      "x": -8,
      "y": 101,
      "z": 7,
      "name": "Rock_Sandstone_Red"
    },
    {
      "x": -8,
      "y": 102,
      "z": 7,
      "name": "Rock_Sandstone_Red"
    },
    {
      "x": -8,
      "y": 103,
      "z": 7,
      "name": "Soil_Clay_Orange"
    },
    {
      "x": -8,
      "y": 104,
      "z": 7,
      "name": "Soil_Clay_Orange"
    },
    {
      "x": -8,
      "y": 105,
      "z": 7,
      "name": "Soil_Clay_Orange"
    },
    {
      "x": -8,
      "y": 106,
      "z": 7,
      "name": "Rock_Sandstone"
    },
    {
      "x": -8,
      "y": 107,
      "z": 7,
      "name": "Rock_Sandstone_Red"
    },
    {
      "x": -8,
      "y": 108,
      "z": 7,
      "name": "Soil_Clay_Smooth_Red"
    },
    {
      "x": -8,
      "y": 93,
      "z": 8,
      "name": "Rock_Sandstone_Red"
    },
    {
      "x": -8,
      "y": 94,
      "z": 8,
      "name": "Rock_Sandstone_Red"
    },
    {
      "x": -8,
      "y": 95,
      "z": 8,
      "name": "Rock_Sandstone_Red"
    },
    {
      "x": -8,
      "y": 96,
      "z": 8,
      "name": "Rock_Sandstone_Red"
    },
    {
      "x": -8,
      "y": 97,
      "z": 8,
      "name": "Rock_Sandstone_Red"
    },
    {
      "x": -8,
      "y": 99,
      "z": 8,
      "name": "Rock_Sandstone_Red"
    },
    {
      "x": -8,
      "y": 100,
      "z": 8,
      "name": "Rock_Sandstone_Red"
    },
    {
      "x": -8,
      "y": 101,
      "z": 8,
      "name": "Rock_Sandstone_Red"
    },
    {
      "x": -8,
      "y": 102,
      "z": 8,
      "name": "Rock_Sandstone_Red"
    },
    {
      "x": -8,
      "y": 103,
      "z": 8,
      "name": "Soil_Clay_Orange"
    },
    {
      "x": -8,
      "y": 104,
      "z": 8,
      "name": "Soil_Clay_Orange"
    },
    {
      "x": -8,
      "y": 105,
      "z": 8,
      "name": "Soil_Clay_Orange"
    },
    {
      "x": -8,
      "y": 106,
      "z": 8,
      "name": "Rock_Sandstone"
    },
    {
      "x": -8,
      "y": 107,
      "z": 8,
      "name": "Rock_Sandstone_Red"
    },
    {
      "x": -8,
      "y": 108,
      "z": 8,
      "name": "Rock_Sandstone_Red"
    },
    {
      "x": -8,
      "y": 94,
      "z": 9,
      "name": "Rock_Sandstone_Red"
    },
    {
      "x": -8,
      "y": 95,
      "z": 9,
      "name": "Rock_Sandstone_Red"
    },
    {
      "x": -8,
      "y": 96,
      "z": 9,
      "name": "Rock_Sandstone_Red"
    },
    {
      "x": -8,
      "y": 97,
      "z": 9,
      "name": "Rock_Sandstone_Red"
    },
    {
      "x": -8,
      "y": 99,
      "z": 9,
      "name": "Rock_Sandstone_Red"
    },
    {
      "x": -8,
      "y": 100,
      "z": 9,
      "name": "Rock_Sandstone_Red"
    },
    {
      "x": -8,
      "y": 101,
      "z": 9,
      "name": "Rock_Sandstone_Red"
    },
    {
      "x": -8,
      "y": 102,
      "z": 9,
      "name": "Rock_Sandstone_Red"
    },
    {
      "x": -8,
      "y": 103,
      "z": 9,
      "name": "Soil_Clay_Orange"
    },
    {
      "x": -8,
      "y": 104,
      "z": 9,
      "name": "Soil_Clay_Orange"
    },
    {
      "x": -8,
      "y": 105,
      "z": 9,
      "name": "Soil_Clay_Orange"
    },
    {
      "x": -8,
      "y": 106,
      "z": 9,
      "name": "Rock_Sandstone"
    },
    {
      "x": -8,
      "y": 107,
      "z": 9,
      "name": "Rock_Sandstone_Red"
    },
    {
      "x": -8,
      "y": 108,
      "z": 9,
      "name": "Rock_Sandstone_Red"
    },
    {
      "x": -8,
      "y": 99,
      "z": 10,
      "name": "Rock_Sandstone_Red"
    },
    {
      "x": -8,
      "y": 100,
      "z": 10,
      "name": "Rock_Sandstone_Red"
    },
    {
      "x": -8,
      "y": 101,
      "z": 10,
      "name": "Rock_Sandstone_Red"
    },
    {
      "x": -8,
      "y": 102,
      "z": 10,
      "name": "Rock_Sandstone_Red"
    },
    {
      "x": -8,
      "y": 103,
      "z": 10,
      "name": "Soil_Clay_Orange"
    },
    {
      "x": -8,
      "y": 104,
      "z": 10,
      "name": "Soil_Clay_Orange"
    },
    {
      "x": -8,
      "y": 105,
      "z": 10,
      "name": "Soil_Clay_Orange"
    },
    {
      "x": -8,
      "y": 106,
      "z": 10,
      "name": "Rock_Sandstone"
    },
    {
      "x": -8,
      "y": 107,
      "z": 10,
      "name": "Soil_Clay_Orange"
    },
    {
      "x": -7,
      "y": 83,
      "z": -7,
      "name": "Rock_Sandstone_Red"
    },
    {
      "x": -7,
      "y": 84,
      "z": -7,
      "name": "Rock_Sandstone_Red"
    },
    {
      "x": -7,
      "y": 100,
      "z": -7,
      "name": "Rock_Sandstone_Red"
    },
    {
      "x": -7,
      "y": 101,
      "z": -7,
      "name": "Rock_Sandstone_Red"
    },
    {
      "x": -7,
      "y": 102,
      "z": -7,
      "name": "Rock_Sandstone_Red"
    },
    {
      "x": -7,
      "y": 104,
      "z": -7,
      "name": "Soil_Clay_Orange"
    },
    {
      "x": -7,
      "y": 105,
      "z": -7,
      "name": "Soil_Clay_Orange"
    },
    {
      "x": -7,
      "y": 106,
      "z": -7,
      "name": "Soil_Clay_Orange"
    },
    {
      "x": -7,
      "y": 107,
      "z": -7,
      "name": "Soil_Clay_Orange"
    },
    {
      "x": -7,
      "y": 92,
      "z": -6,
      "name": "Soil_Clay_Orange"
    },
    {
      "x": -7,
      "y": 93,
      "z": -6,
      "name": "Soil_Clay_Orange"
    },
    {
      "x": -7,
      "y": 94,
      "z": -6,
      "name": "Rock_Sandstone"
    },
    {
      "x": -7,
      "y": 95,
      "z": -6,
      "name": "Rock_Sandstone_Red"
    },
    {
      "x": -7,
      "y": 96,
      "z": -6,
      "name": "Rock_Sandstone_Red"
    },
    {
      "x": -7,
      "y": 97,
      "z": -6,
      "name": "Rock_Sandstone_Red"
    },
    {
      "x": -7,
      "y": 98,
      "z": -6,
      "name": "Soil_Clay_Orange"
    },
    {
      "x": -7,
      "y": 99,
      "z": -6,
      "name": "Soil_Clay_Orange"
    },
    {
      "x": -7,
      "y": 108,
      "z": -6,
      "name": "Soil_Clay_Smooth_Red"
    },
    {
      "x": -7,
      "y": 89,
      "z": -5,
      "name": "Soil_Clay_Yellow"
    },
    {
      "x": -7,
      "y": 90,
      "z": -5,
      "name": "Soil_Clay_Orange"
    },
    {
      "x": -7,
      "y": 91,
      "z": -5,
      "name": "Soil_Clay_Orange"
    },
    {
      "x": -7,
      "y": 92,
      "z": -5,
      "name": "Rock_Sandstone_Red"
    },
    {
      "x": -7,
      "y": 93,
      "z": -5,
      "name": "Soil_Clay_Orange"
    },
    {
      "x": -7,
      "y": 94,
      "z": -5,
      "name": "Rock_Sandstone"
    },
    {
      "x": -7,
      "y": 95,
      "z": -5,
      "name": "Rock_Sandstone_Red"
    },
    {
      "x": -7,
      "y": 96,
      "z": -5,
      "name": "Rock_Sandstone_Red"
    },
    {
      "x": -7,
      "y": 97,
      "z": -5,
      "name": "Rock_Sandstone_Red"
    },
    {
      "x": -7,
      "y": 98,
      "z": -5,
      "name": "Soil_Clay_Orange"
    },
    {
      "x": -7,
      "y": 99,
      "z": -5,
      "name": "Rock_Sandstone_Red"
    },
    {
      "x": -7,
      "y": 101,
      "z": -5,
      "name": "Rock_Sandstone_Red"
    },
    {
      "x": -7,
      "y": 102,
      "z": -5,
      "name": "Rock_Sandstone_Red"
    },
    {
      "x": -7,
      "y": 103,
      "z": -5,
      "name": "Rock_Sandstone_Red"
    },
    {
      "x": -7,
      "y": 104,
      "z": -5,
      "name": "Rock_Sandstone_Red"
    },
    {
      "x": -7,
      "y": 105,
      "z": -5,
      "name": "Rock_Sandstone_Red"
    },
    {
      "x": -7,
      "y": 106,
      "z": -5,
      "name": "Soil_Clay_Orange"
    },
    {
      "x": -7,
      "y": 107,
      "z": -5,
      "name": "Soil_Clay_Orange"
    },
    {
      "x": -7,
      "y": 108,
      "z": -5,
      "name": "Soil_Clay_Smooth_Red"
    },
    {
      "x": -7,
      "y": 90,
      "z": -4,
      "name": "Soil_Clay_Orange"
    },
    {
      "x": -7,
      "y": 91,
      "z": -4,
      "name": "Soil_Clay_Orange"
    },
    {
      "x": -7,
      "y": 92,
      "z": -4,
      "name": "Rock_Sandstone_Red"
    },
    {
      "x": -7,
      "y": 93,
      "z": -4,
      "name": "Soil_Clay_Orange"
    },
    {
      "x": -7,
      "y": 94,
      "z": -4,
      "name": "Soil_Clay_Yellow"
    },
    {
      "x": -7,
      "y": 95,
      "z": -4,
      "name": "Rock_Sandstone_Red"
    },
    {
      "x": -7,
      "y": 96,
      "z": -4,
      "name": "Rock_Sandstone_Red"
    },
    {
      "x": -7,
      "y": 97,
      "z": -4,
      "name": "Soil_Clay_Smooth_Red"
    },
    {
      "x": -7,
      "y": 100,
      "z": -4,
      "name": "Rock_Sandstone_Red"
    },
    {
      "x": -7,
      "y": 101,
      "z": -4,
      "name": "Rock_Sandstone_Red"
    },
    {
      "x": -7,
      "y": 102,
      "z": -4,
      "name": "Rock_Sandstone_Red"
    },
    {
      "x": -7,
      "y": 103,
      "z": -4,
      "name": "Rock_Sandstone_Red"
    },
    {
      "x": -7,
      "y": 104,
      "z": -4,
      "name": "Rock_Sandstone_Red"
    },
    {
      "x": -7,
      "y": 105,
      "z": -4,
      "name": "Soil_Clay_Orange"
    },
    {
      "x": -7,
      "y": 106,
      "z": -4,
      "name": "Soil_Clay_Orange"
    },
    {
      "x": -7,
      "y": 107,
      "z": -4,
      "name": "Soil_Clay_Orange"
    },
    {
      "x": -7,
      "y": 108,
      "z": -4,
      "name": "Soil_Clay_Smooth_Red"
    },
    {
      "x": -7,
      "y": 89,
      "z": -3,
      "name": "Rock_Sandstone"
    },
    {
      "x": -7,
      "y": 90,
      "z": -3,
      "name": "Soil_Clay_Orange"
    },
    {
      "x": -7,
      "y": 91,
      "z": -3,
      "name": "Soil_Clay_Orange"
    },
    {
      "x": -7,
      "y": 92,
      "z": -3,
      "name": "Rock_Sandstone_Red"
    },
    {
      "x": -7,
      "y": 93,
      "z": -3,
      "name": "Soil_Clay_Orange"
    },
    {
      "x": -7,
      "y": 94,
      "z": -3,
      "name": "Rock_Sandstone"
    },
    {
      "x": -7,
      "y": 95,
      "z": -3,
      "name": "Rock_Sandstone_Red"
    },
    {
      "x": -7,
      "y": 96,
      "z": -3,
      "name": "Rock_Sandstone_Red"
    },
    {
      "x": -7,
      "y": 97,
      "z": -3,
      "name": "Soil_Clay_Smooth_Red"
    },
    {
      "x": -7,
      "y": 99,
      "z": -3,
      "name": "Rock_Sandstone_Red"
    },
    {
      "x": -7,
      "y": 100,
      "z": -3,
      "name": "Rock_Sandstone_Red"
    },
    {
      "x": -7,
      "y": 101,
      "z": -3,
      "name": "Rock_Sandstone_Red"
    },
    {
      "x": -7,
      "y": 102,
      "z": -3,
      "name": "Rock_Sandstone_Red"
    },
    {
      "x": -7,
      "y": 103,
      "z": -3,
      "name": "Rock_Sandstone_Red"
    },
    {
      "x": -7,
      "y": 104,
      "z": -3,
      "name": "Rock_Sandstone_Red"
    },
    {
      "x": -7,
      "y": 105,
      "z": -3,
      "name": "Soil_Clay_Orange"
    },
    {
      "x": -7,
      "y": 106,
      "z": -3,
      "name": "Soil_Clay_Orange"
    },
    {
      "x": -7,
      "y": 107,
      "z": -3,
      "name": "Soil_Clay_Orange"
    },
    {
      "x": -7,
      "y": 108,
      "z": -3,
      "name": "Soil_Clay_Orange"
    },
    {
      "x": -7,
      "y": 109,
      "z": -3,
      "name": "Soil_Clay_Smooth_Red"
    },
    {
      "x": -7,
      "y": 89,
      "z": -2,
      "name": "Rock_Sandstone"
    },
    {
      "x": -7,
      "y": 90,
      "z": -2,
      "name": "Soil_Clay_Orange"
    },
    {
      "x": -7,
      "y": 91,
      "z": -2,
      "name": "Soil_Clay_Orange"
    },
    {
      "x": -7,
      "y": 92,
      "z": -2,
      "name": "Rock_Sandstone_Red"
    },
    {
      "x": -7,
      "y": 93,
      "z": -2,
      "name": "Rock_Sandstone_Red"
    },
    {
      "x": -7,
      "y": 94,
      "z": -2,
      "name": "Rock_Sandstone"
    },
    {
      "x": -7,
      "y": 95,
      "z": -2,
      "name": "Rock_Sandstone_Red"
    },
    {
      "x": -7,
      "y": 96,
      "z": -2,
      "name": "Rock_Sandstone_Red"
    },
    {
      "x": -7,
      "y": 97,
      "z": -2,
      "name": "Rock_Sandstone_Red"
    },
    {
      "x": -7,
      "y": 98,
      "z": -2,
      "name": "Rock_Sandstone_Red"
    },
    {
      "x": -7,
      "y": 99,
      "z": -2,
      "name": "Rock_Sandstone_Red"
    },
    {
      "x": -7,
      "y": 100,
      "z": -2,
      "name": "Rock_Sandstone_Red"
    },
    {
      "x": -7,
      "y": 101,
      "z": -2,
      "name": "Rock_Sandstone_Red"
    },
    {
      "x": -7,
      "y": 102,
      "z": -2,
      "name": "Rock_Sandstone_Red"
    },
    {
      "x": -7,
      "y": 103,
      "z": -2,
      "name": "Rock_Sandstone_Red"
    },
    {
      "x": -7,
      "y": 104,
      "z": -2,
      "name": "Rock_Sandstone_Red"
    },
    {
      "x": -7,
      "y": 105,
      "z": -2,
      "name": "Soil_Clay_Orange"
    },
    {
      "x": -7,
      "y": 106,
      "z": -2,
      "name": "Soil_Clay_Orange"
    },
    {
      "x": -7,
      "y": 107,
      "z": -2,
      "name": "Soil_Clay_Orange"
    },
    {
      "x": -7,
      "y": 108,
      "z": -2,
      "name": "Soil_Clay_Orange"
    },
    {
      "x": -7,
      "y": 109,
      "z": -2,
      "name": "Soil_Clay_Smooth_Red"
    },
    {
      "x": -7,
      "y": 89,
      "z": -1,
      "name": "Rock_Sandstone"
    },
    {
      "x": -7,
      "y": 90,
      "z": -1,
      "name": "Soil_Clay_Orange"
    },
    {
      "x": -7,
      "y": 91,
      "z": -1,
      "name": "Soil_Clay_Orange"
    },
    {
      "x": -7,
      "y": 92,
      "z": -1,
      "name": "Rock_Sandstone_Red"
    },
    {
      "x": -7,
      "y": 93,
      "z": -1,
      "name": "Rock_Sandstone_Red"
    },
    {
      "x": -7,
      "y": 94,
      "z": -1,
      "name": "Rock_Sandstone_Red"
    },
    {
      "x": -7,
      "y": 95,
      "z": -1,
      "name": "Rock_Sandstone_Red"
    },
    {
      "x": -7,
      "y": 96,
      "z": -1,
      "name": "Rock_Sandstone_Red"
    },
    {
      "x": -7,
      "y": 97,
      "z": -1,
      "name": "Rock_Sandstone_Red"
    },
    {
      "x": -7,
      "y": 98,
      "z": -1,
      "name": "Rock_Sandstone_Red"
    },
    {
      "x": -7,
      "y": 99,
      "z": -1,
      "name": "Rock_Sandstone_Red"
    },
    {
      "x": -7,
      "y": 100,
      "z": -1,
      "name": "Rock_Sandstone_Red"
    },
    {
      "x": -7,
      "y": 101,
      "z": -1,
      "name": "Rock_Sandstone_Red"
    },
    {
      "x": -7,
      "y": 102,
      "z": -1,
      "name": "Rock_Sandstone_Red"
    },
    {
      "x": -7,
      "y": 103,
      "z": -1,
      "name": "Rock_Sandstone_Red"
    },
    {
      "x": -7,
      "y": 104,
      "z": -1,
      "name": "Rock_Sandstone_Red"
    },
    {
      "x": -7,
      "y": 105,
      "z": -1,
      "name": "Soil_Clay_Orange"
    },
    {
      "x": -7,
      "y": 106,
      "z": -1,
      "name": "Rock_Sandstone"
    },
    {
      "x": -7,
      "y": 107,
      "z": -1,
      "name": "Soil_Clay_Orange"
    },
    {
      "x": -7,
      "y": 108,
      "z": -1,
      "name": "Soil_Clay_Orange"
    },
    {
      "x": -7,
      "y": 109,
      "z": -1,
      "name": "Soil_Clay_Orange"
    },
    {
      "x": -7,
      "y": 110,
      "z": -1,
      "name": "Soil_Clay_Smooth_Red"
    },
    {
      "x": -7,
      "y": 89,
      "z": 0,
      "name": "Rock_Sandstone"
    },
    {
      "x": -7,
      "y": 90,
      "z": 0,
      "name": "Soil_Clay_Orange"
    },
    {
      "x": -7,
      "y": 91,
      "z": 0,
      "name": "Soil_Clay_Orange"
    },
    {
      "x": -7,
      "y": 92,
      "z": 0,
      "name": "Rock_Sandstone_Red"
    },
    {
      "x": -7,
      "y": 93,
      "z": 0,
      "name": "Rock_Sandstone_Red"
    },
    {
      "x": -7,
      "y": 94,
      "z": 0,
      "name": "Rock_Sandstone_Red"
    },
    {
      "x": -7,
      "y": 95,
      "z": 0,
      "name": "Rock_Sandstone"
    },
    {
      "x": -7,
      "y": 96,
      "z": 0,
      "name": "Rock_Sandstone_Red"
    },
    {
      "x": -7,
      "y": 97,
      "z": 0,
      "name": "Rock_Sandstone_Red"
    },
    {
      "x": -7,
      "y": 98,
      "z": 0,
      "name": "Rock_Sandstone_Red"
    },
    {
      "x": -7,
      "y": 99,
      "z": 0,
      "name": "Rock_Sandstone_Red"
    },
    {
      "x": -7,
      "y": 100,
      "z": 0,
      "name": "Rock_Sandstone_Red"
    },
    {
      "x": -7,
      "y": 101,
      "z": 0,
      "name": "Rock_Sandstone_Red"
    },
    {
      "x": -7,
      "y": 102,
      "z": 0,
      "name": "Rock_Sandstone_Red"
    },
    {
      "x": -7,
      "y": 103,
      "z": 0,
      "name": "Rock_Sandstone_Red"
    },
    {
      "x": -7,
      "y": 104,
      "z": 0,
      "name": "Rock_Sandstone_Red"
    },
    {
      "x": -7,
      "y": 105,
      "z": 0,
      "name": "Soil_Clay_Orange"
    },
    {
      "x": -7,
      "y": 106,
      "z": 0,
      "name": "Rock_Sandstone"
    },
    {
      "x": -7,
      "y": 107,
      "z": 0,
      "name": "Soil_Clay_Orange"
    },
    {
      "x": -7,
      "y": 108,
      "z": 0,
      "name": "Soil_Clay_Orange"
    },
    {
      "x": -7,
      "y": 109,
      "z": 0,
      "name": "Soil_Clay_Orange"
    },
    {
      "x": -7,
      "y": 110,
      "z": 0,
      "name": "Soil_Clay_Smooth_Red"
    },
    {
      "x": -7,
      "y": 111,
      "z": 0,
      "name": "Soil_Clay_Smooth_Red"
    },
    {
      "x": -7,
      "y": 89,
      "z": 1,
      "name": "Rock_Sandstone"
    },
    {
      "x": -7,
      "y": 90,
      "z": 1,
      "name": "Soil_Clay_Orange"
    },
    {
      "x": -7,
      "y": 91,
      "z": 1,
      "name": "Soil_Clay_Orange"
    },
    {
      "x": -7,
      "y": 92,
      "z": 1,
      "name": "Rock_Sandstone_Red"
    },
    {
      "x": -7,
      "y": 93,
      "z": 1,
      "name": "Rock_Sandstone_Red"
    },
    {
      "x": -7,
      "y": 94,
      "z": 1,
      "name": "Rock_Sandstone_Red"
    },
    {
      "x": -7,
      "y": 95,
      "z": 1,
      "name": "Rock_Sandstone"
    },
    {
      "x": -7,
      "y": 96,
      "z": 1,
      "name": "Rock_Sandstone_Red"
    },
    {
      "x": -7,
      "y": 97,
      "z": 1,
      "name": "Rock_Sandstone_Red"
    },
    {
      "x": -7,
      "y": 98,
      "z": 1,
      "name": "Rock_Sandstone_Red"
    },
    {
      "x": -7,
      "y": 99,
      "z": 1,
      "name": "Rock_Sandstone_Red"
    },
    {
      "x": -7,
      "y": 100,
      "z": 1,
      "name": "Rock_Sandstone_Red"
    },
    {
      "x": -7,
      "y": 101,
      "z": 1,
      "name": "Rock_Sandstone_Red"
    },
    {
      "x": -7,
      "y": 102,
      "z": 1,
      "name": "Rock_Sandstone_Red"
    },
    {
      "x": -7,
      "y": 103,
      "z": 1,
      "name": "Rock_Sandstone_Red"
    },
    {
      "x": -7,
      "y": 104,
      "z": 1,
      "name": "Rock_Sandstone_Red"
    },
    {
      "x": -7,
      "y": 105,
      "z": 1,
      "name": "Soil_Clay_Orange"
    },
    {
      "x": -7,
      "y": 106,
      "z": 1,
      "name": "Rock_Sandstone"
    },
    {
      "x": -7,
      "y": 107,
      "z": 1,
      "name": "Soil_Clay_Orange"
    },
    {
      "x": -7,
      "y": 108,
      "z": 1,
      "name": "Rock_Sandstone_Red"
    },
    {
      "x": -7,
      "y": 109,
      "z": 1,
      "name": "Soil_Clay_Orange"
    },
    {
      "x": -7,
      "y": 110,
      "z": 1,
      "name": "Soil_Clay_Smooth_Red"
    },
    {
      "x": -7,
      "y": 90,
      "z": 2,
      "name": "Soil_Clay_Orange"
    },
    {
      "x": -7,
      "y": 91,
      "z": 2,
      "name": "Soil_Clay_Orange"
    },
    {
      "x": -7,
      "y": 92,
      "z": 2,
      "name": "Rock_Sandstone_Red"
    },
    {
      "x": -7,
      "y": 93,
      "z": 2,
      "name": "Rock_Sandstone_Red"
    },
    {
      "x": -7,
      "y": 94,
      "z": 2,
      "name": "Rock_Sandstone_Red"
    },
    {
      "x": -7,
      "y": 95,
      "z": 2,
      "name": "Rock_Sandstone"
    },
    {
      "x": -7,
      "y": 96,
      "z": 2,
      "name": "Rock_Sandstone_Red"
    },
    {
      "x": -7,
      "y": 97,
      "z": 2,
      "name": "Rock_Sandstone_Red"
    },
    {
      "x": -7,
      "y": 98,
      "z": 2,
      "name": "Rock_Sandstone_Red"
    },
    {
      "x": -7,
      "y": 99,
      "z": 2,
      "name": "Rock_Sandstone_Red"
    },
    {
      "x": -7,
      "y": 100,
      "z": 2,
      "name": "Rock_Sandstone_Red"
    },
    {
      "x": -7,
      "y": 101,
      "z": 2,
      "name": "Rock_Sandstone_Red"
    },
    {
      "x": -7,
      "y": 102,
      "z": 2,
      "name": "Rock_Sandstone_Red"
    },
    {
      "x": -7,
      "y": 103,
      "z": 2,
      "name": "Rock_Sandstone_Red"
    },
    {
      "x": -7,
      "y": 104,
      "z": 2,
      "name": "Rock_Sandstone_Red"
    },
    {
      "x": -7,
      "y": 105,
      "z": 2,
      "name": "Soil_Clay_Orange"
    },
    {
      "x": -7,
      "y": 106,
      "z": 2,
      "name": "Rock_Sandstone"
    },
    {
      "x": -7,
      "y": 107,
      "z": 2,
      "name": "Rock_Sandstone_Red"
    },
    {
      "x": -7,
      "y": 108,
      "z": 2,
      "name": "Rock_Sandstone_Red"
    },
    {
      "x": -7,
      "y": 109,
      "z": 2,
      "name": "Rock_Sandstone_Red"
    },
    {
      "x": -7,
      "y": 110,
      "z": 2,
      "name": "Soil_Clay_Smooth_Red"
    },
    {
      "x": -7,
      "y": 90,
      "z": 3,
      "name": "Soil_Clay_Orange"
    },
    {
      "x": -7,
      "y": 91,
      "z": 3,
      "name": "Soil_Clay_Orange"
    },
    {
      "x": -7,
      "y": 92,
      "z": 3,
      "name": "Rock_Sandstone_Red"
    },
    {
      "x": -7,
      "y": 93,
      "z": 3,
      "name": "Rock_Sandstone_Red"
    },
    {
      "x": -7,
      "y": 94,
      "z": 3,
      "name": "Rock_Sandstone_Red"
    },
    {
      "x": -7,
      "y": 95,
      "z": 3,
      "name": "Soil_Clay_Yellow"
    },
    {
      "x": -7,
      "y": 96,
      "z": 3,
      "name": "Rock_Sandstone_Red"
    },
    {
      "x": -7,
      "y": 97,
      "z": 3,
      "name": "Rock_Sandstone_Red"
    },
    {
      "x": -7,
      "y": 98,
      "z": 3,
      "name": "Rock_Sandstone_Red"
    },
    {
      "x": -7,
      "y": 99,
      "z": 3,
      "name": "Rock_Sandstone_Red"
    },
    {
      "x": -7,
      "y": 100,
      "z": 3,
      "name": "Rock_Sandstone_Red"
    },
    {
      "x": -7,
      "y": 101,
      "z": 3,
      "name": "Rock_Sandstone_Red"
    },
    {
      "x": -7,
      "y": 102,
      "z": 3,
      "name": "Rock_Sandstone_Red"
    },
    {
      "x": -7,
      "y": 103,
      "z": 3,
      "name": "Rock_Sandstone_Red"
    },
    {
      "x": -7,
      "y": 104,
      "z": 3,
      "name": "Soil_Clay_Orange"
    },
    {
      "x": -7,
      "y": 105,
      "z": 3,
      "name": "Soil_Clay_Orange"
    },
    {
      "x": -7,
      "y": 106,
      "z": 3,
      "name": "Rock_Sandstone"
    },
    {
      "x": -7,
      "y": 107,
      "z": 3,
      "name": "Rock_Sandstone_Red"
    },
    {
      "x": -7,
      "y": 108,
      "z": 3,
      "name": "Rock_Sandstone_Red"
    },
    {
      "x": -7,
      "y": 109,
      "z": 3,
      "name": "Rock_Sandstone_Red"
    },
    {
      "x": -7,
      "y": 110,
      "z": 3,
      "name": "Soil_Clay_Smooth_Red"
    },
    {
      "x": -7,
      "y": 90,
      "z": 4,
      "name": "Soil_Clay_Orange"
    },
    {
      "x": -7,
      "y": 91,
      "z": 4,
      "name": "Soil_Clay_Orange"
    },
    {
      "x": -7,
      "y": 92,
      "z": 4,
      "name": "Rock_Sandstone_Red"
    },
    {
      "x": -7,
      "y": 93,
      "z": 4,
      "name": "Rock_Sandstone_Red"
    },
    {
      "x": -7,
      "y": 94,
      "z": 4,
      "name": "Rock_Sandstone_Red"
    },
    {
      "x": -7,
      "y": 95,
      "z": 4,
      "name": "Rock_Sandstone"
    },
    {
      "x": -7,
      "y": 96,
      "z": 4,
      "name": "Rock_Sandstone_Red"
    },
    {
      "x": -7,
      "y": 97,
      "z": 4,
      "name": "Rock_Sandstone_Red"
    },
    {
      "x": -7,
      "y": 98,
      "z": 4,
      "name": "Rock_Sandstone_Red"
    },
    {
      "x": -7,
      "y": 99,
      "z": 4,
      "name": "Rock_Sandstone_Red"
    },
    {
      "x": -7,
      "y": 100,
      "z": 4,
      "name": "Rock_Sandstone_Red"
    },
    {
      "x": -7,
      "y": 101,
      "z": 4,
      "name": "Rock_Sandstone_Red"
    },
    {
      "x": -7,
      "y": 102,
      "z": 4,
      "name": "Rock_Sandstone_Red"
    },
    {
      "x": -7,
      "y": 103,
      "z": 4,
      "name": "Rock_Sandstone_Red"
    },
    {
      "x": -7,
      "y": 104,
      "z": 4,
      "name": "Soil_Clay_Orange"
    },
    {
      "x": -7,
      "y": 105,
      "z": 4,
      "name": "Soil_Clay_Orange"
    },
    {
      "x": -7,
      "y": 106,
      "z": 4,
      "name": "Rock_Sandstone"
    },
    {
      "x": -7,
      "y": 107,
      "z": 4,
      "name": "Rock_Sandstone_Red"
    },
    {
      "x": -7,
      "y": 108,
      "z": 4,
      "name": "Rock_Sandstone_Red"
    },
    {
      "x": -7,
      "y": 109,
      "z": 4,
      "name": "Rock_Sandstone_Red"
    },
    {
      "x": -7,
      "y": 110,
      "z": 4,
      "name": "Soil_Clay_Smooth_Red"
    },
    {
      "x": -7,
      "y": 91,
      "z": 5,
      "name": "Soil_Clay_Orange"
    },
    {
      "x": -7,
      "y": 92,
      "z": 5,
      "name": "Rock_Sandstone_Red"
    },
    {
      "x": -7,
      "y": 93,
      "z": 5,
      "name": "Rock_Sandstone_Red"
    },
    {
      "x": -7,
      "y": 94,
      "z": 5,
      "name": "Rock_Sandstone_Red"
    },
    {
      "x": -7,
      "y": 95,
      "z": 5,
      "name": "Rock_Sandstone"
    },
    {
      "x": -7,
      "y": 96,
      "z": 5,
      "name": "Rock_Sandstone_Red"
    },
    {
      "x": -7,
      "y": 97,
      "z": 5,
      "name": "Rock_Sandstone_Red"
    },
    {
      "x": -7,
      "y": 98,
      "z": 5,
      "name": "Rock_Sandstone_Red"
    },
    {
      "x": -7,
      "y": 99,
      "z": 5,
      "name": "Rock_Sandstone_Red"
    },
    {
      "x": -7,
      "y": 100,
      "z": 5,
      "name": "Rock_Sandstone_Red"
    },
    {
      "x": -7,
      "y": 101,
      "z": 5,
      "name": "Rock_Sandstone_Red"
    },
    {
      "x": -7,
      "y": 102,
      "z": 5,
      "name": "Rock_Sandstone_Red"
    },
    {
      "x": -7,
      "y": 103,
      "z": 5,
      "name": "Rock_Sandstone_Red"
    },
    {
      "x": -7,
      "y": 104,
      "z": 5,
      "name": "Soil_Clay_Orange"
    },
    {
      "x": -7,
      "y": 105,
      "z": 5,
      "name": "Soil_Clay_Orange"
    },
    {
      "x": -7,
      "y": 106,
      "z": 5,
      "name": "Rock_Sandstone"
    },
    {
      "x": -7,
      "y": 107,
      "z": 5,
      "name": "Rock_Sandstone_Red"
    },
    {
      "x": -7,
      "y": 108,
      "z": 5,
      "name": "Rock_Sandstone_Red"
    },
    {
      "x": -7,
      "y": 109,
      "z": 5,
      "name": "Soil_Clay_Smooth_Red"
    },
    {
      "x": -7,
      "y": 92,
      "z": 6,
      "name": "Rock_Sandstone_Red"
    },
    {
      "x": -7,
      "y": 93,
      "z": 6,
      "name": "Rock_Sandstone_Red"
    },
    {
      "x": -7,
      "y": 94,
      "z": 6,
      "name": "Rock_Sandstone_Red"
    },
    {
      "x": -7,
      "y": 95,
      "z": 6,
      "name": "Rock_Sandstone"
    },
    {
      "x": -7,
      "y": 96,
      "z": 6,
      "name": "Rock_Sandstone_Red"
    },
    {
      "x": -7,
      "y": 97,
      "z": 6,
      "name": "Rock_Sandstone_Red"
    },
    {
      "x": -7,
      "y": 98,
      "z": 6,
      "name": "Rock_Sandstone_Red"
    },
    {
      "x": -7,
      "y": 99,
      "z": 6,
      "name": "Rock_Sandstone_Red"
    },
    {
      "x": -7,
      "y": 100,
      "z": 6,
      "name": "Rock_Sandstone_Red"
    },
    {
      "x": -7,
      "y": 101,
      "z": 6,
      "name": "Rock_Sandstone_Red"
    },
    {
      "x": -7,
      "y": 102,
      "z": 6,
      "name": "Rock_Sandstone_Red"
    },
    {
      "x": -7,
      "y": 103,
      "z": 6,
      "name": "Soil_Clay_Orange"
    },
    {
      "x": -7,
      "y": 104,
      "z": 6,
      "name": "Soil_Clay_Orange"
    },
    {
      "x": -7,
      "y": 105,
      "z": 6,
      "name": "Soil_Clay_Orange"
    },
    {
      "x": -7,
      "y": 106,
      "z": 6,
      "name": "Rock_Sandstone"
    },
    {
      "x": -7,
      "y": 107,
      "z": 6,
      "name": "Rock_Sandstone_Red"
    },
    {
      "x": -7,
      "y": 108,
      "z": 6,
      "name": "Rock_Sandstone_Red"
    },
    {
      "x": -7,
      "y": 109,
      "z": 6,
      "name": "Soil_Clay_Smooth_Red"
    },
    {
      "x": -7,
      "y": 93,
      "z": 7,
      "name": "Rock_Sandstone_Red"
    },
    {
      "x": -7,
      "y": 94,
      "z": 7,
      "name": "Rock_Sandstone_Red"
    },
    {
      "x": -7,
      "y": 95,
      "z": 7,
      "name": "Rock_Sandstone_Red"
    },
    {
      "x": -7,
      "y": 96,
      "z": 7,
      "name": "Rock_Sandstone_Red"
    },
    {
      "x": -7,
      "y": 97,
      "z": 7,
      "name": "Rock_Sandstone_Red"
    },
    {
      "x": -7,
      "y": 98,
      "z": 7,
      "name": "Rock_Sandstone_Red"
    },
    {
      "x": -7,
      "y": 99,
      "z": 7,
      "name": "Rock_Sandstone_Red"
    },
    {
      "x": -7,
      "y": 100,
      "z": 7,
      "name": "Rock_Sandstone_Red"
    },
    {
      "x": -7,
      "y": 101,
      "z": 7,
      "name": "Rock_Sandstone_Red"
    },
    {
      "x": -7,
      "y": 102,
      "z": 7,
      "name": "Rock_Sandstone_Red"
    },
    {
      "x": -7,
      "y": 103,
      "z": 7,
      "name": "Soil_Clay_Orange"
    },
    {
      "x": -7,
      "y": 104,
      "z": 7,
      "name": "Soil_Clay_Orange"
    },
    {
      "x": -7,
      "y": 105,
      "z": 7,
      "name": "Soil_Clay_Orange"
    },
    {
      "x": -7,
      "y": 106,
      "z": 7,
      "name": "Rock_Sandstone"
    },
    {
      "x": -7,
      "y": 107,
      "z": 7,
      "name": "Rock_Sandstone_Red"
    },
    {
      "x": -7,
      "y": 108,
      "z": 7,
      "name": "Rock_Sandstone_Red"
    },
    {
      "x": -7,
      "y": 109,
      "z": 7,
      "name": "Soil_Clay_Smooth_Red"
    },
    {
      "x": -7,
      "y": 93,
      "z": 8,
      "name": "Rock_Sandstone_Red"
    },
    {
      "x": -7,
      "y": 94,
      "z": 8,
      "name": "Rock_Sandstone_Red"
    },
    {
      "x": -7,
      "y": 95,
      "z": 8,
      "name": "Rock_Sandstone_Red"
    },
    {
      "x": -7,
      "y": 96,
      "z": 8,
      "name": "Rock_Sandstone_Red"
    },
    {
      "x": -7,
      "y": 97,
      "z": 8,
      "name": "Rock_Sandstone_Red"
    },
    {
      "x": -7,
      "y": 98,
      "z": 8,
      "name": "Rock_Sandstone_Red"
    },
    {
      "x": -7,
      "y": 99,
      "z": 8,
      "name": "Rock_Sandstone_Red"
    },
    {
      "x": -7,
      "y": 100,
      "z": 8,
      "name": "Rock_Sandstone_Red"
    },
    {
      "x": -7,
      "y": 101,
      "z": 8,
      "name": "Rock_Sandstone_Red"
    },
    {
      "x": -7,
      "y": 102,
      "z": 8,
      "name": "Rock_Sandstone_Red"
    },
    {
      "x": -7,
      "y": 103,
      "z": 8,
      "name": "Soil_Clay_Orange"
    },
    {
      "x": -7,
      "y": 104,
      "z": 8,
      "name": "Soil_Clay_Orange"
    },
    {
      "x": -7,
      "y": 105,
      "z": 8,
      "name": "Soil_Clay_Orange"
    },
    {
      "x": -7,
      "y": 106,
      "z": 8,
      "name": "Rock_Sandstone"
    },
    {
      "x": -7,
      "y": 107,
      "z": 8,
      "name": "Rock_Sandstone_Red"
    },
    {
      "x": -7,
      "y": 108,
      "z": 8,
      "name": "Soil_Clay_Smooth_Red"
    },
    {
      "x": -7,
      "y": 95,
      "z": 9,
      "name": "Soil_Clay_Orange"
    },
    {
      "x": -7,
      "y": 96,
      "z": 9,
      "name": "Rock_Sandstone"
    },
    {
      "x": -7,
      "y": 97,
      "z": 9,
      "name": "Rock_Sandstone_Red"
    },
    {
      "x": -7,
      "y": 98,
      "z": 9,
      "name": "Rock_Sandstone_Red"
    },
    {
      "x": -7,
      "y": 99,
      "z": 9,
      "name": "Rock_Sandstone_Red"
    },
    {
      "x": -7,
      "y": 100,
      "z": 9,
      "name": "Rock_Sandstone_Red"
    },
    {
      "x": -7,
      "y": 101,
      "z": 9,
      "name": "Rock_Sandstone_Red"
    },
    {
      "x": -7,
      "y": 102,
      "z": 9,
      "name": "Rock_Sandstone_Red"
    },
    {
      "x": -7,
      "y": 103,
      "z": 9,
      "name": "Soil_Clay_Orange"
    },
    {
      "x": -7,
      "y": 104,
      "z": 9,
      "name": "Soil_Clay_Orange"
    },
    {
      "x": -7,
      "y": 105,
      "z": 9,
      "name": "Soil_Clay_Orange"
    },
    {
      "x": -7,
      "y": 106,
      "z": 9,
      "name": "Rock_Sandstone"
    },
    {
      "x": -7,
      "y": 107,
      "z": 9,
      "name": "Rock_Sandstone_Red"
    },
    {
      "x": -7,
      "y": 108,
      "z": 9,
      "name": "Soil_Clay_Smooth_Red"
    },
    {
      "x": -7,
      "y": 98,
      "z": 10,
      "name": "Rock_Sandstone_Red"
    },
    {
      "x": -7,
      "y": 99,
      "z": 10,
      "name": "Rock_Sandstone_Red"
    },
    {
      "x": -7,
      "y": 100,
      "z": 10,
      "name": "Rock_Sandstone_Red"
    },
    {
      "x": -7,
      "y": 101,
      "z": 10,
      "name": "Rock_Sandstone_Red"
    },
    {
      "x": -7,
      "y": 102,
      "z": 10,
      "name": "Rock_Sandstone_Red"
    },
    {
      "x": -7,
      "y": 103,
      "z": 10,
      "name": "Soil_Clay_Orange"
    },
    {
      "x": -7,
      "y": 104,
      "z": 10,
      "name": "Soil_Clay_Orange"
    },
    {
      "x": -7,
      "y": 105,
      "z": 10,
      "name": "Soil_Clay_Orange"
    },
    {
      "x": -7,
      "y": 106,
      "z": 10,
      "name": "Rock_Sandstone"
    },
    {
      "x": -7,
      "y": 107,
      "z": 10,
      "name": "Rock_Sandstone_Red"
    },
    {
      "x": -7,
      "y": 108,
      "z": 10,
      "name": "Soil_Clay_Smooth_Red"
    },
    {
      "x": -7,
      "y": 98,
      "z": 11,
      "name": "Rock_Sandstone_Red"
    },
    {
      "x": -7,
      "y": 99,
      "z": 11,
      "name": "Rock_Sandstone_Red"
    },
    {
      "x": -7,
      "y": 100,
      "z": 11,
      "name": "Rock_Sandstone_Red"
    },
    {
      "x": -7,
      "y": 101,
      "z": 11,
      "name": "Rock_Sandstone_Red"
    },
    {
      "x": -7,
      "y": 102,
      "z": 11,
      "name": "Soil_Clay_Orange"
    },
    {
      "x": -7,
      "y": 103,
      "z": 11,
      "name": "Soil_Clay_Orange"
    },
    {
      "x": -7,
      "y": 104,
      "z": 11,
      "name": "Soil_Clay_Orange"
    },
    {
      "x": -7,
      "y": 105,
      "z": 11,
      "name": "Soil_Clay_Orange"
    },
    {
      "x": -7,
      "y": 106,
      "z": 11,
      "name": "Rock_Sandstone"
    },
    {
      "x": -7,
      "y": 107,
      "z": 11,
      "name": "Rock_Sandstone_Red"
    },
    {
      "x": -7,
      "y": 108,
      "z": 11,
      "name": "Rock_Sandstone_Red"
    },
    {
      "x": -6,
      "y": 83,
      "z": -9,
      "name": "Rock_Sandstone_Red"
    },
    {
      "x": -6,
      "y": 84,
      "z": -9,
      "name": "Rock_Sandstone_Red"
    },
    {
      "x": -6,
      "y": 83,
      "z": -8,
      "name": "Rock_Sandstone_Red"
    },
    {
      "x": -6,
      "y": 84,
      "z": -8,
      "name": "Rock_Sandstone_Red"
    },
    {
      "x": -6,
      "y": 85,
      "z": -8,
      "name": "Soil_Clay_Smooth_Red"
    },
    {
      "x": -6,
      "y": 89,
      "z": -8,
      "name": "Rock_Sandstone"
    },
    {
      "x": -6,
      "y": 90,
      "z": -8,
      "name": "Rock_Sandstone_Red"
    },
    {
      "x": -6,
      "y": 91,
      "z": -8,
      "name": "Rock_Sandstone_Red"
    },
    {
      "x": -6,
      "y": 92,
      "z": -8,
      "name": "Soil_Clay_Orange"
    },
    {
      "x": -6,
      "y": 93,
      "z": -8,
      "name": "Soil_Clay_Orange"
    },
    {
      "x": -6,
      "y": 94,
      "z": -8,
      "name": "Rock_Sandstone"
    },
    {
      "x": -6,
      "y": 95,
      "z": -8,
      "name": "Rock_Sandstone_Red"
    },
    {
      "x": -6,
      "y": 99,
      "z": -8,
      "name": "Rock_Sandstone_Red"
    },
    {
      "x": -6,
      "y": 100,
      "z": -8,
      "name": "Rock_Sandstone_Red"
    },
    {
      "x": -6,
      "y": 101,
      "z": -8,
      "name": "Rock_Sandstone_Red"
    },
    {
      "x": -6,
      "y": 102,
      "z": -8,
      "name": "Rock_Sandstone_Red"
    },
    {
      "x": -6,
      "y": 104,
      "z": -8,
      "name": "Soil_Clay_Orange"
    },
    {
      "x": -6,
      "y": 105,
      "z": -8,
      "name": "Soil_Clay_Orange"
    },
    {
      "x": -6,
      "y": 106,
      "z": -8,
      "name": "Soil_Clay_Orange"
    },
    {
      "x": -6,
      "y": 107,
      "z": -8,
      "name": "Soil_Clay_Orange"
    },
    {
      "x": -6,
      "y": 82,
      "z": -7,
      "name": "Rock_Sandstone_Red"
    },
    {
      "x": -6,
      "y": 83,
      "z": -7,
      "name": "Rock_Sandstone_Red"
    },
    {
      "x": -6,
      "y": 84,
      "z": -7,
      "name": "Rock_Sandstone_Red"
    },
    {
      "x": -6,
      "y": 85,
      "z": -7,
      "name": "Soil_Clay_Smooth_Red"
    },
    {
      "x": -6,
      "y": 89,
      "z": -7,
      "name": "Rock_Sandstone"
    },
    {
      "x": -6,
      "y": 90,
      "z": -7,
      "name": "Rock_Sandstone_Red"
    },
    {
      "x": -6,
      "y": 91,
      "z": -7,
      "name": "Soil_Clay_Orange"
    },
    {
      "x": -6,
      "y": 92,
      "z": -7,
      "name": "Soil_Clay_Orange"
    },
    {
      "x": -6,
      "y": 93,
      "z": -7,
      "name": "Soil_Clay_Orange"
    },
    {
      "x": -6,
      "y": 94,
      "z": -7,
      "name": "Rock_Sandstone"
    },
    {
      "x": -6,
      "y": 95,
      "z": -7,
      "name": "Rock_Sandstone_Red"
    },
    {
      "x": -6,
      "y": 96,
      "z": -7,
      "name": "Rock_Sandstone_Red"
    },
    {
      "x": -6,
      "y": 98,
      "z": -7,
      "name": "Soil_Clay_Orange"
    },
    {
      "x": -6,
      "y": 99,
      "z": -7,
      "name": "Rock_Sandstone_Red"
    },
    {
      "x": -6,
      "y": 100,
      "z": -7,
      "name": "Rock_Sandstone_Red"
    },
    {
      "x": -6,
      "y": 101,
      "z": -7,
      "name": "Rock_Sandstone_Red"
    },
    {
      "x": -6,
      "y": 102,
      "z": -7,
      "name": "Rock_Sandstone_Red"
    },
    {
      "x": -6,
      "y": 103,
      "z": -7,
      "name": "Rock_Sandstone_Red"
    },
    {
      "x": -6,
      "y": 104,
      "z": -7,
      "name": "Soil_Clay_Orange"
    },
    {
      "x": -6,
      "y": 105,
      "z": -7,
      "name": "Soil_Clay_Orange"
    },
    {
      "x": -6,
      "y": 106,
      "z": -7,
      "name": "Soil_Clay_Orange"
    },
    {
      "x": -6,
      "y": 107,
      "z": -7,
      "name": "Soil_Clay_Orange"
    },
    {
      "x": -6,
      "y": 108,
      "z": -7,
      "name": "Soil_Clay_Smooth_Red"
    },
    {
      "x": -6,
      "y": 82,
      "z": -6,
      "name": "Rock_Sandstone_Red"
    },
    {
      "x": -6,
      "y": 83,
      "z": -6,
      "name": "Rock_Sandstone_Red"
    },
    {
      "x": -6,
      "y": 84,
      "z": -6,
      "name": "Rock_Sandstone_Red"
    },
    {
      "x": -6,
      "y": 89,
      "z": -6,
      "name": "Rock_Sandstone"
    },
    {
      "x": -6,
      "y": 90,
      "z": -6,
      "name": "Soil_Clay_Orange"
    },
    {
      "x": -6,
      "y": 91,
      "z": -6,
      "name": "Soil_Clay_Orange"
    },
    {
      "x": -6,
      "y": 92,
      "z": -6,
      "name": "Soil_Clay_Orange"
    },
    {
      "x": -6,
      "y": 93,
      "z": -6,
      "name": "Soil_Clay_Orange"
    },
    {
      "x": -6,
      "y": 94,
      "z": -6,
      "name": "Rock_Sandstone"
    },
    {
      "x": -6,
      "y": 95,
      "z": -6,
      "name": "Rock_Sandstone_Red"
    },
    {
      "x": -6,
      "y": 96,
      "z": -6,
      "name": "Rock_Sandstone_Red"
    },
    {
      "x": -6,
      "y": 97,
      "z": -6,
      "name": "Rock_Sandstone_Red"
    },
    {
      "x": -6,
      "y": 98,
      "z": -6,
      "name": "Rock_Sandstone_Red"
    },
    {
      "x": -6,
      "y": 99,
      "z": -6,
      "name": "Rock_Sandstone_Red"
    },
    {
      "x": -6,
      "y": 100,
      "z": -6,
      "name": "Rock_Sandstone_Red"
    },
    {
      "x": -6,
      "y": 101,
      "z": -6,
      "name": "Rock_Sandstone_Red"
    },
    {
      "x": -6,
      "y": 102,
      "z": -6,
