{
  "version": 8,
  "blockIdVersion": 10,
  "anchorX": 0,
  "anchorY": 0,
  "anchorZ": 0,
  "blocks": [
    {
      "x": -11,
      "y": 74,
      "z": -3,
      "name": "Soil_Clay_Orange"
    },
    {
      "x": -11,
      "y": 75,
      "z": -3,
      "name": "Soil_Clay_Orange"
    },
    {
      "x": -11,
      "y": 76,
      "z": -3,
      "name": "Rock_Sandstone"
    },
    {
      "x": -11,
      "y": 79,
      "z": -3,
      "name": "Soil_Clay_Orange"
    },
    {
      "x": -11,
      "y": 80,
      "z": -3,
      "name": "Soil_Clay_Orange"
    },
    {
      "x": -11,
      "y": 81,
      "z": -3,
      "name": "Rock_Sandstone_Red"
    },
    {
      "x": -11,
      "y": 82,
      "z": -3,
      "name": "Rock_Sandstone_Red"
    },
    {
      "x": -11,
      "y": 83,
      "z": -3,
      "name": "Rock_Sandstone_Red"
    },
    {
      "x": -11,
      "y": 84,
      "z": -3,
      "name": "Rock_Sandstone_Red"
    },
    {
      "x": -11,
      "y": 85,
      "z": -3,
      "name": "Soil_Clay_Yellow"
    },
    {
      "x": -11,
      "y": 86,
      "z": -3,
      "name": "Soil_Clay_Orange"
    },
    {
      "x": -11,
      "y": 87,
      "z": -3,
      "name": "Soil_Clay_Orange"
    },
    {
      "x": -11,
      "y": 88,
      "z": -3,
      "name": "Soil_Clay_Orange"
    },
    {
      "x": -11,
      "y": 89,
      "z": -3,
      "name": "Soil_Clay_Orange"
    },
    {
      "x": -11,
      "y": 75,
      "z": -2,
      "name": "Soil_Clay_Orange"
    },
    {
      "x": -11,
      "y": 76,
      "z": -2,
      "name": "Soil_Clay_Orange"
    },
    {
      "x": -11,
      "y": 77,
      "z": -2,
      "name": "Soil_Clay_Orange"
    },
    {
      "x": -11,
      "y": 80,
      "z": -2,
      "name": "Soil_Clay_Orange"
    },
    {
      "x": -11,
      "y": 81,
      "z": -2,
      "name": "Rock_Sandstone_Red"
    },
    {
      "x": -11,
      "y": 82,
      "z": -2,
      "name": "Rock_Sandstone_Red"
    },
    {
      "x": -11,
      "y": 83,
      "z": -2,
      "name": "Rock_Sandstone_Red"
    },
    {
      "x": -11,
      "y": 84,
      "z": -2,
      "name": "Rock_Sandstone_Red"
    },
    {
      "x": -11,
      "y": 85,
      "z": -2,
      "name": "Soil_Clay_Yellow"
    },
    {
      "x": -11,
      "y": 86,
      "z": -2,
      "name": "Soil_Clay_Orange"
    },
    {
      "x": -11,
      "y": 87,
      "z": -2,
      "name": "Soil_Clay_Orange"
    },
    {
      "x": -11,
      "y": 88,
      "z": -2,
      "name": "Soil_Clay_Orange"
    },
    {
      "x": -11,
      "y": 89,
      "z": -2,
      "name": "Rock_Sandstone_Red"
    },
    {
      "x": -11,
      "y": 90,
      "z": -2,
      "name": "Soil_Clay_Smooth_Red"
    },
    {
      "x": -11,
      "y": 75,
      "z": -1,
      "name": "Soil_Clay_Orange"
    },
    {
      "x": -11,
      "y": 76,
      "z": -1,
      "name": "Soil_Clay_Orange"
    },
    {
      "x": -11,
      "y": 77,
      "z": -1,
      "name": "Soil_Clay_Orange"
    },
    {
      "x": -11,
      "y": 80,
      "z": -1,
      "name": "Soil_Clay_Orange"
    },
    {
      "x": -11,
      "y": 81,
      "z": -1,
      "name": "Rock_Sandstone_Red"
    },
    {
      "x": -11,
      "y": 82,
      "z": -1,
      "name": "Rock_Sandstone_Red"
    },
    {
      "x": -11,
      "y": 83,
      "z": -1,
      "name": "Rock_Sandstone_Red"
    },
    {
      "x": -11,
      "y": 84,
      "z": -1,
      "name": "Rock_Sandstone_Red"
    },
    {
      "x": -11,
      "y": 85,
      "z": -1,
      "name": "Soil_Clay_Yellow"
    },
    {
      "x": -11,
      "y": 86,
      "z": -1,
      "name": "Rock_Sandstone"
    },
    {
      "x": -11,
      "y": 87,
      "z": -1,
      "name": "Soil_Clay_Orange"
    },
    {
      "x": -11,
      "y": 88,
      "z": -1,
      "name": "Soil_Clay_Orange"
    },
    {
      "x": -11,
      "y": 89,
      "z": -1,
      "name": "Soil_Clay_Orange"
    },
    {
      "x": -10,
      "y": 75,
      "z": -4,
      "name": "Rock_Sandstone"
    },
    {
      "x": -10,
      "y": 76,
      "z": -4,
      "name": "Soil_Clay_Orange"
    },
    {
      "x": -10,
      "y": 77,
      "z": -4,
      "name": "Soil_Clay_Orange"
    },
    {
      "x": -10,
      "y": 78,
      "z": -4,
      "name": "Soil_Clay_Orange"
    },
    {
      "x": -10,
      "y": 79,
      "z": -4,
      "name": "Soil_Clay_Orange"
    },
    {
      "x": -10,
      "y": 80,
      "z": -4,
      "name": "Soil_Clay_Orange"
    },
    {
      "x": -10,
      "y": 81,
      "z": -4,
      "name": "Rock_Sandstone_Red"
    },
    {
      "x": -10,
      "y": 82,
      "z": -4,
      "name": "Rock_Sandstone_Red"
    },
    {
      "x": -10,
      "y": 83,
      "z": -4,
      "name": "Rock_Sandstone_Red"
    },
    {
      "x": -10,
      "y": 84,
      "z": -4,
      "name": "Rock_Sandstone_Red"
    },
    {
      "x": -10,
      "y": 85,
      "z": -4,
      "name": "Soil_Clay_Yellow"
    },
    {
      "x": -10,
      "y": 86,
      "z": -4,
      "name": "Soil_Clay_Orange"
    },
    {
      "x": -10,
      "y": 87,
      "z": -4,
      "name": "Soil_Clay_Orange"
    },
    {
      "x": -10,
      "y": 88,
      "z": -4,
      "name": "Soil_Clay_Orange"
    },
    {
      "x": -10,
      "y": 89,
      "z": -4,
      "name": "Rock_Sandstone_Red"
    },
    {
      "x": -10,
      "y": 90,
      "z": -4,
      "name": "Soil_Clay_Smooth_Red"
    },
    {
      "x": -10,
      "y": 74,
      "z": -3,
      "name": "Soil_Clay_Orange"
    },
    {
      "x": -10,
      "y": 75,
      "z": -3,
      "name": "Soil_Clay_Orange"
    },
    {
      "x": -10,
      "y": 76,
      "z": -3,
      "name": "Soil_Clay_Orange"
    },
    {
      "x": -10,
      "y": 77,
      "z": -3,
      "name": "Soil_Clay_Orange"
    },
    {
      "x": -10,
      "y": 78,
      "z": -3,
      "name": "Soil_Clay_Orange"
    },
    {
      "x": -10,
      "y": 79,
      "z": -3,
      "name": "Soil_Clay_Orange"
    },
    {
      "x": -10,
      "y": 80,
      "z": -3,
      "name": "Soil_Clay_Orange"
    },
    {
      "x": -10,
      "y": 81,
      "z": -3,
      "name": "Rock_Sandstone_Red"
    },
    {
      "x": -10,
      "y": 82,
      "z": -3,
      "name": "Rock_Sandstone_Red"
    },
    {
      "x": -10,
      "y": 83,
      "z": -3,
      "name": "Rock_Sandstone_Red"
    },
    {
      "x": -10,
      "y": 84,
      "z": -3,
      "name": "Rock_Sandstone_Red"
    },
    {
      "x": -10,
      "y": 85,
      "z": -3,
      "name": "Soil_Clay_Yellow"
    },
    {
      "x": -10,
      "y": 86,
      "z": -3,
      "name": "Soil_Clay_Orange"
    },
    {
      "x": -10,
      "y": 87,
      "z": -3,
      "name": "Soil_Clay_Orange"
    },
    {
      "x": -10,
      "y": 88,
      "z": -3,
      "name": "Soil_Clay_Orange"
    },
    {
      "x": -10,
      "y": 89,
      "z": -3,
      "name": "Rock_Sandstone_Red"
    },
    {
      "x": -10,
      "y": 90,
      "z": -3,
      "name": "Soil_Clay_Smooth_Red"
    },
    {
      "x": -10,
      "y": 74,
      "z": -2,
      "name": "Soil_Clay_Orange"
    },
    {
      "x": -10,
      "y": 75,
      "z": -2,
      "name": "Soil_Clay_Orange"
    },
    {
      "x": -10,
      "y": 76,
      "z": -2,
      "name": "Soil_Clay_Orange"
    },
    {
      "x": -10,
      "y": 77,
      "z": -2,
      "name": "Soil_Clay_Orange"
    },
    {
      "x": -10,
      "y": 78,
      "z": -2,
      "name": "Soil_Clay_Orange"
    },
    {
      "x": -10,
      "y": 79,
      "z": -2,
      "name": "Soil_Clay_Orange"
    },
    {
      "x": -10,
      "y": 80,
      "z": -2,
      "name": "Soil_Clay_Orange"
    },
    {
      "x": -10,
      "y": 81,
      "z": -2,
      "name": "Rock_Sandstone_Red"
    },
    {
      "x": -10,
      "y": 82,
      "z": -2,
      "name": "Rock_Sandstone_Red"
    },
    {
      "x": -10,
      "y": 83,
      "z": -2,
      "name": "Rock_Sandstone_Red"
    },
    {
      "x": -10,
      "y": 84,
      "z": -2,
      "name": "Rock_Sandstone_Red"
    },
    {
      "x": -10,
      "y": 85,
      "z": -2,
      "name": "Rock_Sandstone"
    },
    {
      "x": -10,
      "y": 86,
      "z": -2,
      "name": "Rock_Sandstone"
    },
    {
      "x": -10,
      "y": 87,
      "z": -2,
      "name": "Soil_Clay_Orange"
    },
    {
      "x": -10,
      "y": 88,
      "z": -2,
      "name": "Soil_Clay_Orange"
    },
    {
      "x": -10,
      "y": 89,
      "z": -2,
      "name": "Rock_Sandstone_Red"
    },
    {
      "x": -10,
      "y": 90,
      "z": -2,
      "name": "Soil_Clay_Smooth_Red"
    },
    {
      "x": -10,
      "y": 74,
      "z": -1,
      "name": "Rock_Sandstone_Red"
    },
    {
      "x": -10,
      "y": 75,
      "z": -1,
      "name": "Soil_Clay_Orange"
    },
    {
      "x": -10,
      "y": 76,
      "z": -1,
      "name": "Soil_Clay_Orange"
    },
    {
      "x": -10,
      "y": 77,
      "z": -1,
      "name": "Soil_Clay_Orange"
    },
    {
      "x": -10,
      "y": 78,
      "z": -1,
      "name": "Soil_Clay_Orange"
    },
    {
      "x": -10,
      "y": 79,
      "z": -1,
      "name": "Soil_Clay_Orange"
    },
    {
      "x": -10,
      "y": 80,
      "z": -1,
      "name": "Soil_Clay_Orange"
    },
    {
      "x": -10,
      "y": 81,
      "z": -1,
      "name": "Rock_Sandstone_Red"
    },
    {
      "x": -10,
      "y": 82,
      "z": -1,
      "name": "Rock_Sandstone_Red"
    },
    {
      "x": -10,
      "y": 83,
      "z": -1,
      "name": "Rock_Sandstone_Red"
    },
    {
      "x": -10,
      "y": 84,
      "z": -1,
      "name": "Rock_Sandstone_Red"
    },
    {
      "x": -10,
      "y": 85,
      "z": -1,
      "name": "Rock_Sandstone"
    },
    {
      "x": -10,
      "y": 86,
      "z": -1,
      "name": "Rock_Sandstone"
    },
    {
      "x": -10,
      "y": 87,
      "z": -1,
      "name": "Soil_Clay_Orange"
    },
    {
      "x": -10,
      "y": 88,
      "z": -1,
      "name": "Soil_Clay_Orange"
    },
    {
      "x": -10,
      "y": 89,
      "z": -1,
      "name": "Rock_Sandstone_Red"
    },
    {
      "x": -10,
      "y": 90,
      "z": -1,
      "name": "Soil_Clay_Smooth_Red"
    },
    {
      "x": -10,
      "y": 74,
      "z": 0,
      "name": "Rock_Sandstone_Red"
    },
    {
      "x": -10,
      "y": 75,
      "z": 0,
      "name": "Rock_Sandstone_Red"
    },
    {
      "x": -10,
      "y": 76,
      "z": 0,
      "name": "Soil_Clay_Orange"
    },
    {
      "x": -10,
      "y": 77,
      "z": 0,
      "name": "Soil_Clay_Orange"
    },
    {
      "x": -10,
      "y": 79,
      "z": 0,
      "name": "Soil_Clay_Orange"
    },
    {
      "x": -10,
      "y": 80,
      "z": 0,
      "name": "Soil_Clay_Orange"
    },
    {
      "x": -10,
      "y": 81,
      "z": 0,
      "name": "Rock_Sandstone_Red"
    },
    {
      "x": -10,
      "y": 82,
      "z": 0,
      "name": "Rock_Sandstone_Red"
    },
    {
      "x": -10,
      "y": 83,
      "z": 0,
      "name": "Rock_Sandstone_Red"
    },
    {
      "x": -10,
      "y": 84,
      "z": 0,
      "name": "Rock_Sandstone_Red"
    },
    {
      "x": -10,
      "y": 85,
      "z": 0,
      "name": "Rock_Sandstone"
    },
    {
      "x": -10,
      "y": 86,
      "z": 0,
      "name": "Rock_Sandstone"
    },
    {
      "x": -10,
      "y": 87,
      "z": 0,
      "name": "Soil_Clay_Orange"
    },
    {
      "x": -10,
      "y": 88,
      "z": 0,
      "name": "Soil_Clay_Orange"
    },
    {
      "x": -10,
      "y": 89,
      "z": 0,
      "name": "Rock_Sandstone_Red"
    },
    {
      "x": -10,
      "y": 90,
      "z": 0,
      "name": "Soil_Clay_Smooth_Red"
    },
    {
      "x": -10,
      "y": 56,
      "z": 1,
      "name": "Soil_Clay_Orange"
    },
    {
      "x": -10,
      "y": 57,
      "z": 1,
      "name": "Soil_Clay_Orange"
    },
    {
      "x": -10,
      "y": 59,
      "z": 1,
      "name": "Rock_Sandstone"
    },
    {
      "x": -10,
      "y": 60,
      "z": 1,
      "name": "Rock_Sandstone"
    },
    {
      "x": -10,
      "y": 61,
      "z": 1,
      "name": "Rock_Sandstone_Red"
    },
    {
      "x": -10,
      "y": 62,
      "z": 1,
      "name": "Rock_Sandstone_Red"
    },
    {
      "x": -10,
      "y": 63,
      "z": 1,
      "name": "Rock_Sandstone_Red"
    },
    {
      "x": -10,
      "y": 64,
      "z": 1,
      "name": "Rock_Sandstone"
    },
    {
      "x": -10,
      "y": 65,
      "z": 1,
      "name": "Rock_Sandstone_Red"
    },
    {
      "x": -10,
      "y": 66,
      "z": 1,
      "name": "Rock_Sandstone_Red"
    },
    {
      "x": -10,
      "y": 67,
      "z": 1,
      "name": "Rock_Sandstone_Red"
    },
    {
      "x": -10,
      "y": 68,
      "z": 1,
      "name": "Soil_Clay_Orange"
    },
    {
      "x": -10,
      "y": 69,
      "z": 1,
      "name": "Rock_Sandstone_Red"
    },
    {
      "x": -10,
      "y": 70,
      "z": 1,
      "name": "Rock_Sandstone_Red"
    },
    {
      "x": -10,
      "y": 56,
      "z": 2,
      "name": "Rock_Sandstone"
    },
    {
      "x": -10,
      "y": 58,
      "z": 2,
      "name": "Soil_Clay_Orange"
    },
    {
      "x": -10,
      "y": 59,
      "z": 2,
      "name": "Rock_Sandstone"
    },
    {
      "x": -10,
      "y": 60,
      "z": 2,
      "name": "Rock_Sandstone"
    },
    {
      "x": -10,
      "y": 61,
      "z": 2,
      "name": "Rock_Sandstone_Red"
    },
    {
      "x": -10,
      "y": 62,
      "z": 2,
      "name": "Rock_Sandstone_Red"
    },
    {
      "x": -10,
      "y": 63,
      "z": 2,
      "name": "Rock_Sandstone_Red"
    },
    {
      "x": -10,
      "y": 64,
      "z": 2,
      "name": "Rock_Sandstone_Red"
    },
    {
      "x": -10,
      "y": 65,
      "z": 2,
      "name": "Rock_Sandstone_Red"
    },
    {
      "x": -10,
      "y": 66,
      "z": 2,
      "name": "Rock_Sandstone_Red"
    },
    {
      "x": -10,
      "y": 67,
      "z": 2,
      "name": "Rock_Sandstone_Red"
    },
    {
      "x": -10,
      "y": 68,
      "z": 2,
      "name": "Soil_Clay_Orange"
    },
    {
      "x": -10,
      "y": 69,
      "z": 2,
      "name": "Rock_Sandstone_Red"
    },
    {
      "x": -10,
      "y": 70,
      "z": 2,
      "name": "Rock_Sandstone_Red"
    },
    {
      "x": -10,
      "y": 71,
      "z": 2,
      "name": "Soil_Clay_Orange"
    },
    {
      "x": -10,
      "y": 56,
      "z": 3,
      "name": "Rock_Sandstone"
    },
    {
      "x": -10,
      "y": 57,
      "z": 3,
      "name": "Soil_Clay_Orange"
    },
    {
      "x": -10,
      "y": 58,
      "z": 3,
      "name": "Soil_Clay_Orange"
    },
    {
      "x": -10,
      "y": 59,
      "z": 3,
      "name": "Rock_Sandstone"
    },
    {
      "x": -10,
      "y": 60,
      "z": 3,
      "name": "Rock_Sandstone"
    },
    {
      "x": -10,
      "y": 61,
      "z": 3,
      "name": "Rock_Sandstone_Red"
    },
    {
      "x": -10,
      "y": 62,
      "z": 3,
      "name": "Rock_Sandstone_Red"
    },
    {
      "x": -10,
      "y": 63,
      "z": 3,
      "name": "Rock_Sandstone_Red"
    },
    {
      "x": -10,
      "y": 64,
      "z": 3,
      "name": "Rock_Sandstone_Red"
    },
    {
      "x": -10,
      "y": 65,
      "z": 3,
      "name": "Rock_Sandstone_Red"
    },
    {
      "x": -10,
      "y": 66,
      "z": 3,
      "name": "Rock_Sandstone_Red"
    },
    {
      "x": -10,
      "y": 67,
      "z": 3,
      "name": "Rock_Sandstone_Red"
    },
    {
      "x": -10,
      "y": 68,
      "z": 3,
      "name": "Soil_Clay_Orange"
    },
    {
      "x": -10,
      "y": 69,
      "z": 3,
      "name": "Rock_Sandstone_Red"
    },
    {
      "x": -10,
      "y": 70,
      "z": 3,
      "name": "Rock_Sandstone_Red"
    },
    {
      "x": -9,
      "y": 24,
      "z": -6,
      "name": "Rock_Sandstone_Red"
    },
    {
      "x": -9,
      "y": 25,
      "z": -6,
      "name": "Rock_Sandstone_Red"
    },
    {
      "x": -9,
      "y": 74,
      "z": -5,
      "name": "Soil_Clay_Orange"
    },
    {
      "x": -9,
      "y": 75,
      "z": -5,
      "name": "Rock_Sandstone"
    },
    {
      "x": -9,
      "y": 76,
      "z": -5,
      "name": "Soil_Clay_Orange"
    },
    {
      "x": -9,
      "y": 77,
      "z": -5,
      "name": "Rock_Sandstone_Red"
    },
    {
      "x": -9,
      "y": 78,
      "z": -5,
      "name": "Rock_Sandstone_Red"
    },
    {
      "x": -9,
      "y": 79,
      "z": -5,
      "name": "Soil_Clay_Orange"
    },
    {
      "x": -9,
      "y": 80,
      "z": -5,
      "name": "Soil_Clay_Orange"
    },
    {
      "x": -9,
      "y": 81,
      "z": -5,
      "name": "Rock_Sandstone_Red"
    },
    {
      "x": -9,
      "y": 82,
      "z": -5,
      "name": "Rock_Sandstone_Red"
    },
    {
      "x": -9,
      "y": 83,
      "z": -5,
      "name": "Rock_Sandstone_Red"
    },
    {
      "x": -9,
      "y": 84,
      "z": -5,
      "name": "Rock_Sandstone_Red"
    },
    {
      "x": -9,
      "y": 85,
      "z": -5,
      "name": "Rock_Sandstone"
    },
    {
      "x": -9,
      "y": 86,
      "z": -5,
      "name": "Rock_Sandstone_Red"
    },
    {
      "x": -9,
      "y": 87,
      "z": -5,
      "name": "Rock_Sandstone_Red"
    },
    {
      "x": -9,
      "y": 88,
      "z": -5,
      "name": "Rock_Sandstone_Red"
    },
    {
      "x": -9,
      "y": 89,
      "z": -5,
      "name": "Rock_Sandstone_Red"
    },
    {
      "x": -9,
      "y": 90,
      "z": -5,
      "name": "Soil_Clay_Smooth_Red"
    },
    {
      "x": -9,
      "y": 74,
      "z": -4,
      "name": "Soil_Clay_Orange"
    },
    {
      "x": -9,
      "y": 75,
      "z": -4,
      "name": "Rock_Sandstone"
    },
    {
      "x": -9,
      "y": 76,
      "z": -4,
      "name": "Soil_Clay_Orange"
    },
    {
      "x": -9,
      "y": 77,
      "z": -4,
      "name": "Rock_Sandstone_Red"
    },
    {
      "x": -9,
      "y": 78,
      "z": -4,
      "name": "Rock_Sandstone_Red"
    },
    {
      "x": -9,
      "y": 79,
      "z": -4,
      "name": "Soil_Clay_Orange"
    },
    {
      "x": -9,
      "y": 80,
      "z": -4,
      "name": "Soil_Clay_Orange"
    },
    {
      "x": -9,
      "y": 81,
      "z": -4,
      "name": "Rock_Sandstone_Red"
    },
    {
      "x": -9,
      "y": 82,
      "z": -4,
      "name": "Rock_Sandstone_Red"
    },
    {
      "x": -9,
      "y": 83,
      "z": -4,
      "name": "Rock_Sandstone_Red"
    },
    {
      "x": -9,
      "y": 84,
      "z": -4,
      "name": "Rock_Sandstone_Red"
    },
    {
      "x": -9,
      "y": 85,
      "z": -4,
      "name": "Rock_Sandstone"
    },
    {
      "x": -9,
      "y": 86,
      "z": -4,
      "name": "Soil_Clay_Orange"
    },
    {
      "x": -9,
      "y": 87,
      "z": -4,
      "name": "Rock_Sandstone_Red"
    },
    {
      "x": -9,
      "y": 88,
      "z": -4,
      "name": "Soil_Clay_Orange"
    },
    {
      "x": -9,
      "y": 89,
      "z": -4,
      "name": "Rock_Sandstone_Red"
    },
    {
      "x": -9,
      "y": 90,
      "z": -4,
      "name": "Soil_Clay_Smooth_Red"
    },
    {
      "x": -9,
      "y": 73,
      "z": -3,
      "name": "Soil_Clay_Orange"
    },
    {
      "x": -9,
      "y": 74,
      "z": -3,
      "name": "Soil_Clay_Orange"
    },
    {
      "x": -9,
      "y": 75,
      "z": -3,
      "name": "Rock_Sandstone"
    },
    {
      "x": -9,
      "y": 76,
      "z": -3,
      "name": "Soil_Clay_Orange"
    },
    {
      "x": -9,
      "y": 77,
      "z": -3,
      "name": "Soil_Clay_Orange"
    },
    {
      "x": -9,
      "y": 78,
      "z": -3,
      "name": "Rock_Sandstone_Red"
    },
    {
      "x": -9,
      "y": 79,
      "z": -3,
      "name": "Soil_Clay_Orange"
    },
    {
      "x": -9,
      "y": 80,
      "z": -3,
      "name": "Soil_Clay_Orange"
    },
    {
      "x": -9,
      "y": 81,
      "z": -3,
      "name": "Rock_Sandstone_Red"
    },
    {
      "x": -9,
      "y": 82,
      "z": -3,
      "name": "Rock_Sandstone_Red"
    },
    {
      "x": -9,
      "y": 83,
      "z": -3,
      "name": "Rock_Sandstone_Red"
    },
    {
      "x": -9,
      "y": 84,
      "z": -3,
      "name": "Rock_Sandstone_Red"
    },
    {
      "x": -9,
      "y": 85,
      "z": -3,
      "name": "Rock_Sandstone"
    },
    {
      "x": -9,
      "y": 86,
      "z": -3,
      "name": "Rock_Sandstone"
    },
    {
      "x": -9,
      "y": 87,
      "z": -3,
      "name": "Soil_Clay_Orange"
    },
    {
      "x": -9,
      "y": 88,
      "z": -3,
      "name": "Soil_Clay_Orange"
    },
    {
      "x": -9,
      "y": 89,
      "z": -3,
      "name": "Rock_Sandstone_Red"
    },
    {
      "x": -9,
      "y": 90,
      "z": -3,
      "name": "Soil_Clay_Smooth_Red"
    },
    {
      "x": -9,
      "y": 73,
      "z": -2,
      "name": "Soil_Clay_Orange"
    },
    {
      "x": -9,
      "y": 74,
      "z": -2,
      "name": "Soil_Clay_Orange"
    },
    {
      "x": -9,
      "y": 75,
      "z": -2,
      "name": "Soil_Clay_Orange"
    },
    {
      "x": -9,
      "y": 76,
      "z": -2,
      "name": "Soil_Clay_Orange"
    },
    {
      "x": -9,
      "y": 77,
      "z": -2,
      "name": "Soil_Clay_Orange"
    },
    {
      "x": -9,
      "y": 78,
      "z": -2,
      "name": "Rock_Sandstone_Red"
    },
    {
      "x": -9,
      "y": 79,
      "z": -2,
      "name": "Soil_Clay_Orange"
    },
    {
      "x": -9,
      "y": 80,
      "z": -2,
      "name": "Soil_Clay_Orange"
    },
    {
      "x": -9,
      "y": 81,
      "z": -2,
      "name": "Rock_Sandstone_Red"
    },
    {
      "x": -9,
      "y": 82,
      "z": -2,
      "name": "Rock_Sandstone_Red"
    },
    {
      "x": -9,
      "y": 83,
      "z": -2,
      "name": "Rock_Sandstone_Red"
    },
    {
      "x": -9,
      "y": 84,
      "z": -2,
      "name": "Rock_Sandstone_Red"
    },
    {
      "x": -9,
      "y": 85,
      "z": -2,
      "name": "Rock_Sandstone"
    },
    {
      "x": -9,
      "y": 86,
      "z": -2,
      "name": "Rock_Sandstone"
    },
    {
      "x": -9,
      "y": 87,
      "z": -2,
      "name": "Rock_Sandstone_Red"
    },
    {
      "x": -9,
      "y": 88,
      "z": -2,
      "name": "Soil_Clay_Orange"
    },
    {
      "x": -9,
      "y": 89,
      "z": -2,
      "name": "Rock_Sandstone_Red"
    },
    {
      "x": -9,
      "y": 90,
      "z": -2,
      "name": "Soil_Clay_Smooth_Red"
    },
    {
      "x": -9,
      "y": 73,
      "z": -1,
      "name": "Rock_Sandstone_Red"
    },
    {
      "x": -9,
      "y": 74,
      "z": -1,
      "name": "Rock_Sandstone_Red"
    },
    {
      "x": -9,
      "y": 75,
      "z": -1,
      "name": "Soil_Clay_Orange"
    },
    {
      "x": -9,
      "y": 76,
      "z": -1,
      "name": "Soil_Clay_Orange"
    },
    {
      "x": -9,
      "y": 77,
      "z": -1,
      "name": "Soil_Clay_Orange"
    },
    {
      "x": -9,
      "y": 78,
      "z": -1,
      "name": "Soil_Clay_Orange"
    },
    {
      "x": -9,
      "y": 79,
      "z": -1,
      "name": "Soil_Clay_Orange"
    },
    {
      "x": -9,
      "y": 80,
      "z": -1,
      "name": "Soil_Clay_Orange"
    },
    {
      "x": -9,
      "y": 81,
      "z": -1,
      "name": "Rock_Sandstone_Red"
    },
    {
      "x": -9,
      "y": 82,
      "z": -1,
      "name": "Rock_Sandstone_Red"
    },
    {
      "x": -9,
      "y": 83,
      "z": -1,
      "name": "Rock_Sandstone_Red"
    },
    {
      "x": -9,
      "y": 84,
      "z": -1,
      "name": "Rock_Sandstone_Red"
    },
    {
      "x": -9,
      "y": 85,
      "z": -1,
      "name": "Rock_Sandstone"
    },
    {
      "x": -9,
      "y": 86,
      "z": -1,
      "name": "Rock_Sandstone"
    },
    {
      "x": -9,
      "y": 87,
      "z": -1,
      "name": "Rock_Sandstone_Red"
    },
    {
      "x": -9,
      "y": 88,
      "z": -1,
      "name": "Soil_Clay_Orange"
    },
    {
      "x": -9,
      "y": 89,
      "z": -1,
      "name": "Rock_Sandstone_Red"
    },
    {
      "x": -9,
      "y": 90,
      "z": -1,
      "name": "Soil_Clay_Smooth_Red"
    },
    {
      "x": -9,
      "y": 55,
      "z": 0,
      "name": "Rock_Sandstone"
    },
    {
      "x": -9,
      "y": 56,
      "z": 0,
      "name": "Soil_Clay_Orange"
    },
    {
      "x": -9,
      "y": 57,
      "z": 0,
      "name": "Soil_Clay_Orange"
    },
    {
      "x": -9,
      "y": 58,
      "z": 0,
      "name": "Rock_Sandstone"
    },
    {
      "x": -9,
      "y": 60,
      "z": 0,
      "name": "Rock_Sandstone"
    },
    {
      "x": -9,
      "y": 61,
      "z": 0,
      "name": "Rock_Sandstone_Red"
    },
    {
      "x": -9,
      "y": 62,
      "z": 0,
      "name": "Rock_Sandstone_Red"
    },
    {
      "x": -9,
      "y": 63,
      "z": 0,
      "name": "Rock_Sandstone_Red"
    },
    {
      "x": -9,
      "y": 64,
      "z": 0,
      "name": "Rock_Sandstone"
    },
    {
      "x": -9,
      "y": 65,
      "z": 0,
      "name": "Rock_Sandstone_Red"
    },
    {
      "x": -9,
      "y": 66,
      "z": 0,
      "name": "Rock_Sandstone_Red"
    },
    {
      "x": -9,
      "y": 67,
      "z": 0,
      "name": "Rock_Sandstone_Red"
    },
    {
      "x": -9,
      "y": 68,
      "z": 0,
      "name": "Rock_Sandstone_Red"
    },
    {
      "x": -9,
      "y": 69,
      "z": 0,
      "name": "Rock_Sandstone_Red"
    },
    {
      "x": -9,
      "y": 70,
      "z": 0,
      "name": "Rock_Sandstone_Red"
    },
    {
      "x": -9,
      "y": 71,
      "z": 0,
      "name": "Rock_Sandstone_Red"
    },
    {
      "x": -9,
      "y": 73,
      "z": 0,
      "name": "Rock_Sandstone_Red"
    },
    {
      "x": -9,
      "y": 74,
      "z": 0,
      "name": "Rock_Sandstone_Red"
    },
    {
      "x": -9,
      "y": 75,
      "z": 0,
      "name": "Rock_Sandstone_Red"
    },
    {
      "x": -9,
      "y": 76,
      "z": 0,
      "name": "Soil_Clay_Orange"
    },
    {
      "x": -9,
      "y": 77,
      "z": 0,
      "name": "Soil_Clay_Orange"
    },
    {
      "x": -9,
      "y": 78,
      "z": 0,
      "name": "Soil_Clay_Orange"
    },
    {
      "x": -9,
      "y": 79,
      "z": 0,
      "name": "Soil_Clay_Orange"
    },
    {
      "x": -9,
      "y": 80,
      "z": 0,
      "name": "Soil_Clay_Orange"
    },
    {
      "x": -9,
      "y": 81,
      "z": 0,
      "name": "Rock_Sandstone_Red"
    },
    {
      "x": -9,
      "y": 82,
      "z": 0,
      "name": "Rock_Sandstone_Red"
    },
    {
      "x": -9,
      "y": 83,
      "z": 0,
      "name": "Rock_Sandstone_Red"
    },
    {
      "x": -9,
      "y": 84,
      "z": 0,
      "name": "Rock_Sandstone_Red"
    },
    {
      "x": -9,
      "y": 85,
      "z": 0,
      "name": "Rock_Sandstone"
    },
    {
      "x": -9,
      "y": 86,
      "z": 0,
      "name": "Soil_Clay_Yellow"
    },
    {
      "x": -9,
      "y": 87,
      "z": 0,
      "name": "Soil_Clay_Orange"
    },
    {
      "x": -9,
      "y": 88,
      "z": 0,
      "name": "Soil_Clay_Orange"
    },
    {
      "x": -9,
      "y": 89,
      "z": 0,
      "name": "Rock_Sandstone_Red"
    },
    {
      "x": -9,
      "y": 90,
      "z": 0,
      "name": "Soil_Clay_Smooth_Red"
    },
    {
      "x": -9,
      "y": 55,
      "z": 1,
      "name": "Rock_Sandstone"
    },
    {
      "x": -9,
      "y": 56,
      "z": 1,
      "name": "Soil_Clay_Orange"
    },
    {
      "x": -9,
      "y": 57,
      "z": 1,
      "name": "Soil_Clay_Orange"
    },
    {
      "x": -9,
      "y": 58,
      "z": 1,
      "name": "Rock_Sandstone"
    },
    {
      "x": -9,
      "y": 59,
      "z": 1,
      "name": "Rock_Sandstone"
    },
    {
      "x": -9,
      "y": 60,
      "z": 1,
      "name": "Soil_Clay_Orange"
    },
    {
      "x": -9,
      "y": 61,
      "z": 1,
      "name": "Rock_Sandstone_Red"
    },
    {
      "x": -9,
      "y": 62,
      "z": 1,
      "name": "Rock_Sandstone_Red"
    },
    {
      "x": -9,
      "y": 63,
      "z": 1,
      "name": "Rock_Sandstone_Red"
    },
    {
      "x": -9,
      "y": 64,
      "z": 1,
      "name": "Rock_Sandstone"
    },
    {
      "x": -9,
      "y": 65,
      "z": 1,
      "name": "Rock_Sandstone_Red"
    },
    {
      "x": -9,
      "y": 66,
      "z": 1,
      "name": "Rock_Sandstone_Red"
    },
    {
      "x": -9,
      "y": 67,
      "z": 1,
      "name": "Rock_Sandstone_Red"
    },
    {
      "x": -9,
      "y": 68,
      "z": 1,
      "name": "Rock_Sandstone_Red"
    },
    {
      "x": -9,
      "y": 69,
      "z": 1,
      "name": "Rock_Sandstone_Red"
    },
    {
      "x": -9,
      "y": 70,
      "z": 1,
      "name": "Rock_Sandstone_Red"
    },
    {
      "x": -9,
      "y": 71,
      "z": 1,
      "name": "Rock_Sandstone_Red"
    },
    {
      "x": -9,
      "y": 73,
      "z": 1,
      "name": "Rock_Sandstone_Red"
    },
    {
      "x": -9,
      "y": 74,
      "z": 1,
      "name": "Rock_Sandstone_Red"
    },
    {
      "x": -9,
      "y": 75,
      "z": 1,
      "name": "Rock_Sandstone_Red"
    },
    {
      "x": -9,
      "y": 76,
      "z": 1,
      "name": "Soil_Clay_Orange"
    },
    {
      "x": -9,
      "y": 77,
      "z": 1,
      "name": "Soil_Clay_Orange"
    },
    {
      "x": -9,
      "y": 78,
      "z": 1,
      "name": "Soil_Clay_Orange"
    },
    {
      "x": -9,
      "y": 79,
      "z": 1,
      "name": "Soil_Clay_Orange"
    },
    {
      "x": -9,
      "y": 80,
      "z": 1,
      "name": "Soil_Clay_Orange"
    },
    {
      "x": -9,
      "y": 81,
      "z": 1,
      "name": "Rock_Sandstone_Red"
    },
    {
      "x": -9,
      "y": 82,
      "z": 1,
      "name": "Rock_Sandstone_Red"
    },
    {
      "x": -9,
      "y": 83,
      "z": 1,
      "name": "Rock_Sandstone_Red"
    },
    {
      "x": -9,
      "y": 84,
      "z": 1,
      "name": "Rock_Sandstone_Red"
    },
    {
      "x": -9,
      "y": 85,
      "z": 1,
      "name": "Rock_Sandstone_Red"
    },
    {
      "x": -9,
      "y": 86,
      "z": 1,
      "name": "Soil_Clay_Yellow"
    },
    {
      "x": -9,
      "y": 87,
      "z": 1,
      "name": "Soil_Clay_Orange"
    },
    {
      "x": -9,
      "y": 88,
      "z": 1,
      "name": "Soil_Clay_Orange"
    },
    {
      "x": -9,
      "y": 89,
      "z": 1,
      "name": "Rock_Sandstone_Red"
    },
    {
      "x": -9,
      "y": 90,
      "z": 1,
      "name": "Rock_Sandstone_Red"
    },
    {
      "x": -9,
      "y": 55,
      "z": 2,
      "name": "Rock_Sandstone"
    },
    {
      "x": -9,
      "y": 56,
      "z": 2,
      "name": "Soil_Clay_Orange"
    },
    {
      "x": -9,
      "y": 57,
      "z": 2,
      "name": "Soil_Clay_Orange"
    },
    {
      "x": -9,
      "y": 58,
      "z": 2,
      "name": "Soil_Clay_Orange"
    },
    {
      "x": -9,
      "y": 59,
      "z": 2,
      "name": "Rock_Sandstone"
    },
    {
      "x": -9,
      "y": 60,
      "z": 2,
      "name": "Soil_Clay_Orange"
    },
    {
      "x": -9,
      "y": 61,
      "z": 2,
      "name": "Rock_Sandstone_Red"
    },
    {
      "x": -9,
      "y": 62,
      "z": 2,
      "name": "Rock_Sandstone_Red"
    },
    {
      "x": -9,
      "y": 63,
      "z": 2,
      "name": "Rock_Sandstone_Red"
    },
    {
      "x": -9,
      "y": 64,
      "z": 2,
      "name": "Rock_Sandstone"
    },
    {
      "x": -9,
      "y": 65,
      "z": 2,
      "name": "Rock_Sandstone_Red"
    },
    {
      "x": -9,
      "y": 66,
      "z": 2,
      "name": "Rock_Sandstone_Red"
    },
    {
      "x": -9,
      "y": 67,
      "z": 2,
      "name": "Rock_Sandstone_Red"
    },
    {
      "x": -9,
      "y": 68,
      "z": 2,
      "name": "Rock_Sandstone_Red"
    },
    {
      "x": -9,
      "y": 69,
      "z": 2,
      "name": "Rock_Sandstone_Red"
    },
    {
      "x": -9,
      "y": 70,
      "z": 2,
      "name": "Rock_Sandstone_Red"
    },
    {
      "x": -9,
      "y": 71,
      "z": 2,
      "name": "Rock_Sandstone_Red"
    },
    {
      "x": -9,
      "y": 55,
      "z": 3,
      "name": "Rock_Sandstone"
    },
    {
      "x": -9,
      "y": 56,
      "z": 3,
      "name": "Rock_Sandstone"
    },
    {
      "x": -9,
      "y": 57,
      "z": 3,
      "name": "Soil_Clay_Orange"
    },
    {
      "x": -9,
      "y": 58,
      "z": 3,
      "name": "Soil_Clay_Orange"
    },
    {
      "x": -9,
      "y": 59,
      "z": 3,
      "name": "Rock_Sandstone"
    },
    {
      "x": -9,
      "y": 60,
      "z": 3,
      "name": "Soil_Clay_Orange"
    },
    {
      "x": -9,
      "y": 61,
      "z": 3,
      "name": "Rock_Sandstone_Red"
    },
    {
      "x": -9,
      "y": 62,
      "z": 3,
      "name": "Rock_Sandstone_Red"
    },
    {
      "x": -9,
      "y": 63,
      "z": 3,
      "name": "Rock_Sandstone_Red"
    },
    {
      "x": -9,
      "y": 64,
      "z": 3,
      "name": "Rock_Sandstone"
    },
    {
      "x": -9,
      "y": 65,
      "z": 3,
      "name": "Rock_Sandstone_Red"
    },
    {
      "x": -9,
      "y": 66,
      "z": 3,
      "name": "Rock_Sandstone_Red"
    },
    {
      "x": -9,
      "y": 67,
      "z": 3,
      "name": "Rock_Sandstone_Red"
    },
    {
      "x": -9,
      "y": 68,
      "z": 3,
      "name": "Rock_Sandstone_Red"
    },
    {
      "x": -9,
      "y": 69,
      "z": 3,
      "name": "Rock_Sandstone_Red"
    },
    {
      "x": -9,
      "y": 70,
      "z": 3,
      "name": "Rock_Sandstone_Red"
    },
    {
      "x": -9,
      "y": 71,
      "z": 3,
      "name": "Rock_Sandstone_Red"
    },
    {
      "x": -9,
      "y": 55,
      "z": 4,
      "name": "Rock_Sandstone"
    },
    {
      "x": -9,
      "y": 56,
      "z": 4,
      "name": "Rock_Sandstone"
    },
    {
      "x": -9,
      "y": 57,
      "z": 4,
      "name": "Soil_Clay_Orange"
    },
    {
      "x": -9,
      "y": 58,
      "z": 4,
      "name": "Soil_Clay_Orange"
    },
    {
      "x": -9,
      "y": 59,
      "z": 4,
      "name": "Rock_Sandstone"
    },
    {
      "x": -9,
      "y": 60,
      "z": 4,
      "name": "Rock_Sandstone"
    },
    {
      "x": -9,
      "y": 61,
      "z": 4,
      "name": "Rock_Sandstone_Red"
    },
    {
      "x": -9,
      "y": 62,
      "z": 4,
      "name": "Rock_Sandstone_Red"
    },
    {
      "x": -9,
      "y": 63,
      "z": 4,
      "name": "Rock_Sandstone_Red"
    },
    {
      "x": -9,
      "y": 64,
      "z": 4,
      "name": "Rock_Sandstone"
    },
    {
      "x": -9,
      "y": 65,
      "z": 4,
      "name": "Rock_Sandstone_Red"
    },
    {
      "x": -9,
      "y": 66,
      "z": 4,
      "name": "Rock_Sandstone_Red"
    },
    {
      "x": -9,
      "y": 67,
      "z": 4,
      "name": "Rock_Sandstone_Red"
    },
    {
      "x": -9,
      "y": 68,
      "z": 4,
      "name": "Rock_Sandstone_Red"
    },
    {
      "x": -9,
      "y": 69,
      "z": 4,
      "name": "Rock_Sandstone_Red"
    },
    {
      "x": -9,
      "y": 70,
      "z": 4,
      "name": "Rock_Sandstone_Red"
    },
    {
      "x": -9,
      "y": 71,
      "z": 4,
      "name": "Soil_Clay_Orange"
    },
    {
      "x": -9,
      "y": 79,
      "z": 7,
      "name": "Soil_Clay_Orange"
    },
    {
      "x": -9,
      "y": 80,
      "z": 7,
      "name": "Soil_Clay_Orange"
    },
    {
      "x": -9,
      "y": 81,
      "z": 7,
      "name": "Soil_Clay_Orange"
    },
    {
      "x": -9,
      "y": 82,
      "z": 7,
      "name": "Rock_Sandstone_Red"
    },
    {
      "x": -9,
      "y": 83,
      "z": 7,
      "name": "Rock_Sandstone_Red"
    },
    {
      "x": -9,
      "y": 84,
      "z": 7,
      "name": "Rock_Sandstone_Red"
    },
    {
      "x": -9,
      "y": 86,
      "z": 7,
      "name": "Rock_Sandstone"
    },
    {
      "x": -9,
      "y": 87,
      "z": 7,
      "name": "Rock_Sandstone"
    },
    {
      "x": -9,
      "y": 88,
      "z": 7,
      "name": "Soil_Clay_Orange"
    },
    {
      "x": -9,
      "y": 89,
      "z": 7,
      "name": "Soil_Clay_Orange"
    },
    {
      "x": -9,
      "y": 79,
      "z": 8,
      "name": "Rock_Sandstone"
    },
    {
      "x": -9,
      "y": 80,
      "z": 8,
      "name": "Soil_Clay_Orange"
    },
    {
      "x": -9,
      "y": 81,
      "z": 8,
      "name": "Soil_Clay_Orange"
    },
    {
      "x": -9,
      "y": 82,
      "z": 8,
      "name": "Rock_Sandstone_Red"
    },
    {
      "x": -9,
      "y": 83,
      "z": 8,
      "name": "Rock_Sandstone_Red"
    },
    {
      "x": -9,
      "y": 84,
      "z": 8,
      "name": "Rock_Sandstone_Red"
    },
    {
      "x": -9,
      "y": 87,
      "z": 8,
      "name": "Rock_Sandstone"
    },
    {
      "x": -9,
      "y": 88,
      "z": 8,
      "name": "Soil_Clay_Orange"
    },
    {
      "x": -9,
      "y": 90,
      "z": 8,
      "name": "Rock_Sandstone"
    },
    {
      "x": -8,
      "y": 24,
      "z": -8,
      "name": "Rock_Sandstone_Red"
    },
    {
      "x": -8,
      "y": 25,
      "z": -8,
      "name": "Rock_Sandstone_Red"
    },
    {
      "x": -8,
      "y": 60,
      "z": -8,
      "name": "Rock_Sandstone_Red"
    },
    {
      "x": -8,
      "y": 61,
      "z": -8,
      "name": "Rock_Sandstone_Red"
    },
    {
      "x": -8,
      "y": 62,
      "z": -8,
      "name": "Rock_Sandstone_Red"
    },
    {
      "x": -8,
      "y": 63,
      "z": -8,
      "name": "Rock_Sandstone"
    },
    {
      "x": -8,
      "y": 64,
      "z": -8,
      "name": "Soil_Clay_Orange"
    },
    {
      "x": -8,
      "y": 65,
      "z": -8,
      "name": "Rock_Sandstone_Red"
    },
    {
      "x": -8,
      "y": 66,
      "z": -8,
      "name": "Rock_Sandstone_Red"
    },
    {
      "x": -8,
      "y": 67,
      "z": -8,
      "name": "Soil_Clay_Orange"
    },
    {
      "x": -8,
      "y": 71,
      "z": -8,
      "name": "Soil_Clay_Orange"
    },
    {
      "x": -8,
      "y": 23,
      "z": -7,
      "name": "Rock_Sandstone_Red"
    },
    {
      "x": -8,
      "y": 24,
      "z": -7,
      "name": "Rock_Sandstone_Red"
    },
    {
      "x": -8,
      "y": 25,
      "z": -7,
      "name": "Rock_Sandstone_Red"
    },
    {
      "x": -8,
      "y": 26,
      "z": -7,
      "name": "Soil_Clay_Smooth_Red"
    },
    {
      "x": -8,
      "y": 47,
      "z": -7,
      "name": "Rock_Sandstone"
    },
    {
      "x": -8,
      "y": 48,
      "z": -7,
      "name": "Soil_Clay_Orange"
    },
    {
      "x": -8,
      "y": 49,
      "z": -7,
      "name": "Soil_Clay_Orange"
    },
    {
      "x": -8,
      "y": 60,
      "z": -7,
      "name": "Rock_Sandstone_Red"
    },
    {
      "x": -8,
      "y": 61,
      "z": -7,
      "name": "Rock_Sandstone_Red"
    },
    {
      "x": -8,
      "y": 62,
      "z": -7,
      "name": "Rock_Sandstone_Red"
    },
    {
      "x": -8,
      "y": 63,
      "z": -7,
      "name": "Rock_Sandstone"
    },
    {
      "x": -8,
      "y": 64,
      "z": -7,
      "name": "Soil_Clay_Orange"
    },
    {
      "x": -8,
      "y": 65,
      "z": -7,
      "name": "Rock_Sandstone_Red"
    },
    {
      "x": -8,
      "y": 66,
      "z": -7,
      "name": "Rock_Sandstone_Red"
    },
    {
      "x": -8,
      "y": 67,
      "z": -7,
      "name": "Rock_Sandstone_Red"
    },
    {
      "x": -8,
      "y": 70,
      "z": -7,
      "name": "Rock_Sandstone_Red"
    },
    {
      "x": -8,
      "y": 74,
      "z": -7,
      "name": "Rock_Sandstone"
    },
    {
      "x": -8,
      "y": 75,
      "z": -7,
      "name": "Soil_Clay_Yellow"
    },
    {
      "x": -8,
      "y": 76,
      "z": -7,
      "name": "Rock_Sandstone_Red"
    },
    {
      "x": -8,
      "y": 77,
      "z": -7,
      "name": "Rock_Sandstone_Red"
    },
    {
      "x": -8,
      "y": 78,
      "z": -7,
      "name": "Rock_Sandstone_Red"
    },
    {
      "x": -8,
      "y": 79,
      "z": -7,
      "name": "Rock_Sandstone_Red"
    },
    {
      "x": -8,
      "y": 80,
      "z": -7,
      "name": "Rock_Sandstone_Red"
    },
    {
      "x": -8,
      "y": 81,
      "z": -7,
      "name": "Rock_Sandstone_Red"
    },
    {
      "x": -8,
      "y": 82,
      "z": -7,
      "name": "Rock_Sandstone_Red"
    },
    {
      "x": -8,
      "y": 83,
      "z": -7,
      "name": "Rock_Sandstone_Red"
    },
    {
      "x": -8,
      "y": 84,
      "z": -7,
      "name": "Rock_Sandstone_Red"
    },
    {
      "x": -8,
      "y": 85,
      "z": -7,
      "name": "Rock_Sandstone"
    },
    {
      "x": -8,
      "y": 86,
      "z": -7,
      "name": "Rock_Sandstone_Red"
    },
    {
      "x": -8,
      "y": 87,
      "z": -7,
      "name": "Rock_Sandstone_Red"
    },
    {
      "x": -8,
      "y": 88,
      "z": -7,
      "name": "Rock_Sandstone_Red"
    },
    {
      "x": -8,
      "y": 89,
      "z": -7,
      "name": "Rock_Sandstone_Red"
    },
    {
      "x": -8,
      "y": 23,
      "z": -6,
      "name": "Rock_Sandstone_Red"
    },
    {
      "x": -8,
      "y": 24,
      "z": -6,
      "name": "Rock_Sandstone_Red"
    },
    {
      "x": -8,
      "y": 25,
      "z": -6,
      "name": "Rock_Sandstone_Red"
    },
    {
      "x": -8,
      "y": 26,
      "z": -6,
      "name": "Soil_Clay_Smooth_Red"
    },
    {
      "x": -8,
      "y": 74,
      "z": -6,
      "name": "Rock_Sandstone"
    },
    {
      "x": -8,
      "y": 75,
      "z": -6,
      "name": "Rock_Sandstone"
    },
    {
      "x": -8,
      "y": 76,
      "z": -6,
      "name": "Rock_Sandstone_Red"
    },
    {
      "x": -8,
      "y": 77,
      "z": -6,
      "name": "Rock_Sandstone_Red"
    },
    {
      "x": -8,
      "y": 78,
      "z": -6,
      "name": "Rock_Sandstone_Red"
    },
    {
      "x": -8,
      "y": 79,
      "z": -6,
      "name": "Rock_Sandstone_Red"
    },
    {
      "x": -8,
      "y": 80,
      "z": -6,
      "name": "Soil_Clay_Orange"
    },
    {
      "x": -8,
      "y": 81,
      "z": -6,
      "name": "Rock_Sandstone_Red"
    },
    {
      "x": -8,
      "y": 82,
      "z": -6,
      "name": "Rock_Sandstone_Red"
    },
    {
      "x": -8,
      "y": 83,
      "z": -6,
      "name": "Rock_Sandstone_Red"
    },
    {
      "x": -8,
      "y": 84,
      "z": -6,
      "name": "Rock_Sandstone_Red"
    },
    {
      "x": -8,
      "y": 85,
      "z": -6,
      "name": "Rock_Sandstone"
    },
    {
      "x": -8,
      "y": 86,
      "z": -6,
      "name": "Rock_Sandstone_Red"
    },
    {
      "x": -8,
      "y": 87,
      "z": -6,
      "name": "Rock_Sandstone_Red"
    },
    {
      "x": -8,
      "y": 88,
      "z": -6,
      "name": "Rock_Sandstone_Red"
    },
    {
      "x": -8,
      "y": 89,
      "z": -6,
      "name": "Rock_Sandstone_Red"
    },
    {
      "x": -8,
      "y": 90,
      "z": -6,
      "name": "Soil_Clay_Smooth_Red"
    },
    {
      "x": -8,
      "y": 24,
      "z": -5,
      "name": "Rock_Sandstone_Red"
    },
    {
      "x": -8,
      "y": 25,
      "z": -5,
      "name": "Rock_Sandstone_Red"
    },
    {
      "x": -8,
      "y": 73,
      "z": -5,
      "name": "Soil_Clay_Orange"
    },
    {
      "x": -8,
      "y": 74,
      "z": -5,
      "name": "Soil_Clay_Orange"
    },
    {
      "x": -8,
      "y": 75,
      "z": -5,
      "name": "Rock_Sandstone"
    },
    {
      "x": -8,
      "y": 76,
      "z": -5,
      "name": "Rock_Sandstone_Red"
    },
    {
      "x": -8,
      "y": 77,
      "z": -5,
      "name": "Rock_Sandstone_Red"
    },
    {
      "x": -8,
      "y": 78,
      "z": -5,
      "name": "Rock_Sandstone_Red"
    },
    {
      "x": -8,
      "y": 79,
      "z": -5,
      "name": "Rock_Sandstone_Red"
    },
    {
      "x": -8,
      "y": 80,
      "z": -5,
      "name": "Rock_Sandstone_Red"
    },
    {
      "x": -8,
      "y": 81,
      "z": -5,
      "name": "Rock_Sandstone_Red"
    },
    {
      "x": -8,
      "y": 82,
      "z": -5,
      "name": "Rock_Sandstone_Red"
    },
    {
      "x": -8,
      "y": 83,
      "z": -5,
      "name": "Rock_Sandstone_Red"
    },
    {
      "x": -8,
      "y": 84,
      "z": -5,
      "name": "Rock_Sandstone_Red"
    },
    {
      "x": -8,
      "y": 85,
      "z": -5,
      "name": "Rock_Sandstone"
    },
    {
      "x": -8,
      "y": 86,
      "z": -5,
      "name": "Rock_Sandstone_Red"
    },
    {
      "x": -8,
      "y": 87,
      "z": -5,
      "name": "Rock_Sandstone_Red"
    },
    {
      "x": -8,
      "y": 88,
      "z": -5,
      "name": "Rock_Sandstone_Red"
    },
    {
      "x": -8,
      "y": 89,
      "z": -5,
      "name": "Rock_Sandstone_Red"
    },
    {
      "x": -8,
      "y": 90,
      "z": -5,
      "name": "Soil_Clay_Smooth_Red"
    },
    {
      "x": -8,
      "y": 24,
      "z": -4,
      "name": "Rock_Sandstone_Red"
    },
    {
      "x": -8,
      "y": 25,
      "z": -4,
      "name": "Soil_Clay_Orange"
    },
    {
      "x": -8,
      "y": 30,
      "z": -4,
      "name": "Soil_Clay_Orange"
    },
    {
      "x": -8,
      "y": 31,
      "z": -4,
      "name": "Rock_Sandstone_Red"
    },
    {
      "x": -8,
      "y": 32,
      "z": -4,
      "name": "Rock_Sandstone_Red"
    },
    {
      "x": -8,
      "y": 33,
      "z": -4,
      "name": "Rock_Sandstone_Red"
    },
    {
      "x": -8,
      "y": 34,
      "z": -4,
      "name": "Rock_Sandstone"
    },
    {
      "x": -8,
      "y": 35,
      "z": -4,
      "name": "Rock_Sandstone_Red"
    },
    {
      "x": -8,
      "y": 36,
      "z": -4,
      "name": "Rock_Sandstone_Red"
    },
    {
      "x": -8,
      "y": 37,
      "z": -4,
      "name": "Soil_Clay_Orange"
    },
    {
      "x": -8,
      "y": 73,
      "z": -4,
      "name": "Rock_Sandstone_Red"
    },
    {
      "x": -8,
      "y": 74,
      "z": -4,
      "name": "Soil_Clay_Orange"
    },
    {
      "x": -8,
      "y": 75,
      "z": -4,
      "name": "Rock_Sandstone"
    },
    {
      "x": -8,
      "y": 76,
      "z": -4,
      "name": "Rock_Sandstone_Red"
    },
    {
      "x": -8,
      "y": 77,
      "z": -4,
      "name": "Rock_Sandstone_Red"
    },
    {
      "x": -8,
      "y": 78,
      "z": -4,
      "name": "Rock_Sandstone_Red"
    },
    {
      "x": -8,
      "y": 79,
      "z": -4,
      "name": "Rock_Sandstone_Red"
    },
    {
      "x": -8,
      "y": 80,
      "z": -4,
      "name": "Rock_Sandstone_Red"
    },
    {
      "x": -8,
      "y": 81,
      "z": -4,
      "name": "Rock_Sandstone_Red"
    },
    {
      "x": -8,
      "y": 82,
      "z": -4,
      "name": "Rock_Sandstone_Red"
    },
    {
      "x": -8,
      "y": 83,
      "z": -4,
      "name": "Rock_Sandstone_Red"
    },
    {
      "x": -8,
      "y": 84,
      "z": -4,
      "name": "Rock_Sandstone_Red"
    },
    {
      "x": -8,
      "y": 85,
      "z": -4,
      "name": "Rock_Sandstone"
    },
    {
      "x": -8,
      "y": 86,
      "z": -4,
      "name": "Rock_Sandstone_Red"
    },
    {
      "x": -8,
      "y": 87,
      "z": -4,
      "name": "Rock_Sandstone_Red"
    },
    {
      "x": -8,
      "y": 88,
      "z": -4,
      "name": "Rock_Sandstone_Red"
    },
    {
      "x": -8,
      "y": 89,
      "z": -4,
      "name": "Rock_Sandstone_Red"
    },
    {
      "x": -8,
      "y": 90,
      "z": -4,
      "name": "Soil_Clay_Smooth_Red"
    },
    {
      "x": -8,
      "y": 30,
      "z": -3,
      "name": "Soil_Clay_Orange"
    },
    {
      "x": -8,
      "y": 31,
      "z": -3,
      "name": "Rock_Sandstone_Red"
    },
    {
      "x": -8,
      "y": 32,
      "z": -3,
      "name": "Rock_Sandstone_Red"
    },
    {
      "x": -8,
      "y": 33,
      "z": -3,
      "name": "Rock_Sandstone_Red"
    },
    {
      "x": -8,
      "y": 34,
      "z": -3,
      "name": "Rock_Sandstone"
    },
    {
      "x": -8,
      "y": 35,
      "z": -3,
      "name": "Rock_Sandstone_Red"
    },
    {
      "x": -8,
      "y": 36,
      "z": -3,
      "name": "Rock_Sandstone_Red"
    },
    {
      "x": -8,
      "y": 37,
      "z": -3,
      "name": "Soil_Clay_Orange"
    },
    {
      "x": -8,
      "y": 38,
      "z": -3,
      "name": "Rock_Sandstone"
    },
    {
      "x": -8,
      "y": 39,
      "z": -3,
      "name": "Rock_Sandstone_Red"
    },
    {
      "x": -8,
      "y": 40,
      "z": -3,
      "name": "Soil_Clay_Smooth_Red"
    },
    {
      "x": -8,
      "y": 73,
      "z": -3,
      "name": "Rock_Sandstone_Red"
    },
    {
      "x": -8,
      "y": 74,
      "z": -3,
      "name": "Soil_Clay_Orange"
    },
    {
      "x": -8,
      "y": 75,
      "z": -3,
      "name": "Rock_Sandstone"
    },
    {
      "x": -8,
      "y": 76,
      "z": -3,
      "name": "Soil_Clay_Orange"
    },
    {
      "x": -8,
      "y": 77,
      "z": -3,
      "name": "Rock_Sandstone_Red"
    },
    {
      "x": -8,
      "y": 78,
      "z": -3,
      "name": "Rock_Sandstone_Red"
    },
    {
      "x": -8,
      "y": 79,
      "z": -3,
      "name": "Rock_Sandstone_Red"
    },
    {
      "x": -8,
      "y": 80,
      "z": -3,
      "name": "Rock_Sandstone_Red"
    },
    {
      "x": -8,
      "y": 81,
      "z": -3,
      "name": "Rock_Sandstone_Red"
    },
    {
      "x": -8,
      "y": 82,
      "z": -3,
      "name": "Rock_Sandstone_Red"
    },
    {
      "x": -8,
      "y": 83,
      "z": -3,
      "name": "Rock_Sandstone_Red"
    },
    {
      "x": -8,
      "y": 84,
      "z": -3,
      "name": "Rock_Sandstone_Red"
    },
    {
      "x": -8,
      "y": 85,
      "z": -3,
      "name": "Rock_Sandstone"
    },
    {
      "x": -8,
      "y": 86,
      "z": -3,
      "name": "Rock_Sandstone"
    },
    {
      "x": -8,
      "y": 87,
      "z": -3,
      "name": "Rock_Sandstone_Red"
    },
    {
      "x": -8,
      "y": 88,
      "z": -3,
      "name": "Soil_Clay_Orange"
    },
    {
      "x": -8,
      "y": 89,
      "z": -3,
      "name": "Rock_Sandstone_Red"
    },
    {
      "x": -8,
      "y": 90,
      "z": -3,
      "name": "Soil_Clay_Smooth_Red"
    },
    {
      "x": -8,
      "y": 30,
      "z": -2,
      "name": "Soil_Clay_Orange"
    },
    {
      "x": -8,
      "y": 31,
      "z": -2,
      "name": "Rock_Sandstone_Red"
    },
    {
      "x": -8,
      "y": 32,
      "z": -2,
      "name": "Rock_Sandstone_Red"
    },
    {
      "x": -8,
      "y": 33,
      "z": -2,
      "name": "Rock_Sandstone_Red"
    },
    {
      "x": -8,
      "y": 34,
      "z": -2,
      "name": "Rock_Sandstone"
    },
    {
      "x": -8,
      "y": 35,
      "z": -2,
      "name": "Rock_Sandstone_Red"
    },
    {
      "x": -8,
      "y": 36,
      "z": -2,
      "name": "Rock_Sandstone_Red"
    },
    {
      "x": -8,
      "y": 37,
      "z": -2,
      "name": "Soil_Clay_Orange"
    },
    {
      "x": -8,
      "y": 38,
      "z": -2,
      "name": "Rock_Sandstone"
    },
    {
      "x": -8,
      "y": 39,
      "z": -2,
      "name": "Rock_Sandstone_Red"
    },
    {
      "x": -8,
      "y": 40,
      "z": -2,
      "name": "Soil_Clay_Smooth_Red"
    },
    {
      "x": -8,
      "y": 73,
      "z": -2,
      "name": "Rock_Sandstone_Red"
    },
    {
      "x": -8,
      "y": 74,
      "z": -2,
      "name": "Soil_Clay_Orange"
    },
    {
      "x": -8,
      "y": 75,
      "z": -2,
      "name": "Soil_Clay_Orange"
    },
    {
      "x": -8,
      "y": 76,
      "z": -2,
      "name": "Soil_Clay_Orange"
    },
    {
      "x": -8,
      "y": 77,
      "z": -2,
      "name": "Rock_Sandstone_Red"
    },
    {
      "x": -8,
      "y": 78,
      "z": -2,
      "name": "Rock_Sandstone_Red"
    },
    {
      "x": -8,
      "y": 79,
      "z": -2,
      "name": "Rock_Sandstone_Red"
    },
    {
      "x": -8,
      "y": 80,
      "z": -2,
      "name": "Rock_Sandstone_Red"
    },
    {
      "x": -8,
      "y": 81,
      "z": -2,
      "name": "Rock_Sandstone_Red"
    },
    {
      "x": -8,
      "y": 82,
      "z": -2,
      "name": "Rock_Sandstone_Red"
    },
    {
      "x": -8,
      "y": 83,
      "z": -2,
      "name": "Rock_Sandstone_Red"
    },
    {
      "x": -8,
      "y": 84,
      "z": -2,
      "name": "Rock_Sandstone_Red"
    },
    {
      "x": -8,
      "y": 85,
      "z": -2,
      "name": "Rock_Sandstone"
    },
    {
      "x": -8,
      "y": 86,
      "z": -2,
      "name": "Rock_Sandstone"
    },
    {
      "x": -8,
      "y": 87,
      "z": -2,
      "name": "Rock_Sandstone_Red"
    },
    {
      "x": -8,
      "y": 88,
      "z": -2,
      "name": "Rock_Sandstone_Red"
    },
    {
      "x": -8,
      "y": 89,
      "z": -2,
      "name": "Rock_Sandstone_Red"
    },
    {
      "x": -8,
      "y": 90,
      "z": -2,
      "name": "Rock_Sandstone_Red"
    },
    {
      "x": -8,
      "y": 91,
      "z": -2,
      "name": "Soil_Clay_Smooth_Red"
    },
    {
      "x": -8,
      "y": 30,
      "z": -1,
      "name": "Soil_Clay_Orange"
    },
    {
      "x": -8,
      "y": 31,
      "z": -1,
      "name": "Soil_Clay_Orange"
    },
    {
      "x": -8,
      "y": 32,
      "z": -1,
      "name": "Rock_Sandstone_Red"
    },
    {
      "x": -8,
      "y": 33,
      "z": -1,
      "name": "Rock_Sandstone_Red"
    },
    {
      "x": -8,
      "y": 34,
      "z": -1,
      "name": "Rock_Sandstone_Red"
    },
    {
      "x": -8,
      "y": 35,
      "z": -1,
      "name": "Rock_Sandstone_Red"
    },
    {
      "x": -8,
      "y": 36,
      "z": -1,
      "name": "Rock_Sandstone_Red"
    },
    {
      "x": -8,
      "y": 37,
      "z": -1,
      "name": "Soil_Clay_Orange"
    },
    {
      "x": -8,
      "y": 38,
      "z": -1,
      "name": "Rock_Sandstone"
    },
    {
      "x": -8,
      "y": 39,
      "z": -1,
      "name": "Soil_Clay_Orange"
    },
    {
      "x": -8,
      "y": 55,
      "z": -1,
      "name": "Soil_Clay_Orange"
    },
    {
      "x": -8,
      "y": 56,
      "z": -1,
      "name": "Soil_Clay_Orange"
    },
    {
      "x": -8,
      "y": 57,
      "z": -1,
      "name": "Rock_Sandstone"
    },
    {
      "x": -8,
      "y": 58,
      "z": -1,
      "name": "Rock_Sandstone"
    },
    {
      "x": -8,
      "y": 60,
      "z": -1,
      "name": "Rock_Sandstone_Red"
    },
    {
      "x": -8,
      "y": 61,
      "z": -1,
      "name": "Rock_Sandstone_Red"
    },
    {
      "x": -8,
      "y": 62,
      "z": -1,
      "name": "Rock_Sandstone_Red"
    },
    {
      "x": -8,
      "y": 63,
      "z": -1,
      "name": "Rock_Sandstone_Red"
    },
    {
      "x": -8,
      "y": 64,
      "z": -1,
      "name": "Soil_Clay_Orange"
    },
    {
      "x": -8,
      "y": 65,
      "z": -1,
      "name": "Rock_Sandstone_Red"
    },
    {
      "x": -8,
      "y": 66,
      "z": -1,
      "name": "Rock_Sandstone_Red"
    },
    {
      "x": -8,
      "y": 67,
      "z": -1,
      "name": "Rock_Sandstone_Red"
    },
    {
      "x": -8,
      "y": 68,
      "z": -1,
      "name": "Rock_Sandstone_Red"
    },
    {
      "x": -8,
      "y": 69,
      "z": -1,
      "name": "Rock_Sandstone_Red"
    },
    {
      "x": -8,
      "y": 70,
      "z": -1,
      "name": "Rock_Sandstone_Red"
    },
    {
      "x": -8,
      "y": 71,
      "z": -1,
      "name": "Rock_Sandstone_Red"
    },
    {
      "x": -8,
      "y": 73,
      "z": -1,
      "name": "Rock_Sandstone_Red"
    },
    {
      "x": -8,
      "y": 74,
      "z": -1,
      "name": "Rock_Sandstone_Red"
    },
    {
      "x": -8,
      "y": 75,
      "z": -1,
      "name": "Soil_Clay_Orange"
    },
    {
      "x": -8,
      "y": 76,
      "z": -1,
      "name": "Soil_Clay_Orange"
    },
    {
      "x": -8,
      "y": 77,
      "z": -1,
      "name": "Soil_Clay_Orange"
    },
    {
      "x": -8,
      "y": 78,
      "z": -1,
      "name": "Rock_Sandstone_Red"
    },
    {
      "x": -8,
      "y": 79,
      "z": -1,
      "name": "Soil_Clay_Orange"
    },
    {
      "x": -8,
      "y": 80,
      "z": -1,
      "name": "Rock_Sandstone_Red"
    },
    {
      "x": -8,
      "y": 81,
      "z": -1,
      "name": "Rock_Sandstone_Red"
    },
    {
      "x": -8,
      "y": 82,
      "z": -1,
      "name": "Rock_Sandstone_Red"
    },
    {
      "x": -8,
      "y": 83,
      "z": -1,
      "name": "Rock_Sandstone_Red"
    },
    {
      "x": -8,
      "y": 84,
      "z": -1,
      "name": "Rock_Sandstone_Red"
    },
    {
      "x": -8,
      "y": 85,
      "z": -1,
      "name": "Rock_Sandstone"
    },
    {
      "x": -8,
      "y": 86,
      "z": -1,
      "name": "Rock_Sandstone"
    },
    {
      "x": -8,
      "y": 87,
      "z": -1,
      "name": "Rock_Sandstone_Red"
    },
    {
      "x": -8,
      "y": 88,
      "z": -1,
      "name": "Rock_Sandstone_Red"
    },
    {
      "x": -8,
      "y": 89,
      "z": -1,
      "name": "Rock_Sandstone_Red"
    },
    {
      "x": -8,
      "y": 90,
      "z": -1,
      "name": "Rock_Sandstone_Red"
    },
    {
      "x": -8,
      "y": 91,
      "z": -1,
      "name": "Soil_Clay_Smooth_Red"
    },
    {
      "x": -8,
      "y": 30,
      "z": 0,
      "name": "Soil_Clay_Orange"
    },
    {
      "x": -8,
      "y": 31,
      "z": 0,
      "name": "Soil_Clay_Orange"
    },
    {
      "x": -8,
      "y": 32,
      "z": 0,
      "name": "Rock_Sandstone_Red"
    },
    {
      "x": -8,
      "y": 33,
      "z": 0,
      "name": "Rock_Sandstone_Red"
    },
    {
      "x": -8,
      "y": 34,
      "z": 0,
      "name": "Rock_Sandstone_Red"
    },
    {
      "x": -8,
      "y": 35,
      "z": 0,
      "name": "Rock_Sandstone_Red"
    },
    {
      "x": -8,
      "y": 36,
      "z": 0,
      "name": "Rock_Sandstone_Red"
    },
    {
      "x": -8,
      "y": 37,
      "z": 0,
      "name": "Soil_Clay_Orange"
    },
    {
      "x": -8,
      "y": 38,
      "z": 0,
      "name": "Soil_Clay_Orange"
    },
    {
      "x": -8,
      "y": 39,
      "z": 0,
      "name": "Soil_Clay_Orange"
    },
    {
      "x": -8,
      "y": 54,
      "z": 0,
      "name": "Rock_Sandstone"
    },
    {
      "x": -8,
      "y": 55,
      "z": 0,
      "name": "Rock_Sandstone"
    },
    {
      "x": -8,
      "y": 56,
      "z": 0,
      "name": "Soil_Clay_Orange"
    },
    {
      "x": -8,
      "y": 57,
      "z": 0,
      "name": "Rock_Sandstone"
    },
    {
      "x": -8,
      "y": 58,
      "z": 0,
      "name": "Rock_Sandstone"
    },
    {
      "x": -8,
      "y": 59,
      "z": 0,
      "name": "Soil_Clay_Orange"
    },
    {
      "x": -8,
      "y": 60,
      "z": 0,
      "name": "Rock_Sandstone_Red"
    },
    {
      "x": -8,
      "y": 61,
      "z": 0,
      "name": "Rock_Sandstone_Red"
    },
    {
      "x": -8,
      "y": 62,
      "z": 0,
      "name": "Rock_Sandstone_Red"
    },
    {
      "x": -8,
      "y": 63,
      "z": 0,
      "name": "Rock_Sandstone_Red"
    },
    {
      "x": -8,
      "y": 64,
      "z": 0,
      "name": "Rock_Sandstone"
    },
    {
      "x": -8,
      "y": 65,
      "z": 0,
      "name": "Rock_Sandstone_Red"
    },
    {
      "x": -8,
      "y": 66,
      "z": 0,
      "name": "Rock_Sandstone_Red"
    },
    {
      "x": -8,
      "y": 67,
      "z": 0,
      "name": "Rock_Sandstone_Red"
    },
    {
      "x": -8,
      "y": 68,
      "z": 0,
      "name": "Rock_Sandstone_Red"
    },
    {
      "x": -8,
      "y": 69,
      "z": 0,
      "name": "Rock_Sandstone_Red"
    },
    {
      "x": -8,
      "y": 70,
      "z": 0,
      "name": "Rock_Sandstone_Red"
    },
    {
      "x": -8,
      "y": 71,
      "z": 0,
      "name": "Rock_Sandstone_Red"
    },
    {
      "x": -8,
      "y": 73,
      "z": 0,
      "name": "Rock_Sandstone_Red"
    },
    {
      "x": -8,
      "y": 74,
      "z": 0,
      "name": "Rock_Sandstone_Red"
    },
    {
      "x": -8,
      "y": 75,
      "z": 0,
      "name": "Soil_Clay_Orange"
    },
    {
      "x": -8,
      "y": 76,
      "z": 0,
      "name": "Soil_Clay_Orange"
    },
    {
      "x": -8,
      "y": 77,
      "z": 0,
      "name": "Soil_Clay_Orange"
    },
    {
      "x": -8,
      "y": 78,
      "z": 0,
      "name": "Rock_Sandstone_Red"
    },
    {
      "x": -8,
      "y": 79,
      "z": 0,
      "name": "Soil_Clay_Orange"
    },
    {
      "x": -8,
      "y": 80,
      "z": 0,
      "name": "Rock_Sandstone_Red"
    },
    {
      "x": -8,
      "y": 81,
      "z": 0,
      "name": "Rock_Sandstone_Red"
    },
    {
      "x": -8,
      "y": 82,
      "z": 0,
      "name": "Rock_Sandstone_Red"
    },
    {
      "x": -8,
      "y": 83,
      "z": 0,
      "name": "Rock_Sandstone_Red"
    },
    {
      "x": -8,
      "y": 84,
      "z": 0,
      "name": "Rock_Sandstone_Red"
    },
    {
      "x": -8,
      "y": 85,
      "z": 0,
      "name": "Rock_Sandstone_Red"
    },
    {
      "x": -8,
      "y": 86,
      "z": 0,
      "name": "Soil_Clay_Yellow"
    },
    {
      "x": -8,
      "y": 87,
      "z": 0,
      "name": "Rock_Sandstone_Red"
    },
    {
      "x": -8,
      "y": 88,
      "z": 0,
      "name": "Soil_Clay_Orange"
    },
    {
      "x": -8,
      "y": 89,
      "z": 0,
      "name": "Rock_Sandstone_Red"
    },
    {
      "x": -8,
      "y": 90,
      "z": 0,
      "name": "Soil_Clay_Smooth_Red"
    },
    {
      "x": -8,
      "y": 54,
      "z": 1,
      "name": "Rock_Sandstone"
    },
    {
      "x": -8,
      "y": 55,
      "z": 1,
      "name": "Rock_Sandstone"
    },
    {
      "x": -8,
      "y": 56,
      "z": 1,
      "name": "Soil_Clay_Orange"
    },
    {
      "x": -8,
      "y": 57,
      "z": 1,
      "name": "Rock_Sandstone"
    },
    {
      "x": -8,
      "y": 58,
      "z": 1,
      "name": "Rock_Sandstone"
    },
    {
      "x": -8,
      "y": 59,
      "z": 1,
      "name": "Soil_Clay_Orange"
    },
    {
      "x": -8,
      "y": 60,
      "z": 1,
      "name": "Soil_Clay_Orange"
    },
    {
      "x": -8,
      "y": 61,
      "z": 1,
      "name": "Rock_Sandstone_Red"
    },
    {
      "x": -8,
      "y": 62,
      "z": 1,
      "name": "Rock_Sandstone_Red"
    },
    {
      "x": -8,
      "y": 63,
      "z": 1,
      "name": "Rock_Sandstone_Red"
    },
    {
      "x": -8,
      "y": 64,
      "z": 1,
      "name": "Rock_Sandstone"
    },
    {
      "x": -8,
      "y": 65,
      "z": 1,
      "name": "Rock_Sandstone_Red"
    },
    {
      "x": -8,
      "y": 66,
      "z": 1,
      "name": "Rock_Sandstone_Red"
    },
    {
      "x": -8,
      "y": 67,
      "z": 1,
      "name": "Rock_Sandstone_Red"
    },
    {
      "x": -8,
      "y": 68,
      "z": 1,
      "name": "Rock_Sandstone_Red"
    },
    {
      "x": -8,
      "y": 69,
      "z": 1,
      "name": "Rock_Sandstone_Red"
    },
    {
      "x": -8,
      "y": 70,
      "z": 1,
      "name": "Rock_Sandstone_Red"
    },
    {
      "x": -8,
      "y": 71,
      "z": 1,
      "name": "Rock_Sandstone_Red"
    },
    {
      "x": -8,
      "y": 73,
      "z": 1,
      "name": "Rock_Sandstone_Red"
    },
    {
      "x": -8,
      "y": 74,
      "z": 1,
      "name": "Rock_Sandstone_Red"
    },
    {
      "x": -8,
      "y": 75,
      "z": 1,
      "name": "Rock_Sandstone_Red"
    },
    {
      "x": -8,
      "y": 76,
      "z": 1,
      "name": "Soil_Clay_Orange"
    },
    {
      "x": -8,
      "y": 77,
      "z": 1,
      "name": "Soil_Clay_Orange"
    },
    {
      "x": -8,
      "y": 78,
      "z": 1,
      "name": "Soil_Clay_Orange"
    },
    {
      "x": -8,
      "y": 79,
      "z": 1,
      "name": "Soil_Clay_Orange"
    },
    {
      "x": -8,
      "y": 80,
      "z": 1,
      "name": "Soil_Clay_Orange"
    },
    {
      "x": -8,
      "y": 81,
      "z": 1,
      "name": "Rock_Sandstone_Red"
    },
    {
      "x": -8,
      "y": 82,
      "z": 1,
      "name": "Rock_Sandstone_Red"
    },
    {
      "x": -8,
      "y": 83,
      "z": 1,
      "name": "Rock_Sandstone_Red"
    },
    {
      "x": -8,
      "y": 84,
      "z": 1,
      "name": "Rock_Sandstone_Red"
    },
    {
      "x": -8,
      "y": 85,
      "z": 1,
      "name": "Rock_Sandstone_Red"
    },
    {
      "x": -8,
      "y": 86,
      "z": 1,
      "name": "Soil_Clay_Yellow"
    },
    {
      "x": -8,
      "y": 87,
      "z": 1,
      "name": "Soil_Clay_Orange"
    },
    {
      "x": -8,
      "y": 88,
      "z": 1,
      "name": "Soil_Clay_Orange"
    },
    {
      "x": -8,
      "y": 89,
      "z": 1,
      "name": "Rock_Sandstone_Red"
    },
    {
      "x": -8,
      "y": 90,
      "z": 1,
      "name": "Rock_Sandstone_Red"
    },
    {
      "x": -8,
      "y": 54,
      "z": 2,
      "name": "Rock_Sandstone"
    },
    {
      "x": -8,
      "y": 55,
      "z": 2,
      "name": "Rock_Sandstone"
    },
    {
      "x": -8,
      "y": 56,
      "z": 2,
      "name": "Soil_Clay_Orange"
    },
    {
      "x": -8,
      "y": 57,
      "z": 2,
      "name": "Soil_Clay_Orange"
    },
    {
      "x": -8,
      "y": 58,
      "z": 2,
      "name": "Soil_Clay_Orange"
    },
    {
      "x": -8,
      "y": 59,
      "z": 2,
      "name": "Soil_Clay_Orange"
    },
    {
      "x": -8,
      "y": 60,
      "z": 2,
      "name": "Soil_Clay_Orange"
    },
    {
      "x": -8,
      "y": 61,
      "z": 2,
      "name": "Rock_Sandstone_Red"
    },
    {
      "x": -8,
      "y": 62,
      "z": 2,
      "name": "Rock_Sandstone_Red"
    },
    {
      "x": -8,
      "y": 63,
      "z": 2,
      "name": "Rock_Sandstone_Red"
    },
    {
      "x": -8,
      "y": 64,
      "z": 2,
      "name": "Rock_Sandstone"
    },
    {
      "x": -8,
      "y": 65,
      "z": 2,
      "name": "Rock_Sandstone_Red"
    },
    {
      "x": -8,
      "y": 66,
      "z": 2,
      "name": "Rock_Sandstone_Red"
    },
    {
      "x": -8,
      "y": 67,
      "z": 2,
      "name": "Rock_Sandstone_Red"
    },
    {
      "x": -8,
      "y": 68,
      "z": 2,
      "name": "Rock_Sandstone_Red"
    },
    {
      "x": -8,
      "y": 69,
      "z": 2,
      "name": "Rock_Sandstone_Red"
    },
    {
      "x": -8,
      "y": 70,
      "z": 2,
      "name": "Rock_Sandstone_Red"
    },
    {
      "x": -8,
      "y": 71,
      "z": 2,
      "name": "Soil_Clay_Smooth_Red"
    },
    {
      "x": -8,
      "y": 73,
      "z": 2,
      "name": "Rock_Sandstone_Red"
    },
    {
      "x": -8,
      "y": 74,
      "z": 2,
      "name": "Rock_Sandstone_Red"
    },
    {
      "x": -8,
      "y": 76,
      "z": 2,
      "name": "Soil_Clay_Orange"
    },
    {
      "x": -8,
      "y": 77,
      "z": 2,
      "name": "Soil_Clay_Orange"
    },
    {
      "x": -8,
      "y": 78,
      "z": 2,
      "name": "Soil_Clay_Orange"
    },
    {
      "x": -8,
      "y": 81,
      "z": 2,
      "name": "Rock_Sandstone_Red"
    },
    {
      "x": -8,
      "y": 82,
      "z": 2,
      "name": "Rock_Sandstone_Red"
    },
    {
      "x": -8,
      "y": 83,
      "z": 2,
      "name": "Rock_Sandstone_Red"
    },
    {
      "x": -8,
      "y": 84,
      "z": 2,
      "name": "Rock_Sandstone_Red"
    },
    {
      "x": -8,
      "y": 85,
      "z": 2,
      "name": "Soil_Clay_Orange"
    },
    {
      "x": -8,
      "y": 86,
      "z": 2,
      "name": "Rock_Sandstone_White"
    },
    {
      "x": -8,
      "y": 87,
      "z": 2,
      "name": "Soil_Clay_Orange"
    },
    {
      "x": -8,
      "y": 88,
      "z": 2,
      "name": "Soil_Clay_Orange"
    },
    {
      "x": -8,
      "y": 89,
      "z": 2,
      "name": "Soil_Clay_Orange"
    },
    {
      "x": -8,
      "y": 55,
      "z": 3,
      "name": "Rock_Sandstone"
    },
    {
      "x": -8,
      "y": 56,
      "z": 3,
      "name": "Rock_Sandstone"
    },
    {
      "x": -8,
      "y": 57,
      "z": 3,
      "name": "Soil_Clay_Orange"
    },
    {
      "x": -8,
      "y": 58,
      "z": 3,
      "name": "Soil_Clay_Orange"
    },
    {
      "x": -8,
      "y": 59,
      "z": 3,
      "name": "Soil_Clay_Orange"
    },
    {
      "x": -8,
      "y": 60,
      "z": 3,
      "name": "Soil_Clay_Orange"
    },
    {
      "x": -8,
      "y": 61,
      "z": 3,
      "name": "Rock_Sandstone_Red"
    },
    {
      "x": -8,
      "y": 62,
      "z": 3,
      "name": "Rock_Sandstone_Red"
    },
    {
      "x": -8,
      "y": 63,
      "z": 3,
      "name": "Rock_Sandstone_Red"
    },
    {
      "x": -8,
      "y": 64,
      "z": 3,
      "name": "Rock_Sandstone"
    },
    {
      "x": -8,
      "y": 65,
      "z": 3,
      "name": "Rock_Sandstone_Red"
    },
    {
      "x": -8,
      "y": 66,
      "z": 3,
      "name": "Rock_Sandstone_Red"
    },
    {
      "x": -8,
      "y": 67,
      "z": 3,
      "name": "Rock_Sandstone_Red"
    },
    {
      "x": -8,
      "y": 68,
      "z": 3,
      "name": "Rock_Sandstone_Red"
    },
    {
      "x": -8,
      "y": 69,
      "z": 3,
      "name": "Rock_Sandstone_Red"
    },
    {
      "x": -8,
      "y": 70,
      "z": 3,
      "name": "Rock_Sandstone_Red"
    },
    {
      "x": -8,
      "y": 71,
      "z": 3,
      "name": "Soil_Clay_Smooth_Red"
    },
    {
      "x": -8,
      "y": 55,
      "z": 4,
      "name": "Rock_Sandstone"
    },
    {
      "x": -8,
      "y": 56,
      "z": 4,
      "name": "Rock_Sandstone"
    },
    {
      "x": -8,
      "y": 57,
      "z": 4,
      "name": "Soil_Clay_Orange"
    },
    {
      "x": -8,
      "y": 58,
      "z": 4,
      "name": "Soil_Clay_Orange"
    },
    {
      "x": -8,
      "y": 59,
      "z": 4,
      "name": "Rock_Sandstone"
    },
    {
      "x": -8,
      "y": 60,
      "z": 4,
      "name": "Soil_Clay_Orange"
    },
    {
      "x": -8,
      "y": 61,
      "z": 4,
      "name": "Rock_Sandstone_Red"
    },
    {
      "x": -8,
      "y": 62,
      "z": 4,
      "name": "Rock_Sandstone_Red"
    },
    {
      "x": -8,
      "y": 63,
      "z": 4,
      "name": "Rock_Sandstone_Red"
    },
    {
      "x": -8,
      "y": 64,
      "z": 4,
      "name": "Rock_Sandstone"
    },
    {
      "x": -8,
      "y": 65,
      "z": 4,
      "name": "Rock_Sandstone_Red"
    },
    {
      "x": -8,
      "y": 66,
      "z": 4,
      "name": "Rock_Sandstone_Red"
    },
    {
      "x": -8,
      "y": 67,
      "z": 4,
      "name": "Rock_Sandstone_Red"
    },
    {
      "x": -8,
      "y": 68,
      "z": 4,
      "name": "Rock_Sandstone_Red"
    },
    {
      "x": -8,
      "y": 69,
      "z": 4,
      "name": "Rock_Sandstone_Red"
    },
    {
      "x": -8,
      "y": 70,
      "z": 4,
      "name": "Rock_Sandstone_Red"
    },
    {
      "x": -8,
      "y": 71,
      "z": 4,
      "name": "Rock_Sandstone_Red"
    },
    {
      "x": -8,
      "y": 55,
      "z": 5,
      "name": "Rock_Sandstone"
    },
    {
      "x": -8,
      "y": 56,
      "z": 5,
      "name": "Rock_Sandstone"
    },
    {
      "x": -8,
      "y": 57,
      "z": 5,
      "name": "Soil_Clay_Orange"
    },
    {
      "x": -8,
      "y": 58,
      "z": 5,
      "name": "Soil_Clay_Orange"
    },
    {
      "x": -8,
      "y": 59,
      "z": 5,
      "name": "Rock_Sandstone"
    },
    {
      "x": -8,
      "y": 60,
      "z": 5,
      "name": "Soil_Clay_Orange"
    },
    {
      "x": -8,
      "y": 61,
      "z": 5,
      "name": "Rock_Sandstone_Red"
    },
    {
      "x": -8,
      "y": 62,
      "z": 5,
      "name": "Rock_Sandstone_Red"
    },
    {
      "x": -8,
      "y": 63,
      "z": 5,
      "name": "Rock_Sandstone_Red"
    },
    {
      "x": -8,
      "y": 64,
      "z": 5,
      "name": "Rock_Sandstone"
    },
    {
      "x": -8,
      "y": 65,
      "z": 5,
      "name": "Rock_Sandstone_Red"
    },
    {
      "x": -8,
      "y": 66,
      "z": 5,
      "name": "Rock_Sandstone_Red"
    },
    {
      "x": -8,
      "y": 67,
      "z": 5,
      "name": "Rock_Sandstone_Red"
    },
    {
      "x": -8,
      "y": 68,
      "z": 5,
      "name": "Rock_Sandstone_Red"
    },
    {
      "x": -8,
      "y": 69,
      "z": 5,
      "name": "Rock_Sandstone_Red"
    },
    {
      "x": -8,
      "y": 70,
      "z": 5,
      "name": "Rock_Sandstone_Red"
    },
    {
      "x": -8,
      "y": 71,
      "z": 5,
      "name": "Rock_Sandstone_Red"
    },
    {
      "x": -8,
      "y": 79,
      "z": 5,
      "name": "Soil_Clay_Orange"
    },
    {
      "x": -8,
      "y": 80,
      "z": 5,
      "name": "Soil_Clay_Orange"
    },
    {
      "x": -8,
      "y": 81,
      "z": 5,
      "name": "Rock_Sandstone_Red"
    },
    {
      "x": -8,
      "y": 82,
      "z": 5,
      "name": "Rock_Sandstone_Red"
    },
    {
      "x": -8,
      "y": 83,
      "z": 5,
      "name": "Rock_Sandstone_Red"
    },
    {
      "x": -8,
      "y": 84,
      "z": 5,
      "name": "Rock_Sandstone_Red"
    },
    {
      "x": -8,
      "y": 85,
      "z": 5,
      "name": "Rock_Sandstone_Red"
    },
    {
      "x": -8,
      "y": 86,
      "z": 5,
      "name": "Soil_Clay_Yellow"
    },
    {
      "x": -8,
      "y": 89,
      "z": 5,
      "name": "Soil_Clay_Orange"
    },
    {
      "x": -8,
      "y": 74,
      "z": 6,
      "name": "Rock_Sandstone_Red"
    },
    {
      "x": -8,
      "y": 75,
      "z": 6,
      "name": "Rock_Sandstone_Red"
    },
    {
      "x": -8,
      "y": 79,
      "z": 6,
      "name": "Soil_Clay_Orange"
    },
    {
      "x": -8,
      "y": 80,
      "z": 6,
      "name": "Soil_Clay_Orange"
    },
    {
      "x": -8,
      "y": 81,
      "z": 6,
      "name": "Soil_Clay_Orange"
    },
    {
      "x": -8,
      "y": 82,
      "z": 6,
      "name": "Rock_Sandstone_Red"
    },
    {
      "x": -8,
      "y": 83,
      "z": 6,
      "name": "Rock_Sandstone_Red"
    },
    {
      "x": -8,
      "y": 84,
      "z": 6,
      "name": "Rock_Sandstone_Red"
    },
    {
      "x": -8,
      "y": 85,
      "z": 6,
      "name": "Rock_Sandstone_Red"
    },
    {
      "x": -8,
      "y": 86,
      "z": 6,
      "name": "Soil_Clay_Yellow"
    },
    {
      "x": -8,
      "y": 87,
      "z": 6,
      "name": "Soil_Clay_Orange"
    },
    {
      "x": -8,
      "y": 88,
      "z": 6,
      "name": "Soil_Clay_Orange"
    },
    {
      "x": -8,
      "y": 89,
      "z": 6,
      "name": "Soil_Clay_Orange"
    },
    {
      "x": -8,
      "y": 90,
      "z": 6,
      "name": "Soil_Clay_Orange"
    },
    {
      "x": -8,
      "y": 74,
      "z": 7,
      "name": "Rock_Sandstone_Red"
    },
    {
      "x": -8,
      "y": 75,
      "z": 7,
      "name": "Rock_Sandstone_Red"
    },
    {
      "x": -8,
      "y": 79,
      "z": 7,
      "name": "Soil_Clay_Orange"
    },
    {
      "x": -8,
      "y": 80,
      "z": 7,
      "name": "Soil_Clay_Orange"
    },
    {
      "x": -8,
      "y": 81,
      "z": 7,
      "name": "Soil_Clay_Orange"
    },
    {
      "x": -8,
      "y": 82,
      "z": 7,
      "name": "Rock_Sandstone_Red"
    },
    {
      "x": -8,
      "y": 83,
      "z": 7,
      "name": "Rock_Sandstone_Red"
    },
    {
      "x": -8,
      "y": 84,
      "z": 7,
      "name": "Rock_Sandstone_Red"
    },
    {
      "x": -8,
      "y": 85,
      "z": 7,
      "name": "Rock_Sandstone_Red"
    },
    {
      "x": -8,
      "y": 86,
      "z": 7,
      "name": "Rock_Sandstone"
    },
    {
      "x": -8,
      "y": 87,
      "z": 7,
      "name": "Rock_Sandstone"
    },
    {
      "x": -8,
      "y": 88,
      "z": 7,
      "name": "Soil_Clay_Orange"
    },
    {
      "x": -8,
      "y": 89,
      "z": 7,
      "name": "Soil_Clay_Orange"
    },
    {
      "x": -8,
      "y": 90,
      "z": 7,
      "name": "Soil_Clay_Orange"
    },
    {
      "x": -8,
      "y": 74,
      "z": 8,
      "name": "Rock_Sandstone_Red"
    },
    {
      "x": -8,
      "y": 75,
      "z": 8,
      "name": "Rock_Sandstone_Red"
    },
    {
      "x": -8,
      "y": 79,
      "z": 8,
      "name": "Rock_Sandstone"
    },
    {
      "x": -8,
      "y": 80,
      "z": 8,
      "name": "Soil_Clay_Orange"
    },
    {
      "x": -8,
      "y": 81,
      "z": 8,
      "name": "Soil_Clay_Orange"
    },
    {
      "x": -8,
      "y": 82,
      "z": 8,
      "name": "Rock_Sandstone_Red"
    },
    {
      "x": -8,
      "y": 83,
      "z": 8,
      "name": "Rock_Sandstone_Red"
    },
    {
      "x": -8,
      "y": 84,
      "z": 8,
      "name": "Rock_Sandstone_Red"
    },
    {
      "x": -8,
      "y": 85,
      "z": 8,
      "name": "Rock_Sandstone_Red"
    },
    {
      "x": -8,
      "y": 86,
      "z": 8,
      "name": "Rock_Sandstone"
    },
    {
      "x": -8,
      "y": 87,
      "z": 8,
      "name": "Rock_Sandstone"
    },
    {
      "x": -8,
      "y": 88,
      "z": 8,
      "name": "Soil_Clay_Orange"
    },
    {
      "x": -8,
      "y": 89,
      "z": 8,
      "name": "Soil_Clay_Orange"
    },
    {
      "x": -8,
      "y": 90,
      "z": 8,
      "name": "Rock_Sandstone"
    },
    {
      "x": -8,
      "y": 79,
      "z": 9,
      "name": "Rock_Sandstone"
    },
    {
      "x": -8,
      "y": 80,
      "z": 9,
      "name": "Soil_Clay_Orange"
    },
    {
      "x": -8,
      "y": 81,
      "z": 9,
      "name": "Soil_Clay_Orange"
    },
    {
      "x": -8,
      "y": 82,
      "z": 9,
      "name": "Rock_Sandstone_Red"
    },
    {
      "x": -8,
      "y": 83,
      "z": 9,
      "name": "Rock_Sandstone_Red"
    },
    {
      "x": -8,
      "y": 84,
      "z": 9,
      "name": "Rock_Sandstone_Red"
    },
    {
      "x": -8,
      "y": 85,
      "z": 9,
      "name": "Rock_Sandstone_Red"
    },
    {
      "x": -8,
      "y": 86,
      "z": 9,
      "name": "Soil_Clay_Orange"
    },
    {
      "x": -8,
      "y": 87,
      "z": 9,
      "name": "Rock_Sandstone"
    },
    {
      "x": -8,
      "y": 88,
      "z": 9,
      "name": "Soil_Clay_Orange"
    },
    {
      "x": -8,
      "y": 90,
      "z": 9,
      "name": "Rock_Sandstone"
    },
    {
      "x": -7,
      "y": 47,
      "z": -9,
      "name": "Rock_Sandstone"
    },
    {
      "x": -7,
      "y": 48,
      "z": -9,
      "name": "Soil_Clay_Orange"
    },
    {
      "x": -7,
      "y": 49,
      "z": -9,
      "name": "Soil_Clay_Orange"
    },
    {
      "x": -7,
      "y": 60,
      "z": -9,
      "name": "Rock_Sandstone_Red"
    },
    {
      "x": -7,
      "y": 61,
      "z": -9,
      "name": "Rock_Sandstone_Red"
    },
    {
      "x": -7,
      "y": 62,
      "z": -9,
      "name": "Rock_Sandstone"
    },
    {
      "x": -7,
      "y": 63,
      "z": -9,
      "name": "Rock_Sandstone"
    },
    {
      "x": -7,
      "y": 64,
      "z": -9,
      "name": "Rock_Sandstone_Red"
    },
    {
      "x": -7,
      "y": 65,
      "z": -9,
      "name": "Rock_Sandstone_Red"
    },
    {
      "x": -7,
      "y": 66,
      "z": -9,
      "name": "Rock_Sandstone_Red"
    },
    {
      "x": -7,
      "y": 67,
      "z": -9,
      "name": "Rock_Sandstone_Red"
    },
    {
      "x": -7,
      "y": 69,
      "z": -9,
      "name": "Rock_Sandstone_Red"
    },
    {
      "x": -7,
      "y": 70,
      "z": -9,
      "name": "Rock_Sandstone_Red"
    },
    {
      "x": -7,
      "y": 71,
      "z": -9,
      "name": "Rock_Sandstone_Red"
    },
    {
      "x": -7,
      "y": 24,
      "z": -8,
      "name": "Rock_Sandstone_Red"
    },
    {
      "x": -7,
      "y": 26,
      "z": -8,
      "name": "Soil_Clay_Smooth_Red"
    },
    {
      "x": -7,
      "y": 47,
      "z": -8,
      "name": "Rock_Sandstone"
    },
    {
      "x": -7,
      "y": 48,
      "z": -8,
      "name": "Soil_Clay_Orange"
    },
    {
      "x": -7,
      "y": 49,
      "z": -8,
      "name": "Soil_Clay_Orange"
    },
    {
      "x": -7,
      "y": 50,
      "z": -8,
      "name": "Soil_Clay_Smooth_Red"
    },
    {
      "x": -7,
      "y": 55,
      "z": -8,
      "name": "Rock_Sandstone_Red"
    },
    {
      "x": -7,
      "y": 56,
      "z": -8,
      "name": "Soil_Clay_Orange"
    },
    {
      "x": -7,
      "y": 60,
      "z": -8,
      "name": "Rock_Sandstone_Red"
    },
    {
      "x": -7,
      "y": 61,
      "z": -8,
      "name": "Rock_Sandstone_Red"
    },
    {
      "x": -7,
      "y": 62,
      "z": -8,
      "name": "Rock_Sandstone_Red"
    },
    {
      "x": -7,
      "y": 63,
      "z": -8,
      "name": "Rock_Sandstone"
    },
    {
      "x": -7,
      "y": 64,
      "z": -8,
      "name": "Rock_Sandstone_Red"
    },
    {
      "x": -7,
      "y": 65,
      "z": -8,
      "name": "Rock_Sandstone_Red"
    },
    {
      "x": -7,
      "y": 66,
      "z": -8,
      "name": "Rock_Sandstone_Red"
    },
    {
      "x": -7,
      "y": 67,
      "z": -8,
      "name": "Rock_Sandstone_Red"
    },
    {
      "x": -7,
      "y": 68,
      "z": -8,
      "name": "Rock_Sandstone_Red"
    },
    {
      "x": -7,
      "y": 69,
      "z": -8,
      "name": "Rock_Sandstone_Red"
    },
    {
      "x": -7,
      "y": 70,
      "z": -8,
      "name": "Rock_Sandstone_Red"
    },
    {
      "x": -7,
      "y": 71,
      "z": -8,
      "name": "Rock_Sandstone_Red"
    },
    {
      "x": -7,
      "y": 74,
      "z": -8,
      "name": "Rock_Sandstone"
    },
    {
      "x": -7,
      "y": 75,
      "z": -8,
      "name": "Rock_Sandstone"
    },
    {
      "x": -7,
      "y": 76,
      "z": -8,
      "name": "Rock_Sandstone_Red"
    },
    {
      "x": -7,
      "y": 77,
      "z": -8,
      "name": "Rock_Sandstone_Red"
    },
    {
      "x": -7,
      "y": 78,
      "z": -8,
      "name": "Rock_Sandstone_Red"
    },
    {
      "x": -7,
      "y": 79,
      "z": -8,
      "name": "Rock_Sandstone_Red"
    },
    {
      "x": -7,
      "y": 80,
      "z": -8,
      "name": "Rock_Sandstone_Red"
    },
    {
      "x": -7,
      "y": 81,
      "z": -8,
      "name": "Rock_Sandstone_Red"
    },
    {
      "x": -7,
      "y": 82,
      "z": -8,
      "name": "Rock_Sandstone_Red"
    },
    {
      "x": -7,
      "y": 83,
      "z": -8,
      "name": "Rock_Sandstone_Red"
    },
    {
      "x": -7,
      "y": 84,
      "z": -8,
      "name": "Rock_Sandstone_Red"
    },
    {
      "x": -7,
      "y": 85,
      "z": -8,
      "name": "Rock_Sandstone"
    },
    {
      "x": -7,
      "y": 86,
      "z": -8,
      "name": "Rock_Sandstone_Red"
    },
    {
      "x": -7,
      "y": 87,
      "z": -8,
      "name": "Rock_Sandstone_Red"
    },
    {
      "x": -7,
      "y": 88,
      "z": -8,
      "name": "Rock_Sandstone_Red"
    },
    {
      "x": -7,
      "y": 89,
      "z": -8,
      "name": "Rock_Sandstone_Red"
    },
    {
      "x": -7,
      "y": 23,
      "z": -7,
      "name": "Rock_Sandstone_Red"
    },
    {
      "x": -7,
      "y": 24,
      "z": -7,
      "name": "Rock_Sandstone_Red"
    },
    {
      "x": -7,
      "y": 25,
      "z": -7,
      "name": "Rock_Sandstone_Red"
    },
    {
      "x": -7,
      "y": 26,
      "z": -7,
      "name": "Soil_Clay_Smooth_Red"
    },
    {
      "x": -7,
      "y": 46,
      "z": -7,
      "name": "Soil_Clay_Orange"
    },
    {
      "x": -7,
      "y": 47,
      "z": -7,
      "name": "Rock_Sandstone"
    },
    {
      "x": -7,
      "y": 48,
      "z": -7,
      "name": "Soil_Clay_Orange"
    },
    {
      "x": -7,
      "y": 49,
      "z": -7,
      "name": "Soil_Clay_Orange"
    },
    {
      "x": -7,
      "y": 50,
      "z": -7,
      "name": "Soil_Clay_Smooth_Red"
    },
    {
      "x": -7,
      "y": 55,
      "z": -7,
      "name": "Rock_Sandstone_Red"
    },
    {
      "x": -7,
      "y": 56,
      "z": -7,
      "name": "Rock_Sandstone_Red"
    },
    {
      "x": -7,
      "y": 60,
      "z": -7,
      "name": "Rock_Sandstone_Red"
    },
    {
      "x": -7,
      "y": 61,
      "z": -7,
      "name": "Rock_Sandstone_Red"
    },
    {
      "x": -7,
      "y": 62,
      "z": -7,
      "name": "Rock_Sandstone_Red"
    },
    {
      "x": -7,
      "y": 63,
      "z": -7,
      "name": "Rock_Sandstone"
    },
    {
      "x": -7,
      "y": 64,
      "z": -7,
      "name": "Rock_Sandstone_Red"
    },
    {
      "x": -7,
      "y": 65,
      "z": -7,
      "name": "Rock_Sandstone_Red"
    },
    {
      "x": -7,
      "y": 66,
      "z": -7,
      "name": "Rock_Sandstone_Red"
    },
    {
      "x": -7,
      "y": 67,
      "z": -7,
      "name": "Rock_Sandstone_Red"
    },
    {
      "x": -7,
      "y": 68,
      "z": -7,
      "name": "Rock_Sandstone_Red"
    },
    {
      "x": -7,
      "y": 69,
      "z": -7,
      "name": "Rock_Sandstone_Red"
    },
    {
      "x": -7,
      "y": 70,
      "z": -7,
      "name": "Rock_Sandstone_Red"
    },
    {
      "x": -7,
      "y": 71,
      "z": -7,
      "name": "Rock_Sandstone_Red"
    },
    {
      "x": -7,
      "y": 73,
      "z": -7,
      "name": "Soil_Clay_Orange"
    },
    {
      "x": -7,
      "y": 74,
      "z": -7,
      "name": "Rock_Sandstone"
    },
    {
      "x": -7,
      "y": 75,
      "z": -7,
      "name": "Rock_Sandstone"
    },
    {
      "x": -7,
      "y": 76,
      "z": -7,
      "name": "Rock_Sandstone_Red"
    },
    {
      "x": -7,
      "y": 77,
      "z": -7,
      "name": "Rock_Sandstone_Red"
    },
    {
      "x": -7,
      "y": 78,
      "z": -7,
      "name": "Rock_Sandstone_Red"
    },
    {
      "x": -7,
      "y": 79,
      "z": -7,
      "name": "Rock_Sandstone_Red"
    },
    {
      "x": -7,
      "y": 80,
      "z": -7,
      "name": "Rock_Sandstone_Red"
    },
    {
      "x": -7,
      "y": 81,
      "z": -7,
      "name": "Rock_Sandstone_Red"
    },
    {
      "x": -7,
      "y": 82,
      "z": -7,
      "name": "Rock_Sandstone_Red"
    },
    {
      "x": -7,
      "y": 83,
      "z": -7,
      "name": "Rock_Sandstone_Red"
    },
    {
      "x": -7,
      "y": 84,
      "z": -7,
      "name": "Rock_Sandstone_Red"
    },
    {
      "x": -7,
      "y": 85,
      "z": -7,
      "name": "Rock_Sandstone"
    },
    {
      "x": -7,
      "y": 86,
      "z": -7,
      "name": "Rock_Sandstone_Red"
    },
    {
      "x": -7,
      "y": 87,
      "z": -7,
      "name": "Rock_Sandstone_Red"
    },
    {
      "x": -7,
      "y": 88,
      "z": -7,
      "name": "Rock_Sandstone_Red"
    },
    {
      "x": -7,
      "y": 89,
      "z": -7,
      "name": "Rock_Sandstone_Red"
    },
    {
      "x": -7,
      "y": 90,
      "z": -7,
      "name": "Soil_Clay_Smooth_Red"
    },
    {
      "x": -7,
      "y": 24,
      "z": -6,
      "name": "Rock_Sandstone_Red"
    },
    {
      "x": -7,
      "y": 25,
      "z": -6,
      "name": "Rock_Sandstone_Red"
    },
    {
      "x": -7,
      "y": 26,
      "z": -6,
      "name": "Soil_Clay_Smooth_Red"
    },
    {
      "x": -7,
      "y": 47,
      "z": -6,
      "name": "Rock_Sandstone"
    },
    {
      "x": -7,
      "y": 48,
      "z": -6,
      "name": "Soil_Clay_Orange"
    },
    {
      "x": -7,
      "y": 49,
      "z": -6,
      "name": "Soil_Clay_Orange"
    },
    {
      "x": -7,
      "y": 50,
      "z": -6,
      "name": "Soil_Clay_Smooth_Red"
    },
    {
      "x": -7,
      "y": 55,
      "z": -6,
      "name": "Rock_Sandstone_Red"
    },
    {
      "x": -7,
      "y": 56,
      "z": -6,
      "name": "Rock_Sandstone"
    },
    {
      "x": -7,
      "y": 60,
      "z": -6,
      "name": "Rock_Sandstone_Red"
    },
    {
      "x": -7,
      "y": 61,
      "z": -6,
      "name": "Rock_Sandstone_Red"
    },
    {
      "x": -7,
      "y": 62,
      "z": -6,
      "name": "Rock_Sandstone_Red"
    },
    {
      "x": -7,
      "y": 63,
      "z": -6,
      "name": "Rock_Sandstone"
    },
    {
      "x": -7,
      "y": 64,
      "z": -6,
      "name": "Rock_Sandstone_Red"
    },
    {
      "x": -7,
      "y": 65,
      "z": -6,
      "name": "Rock_Sandstone_Red"
    },
    {
      "x": -7,
      "y": 66,
      "z": -6,
      "name": "Rock_Sandstone_Red"
    },
    {
      "x": -7,
      "y": 67,
      "z": -6,
      "name": "Rock_Sandstone_Red"
    },
    {
      "x": -7,
      "y": 68,
      "z": -6,
      "name": "Rock_Sandstone_Red"
    },
    {
      "x": -7,
      "y": 69,
      "z": -6,
      "name": "Rock_Sandstone_Red"
    },
    {
      "x": -7,
      "y": 70,
      "z": -6,
      "name": "Rock_Sandstone_Red"
    },
    {
      "x": -7,
      "y": 71,
      "z": -6,
      "name": "Rock_Sandstone_Red"
    },
    {
      "x": -7,
      "y": 73,
      "z": -6,
      "name": "Soil_Clay_Orange"
    },
    {
      "x": -7,
      "y": 74,
      "z": -6,
      "name": "Rock_Sandstone"
    },
    {
      "x": -7,
      "y": 75,
      "z": -6,
      "name": "Rock_Sandstone"
    },
    {
      "x": -7,
      "y": 76,
      "z": -6,
      "name": "Rock_Sandstone_Red"
    },
    {
      "x": -7,
      "y": 77,
      "z": -6,
      "name": "Rock_Sandstone_Red"
    },
    {
      "x": -7,
      "y": 78,
      "z": -6,
      "name": "Rock_Sandstone_Red"
    },
    {
      "x": -7,
      "y": 79,
      "z": -6,
      "name": "Rock_Sandstone_Red"
    },
    {
      "x": -7,
      "y": 80,
      "z": -6,
      "name": "Rock_Sandstone_Red"
    },
    {
      "x": -7,
      "y": 81,
      "z": -6,
      "name": "Rock_Sandstone_Red"
    },
    {
      "x": -7,
      "y": 82,
      "z": -6,
      "name": "Rock_Sandstone_Red"
    },
    {
      "x": -7,
      "y": 83,
      "z": -6,
      "name": "Rock_Sandstone_Red"
    },
    {
      "x": -7,
      "y": 84,
      "z": -6,
      "name": "Rock_Sandstone_Red"
    },
    {
      "x": -7,
      "y": 85,
      "z": -6,
      "name": "Rock_Sandstone"
    },
    {
      "x": -7,
      "y": 86,
      "z": -6,
      "name": "Rock_Sandstone_Red"
    },
    {
      "x": -7,
      "y": 87,
      "z": -6,
      "name": "Rock_Sandstone_Red"
    },
    {
      "x": -7,
      "y": 88,
      "z": -6,
      "name": "Rock_Sandstone_Red"
    },
    {
      "x": -7,
      "y": 89,
      "z": -6,
      "name": "Rock_Sandstone_Red"
    },
    {
      "x": -7,
      "y": 90,
      "z": -6,
      "name": "Soil_Clay_Smooth_Red"
    },
    {
      "x": -7,
      "y": 23,
      "z": -5,
      "name": "Rock_Sandstone_Red"
    },
    {
      "x": -7,
      "y": 24,
      "z": -5,
      "name": "Rock_Sandstone_Red"
    },
    {
      "x": -7,
      "y": 25,
      "z": -5,
      "name": "Rock_Sandstone_Red"
    },
    {
      "x": -7,
      "y": 26,
      "z": -5,
      "name": "Soil_Clay_Smooth_Red"
    },
    {
      "x": -7,
      "y": 47,
      "z": -5,
      "name": "Rock_Sandstone"
    },
    {
      "x": -7,
      "y": 48,
      "z": -5,
      "name": "Soil_Clay_Orange"
    },
    {
      "x": -7,
      "y": 49,
      "z": -5,
      "name": "Soil_Clay_Orange"
    },
    {
      "x": -7,
      "y": 60,
      "z": -5,
      "name": "Rock_Sandstone_Red"
    },
    {
      "x": -7,
      "y": 61,
      "z": -5,
      "name": "Rock_Sandstone_Red"
    },
    {
      "x": -7,
      "y": 62,
      "z": -5,
      "name": "Rock_Sandstone_Red"
    },
    {
      "x": -7,
      "y": 63,
      "z": -5,
      "name": "Rock_Sandstone"
    },
    {
      "x": -7,
      "y": 70,
      "z": -5,
      "name": "Rock_Sandstone_Red"
    },
    {
      "x": -7,
      "y": 73,
      "z": -5,
      "name": "Rock_Sandstone_Red"
    },
    {
      "x": -7,
      "y": 74,
      "z": -5,
      "name": "Rock_Sandstone"
    },
    {
      "x": -7,
      "y": 75,
      "z": -5,
      "name": "Rock_Sandstone"
    },
    {
      "x": -7,
      "y": 76,
      "z": -5,
      "name": "Rock_Sandstone_Red"
    },
    {
      "x": -7,
      "y": 77,
      "z": -5,
      "name": "Rock_Sandstone_Red"
    },
    {
      "x": -7,
      "y": 78,
      "z": -5,
      "name": "Rock_Sandstone_Red"
    },
    {
      "x": -7,
      "y": 79,
      "z": -5,
      "name": "Rock_Sandstone_Red"
    },
    {
      "x": -7,
      "y": 80,
      "z": -5,
      "name": "Rock_Sandstone_Red"
    },
    {
      "x": -7,
      "y": 81,
      "z": -5,
      "name": "Rock_Sandstone_Red"
    },
    {
      "x": -7,
      "y": 82,
      "z": -5,
      "name": "Rock_Sandstone_Red"
    },
    {
      "x": -7,
      "y": 83,
      "z": -5,
      "name": "Rock_Sandstone_Red"
    },
    {
      "x": -7,
      "y": 84,
      "z": -5,
      "name": "Rock_Sandstone_Red"
    },
    {
      "x": -7,
      "y": 85,
      "z": -5,
      "name": "Rock_Sandstone"
    },
    {
      "x": -7,
      "y": 86,
      "z": -5,
      "name": "Rock_Sandstone_Red"
    },
    {
      "x": -7,
      "y": 87,
      "z": -5,
      "name": "Rock_Sandstone_Red"
    },
    {
      "x": -7,
      "y": 88,
      "z": -5,
      "name": "Rock_Sandstone_Red"
    },
    {
      "x": -7,
      "y": 89,
      "z": -5,
      "name": "Rock_Sandstone_Red"
    },
    {
      "x": -7,
      "y": 90,
      "z": -5,
      "name": "Soil_Clay_Smooth_Red"
    },
    {
      "x": -7,
      "y": 23,
      "z": -4,
      "name": "Rock_Sandstone_Red"
    },
    {
      "x": -7,
      "y": 24,
      "z": -4,
      "name": "Rock_Sandstone_Red"
    },
    {
      "x": -7,
      "y": 25,
      "z": -4,
      "name": "Rock_Sandstone_Red"
    },
    {
      "x": -7,
      "y": 26,
      "z": -4,
      "name": "Soil_Clay_Smooth_Red"
    },
    {
      "x": -7,
      "y": 30,
      "z": -4,
      "name": "Soil_Clay_Orange"
    },
    {
      "x": -7,
      "y": 31,
      "z": -4,
      "name": "Rock_Sandstone"
    },
    {
      "x": -7,
      "y": 32,
      "z": -4,
      "name": "Rock_Sandstone_Red"
    },
    {
      "x": -7,
      "y": 33,
      "z": -4,
      "name": "Rock_Sandstone_Red"
    },
    {
      "x": -7,
      "y": 34,
      "z": -4,
      "name": "Rock_Sandstone"
    },
    {
      "x": -7,
      "y": 35,
      "z": -4,
      "name": "Rock_Sandstone_Red"
    },
    {
      "x": -7,
      "y": 36,
      "z": -4,
      "name": "Rock_Sandstone_Red"
    },
    {
      "x": -7,
      "y": 37,
      "z": -4,
      "name": "Soil_Clay_Orange"
    },
    {
      "x": -7,
      "y": 38,
      "z": -4,
      "name": "Rock_Sandstone"
    },
    {
      "x": -7,
      "y": 39,
      "z": -4,
      "name": "Rock_Sandstone_Red"
    },
    {
      "x": -7,
      "y": 40,
      "z": -4,
      "name": "Rock_Sandstone_Red"
    },
    {
      "x": -7,
      "y": 73,
      "z": -4,
      "name": "Rock_Sandstone_Red"
    },
    {
      "x": -7,
      "y": 74,
      "z": -4,
      "name": "Rock_Sandstone_Red"
    },
    {
      "x": -7,
      "y": 75,
      "z": -4,
      "name": "Rock_Sandstone"
    },
    {
      "x": -7,
      "y": 76,
      "z": -4,
      "name": "Rock_Sandstone_Red"
    },
    {
      "x": -7,
      "y": 77,
      "z": -4,
      "name": "Rock_Sandstone_Red"
    },
    {
      "x": -7,
      "y": 78,
      "z": -4,
      "name": "Rock_Sandstone_Red"
    },
    {
      "x": -7,
      "y": 79,
      "z": -4,
      "name": "Rock_Sandstone_Red"
    },
    {
      "x": -7,
      "y": 80,
      "z": -4,
      "name": "Rock_Sandstone_Red"
    },
    {
      "x": -7,
      "y": 81,
      "z": -4,
      "name": "Rock_Sandstone_Red"
    },
    {
      "x": -7,
      "y": 82,
      "z": -4,
      "name": "Rock_Sandstone_Red"
    },
    {
      "x": -7,
      "y": 83,
      "z": -4,
      "name": "Rock_Sandstone_Red"
    },
    {
      "x": -7,
      "y": 84,
      "z": -4,
      "name": "Rock_Sandstone_Red"
    },
    {
      "x": -7,
      "y": 85,
      "z": -4,
      "name": "Rock_Sandstone"
    },
    {
      "x": -7,
      "y": 86,
      "z": -4,
      "name": "Rock_Sandstone"
    },
    {
      "x": -7,
      "y": 87,
      "z": -4,
      "name": "Rock_Sandstone_Red"
    },
    {
      "x": -7,
      "y": 88,
      "z": -4,
      "name": "Rock_Sandstone_Red"
    },
    {
      "x": -7,
      "y": 89,
      "z": -4,
      "name": "Rock_Sandstone_Red"
    },
    {
      "x": -7,
      "y": 90,
      "z": -4,
      "name": "Rock_Sandstone_Red"
    },
    {
      "x": -7,
      "y": 91,
      "z": -4,
      "name": "Soil_Clay_Smooth_Red"
    },
    {
      "x": -7,
      "y": 23,
      "z": -3,
      "name": "Soil_Clay_Orange"
    },
    {
      "x": -7,
      "y": 26,
      "z": -3,
      "name": "Soil_Clay_Orange"
    },
    {
      "x": -7,
      "y": 30,
      "z": -3,
      "name": "Soil_Clay_Orange"
    },
    {
      "x": -7,
      "y": 31,
      "z": -3,
      "name": "Rock_Sandstone"
    },
    {
      "x": -7,
      "y": 32,
      "z": -3,
      "name": "Rock_Sandstone_Red"
    },
    {
      "x": -7,
      "y": 33,
      "z": -3,
      "name": "Rock_Sandstone_Red"
    },
    {
      "x": -7,
      "y": 34,
      "z": -3,
      "name": "Rock_Sandstone"
    },
    {
      "x": -7,
      "y": 35,
      "z": -3,
      "name": "Rock_Sandstone_Red"
    },
    {
      "x": -7,
      "y": 36,
      "z": -3,
      "name": "Rock_Sandstone_Red"
    },
    {
      "x": -7,
      "y": 37,
      "z": -3,
      "name": "Soil_Clay_Orange"
    },
    {
      "x": -7,
      "y": 38,
      "z": -3,
      "name": "Rock_Sandstone"
    },
    {
      "x": -7,
      "y": 39,
      "z": -3,
      "name": "Rock_Sandstone_Red"
    },
    {
      "x": -7,
      "y": 40,
      "z": -3,
      "name": "Soil_Clay_Smooth_Red"
    },
    {
      "x": -7,
      "y": 72,
      "z": -3,
      "name": "Rock_Sandstone_Red"
    },
    {
      "x": -7,
      "y": 73,
      "z": -3,
      "name": "Rock_Sandstone_Red"
    },
    {
      "x": -7,
      "y": 74,
      "z": -3,
      "name": "Rock_Sandstone_Red"
    },
    {
      "x": -7,
      "y": 75,
      "z": -3,
      "name": "Soil_Clay_Orange"
    },
    {
      "x": -7,
      "y": 76,
      "z": -3,
      "name": "Rock_Sandstone_Red"
    },
    {
      "x": -7,
      "y": 77,
      "z": -3,
      "name": "Rock_Sandstone_Red"
    },
    {
      "x": -7,
      "y": 78,
      "z": -3,
      "name": "Rock_Sandstone_Red"
    },
    {
      "x": -7,
      "y": 79,
      "z": -3,
      "name": "Rock_Sandstone_Red"
    },
    {
      "x": -7,
      "y": 80,
      "z": -3,
      "name": "Rock_Sandstone_Red"
    },
    {
      "x": -7,
      "y": 81,
      "z": -3,
      "name": "Rock_Sandstone_Red"
    },
    {
      "x": -7,
      "y": 82,
      "z": -3,
      "name": "Rock_Sandstone_Red"
    },
    {
      "x": -7,
      "y": 83,
      "z": -3,
      "name": "Rock_Sandstone_Red"
    },
    {
      "x": -7,
      "y": 84,
      "z": -3,
      "name": "Rock_Sandstone_Red"
    },
    {
      "x": -7,
      "y": 85,
      "z": -3,
      "name": "Rock_Sandstone"
    },
    {
      "x": -7,
      "y": 86,
      "z": -3,
      "name": "Rock_Sandstone"
    },
    {
      "x": -7,
      "y": 87,
      "z": -3,
      "name": "Rock_Sandstone_Red"
    },
    {
      "x": -7,
      "y": 88,
      "z": -3,
      "name": "Rock_Sandstone_Red"
    },
    {
      "x": -7,
      "y": 89,
      "z": -3,
      "name": "Rock_Sandstone_Red"
    },
    {
      "x": -7,
      "y": 90,
      "z": -3,
      "name": "Rock_Sandstone_Red"
    },
    {
      "x": -7,
      "y": 91,
      "z": -3,
      "name": "Soil_Clay_Smooth_Red"
    },
    {
      "x": -7,
      "y": 2,
      "z": -2,
      "name": "Rock_Sandstone_Red"
    },
    {
      "x": -7,
      "y": 3,
      "z": -2,
      "name": "Rock_Sandstone_Red"
    },
    {
      "x": -7,
      "y": 4,
      "z": -2,
      "name": "Rock_Sandstone_Red"
    },
    {
      "x": -7,
      "y": 5,
      "z": -2,
      "name": "Rock_Sandstone_Red"
    },
    {
      "x": -7,
      "y": 8,
      "z": -2,
      "name": "Rock_Sandstone_Red"
    },
    {
      "x": -7,
      "y": 9,
      "z": -2,
      "name": "Rock_Sandstone_Red"
    },
    {
      "x": -7,
      "y": 10,
      "z": -2,
      "name": "Rock_Sandstone_Red"
    },
    {
      "x": -7,
      "y": 11,
      "z": -2,
      "name": "Soil_Clay_Orange"
    },
    {
      "x": -7,
      "y": 12,
      "z": -2,
      "name": "Rock_Sandstone_Red"
    },
    {
      "x": -7,
      "y": 14,
      "z": -2,
      "name": "Rock_Sandstone"
    },
    {
      "x": -7,
      "y": 15,
      "z": -2,
      "name": "Rock_Sandstone_Red"
    },
    {
      "x": -7,
      "y": 16,
      "z": -2,
      "name": "Rock_Sandstone_Red"
    },
    {
      "x": -7,
      "y": 24,
      "z": -2,
      "name": "Soil_Clay_Orange"
    },
    {
      "x": -7,
      "y": 25,
      "z": -2,
      "name": "Soil_Clay_Orange"
    },
    {
      "x": -7,
      "y": 30,
      "z": -2,
      "name": "Soil_Clay_Orange"
    },
    {
      "x": -7,
      "y": 31,
      "z": -2,
      "name": "Rock_Sandstone_Red"
    },
    {
      "x": -7,
      "y": 32,
      "z": -2,
      "name": "Rock_Sandstone_Red"
    },
    {
      "x": -7,
      "y": 33,
      "z": -2,
      "name": "Rock_Sandstone_Red"
    },
    {
      "x": -7,
      "y": 34,
      "z": -2,
      "name": "Rock_Sandstone"
    },
    {
      "x": -7,
      "y": 35,
      "z": -2,
      "name": "Rock_Sandstone_Red"
    },
    {
      "x": -7,
      "y": 36,
      "z": -2,
      "name": "Rock_Sandstone_Red"
    },
    {
      "x": -7,
      "y": 37,
      "z": -2,
