{
  "version": 8,
  "blockIdVersion": 10,
  "anchorX": 0,
  "anchorY": 5,
  "anchorZ": 0,
  "blocks": [
    {
      "x": -5,
      "y": 0,
      "z": 1,
      "name": "Rock_Acid_Trunk_Light"
    },
    {
      "x": -5,
      "y": 1,
      "z": 1,
      "name": "Rock_Acid_Trunk_Light"
    },
    {
      "x": -5,
      "y": 2,
      "z": 1,
      "name": "Rock_Acid_Trunk_Medium"
    },
    {
      "x": -5,
      "y": 3,
      "z": 1,
      "name": "Rock_Acid_Trunk_Medium"
    },
    {
      "x": -5,
      "y": 4,
      "z": 1,
      "name": "Rock_Acid_Trunk_Medium"
    },
    {
      "x": -5,
      "y": 5,
      "z": 1,
      "name": "Rock_Acid_Trunk_Medium"
    },
    {
      "x": -5,
      "y": 6,
      "z": 1,
      "name": "Rock_Acid_Trunk_Medium"
    },
    {
      "x": -5,
      "y": 7,
      "z": 1,
      "name": "Rock_Acid_Trunk_Standard"
    },
    {
      "x": -5,
      "y": 33,
      "z": 1,
      "name": "Rock_Acid_Trunk_Crimson"
    },
    {
      "x": -5,
      "y": 34,
      "z": 1,
      "name": "Rock_Acid_Trunk_Crimson"
    },
    {
      "x": -5,
      "y": 35,
      "z": 1,
      "name": "Rock_Acid_Trunk_Magenta"
    },
    {
      "x": -5,
      "y": 0,
      "z": 2,
      "name": "Rock_Acid_Trunk_Light"
    },
    {
      "x": -5,
      "y": 1,
      "z": 2,
      "name": "Rock_Acid_Trunk_Light"
    },
    {
      "x": -5,
      "y": 2,
      "z": 2,
      "name": "Rock_Acid_Trunk_Light"
    },
    {
      "x": -5,
      "y": 3,
      "z": 2,
      "name": "Rock_Acid_Trunk_Medium"
    },
    {
      "x": -5,
      "y": 4,
      "z": 2,
      "name": "Rock_Acid_Trunk_Medium"
    },
    {
      "x": -5,
      "y": 5,
      "z": 2,
      "name": "Rock_Acid_Trunk_Standard"
    },
    {
      "x": -5,
      "y": 6,
      "z": 2,
      "name": "Rock_Acid_Trunk_Standard"
    },
    {
      "x": -5,
      "y": 32,
      "z": 2,
      "name": "Rock_Acid_Trunk_Orange"
    },
    {
      "x": -5,
      "y": 33,
      "z": 2,
      "name": "Rock_Acid_Trunk_Crimson"
    },
    {
      "x": -5,
      "y": 34,
      "z": 2,
      "name": "Rock_Acid_Trunk_Magenta"
    },
    {
      "x": -5,
      "y": 35,
      "z": 2,
      "name": "Rock_Acid_Trunk_Magenta"
    },
    {
      "x": -5,
      "y": 30,
      "z": 3,
      "name": "Rock_Acid_Trunk_Orange"
    },
    {
      "x": -5,
      "y": 31,
      "z": 3,
      "name": "Rock_Acid_Trunk_Orange"
    },
    {
      "x": -5,
      "y": 32,
      "z": 3,
      "name": "Rock_Acid_Trunk_Crimson"
    },
    {
      "x": -5,
      "y": 33,
      "z": 3,
      "name": "Rock_Acid_Trunk_Crimson"
    },
    {
      "x": -5,
      "y": 30,
      "z": 4,
      "name": "Rock_Acid_Trunk_Bright"
    },
    {
      "x": -5,
      "y": 31,
      "z": 4,
      "name": "Rock_Acid_Trunk_Orange"
    },
    {
      "x": -5,
      "y": 32,
      "z": 4,
      "name": "Rock_Acid_Trunk_Orange"
    },
    {
      "x": -5,
      "y": 33,
      "z": 4,
      "name": "Rock_Acid_Trunk_Magenta"
    },
    {
      "x": -5,
      "y": 31,
      "z": 5,
      "name": "Rock_Acid_Trunk_Orange"
    },
    {
      "x": -5,
      "y": 32,
      "z": 5,
      "name": "Rock_Acid_Trunk_Orange"
    },
    {
      "x": -5,
      "y": 33,
      "z": 5,
      "name": "Rock_Acid_Trunk_Crimson"
    },
    {
      "x": -4,
      "y": 22,
      "z": -6,
      "name": "Rock_Acid_Trunk_Orange"
    },
    {
      "x": -4,
      "y": 23,
      "z": -6,
      "name": "Rock_Acid_Trunk_Magenta"
    },
    {
      "x": -4,
      "y": 24,
      "z": -6,
      "name": "Rock_Acid_Trunk_Magenta"
    },
    {
      "x": -4,
      "y": 21,
      "z": -5,
      "name": "Rock_Acid_Trunk_Orange"
    },
    {
      "x": -4,
      "y": 22,
      "z": -5,
      "name": "Rock_Acid_Trunk_Crimson"
    },
    {
      "x": -4,
      "y": 23,
      "z": -5,
      "name": "Rock_Acid_Trunk_Crimson"
    },
    {
      "x": -4,
      "y": 24,
      "z": -5,
      "name": "Rock_Acid_Trunk_Magenta"
    },
    {
      "x": -4,
      "y": 21,
      "z": -4,
      "name": "Rock_Acid_Trunk_Orange"
    },
    {
      "x": -4,
      "y": 22,
      "z": -4,
      "name": "Rock_Acid_Trunk_Crimson"
    },
    {
      "x": -4,
      "y": 21,
      "z": -3,
      "name": "Rock_Acid_Trunk_Orange"
    },
    {
      "x": -4,
      "y": 22,
      "z": -3,
      "name": "Rock_Acid_Trunk_Crimson"
    },
    {
      "x": -4,
      "y": 6,
      "z": 0,
      "name": "Rock_Acid_Trunk_Medium"
    },
    {
      "x": -4,
      "y": 7,
      "z": 0,
      "name": "Rock_Acid_Trunk_Medium"
    },
    {
      "x": -4,
      "y": 8,
      "z": 0,
      "name": "Rock_Acid_Trunk_Standard"
    },
    {
      "x": -4,
      "y": 31,
      "z": 0,
      "name": "Rock_Acid_Trunk_Orange"
    },
    {
      "x": -4,
      "y": 32,
      "z": 0,
      "name": "Rock_Acid_Trunk_Crimson"
    },
    {
      "x": -4,
      "y": 33,
      "z": 0,
      "name": "Rock_Acid_Trunk_Crimson"
    },
    {
      "x": -4,
      "y": 0,
      "z": 1,
      "name": "Rock_Acid_Trunk_Light"
    },
    {
      "x": -4,
      "y": 1,
      "z": 1,
      "name": "Rock_Acid_Trunk_Medium"
    },
    {
      "x": -4,
      "y": 2,
      "z": 1,
      "name": "Rock_Acid_Trunk_Medium"
    },
    {
      "x": -4,
      "y": 3,
      "z": 1,
      "name": "Rock_Acid_Trunk_Medium"
    },
    {
      "x": -4,
      "y": 4,
      "z": 1,
      "name": "Rock_Acid_Trunk_Medium"
    },
    {
      "x": -4,
      "y": 5,
      "z": 1,
      "name": "Rock_Acid_Trunk_Medium"
    },
    {
      "x": -4,
      "y": 6,
      "z": 1,
      "name": "Rock_Acid_Trunk_Medium"
    },
    {
      "x": -4,
      "y": 7,
      "z": 1,
      "name": "Rock_Acid_Trunk_Standard"
    },
    {
      "x": -4,
      "y": 8,
      "z": 1,
      "name": "Rock_Acid_Trunk_Standard"
    },
    {
      "x": -4,
      "y": 9,
      "z": 1,
      "name": "Rock_Acid_Trunk_Standard"
    },
    {
      "x": -4,
      "y": 28,
      "z": 1,
      "name": "Rock_Acid_Trunk_Orange"
    },
    {
      "x": -4,
      "y": 29,
      "z": 1,
      "name": "Rock_Acid_Trunk_Bright"
    },
    {
      "x": -4,
      "y": 30,
      "z": 1,
      "name": "Rock_Acid_Trunk_Bright"
    },
    {
      "x": -4,
      "y": 31,
      "z": 1,
      "name": "Rock_Acid_Trunk_Orange"
    },
    {
      "x": -4,
      "y": 32,
      "z": 1,
      "name": "Rock_Acid_Trunk_Crimson"
    },
    {
      "x": -4,
      "y": 33,
      "z": 1,
      "name": "Rock_Acid_Trunk_Crimson"
    },
    {
      "x": -4,
      "y": 0,
      "z": 2,
      "name": "Rock_Acid_Trunk_Light"
    },
    {
      "x": -4,
      "y": 1,
      "z": 2,
      "name": "Rock_Acid_Trunk_Light"
    },
    {
      "x": -4,
      "y": 2,
      "z": 2,
      "name": "Rock_Acid_Trunk_Medium"
    },
    {
      "x": -4,
      "y": 3,
      "z": 2,
      "name": "Rock_Acid_Trunk_Medium"
    },
    {
      "x": -4,
      "y": 4,
      "z": 2,
      "name": "Rock_Acid_Trunk_Medium"
    },
    {
      "x": -4,
      "y": 5,
      "z": 2,
      "name": "Rock_Acid_Trunk_Medium"
    },
    {
      "x": -4,
      "y": 6,
      "z": 2,
      "name": "Rock_Acid_Trunk_Standard"
    },
    {
      "x": -4,
      "y": 26,
      "z": 2,
      "name": "Rock_Acid_Trunk_Bright"
    },
    {
      "x": -4,
      "y": 27,
      "z": 2,
      "name": "Rock_Acid_Trunk_Bright"
    },
    {
      "x": -4,
      "y": 28,
      "z": 2,
      "name": "Rock_Acid_Trunk_Bright"
    },
    {
      "x": -4,
      "y": 29,
      "z": 2,
      "name": "Rock_Acid_Trunk_Bright"
    },
    {
      "x": -4,
      "y": 30,
      "z": 2,
      "name": "Rock_Acid_Trunk_Orange"
    },
    {
      "x": -4,
      "y": 31,
      "z": 2,
      "name": "Rock_Acid_Trunk_Orange"
    },
    {
      "x": -4,
      "y": 32,
      "z": 2,
      "name": "Rock_Acid_Trunk_Crimson"
    },
    {
      "x": -4,
      "y": 33,
      "z": 2,
      "name": "Rock_Crystal_Green_Block"
    },
    {
      "x": -4,
      "y": 36,
      "z": 2,
      "name": "Rock_Acid_Trunk_Magenta"
    },
    {
      "x": -4,
      "y": 25,
      "z": 3,
      "name": "Rock_Acid_Trunk_Bright"
    },
    {
      "x": -4,
      "y": 26,
      "z": 3,
      "name": "Rock_Acid_Trunk_Bright"
    },
    {
      "x": -4,
      "y": 27,
      "z": 3,
      "name": "Rock_Acid_Trunk_Orange"
    },
    {
      "x": -4,
      "y": 28,
      "z": 3,
      "name": "Rock_Acid_Trunk_Bright"
    },
    {
      "x": -4,
      "y": 29,
      "z": 3,
      "name": "Rock_Acid_Trunk_Orange"
    },
    {
      "x": -4,
      "y": 30,
      "z": 3,
      "name": "Rock_Acid_Trunk_Medium"
    },
    {
      "x": -4,
      "y": 31,
      "z": 3,
      "name": "Rock_Acid_Trunk_Medium"
    },
    {
      "x": -4,
      "y": 32,
      "z": 3,
      "name": "Rock_Acid_Trunk_Crimson"
    },
    {
      "x": -4,
      "y": 33,
      "z": 3,
      "name": "Empty"
    },
    {
      "x": -4,
      "y": 25,
      "z": 4,
      "name": "Rock_Acid_Trunk_Bright"
    },
    {
      "x": -4,
      "y": 26,
      "z": 4,
      "name": "Rock_Acid_Trunk_Bright"
    },
    {
      "x": -4,
      "y": 27,
      "z": 4,
      "name": "Rock_Acid_Trunk_Bright"
    },
    {
      "x": -4,
      "y": 28,
      "z": 4,
      "name": "Rock_Acid_Trunk_Bright"
    },
    {
      "x": -4,
      "y": 29,
      "z": 4,
      "name": "Rock_Acid_Trunk_Bright"
    },
    {
      "x": -4,
      "y": 30,
      "z": 4,
      "name": "Rock_Acid_Trunk_Medium"
    },
    {
      "x": -4,
      "y": 31,
      "z": 4,
      "name": "Rock_Acid_Trunk_Medium"
    },
    {
      "x": -4,
      "y": 32,
      "z": 4,
      "name": "Rock_Acid_Trunk_Crimson"
    },
    {
      "x": -4,
      "y": 33,
      "z": 4,
      "name": "Empty"
    },
    {
      "x": -4,
      "y": 26,
      "z": 5,
      "name": "Rock_Acid_Trunk_Bright"
    },
    {
      "x": -4,
      "y": 27,
      "z": 5,
      "name": "Rock_Acid_Trunk_Orange"
    },
    {
      "x": -4,
      "y": 28,
      "z": 5,
      "name": "Rock_Acid_Trunk_Bright"
    },
    {
      "x": -4,
      "y": 29,
      "z": 5,
      "name": "Rock_Acid_Trunk_Bright"
    },
    {
      "x": -4,
      "y": 30,
      "z": 5,
      "name": "Rock_Acid_Trunk_Bright"
    },
    {
      "x": -4,
      "y": 31,
      "z": 5,
      "name": "Rock_Acid_Trunk_Medium"
    },
    {
      "x": -4,
      "y": 32,
      "z": 5,
      "name": "Rock_Acid_Trunk_Crimson"
    },
    {
      "x": -4,
      "y": 33,
      "z": 5,
      "name": "Rock_Acid_Trunk_Crimson"
    },
    {
      "x": -4,
      "y": 30,
      "z": 6,
      "name": "Rock_Acid_Trunk_Orange"
    },
    {
      "x": -4,
      "y": 31,
      "z": 6,
      "name": "Rock_Acid_Trunk_Orange"
    },
    {
      "x": -4,
      "y": 32,
      "z": 6,
      "name": "Rock_Acid_Trunk_Crimson"
    },
    {
      "x": -4,
      "y": 33,
      "z": 6,
      "name": "Rock_Acid_Trunk_Crimson"
    },
    {
      "x": -4,
      "y": 34,
      "z": 6,
      "name": "Rock_Acid_Trunk_Crimson"
    },
    {
      "x": -4,
      "y": 35,
      "z": 6,
      "name": "Rock_Acid_Trunk_Magenta"
    },
    {
      "x": -3,
      "y": 22,
      "z": -7,
      "name": "Rock_Acid_Trunk_Crimson"
    },
    {
      "x": -3,
      "y": 21,
      "z": -6,
      "name": "Rock_Acid_Trunk_Orange"
    },
    {
      "x": -3,
      "y": 22,
      "z": -6,
      "name": "Empty"
    },
    {
      "x": -3,
      "y": 20,
      "z": -5,
      "name": "Rock_Acid_Trunk_Bright"
    },
    {
      "x": -3,
      "y": 21,
      "z": -5,
      "name": "Rock_Acid_Trunk_Crimson"
    },
    {
      "x": -3,
      "y": 22,
      "z": -5,
      "name": "Empty"
    },
    {
      "x": -3,
      "y": 25,
      "z": -5,
      "name": "Rock_Acid_Trunk_Magenta"
    },
    {
      "x": -3,
      "y": 0,
      "z": -4,
      "name": "Rock_Acid_Trunk_Light"
    },
    {
      "x": -3,
      "y": 1,
      "z": -4,
      "name": "Rock_Acid_Trunk_Light"
    },
    {
      "x": -3,
      "y": 2,
      "z": -4,
      "name": "Rock_Acid_Trunk_Light"
    },
    {
      "x": -3,
      "y": 3,
      "z": -4,
      "name": "Rock_Acid_Trunk_Medium"
    },
    {
      "x": -3,
      "y": 4,
      "z": -4,
      "name": "Rock_Acid_Trunk_Medium"
    },
    {
      "x": -3,
      "y": 5,
      "z": -4,
      "name": "Rock_Acid_Trunk_Medium"
    },
    {
      "x": -3,
      "y": 6,
      "z": -4,
      "name": "Rock_Acid_Trunk_Medium"
    },
    {
      "x": -3,
      "y": 7,
      "z": -4,
      "name": "Rock_Acid_Trunk_Medium"
    },
    {
      "x": -3,
      "y": 8,
      "z": -4,
      "name": "Rock_Acid_Trunk_Standard"
    },
    {
      "x": -3,
      "y": 20,
      "z": -4,
      "name": "Rock_Acid_Trunk_Bright"
    },
    {
      "x": -3,
      "y": 21,
      "z": -4,
      "name": "Rock_Acid_Trunk_Crimson"
    },
    {
      "x": -3,
      "y": 22,
      "z": -4,
      "name": "Empty"
    },
    {
      "x": -3,
      "y": 0,
      "z": -3,
      "name": "Rock_Acid_Trunk_Light"
    },
    {
      "x": -3,
      "y": 1,
      "z": -3,
      "name": "Rock_Acid_Trunk_Light"
    },
    {
      "x": -3,
      "y": 2,
      "z": -3,
      "name": "Rock_Acid_Trunk_Medium"
    },
    {
      "x": -3,
      "y": 3,
      "z": -3,
      "name": "Rock_Acid_Trunk_Medium"
    },
    {
      "x": -3,
      "y": 4,
      "z": -3,
      "name": "Rock_Acid_Trunk_Medium"
    },
    {
      "x": -3,
      "y": 5,
      "z": -3,
      "name": "Rock_Acid_Trunk_Medium"
    },
    {
      "x": -3,
      "y": 6,
      "z": -3,
      "name": "Rock_Acid_Trunk_Medium"
    },
    {
      "x": -3,
      "y": 7,
      "z": -3,
      "name": "Rock_Acid_Trunk_Medium"
    },
    {
      "x": -3,
      "y": 8,
      "z": -3,
      "name": "Rock_Acid_Trunk_Medium"
    },
    {
      "x": -3,
      "y": 9,
      "z": -3,
      "name": "Rock_Acid_Trunk_Standard"
    },
    {
      "x": -3,
      "y": 20,
      "z": -3,
      "name": "Rock_Acid_Trunk_Bright"
    },
    {
      "x": -3,
      "y": 21,
      "z": -3,
      "name": "Rock_Acid_Trunk_Crimson"
    },
    {
      "x": -3,
      "y": 22,
      "z": -3,
      "name": "Empty"
    },
    {
      "x": -3,
      "y": 21,
      "z": -2,
      "name": "Rock_Acid_Trunk_Orange"
    },
    {
      "x": -3,
      "y": 22,
      "z": -2,
      "name": "Rock_Acid_Trunk_Crimson"
    },
    {
      "x": -3,
      "y": 23,
      "z": -2,
      "name": "Rock_Acid_Trunk_Magenta"
    },
    {
      "x": -3,
      "y": 33,
      "z": -2,
      "name": "Rock_Acid_Trunk_Crimson"
    },
    {
      "x": -3,
      "y": 30,
      "z": -1,
      "name": "Rock_Acid_Trunk_Orange"
    },
    {
      "x": -3,
      "y": 31,
      "z": -1,
      "name": "Rock_Acid_Trunk_Orange"
    },
    {
      "x": -3,
      "y": 32,
      "z": -1,
      "name": "Rock_Acid_Trunk_Crimson"
    },
    {
      "x": -3,
      "y": 33,
      "z": -1,
      "name": "Rock_Acid_Trunk_Magenta"
    },
    {
      "x": -3,
      "y": 6,
      "z": 0,
      "name": "Rock_Acid_Trunk_Medium"
    },
    {
      "x": -3,
      "y": 7,
      "z": 0,
      "name": "Rock_Acid_Trunk_Medium"
    },
    {
      "x": -3,
      "y": 8,
      "z": 0,
      "name": "Rock_Acid_Trunk_Medium"
    },
    {
      "x": -3,
      "y": 9,
      "z": 0,
      "name": "Rock_Acid_Trunk_Standard"
    },
    {
      "x": -3,
      "y": 10,
      "z": 0,
      "name": "Rock_Acid_Trunk_Standard"
    },
    {
      "x": -3,
      "y": 15,
      "z": 0,
      "name": "Rock_Acid_Trunk_Bright"
    },
    {
      "x": -3,
      "y": 16,
      "z": 0,
      "name": "Rock_Acid_Trunk_Bright"
    },
    {
      "x": -3,
      "y": 26,
      "z": 0,
      "name": "Rock_Acid_Trunk_Bright"
    },
    {
      "x": -3,
      "y": 27,
      "z": 0,
      "name": "Rock_Acid_Trunk_Bright"
    },
    {
      "x": -3,
      "y": 28,
      "z": 0,
      "name": "Rock_Acid_Trunk_Orange"
    },
    {
      "x": -3,
      "y": 29,
      "z": 0,
      "name": "Rock_Acid_Trunk_Orange"
    },
    {
      "x": -3,
      "y": 30,
      "z": 0,
      "name": "Rock_Acid_Trunk_Orange"
    },
    {
      "x": -3,
      "y": 31,
      "z": 0,
      "name": "Rock_Acid_Trunk_Medium"
    },
    {
      "x": -3,
      "y": 32,
      "z": 0,
      "name": "Rock_Acid_Trunk_Crimson"
    },
    {
      "x": -3,
      "y": 33,
      "z": 0,
      "name": "Empty"
    },
    {
      "x": -3,
      "y": 6,
      "z": 1,
      "name": "Rock_Acid_Trunk_Medium"
    },
    {
      "x": -3,
      "y": 7,
      "z": 1,
      "name": "Rock_Acid_Trunk_Medium"
    },
    {
      "x": -3,
      "y": 8,
      "z": 1,
      "name": "Rock_Acid_Trunk_Medium"
    },
    {
      "x": -3,
      "y": 9,
      "z": 1,
      "name": "Rock_Acid_Trunk_Standard"
    },
    {
      "x": -3,
      "y": 10,
      "z": 1,
      "name": "Rock_Acid_Trunk_Standard"
    },
    {
      "x": -3,
      "y": 12,
      "z": 1,
      "name": "Rock_Acid_Trunk_Bright"
    },
    {
      "x": -3,
      "y": 13,
      "z": 1,
      "name": "Rock_Acid_Trunk_Bright"
    },
    {
      "x": -3,
      "y": 14,
      "z": 1,
      "name": "Rock_Acid_Trunk_Bright"
    },
    {
      "x": -3,
      "y": 15,
      "z": 1,
      "name": "Rock_Acid_Trunk_Bright"
    },
    {
      "x": -3,
      "y": 16,
      "z": 1,
      "name": "Rock_Acid_Trunk_Bright"
    },
    {
      "x": -3,
      "y": 17,
      "z": 1,
      "name": "Rock_Acid_Trunk_Bright"
    },
    {
      "x": -3,
      "y": 22,
      "z": 1,
      "name": "Rock_Acid_Trunk_Bright"
    },
    {
      "x": -3,
      "y": 23,
      "z": 1,
      "name": "Rock_Acid_Trunk_Bright"
    },
    {
      "x": -3,
      "y": 24,
      "z": 1,
      "name": "Rock_Acid_Trunk_Bright"
    },
    {
      "x": -3,
      "y": 25,
      "z": 1,
      "name": "Rock_Acid_Trunk_Bright"
    },
    {
      "x": -3,
      "y": 26,
      "z": 1,
      "name": "Rock_Acid_Trunk_Bright"
    },
    {
      "x": -3,
      "y": 27,
      "z": 1,
      "name": "Rock_Acid_Trunk_Bright"
    },
    {
      "x": -3,
      "y": 28,
      "z": 1,
      "name": "Rock_Acid_Trunk_Medium"
    },
    {
      "x": -3,
      "y": 29,
      "z": 1,
      "name": "Rock_Acid_Trunk_Medium"
    },
    {
      "x": -3,
      "y": 30,
      "z": 1,
      "name": "Rock_Acid_Trunk_Medium"
    },
    {
      "x": -3,
      "y": 31,
      "z": 1,
      "name": "Rock_Acid_Trunk_Crimson"
    },
    {
      "x": -3,
      "y": 32,
      "z": 1,
      "name": "Rock_Crystal_Green_Block",
      "rotation": 5
    },
    {
      "x": -3,
      "y": 33,
      "z": 1,
      "name": "Empty"
    },
    {
      "x": -3,
      "y": 12,
      "z": 2,
      "name": "Rock_Acid_Trunk_Bright"
    },
    {
      "x": -3,
      "y": 13,
      "z": 2,
      "name": "Rock_Acid_Trunk_Bright"
    },
    {
      "x": -3,
      "y": 14,
      "z": 2,
      "name": "Rock_Acid_Trunk_Bright"
    },
    {
      "x": -3,
      "y": 15,
      "z": 2,
      "name": "Rock_Acid_Trunk_Bright"
    },
    {
      "x": -3,
      "y": 16,
      "z": 2,
      "name": "Rock_Acid_Trunk_Bright"
    },
    {
      "x": -3,
      "y": 17,
      "z": 2,
      "name": "Rock_Acid_Trunk_Bright"
    },
    {
      "x": -3,
      "y": 18,
      "z": 2,
      "name": "Rock_Acid_Trunk_Bright"
    },
    {
      "x": -3,
      "y": 21,
      "z": 2,
      "name": "Rock_Acid_Trunk_Bright"
    },
    {
      "x": -3,
      "y": 22,
      "z": 2,
      "name": "Rock_Acid_Trunk_Bright"
    },
    {
      "x": -3,
      "y": 23,
      "z": 2,
      "name": "Rock_Acid_Trunk_Bright"
    },
    {
      "x": -3,
      "y": 24,
      "z": 2,
      "name": "Rock_Acid_Trunk_Bright"
    },
    {
      "x": -3,
      "y": 25,
      "z": 2,
      "name": "Rock_Acid_Trunk_Bright"
    },
    {
      "x": -3,
      "y": 26,
      "z": 2,
      "name": "Rock_Acid_Trunk_Medium"
    },
    {
      "x": -3,
      "y": 27,
      "z": 2,
      "name": "Rock_Acid_Trunk_Medium"
    },
    {
      "x": -3,
      "y": 28,
      "z": 2,
      "name": "Rock_Acid_Trunk_Medium"
    },
    {
      "x": -3,
      "y": 29,
      "z": 2,
      "name": "Rock_Acid_Trunk_Medium"
    },
    {
      "x": -3,
      "y": 30,
      "z": 2,
      "name": "Rock_Acid_Trunk_Medium"
    },
    {
      "x": -3,
      "y": 31,
      "z": 2,
      "name": "Rock_Acid_Trunk_Crimson"
    },
    {
      "x": -3,
      "y": 32,
      "z": 2,
      "name": "Rock_Crystal_Green_Block",
      "rotation": 5
    },
    {
      "x": -3,
      "y": 33,
      "z": 2,
      "name": "Empty"
    },
    {
      "x": -3,
      "y": 13,
      "z": 3,
      "name": "Rock_Acid_Trunk_Bright"
    },
    {
      "x": -3,
      "y": 14,
      "z": 3,
      "name": "Rock_Acid_Trunk_Bright"
    },
    {
      "x": -3,
      "y": 15,
      "z": 3,
      "name": "Rock_Acid_Trunk_Bright"
    },
    {
      "x": -3,
      "y": 16,
      "z": 3,
      "name": "Rock_Acid_Trunk_Bright"
    },
    {
      "x": -3,
      "y": 17,
      "z": 3,
      "name": "Rock_Acid_Trunk_Bright"
    },
    {
      "x": -3,
      "y": 18,
      "z": 3,
      "name": "Rock_Acid_Trunk_Bright"
    },
    {
      "x": -3,
      "y": 19,
      "z": 3,
      "name": "Rock_Acid_Trunk_Bright"
    },
    {
      "x": -3,
      "y": 21,
      "z": 3,
      "name": "Rock_Acid_Trunk_Bright"
    },
    {
      "x": -3,
      "y": 22,
      "z": 3,
      "name": "Rock_Acid_Trunk_Bright"
    },
    {
      "x": -3,
      "y": 23,
      "z": 3,
      "name": "Rock_Acid_Trunk_Bright"
    },
    {
      "x": -3,
      "y": 24,
      "z": 3,
      "name": "Rock_Acid_Trunk_Bright"
    },
    {
      "x": -3,
      "y": 25,
      "z": 3,
      "name": "Rock_Acid_Trunk_Medium"
    },
    {
      "x": -3,
      "y": 26,
      "z": 3,
      "name": "Rock_Acid_Trunk_Medium"
    },
    {
      "x": -3,
      "y": 27,
      "z": 3,
      "name": "Rock_Acid_Trunk_Medium"
    },
    {
      "x": -3,
      "y": 28,
      "z": 3,
      "name": "Rock_Acid_Trunk_Medium"
    },
    {
      "x": -3,
      "y": 29,
      "z": 3,
      "name": "Rock_Acid_Trunk_Medium"
    },
    {
      "x": -3,
      "y": 30,
      "z": 3,
      "name": "Rock_Acid_Trunk_Medium"
    },
    {
      "x": -3,
      "y": 31,
      "z": 3,
      "name": "Rock_Acid_Trunk_Crimson"
    },
    {
      "x": -3,
      "y": 32,
      "z": 3,
      "name": "Rock_Crystal_Green_Block",
      "rotation": 5
    },
    {
      "x": -3,
      "y": 33,
      "z": 3,
      "name": "Empty"
    },
    {
      "x": -3,
      "y": 14,
      "z": 4,
      "name": "Rock_Acid_Trunk_Bright"
    },
    {
      "x": -3,
      "y": 15,
      "z": 4,
      "name": "Rock_Acid_Trunk_Bright"
    },
    {
      "x": -3,
      "y": 16,
      "z": 4,
      "name": "Rock_Acid_Trunk_Bright"
    },
    {
      "x": -3,
      "y": 17,
      "z": 4,
      "name": "Rock_Acid_Trunk_Bright"
    },
    {
      "x": -3,
      "y": 18,
      "z": 4,
      "name": "Rock_Acid_Trunk_Bright"
    },
    {
      "x": -3,
      "y": 19,
      "z": 4,
      "name": "Rock_Acid_Trunk_Bright"
    },
    {
      "x": -3,
      "y": 21,
      "z": 4,
      "name": "Rock_Acid_Trunk_Bright"
    },
    {
      "x": -3,
      "y": 22,
      "z": 4,
      "name": "Rock_Acid_Trunk_Bright"
    },
    {
      "x": -3,
      "y": 23,
      "z": 4,
      "name": "Rock_Acid_Trunk_Bright"
    },
    {
      "x": -3,
      "y": 24,
      "z": 4,
      "name": "Rock_Acid_Trunk_Bright"
    },
    {
      "x": -3,
      "y": 25,
      "z": 4,
      "name": "Rock_Acid_Trunk_Medium"
    },
    {
      "x": -3,
      "y": 26,
      "z": 4,
      "name": "Rock_Acid_Trunk_Medium"
    },
    {
      "x": -3,
      "y": 27,
      "z": 4,
      "name": "Rock_Acid_Trunk_Medium"
    },
    {
      "x": -3,
      "y": 28,
      "z": 4,
      "name": "Rock_Acid_Trunk_Medium"
    },
    {
      "x": -3,
      "y": 29,
      "z": 4,
      "name": "Rock_Acid_Trunk_Medium"
    },
    {
      "x": -3,
      "y": 30,
      "z": 4,
      "name": "Rock_Acid_Trunk_Medium"
    },
    {
      "x": -3,
      "y": 31,
      "z": 4,
      "name": "Rock_Acid_Trunk_Crimson"
    },
    {
      "x": -3,
      "y": 32,
      "z": 4,
      "name": "Rock_Crystal_Green_Block",
      "rotation": 5
    },
    {
      "x": -3,
      "y": 33,
      "z": 4,
      "name": "Empty"
    },
    {
      "x": -3,
      "y": 16,
      "z": 5,
      "name": "Rock_Acid_Trunk_Bright"
    },
    {
      "x": -3,
      "y": 17,
      "z": 5,
      "name": "Rock_Acid_Trunk_Bright"
    },
    {
      "x": -3,
      "y": 18,
      "z": 5,
      "name": "Rock_Acid_Trunk_Bright"
    },
    {
      "x": -3,
      "y": 22,
      "z": 5,
      "name": "Rock_Acid_Trunk_Bright"
    },
    {
      "x": -3,
      "y": 23,
      "z": 5,
      "name": "Rock_Acid_Trunk_Bright"
    },
    {
      "x": -3,
      "y": 24,
      "z": 5,
      "name": "Rock_Acid_Trunk_Bright"
    },
    {
      "x": -3,
      "y": 25,
      "z": 5,
      "name": "Rock_Acid_Trunk_Bright"
    },
    {
      "x": -3,
      "y": 26,
      "z": 5,
      "name": "Rock_Acid_Trunk_Medium"
    },
    {
      "x": -3,
      "y": 27,
      "z": 5,
      "name": "Rock_Acid_Trunk_Medium"
    },
    {
      "x": -3,
      "y": 28,
      "z": 5,
      "name": "Rock_Acid_Trunk_Medium"
    },
    {
      "x": -3,
      "y": 29,
      "z": 5,
      "name": "Rock_Acid_Trunk_Medium"
    },
    {
      "x": -3,
      "y": 30,
      "z": 5,
      "name": "Rock_Acid_Trunk_Medium"
    },
    {
      "x": -3,
      "y": 31,
      "z": 5,
      "name": "Rock_Acid_Trunk_Crimson"
    },
    {
      "x": -3,
      "y": 32,
      "z": 5,
      "name": "Rock_Crystal_Green_Block",
      "rotation": 5
    },
    {
      "x": -3,
      "y": 33,
      "z": 5,
      "name": "Empty"
    },
    {
      "x": -3,
      "y": 24,
      "z": 6,
      "name": "Rock_Acid_Trunk_Bright"
    },
    {
      "x": -3,
      "y": 25,
      "z": 6,
      "name": "Rock_Acid_Trunk_Bright"
    },
    {
      "x": -3,
      "y": 26,
      "z": 6,
      "name": "Rock_Acid_Trunk_Bright"
    },
    {
      "x": -3,
      "y": 27,
      "z": 6,
      "name": "Rock_Acid_Trunk_Bright"
    },
    {
      "x": -3,
      "y": 28,
      "z": 6,
      "name": "Rock_Acid_Trunk_Orange"
    },
    {
      "x": -3,
      "y": 29,
      "z": 6,
      "name": "Rock_Acid_Trunk_Orange"
    },
    {
      "x": -3,
      "y": 30,
      "z": 6,
      "name": "Rock_Acid_Trunk_Orange"
    },
    {
      "x": -3,
      "y": 31,
      "z": 6,
      "name": "Rock_Acid_Trunk_Crimson"
    },
    {
      "x": -3,
      "y": 32,
      "z": 6,
      "name": "Rock_Acid_Trunk_Crimson"
    },
    {
      "x": -3,
      "y": 33,
      "z": 6,
      "name": "Rock_Acid_Trunk_Crimson"
    },
    {
      "x": -3,
      "y": 32,
      "z": 7,
      "name": "Rock_Acid_Trunk_Crimson"
    },
    {
      "x": -3,
      "y": 33,
      "z": 7,
      "name": "Rock_Acid_Trunk_Crimson"
    },
    {
      "x": -3,
      "y": 34,
      "z": 7,
      "name": "Rock_Acid_Trunk_Crimson"
    },
    {
      "x": -2,
      "y": 22,
      "z": -8,
      "name": "Rock_Acid_Trunk_Crimson"
    },
    {
      "x": -2,
      "y": 21,
      "z": -7,
      "name": "Rock_Acid_Trunk_Orange"
    },
    {
      "x": -2,
      "y": 22,
      "z": -7,
      "name": "Empty"
    },
    {
      "x": -2,
      "y": 20,
      "z": -6,
      "name": "Rock_Acid_Trunk_Bright"
    },
    {
      "x": -2,
      "y": 21,
      "z": -6,
      "name": "Rock_Acid_Trunk_Crimson"
    },
    {
      "x": -2,
      "y": 22,
      "z": -6,
      "name": "Empty"
    },
    {
      "x": -2,
      "y": 19,
      "z": -5,
      "name": "Rock_Acid_Trunk_Medium"
    },
    {
      "x": -2,
      "y": 20,
      "z": -5,
      "name": "Rock_Acid_Trunk_Orange"
    },
    {
      "x": -2,
      "y": 21,
      "z": -5,
      "name": "Rock_Crystal_Green_Block",
      "rotation": 4
    },
    {
      "x": -2,
      "y": 22,
      "z": -5,
      "name": "Empty"
    },
    {
      "x": -2,
      "y": 0,
      "z": -4,
      "name": "Rock_Acid_Trunk_Light"
    },
    {
      "x": -2,
      "y": 1,
      "z": -4,
      "name": "Rock_Acid_Trunk_Medium"
    },
    {
      "x": -2,
      "y": 2,
      "z": -4,
      "name": "Rock_Acid_Trunk_Medium"
    },
    {
      "x": -2,
      "y": 3,
      "z": -4,
      "name": "Rock_Acid_Trunk_Medium"
    },
    {
      "x": -2,
      "y": 4,
      "z": -4,
      "name": "Rock_Acid_Trunk_Medium"
    },
    {
      "x": -2,
      "y": 5,
      "z": -4,
      "name": "Rock_Acid_Trunk_Medium"
    },
    {
      "x": -2,
      "y": 6,
      "z": -4,
      "name": "Rock_Acid_Trunk_Medium"
    },
    {
      "x": -2,
      "y": 7,
      "z": -4,
      "name": "Rock_Acid_Trunk_Medium"
    },
    {
      "x": -2,
      "y": 8,
      "z": -4,
      "name": "Rock_Acid_Trunk_Medium"
    },
    {
      "x": -2,
      "y": 9,
      "z": -4,
      "name": "Rock_Acid_Trunk_Standard"
    },
    {
      "x": -2,
      "y": 18,
      "z": -4,
      "name": "Rock_Acid_Trunk_Medium"
    },
    {
      "x": -2,
      "y": 19,
      "z": -4,
      "name": "Rock_Acid_Trunk_Bright"
    },
    {
      "x": -2,
      "y": 20,
      "z": -4,
      "name": "Rock_Acid_Trunk_Crimson"
    },
    {
      "x": -2,
      "y": 21,
      "z": -4,
      "name": "Rock_Crystal_Green_Block",
      "rotation": 4
    },
    {
      "x": -2,
      "y": 22,
      "z": -4,
      "name": "Empty"
    },
    {
      "x": -2,
      "y": 0,
      "z": -3,
      "name": "Rock_Acid_Trunk_Light"
    },
    {
      "x": -2,
      "y": 1,
      "z": -3,
      "name": "Rock_Acid_Trunk_Medium"
    },
    {
      "x": -2,
      "y": 2,
      "z": -3,
      "name": "Rock_Acid_Trunk_Medium"
    },
    {
      "x": -2,
      "y": 3,
      "z": -3,
      "name": "Rock_Acid_Trunk_Medium"
    },
    {
      "x": -2,
      "y": 4,
      "z": -3,
      "name": "Rock_Acid_Trunk_Medium"
    },
    {
      "x": -2,
      "y": 5,
      "z": -3,
      "name": "Rock_Acid_Trunk_Medium"
    },
    {
      "x": -2,
      "y": 6,
      "z": -3,
      "name": "Rock_Acid_Trunk_Medium"
    },
    {
      "x": -2,
      "y": 7,
      "z": -3,
      "name": "Rock_Acid_Trunk_Medium"
    },
    {
      "x": -2,
      "y": 8,
      "z": -3,
      "name": "Rock_Acid_Trunk_Medium"
    },
    {
      "x": -2,
      "y": 9,
      "z": -3,
      "name": "Rock_Acid_Trunk_Medium"
    },
    {
      "x": -2,
      "y": 10,
      "z": -3,
      "name": "Rock_Acid_Trunk_Standard"
    },
    {
      "x": -2,
      "y": 11,
      "z": -3,
      "name": "Rock_Acid_Trunk_Standard"
    },
    {
      "x": -2,
      "y": 18,
      "z": -3,
      "name": "Rock_Acid_Trunk_Bright"
    },
    {
      "x": -2,
      "y": 19,
      "z": -3,
      "name": "Rock_Acid_Trunk_Bright"
    },
    {
      "x": -2,
      "y": 20,
      "z": -3,
      "name": "Rock_Acid_Trunk_Crimson"
    },
    {
      "x": -2,
      "y": 21,
      "z": -3,
      "name": "Rock_Crystal_Green_Block",
      "rotation": 4
    },
    {
      "x": -2,
      "y": 22,
      "z": -3,
      "name": "Empty"
    },
    {
      "x": -2,
      "y": 33,
      "z": -3,
      "name": "Rock_Acid_Trunk_Crimson"
    },
    {
      "x": -2,
      "y": 34,
      "z": -3,
      "name": "Rock_Acid_Trunk_Magenta"
    },
    {
      "x": -2,
      "y": 9,
      "z": -2,
      "name": "Rock_Acid_Trunk_Medium"
    },
    {
      "x": -2,
      "y": 10,
      "z": -2,
      "name": "Rock_Acid_Trunk_Standard"
    },
    {
      "x": -2,
      "y": 19,
      "z": -2,
      "name": "Rock_Acid_Trunk_Orange"
    },
    {
      "x": -2,
      "y": 20,
      "z": -2,
      "name": "Rock_Acid_Trunk_Orange"
    },
    {
      "x": -2,
      "y": 21,
      "z": -2,
      "name": "Rock_Acid_Trunk_Crimson"
    },
    {
      "x": -2,
      "y": 22,
      "z": -2,
      "name": "Empty"
    },
    {
      "x": -2,
      "y": 30,
      "z": -2,
      "name": "Rock_Acid_Trunk_Orange"
    },
    {
      "x": -2,
      "y": 31,
      "z": -2,
      "name": "Rock_Acid_Trunk_Orange"
    },
    {
      "x": -2,
      "y": 32,
      "z": -2,
      "name": "Rock_Acid_Trunk_Crimson"
    },
    {
      "x": -2,
      "y": 33,
      "z": -2,
      "name": "Rock_Acid_Trunk_Crimson"
    },
    {
      "x": -2,
      "y": 13,
      "z": -1,
      "name": "Rock_Acid_Trunk_Bright"
    },
    {
      "x": -2,
      "y": 14,
      "z": -1,
      "name": "Rock_Acid_Trunk_Bright"
    },
    {
      "x": -2,
      "y": 15,
      "z": -1,
      "name": "Rock_Acid_Trunk_Bright"
    },
    {
      "x": -2,
      "y": 20,
      "z": -1,
      "name": "Rock_Acid_Trunk_Orange"
    },
    {
      "x": -2,
      "y": 21,
      "z": -1,
      "name": "Rock_Acid_Trunk_Orange"
    },
    {
      "x": -2,
      "y": 22,
      "z": -1,
      "name": "Rock_Acid_Trunk_Crimson"
    },
    {
      "x": -2,
      "y": 27,
      "z": -1,
      "name": "Rock_Acid_Trunk_Bright"
    },
    {
      "x": -2,
      "y": 28,
      "z": -1,
      "name": "Rock_Acid_Trunk_Bright"
    },
    {
      "x": -2,
      "y": 29,
      "z": -1,
      "name": "Rock_Acid_Trunk_Bright"
    },
    {
      "x": -2,
      "y": 30,
      "z": -1,
      "name": "Rock_Acid_Trunk_Medium"
    },
    {
      "x": -2,
      "y": 31,
      "z": -1,
      "name": "Rock_Acid_Trunk_Medium"
    },
    {
      "x": -2,
      "y": 32,
      "z": -1,
      "name": "Rock_Acid_Trunk_Crimson"
    },
    {
      "x": -2,
      "y": 33,
      "z": -1,
      "name": "Empty"
    },
    {
      "x": -2,
      "y": 7,
      "z": 0,
      "name": "Rock_Acid_Trunk_Medium"
    },
    {
      "x": -2,
      "y": 8,
      "z": 0,
      "name": "Rock_Acid_Trunk_Medium"
    },
    {
      "x": -2,
      "y": 9,
      "z": 0,
      "name": "Rock_Acid_Trunk_Medium"
    },
    {
      "x": -2,
      "y": 10,
      "z": 0,
      "name": "Rock_Acid_Trunk_Standard"
    },
    {
      "x": -2,
      "y": 11,
      "z": 0,
      "name": "Rock_Acid_Trunk_Medium"
    },
    {
      "x": -2,
      "y": 13,
      "z": 0,
      "name": "Rock_Acid_Trunk_Bright"
    },
    {
      "x": -2,
      "y": 14,
      "z": 0,
      "name": "Rock_Acid_Trunk_Bright"
    },
    {
      "x": -2,
      "y": 15,
      "z": 0,
      "name": "Rock_Acid_Trunk_Medium"
    },
    {
      "x": -2,
      "y": 16,
      "z": 0,
      "name": "Rock_Acid_Trunk_Bright"
    },
    {
      "x": -2,
      "y": 17,
      "z": 0,
      "name": "Rock_Acid_Trunk_Bright"
    },
    {
      "x": -2,
      "y": 23,
      "z": 0,
      "name": "Rock_Acid_Trunk_Bright"
    },
    {
      "x": -2,
      "y": 24,
      "z": 0,
      "name": "Rock_Acid_Trunk_Bright"
    },
    {
      "x": -2,
      "y": 25,
      "z": 0,
      "name": "Rock_Acid_Trunk_Bright"
    },
    {
      "x": -2,
      "y": 26,
      "z": 0,
      "name": "Rock_Acid_Trunk_Orange"
    },
    {
      "x": -2,
      "y": 27,
      "z": 0,
      "name": "Rock_Acid_Trunk_Medium"
    },
    {
      "x": -2,
      "y": 28,
      "z": 0,
      "name": "Rock_Acid_Trunk_Medium"
    },
    {
      "x": -2,
      "y": 29,
      "z": 0,
      "name": "Rock_Acid_Trunk_Medium"
    },
    {
      "x": -2,
      "y": 30,
      "z": 0,
      "name": "Rock_Acid_Trunk_Medium"
    },
    {
      "x": -2,
      "y": 31,
      "z": 0,
      "name": "Rock_Acid_Trunk_Crimson"
    },
    {
      "x": -2,
      "y": 32,
      "z": 0,
      "name": "Rock_Crystal_Green_Block",
      "rotation": 5
    },
    {
      "x": -2,
      "y": 33,
      "z": 0,
      "name": "Empty"
    },
    {
      "x": -2,
      "y": 7,
      "z": 1,
      "name": "Rock_Acid_Trunk_Medium"
    },
    {
      "x": -2,
      "y": 8,
      "z": 1,
      "name": "Rock_Acid_Trunk_Medium"
    },
    {
      "x": -2,
      "y": 9,
      "z": 1,
      "name": "Rock_Acid_Trunk_Medium"
    },
    {
      "x": -2,
      "y": 10,
      "z": 1,
      "name": "Rock_Acid_Trunk_Medium"
    },
    {
      "x": -2,
      "y": 11,
      "z": 1,
      "name": "Rock_Acid_Trunk_Medium"
    },
    {
      "x": -2,
      "y": 12,
      "z": 1,
      "name": "Rock_Acid_Trunk_Bright"
    },
    {
      "x": -2,
      "y": 13,
      "z": 1,
      "name": "Rock_Acid_Trunk_Medium"
    },
    {
      "x": -2,
      "y": 14,
      "z": 1,
      "name": "Rock_Acid_Trunk_Medium"
    },
    {
      "x": -2,
      "y": 15,
      "z": 1,
      "name": "Rock_Acid_Trunk_Medium"
    },
    {
      "x": -2,
      "y": 16,
      "z": 1,
      "name": "Rock_Acid_Trunk_Medium"
    },
    {
      "x": -2,
      "y": 17,
      "z": 1,
      "name": "Rock_Acid_Trunk_Medium"
    },
    {
      "x": -2,
      "y": 18,
      "z": 1,
      "name": "Rock_Acid_Trunk_Bright"
    },
    {
      "x": -2,
      "y": 19,
      "z": 1,
      "name": "Rock_Acid_Trunk_Bright"
    },
    {
      "x": -2,
      "y": 21,
      "z": 1,
      "name": "Rock_Acid_Trunk_Bright"
    },
    {
      "x": -2,
      "y": 22,
      "z": 1,
      "name": "Rock_Acid_Trunk_Bright"
    },
    {
      "x": -2,
      "y": 23,
      "z": 1,
      "name": "Rock_Acid_Trunk_Medium"
    },
    {
      "x": -2,
      "y": 24,
      "z": 1,
      "name": "Rock_Acid_Trunk_Medium"
    },
    {
      "x": -2,
      "y": 25,
      "z": 1,
      "name": "Rock_Acid_Trunk_Medium"
    },
    {
      "x": -2,
      "y": 26,
      "z": 1,
      "name": "Rock_Acid_Trunk_Medium"
    },
    {
      "x": -2,
      "y": 27,
      "z": 1,
      "name": "Rock_Acid_Trunk_Medium"
    },
    {
      "x": -2,
      "y": 28,
      "z": 1,
      "name": "Rock_Acid_Trunk_Medium"
    },
    {
      "x": -2,
      "y": 29,
      "z": 1,
      "name": "Rock_Acid_Trunk_Medium"
    },
    {
      "x": -2,
      "y": 30,
      "z": 1,
      "name": "Rock_Acid_Trunk_Medium"
    },
    {
      "x": -2,
      "y": 31,
      "z": 1,
      "name": "Rock_Acid_Trunk_Crimson"
    },
    {
      "x": -2,
      "y": 32,
      "z": 1,
      "name": "Rock_Crystal_Green_Block",
      "rotation": 5
    },
    {
      "x": -2,
      "y": 33,
      "z": 1,
      "name": "Empty"
    },
    {
      "x": -2,
      "y": 7,
      "z": 2,
      "name": "Rock_Acid_Trunk_Medium"
    },
    {
      "x": -2,
      "y": 8,
      "z": 2,
      "name": "Rock_Acid_Trunk_Medium"
    },
    {
      "x": -2,
      "y": 9,
      "z": 2,
      "name": "Rock_Acid_Trunk_Medium"
    },
    {
      "x": -2,
      "y": 10,
      "z": 2,
      "name": "Rock_Acid_Trunk_Medium"
    },
    {
      "x": -2,
      "y": 11,
      "z": 2,
      "name": "Rock_Acid_Trunk_Medium"
    },
    {
      "x": -2,
      "y": 12,
      "z": 2,
      "name": "Rock_Acid_Trunk_Medium"
    },
    {
      "x": -2,
      "y": 13,
      "z": 2,
      "name": "Rock_Acid_Trunk_Medium"
    },
    {
      "x": -2,
      "y": 14,
      "z": 2,
      "name": "Rock_Acid_Trunk_Medium"
    },
    {
      "x": -2,
      "y": 15,
      "z": 2,
      "name": "Rock_Acid_Trunk_Medium"
    },
    {
      "x": -2,
      "y": 16,
      "z": 2,
      "name": "Rock_Acid_Trunk_Medium"
    },
    {
      "x": -2,
      "y": 17,
      "z": 2,
      "name": "Rock_Acid_Trunk_Medium"
    },
    {
      "x": -2,
      "y": 18,
      "z": 2,
      "name": "Rock_Acid_Trunk_Medium"
    },
    {
      "x": -2,
      "y": 19,
      "z": 2,
      "name": "Rock_Acid_Trunk_Bright"
    },
    {
      "x": -2,
      "y": 20,
      "z": 2,
      "name": "Rock_Acid_Trunk_Bright"
    },
    {
      "x": -2,
      "y": 21,
      "z": 2,
      "name": "Rock_Acid_Trunk_Medium"
    },
    {
      "x": -2,
      "y": 22,
      "z": 2,
      "name": "Rock_Acid_Trunk_Medium"
    },
    {
      "x": -2,
      "y": 23,
      "z": 2,
      "name": "Rock_Acid_Trunk_Medium"
    },
    {
      "x": -2,
      "y": 24,
      "z": 2,
      "name": "Rock_Acid_Trunk_Medium"
    },
    {
      "x": -2,
      "y": 25,
      "z": 2,
      "name": "Rock_Acid_Trunk_Medium"
    },
    {
      "x": -2,
      "y": 26,
      "z": 2,
      "name": "Rock_Acid_Trunk_Medium"
    },
    {
      "x": -2,
      "y": 27,
      "z": 2,
      "name": "Rock_Acid_Trunk_Medium"
    },
    {
      "x": -2,
      "y": 28,
      "z": 2,
      "name": "Rock_Acid_Trunk_Medium"
    },
    {
      "x": -2,
      "y": 29,
      "z": 2,
      "name": "Rock_Acid_Trunk_Medium"
    },
    {
      "x": -2,
      "y": 30,
      "z": 2,
      "name": "Rock_Acid_Trunk_Crimson"
    },
    {
      "x": -2,
      "y": 31,
      "z": 2,
      "name": "Rock_Crystal_Green_Block",
      "rotation": 5
    },
    {
      "x": -2,
      "y": 32,
      "z": 2,
      "name": "Rock_Crystal_Green_Block",
      "rotation": 5
    },
    {
      "x": -2,
      "y": 33,
      "z": 2,
      "name": "Empty"
    },
    {
      "x": -2,
      "y": 8,
      "z": 3,
      "name": "Rock_Acid_Trunk_Medium"
    },
    {
      "x": -2,
      "y": 9,
      "z": 3,
      "name": "Rock_Acid_Trunk_Medium"
    },
    {
      "x": -2,
      "y": 10,
      "z": 3,
      "name": "Rock_Acid_Trunk_Medium"
    },
    {
      "x": -2,
      "y": 11,
      "z": 3,
      "name": "Rock_Acid_Trunk_Medium"
    },
    {
      "x": -2,
      "y": 12,
      "z": 3,
      "name": "Rock_Acid_Trunk_Medium"
    },
    {
      "x": -2,
      "y": 13,
      "z": 3,
      "name": "Rock_Acid_Trunk_Medium"
    },
    {
      "x": -2,
      "y": 14,
      "z": 3,
      "name": "Rock_Acid_Trunk_Medium"
    },
    {
      "x": -2,
      "y": 15,
      "z": 3,
      "name": "Rock_Acid_Trunk_Medium"
    },
    {
      "x": -2,
      "y": 16,
      "z": 3,
      "name": "Rock_Acid_Trunk_Medium"
    },
    {
      "x": -2,
      "y": 17,
      "z": 3,
      "name": "Rock_Acid_Trunk_Medium"
    },
    {
      "x": -2,
      "y": 18,
      "z": 3,
      "name": "Rock_Acid_Trunk_Medium"
    },
    {
      "x": -2,
      "y": 19,
      "z": 3,
      "name": "Rock_Acid_Trunk_Medium"
    },
    {
      "x": -2,
      "y": 20,
      "z": 3,
      "name": "Rock_Acid_Trunk_Bright"
    },
    {
      "x": -2,
      "y": 21,
      "z": 3,
      "name": "Rock_Acid_Trunk_Medium"
    },
    {
      "x": -2,
      "y": 22,
      "z": 3,
      "name": "Rock_Acid_Trunk_Medium"
    },
    {
      "x": -2,
      "y": 23,
      "z": 3,
      "name": "Rock_Acid_Trunk_Medium"
    },
    {
      "x": -2,
      "y": 24,
      "z": 3,
      "name": "Rock_Acid_Trunk_Medium"
    },
    {
      "x": -2,
      "y": 25,
      "z": 3,
      "name": "Rock_Acid_Trunk_Medium"
    },
    {
      "x": -2,
      "y": 26,
      "z": 3,
      "name": "Rock_Acid_Trunk_Medium"
    },
    {
      "x": -2,
      "y": 27,
      "z": 3,
      "name": "Rock_Acid_Trunk_Medium"
    },
    {
      "x": -2,
      "y": 28,
      "z": 3,
      "name": "Rock_Acid_Trunk_Medium"
    },
    {
      "x": -2,
      "y": 29,
      "z": 3,
      "name": "Rock_Acid_Trunk_Medium"
    },
    {
      "x": -2,
      "y": 30,
      "z": 3,
      "name": "Rock_Acid_Trunk_Crimson"
    },
    {
      "x": -2,
      "y": 31,
      "z": 3,
      "name": "Rock_Crystal_Green_Block",
      "rotation": 5
    },
    {
      "x": -2,
      "y": 32,
      "z": 3,
      "name": "Rock_Crystal_Green_Block",
      "rotation": 5
    },
    {
      "x": -2,
      "y": 33,
      "z": 3,
      "name": "Empty"
    },
    {
      "x": -2,
      "y": 10,
      "z": 4,
      "name": "Rock_Acid_Trunk_Medium"
    },
    {
      "x": -2,
      "y": 11,
      "z": 4,
      "name": "Rock_Acid_Trunk_Medium"
    },
    {
      "x": -2,
      "y": 12,
      "z": 4,
      "name": "Rock_Acid_Trunk_Medium"
    },
    {
      "x": -2,
      "y": 13,
      "z": 4,
      "name": "Rock_Acid_Trunk_Medium"
    },
    {
      "x": -2,
      "y": 14,
      "z": 4,
      "name": "Rock_Acid_Trunk_Medium"
    },
    {
      "x": -2,
      "y": 15,
      "z": 4,
      "name": "Rock_Acid_Trunk_Medium"
    },
    {
      "x": -2,
      "y": 16,
      "z": 4,
      "name": "Rock_Acid_Trunk_Medium"
    },
    {
      "x": -2,
      "y": 17,
      "z": 4,
      "name": "Rock_Acid_Trunk_Medium"
    },
    {
      "x": -2,
      "y": 18,
      "z": 4,
      "name": "Rock_Acid_Trunk_Medium"
    },
    {
      "x": -2,
      "y": 19,
      "z": 4,
      "name": "Rock_Acid_Trunk_Medium"
    },
    {
      "x": -2,
      "y": 20,
      "z": 4,
      "name": "Rock_Acid_Trunk_Bright"
    },
    {
      "x": -2,
      "y": 21,
      "z": 4,
      "name": "Rock_Acid_Trunk_Medium"
    },
    {
      "x": -2,
      "y": 22,
      "z": 4,
      "name": "Rock_Acid_Trunk_Medium"
    },
    {
      "x": -2,
      "y": 23,
      "z": 4,
      "name": "Rock_Acid_Trunk_Medium"
    },
    {
      "x": -2,
      "y": 24,
      "z": 4,
      "name": "Rock_Acid_Trunk_Medium"
    },
    {
      "x": -2,
      "y": 25,
      "z": 4,
      "name": "Rock_Acid_Trunk_Medium"
    },
    {
      "x": -2,
      "y": 26,
      "z": 4,
      "name": "Rock_Acid_Trunk_Medium"
    },
    {
      "x": -2,
      "y": 27,
      "z": 4,
      "name": "Rock_Acid_Trunk_Medium"
    },
    {
      "x": -2,
      "y": 28,
      "z": 4,
      "name": "Rock_Acid_Trunk_Medium"
    },
    {
      "x": -2,
      "y": 29,
      "z": 4,
      "name": "Rock_Acid_Trunk_Medium"
    },
    {
      "x": -2,
      "y": 30,
      "z": 4,
      "name": "Rock_Acid_Trunk_Crimson"
    },
    {
      "x": -2,
      "y": 31,
      "z": 4,
      "name": "Rock_Crystal_Green_Block",
      "rotation": 5
    },
    {
      "x": -2,
      "y": 32,
      "z": 4,
      "name": "Rock_Crystal_Green_Block",
      "rotation": 5
    },
    {
      "x": -2,
      "y": 33,
      "z": 4,
      "name": "Empty"
    },
    {
      "x": -2,
      "y": 12,
      "z": 5,
      "name": "Rock_Acid_Trunk_Medium"
    },
    {
      "x": -2,
      "y": 13,
      "z": 5,
      "name": "Rock_Acid_Trunk_Medium"
    },
    {
      "x": -2,
      "y": 14,
      "z": 5,
      "name": "Rock_Acid_Trunk_Medium"
    },
    {
      "x": -2,
      "y": 15,
      "z": 5,
      "name": "Rock_Acid_Trunk_Medium"
    },
    {
      "x": -2,
      "y": 16,
      "z": 5,
      "name": "Rock_Acid_Trunk_Medium"
    },
    {
      "x": -2,
      "y": 17,
      "z": 5,
      "name": "Rock_Acid_Trunk_Medium"
    },
    {
      "x": -2,
      "y": 18,
      "z": 5,
      "name": "Rock_Acid_Trunk_Medium"
    },
    {
      "x": -2,
      "y": 19,
      "z": 5,
      "name": "Rock_Acid_Trunk_Bright"
    },
    {
      "x": -2,
      "y": 20,
      "z": 5,
      "name": "Rock_Acid_Trunk_Bright"
    },
    {
      "x": -2,
      "y": 21,
      "z": 5,
      "name": "Rock_Acid_Trunk_Bright"
    },
    {
      "x": -2,
      "y": 22,
      "z": 5,
      "name": "Rock_Acid_Trunk_Medium"
    },
    {
      "x": -2,
      "y": 23,
      "z": 5,
      "name": "Rock_Acid_Trunk_Medium"
    },
    {
      "x": -2,
      "y": 24,
      "z": 5,
      "name": "Rock_Acid_Trunk_Medium"
    },
    {
      "x": -2,
      "y": 25,
      "z": 5,
      "name": "Rock_Acid_Trunk_Medium"
    },
    {
      "x": -2,
      "y": 26,
      "z": 5,
      "name": "Rock_Acid_Trunk_Medium"
    },
    {
      "x": -2,
      "y": 27,
      "z": 5,
      "name": "Rock_Acid_Trunk_Medium"
    },
    {
      "x": -2,
      "y": 28,
      "z": 5,
      "name": "Rock_Acid_Trunk_Medium"
    },
    {
      "x": -2,
      "y": 29,
      "z": 5,
      "name": "Rock_Acid_Trunk_Medium"
    },
    {
      "x": -2,
      "y": 30,
      "z": 5,
      "name": "Rock_Acid_Trunk_Medium"
    },
    {
      "x": -2,
      "y": 31,
      "z": 5,
      "name": "Rock_Acid_Trunk_Crimson"
    },
    {
      "x": -2,
      "y": 32,
      "z": 5,
      "name": "Rock_Crystal_Green_Block",
      "rotation": 5
    },
    {
      "x": -2,
      "y": 33,
      "z": 5,
      "name": "Empty"
    },
    {
      "x": -2,
      "y": 15,
      "z": 6,
      "name": "Rock_Acid_Trunk_Medium"
    },
    {
      "x": -2,
      "y": 16,
      "z": 6,
      "name": "Rock_Acid_Trunk_Medium"
    },
    {
      "x": -2,
      "y": 17,
      "z": 6,
      "name": "Rock_Acid_Trunk_Bright"
    },
    {
      "x": -2,
      "y": 18,
      "z": 6,
      "name": "Rock_Acid_Trunk_Bright"
    },
    {
      "x": -2,
      "y": 19,
      "z": 6,
      "name": "Rock_Acid_Trunk_Bright"
    },
    {
      "x": -2,
      "y": 20,
      "z": 6,
      "name": "Rock_Acid_Trunk_Bright"
    },
    {
      "x": -2,
      "y": 21,
      "z": 6,
      "name": "Rock_Acid_Trunk_Bright"
    },
    {
      "x": -2,
      "y": 22,
      "z": 6,
      "name": "Rock_Acid_Trunk_Bright"
    },
    {
      "x": -2,
      "y": 23,
      "z": 6,
      "name": "Rock_Acid_Trunk_Bright"
    },
    {
      "x": -2,
      "y": 24,
      "z": 6,
      "name": "Rock_Acid_Trunk_Medium"
    },
    {
      "x": -2,
      "y": 25,
      "z": 6,
      "name": "Rock_Acid_Trunk_Medium"
    },
    {
      "x": -2,
      "y": 26,
      "z": 6,
      "name": "Rock_Acid_Trunk_Medium"
    },
    {
      "x": -2,
      "y": 27,
      "z": 6,
      "name": "Rock_Acid_Trunk_Bright"
    },
    {
      "x": -2,
      "y": 28,
      "z": 6,
      "name": "Rock_Acid_Trunk_Bright"
    },
    {
      "x": -2,
      "y": 29,
      "z": 6,
      "name": "Rock_Acid_Trunk_Medium"
    },
    {
      "x": -2,
      "y": 30,
      "z": 6,
      "name": "Rock_Acid_Trunk_Medium"
    },
    {
      "x": -2,
      "y": 31,
      "z": 6,
      "name": "Rock_Acid_Trunk_Crimson"
    },
    {
      "x": -2,
      "y": 32,
      "z": 6,
      "name": "Rock_Crystal_Green_Block",
      "rotation": 5
    },
    {
      "x": -2,
      "y": 33,
      "z": 6,
      "name": "Empty"
    },
    {
      "x": -2,
      "y": 16,
      "z": 7,
      "name": "Rock_Acid_Trunk_Medium"
    },
    {
      "x": -2,
      "y": 17,
      "z": 7,
      "name": "Rock_Acid_Trunk_Bright"
    },
    {
      "x": -2,
      "y": 18,
      "z": 7,
      "name": "Rock_Acid_Trunk_Bright"
    },
    {
      "x": -2,
      "y": 22,
      "z": 7,
      "name": "Rock_Acid_Trunk_Bright"
    },
    {
      "x": -2,
      "y": 23,
      "z": 7,
      "name": "Rock_Acid_Trunk_Bright"
    },
    {
      "x": -2,
      "y": 24,
      "z": 7,
      "name": "Rock_Acid_Trunk_Bright"
    },
    {
      "x": -2,
      "y": 25,
      "z": 7,
      "name": "Rock_Acid_Trunk_Bright"
    },
    {
      "x": -2,
      "y": 26,
      "z": 7,
      "name": "Rock_Acid_Trunk_Bright"
    },
    {
      "x": -2,
      "y": 29,
      "z": 7,
      "name": "Rock_Acid_Trunk_Bright"
    },
    {
      "x": -2,
      "y": 30,
      "z": 7,
      "name": "Rock_Acid_Trunk_Orange"
    },
    {
      "x": -2,
      "y": 31,
      "z": 7,
      "name": "Rock_Acid_Trunk_Orange"
    },
    {
      "x": -2,
      "y": 32,
      "z": 7,
      "name": "Rock_Acid_Trunk_Crimson"
    },
    {
      "x": -2,
      "y": 33,
      "z": 7,
      "name": "Rock_Acid_Trunk_Crimson"
    },
    {
      "x": -2,
      "y": 31,
      "z": 8,
      "name": "Rock_Acid_Trunk_Orange"
    },
    {
      "x": -2,
      "y": 32,
      "z": 8,
      "name": "Rock_Acid_Trunk_Orange"
    },
    {
      "x": -2,
      "y": 33,
      "z": 8,
      "name": "Rock_Acid_Trunk_Crimson"
    },
    {
      "x": -1,
      "y": 21,
      "z": -8,
      "name": "Rock_Acid_Trunk_Orange"
    },
    {
      "x": -1,
      "y": 22,
      "z": -8,
      "name": "Rock_Acid_Trunk_Magenta"
    },
    {
      "x": -1,
      "y": 20,
      "z": -7,
      "name": "Rock_Acid_Trunk_Bright"
    },
    {
      "x": -1,
      "y": 21,
      "z": -7,
      "name": "Rock_Acid_Trunk_Crimson"
    },
    {
      "x": -1,
      "y": 22,
      "z": -7,
      "name": "Empty"
    },
    {
      "x": -1,
      "y": 18,
      "z": -6,
      "name": "Rock_Acid_Trunk_Medium"
    },
    {
      "x": -1,
      "y": 19,
      "z": -6,
      "name": "Rock_Acid_Trunk_Bright"
    },
    {
      "x": -1,
      "y": 20,
      "z": -6,
      "name": "Rock_Acid_Trunk_Orange"
    },
    {
      "x": -1,
      "y": 21,
      "z": -6,
      "name": "Rock_Crystal_Green_Block",
      "rotation": 4
    },
    {
      "x": -1,
      "y": 22,
      "z": -6,
      "name": "Empty"
    },
    {
      "x": -1,
      "y": 17,
      "z": -5,
      "name": "Rock_Acid_Trunk_Medium"
    },
    {
      "x": -1,
      "y": 18,
      "z": -5,
      "name": "Rock_Acid_Trunk_Medium"
    },
    {
      "x": -1,
      "y": 19,
      "z": -5,
      "name": "Rock_Acid_Trunk_Bright"
    },
    {
      "x": -1,
      "y": 20,
      "z": -5,
      "name": "Rock_Crystal_Green_Block",
      "rotation": 4
    },
    {
      "x": -1,
      "y": 21,
      "z": -5,
      "name": "Rock_Crystal_Green_Block",
      "rotation": 4
    },
    {
      "x": -1,
      "y": 22,
      "z": -5,
      "name": "Empty"
    },
    {
      "x": -1,
      "y": 16,
      "z": -4,
      "name": "Rock_Acid_Trunk_Medium"
    },
    {
      "x": -1,
      "y": 17,
      "z": -4,
      "name": "Rock_Acid_Trunk_Medium"
    },
    {
      "x": -1,
      "y": 18,
      "z": -4,
      "name": "Rock_Acid_Trunk_Medium"
    },
    {
      "x": -1,
      "y": 19,
      "z": -4,
      "name": "Rock_Acid_Trunk_Orange"
    },
    {
      "x": -1,
      "y": 20,
      "z": -4,
      "name": "Rock_Crystal_Green_Block",
      "rotation": 4
    },
    {
      "x": -1,
      "y": 21,
      "z": -4,
      "name": "Rock_Crystal_Green_Block",
      "rotation": 4
    },
    {
      "x": -1,
      "y": 22,
      "z": -4,
      "name": "Empty"
    },
    {
      "x": -1,
      "y": 4,
      "z": -3,
      "name": "Rock_Acid_Trunk_Medium"
    },
    {
      "x": -1,
      "y": 5,
      "z": -3,
      "name": "Rock_Acid_Trunk_Medium"
    },
    {
      "x": -1,
      "y": 6,
      "z": -3,
      "name": "Rock_Acid_Trunk_Medium"
    },
    {
      "x": -1,
      "y": 7,
      "z": -3,
      "name": "Rock_Acid_Trunk_Medium"
    },
    {
      "x": -1,
      "y": 8,
      "z": -3,
      "name": "Rock_Acid_Trunk_Medium"
    },
    {
      "x": -1,
      "y": 9,
      "z": -3,
      "name": "Rock_Acid_Trunk_Medium"
    },
    {
      "x": -1,
      "y": 10,
      "z": -3,
      "name": "Rock_Acid_Trunk_Standard"
    },
    {
      "x": -1,
      "y": 11,
      "z": -3,
      "name": "Rock_Acid_Trunk_Standard"
    },
    {
      "x": -1,
      "y": 12,
      "z": -3,
      "name": "Rock_Acid_Trunk_Standard"
    },
    {
      "x": -1,
      "y": 15,
      "z": -3,
      "name": "Rock_Acid_Trunk_Medium"
    },
    {
      "x": -1,
      "y": 16,
      "z": -3,
      "name": "Rock_Acid_Trunk_Medium"
    },
    {
      "x": -1,
      "y": 17,
      "z": -3,
      "name": "Rock_Acid_Trunk_Medium"
    },
    {
      "x": -1,
      "y": 18,
      "z": -3,
      "name": "Rock_Acid_Trunk_Medium"
    },
    {
      "x": -1,
      "y": 19,
      "z": -3,
      "name": "Rock_Acid_Trunk_Medium"
    },
    {
      "x": -1,
      "y": 20,
      "z": -3,
      "name": "Rock_Acid_Trunk_Crimson"
    },
    {
      "x": -1,
      "y": 21,
      "z": -3,
      "name": "Rock_Crystal_Green_Block",
      "rotation": 4
    },
    {
      "x": -1,
      "y": 22,
      "z": -3,
      "name": "Empty"
    },
    {
      "x": -1,
      "y": 31,
      "z": -3,
      "name": "Rock_Acid_Trunk_Orange"
    },
    {
      "x": -1,
      "y": 32,
      "z": -3,
      "name": "Rock_Acid_Trunk_Orange"
    },
    {
      "x": -1,
      "y": 33,
      "z": -3,
      "name": "Rock_Acid_Trunk_Crimson"
    },
    {
      "x": -1,
      "y": 34,
      "z": -3,
      "name": "Rock_Acid_Trunk_Crimson"
    },
    {
      "x": -1,
      "y": 35,
      "z": -3,
      "name": "Rock_Acid_Trunk_Magenta"
    },
    {
      "x": -1,
      "y": 8,
      "z": -2,
      "name": "Rock_Acid_Trunk_Medium"
    },
    {
      "x": -1,
      "y": 9,
      "z": -2,
      "name": "Rock_Acid_Trunk_Medium"
    },
    {
      "x": -1,
      "y": 10,
      "z": -2,
      "name": "Rock_Acid_Trunk_Medium"
    },
    {
      "x": -1,
      "y": 11,
      "z": -2,
      "name": "Rock_Acid_Trunk_Standard"
    },
    {
      "x": -1,
      "y": 12,
      "z": -2,
      "name": "Rock_Acid_Trunk_Standard"
    },
    {
      "x": -1,
      "y": 13,
      "z": -2,
      "name": "Rock_Acid_Trunk_Bright"
    },
    {
      "x": -1,
      "y": 15,
      "z": -2,
      "name": "Rock_Acid_Trunk_Medium"
    },
    {
      "x": -1,
      "y": 16,
      "z": -2,
      "name": "Rock_Acid_Trunk_Bright"
    },
    {
      "x": -1,
      "y": 17,
      "z": -2,
      "name": "Rock_Acid_Trunk_Bright"
    },
    {
      "x": -1,
      "y": 18,
      "z": -2,
      "name": "Rock_Acid_Trunk_Bright"
    },
    {
      "x": -1,
      "y": 19,
      "z": -2,
      "name": "Rock_Acid_Trunk_Medium"
    },
    {
      "x": -1,
      "y": 20,
      "z": -2,
      "name": "Rock_Acid_Trunk_Crimson"
    },
    {
      "x": -1,
      "y": 21,
      "z": -2,
      "name": "Rock_Crystal_Green_Block",
      "rotation": 4
    },
    {
      "x": -1,
      "y": 22,
      "z": -2,
      "name": "Empty"
    },
    {
      "x": -1,
      "y": 28,
      "z": -2,
      "name": "Rock_Acid_Trunk_Bright"
    },
    {
      "x": -1,
      "y": 29,
      "z": -2,
      "name": "Rock_Acid_Trunk_Orange"
    },
    {
      "x": -1,
      "y": 30,
      "z": -2,
      "name": "Rock_Acid_Trunk_Orange"
    },
    {
      "x": -1,
      "y": 31,
      "z": -2,
      "name": "Rock_Acid_Trunk_Medium"
    },
    {
      "x": -1,
      "y": 32,
      "z": -2,
      "name": "Rock_Acid_Trunk_Crimson"
    },
    {
      "x": -1,
      "y": 33,
      "z": -2,
      "name": "Empty"
    },
    {
      "x": -1,
      "y": 36,
      "z": -2,
      "name": "Rock_Acid_Trunk_Magenta"
    },
    {
      "x": -1,
      "y": 7,
      "z": -1,
      "name": "Rock_Acid_Trunk_Medium"
    },
    {
      "x": -1,
      "y": 8,
      "z": -1,
      "name": "Rock_Acid_Trunk_Medium"
    },
    {
      "x": -1,
      "y": 9,
      "z": -1,
      "name": "Rock_Acid_Trunk_Medium"
    },
    {
      "x": -1,
      "y": 10,
      "z": -1,
      "name": "Rock_Acid_Trunk_Standard"
    },
    {
      "x": -1,
      "y": 11,
      "z": -1,
      "name": "Rock_Acid_Trunk_Standard"
    },
    {
      "x": -1,
      "y": 12,
      "z": -1,
      "name": "Rock_Acid_Trunk_Standard"
    },
    {
      "x": -1,
      "y": 13,
      "z": -1,
      "name": "Rock_Acid_Trunk_Medium"
    },
    {
      "x": -1,
      "y": 14,
      "z": -1,
      "name": "Rock_Acid_Trunk_Bright"
    },
    {
      "x": -1,
      "y": 15,
      "z": -1,
      "name": "Rock_Acid_Trunk_Medium"
    },
    {
      "x": -1,
      "y": 16,
      "z": -1,
      "name": "Rock_Acid_Trunk_Bright"
    },
    {
      "x": -1,
      "y": 17,
      "z": -1,
      "name": "Rock_Acid_Trunk_Bright"
    },
    {
      "x": -1,
      "y": 18,
      "z": -1,
      "name": "Rock_Acid_Trunk_Bright"
    },
    {
      "x": -1,
      "y": 19,
      "z": -1,
      "name": "Rock_Acid_Trunk_Orange"
    },
    {
      "x": -1,
      "y": 20,
      "z": -1,
      "name": "Rock_Acid_Trunk_Orange"
    },
    {
      "x": -1,
      "y": 21,
      "z": -1,
      "name": "Rock_Acid_Trunk_Standard"
    },
    {
      "x": -1,
      "y": 22,
      "z": -1,
      "name": "Empty"
    },
    {
      "x": -1,
      "y": 25,
      "z": -1,
      "name": "Rock_Acid_Trunk_Bright"
    },
    {
      "x": -1,
      "y": 26,
      "z": -1,
      "name": "Rock_Acid_Trunk_Orange"
    },
    {
      "x": -1,
      "y": 27,
      "z": -1,
      "name": "Rock_Acid_Trunk_Bright"
    },
    {
      "x": -1,
      "y": 28,
      "z": -1,
      "name": "Rock_Acid_Trunk_Medium"
    },
    {
      "x": -1,
      "y": 29,
      "z": -1,
      "name": "Rock_Acid_Trunk_Medium"
    },
    {
      "x": -1,
      "y": 30,
      "z": -1,
      "name": "Rock_Acid_Trunk_Medium"
    },
    {
      "x": -1,
      "y": 31,
      "z": -1,
      "name": "Rock_Acid_Trunk_Crimson"
    },
    {
      "x": -1,
      "y": 32,
      "z": -1,
      "name": "Rock_Crystal_Green_Block",
      "rotation": 5
    },
    {
      "x": -1,
      "y": 33,
      "z": -1,
      "name": "Empty"
    },
    {
      "x": -1,
      "y": 6,
      "z": 0,
      "name": "Rock_Acid_Trunk_Medium"
    },
    {
      "x": -1,
      "y": 7,
      "z": 0,
      "name": "Rock_Acid_Trunk_Medium"
    },
    {
      "x": -1,
      "y": 8,
      "z": 0,
      "name": "Rock_Acid_Trunk_Medium"
    },
    {
      "x": -1,
      "y": 9,
      "z": 0,
      "name": "Rock_Acid_Trunk_Medium"
    },
    {
      "x": -1,
      "y": 10,
      "z": 0,
      "name": "Rock_Acid_Trunk_Medium"
    },
    {
      "x": -1,
      "y": 11,
      "z": 0,
      "name": "Rock_Acid_Trunk_Medium"
    },
    {
      "x": -1,
      "y": 12,
      "z": 0,
      "name": "Rock_Acid_Trunk_Medium"
    },
    {
      "x": -1,
      "y": 13,
      "z": 0,
      "name": "Rock_Acid_Trunk_Medium"
    },
    {
      "x": -1,
      "y": 14,
      "z": 0,
      "name": "Rock_Acid_Trunk_Medium"
    },
    {
      "x": -1,
      "y": 15,
      "z": 0,
      "name": "Rock_Acid_Trunk_Medium"
    },
    {
      "x": -1,
      "y": 16,
      "z": 0,
      "name": "Rock_Acid_Trunk_Medium"
    },
    {
      "x": -1,
      "y": 17,
      "z": 0,
      "name": "Rock_Acid_Trunk_Medium"
    },
    {
      "x": -1,
      "y": 18,
      "z": 0,
      "name": "Rock_Acid_Trunk_Bright"
    },
    {
      "x": -1,
      "y": 19,
      "z": 0,
      "name": "Rock_Acid_Trunk_Orange"
    },
    {
      "x": -1,
      "y": 22,
      "z": 0,
      "name": "Rock_Acid_Trunk_Bright"
    },
    {
      "x": -1,
      "y": 23,
      "z": 0,
      "name": "Rock_Acid_Trunk_Bright"
    },
    {
      "x": -1,
      "y": 24,
      "z": 0,
      "name": "Rock_Acid_Trunk_Bright"
    },
    {
      "x": -1,
      "y": 25,
      "z": 0,
      "name": "Rock_Acid_Trunk_Medium"
    },
    {
      "x": -1,
      "y": 26,
      "z": 0,
      "name": "Rock_Acid_Trunk_Medium"
    },
    {
      "x": -1,
      "y": 27,
      "z": 0,
      "name": "Rock_Acid_Trunk_Medium"
    },
    {
      "x": -1,
      "y": 28,
      "z": 0,
      "name": "Rock_Acid_Trunk_Medium"
    },
    {
      "x": -1,
      "y": 29,
      "z": 0,
      "name": "Rock_Acid_Trunk_Medium"
    },
    {
      "x": -1,
      "y": 30,
      "z": 0,
      "name": "Rock_Acid_Trunk_Medium"
    },
    {
      "x": -1,
      "y": 31,
      "z": 0,
      "name": "Rock_Acid_Trunk_Crimson"
    },
    {
      "x": -1,
      "y": 32,
      "z": 0,
      "name": "Rock_Crystal_Green_Block",
      "rotation": 5
    },
    {
      "x": -1,
      "y": 33,
      "z": 0,
      "name": "Empty"
    },
    {
      "x": -1,
      "y": 6,
      "z": 1,
      "name": "Rock_Acid_Trunk_Medium"
    },
    {
      "x": -1,
      "y": 7,
      "z": 1,
      "name": "Rock_Acid_Trunk_Medium"
    },
    {
      "x": -1,
      "y": 8,
      "z": 1,
      "name": "Rock_Acid_Trunk_Medium"
    },
    {
      "x": -1,
      "y": 9,
      "z": 1,
      "name": "Rock_Acid_Trunk_Medium"
    },
    {
      "x": -1,
      "y": 10,
      "z": 1,
      "name": "Rock_Acid_Trunk_Medium"
    },
    {
      "x": -1,
      "y": 11,
      "z": 1,
      "name": "Rock_Acid_Trunk_Medium"
    },
    {
      "x": -1,
      "y": 12,
      "z": 1,
      "name": "Rock_Acid_Trunk_Medium"
    },
    {
      "x": -1,
      "y": 13,
      "z": 1,
      "name": "Rock_Acid_Trunk_Medium"
    },
    {
      "x": -1,
      "y": 14,
      "z": 1,
      "name": "Rock_Acid_Trunk_Medium"
    },
    {
      "x": -1,
      "y": 15,
      "z": 1,
      "name": "Rock_Acid_Trunk_Medium"
    },
    {
      "x": -1,
      "y": 16,
      "z": 1,
      "name": "Rock_Acid_Trunk_Medium"
    },
    {
      "x": -1,
      "y": 17,
      "z": 1,
      "name": "Rock_Acid_Trunk_Medium"
    },
    {
      "x": -1,
      "y": 18,
      "z": 1,
      "name": "Rock_Acid_Trunk_Medium"
    },
    {
      "x": -1,
      "y": 19,
      "z": 1,
      "name": "Rock_Acid_Trunk_Medium"
    },
    {
      "x": -1,
      "y": 20,
      "z": 1,
      "name": "Rock_Acid_Trunk_Bright"
    },
    {
      "x": -1,
      "y": 21,
      "z": 1,
      "name": "Rock_Acid_Trunk_Bright"
    },
    {
      "x": -1,
      "y": 22,
      "z": 1,
      "name": "Rock_Acid_Trunk_Medium"
    },
    {
      "x": -1,
      "y": 23,
      "z": 1,
      "name": "Rock_Acid_Trunk_Medium"
    },
    {
      "x": -1,
      "y": 24,
      "z": 1,
      "name": "Rock_Acid_Trunk_Medium"
    },
    {
      "x": -1,
      "y": 25,
      "z": 1,
      "name": "Rock_Acid_Trunk_Medium"
    },
    {
      "x": -1,
      "y": 26,
      "z": 1,
      "name": "Rock_Acid_Trunk_Medium"
    },
    {
      "x": -1,
      "y": 27,
      "z": 1,
      "name": "Rock_Acid_Trunk_Medium"
    },
    {
      "x": -1,
      "y": 28,
      "z": 1,
      "name": "Rock_Acid_Trunk_Medium"
    },
    {
      "x": -1,
      "y": 29,
      "z": 1,
      "name": "Rock_Acid_Trunk_Medium"
    },
    {
      "x": -1,
      "y": 30,
      "z": 1,
      "name": "Rock_Acid_Trunk_Crimson"
    },
    {
      "x": -1,
      "y": 31,
      "z": 1,
      "name": "Rock_Crystal_Green_Block",
      "rotation": 5
    },
    {
      "x": -1,
      "y": 32,
      "z": 1,
      "name": "Rock_Crystal_Green_Block",
      "rotation": 5
    },
    {
      "x": -1,
      "y": 33,
      "z": 1,
      "name": "Empty"
    },
    {
      "x": -1,
      "y": 7,
      "z": 2,
      "name": "Rock_Acid_Trunk_Medium"
    },
    {
      "x": -1,
      "y": 8,
      "z": 2,
      "name": "Rock_Acid_Trunk_Medium"
    },
    {
      "x": -1,
      "y": 9,
      "z": 2,
      "name": "Rock_Acid_Trunk_Medium"
    },
    {
      "x": -1,
      "y": 10,
      "z": 2,
      "name": "Rock_Acid_Trunk_Medium"
    },
    {
      "x": -1,
      "y": 11,
      "z": 2,
      "name": "Rock_Acid_Trunk_Medium"
    },
    {
      "x": -1,
      "y": 12,
      "z": 2,
      "name": "Rock_Acid_Trunk_Medium"
    },
    {
      "x": -1,
      "y": 13,
      "z": 2,
      "name": "Rock_Acid_Trunk_Medium"
    },
    {
      "x": -1,
      "y": 14,
      "z": 2,
      "name": "Rock_Acid_Trunk_Medium"
    },
    {
      "x": -1,
      "y": 15,
      "z": 2,
      "name": "Rock_Acid_Trunk_Medium"
    },
    {
      "x": -1,
      "y": 16,
      "z": 2,
      "name": "Rock_Acid_Trunk_Medium"
    },
    {
      "x": -1,
      "y": 17,
      "z": 2,
      "name": "Rock_Acid_Trunk_Medium"
    },
    {
      "x": -1,
      "y": 18,
      "z": 2,
      "name": "Rock_Acid_Trunk_Medium"
    },
    {
      "x": -1,
      "y": 19,
      "z": 2,
      "name": "Rock_Acid_Trunk_Medium"
    },
    {
      "x": -1,
      "y": 20,
      "z": 2,
      "name": "Rock_Acid_Trunk_Medium"
    },
    {
      "x": -1,
      "y": 21,
      "z": 2,
      "name": "Rock_Acid_Trunk_Medium"
    },
    {
      "x": -1,
      "y": 22,
      "z": 2,
      "name": "Rock_Acid_Trunk_Medium"
    },
    {
      "x": -1,
      "y": 23,
      "z": 2,
      "name": "Rock_Acid_Trunk_Medium"
    },
    {
      "x": -1,
      "y": 24,
      "z": 2,
      "name": "Rock_Acid_Trunk_Medium"
    },
    {
      "x": -1,
      "y": 25,
      "z": 2,
      "name": "Rock_Acid_Trunk_Medium"
    },
    {
      "x": -1,
      "y": 26,
      "z": 2,
      "name": "Rock_Acid_Trunk_Medium"
    },
    {
      "x": -1,
      "y": 27,
      "z": 2,
      "name": "Rock_Acid_Trunk_Medium"
    },
    {
      "x": -1,
      "y": 28,
      "z": 2,
      "name": "Rock_Acid_Trunk_Medium"
    },
    {
      "x": -1,
      "y": 29,
      "z": 2,
      "name": "Rock_Acid_Trunk_Medium"
    },
    {
      "x": -1,
      "y": 30,
      "z": 2,
      "name": "Rock_Acid_Trunk_Crimson"
    },
    {
      "x": -1,
      "y": 31,
      "z": 2,
      "name": "Rock_Crystal_Green_Block",
      "rotation": 5
    },
    {
      "x": -1,
      "y": 32,
      "z": 2,
      "name": "Rock_Crystal_Green_Block",
      "rotation": 5
    },
    {
      "x": -1,
      "y": 33,
      "z": 2,
      "name": "Empty"
    },
    {
      "x": -1,
      "y": 8,
      "z": 3,
      "name": "Rock_Acid_Trunk_Medium"
    },
    {
      "x": -1,
      "y": 9,
      "z": 3,
      "name": "Rock_Acid_Trunk_Medium"
    },
    {
      "x": -1,
      "y": 10,
      "z": 3,
      "name": "Rock_Acid_Trunk_Medium"
    },
    {
      "x": -1,
      "y": 11,
      "z": 3,
      "name": "Rock_Acid_Trunk_Medium"
    },
    {
      "x": -1,
      "y": 12,
      "z": 3,
      "name": "Rock_Acid_Trunk_Medium"
    },
    {
      "x": -1,
      "y": 13,
      "z": 3,
      "name": "Rock_Acid_Trunk_Medium"
    },
    {
      "x": -1,
      "y": 14,
      "z": 3,
      "name": "Rock_Acid_Trunk_Medium"
    },
    {
      "x": -1,
      "y": 15,
      "z": 3,
      "name": "Rock_Acid_Trunk_Medium"
    },
    {
      "x": -1,
      "y": 16,
      "z": 3,
      "name": "Rock_Acid_Trunk_Medium"
    },
    {
      "x": -1,
      "y": 17,
      "z": 3,
      "name": "Rock_Acid_Trunk_Medium"
    },
    {
      "x": -1,
      "y": 18,
      "z": 3,
      "name": "Rock_Acid_Trunk_Medium"
    },
    {
      "x": -1,
      "y": 19,
      "z": 3,
      "name": "Rock_Acid_Trunk_Medium"
    },
    {
      "x": -1,
      "y": 20,
      "z": 3,
      "name": "Rock_Acid_Trunk_Medium"
    },
    {
      "x": -1,
      "y": 21,
      "z": 3,
      "name": "Rock_Acid_Trunk_Medium"
    },
    {
      "x": -1,
      "y": 22,
      "z": 3,
      "name": "Rock_Acid_Trunk_Medium"
    },
    {
      "x": -1,
      "y": 23,
      "z": 3,
      "name": "Rock_Acid_Trunk_Medium"
    },
    {
      "x": -1,
      "y": 24,
      "z": 3,
      "name": "Rock_Acid_Trunk_Medium"
    },
    {
      "x": -1,
      "y": 25,
      "z": 3,
      "name": "Rock_Acid_Trunk_Medium"
    },
    {
      "x": -1,
      "y": 26,
      "z": 3,
      "name": "Rock_Acid_Trunk_Medium"
    },
    {
      "x": -1,
      "y": 27,
      "z": 3,
      "name": "Rock_Acid_Trunk_Medium"
    },
    {
      "x": -1,
      "y": 28,
      "z": 3,
      "name": "Rock_Acid_Trunk_Medium"
    },
    {
      "x": -1,
      "y": 29,
      "z": 3,
      "name": "Rock_Acid_Trunk_Crimson"
    },
    {
      "x": -1,
      "y": 30,
      "z": 3,
      "name": "Rock_Crystal_Green_Block",
      "rotation": 5
    },
    {
      "x": -1,
      "y": 31,
      "z": 3,
      "name": "Rock_Crystal_Green_Block",
      "rotation": 5
    },
    {
      "x": -1,
      "y": 32,
      "z": 3,
      "name": "Rock_Crystal_Green_Block",
      "rotation": 5
    },
    {
      "x": -1,
      "y": 33,
      "z": 3,
      "name": "Empty"
    },
    {
      "x": -1,
      "y": 0,
      "z": 4,
      "name": "Rock_Acid_Trunk_Light"
    },
    {
      "x": -1,
      "y": 1,
      "z": 4,
      "name": "Rock_Acid_Trunk_Medium"
    },
    {
      "x": -1,
      "y": 2,
      "z": 4,
      "name": "Rock_Acid_Trunk_Medium"
    },
    {
      "x": -1,
      "y": 3,
      "z": 4,
      "name": "Rock_Acid_Trunk_Medium"
    },
    {
      "x": -1,
      "y": 4,
      "z": 4,
      "name": "Rock_Acid_Trunk_Medium"
    },
    {
      "x": -1,
      "y": 5,
      "z": 4,
      "name": "Rock_Acid_Trunk_Medium"
    },
    {
      "x": -1,
      "y": 6,
      "z": 4,
      "name": "Rock_Acid_Trunk_Standard"
    },
    {
      "x": -1,
      "y": 9,
      "z": 4,
      "name": "Rock_Acid_Trunk_Medium"
    },
    {
      "x": -1,
      "y": 10,
      "z": 4,
      "name": "Rock_Acid_Trunk_Medium"
    },
    {
      "x": -1,
      "y": 11,
      "z": 4,
      "name": "Rock_Acid_Trunk_Medium"
    },
    {
      "x": -1,
      "y": 12,
      "z": 4,
      "name": "Rock_Acid_Trunk_Medium"
    },
    {
      "x": -1,
      "y": 13,
      "z": 4,
      "name": "Rock_Acid_Trunk_Medium"
    },
    {
      "x": -1,
      "y": 14,
      "z": 4,
      "name": "Rock_Acid_Trunk_Medium"
    },
    {
      "x": -1,
      "y": 15,
      "z": 4,
      "name": "Rock_Acid_Trunk_Medium"
    },
    {
      "x": -1,
      "y": 16,
      "z": 4,
      "name": "Rock_Acid_Trunk_Medium"
    },
    {
      "x": -1,
      "y": 17,
      "z": 4,
      "name": "Rock_Acid_Trunk_Medium"
    },
    {
      "x": -1,
      "y": 18,
      "z": 4,
      "name": "Rock_Acid_Trunk_Medium"
    },
    {
      "x": -1,
      "y": 19,
      "z": 4,
      "name": "Rock_Acid_Trunk_Medium"
    },
    {
      "x": -1,
      "y": 20,
      "z": 4,
      "name": "Rock_Acid_Trunk_Medium"
    },
    {
      "x": -1,
      "y": 21,
      "z": 4,
      "name": "Rock_Acid_Trunk_Medium"
    },
    {
      "x": -1,
      "y": 22,
      "z": 4,
      "name": "Rock_Acid_Trunk_Medium"
    },
    {
      "x": -1,
      "y": 23,
      "z": 4,
      "name": "Rock_Acid_Trunk_Medium"
    },
    {
      "x": -1,
      "y": 24,
      "z": 4,
      "name": "Rock_Acid_Trunk_Medium"
    },
    {
      "x": -1,
      "y": 25,
      "z": 4,
      "name": "Rock_Acid_Trunk_Medium"
    },
    {
      "x": -1,
      "y": 26,
      "z": 4,
      "name": "Rock_Acid_Trunk_Medium"
    },
    {
      "x": -1,
      "y": 27,
      "z": 4,
      "name": "Rock_Acid_Trunk_Medium"
    },
    {
      "x": -1,
      "y": 28,
      "z": 4,
      "name": "Rock_Acid_Trunk_Medium"
    },
    {
      "x": -1,
      "y": 29,
      "z": 4,
      "name": "Rock_Acid_Trunk_Medium"
    },
    {
      "x": -1,
      "y": 30,
      "z": 4,
      "name": "Rock_Acid_Trunk_Crimson"
    },
    {
      "x": -1,
      "y": 31,
      "z": 4,
      "name": "Rock_Crystal_Green_Block",
      "rotation": 5
    },
    {
      "x": -1,
      "y": 32,
      "z": 4,
      "name": "Rock_Crystal_Green_Block",
      "rotation": 5
    },
    {
      "x": -1,
      "y": 33,
      "z": 4,
      "name": "Empty"
    },
    {
      "x": -1,
      "y": 0,
      "z": 5,
      "name": "Rock_Acid_Trunk_Light"
    },
    {
      "x": -1,
      "y": 1,
      "z": 5,
      "name": "Rock_Acid_Trunk_Light"
    },
    {
      "x": -1,
      "y": 2,
      "z": 5,
      "name": "Rock_Acid_Trunk_Medium"
    },
    {
      "x": -1,
      "y": 3,
      "z": 5,
      "name": "Rock_Acid_Trunk_Medium"
    },
    {
      "x": -1,
      "y": 4,
      "z": 5,
      "name": "Rock_Acid_Trunk_Standard"
    },
    {
      "x": -1,
      "y": 5,
      "z": 5,
      "name": "Rock_Acid_Trunk_Standard"
    },
    {
      "x": -1,
      "y": 10,
      "z": 5,
      "name": "Rock_Acid_Trunk_Medium"
    },
    {
      "x": -1,
      "y": 11,
      "z": 5,
      "name": "Rock_Acid_Trunk_Medium"
    },
    {
      "x": -1,
      "y": 12,
      "z": 5,
      "name": "Rock_Acid_Trunk_Medium"
    },
    {
      "x": -1,
      "y": 13,
      "z": 5,
      "name": "Rock_Acid_Trunk_Medium"
    },
    {
      "x": -1,
      "y": 14,
      "z": 5,
      "name": "Rock_Acid_Trunk_Medium"
    },
    {
      "x": -1,
      "y": 15,
      "z": 5,
      "name": "Rock_Acid_Trunk_Medium"
    },
    {
      "x": -1,
      "y": 16,
      "z": 5,
      "name": "Rock_Acid_Trunk_Medium"
    },
    {
      "x": -1,
      "y": 17,
      "z": 5,
      "name": "Rock_Acid_Trunk_Medium"
    },
    {
      "x": -1,
      "y": 18,
      "z": 5,
      "name": "Rock_Acid_Trunk_Medium"
    },
    {
      "x": -1,
      "y": 19,
      "z": 5,
      "name": "Rock_Acid_Trunk_Medium"
    },
    {
      "x": -1,
      "y": 20,
      "z": 5,
      "name": "Rock_Acid_Trunk_Medium"
    },
    {
      "x": -1,
      "y": 21,
      "z": 5,
      "name": "Rock_Acid_Trunk_Medium"
    },
    {
      "x": -1,
      "y": 22,
      "z": 5,
      "name": "Rock_Acid_Trunk_Medium"
    },
    {
      "x": -1,
      "y": 23,
      "z": 5,
      "name": "Rock_Acid_Trunk_Medium"
    },
    {
      "x": -1,
      "y": 24,
      "z": 5,
      "name": "Rock_Acid_Trunk_Medium"
    },
    {
      "x": -1,
      "y": 25,
      "z": 5,
      "name": "Rock_Acid_Trunk_Medium"
    },
    {
      "x": -1,
      "y": 26,
      "z": 5,
      "name": "Rock_Acid_Trunk_Medium"
    },
    {
      "x": -1,
      "y": 27,
      "z": 5,
      "name": "Rock_Acid_Trunk_Medium"
    },
    {
      "x": -1,
      "y": 28,
      "z": 5,
      "name": "Rock_Acid_Trunk_Medium"
    },
    {
      "x": -1,
      "y": 29,
      "z": 5,
      "name": "Rock_Acid_Trunk_Medium"
    },
    {
      "x": -1,
      "y": 30,
      "z": 5,
      "name": "Rock_Acid_Trunk_Crimson"
    },
    {
      "x": -1,
      "y": 31,
      "z": 5,
      "name": "Rock_Crystal_Green_Block",
      "rotation": 5
    },
    {
      "x": -1,
      "y": 32,
      "z": 5,
      "name": "Rock_Crystal_Green_Block",
      "rotation": 5
    },
    {
      "x": -1,
      "y": 33,
      "z": 5,
      "name": "Empty"
    },
    {
      "x": -1,
      "y": 13,
      "z": 6,
      "name": "Rock_Acid_Trunk_Medium"
    },
    {
      "x": -1,
      "y": 14,
      "z": 6,
      "name": "Rock_Acid_Trunk_Medium"
    },
    {
      "x": -1,
      "y": 15,
      "z": 6,
      "name": "Rock_Acid_Trunk_Medium"
    },
    {
      "x": -1,
      "y": 16,
      "z": 6,
      "name": "Rock_Acid_Trunk_Medium"
    },
    {
      "x": -1,
      "y": 17,
      "z": 6,
      "name": "Rock_Acid_Trunk_Medium"
    },
    {
      "x": -1,
      "y": 18,
      "z": 6,
      "name": "Rock_Acid_Trunk_Medium"
    },
    {
      "x": -1,
      "y": 19,
      "z": 6,
      "name": "Rock_Acid_Trunk_Medium"
    },
    {
      "x": -1,
      "y": 20,
      "z": 6,
      "name": "Rock_Acid_Trunk_Medium"
    },
    {
      "x": -1,
      "y": 21,
      "z": 6,
      "name": "Rock_Acid_Trunk_Medium"
    },
    {
      "x": -1,
      "y": 22,
      "z": 6,
      "name": "Rock_Acid_Trunk_Medium"
    },
    {
      "x": -1,
      "y": 23,
      "z": 6,
      "name": "Rock_Acid_Trunk_Medium"
    },
    {
      "x": -1,
      "y": 24,
      "z": 6,
      "name": "Rock_Acid_Trunk_Medium"
    },
    {
      "x": -1,
      "y": 25,
      "z": 6,
      "name": "Rock_Acid_Trunk_Medium"
    },
    {
      "x": -1,
      "y": 26,
      "z": 6,
      "name": "Rock_Acid_Trunk_Medium"
    },
    {
      "x": -1,
      "y": 27,
      "z": 6,
      "name": "Rock_Acid_Trunk_Medium"
    },
    {
      "x": -1,
      "y": 28,
      "z": 6,
      "name": "Rock_Acid_Trunk_Medium"
    },
    {
      "x": -1,
      "y": 29,
      "z": 6,
      "name": "Rock_Acid_Trunk_Medium"
    },
    {
      "x": -1,
      "y": 30,
      "z": 6,
      "name": "Rock_Acid_Trunk_Medium"
    },
    {
      "x": -1,
      "y": 31,
      "z": 6,
      "name": "Rock_Acid_Trunk_Crimson"
    },
    {
      "x": -1,
      "y": 32,
      "z": 6,
      "name": "Rock_Crystal_Green_Block",
      "rotation": 5
    },
    {
      "x": -1,
      "y": 33,
      "z": 6,
      "name": "Empty"
    },
    {
      "x": -1,
      "y": 16,
      "z": 7,
      "name": "Rock_Acid_Trunk_Medium"
    },
    {
      "x": -1,
      "y": 17,
      "z": 7,
      "name": "Rock_Acid_Trunk_Medium"
    },
    {
      "x": -1,
      "y": 18,
      "z": 7,
      "name": "Rock_Acid_Trunk_Medium"
    },
    {
      "x": -1,
      "y": 19,
      "z": 7,
      "name": "Rock_Acid_Trunk_Bright"
    },
    {
      "x": -1,
      "y": 20,
      "z": 7,
      "name": "Rock_Acid_Trunk_Bright"
    },
    {
      "x": -1,
      "y": 21,
      "z": 7,
      "name": "Rock_Acid_Trunk_Bright"
    },
    {
      "x": -1,
      "y": 22,
      "z": 7,
      "name": "Rock_Acid_Trunk_Medium"
    },
    {
      "x": -1,
      "y": 23,
      "z": 7,
      "name": "Rock_Acid_Trunk_Medium"
    },
    {
      "x": -1,
      "y": 24,
      "z": 7,
      "name": "Rock_Acid_Trunk_Medium"
    },
    {
      "x": -1,
      "y": 25,
      "z": 7,
      "name": "Rock_Acid_Trunk_Medium"
    },
    {
      "x": -1,
      "y": 26,
      "z": 7,
      "name": "Rock_Acid_Trunk_Orange"
    },
    {
      "x": -1,
      "y": 27,
      "z": 7,
      "name": "Rock_Acid_Trunk_Bright"
    },
    {
      "x": -1,
      "y": 28,
      "z": 7,
      "name": "Rock_Acid_Trunk_Bright"
    },
    {
      "x": -1,
      "y": 29,
      "z": 7,
      "name": "Rock_Acid_Trunk_Bright"
    },
    {
      "x": -1,
      "y": 30,
      "z": 7,
      "name": "Rock_Acid_Trunk_Medium"
    },
    {
      "x": -1,
      "y": 31,
      "z": 7,
      "name": "Rock_Acid_Trunk_Crimson"
    },
    {
      "x": -1,
      "y": 32,
      "z": 7,
      "name": "Rock_Crystal_Green_Block",
      "rotation": 5
    },
    {
      "x": -1,
      "y": 33,
      "z": 7,
      "name": "Empty"
    },
    {
      "x": -1,
      "y": 17,
      "z": 8,
      "name": "Rock_Acid_Trunk_Bright"
    },
    {
      "x": -1,
      "y": 18,
      "z": 8,
      "name": "Rock_Acid_Trunk_Bright"
    },
    {
      "x": -1,
      "y": 19,
      "z": 8,
      "name": "Rock_Acid_Trunk_Bright"
    },
    {
      "x": -1,
      "y": 20,
      "z": 8,
      "name": "Rock_Acid_Trunk_Bright"
    },
    {
      "x": -1,
      "y": 21,
      "z": 8,
      "name": "Rock_Acid_Trunk_Bright"
    },
    {
      "x": -1,
      "y": 22,
      "z": 8,
      "name": "Rock_Acid_Trunk_Bright"
    },
    {
      "x": -1,
      "y": 23,
      "z": 8,
      "name": "Rock_Acid_Trunk_Bright"
    },
    {
      "x": -1,
      "y": 24,
      "z": 8,
      "name": "Rock_Acid_Trunk_Bright"
    },
    {
      "x": -1,
      "y": 25,
      "z": 8,
      "name": "Rock_Acid_Trunk_Bright"
    },
    {
      "x": -1,
      "y": 30,
      "z": 8,
      "name": "Rock_Acid_Trunk_Orange"
    },
    {
      "x": -1,
      "y": 31,
      "z": 8,
      "name": "Rock_Acid_Trunk_Orange"
    },
    {
      "x": -1,
      "y": 32,
      "z": 8,
      "name": "Rock_Acid_Trunk_Orange"
    },
    {
      "x": -1,
      "y": 33,
      "z": 8,
      "name": "Rock_Acid_Trunk_Crimson"
    },
    {
      "x": -1,
      "y": 33,
      "z": 9,
      "name": "Rock_Acid_Trunk_Orange"
    },
    {
      "x": -1,
      "y": 34,
      "z": 9,
      "name": "Rock_Acid_Trunk_Crimson"
    },
    {
      "x": -1,
      "y": 35,
      "z": 9,
      "name": "Rock_Acid_Trunk_Magenta"
    },
    {
      "x": 0,
      "y": 21,
      "z": -8,
      "name": "Rock_Acid_Trunk_Magenta"
    },
    {
      "x": 0,
      "y": 22,
      "z": -8,
      "name": "Rock_Acid_Trunk_Magenta"
    },
    {
      "x": 0,
      "y": 23,
      "z": -8,
      "name": "Rock_Acid_Trunk_Magenta"
    },
    {
      "x": 0,
      "y": 19,
      "z": -7,
      "name": "Rock_Acid_Trunk_Bright"
    },
    {
      "x": 0,
      "y": 20,
      "z": -7,
      "name": "Rock_Acid_Trunk_Orange"
    },
    {
      "x": 0,
      "y": 21,
      "z": -7,
      "name": "Rock_Acid_Trunk_Crimson"
    },
    {
      "x": 0,
      "y": 22,
      "z": -7,
      "name": "Empty"
    },
    {
      "x": 0,
      "y": 17,
      "z": -6,
      "name": "Rock_Acid_Trunk_Medium"
    },
    {
      "x": 0,
      "y": 18,
      "z": -6,
      "name": "Rock_Acid_Trunk_Medium"
    },
    {
      "x": 0,
      "y": 19,
      "z": -6,
      "name": "Rock_Acid_Trunk_Medium"
    },
    {
      "x": 0,
      "y": 20,
      "z": -6,
      "name": "Rock_Acid_Trunk_Crimson"
    },
    {
      "x": 0,
      "y": 21,
      "z": -6,
      "name": "Rock_Crystal_Green_Block",
      "rotation": 4
    },
    {
      "x": 0,
      "y": 22,
      "z": -6,
      "name": "Empty"
    },
    {
      "x": 0,
      "y": 16,
      "z": -5,
      "name": "Rock_Acid_Trunk_Light"
    },
    {
      "x": 0,
      "y": 17,
      "z": -5,
      "name": "Rock_Acid_Trunk_Medium"
    },
    {
      "x": 0,
      "y": 18,
      "z": -5,
      "name": "Rock_Acid_Trunk_Medium"
    },
    {
      "x": 0,
      "y": 19,
      "z": -5,
      "name": "Rock_Acid_Trunk_Crimson"
    },
    {
      "x": 0,
      "y": 20,
      "z": -5,
      "name": "Rock_Crystal_Green_Block",
      "rotation": 4
    },
    {
      "x": 0,
      "y": 21,
      "z": -5,
      "name": "Rock_Crystal_Green_Block",
      "rotation": 4
    },
    {
      "x": 0,
      "y": 22,
      "z": -5,
      "name": "Empty"
    },
    {
      "x": 0,
      "y": 9,
      "z": -4,
      "name": "Rock_Acid_Trunk_Standard"
    },
    {
      "x": 0,
      "y": 10,
      "z": -4,
      "name": "Rock_Acid_Trunk_Standard"
    },
    {
      "x": 0,
      "y": 11,
      "z": -4,
      "name": "Rock_Acid_Trunk_Standard"
    },
    {
      "x": 0,
      "y": 15,
      "z": -4,
      "name": "Rock_Acid_Trunk_Light"
    },
    {
      "x": 0,
      "y": 16,
      "z": -4,
      "name": "Rock_Acid_Trunk_Medium"
    },
    {
      "x": 0,
      "y": 17,
      "z": -4,
      "name": "Rock_Acid_Trunk_Medium"
    },
    {
      "x": 0,
      "y": 18,
      "z": -4,
      "name": "Rock_Acid_Trunk_Medium"
    },
    {
      "x": 0,
      "y": 19,
      "z": -4,
      "name": "Rock_Acid_Trunk_Crimson"
    },
    {
      "x": 0,
      "y": 20,
      "z": -4,
      "name": "Rock_Crystal_Green_Block",
      "rotation": 4
    },
    {
      "x": 0,
      "y": 21,
      "z": -4,
      "name": "Rock_Crystal_Green_Block",
      "rotation": 4
    },
    {
      "x": 0,
      "y": 22,
      "z": -4,
      "name": "Empty"
    },
    {
      "x": 0,
      "y": 32,
      "z": -4,
      "name": "Rock_Acid_Trunk_Orange"
    },
    {
      "x": 0,
      "y": 33,
      "z": -4,
      "name": "Rock_Acid_Trunk_Crimson"
    },
    {
      "x": 0,
      "y": 8,
      "z": -3,
      "name": "Rock_Acid_Trunk_Medium"
    },
    {
      "x": 0,
      "y": 9,
      "z": -3,
      "name": "Rock_Acid_Trunk_Medium"
    },
    {
      "x": 0,
      "y": 10,
      "z": -3,
      "name": "Rock_Acid_Trunk_Medium"
    },
    {
      "x": 0,
      "y": 11,
      "z": -3,
      "name": "Rock_Acid_Trunk_Medium"
    },
    {
      "x": 0,
      "y": 12,
      "z": -3,
      "name": "Rock_Acid_Trunk_Standard"
    },
    {
      "x": 0,
      "y": 14,
      "z": -3,
      "name": "Rock_Acid_Trunk_Medium"
    },
    {
      "x": 0,
      "y": 15,
      "z": -3,
      "name": "Rock_Acid_Trunk_Medium"
    },
    {
      "x": 0,
      "y": 16,
      "z": -3,
      "name": "Rock_Acid_Trunk_Medium"
    },
    {
      "x": 0,
      "y": 17,
      "z": -3,
      "name": "Rock_Acid_Trunk_Medium"
    },
    {
      "x": 0,
      "y": 18,
      "z": -3,
      "name": "Rock_Acid_Trunk_Medium"
    },
    {
      "x": 0,
      "y": 19,
      "z": -3,
      "name": "Rock_Acid_Trunk_Crimson"
    },
    {
      "x": 0,
      "y": 20,
      "z": -3,
      "name": "Rock_Crystal_Green_Block",
      "rotation": 4
    },
    {
      "x": 0,
      "y": 21,
      "z": -3,
      "name": "Rock_Crystal_Green_Block",
      "rotation": 4
    },
    {
      "x": 0,
      "y": 22,
      "z": -3,
      "name": "Empty"
    },
    {
      "x": 0,
      "y": 30,
      "z": -3,
      "name": "Rock_Acid_Trunk_Orange"
    },
    {
      "x": 0,
      "y": 31,
      "z": -3,
      "name": "Rock_Acid_Trunk_Orange"
    },
    {
      "x": 0,
      "y": 32,
      "z": -3,
      "name": "Rock_Acid_Trunk_Crimson"
    },
    {
      "x": 0,
      "y": 33,
      "z": -3,
      "name": "Rock_Acid_Trunk_Crimson"
    },
    {
      "x": 0,
      "y": 8,
      "z": -2,
      "name": "Rock_Acid_Trunk_Medium"
    },
    {
      "x": 0,
      "y": 9,
      "z": -2,
      "name": "Rock_Acid_Trunk_Medium"
    },
    {
      "x": 0,
      "y": 10,
      "z": -2,
      "name": "Rock_Acid_Trunk_Medium"
    },
    {
      "x": 0,
      "y": 11,
      "z": -2,
      "name": "Rock_Acid_Trunk_Medium"
    },
    {
      "x": 0,
      "y": 12,
      "z": -2,
      "name": "Rock_Acid_Trunk_Medium"
    },
    {
      "x": 0,
      "y": 13,
      "z": -2,
      "name": "Rock_Acid_Trunk_Bright"
    },
    {
      "x": 0,
      "y": 14,
      "z": -2,
      "name": "Rock_Acid_Trunk_Medium"
    },
    {
      "x": 0,
      "y": 15,
      "z": -2,
      "name": "Rock_Acid_Trunk_Medium"
    },
    {
      "x": 0,
      "y": 16,
      "z": -2,
      "name": "Rock_Acid_Trunk_Medium"
    },
    {
      "x": 0,
      "y": 17,
      "z": -2,
      "name": "Rock_Acid_Trunk_Medium"
    },
    {
      "x": 0,
      "y": 18,
      "z": -2,
      "name": "Rock_Acid_Trunk_Medium"
    },
    {
      "x": 0,
      "y": 19,
      "z": -2,
      "name": "Rock_Acid_Trunk_Medium"
    },
    {
      "x": 0,
      "y": 20,
      "z": -2,
      "name": "Rock_Acid_Trunk_Crimson"
    },
    {
      "x": 0,
      "y": 21,
      "z": -2,
      "name": "Rock_Crystal_Green_Block",
      "rotation": 4
    },
    {
      "x": 0,
      "y": 22,
      "z": -2,
      "name": "Empty"
    },
    {
      "x": 0,
      "y": 27,
      "z": -2,
      "name": "Rock_Acid_Trunk_Orange"
    },
    {
      "x": 0,
      "y": 28,
      "z": -2,
      "name": "Rock_Acid_Trunk_Orange"
    },
    {
      "x": 0,
      "y": 29,
      "z": -2,
      "name": "Rock_Acid_Trunk_Orange"
    },
    {
      "x": 0,
      "y": 30,
      "z": -2,
      "name": "Rock_Acid_Trunk_Medium"
    },
    {
      "x": 0,
      "y": 31,
      "z": -2,
      "name": "Rock_Acid_Trunk_Crimson"
    },
    {
      "x": 0,
      "y": 32,
      "z": -2,
      "name": "Rock_Crystal_Green_Block",
      "rotation": 5
    },
    {
      "x": 0,
      "y": 33,
      "z": -2,
      "name": "Empty"
    },
    {
      "x": 0,
      "y": 0,
      "z": -1,
      "name": "Rock_Acid_Trunk_Light"
    },
    {
      "x": 0,
      "y": 1,
      "z": -1,
      "name": "Rock_Acid_Trunk_Light"
    },
    {
      "x": 0,
      "y": 2,
      "z": -1,
      "name": "Rock_Acid_Trunk_Medium"
    },
    {
      "x": 0,
      "y": 3,
      "z": -1,
      "name": "Rock_Acid_Trunk_Medium"
    },
    {
      "x": 0,
      "y": 4,
      "z": -1,
      "name": "Rock_Acid_Trunk_Medium"
    },
    {
      "x": 0,
      "y": 5,
      "z": -1,
      "name": "Rock_Acid_Trunk_Medium"
    },
    {
      "x": 0,
      "y": 6,
      "z": -1,
      "name": "Rock_Acid_Trunk_Medium"
    },
    {
      "x": 0,
      "y": 7,
      "z": -1,
      "name": "Rock_Acid_Trunk_Medium"
    },
    {
      "x": 0,
      "y": 8,
      "z": -1,
      "name": "Rock_Acid_Trunk_Medium"
    },
    {
      "x": 0,
      "y": 9,
      "z": -1,
      "name": "Rock_Acid_Trunk_Medium"
    },
    {
      "x": 0,
      "y": 10,
      "z": -1,
      "name": "Rock_Acid_Trunk_Medium"
    },
    {
      "x": 0,
      "y": 11,
      "z": -1,
      "name": "Rock_Acid_Trunk_Medium"
    },
    {
      "x": 0,
      "y": 12,
      "z": -1,
      "name": "Rock_Acid_Trunk_Medium"
    },
    {
      "x": 0,
      "y": 13,
      "z": -1,
      "name": "Rock_Acid_Trunk_Medium"
    },
    {
      "x": 0,
      "y": 14,
      "z": -1,
      "name": "Rock_Acid_Trunk_Medium"
    },
    {
      "x": 0,
      "y": 15,
      "z": -1,
      "name": "Rock_Acid_Trunk_Medium"
    },
    {
      "x": 0,
      "y": 16,
      "z": -1,
      "name": "Rock_Acid_Trunk_Medium"
    },
    {
      "x": 0,
      "y": 17,
      "z": -1,
      "name": "Rock_Acid_Trunk_Medium"
    },
    {
      "x": 0,
      "y": 18,
      "z": -1,
      "name": "Rock_Acid_Trunk_Medium"
    },
    {
      "x": 0,
      "y": 19,
      "z": -1,
      "name": "Rock_Acid_Trunk_Medium"
    },
    {
      "x": 0,
      "y": 20,
      "z": -1,
      "name": "Rock_Acid_Trunk_Medium"
    },
    {
      "x": 0,
      "y": 21,
      "z": -1,
      "name": "Rock_Acid_Trunk_Crimson"
    },
    {
      "x": 0,
      "y": 22,
      "z": -1,
      "name": "Empty"
    },
    {
      "x": 0,
      "y": 24,
      "z": -1,
      "name": "Rock_Acid_Trunk_Bright"
    },
    {
      "x": 0,
      "y": 25,
      "z": -1,
      "name": "Rock_Acid_Trunk_Bright"
    },
    {
      "x": 0,
      "y": 26,
      "z": -1,
      "name": "Rock_Acid_Trunk_Bright"
    },
    {
      "x": 0,
      "y": 27,
      "z": -1,
      "name": "Rock_Acid_Trunk_Medium"
    },
    {
      "x": 0,
      "y": 28,
      "z": -1,
      "name": "Rock_Acid_Trunk_Medium"
    },
    {
      "x": 0,
      "y": 29,
      "z": -1,
      "name": "Rock_Acid_Trunk_Medium"
    },
    {
      "x": 0,
      "y": 30,
      "z": -1,
      "name": "Rock_Acid_Trunk_Medium"
    },
    {
      "x": 0,
      "y": 31,
      "z": -1,
      "name": "Rock_Acid_Trunk_Crimson"
    },
    {
      "x": 0,
      "y": 32,
      "z": -1,
      "name": "Rock_Crystal_Green_Block",
      "rotation": 5
    },
    {
      "x": 0,
      "y": 33,
      "z": -1,
      "name": "Empty"
    },
    {
      "x": 0,
      "y": 0,
      "z": 0,
      "name": "Rock_Acid_Trunk_Light"
    },
    {
      "x": 0,
      "y": 1,
      "z": 0,
      "name": "Rock_Acid_Trunk_Medium"
    },
    {
      "x": 0,
      "y": 2,
      "z": 0,
      "name": "Rock_Acid_Trunk_Medium"
    },
    {
      "x": 0,
      "y": 3,
      "z": 0,
      "name": "Rock_Acid_Trunk_Medium"
    },
    {
      "x": 0,
      "y": 4,
      "z": 0,
      "name": "Rock_Acid_Trunk_Medium"
    },
    {
      "x": 0,
      "y": 5,
      "z": 0,
      "name": "Rock_Acid_Trunk_Medium"
    },
    {
      "x": 0,
      "y": 6,
      "z": 0,
      "name": "Rock_Acid_Trunk_Medium"
    },
    {
      "x": 0,
      "y": 7,
      "z": 0,
      "name": "Rock_Acid_Trunk_Medium"
    },
    {
      "x": 0,
      "y": 8,
      "z": 0,
      "name": "Rock_Acid_Trunk_Medium"
    },
    {
      "x": 0,
      "y": 9,
      "z": 0,
      "name": "Rock_Acid_Trunk_Medium"
    },
    {
      "x": 0,
      "y": 10,
      "z": 0,
      "name": "Rock_Acid_Trunk_Medium"
    },
    {
      "x": 0,
      "y": 11,
      "z": 0,
      "name": "Rock_Acid_Trunk_Medium"
    },
    {
      "x": 0,
      "y": 12,
      "z": 0,
      "name": "Rock_Acid_Trunk_Medium"
    },
    {
      "x": 0,
      "y": 13,
      "z": 0,
      "name": "Rock_Acid_Trunk_Medium"
    },
    {
      "x": 0,
      "y": 14,
      "z": 0,
      "name": "Rock_Acid_Trunk_Medium"
    },
    {
      "x": 0,
      "y": 15,
      "z": 0,
      "name": "Rock_Acid_Trunk_Medium"
    },
    {
      "x": 0,
      "y": 16,
      "z": 0,
      "name": "Rock_Acid_Trunk_Medium"
    },
    {
      "x": 0,
      "y": 17,
      "z": 0,
      "name": "Rock_Acid_Trunk_Medium"
    },
    {
      "x": 0,
      "y": 18,
      "z": 0,
      "name": "Rock_Acid_Trunk_Medium"
    },
    {
      "x": 0,
      "y": 19,
      "z": 0,
      "name": "Rock_Acid_Trunk_Medium"
    },
    {
      "x": 0,
      "y": 20,
      "z": 0,
      "name": "Rock_Acid_Trunk_Orange"
    },
    {
      "x": 0,
      "y": 22,
      "z": 0,
      "name": "Rock_Acid_Trunk_Orange"
    },
    {
      "x": 0,
      "y": 23,
      "z": 0,
      "name": "Rock_Acid_Trunk_Bright"
    },
    {
      "x": 0,
      "y": 24,
      "z": 0,
      "name": "Rock_Acid_Trunk_Medium"
    },
    {
      "x": 0,
      "y": 25,
      "z": 0,
      "name": "Rock_Acid_Trunk_Medium"
    },
    {
      "x": 0,
      "y": 26,
      "z": 0,
      "name": "Rock_Acid_Trunk_Medium"
    },
    {
      "x": 0,
      "y": 27,
      "z": 0,
      "name": "Rock_Acid_Trunk_Medium"
    },
    {
      "x": 0,
      "y": 28,
      "z": 0,
      "name": "Rock_Acid_Trunk_Medium"
    },
    {
      "x": 0,
      "y": 29,
      "z": 0,
      "name": "Rock_Acid_Trunk_Medium"
    },
    {
      "x": 0,
      "y": 30,
      "z": 0,
      "name": "Rock_Acid_Trunk_Medium"
    },
    {
      "x": 0,
      "y": 31,
      "z": 0,
      "name": "Rock_Acid_Trunk_Crimson"
    },
    {
      "x": 0,
      "y": 32,
      "z": 0,
      "name": "Rock_Crystal_Green_Block",
      "rotation": 5
    },
    {
      "x": 0,
      "y": 33,
      "z": 0,
      "name": "Empty"
    },
    {
      "x": 0,
      "y": 3,
      "z": 1,
      "name": "Rock_Acid_Trunk_Medium"
    },
    {
      "x": 0,
      "y": 4,
      "z": 1,
      "name": "Rock_Acid_Trunk_Medium"
    },
    {
      "x": 0,
      "y": 5,
      "z": 1,
      "name": "Rock_Acid_Trunk_Medium"
    },
    {
      "x": 0,
      "y": 6,
      "z": 1,
      "name": "Rock_Acid_Trunk_Medium"
    },
    {
      "x": 0,
      "y": 7,
      "z": 1,
      "name": "Rock_Acid_Trunk_Medium"
    },
    {
      "x": 0,
      "y": 8,
      "z": 1,
      "name": "Rock_Acid_Trunk_Medium"
    },
    {
      "x": 0,
      "y": 9,
      "z": 1,
      "name": "Rock_Acid_Trunk_Medium"
    },
    {
      "x": 0,
      "y": 10,
      "z": 1,
      "name": "Rock_Acid_Trunk_Medium"
    },
    {
      "x": 0,
      "y": 11,
      "z": 1,
      "name": "Rock_Acid_Trunk_Medium"
    },
    {
      "x": 0,
      "y": 12,
      "z": 1,
      "name": "Rock_Acid_Trunk_Medium"
    },
    {
      "x": 0,
      "y": 13,
      "z": 1,
      "name": "Rock_Acid_Trunk_Medium"
    },
    {
      "x": 0,
      "y": 14,
      "z": 1,
      "name": "Rock_Acid_Trunk_Medium"
    },
    {
      "x": 0,
      "y": 15,
      "z": 1,
      "name": "Rock_Acid_Trunk_Medium"
    },
    {
      "x": 0,
      "y": 16,
      "z": 1,
      "name": "Rock_Acid_Trunk_Medium"
    },
    {
      "x": 0,
      "y": 17,
      "z": 1,
      "name": "Rock_Acid_Trunk_Medium"
    },
    {
      "x": 0,
      "y": 18,
      "z": 1,
      "name": "Rock_Acid_Trunk_Medium"
    },
    {
      "x": 0,
      "y": 19,
      "z": 1,
      "name": "Rock_Acid_Trunk_Medium"
    },
    {
      "x": 0,
      "y": 20,
      "z": 1,
      "name": "Rock_Acid_Trunk_Medium"
    },
    {
      "x": 0,
      "y": 21,
      "z": 1,
      "name": "Rock_Acid_Trunk_Orange"
    },
    {
      "x": 0,
      "y": 22,
      "z": 1,
      "name": "Rock_Acid_Trunk_Medium"
    },
    {
      "x": 0,
      "y": 23,
      "z": 1,
      "name": "Rock_Acid_Trunk_Medium"
    },
    {
      "x": 0,
      "y": 24,
      "z": 1,
      "name": "Rock_Acid_Trunk_Medium"
    },
    {
      "x": 0,
      "y": 25,
      "z": 1,
      "name": "Rock_Acid_Trunk_Medium"
    },
    {
      "x": 0,
      "y": 26,
      "z": 1,
      "name": "Rock_Acid_Trunk_Medium"
    },
    {
      "x": 0,
      "y": 27,
      "z": 1,
      "name": "Rock_Acid_Trunk_Medium"
    },
    {
      "x": 0,
      "y": 28,
      "z": 1,
      "name": "Rock_Acid_Trunk_Medium"
    },
    {
      "x": 0,
      "y": 29,
      "z": 1,
      "name": "Rock_Acid_Trunk_Medium"
    },
    {
      "x": 0,
      "y": 30,
      "z": 1,
      "name": "Rock_Acid_Trunk_Crimson"
    },
    {
      "x": 0,
      "y": 31,
      "z": 1,
      "name": "Rock_Crystal_Green_Block",
      "rotation": 5
    },
    {
      "x": 0,
      "y": 32,
      "z": 1,
      "name": "Rock_Crystal_Green_Block",
      "rotation": 5
    },
    {
      "x": 0,
      "y": 33,
      "z": 1,
      "name": "Empty"
    },
    {
      "x": 0,
      "y": 6,
      "z": 2,
      "name": "Rock_Acid_Trunk_Medium"
    },
    {
      "x": 0,
      "y": 7,
      "z": 2,
      "name": "Rock_Acid_Trunk_Medium"
    },
    {
      "x": 0,
      "y": 8,
      "z": 2,
      "name": "Rock_Acid_Trunk_Medium"
    },
    {
      "x": 0,
      "y": 9,
      "z": 2,
      "name": "Rock_Acid_Trunk_Medium"
    },
    {
      "x": 0,
      "y": 10,
      "z": 2,
      "name": "Rock_Acid_Trunk_Medium"
    },
    {
      "x": 0,
      "y": 11,
      "z": 2,
      "name": "Rock_Acid_Trunk_Medium"
    },
    {
      "x": 0,
      "y": 12,
      "z": 2,
      "name": "Rock_Acid_Trunk_Medium"
    },
    {
      "x": 0,
      "y": 13,
      "z": 2,
      "name": "Rock_Acid_Trunk_Medium"
    },
    {
      "x": 0,
      "y": 14,
      "z": 2,
      "name": "Rock_Acid_Trunk_Medium"
    },
    {
      "x": 0,
      "y": 15,
      "z": 2,
      "name": "Rock_Acid_Trunk_Medium"
    },
    {
      "x": 0,
      "y": 16,
      "z": 2,
      "name": "Rock_Acid_Trunk_Medium"
    },
    {
      "x": 0,
      "y": 17,
      "z": 2,
      "name": "Rock_Acid_Trunk_Medium"
    },
    {
      "x": 0,
      "y": 18,
      "z": 2,
      "name": "Rock_Acid_Trunk_Medium"
    },
    {
      "x": 0,
      "y": 19,
      "z": 2,
      "name": "Rock_Acid_Trunk_Medium"
    },
    {
      "x": 0,
      "y": 20,
      "z": 2,
      "name": "Rock_Acid_Trunk_Medium"
    },
    {
      "x": 0,
      "y": 21,
      "z": 2,
      "name": "Rock_Acid_Trunk_Medium"
    },
    {
      "x": 0,
      "y": 22,
      "z": 2,
      "name": "Rock_Acid_Trunk_Medium"
    },
    {
      "x": 0,
      "y": 23,
      "z": 2,
      "name": "Rock_Acid_Trunk_Medium"
    },
    {
      "x": 0,
      "y": 24,
      "z": 2,
      "name": "Rock_Acid_Trunk_Medium"
    },
    {
      "x": 0,
      "y": 25,
      "z": 2,
      "name": "Rock_Acid_Trunk_Medium"
    },
    {
      "x": 0,
      "y": 26,
      "z": 2,
      "name": "Rock_Acid_Trunk_Medium"
    },
    {
      "x": 0,
      "y": 27,
      "z": 2,
      "name": "Rock_Acid_Trunk_Medium"
    },
    {
      "x": 0,
      "y": 28,
      "z": 2,
      "name": "Rock_Acid_Trunk_Medium"
    },
    {
      "x": 0,
      "y": 29,
      "z": 2,
      "name": "Rock_Acid_Trunk_Crimson"
    },
    {
      "x": 0,
