{
  "version": 8,
  "blockIdVersion": 10,
  "anchorX": 0,
  "anchorY": 5,
  "anchorZ": 0,
  "blocks": [
    {
      "x": -40,
      "y": 2,
      "z": -12,
      "name": "Rock_Acid_Trunk_Light"
    },
    {
      "x": -40,
      "y": 2,
      "z": -11,
      "name": "Rock_Acid_Trunk_Light"
    },
    {
      "x": -39,
      "y": 2,
      "z": -10,
      "name": "Rock_Acid_Trunk_Light"
    },
    {
      "x": -39,
      "y": 2,
      "z": -9,
      "name": "Rock_Acid_Trunk_Light"
    },
    {
      "x": -38,
      "y": 2,
      "z": -8,
      "name": "Rock_Acid_Trunk_Light"
    },
    {
      "x": -38,
      "y": 2,
      "z": -7,
      "name": "Rock_Acid_Trunk_Light"
    },
    {
      "x": -38,
      "y": 3,
      "z": -7,
      "name": "Rock_Acid_Trunk_Light"
    },
    {
      "x": -38,
      "y": 2,
      "z": -6,
      "name": "Rock_Acid_Trunk_Light"
    },
    {
      "x": -37,
      "y": 1,
      "z": -6,
      "name": "Rock_Acid_Trunk_Light"
    },
    {
      "x": -37,
      "y": 2,
      "z": -6,
      "name": "Rock_Acid_Trunk_Light"
    },
    {
      "x": -37,
      "y": 3,
      "z": -6,
      "name": "Rock_Acid_Trunk_Light"
    },
    {
      "x": -37,
      "y": 2,
      "z": -5,
      "name": "Rock_Acid_Trunk_Light"
    },
    {
      "x": -37,
      "y": 2,
      "z": 21,
      "name": "Rock_Acid_Trunk_Light"
    },
    {
      "x": -36,
      "y": 1,
      "z": -5,
      "name": "Rock_Acid_Trunk_Light"
    },
    {
      "x": -36,
      "y": 2,
      "z": -5,
      "name": "Rock_Acid_Trunk_Light"
    },
    {
      "x": -36,
      "y": 3,
      "z": -5,
      "name": "Rock_Acid_Trunk_Light"
    },
    {
      "x": -36,
      "y": 2,
      "z": -4,
      "name": "Rock_Acid_Trunk_Light"
    },
    {
      "x": -36,
      "y": 2,
      "z": 20,
      "name": "Rock_Acid_Trunk_Light"
    },
    {
      "x": -36,
      "y": 3,
      "z": 20,
      "name": "Rock_Acid_Trunk_Light"
    },
    {
      "x": -36,
      "y": 2,
      "z": 21,
      "name": "Rock_Acid_Trunk_Light"
    },
    {
      "x": -35,
      "y": 12,
      "z": -13,
      "name": "Rock_Acid_Trunk_Light"
    },
    {
      "x": -35,
      "y": 13,
      "z": -13,
      "name": "Rock_Acid_Trunk_Medium"
    },
    {
      "x": -35,
      "y": 11,
      "z": -12,
      "name": "Rock_Acid_Trunk_Light"
    },
    {
      "x": -35,
      "y": 12,
      "z": -12,
      "name": "Rock_Acid_Trunk_Light"
    },
    {
      "x": -35,
      "y": 13,
      "z": -12,
      "name": "Rock_Acid_Trunk_Medium"
    },
    {
      "x": -35,
      "y": 14,
      "z": -12,
      "name": "Rock_Acid_Trunk_Medium"
    },
    {
      "x": -35,
      "y": 10,
      "z": -11,
      "name": "Rock_Acid_Trunk_Light"
    },
    {
      "x": -35,
      "y": 11,
      "z": -11,
      "name": "Rock_Acid_Trunk_Light"
    },
    {
      "x": -35,
      "y": 12,
      "z": -11,
      "name": "Rock_Acid_Trunk_Light"
    },
    {
      "x": -35,
      "y": 13,
      "z": -11,
      "name": "Rock_Acid_Trunk_Medium"
    },
    {
      "x": -35,
      "y": 14,
      "z": -11,
      "name": "Rock_Acid_Trunk_Medium"
    },
    {
      "x": -35,
      "y": 11,
      "z": -10,
      "name": "Rock_Acid_Trunk_Light"
    },
    {
      "x": -35,
      "y": 12,
      "z": -10,
      "name": "Rock_Acid_Trunk_Light"
    },
    {
      "x": -35,
      "y": 13,
      "z": -10,
      "name": "Rock_Acid_Trunk_Light"
    },
    {
      "x": -35,
      "y": 1,
      "z": -4,
      "name": "Rock_Acid_Trunk_Light"
    },
    {
      "x": -35,
      "y": 2,
      "z": -4,
      "name": "Rock_Acid_Trunk_Light"
    },
    {
      "x": -35,
      "y": 3,
      "z": -4,
      "name": "Rock_Acid_Trunk_Standard"
    },
    {
      "x": -35,
      "y": 2,
      "z": -3,
      "name": "Rock_Acid_Trunk_Light"
    },
    {
      "x": -35,
      "y": 3,
      "z": -3,
      "name": "Rock_Acid_Trunk_Light"
    },
    {
      "x": -35,
      "y": 4,
      "z": 19,
      "name": "Rock_Acid_Trunk_Light"
    },
    {
      "x": -35,
      "y": 3,
      "z": 20,
      "name": "Rock_Acid_Trunk_Light"
    },
    {
      "x": -35,
      "y": 4,
      "z": 20,
      "name": "Rock_Acid_Trunk_Light"
    },
    {
      "x": -34,
      "y": 11,
      "z": -13,
      "name": "Rock_Acid_Trunk_Light"
    },
    {
      "x": -34,
      "y": 12,
      "z": -13,
      "name": "Rock_Acid_Trunk_Light"
    },
    {
      "x": -34,
      "y": 13,
      "z": -13,
      "name": "Rock_Acid_Trunk_Light"
    },
    {
      "x": -34,
      "y": 14,
      "z": -13,
      "name": "Rock_Acid_Trunk_Medium"
    },
    {
      "x": -34,
      "y": 10,
      "z": -12,
      "name": "Rock_Acid_Trunk_Light"
    },
    {
      "x": -34,
      "y": 11,
      "z": -12,
      "name": "Rock_Acid_Trunk_Medium"
    },
    {
      "x": -34,
      "y": 12,
      "z": -12,
      "name": "Rock_Acid_Trunk_Medium"
    },
    {
      "x": -34,
      "y": 13,
      "z": -12,
      "name": "Rock_Acid_Trunk_Medium"
    },
    {
      "x": -34,
      "y": 14,
      "z": -12,
      "name": "Rock_Acid_Trunk_Medium"
    },
    {
      "x": -34,
      "y": 15,
      "z": -12,
      "name": "Rock_Acid_Trunk_Medium"
    },
    {
      "x": -34,
      "y": 9,
      "z": -11,
      "name": "Rock_Acid_Trunk_Light"
    },
    {
      "x": -34,
      "y": 10,
      "z": -11,
      "name": "Rock_Acid_Trunk_Medium"
    },
    {
      "x": -34,
      "y": 11,
      "z": -11,
      "name": "Rock_Acid_Trunk_Medium"
    },
    {
      "x": -34,
      "y": 12,
      "z": -11,
      "name": "Rock_Acid_Trunk_Medium"
    },
    {
      "x": -34,
      "y": 13,
      "z": -11,
      "name": "Rock_Acid_Trunk_Medium"
    },
    {
      "x": -34,
      "y": 14,
      "z": -11,
      "name": "Rock_Acid_Trunk_Medium"
    },
    {
      "x": -34,
      "y": 15,
      "z": -11,
      "name": "Rock_Acid_Trunk_Medium"
    },
    {
      "x": -34,
      "y": 16,
      "z": -11,
      "name": "Rock_Acid_Trunk_Medium"
    },
    {
      "x": -34,
      "y": 8,
      "z": -10,
      "name": "Rock_Acid_Trunk_Light"
    },
    {
      "x": -34,
      "y": 9,
      "z": -10,
      "name": "Rock_Acid_Trunk_Light"
    },
    {
      "x": -34,
      "y": 10,
      "z": -10,
      "name": "Rock_Acid_Trunk_Light"
    },
    {
      "x": -34,
      "y": 11,
      "z": -10,
      "name": "Rock_Acid_Trunk_Light"
    },
    {
      "x": -34,
      "y": 12,
      "z": -10,
      "name": "Rock_Acid_Trunk_Light"
    },
    {
      "x": -34,
      "y": 13,
      "z": -10,
      "name": "Rock_Acid_Trunk_Light"
    },
    {
      "x": -34,
      "y": 14,
      "z": -10,
      "name": "Rock_Acid_Trunk_Light"
    },
    {
      "x": -34,
      "y": 15,
      "z": -10,
      "name": "Rock_Acid_Trunk_Medium"
    },
    {
      "x": -34,
      "y": 16,
      "z": -10,
      "name": "Rock_Acid_Trunk_Medium"
    },
    {
      "x": -34,
      "y": 9,
      "z": -9,
      "name": "Rock_Acid_Trunk_Light"
    },
    {
      "x": -34,
      "y": 15,
      "z": -9,
      "name": "Rock_Acid_Trunk_Light"
    },
    {
      "x": -34,
      "y": 3,
      "z": -4,
      "name": "Rock_Acid_Trunk_Light"
    },
    {
      "x": -34,
      "y": 3,
      "z": -3,
      "name": "Rock_Acid_Trunk_Light"
    },
    {
      "x": -34,
      "y": 4,
      "z": -3,
      "name": "Rock_Acid_Trunk_Standard"
    },
    {
      "x": -34,
      "y": 3,
      "z": 18,
      "name": "Rock_Acid_Trunk_Light"
    },
    {
      "x": -34,
      "y": 4,
      "z": 18,
      "name": "Rock_Acid_Trunk_Light"
    },
    {
      "x": -34,
      "y": 5,
      "z": 18,
      "name": "Rock_Acid_Trunk_Light"
    },
    {
      "x": -34,
      "y": 3,
      "z": 19,
      "name": "Rock_Acid_Trunk_Light"
    },
    {
      "x": -34,
      "y": 4,
      "z": 19,
      "name": "Rock_Acid_Trunk_Light"
    },
    {
      "x": -34,
      "y": 5,
      "z": 19,
      "name": "Rock_Acid_Trunk_Light"
    },
    {
      "x": -34,
      "y": 4,
      "z": 20,
      "name": "Rock_Acid_Trunk_Light"
    },
    {
      "x": -33,
      "y": 12,
      "z": -13,
      "name": "Rock_Acid_Trunk_Light"
    },
    {
      "x": -33,
      "y": 9,
      "z": -12,
      "name": "Rock_Acid_Trunk_Light"
    },
    {
      "x": -33,
      "y": 10,
      "z": -12,
      "name": "Rock_Acid_Trunk_Light"
    },
    {
      "x": -33,
      "y": 11,
      "z": -12,
      "name": "Rock_Acid_Trunk_Light"
    },
    {
      "x": -33,
      "y": 12,
      "z": -12,
      "name": "Rock_Acid_Trunk_Light"
    },
    {
      "x": -33,
      "y": 13,
      "z": -12,
      "name": "Rock_Acid_Trunk_Light"
    },
    {
      "x": -33,
      "y": 14,
      "z": -12,
      "name": "Rock_Acid_Trunk_Medium"
    },
    {
      "x": -33,
      "y": 15,
      "z": -12,
      "name": "Rock_Acid_Trunk_Medium"
    },
    {
      "x": -33,
      "y": 16,
      "z": -12,
      "name": "Rock_Acid_Trunk_Medium"
    },
    {
      "x": -33,
      "y": 8,
      "z": -11,
      "name": "Rock_Acid_Trunk_Light"
    },
    {
      "x": -33,
      "y": 9,
      "z": -11,
      "name": "Rock_Acid_Trunk_Medium"
    },
    {
      "x": -33,
      "y": 10,
      "z": -11,
      "name": "Rock_Acid_Trunk_Medium"
    },
    {
      "x": -33,
      "y": 11,
      "z": -11,
      "name": "Rock_Acid_Trunk_Medium"
    },
    {
      "x": -33,
      "y": 12,
      "z": -11,
      "name": "Rock_Acid_Trunk_Medium"
    },
    {
      "x": -33,
      "y": 13,
      "z": -11,
      "name": "Rock_Acid_Trunk_Medium"
    },
    {
      "x": -33,
      "y": 14,
      "z": -11,
      "name": "Rock_Acid_Trunk_Medium"
    },
    {
      "x": -33,
      "y": 15,
      "z": -11,
      "name": "Rock_Acid_Trunk_Medium"
    },
    {
      "x": -33,
      "y": 16,
      "z": -11,
      "name": "Rock_Acid_Trunk_Medium"
    },
    {
      "x": -33,
      "y": 17,
      "z": -11,
      "name": "Rock_Acid_Trunk_Standard"
    },
    {
      "x": -33,
      "y": 8,
      "z": -10,
      "name": "Rock_Acid_Trunk_Light"
    },
    {
      "x": -33,
      "y": 9,
      "z": -10,
      "name": "Rock_Acid_Trunk_Medium"
    },
    {
      "x": -33,
      "y": 10,
      "z": -10,
      "name": "Rock_Acid_Trunk_Medium"
    },
    {
      "x": -33,
      "y": 11,
      "z": -10,
      "name": "Rock_Acid_Trunk_Medium"
    },
    {
      "x": -33,
      "y": 12,
      "z": -10,
      "name": "Rock_Acid_Trunk_Light"
    },
    {
      "x": -33,
      "y": 13,
      "z": -10,
      "name": "Rock_Acid_Trunk_Light"
    },
    {
      "x": -33,
      "y": 14,
      "z": -10,
      "name": "Rock_Acid_Trunk_Medium"
    },
    {
      "x": -33,
      "y": 15,
      "z": -10,
      "name": "Rock_Acid_Trunk_Medium"
    },
    {
      "x": -33,
      "y": 16,
      "z": -10,
      "name": "Rock_Acid_Trunk_Medium"
    },
    {
      "x": -33,
      "y": 17,
      "z": -10,
      "name": "Rock_Acid_Trunk_Standard"
    },
    {
      "x": -33,
      "y": 7,
      "z": -9,
      "name": "Rock_Acid_Trunk_Light"
    },
    {
      "x": -33,
      "y": 8,
      "z": -9,
      "name": "Rock_Acid_Trunk_Light"
    },
    {
      "x": -33,
      "y": 9,
      "z": -9,
      "name": "Rock_Acid_Trunk_Medium"
    },
    {
      "x": -33,
      "y": 10,
      "z": -9,
      "name": "Rock_Acid_Trunk_Medium"
    },
    {
      "x": -33,
      "y": 11,
      "z": -9,
      "name": "Rock_Acid_Trunk_Medium"
    },
    {
      "x": -33,
      "y": 14,
      "z": -9,
      "name": "Rock_Acid_Trunk_Light"
    },
    {
      "x": -33,
      "y": 15,
      "z": -9,
      "name": "Rock_Acid_Trunk_Light"
    },
    {
      "x": -33,
      "y": 16,
      "z": -9,
      "name": "Rock_Acid_Trunk_Medium"
    },
    {
      "x": -33,
      "y": 7,
      "z": -8,
      "name": "Rock_Acid_Trunk_Light"
    },
    {
      "x": -33,
      "y": 8,
      "z": -8,
      "name": "Rock_Acid_Trunk_Light"
    },
    {
      "x": -33,
      "y": 9,
      "z": -8,
      "name": "Rock_Acid_Trunk_Medium"
    },
    {
      "x": -33,
      "y": 8,
      "z": -7,
      "name": "Rock_Acid_Trunk_Light"
    },
    {
      "x": -33,
      "y": 3,
      "z": -3,
      "name": "Rock_Acid_Trunk_Light"
    },
    {
      "x": -33,
      "y": 4,
      "z": -3,
      "name": "Rock_Acid_Trunk_Standard"
    },
    {
      "x": -33,
      "y": 3,
      "z": -2,
      "name": "Rock_Acid_Trunk_Light"
    },
    {
      "x": -33,
      "y": 4,
      "z": -2,
      "name": "Rock_Acid_Trunk_Light"
    },
    {
      "x": -33,
      "y": 4,
      "z": 17,
      "name": "Rock_Acid_Trunk_Light"
    },
    {
      "x": -33,
      "y": 5,
      "z": 17,
      "name": "Rock_Acid_Trunk_Light"
    },
    {
      "x": -33,
      "y": 3,
      "z": 18,
      "name": "Rock_Acid_Trunk_Light"
    },
    {
      "x": -33,
      "y": 4,
      "z": 18,
      "name": "Rock_Acid_Trunk_Light"
    },
    {
      "x": -33,
      "y": 5,
      "z": 18,
      "name": "Rock_Acid_Trunk_Light"
    },
    {
      "x": -33,
      "y": 4,
      "z": 19,
      "name": "Rock_Acid_Trunk_Light"
    },
    {
      "x": -33,
      "y": 5,
      "z": 19,
      "name": "Rock_Acid_Trunk_Light"
    },
    {
      "x": -32,
      "y": 10,
      "z": -12,
      "name": "Rock_Acid_Trunk_Light"
    },
    {
      "x": -32,
      "y": 13,
      "z": -12,
      "name": "Rock_Acid_Trunk_Light"
    },
    {
      "x": -32,
      "y": 14,
      "z": -12,
      "name": "Rock_Acid_Trunk_Medium"
    },
    {
      "x": -32,
      "y": 15,
      "z": -12,
      "name": "Rock_Acid_Trunk_Medium"
    },
    {
      "x": -32,
      "y": 16,
      "z": -12,
      "name": "Rock_Acid_Trunk_Medium"
    },
    {
      "x": -32,
      "y": 9,
      "z": -11,
      "name": "Rock_Acid_Trunk_Light"
    },
    {
      "x": -32,
      "y": 10,
      "z": -11,
      "name": "Rock_Acid_Trunk_Light"
    },
    {
      "x": -32,
      "y": 11,
      "z": -11,
      "name": "Rock_Acid_Trunk_Light"
    },
    {
      "x": -32,
      "y": 12,
      "z": -11,
      "name": "Rock_Acid_Trunk_Light"
    },
    {
      "x": -32,
      "y": 13,
      "z": -11,
      "name": "Rock_Acid_Trunk_Light"
    },
    {
      "x": -32,
      "y": 14,
      "z": -11,
      "name": "Rock_Acid_Trunk_Light"
    },
    {
      "x": -32,
      "y": 15,
      "z": -11,
      "name": "Rock_Acid_Trunk_Medium"
    },
    {
      "x": -32,
      "y": 16,
      "z": -11,
      "name": "Rock_Acid_Trunk_Medium"
    },
    {
      "x": -32,
      "y": 17,
      "z": -11,
      "name": "Rock_Acid_Trunk_Standard"
    },
    {
      "x": -32,
      "y": 7,
      "z": -10,
      "name": "Rock_Acid_Trunk_Light"
    },
    {
      "x": -32,
      "y": 8,
      "z": -10,
      "name": "Rock_Acid_Trunk_Light"
    },
    {
      "x": -32,
      "y": 9,
      "z": -10,
      "name": "Rock_Acid_Trunk_Medium"
    },
    {
      "x": -32,
      "y": 10,
      "z": -10,
      "name": "Rock_Acid_Trunk_Medium"
    },
    {
      "x": -32,
      "y": 11,
      "z": -10,
      "name": "Rock_Acid_Trunk_Medium"
    },
    {
      "x": -32,
      "y": 13,
      "z": -10,
      "name": "Rock_Acid_Trunk_Light"
    },
    {
      "x": -32,
      "y": 14,
      "z": -10,
      "name": "Rock_Acid_Trunk_Medium"
    },
    {
      "x": -32,
      "y": 15,
      "z": -10,
      "name": "Rock_Acid_Trunk_Medium"
    },
    {
      "x": -32,
      "y": 16,
      "z": -10,
      "name": "Rock_Acid_Trunk_Medium"
    },
    {
      "x": -32,
      "y": 17,
      "z": -10,
      "name": "Rock_Acid_Trunk_Medium"
    },
    {
      "x": -32,
      "y": 18,
      "z": -10,
      "name": "Rock_Acid_Trunk_Standard"
    },
    {
      "x": -32,
      "y": 6,
      "z": -9,
      "name": "Rock_Acid_Trunk_Light"
    },
    {
      "x": -32,
      "y": 7,
      "z": -9,
      "name": "Rock_Acid_Trunk_Medium"
    },
    {
      "x": -32,
      "y": 8,
      "z": -9,
      "name": "Rock_Acid_Trunk_Medium"
    },
    {
      "x": -32,
      "y": 9,
      "z": -9,
      "name": "Rock_Acid_Trunk_Medium"
    },
    {
      "x": -32,
      "y": 10,
      "z": -9,
      "name": "Rock_Acid_Trunk_Standard"
    },
    {
      "x": -32,
      "y": 14,
      "z": -9,
      "name": "Rock_Acid_Trunk_Light"
    },
    {
      "x": -32,
      "y": 15,
      "z": -9,
      "name": "Rock_Acid_Trunk_Medium"
    },
    {
      "x": -32,
      "y": 16,
      "z": -9,
      "name": "Rock_Acid_Trunk_Medium"
    },
    {
      "x": -32,
      "y": 17,
      "z": -9,
      "name": "Rock_Acid_Trunk_Standard"
    },
    {
      "x": -32,
      "y": 18,
      "z": -9,
      "name": "Rock_Acid_Trunk_Standard"
    },
    {
      "x": -32,
      "y": 6,
      "z": -8,
      "name": "Rock_Acid_Trunk_Light"
    },
    {
      "x": -32,
      "y": 7,
      "z": -8,
      "name": "Rock_Acid_Trunk_Medium"
    },
    {
      "x": -32,
      "y": 8,
      "z": -8,
      "name": "Rock_Acid_Trunk_Medium"
    },
    {
      "x": -32,
      "y": 9,
      "z": -8,
      "name": "Rock_Acid_Trunk_Medium"
    },
    {
      "x": -32,
      "y": 10,
      "z": -8,
      "name": "Rock_Acid_Trunk_Standard"
    },
    {
      "x": -32,
      "y": 15,
      "z": -8,
      "name": "Rock_Acid_Trunk_Light"
    },
    {
      "x": -32,
      "y": 16,
      "z": -8,
      "name": "Rock_Acid_Trunk_Medium"
    },
    {
      "x": -32,
      "y": 17,
      "z": -8,
      "name": "Rock_Acid_Trunk_Medium"
    },
    {
      "x": -32,
      "y": 18,
      "z": -8,
      "name": "Rock_Acid_Trunk_Standard"
    },
    {
      "x": -32,
      "y": 7,
      "z": -7,
      "name": "Rock_Acid_Trunk_Light"
    },
    {
      "x": -32,
      "y": 8,
      "z": -7,
      "name": "Rock_Acid_Trunk_Medium"
    },
    {
      "x": -32,
      "y": 9,
      "z": -7,
      "name": "Rock_Acid_Trunk_Standard"
    },
    {
      "x": -32,
      "y": 17,
      "z": -7,
      "name": "Rock_Acid_Trunk_Medium"
    },
    {
      "x": -32,
      "y": 3,
      "z": -3,
      "name": "Rock_Acid_Trunk_Light"
    },
    {
      "x": -32,
      "y": 3,
      "z": -2,
      "name": "Rock_Acid_Trunk_Light"
    },
    {
      "x": -32,
      "y": 4,
      "z": -2,
      "name": "Rock_Acid_Trunk_Standard"
    },
    {
      "x": -32,
      "y": 4,
      "z": -1,
      "name": "Rock_Acid_Trunk_Light"
    },
    {
      "x": -32,
      "y": 5,
      "z": 16,
      "name": "Rock_Acid_Trunk_Light"
    },
    {
      "x": -32,
      "y": 6,
      "z": 16,
      "name": "Rock_Acid_Trunk_Light"
    },
    {
      "x": -32,
      "y": 4,
      "z": 17,
      "name": "Rock_Acid_Trunk_Light"
    },
    {
      "x": -32,
      "y": 5,
      "z": 17,
      "name": "Rock_Acid_Trunk_Light"
    },
    {
      "x": -32,
      "y": 6,
      "z": 17,
      "name": "Rock_Acid_Trunk_Light"
    },
    {
      "x": -32,
      "y": 4,
      "z": 18,
      "name": "Rock_Acid_Trunk_Light"
    },
    {
      "x": -32,
      "y": 5,
      "z": 18,
      "name": "Rock_Acid_Trunk_Standard"
    },
    {
      "x": -32,
      "y": 5,
      "z": 19,
      "name": "Rock_Acid_Trunk_Light"
    },
    {
      "x": -31,
      "y": 16,
      "z": -11,
      "name": "Rock_Acid_Trunk_Medium"
    },
    {
      "x": -31,
      "y": 8,
      "z": -10,
      "name": "Rock_Acid_Trunk_Light"
    },
    {
      "x": -31,
      "y": 9,
      "z": -10,
      "name": "Rock_Acid_Trunk_Medium"
    },
    {
      "x": -31,
      "y": 14,
      "z": -10,
      "name": "Rock_Acid_Trunk_Light"
    },
    {
      "x": -31,
      "y": 15,
      "z": -10,
      "name": "Rock_Acid_Trunk_Medium"
    },
    {
      "x": -31,
      "y": 16,
      "z": -10,
      "name": "Rock_Acid_Trunk_Medium"
    },
    {
      "x": -31,
      "y": 17,
      "z": -10,
      "name": "Rock_Acid_Trunk_Standard"
    },
    {
      "x": -31,
      "y": 18,
      "z": -10,
      "name": "Rock_Acid_Trunk_Standard"
    },
    {
      "x": -31,
      "y": 6,
      "z": -9,
      "name": "Rock_Acid_Trunk_Light"
    },
    {
      "x": -31,
      "y": 7,
      "z": -9,
      "name": "Rock_Acid_Trunk_Light"
    },
    {
      "x": -31,
      "y": 8,
      "z": -9,
      "name": "Rock_Acid_Trunk_Medium"
    },
    {
      "x": -31,
      "y": 9,
      "z": -9,
      "name": "Rock_Acid_Trunk_Medium"
    },
    {
      "x": -31,
      "y": 10,
      "z": -9,
      "name": "Rock_Acid_Trunk_Medium"
    },
    {
      "x": -31,
      "y": 15,
      "z": -9,
      "name": "Rock_Acid_Trunk_Light"
    },
    {
      "x": -31,
      "y": 16,
      "z": -9,
      "name": "Rock_Acid_Trunk_Medium"
    },
    {
      "x": -31,
      "y": 17,
      "z": -9,
      "name": "Rock_Acid_Trunk_Medium"
    },
    {
      "x": -31,
      "y": 18,
      "z": -9,
      "name": "Rock_Acid_Trunk_Standard"
    },
    {
      "x": -31,
      "y": 6,
      "z": -8,
      "name": "Rock_Acid_Trunk_Light"
    },
    {
      "x": -31,
      "y": 7,
      "z": -8,
      "name": "Rock_Acid_Trunk_Medium"
    },
    {
      "x": -31,
      "y": 8,
      "z": -8,
      "name": "Rock_Acid_Trunk_Medium"
    },
    {
      "x": -31,
      "y": 9,
      "z": -8,
      "name": "Rock_Acid_Trunk_Standard"
    },
    {
      "x": -31,
      "y": 15,
      "z": -8,
      "name": "Rock_Acid_Trunk_Light"
    },
    {
      "x": -31,
      "y": 16,
      "z": -8,
      "name": "Rock_Acid_Trunk_Medium"
    },
    {
      "x": -31,
      "y": 17,
      "z": -8,
      "name": "Rock_Acid_Trunk_Medium"
    },
    {
      "x": -31,
      "y": 18,
      "z": -8,
      "name": "Rock_Acid_Trunk_Standard"
    },
    {
      "x": -31,
      "y": 5,
      "z": -7,
      "name": "Rock_Acid_Trunk_Light"
    },
    {
      "x": -31,
      "y": 6,
      "z": -7,
      "name": "Rock_Acid_Trunk_Light"
    },
    {
      "x": -31,
      "y": 7,
      "z": -7,
      "name": "Rock_Acid_Trunk_Medium"
    },
    {
      "x": -31,
      "y": 8,
      "z": -7,
      "name": "Rock_Acid_Trunk_Standard"
    },
    {
      "x": -31,
      "y": 9,
      "z": -7,
      "name": "Rock_Acid_Trunk_Standard"
    },
    {
      "x": -31,
      "y": 16,
      "z": -7,
      "name": "Rock_Acid_Trunk_Light"
    },
    {
      "x": -31,
      "y": 17,
      "z": -7,
      "name": "Rock_Acid_Trunk_Medium"
    },
    {
      "x": -31,
      "y": 18,
      "z": -7,
      "name": "Rock_Acid_Trunk_Standard"
    },
    {
      "x": -31,
      "y": 5,
      "z": -6,
      "name": "Rock_Acid_Trunk_Light"
    },
    {
      "x": -31,
      "y": 6,
      "z": -6,
      "name": "Rock_Acid_Trunk_Light"
    },
    {
      "x": -31,
      "y": 7,
      "z": -6,
      "name": "Rock_Acid_Trunk_Medium"
    },
    {
      "x": -31,
      "y": 17,
      "z": -6,
      "name": "Rock_Acid_Trunk_Medium"
    },
    {
      "x": -31,
      "y": 6,
      "z": -5,
      "name": "Rock_Acid_Trunk_Light"
    },
    {
      "x": -31,
      "y": 3,
      "z": -2,
      "name": "Rock_Acid_Trunk_Light"
    },
    {
      "x": -31,
      "y": 4,
      "z": -2,
      "name": "Rock_Acid_Trunk_Light"
    },
    {
      "x": -31,
      "y": 4,
      "z": -1,
      "name": "Rock_Acid_Trunk_Light"
    },
    {
      "x": -31,
      "y": 5,
      "z": -1,
      "name": "Rock_Acid_Trunk_Standard"
    },
    {
      "x": -31,
      "y": 5,
      "z": 0,
      "name": "Rock_Acid_Trunk_Light"
    },
    {
      "x": -31,
      "y": 5,
      "z": 16,
      "name": "Rock_Acid_Trunk_Light"
    },
    {
      "x": -31,
      "y": 6,
      "z": 16,
      "name": "Rock_Acid_Trunk_Light"
    },
    {
      "x": -31,
      "y": 7,
      "z": 16,
      "name": "Rock_Acid_Trunk_Light"
    },
    {
      "x": -31,
      "y": 5,
      "z": 17,
      "name": "Rock_Acid_Trunk_Light"
    },
    {
      "x": -31,
      "y": 6,
      "z": 17,
      "name": "Rock_Acid_Trunk_Standard"
    },
    {
      "x": -31,
      "y": 5,
      "z": 18,
      "name": "Rock_Acid_Trunk_Light"
    },
    {
      "x": -31,
      "y": 6,
      "z": 18,
      "name": "Rock_Acid_Trunk_Light"
    },
    {
      "x": -30,
      "y": 16,
      "z": -10,
      "name": "Rock_Acid_Trunk_Medium"
    },
    {
      "x": -30,
      "y": 6,
      "z": -9,
      "name": "Rock_Acid_Trunk_Light"
    },
    {
      "x": -30,
      "y": 7,
      "z": -9,
      "name": "Rock_Acid_Trunk_Light"
    },
    {
      "x": -30,
      "y": 15,
      "z": -9,
      "name": "Rock_Acid_Trunk_Light"
    },
    {
      "x": -30,
      "y": 16,
      "z": -9,
      "name": "Rock_Acid_Trunk_Medium"
    },
    {
      "x": -30,
      "y": 17,
      "z": -9,
      "name": "Rock_Acid_Trunk_Medium"
    },
    {
      "x": -30,
      "y": 18,
      "z": -9,
      "name": "Rock_Acid_Trunk_Standard"
    },
    {
      "x": -30,
      "y": 6,
      "z": -8,
      "name": "Rock_Acid_Trunk_Light"
    },
    {
      "x": -30,
      "y": 7,
      "z": -8,
      "name": "Rock_Acid_Trunk_Medium"
    },
    {
      "x": -30,
      "y": 8,
      "z": -8,
      "name": "Rock_Acid_Trunk_Standard"
    },
    {
      "x": -30,
      "y": 16,
      "z": -8,
      "name": "Rock_Acid_Trunk_Light"
    },
    {
      "x": -30,
      "y": 17,
      "z": -8,
      "name": "Rock_Acid_Trunk_Medium"
    },
    {
      "x": -30,
      "y": 18,
      "z": -8,
      "name": "Rock_Acid_Trunk_Standard"
    },
    {
      "x": -30,
      "y": 5,
      "z": -7,
      "name": "Rock_Acid_Trunk_Light"
    },
    {
      "x": -30,
      "y": 6,
      "z": -7,
      "name": "Rock_Acid_Trunk_Medium"
    },
    {
      "x": -30,
      "y": 7,
      "z": -7,
      "name": "Rock_Acid_Trunk_Medium"
    },
    {
      "x": -30,
      "y": 8,
      "z": -7,
      "name": "Rock_Acid_Trunk_Standard"
    },
    {
      "x": -30,
      "y": 16,
      "z": -7,
      "name": "Rock_Acid_Trunk_Light"
    },
    {
      "x": -30,
      "y": 17,
      "z": -7,
      "name": "Rock_Acid_Trunk_Medium"
    },
    {
      "x": -30,
      "y": 18,
      "z": -7,
      "name": "Rock_Acid_Trunk_Standard"
    },
    {
      "x": -30,
      "y": 5,
      "z": -6,
      "name": "Rock_Acid_Trunk_Light"
    },
    {
      "x": -30,
      "y": 6,
      "z": -6,
      "name": "Rock_Acid_Trunk_Medium"
    },
    {
      "x": -30,
      "y": 7,
      "z": -6,
      "name": "Rock_Acid_Trunk_Medium"
    },
    {
      "x": -30,
      "y": 8,
      "z": -6,
      "name": "Rock_Acid_Trunk_Standard"
    },
    {
      "x": -30,
      "y": 16,
      "z": -6,
      "name": "Rock_Acid_Trunk_Light"
    },
    {
      "x": -30,
      "y": 17,
      "z": -6,
      "name": "Rock_Acid_Trunk_Medium"
    },
    {
      "x": -30,
      "y": 18,
      "z": -6,
      "name": "Rock_Acid_Trunk_Standard"
    },
    {
      "x": -30,
      "y": 5,
      "z": -5,
      "name": "Rock_Acid_Trunk_Light"
    },
    {
      "x": -30,
      "y": 6,
      "z": -5,
      "name": "Rock_Acid_Trunk_Medium"
    },
    {
      "x": -30,
      "y": 7,
      "z": -5,
      "name": "Rock_Acid_Trunk_Medium"
    },
    {
      "x": -30,
      "y": 17,
      "z": -5,
      "name": "Rock_Acid_Trunk_Medium"
    },
    {
      "x": -30,
      "y": 6,
      "z": -4,
      "name": "Rock_Acid_Trunk_Medium"
    },
    {
      "x": -30,
      "y": 4,
      "z": -2,
      "name": "Rock_Acid_Trunk_Light"
    },
    {
      "x": -30,
      "y": 3,
      "z": -1,
      "name": "Rock_Acid_Trunk_Light"
    },
    {
      "x": -30,
      "y": 4,
      "z": -1,
      "name": "Rock_Acid_Trunk_Medium"
    },
    {
      "x": -30,
      "y": 5,
      "z": -1,
      "name": "Rock_Acid_Trunk_Standard"
    },
    {
      "x": -30,
      "y": 4,
      "z": 0,
      "name": "Rock_Acid_Trunk_Light"
    },
    {
      "x": -30,
      "y": 5,
      "z": 0,
      "name": "Rock_Acid_Trunk_Light"
    },
    {
      "x": -30,
      "y": 6,
      "z": 0,
      "name": "Rock_Acid_Trunk_Standard"
    },
    {
      "x": -30,
      "y": 6,
      "z": 15,
      "name": "Rock_Acid_Trunk_Light"
    },
    {
      "x": -30,
      "y": 5,
      "z": 16,
      "name": "Rock_Acid_Trunk_Light"
    },
    {
      "x": -30,
      "y": 6,
      "z": 16,
      "name": "Rock_Acid_Trunk_Light"
    },
    {
      "x": -30,
      "y": 7,
      "z": 16,
      "name": "Rock_Acid_Trunk_Standard"
    },
    {
      "x": -30,
      "y": 5,
      "z": 17,
      "name": "Rock_Acid_Trunk_Light"
    },
    {
      "x": -30,
      "y": 6,
      "z": 17,
      "name": "Rock_Acid_Trunk_Light"
    },
    {
      "x": -30,
      "y": 7,
      "z": 17,
      "name": "Rock_Acid_Trunk_Standard"
    },
    {
      "x": -30,
      "y": 5,
      "z": 18,
      "name": "Rock_Acid_Trunk_Light"
    },
    {
      "x": -30,
      "y": 6,
      "z": 18,
      "name": "Rock_Acid_Trunk_Light"
    },
    {
      "x": -29,
      "y": 6,
      "z": -8,
      "name": "Rock_Acid_Trunk_Light"
    },
    {
      "x": -29,
      "y": 7,
      "z": -8,
      "name": "Rock_Acid_Trunk_Medium"
    },
    {
      "x": -29,
      "y": 16,
      "z": -8,
      "name": "Rock_Acid_Trunk_Medium"
    },
    {
      "x": -29,
      "y": 17,
      "z": -8,
      "name": "Rock_Acid_Trunk_Medium"
    },
    {
      "x": -29,
      "y": 5,
      "z": -7,
      "name": "Rock_Acid_Trunk_Light"
    },
    {
      "x": -29,
      "y": 6,
      "z": -7,
      "name": "Rock_Acid_Trunk_Medium"
    },
    {
      "x": -29,
      "y": 7,
      "z": -7,
      "name": "Rock_Acid_Trunk_Standard"
    },
    {
      "x": -29,
      "y": 8,
      "z": -7,
      "name": "Rock_Acid_Trunk_Standard"
    },
    {
      "x": -29,
      "y": 16,
      "z": -7,
      "name": "Rock_Acid_Trunk_Light"
    },
    {
      "x": -29,
      "y": 17,
      "z": -7,
      "name": "Rock_Acid_Trunk_Medium"
    },
    {
      "x": -29,
      "y": 18,
      "z": -7,
      "name": "Rock_Acid_Trunk_Standard"
    },
    {
      "x": -29,
      "y": 4,
      "z": -6,
      "name": "Rock_Acid_Trunk_Light"
    },
    {
      "x": -29,
      "y": 5,
      "z": -6,
      "name": "Rock_Acid_Trunk_Medium"
    },
    {
      "x": -29,
      "y": 6,
      "z": -6,
      "name": "Rock_Acid_Trunk_Medium"
    },
    {
      "x": -29,
      "y": 7,
      "z": -6,
      "name": "Rock_Acid_Trunk_Standard"
    },
    {
      "x": -29,
      "y": 16,
      "z": -6,
      "name": "Rock_Acid_Trunk_Light"
    },
    {
      "x": -29,
      "y": 17,
      "z": -6,
      "name": "Rock_Acid_Trunk_Medium"
    },
    {
      "x": -29,
      "y": 18,
      "z": -6,
      "name": "Rock_Acid_Trunk_Standard"
    },
    {
      "x": -29,
      "y": 4,
      "z": -5,
      "name": "Rock_Acid_Trunk_Light"
    },
    {
      "x": -29,
      "y": 5,
      "z": -5,
      "name": "Rock_Acid_Trunk_Medium"
    },
    {
      "x": -29,
      "y": 6,
      "z": -5,
      "name": "Rock_Acid_Trunk_Medium"
    },
    {
      "x": -29,
      "y": 7,
      "z": -5,
      "name": "Rock_Acid_Trunk_Standard"
    },
    {
      "x": -29,
      "y": 16,
      "z": -5,
      "name": "Rock_Acid_Trunk_Light"
    },
    {
      "x": -29,
      "y": 17,
      "z": -5,
      "name": "Rock_Acid_Trunk_Medium"
    },
    {
      "x": -29,
      "y": 18,
      "z": -5,
      "name": "Rock_Acid_Trunk_Standard"
    },
    {
      "x": -29,
      "y": 5,
      "z": -4,
      "name": "Rock_Acid_Trunk_Medium"
    },
    {
      "x": -29,
      "y": 6,
      "z": -4,
      "name": "Rock_Acid_Trunk_Medium"
    },
    {
      "x": -29,
      "y": 7,
      "z": -4,
      "name": "Rock_Acid_Trunk_Standard"
    },
    {
      "x": -29,
      "y": 16,
      "z": -4,
      "name": "Rock_Acid_Trunk_Light"
    },
    {
      "x": -29,
      "y": 17,
      "z": -4,
      "name": "Rock_Acid_Trunk_Medium"
    },
    {
      "x": -29,
      "y": 15,
      "z": -3,
      "name": "Rock_Acid_Trunk_Light"
    },
    {
      "x": -29,
      "y": 16,
      "z": -3,
      "name": "Rock_Acid_Trunk_Light"
    },
    {
      "x": -29,
      "y": 4,
      "z": -1,
      "name": "Rock_Acid_Trunk_Light"
    },
    {
      "x": -29,
      "y": 5,
      "z": -1,
      "name": "Rock_Acid_Trunk_Light"
    },
    {
      "x": -29,
      "y": 6,
      "z": -1,
      "name": "Rock_Acid_Trunk_Standard"
    },
    {
      "x": -29,
      "y": 5,
      "z": 0,
      "name": "Rock_Acid_Trunk_Light"
    },
    {
      "x": -29,
      "y": 6,
      "z": 0,
      "name": "Rock_Acid_Trunk_Medium"
    },
    {
      "x": -29,
      "y": 7,
      "z": 0,
      "name": "Rock_Acid_Trunk_Standard"
    },
    {
      "x": -29,
      "y": 6,
      "z": 1,
      "name": "Rock_Acid_Trunk_Light"
    },
    {
      "x": -29,
      "y": 5,
      "z": 15,
      "name": "Rock_Acid_Trunk_Light"
    },
    {
      "x": -29,
      "y": 6,
      "z": 15,
      "name": "Rock_Acid_Trunk_Light"
    },
    {
      "x": -29,
      "y": 4,
      "z": 16,
      "name": "Rock_Acid_Trunk_Light"
    },
    {
      "x": -29,
      "y": 5,
      "z": 16,
      "name": "Rock_Acid_Trunk_Light"
    },
    {
      "x": -29,
      "y": 6,
      "z": 16,
      "name": "Rock_Acid_Trunk_Standard"
    },
    {
      "x": -29,
      "y": 4,
      "z": 17,
      "name": "Rock_Acid_Trunk_Light"
    },
    {
      "x": -29,
      "y": 5,
      "z": 17,
      "name": "Rock_Acid_Trunk_Light"
    },
    {
      "x": -29,
      "y": 6,
      "z": 17,
      "name": "Rock_Acid_Trunk_Light"
    },
    {
      "x": -29,
      "y": 7,
      "z": 17,
      "name": "Rock_Acid_Trunk_Standard"
    },
    {
      "x": -29,
      "y": 6,
      "z": 18,
      "name": "Rock_Acid_Trunk_Light"
    },
    {
      "x": -28,
      "y": 5,
      "z": -7,
      "name": "Rock_Acid_Trunk_Light"
    },
    {
      "x": -28,
      "y": 6,
      "z": -7,
      "name": "Rock_Acid_Trunk_Light"
    },
    {
      "x": -28,
      "y": 4,
      "z": -6,
      "name": "Rock_Acid_Trunk_Light"
    },
    {
      "x": -28,
      "y": 5,
      "z": -6,
      "name": "Rock_Acid_Trunk_Medium"
    },
    {
      "x": -28,
      "y": 6,
      "z": -6,
      "name": "Rock_Acid_Trunk_Medium"
    },
    {
      "x": -28,
      "y": 7,
      "z": -6,
      "name": "Rock_Acid_Trunk_Standard"
    },
    {
      "x": -28,
      "y": 16,
      "z": -6,
      "name": "Rock_Acid_Trunk_Light"
    },
    {
      "x": -28,
      "y": 17,
      "z": -6,
      "name": "Rock_Acid_Trunk_Medium"
    },
    {
      "x": -28,
      "y": 18,
      "z": -6,
      "name": "Rock_Acid_Trunk_Standard"
    },
    {
      "x": -28,
      "y": 4,
      "z": -5,
      "name": "Rock_Acid_Trunk_Light"
    },
    {
      "x": -28,
      "y": 5,
      "z": -5,
      "name": "Rock_Acid_Trunk_Medium"
    },
    {
      "x": -28,
      "y": 6,
      "z": -5,
      "name": "Rock_Acid_Trunk_Medium"
    },
    {
      "x": -28,
      "y": 7,
      "z": -5,
      "name": "Rock_Acid_Trunk_Standard"
    },
    {
      "x": -28,
      "y": 16,
      "z": -5,
      "name": "Rock_Acid_Trunk_Light"
    },
    {
      "x": -28,
      "y": 17,
      "z": -5,
      "name": "Rock_Acid_Trunk_Medium"
    },
    {
      "x": -28,
      "y": 18,
      "z": -5,
      "name": "Rock_Acid_Trunk_Standard"
    },
    {
      "x": -28,
      "y": 4,
      "z": -4,
      "name": "Rock_Acid_Trunk_Light"
    },
    {
      "x": -28,
      "y": 5,
      "z": -4,
      "name": "Rock_Acid_Trunk_Medium"
    },
    {
      "x": -28,
      "y": 6,
      "z": -4,
      "name": "Rock_Acid_Trunk_Standard"
    },
    {
      "x": -28,
      "y": 7,
      "z": -4,
      "name": "Rock_Acid_Trunk_Standard"
    },
    {
      "x": -28,
      "y": 15,
      "z": -4,
      "name": "Rock_Acid_Trunk_Light"
    },
    {
      "x": -28,
      "y": 16,
      "z": -4,
      "name": "Rock_Acid_Trunk_Medium"
    },
    {
      "x": -28,
      "y": 17,
      "z": -4,
      "name": "Rock_Acid_Trunk_Medium"
    },
    {
      "x": -28,
      "y": 18,
      "z": -4,
      "name": "Rock_Acid_Trunk_Standard"
    },
    {
      "x": -28,
      "y": 5,
      "z": -3,
      "name": "Rock_Acid_Trunk_Medium"
    },
    {
      "x": -28,
      "y": 15,
      "z": -3,
      "name": "Rock_Acid_Trunk_Light"
    },
    {
      "x": -28,
      "y": 16,
      "z": -3,
      "name": "Rock_Acid_Trunk_Medium"
    },
    {
      "x": -28,
      "y": 17,
      "z": -3,
      "name": "Rock_Acid_Trunk_Standard"
    },
    {
      "x": -28,
      "y": 14,
      "z": -2,
      "name": "Rock_Acid_Trunk_Light"
    },
    {
      "x": -28,
      "y": 15,
      "z": -2,
      "name": "Rock_Acid_Trunk_Light"
    },
    {
      "x": -28,
      "y": 16,
      "z": -2,
      "name": "Rock_Acid_Trunk_Medium"
    },
    {
      "x": -28,
      "y": 6,
      "z": -1,
      "name": "Rock_Acid_Trunk_Standard"
    },
    {
      "x": -28,
      "y": 7,
      "z": -1,
      "name": "Rock_Acid_Trunk_Standard"
    },
    {
      "x": -28,
      "y": 6,
      "z": 0,
      "name": "Rock_Acid_Trunk_Light"
    },
    {
      "x": -28,
      "y": 7,
      "z": 0,
      "name": "Rock_Acid_Trunk_Medium"
    },
    {
      "x": -28,
      "y": 8,
      "z": 0,
      "name": "Rock_Acid_Trunk_Standard"
    },
    {
      "x": -28,
      "y": 9,
      "z": 0,
      "name": "Rock_Acid_Trunk_Standard"
    },
    {
      "x": -28,
      "y": 7,
      "z": 1,
      "name": "Rock_Acid_Trunk_Light"
    },
    {
      "x": -28,
      "y": 8,
      "z": 1,
      "name": "Rock_Acid_Trunk_Light"
    },
    {
      "x": -28,
      "y": 9,
      "z": 1,
      "name": "Rock_Acid_Trunk_Light"
    },
    {
      "x": -28,
      "y": 3,
      "z": 15,
      "name": "Rock_Acid_Trunk_Light"
    },
    {
      "x": -28,
      "y": 4,
      "z": 15,
      "name": "Rock_Acid_Trunk_Light"
    },
    {
      "x": -28,
      "y": 5,
      "z": 15,
      "name": "Rock_Acid_Trunk_Medium"
    },
    {
      "x": -28,
      "y": 2,
      "z": 16,
      "name": "Rock_Acid_Trunk_Light"
    },
    {
      "x": -28,
      "y": 3,
      "z": 16,
      "name": "Rock_Acid_Trunk_Light"
    },
    {
      "x": -28,
      "y": 4,
      "z": 16,
      "name": "Rock_Acid_Trunk_Light"
    },
    {
      "x": -28,
      "y": 5,
      "z": 16,
      "name": "Rock_Acid_Trunk_Light"
    },
    {
      "x": -28,
      "y": 6,
      "z": 16,
      "name": "Rock_Acid_Trunk_Standard"
    },
    {
      "x": -28,
      "y": 3,
      "z": 17,
      "name": "Rock_Acid_Trunk_Light"
    },
    {
      "x": -28,
      "y": 4,
      "z": 17,
      "name": "Rock_Acid_Trunk_Light"
    },
    {
      "x": -28,
      "y": 5,
      "z": 17,
      "name": "Rock_Acid_Trunk_Light"
    },
    {
      "x": -28,
      "y": 6,
      "z": 17,
      "name": "Rock_Acid_Trunk_Light"
    },
    {
      "x": -27,
      "y": 5,
      "z": -6,
      "name": "Rock_Acid_Trunk_Light"
    },
    {
      "x": -27,
      "y": 6,
      "z": -6,
      "name": "Rock_Acid_Trunk_Medium"
    },
    {
      "x": -27,
      "y": 7,
      "z": -6,
      "name": "Rock_Acid_Trunk_Standard"
    },
    {
      "x": -27,
      "y": 4,
      "z": -5,
      "name": "Rock_Acid_Trunk_Light"
    },
    {
      "x": -27,
      "y": 5,
      "z": -5,
      "name": "Rock_Acid_Trunk_Medium"
    },
    {
      "x": -27,
      "y": 6,
      "z": -5,
      "name": "Rock_Acid_Trunk_Medium"
    },
    {
      "x": -27,
      "y": 7,
      "z": -5,
      "name": "Rock_Acid_Trunk_Standard"
    },
    {
      "x": -27,
      "y": 16,
      "z": -5,
      "name": "Rock_Acid_Trunk_Medium"
    },
    {
      "x": -27,
      "y": 17,
      "z": -5,
      "name": "Rock_Acid_Trunk_Medium"
    },
    {
      "x": -27,
      "y": 18,
      "z": -5,
      "name": "Rock_Acid_Trunk_Standard"
    },
    {
      "x": -27,
      "y": 4,
      "z": -4,
      "name": "Rock_Acid_Trunk_Light"
    },
    {
      "x": -27,
      "y": 5,
      "z": -4,
      "name": "Rock_Acid_Trunk_Medium"
    },
    {
      "x": -27,
      "y": 6,
      "z": -4,
      "name": "Rock_Acid_Trunk_Medium"
    },
    {
      "x": -27,
      "y": 7,
      "z": -4,
      "name": "Rock_Acid_Trunk_Standard"
    },
    {
      "x": -27,
      "y": 15,
      "z": -4,
      "name": "Rock_Acid_Trunk_Light"
    },
    {
      "x": -27,
      "y": 16,
      "z": -4,
      "name": "Rock_Acid_Trunk_Medium"
    },
    {
      "x": -27,
      "y": 17,
      "z": -4,
      "name": "Rock_Acid_Trunk_Standard"
    },
    {
      "x": -27,
      "y": 3,
      "z": -3,
      "name": "Rock_Acid_Trunk_Light"
    },
    {
      "x": -27,
      "y": 4,
      "z": -3,
      "name": "Rock_Acid_Trunk_Light"
    },
    {
      "x": -27,
      "y": 5,
      "z": -3,
      "name": "Rock_Acid_Trunk_Light"
    },
    {
      "x": -27,
      "y": 6,
      "z": -3,
      "name": "Rock_Acid_Trunk_Standard"
    },
    {
      "x": -27,
      "y": 15,
      "z": -3,
      "name": "Rock_Acid_Trunk_Light"
    },
    {
      "x": -27,
      "y": 16,
      "z": -3,
      "name": "Rock_Acid_Trunk_Medium"
    },
    {
      "x": -27,
      "y": 17,
      "z": -3,
      "name": "Rock_Acid_Trunk_Standard"
    },
    {
      "x": -27,
      "y": 4,
      "z": -2,
      "name": "Rock_Acid_Trunk_Light"
    },
    {
      "x": -27,
      "y": 14,
      "z": -2,
      "name": "Rock_Acid_Trunk_Light"
    },
    {
      "x": -27,
      "y": 15,
      "z": -2,
      "name": "Rock_Acid_Trunk_Medium"
    },
    {
      "x": -27,
      "y": 16,
      "z": -2,
      "name": "Rock_Acid_Trunk_Standard"
    },
    {
      "x": -27,
      "y": 7,
      "z": -1,
      "name": "Rock_Acid_Trunk_Standard"
    },
    {
      "x": -27,
      "y": 8,
      "z": -1,
      "name": "Rock_Acid_Trunk_Standard"
    },
    {
      "x": -27,
      "y": 9,
      "z": -1,
      "name": "Rock_Acid_Trunk_Standard"
    },
    {
      "x": -27,
      "y": 10,
      "z": -1,
      "name": "Rock_Acid_Trunk_Standard"
    },
    {
      "x": -27,
      "y": 13,
      "z": -1,
      "name": "Rock_Acid_Trunk_Light"
    },
    {
      "x": -27,
      "y": 14,
      "z": -1,
      "name": "Rock_Acid_Trunk_Medium"
    },
    {
      "x": -27,
      "y": 15,
      "z": -1,
      "name": "Rock_Acid_Trunk_Medium"
    },
    {
      "x": -27,
      "y": 16,
      "z": -1,
      "name": "Rock_Acid_Trunk_Standard"
    },
    {
      "x": -27,
      "y": 7,
      "z": 0,
      "name": "Rock_Acid_Trunk_Light"
    },
    {
      "x": -27,
      "y": 8,
      "z": 0,
      "name": "Rock_Acid_Trunk_Light"
    },
    {
      "x": -27,
      "y": 9,
      "z": 0,
      "name": "Rock_Acid_Trunk_Medium"
    },
    {
      "x": -27,
      "y": 10,
      "z": 0,
      "name": "Rock_Acid_Trunk_Standard"
    },
    {
      "x": -27,
      "y": 11,
      "z": 0,
      "name": "Rock_Acid_Trunk_Light"
    },
    {
      "x": -27,
      "y": 12,
      "z": 0,
      "name": "Rock_Acid_Trunk_Light"
    },
    {
      "x": -27,
      "y": 13,
      "z": 0,
      "name": "Rock_Acid_Trunk_Light"
    },
    {
      "x": -27,
      "y": 14,
      "z": 0,
      "name": "Rock_Acid_Trunk_Medium"
    },
    {
      "x": -27,
      "y": 9,
      "z": 1,
      "name": "Rock_Acid_Trunk_Light"
    },
    {
      "x": -27,
      "y": 10,
      "z": 1,
      "name": "Rock_Acid_Trunk_Light"
    },
    {
      "x": -27,
      "y": 11,
      "z": 1,
      "name": "Rock_Acid_Trunk_Light"
    },
    {
      "x": -27,
      "y": 44,
      "z": 8,
      "name": "Rock_Acid_Trunk_Orange"
    },
    {
      "x": -27,
      "y": 45,
      "z": 8,
      "name": "Rock_Acid_Trunk_Crimson"
    },
    {
      "x": -27,
      "y": 46,
      "z": 8,
      "name": "Rock_Acid_Trunk_Crimson"
    },
    {
      "x": -27,
      "y": 47,
      "z": 8,
      "name": "Rock_Acid_Trunk_Crimson"
    },
    {
      "x": -27,
      "y": 43,
      "z": 9,
      "name": "Rock_Acid_Trunk_Orange"
    },
    {
      "x": -27,
      "y": 44,
      "z": 9,
      "name": "Rock_Acid_Trunk_Orange"
    },
    {
      "x": -27,
      "y": 45,
      "z": 9,
      "name": "Rock_Acid_Trunk_Crimson"
    },
    {
      "x": -27,
      "y": 46,
      "z": 9,
      "name": "Rock_Acid_Trunk_Magenta"
    },
    {
      "x": -27,
      "y": 47,
      "z": 9,
      "name": "Rock_Acid_Trunk_Magenta"
    },
    {
      "x": -27,
      "y": 43,
      "z": 10,
      "name": "Rock_Acid_Trunk_Orange"
    },
    {
      "x": -27,
      "y": 44,
      "z": 10,
      "name": "Rock_Acid_Trunk_Orange"
    },
    {
      "x": -27,
      "y": 45,
      "z": 10,
      "name": "Rock_Acid_Trunk_Crimson"
    },
    {
      "x": -27,
      "y": 46,
      "z": 10,
      "name": "Rock_Acid_Trunk_Crimson"
    },
    {
      "x": -27,
      "y": 44,
      "z": 11,
      "name": "Rock_Acid_Trunk_Orange"
    },
    {
      "x": -27,
      "y": 45,
      "z": 11,
      "name": "Rock_Acid_Trunk_Crimson"
    },
    {
      "x": -27,
      "y": 3,
      "z": 14,
      "name": "Rock_Acid_Trunk_Medium"
    },
    {
      "x": -27,
      "y": 2,
      "z": 15,
      "name": "Rock_Acid_Trunk_Light"
    },
    {
      "x": -27,
      "y": 3,
      "z": 15,
      "name": "Rock_Acid_Trunk_Medium"
    },
    {
      "x": -27,
      "y": 4,
      "z": 15,
      "name": "Rock_Acid_Trunk_Medium"
    },
    {
      "x": -27,
      "y": 5,
      "z": 15,
      "name": "Rock_Acid_Trunk_Medium"
    },
    {
      "x": -27,
      "y": 6,
      "z": 15,
      "name": "Rock_Acid_Trunk_Standard"
    },
    {
      "x": -27,
      "y": 2,
      "z": 16,
      "name": "Rock_Acid_Trunk_Light"
    },
    {
      "x": -27,
      "y": 3,
      "z": 16,
      "name": "Rock_Acid_Trunk_Medium"
    },
    {
      "x": -27,
      "y": 4,
      "z": 16,
      "name": "Rock_Acid_Trunk_Light"
    },
    {
      "x": -27,
      "y": 5,
      "z": 16,
      "name": "Rock_Acid_Trunk_Light"
    },
    {
      "x": -27,
      "y": 6,
      "z": 16,
      "name": "Rock_Acid_Trunk_Standard"
    },
    {
      "x": -27,
      "y": 2,
      "z": 17,
      "name": "Rock_Acid_Trunk_Light"
    },
    {
      "x": -27,
      "y": 3,
      "z": 17,
      "name": "Rock_Acid_Trunk_Light"
    },
    {
      "x": -27,
      "y": 4,
      "z": 17,
      "name": "Rock_Acid_Trunk_Light"
    },
    {
      "x": -26,
      "y": 4,
      "z": -5,
      "name": "Rock_Acid_Trunk_Light"
    },
    {
      "x": -26,
      "y": 5,
      "z": -5,
      "name": "Rock_Acid_Trunk_Light"
    },
    {
      "x": -26,
      "y": 6,
      "z": -5,
      "name": "Rock_Acid_Trunk_Standard"
    },
    {
      "x": -26,
      "y": 7,
      "z": -5,
      "name": "Rock_Acid_Trunk_Standard"
    },
    {
      "x": -26,
      "y": 3,
      "z": -4,
      "name": "Rock_Acid_Trunk_Light"
    },
    {
      "x": -26,
      "y": 4,
      "z": -4,
      "name": "Rock_Acid_Trunk_Medium"
    },
    {
      "x": -26,
      "y": 5,
      "z": -4,
      "name": "Rock_Acid_Trunk_Medium"
    },
    {
      "x": -26,
      "y": 6,
      "z": -4,
      "name": "Rock_Acid_Trunk_Standard"
    },
    {
      "x": -26,
      "y": 3,
      "z": -3,
      "name": "Rock_Acid_Trunk_Light"
    },
    {
      "x": -26,
      "y": 4,
      "z": -3,
      "name": "Rock_Acid_Trunk_Medium"
    },
    {
      "x": -26,
      "y": 5,
      "z": -3,
      "name": "Rock_Acid_Trunk_Medium"
    },
    {
      "x": -26,
      "y": 6,
      "z": -3,
      "name": "Rock_Acid_Trunk_Standard"
    },
    {
      "x": -26,
      "y": 14,
      "z": -3,
      "name": "Rock_Acid_Trunk_Light"
    },
    {
      "x": -26,
      "y": 15,
      "z": -3,
      "name": "Rock_Acid_Trunk_Medium"
    },
    {
      "x": -26,
      "y": 16,
      "z": -3,
      "name": "Rock_Acid_Trunk_Medium"
    },
    {
      "x": -26,
      "y": 32,
      "z": -3,
      "name": "Rock_Acid_Trunk_Bright"
    },
    {
      "x": -26,
      "y": 33,
      "z": -3,
      "name": "Rock_Acid_Trunk_Bright"
    },
    {
      "x": -26,
      "y": 34,
      "z": -3,
      "name": "Rock_Acid_Trunk_Orange"
    },
    {
      "x": -26,
      "y": 35,
      "z": -3,
      "name": "Rock_Acid_Trunk_Orange"
    },
    {
      "x": -26,
      "y": 36,
      "z": -3,
      "name": "Rock_Acid_Trunk_Magenta"
    },
    {
      "x": -26,
      "y": 3,
      "z": -2,
      "name": "Rock_Acid_Trunk_Light"
    },
    {
      "x": -26,
      "y": 4,
      "z": -2,
      "name": "Rock_Acid_Trunk_Light"
    },
    {
      "x": -26,
      "y": 5,
      "z": -2,
      "name": "Rock_Acid_Trunk_Medium"
    },
    {
      "x": -26,
      "y": 13,
      "z": -2,
      "name": "Rock_Acid_Trunk_Light"
    },
    {
      "x": -26,
      "y": 14,
      "z": -2,
      "name": "Rock_Acid_Trunk_Medium"
    },
    {
      "x": -26,
      "y": 15,
      "z": -2,
      "name": "Rock_Acid_Trunk_Medium"
    },
    {
      "x": -26,
      "y": 16,
      "z": -2,
      "name": "Rock_Acid_Trunk_Medium"
    },
    {
      "x": -26,
      "y": 31,
      "z": -2,
      "name": "Rock_Acid_Trunk_Bright"
    },
    {
      "x": -26,
      "y": 32,
      "z": -2,
      "name": "Rock_Acid_Trunk_Bright"
    },
    {
      "x": -26,
      "y": 33,
      "z": -2,
      "name": "Rock_Acid_Trunk_Bright"
    },
    {
      "x": -26,
      "y": 34,
      "z": -2,
      "name": "Rock_Acid_Trunk_Orange"
    },
    {
      "x": -26,
      "y": 35,
      "z": -2,
      "name": "Rock_Acid_Trunk_Orange"
    },
    {
      "x": -26,
      "y": 36,
      "z": -2,
      "name": "Rock_Acid_Trunk_Crimson"
    },
    {
      "x": -26,
      "y": 37,
      "z": -2,
      "name": "Rock_Acid_Trunk_Magenta"
    },
    {
      "x": -26,
      "y": 38,
      "z": -2,
      "name": "Rock_Acid_Trunk_Magenta"
    },
    {
      "x": -26,
      "y": 39,
      "z": -2,
      "name": "Rock_Acid_Trunk_Magenta"
    },
    {
      "x": -26,
      "y": 10,
      "z": -1,
      "name": "Rock_Acid_Trunk_Light"
    },
    {
      "x": -26,
      "y": 11,
      "z": -1,
      "name": "Rock_Acid_Trunk_Light"
    },
    {
      "x": -26,
      "y": 12,
      "z": -1,
      "name": "Rock_Acid_Trunk_Light"
    },
    {
      "x": -26,
      "y": 13,
      "z": -1,
      "name": "Rock_Acid_Trunk_Medium"
    },
    {
      "x": -26,
      "y": 14,
      "z": -1,
      "name": "Rock_Acid_Trunk_Medium"
    },
    {
      "x": -26,
      "y": 15,
      "z": -1,
      "name": "Rock_Acid_Trunk_Medium"
    },
    {
      "x": -26,
      "y": 30,
      "z": -1,
      "name": "Rock_Acid_Trunk_Bright"
    },
    {
      "x": -26,
      "y": 31,
      "z": -1,
      "name": "Rock_Acid_Trunk_Bright"
    },
    {
      "x": -26,
      "y": 32,
      "z": -1,
      "name": "Rock_Acid_Trunk_Bright"
    },
    {
      "x": -26,
      "y": 33,
      "z": -1,
      "name": "Rock_Acid_Trunk_Orange"
    },
    {
      "x": -26,
      "y": 34,
      "z": -1,
      "name": "Rock_Acid_Trunk_Orange"
    },
    {
      "x": -26,
      "y": 35,
      "z": -1,
      "name": "Rock_Acid_Trunk_Orange"
    },
    {
      "x": -26,
      "y": 36,
      "z": -1,
      "name": "Rock_Acid_Trunk_Crimson"
    },
    {
      "x": -26,
      "y": 37,
      "z": -1,
      "name": "Rock_Acid_Trunk_Crimson"
    },
    {
      "x": -26,
      "y": 38,
      "z": -1,
      "name": "Rock_Acid_Trunk_Crimson"
    },
    {
      "x": -26,
      "y": 39,
      "z": -1,
      "name": "Rock_Acid_Trunk_Magenta"
    },
    {
      "x": -26,
      "y": 9,
      "z": 0,
      "name": "Rock_Acid_Trunk_Light"
    },
    {
      "x": -26,
      "y": 10,
      "z": 0,
      "name": "Rock_Acid_Trunk_Light"
    },
    {
      "x": -26,
      "y": 11,
      "z": 0,
      "name": "Rock_Acid_Trunk_Medium"
    },
    {
      "x": -26,
      "y": 12,
      "z": 0,
      "name": "Rock_Acid_Trunk_Medium"
    },
    {
      "x": -26,
      "y": 13,
      "z": 0,
      "name": "Rock_Acid_Trunk_Medium"
    },
    {
      "x": -26,
      "y": 14,
      "z": 0,
      "name": "Rock_Acid_Trunk_Medium"
    },
    {
      "x": -26,
      "y": 15,
      "z": 0,
      "name": "Rock_Acid_Trunk_Standard"
    },
    {
      "x": -26,
      "y": 30,
      "z": 0,
      "name": "Rock_Acid_Trunk_Orange"
    },
    {
      "x": -26,
      "y": 31,
      "z": 0,
      "name": "Rock_Acid_Trunk_Orange"
    },
    {
      "x": -26,
      "y": 32,
      "z": 0,
      "name": "Rock_Acid_Trunk_Orange"
    },
    {
      "x": -26,
      "y": 33,
      "z": 0,
      "name": "Rock_Acid_Trunk_Orange"
    },
    {
      "x": -26,
      "y": 34,
      "z": 0,
      "name": "Rock_Acid_Trunk_Orange"
    },
    {
      "x": -26,
      "y": 35,
      "z": 0,
      "name": "Rock_Acid_Trunk_Orange"
    },
    {
      "x": -26,
      "y": 36,
      "z": 0,
      "name": "Rock_Acid_Trunk_Magenta"
    },
    {
      "x": -26,
      "y": 11,
      "z": 1,
      "name": "Rock_Acid_Trunk_Light"
    },
    {
      "x": -26,
      "y": 12,
      "z": 1,
      "name": "Rock_Acid_Trunk_Light"
    },
    {
      "x": -26,
      "y": 13,
      "z": 1,
      "name": "Rock_Acid_Trunk_Medium"
    },
    {
      "x": -26,
      "y": 31,
      "z": 1,
      "name": "Rock_Acid_Trunk_Bright"
    },
    {
      "x": -26,
      "y": 32,
      "z": 1,
      "name": "Rock_Acid_Trunk_Bright"
    },
    {
      "x": -26,
      "y": 33,
      "z": 1,
      "name": "Rock_Acid_Trunk_Bright"
    },
    {
      "x": -26,
      "y": 34,
      "z": 1,
      "name": "Rock_Acid_Trunk_Orange"
    },
    {
      "x": -26,
      "y": 35,
      "z": 1,
      "name": "Rock_Acid_Trunk_Orange"
    },
    {
      "x": -26,
      "y": 36,
      "z": 1,
      "name": "Rock_Acid_Trunk_Magenta"
    },
    {
      "x": -26,
      "y": 44,
      "z": 5,
      "name": "Rock_Acid_Trunk_Orange"
    },
    {
      "x": -26,
      "y": 45,
      "z": 5,
      "name": "Rock_Acid_Trunk_Magenta"
    },
    {
      "x": -26,
      "y": 42,
      "z": 6,
      "name": "Rock_Acid_Trunk_Bright"
    },
    {
      "x": -26,
      "y": 43,
      "z": 6,
      "name": "Rock_Acid_Trunk_Orange"
    },
    {
      "x": -26,
      "y": 44,
      "z": 6,
      "name": "Rock_Acid_Trunk_Orange"
    },
    {
      "x": -26,
      "y": 45,
      "z": 6,
      "name": "Rock_Acid_Trunk_Crimson"
    },
    {
      "x": -26,
      "y": 41,
      "z": 7,
      "name": "Rock_Acid_Trunk_Bright"
    },
    {
      "x": -26,
      "y": 42,
      "z": 7,
      "name": "Rock_Acid_Trunk_Orange"
    },
    {
      "x": -26,
      "y": 43,
      "z": 7,
      "name": "Rock_Acid_Trunk_Orange"
    },
    {
      "x": -26,
      "y": 44,
      "z": 7,
      "name": "Rock_Acid_Trunk_Crimson"
    },
    {
      "x": -26,
      "y": 45,
      "z": 7,
      "name": "Rock_Acid_Trunk_Crimson"
    },
    {
      "x": -26,
      "y": 40,
      "z": 8,
      "name": "Rock_Acid_Trunk_Bright"
    },
    {
      "x": -26,
      "y": 41,
      "z": 8,
      "name": "Rock_Acid_Trunk_Orange"
    },
    {
      "x": -26,
      "y": 42,
      "z": 8,
      "name": "Rock_Acid_Trunk_Orange"
    },
    {
      "x": -26,
      "y": 43,
      "z": 8,
      "name": "Rock_Acid_Trunk_Orange"
    },
    {
      "x": -26,
      "y": 44,
      "z": 8,
      "name": "Rock_Acid_Trunk_Crimson"
    },
    {
      "x": -26,
      "y": 45,
      "z": 8,
      "name": "Empty"
    },
    {
      "x": -26,
      "y": 48,
      "z": 8,
      "name": "Rock_Acid_Trunk_Magenta"
    },
    {
      "x": -26,
      "y": 49,
      "z": 8,
      "name": "Rock_Acid_Trunk_Magenta"
    },
    {
      "x": -26,
      "y": 40,
      "z": 9,
      "name": "Rock_Acid_Trunk_Orange"
    },
    {
      "x": -26,
      "y": 41,
      "z": 9,
      "name": "Rock_Acid_Trunk_Orange"
    },
    {
      "x": -26,
      "y": 42,
      "z": 9,
      "name": "Rock_Acid_Trunk_Orange"
    },
    {
      "x": -26,
      "y": 43,
      "z": 9,
      "name": "Rock_Acid_Trunk_Medium"
    },
    {
      "x": -26,
      "y": 44,
      "z": 9,
      "name": "Rock_Acid_Trunk_Crimson"
    },
    {
      "x": -26,
      "y": 45,
      "z": 9,
      "name": "Empty"
    },
    {
      "x": -26,
      "y": 48,
      "z": 9,
      "name": "Rock_Acid_Trunk_Magenta"
    },
    {
      "x": -26,
      "y": 41,
      "z": 10,
      "name": "Rock_Acid_Trunk_Bright"
    },
    {
      "x": -26,
      "y": 42,
      "z": 10,
      "name": "Rock_Acid_Trunk_Orange"
    },
    {
      "x": -26,
      "y": 43,
      "z": 10,
      "name": "Rock_Acid_Trunk_Medium"
    },
    {
      "x": -26,
      "y": 44,
      "z": 10,
      "name": "Rock_Acid_Trunk_Crimson"
    },
    {
      "x": -26,
      "y": 45,
      "z": 10,
      "name": "Empty"
    },
    {
      "x": -26,
      "y": 42,
      "z": 11,
      "name": "Rock_Acid_Trunk_Bright"
    },
    {
      "x": -26,
      "y": 43,
      "z": 11,
      "name": "Rock_Acid_Trunk_Orange"
    },
    {
      "x": -26,
      "y": 44,
      "z": 11,
      "name": "Rock_Acid_Trunk_Crimson"
    },
    {
      "x": -26,
      "y": 45,
      "z": 11,
      "name": "Empty"
    },
    {
      "x": -26,
      "y": 43,
      "z": 12,
      "name": "Rock_Acid_Trunk_Bright"
    },
    {
      "x": -26,
      "y": 44,
      "z": 12,
      "name": "Rock_Acid_Trunk_Orange"
    },
    {
      "x": -26,
      "y": 45,
      "z": 12,
      "name": "Rock_Acid_Trunk_Crimson"
    },
    {
      "x": -26,
      "y": 44,
      "z": 13,
      "name": "Rock_Acid_Trunk_Orange"
    },
    {
      "x": -26,
      "y": 45,
      "z": 13,
      "name": "Rock_Acid_Trunk_Crimson"
    },
    {
      "x": -26,
      "y": 2,
      "z": 14,
      "name": "Rock_Acid_Trunk_Light"
    },
    {
      "x": -26,
      "y": 3,
      "z": 14,
      "name": "Rock_Acid_Trunk_Medium"
    },
    {
      "x": -26,
      "y": 4,
      "z": 14,
      "name": "Rock_Acid_Trunk_Medium"
    },
    {
      "x": -26,
      "y": 5,
      "z": 14,
      "name": "Rock_Acid_Trunk_Standard"
    },
    {
      "x": -26,
      "y": 2,
      "z": 15,
      "name": "Rock_Acid_Trunk_Light"
    },
    {
      "x": -26,
      "y": 3,
      "z": 15,
      "name": "Rock_Acid_Trunk_Medium"
    },
    {
      "x": -26,
      "y": 4,
      "z": 15,
      "name": "Rock_Acid_Trunk_Medium"
    },
    {
      "x": -26,
      "y": 5,
      "z": 15,
      "name": "Rock_Acid_Trunk_Medium"
    },
    {
      "x": -26,
      "y": 6,
      "z": 15,
      "name": "Rock_Acid_Trunk_Standard"
    },
    {
      "x": -26,
      "y": 2,
      "z": 16,
      "name": "Rock_Acid_Trunk_Light"
    },
    {
      "x": -26,
      "y": 3,
      "z": 16,
      "name": "Rock_Acid_Trunk_Medium"
    },
    {
      "x": -26,
      "y": 4,
      "z": 16,
      "name": "Rock_Acid_Trunk_Medium"
    },
    {
      "x": -26,
      "y": 5,
      "z": 16,
      "name": "Rock_Acid_Trunk_Standard"
    },
    {
      "x": -26,
      "y": 3,
      "z": 17,
      "name": "Rock_Acid_Trunk_Light"
    },
    {
      "x": -25,
      "y": 5,
      "z": -5,
      "name": "Rock_Acid_Trunk_Medium"
    },
    {
      "x": -25,
      "y": 3,
      "z": -4,
      "name": "Rock_Acid_Trunk_Light"
    },
    {
      "x": -25,
      "y": 4,
      "z": -4,
      "name": "Rock_Acid_Trunk_Light"
    },
    {
      "x": -25,
      "y": 5,
      "z": -4,
      "name": "Rock_Acid_Trunk_Medium"
    },
    {
      "x": -25,
      "y": 6,
      "z": -4,
      "name": "Rock_Acid_Trunk_Standard"
    },
    {
      "x": -25,
      "y": 31,
      "z": -4,
      "name": "Rock_Acid_Trunk_Bright"
    },
    {
      "x": -25,
      "y": 32,
      "z": -4,
      "name": "Rock_Acid_Trunk_Bright"
    },
    {
      "x": -25,
      "y": 33,
      "z": -4,
      "name": "Rock_Acid_Trunk_Orange"
    },
    {
      "x": -25,
      "y": 34,
      "z": -4,
      "name": "Rock_Acid_Trunk_Orange"
    },
    {
      "x": -25,
      "y": 35,
      "z": -4,
      "name": "Rock_Acid_Trunk_Crimson"
    },
    {
      "x": -25,
      "y": 36,
      "z": -4,
      "name": "Rock_Acid_Trunk_Crimson"
    },
    {
      "x": -25,
      "y": 3,
      "z": -3,
      "name": "Rock_Acid_Trunk_Light"
    },
    {
      "x": -25,
      "y": 4,
      "z": -3,
      "name": "Rock_Acid_Trunk_Medium"
    },
    {
      "x": -25,
      "y": 5,
      "z": -3,
      "name": "Rock_Acid_Trunk_Medium"
    },
    {
      "x": -25,
      "y": 6,
      "z": -3,
      "name": "Rock_Acid_Trunk_Standard"
    },
    {
      "x": -25,
      "y": 29,
      "z": -3,
      "name": "Rock_Acid_Trunk_Bright"
    },
    {
      "x": -25,
      "y": 30,
      "z": -3,
      "name": "Rock_Acid_Trunk_Bright"
    },
    {
      "x": -25,
      "y": 31,
      "z": -3,
      "name": "Rock_Acid_Trunk_Bright"
    },
    {
      "x": -25,
      "y": 32,
      "z": -3,
      "name": "Rock_Acid_Trunk_Medium"
    },
    {
      "x": -25,
      "y": 33,
      "z": -3,
      "name": "Rock_Acid_Trunk_Medium"
    },
    {
      "x": -25,
      "y": 34,
      "z": -3,
      "name": "Rock_Acid_Trunk_Medium"
    },
    {
      "x": -25,
      "y": 35,
      "z": -3,
      "name": "Rock_Acid_Trunk_Crimson"
    },
    {
      "x": -25,
      "y": 36,
      "z": -3,
      "name": "Rock_Acid_Trunk_Crimson"
    },
    {
      "x": -25,
      "y": 3,
      "z": -2,
      "name": "Rock_Acid_Trunk_Light"
    },
    {
      "x": -25,
      "y": 4,
      "z": -2,
      "name": "Rock_Acid_Trunk_Medium"
    },
    {
      "x": -25,
      "y": 5,
      "z": -2,
      "name": "Rock_Acid_Trunk_Standard"
    },
    {
      "x": -25,
      "y": 6,
      "z": -2,
      "name": "Rock_Acid_Trunk_Standard"
    },
    {
      "x": -25,
      "y": 29,
      "z": -2,
      "name": "Rock_Acid_Trunk_Bright"
    },
    {
      "x": -25,
      "y": 30,
      "z": -2,
      "name": "Rock_Acid_Trunk_Bright"
    },
    {
      "x": -25,
      "y": 31,
      "z": -2,
      "name": "Rock_Acid_Trunk_Medium"
    },
    {
      "x": -25,
      "y": 32,
      "z": -2,
      "name": "Rock_Acid_Trunk_Medium"
    },
    {
      "x": -25,
      "y": 33,
      "z": -2,
      "name": "Rock_Acid_Trunk_Medium"
    },
    {
      "x": -25,
      "y": 34,
      "z": -2,
      "name": "Rock_Acid_Trunk_Medium"
    },
    {
      "x": -25,
      "y": 35,
      "z": -2,
      "name": "Rock_Acid_Trunk_Crimson"
    },
    {
      "x": -25,
      "y": 36,
      "z": -2,
      "name": "Empty"
    },
    {
      "x": -25,
      "y": 40,
      "z": -2,
      "name": "Rock_Acid_Trunk_Magenta"
    },
    {
      "x": -25,
      "y": 4,
      "z": -1,
      "name": "Rock_Acid_Trunk_Light"
    },
    {
      "x": -25,
      "y": 28,
      "z": -1,
      "name": "Rock_Acid_Trunk_Medium"
    },
    {
      "x": -25,
      "y": 29,
      "z": -1,
      "name": "Rock_Acid_Trunk_Orange"
    },
    {
      "x": -25,
      "y": 30,
      "z": -1,
      "name": "Rock_Acid_Trunk_Medium"
    },
    {
      "x": -25,
      "y": 31,
      "z": -1,
      "name": "Rock_Acid_Trunk_Medium"
    },
    {
      "x": -25,
      "y": 32,
      "z": -1,
      "name": "Rock_Acid_Trunk_Medium"
    },
    {
      "x": -25,
      "y": 33,
      "z": -1,
      "name": "Rock_Acid_Trunk_Medium"
    },
    {
      "x": -25,
      "y": 34,
      "z": -1,
      "name": "Rock_Acid_Trunk_Medium"
    },
    {
      "x": -25,
      "y": 35,
      "z": -1,
      "name": "Rock_Acid_Trunk_Crimson"
    },
    {
      "x": -25,
      "y": 36,
      "z": -1,
      "name": "Empty"
    },
    {
      "x": -25,
      "y": 10,
      "z": 0,
      "name": "Rock_Acid_Trunk_Light"
    },
    {
      "x": -25,
      "y": 11,
      "z": 0,
      "name": "Rock_Acid_Trunk_Light"
    },
    {
      "x": -25,
      "y": 12,
      "z": 0,
      "name": "Rock_Acid_Trunk_Light"
    },
    {
      "x": -25,
      "y": 13,
      "z": 0,
      "name": "Rock_Acid_Trunk_Light"
    },
    {
      "x": -25,
      "y": 14,
      "z": 0,
      "name": "Rock_Acid_Trunk_Medium"
    },
    {
      "x": -25,
      "y": 28,
      "z": 0,
      "name": "Rock_Acid_Trunk_Medium"
    },
    {
      "x": -25,
      "y": 29,
      "z": 0,
      "name": "Rock_Acid_Trunk_Medium"
    },
    {
      "x": -25,
      "y": 30,
      "z": 0,
      "name": "Rock_Acid_Trunk_Medium"
    },
    {
      "x": -25,
      "y": 31,
      "z": 0,
      "name": "Rock_Acid_Trunk_Medium"
    },
    {
      "x": -25,
      "y": 32,
      "z": 0,
      "name": "Rock_Acid_Trunk_Medium"
    },
    {
      "x": -25,
      "y": 33,
      "z": 0,
      "name": "Rock_Acid_Trunk_Medium"
    },
    {
      "x": -25,
      "y": 34,
      "z": 0,
      "name": "Rock_Acid_Trunk_Medium"
    },
    {
      "x": -25,
      "y": 35,
      "z": 0,
      "name": "Rock_Acid_Trunk_Crimson"
    },
    {
      "x": -25,
      "y": 36,
      "z": 0,
      "name": "Empty"
    },
    {
      "x": -25,
      "y": 12,
      "z": 1,
      "name": "Rock_Acid_Trunk_Light"
    },
    {
      "x": -25,
      "y": 28,
      "z": 1,
      "name": "Rock_Acid_Trunk_Medium"
    },
    {
      "x": -25,
      "y": 29,
      "z": 1,
      "name": "Rock_Acid_Trunk_Orange"
    },
    {
      "x": -25,
      "y": 30,
      "z": 1,
      "name": "Rock_Acid_Trunk_Orange"
    },
    {
      "x": -25,
      "y": 31,
      "z": 1,
      "name": "Rock_Acid_Trunk_Medium"
    },
    {
      "x": -25,
      "y": 32,
      "z": 1,
      "name": "Rock_Acid_Trunk_Medium"
    },
    {
      "x": -25,
      "y": 33,
      "z": 1,
      "name": "Rock_Acid_Trunk_Medium"
    },
    {
      "x": -25,
      "y": 34,
      "z": 1,
      "name": "Rock_Acid_Trunk_Medium"
    },
    {
      "x": -25,
      "y": 35,
      "z": 1,
      "name": "Rock_Acid_Trunk_Crimson"
    },
    {
      "x": -25,
      "y": 36,
      "z": 1,
      "name": "Rock_Acid_Trunk_Crimson"
    },
    {
      "x": -25,
      "y": 29,
      "z": 2,
      "name": "Rock_Acid_Trunk_Orange"
    },
    {
      "x": -25,
      "y": 30,
      "z": 2,
      "name": "Rock_Acid_Trunk_Bright"
    },
    {
      "x": -25,
      "y": 31,
      "z": 2,
      "name": "Rock_Acid_Trunk_Bright"
    },
    {
      "x": -25,
      "y": 32,
      "z": 2,
      "name": "Rock_Acid_Trunk_Bright"
    },
    {
      "x": -25,
      "y": 33,
      "z": 2,
      "name": "Rock_Acid_Trunk_Bright"
    },
    {
      "x": -25,
      "y": 34,
      "z": 2,
      "name": "Rock_Acid_Trunk_Orange"
    },
    {
      "x": -25,
      "y": 35,
      "z": 2,
      "name": "Rock_Acid_Trunk_Orange"
    },
    {
      "x": -25,
      "y": 36,
      "z": 2,
      "name": "Rock_Acid_Trunk_Crimson"
    },
    {
      "x": -25,
      "y": 31,
      "z": 3,
      "name": "Rock_Acid_Trunk_Bright"
    },
    {
      "x": -25,
      "y": 32,
      "z": 3,
      "name": "Rock_Acid_Trunk_Bright"
    },
    {
      "x": -25,
      "y": 33,
      "z": 3,
      "name": "Rock_Acid_Trunk_Bright"
    },
    {
      "x": -25,
      "y": 34,
      "z": 3,
      "name": "Rock_Acid_Trunk_Bright"
    },
    {
      "x": -25,
      "y": 35,
      "z": 3,
      "name": "Rock_Acid_Trunk_Orange"
    },
    {
      "x": -25,
      "y": 36,
      "z": 3,
      "name": "Rock_Acid_Trunk_Crimson"
    },
    {
      "x": -25,
      "y": 42,
      "z": 3,
      "name": "Rock_Acid_Trunk_Bright"
    },
    {
      "x": -25,
      "y": 43,
      "z": 3,
      "name": "Rock_Acid_Trunk_Orange"
    },
    {
      "x": -25,
      "y": 44,
      "z": 3,
      "name": "Rock_Acid_Trunk_Orange"
    },
    {
      "x": -25,
      "y": 45,
      "z": 3,
      "name": "Rock_Acid_Trunk_Magenta"
    },
    {
      "x": -25,
      "y": 34,
      "z": 4,
      "name": "Rock_Acid_Trunk_Bright"
    },
    {
      "x": -25,
      "y": 35,
      "z": 4,
      "name": "Rock_Acid_Trunk_Bright"
    },
    {
      "x": -25,
      "y": 36,
      "z": 4,
      "name": "Rock_Acid_Trunk_Bright"
    },
    {
      "x": -25,
      "y": 40,
      "z": 4,
      "name": "Rock_Acid_Trunk_Bright"
    },
    {
      "x": -25,
      "y": 41,
      "z": 4,
      "name": "Rock_Acid_Trunk_Bright"
    },
    {
      "x": -25,
      "y": 42,
      "z": 4,
      "name": "Rock_Acid_Trunk_Bright"
    },
    {
      "x": -25,
      "y": 43,
      "z": 4,
      "name": "Rock_Acid_Trunk_Orange"
    },
    {
      "x": -25,
      "y": 44,
      "z": 4,
      "name": "Rock_Acid_Trunk_Crimson"
    },
    {
      "x": -25,
      "y": 45,
      "z": 4,
      "name": "Rock_Acid_Trunk_Magenta"
    },
    {
      "x": -25,
      "y": 46,
      "z": 4,
      "name": "Rock_Acid_Trunk_Magenta"
    },
    {
      "x": -25,
      "y": 38,
      "z": 5,
      "name": "Rock_Acid_Trunk_Bright"
    },
    {
      "x": -25,
      "y": 39,
      "z": 5,
      "name": "Rock_Acid_Trunk_Bright"
    },
    {
      "x": -25,
      "y": 40,
      "z": 5,
      "name": "Rock_Acid_Trunk_Bright"
    },
    {
      "x": -25,
      "y": 41,
      "z": 5,
      "name": "Rock_Acid_Trunk_Bright"
    },
    {
      "x": -25,
      "y": 42,
      "z": 5,
      "name": "Rock_Acid_Trunk_Bright"
    },
    {
      "x": -25,
      "y": 43,
      "z": 5,
      "name": "Rock_Acid_Trunk_Orange"
    },
    {
      "x": -25,
      "y": 44,
      "z": 5,
      "name": "Rock_Acid_Trunk_Crimson"
    },
    {
      "x": -25,
      "y": 45,
      "z": 5,
      "name": "Empty"
    },
    {
      "x": -25,
      "y": 47,
      "z": 5,
      "name": "Rock_Acid_Trunk_Magenta"
    },
    {
      "x": -25,
      "y": 37,
      "z": 6,
      "name": "Rock_Acid_Trunk_Bright"
    },
    {
      "x": -25,
      "y": 38,
      "z": 6,
      "name": "Rock_Acid_Trunk_Bright"
    },
    {
      "x": -25,
      "y": 39,
      "z": 6,
      "name": "Rock_Acid_Trunk_Bright"
    },
    {
      "x": -25,
      "y": 40,
      "z": 6,
      "name": "Rock_Acid_Trunk_Bright"
    },
    {
      "x": -25,
      "y": 41,
      "z": 6,
      "name": "Rock_Acid_Trunk_Bright"
    },
    {
      "x": -25,
      "y": 42,
      "z": 6,
      "name": "Rock_Acid_Trunk_Medium"
    },
    {
      "x": -25,
      "y": 43,
      "z": 6,
      "name": "Rock_Acid_Trunk_Medium"
    },
    {
      "x": -25,
      "y": 44,
      "z": 6,
      "name": "Rock_Acid_Trunk_Crimson"
    },
    {
      "x": -25,
      "y": 45,
      "z": 6,
      "name": "Empty"
    },
    {
      "x": -25,
      "y": 37,
      "z": 7,
      "name": "Rock_Acid_Trunk_Bright"
    },
    {
      "x": -25,
      "y": 38,
      "z": 7,
      "name": "Rock_Acid_Trunk_Bright"
    },
    {
      "x": -25,
      "y": 39,
      "z": 7,
      "name": "Rock_Acid_Trunk_Bright"
    },
    {
      "x": -25,
      "y": 40,
      "z": 7,
      "name": "Rock_Acid_Trunk_Bright"
    },
    {
      "x": -25,
      "y": 41,
      "z": 7,
      "name": "Rock_Acid_Trunk_Medium"
    },
    {
      "x": -25,
      "y": 42,
      "z": 7,
      "name": "Rock_Acid_Trunk_Medium"
    },
    {
      "x": -25,
      "y": 43,
      "z": 7,
      "name": "Rock_Acid_Trunk_Medium"
    },
    {
      "x": -25,
      "y": 44,
      "z": 7,
      "name": "Rock_Acid_Trunk_Crimson"
    },
    {
      "x": -25,
      "y": 45,
      "z": 7,
      "name": "Empty"
    },
    {
      "x": -25,
      "y": 36,
      "z": 8,
      "name": "Rock_Acid_Trunk_Orange"
    },
    {
      "x": -25,
      "y": 37,
      "z": 8,
      "name": "Rock_Acid_Trunk_Bright"
    },
    {
      "x": -25,
      "y": 38,
      "z": 8,
      "name": "Rock_Acid_Trunk_Bright"
    },
    {
      "x": -25,
      "y": 39,
      "z": 8,
      "name": "Rock_Acid_Trunk_Bright"
    },
    {
      "x": -25,
      "y": 40,
      "z": 8,
      "name": "Rock_Acid_Trunk_Medium"
    },
    {
      "x": -25,
      "y": 41,
      "z": 8,
      "name": "Rock_Acid_Trunk_Medium"
    },
    {
      "x": -25,
      "y": 42,
      "z": 8,
      "name": "Rock_Acid_Trunk_Medium"
    },
    {
      "x": -25,
      "y": 43,
      "z": 8,
      "name": "Rock_Acid_Trunk_Medium"
    },
    {
      "x": -25,
      "y": 44,
      "z": 8,
      "name": "Rock_Acid_Trunk_Crimson"
    },
    {
      "x": -25,
      "y": 45,
      "z": 8,
      "name": "Empty"
    },
    {
      "x": -25,
      "y": 36,
      "z": 9,
      "name": "Rock_Acid_Trunk_Orange"
    },
    {
      "x": -25,
      "y": 37,
      "z": 9,
      "name": "Rock_Acid_Trunk_Orange"
    },
    {
      "x": -25,
      "y": 38,
      "z": 9,
      "name": "Rock_Acid_Trunk_Orange"
    },
    {
      "x": -25,
      "y": 39,
      "z": 9,
      "name": "Rock_Acid_Trunk_Orange"
    },
    {
      "x": -25,
      "y": 40,
      "z": 9,
      "name": "Rock_Acid_Trunk_Medium"
    },
    {
      "x": -25,
      "y": 41,
      "z": 9,
      "name": "Rock_Acid_Trunk_Medium"
    },
    {
      "x": -25,
      "y": 42,
      "z": 9,
      "name": "Rock_Acid_Trunk_Medium"
    },
    {
      "x": -25,
      "y": 43,
      "z": 9,
      "name": "Rock_Acid_Trunk_Medium"
    },
    {
      "x": -25,
      "y": 44,
      "z": 9,
      "name": "Rock_Acid_Trunk_Crimson"
    },
    {
      "x": -25,
      "y": 45,
      "z": 9,
      "name": "Empty"
    },
    {
      "x": -25,
      "y": 37,
      "z": 10,
      "name": "Rock_Acid_Trunk_Bright"
    },
    {
      "x": -25,
      "y": 38,
      "z": 10,
      "name": "Rock_Acid_Trunk_Bright"
    },
    {
      "x": -25,
      "y": 39,
      "z": 10,
      "name": "Rock_Acid_Trunk_Bright"
    },
    {
      "x": -25,
      "y": 40,
      "z": 10,
      "name": "Rock_Acid_Trunk_Bright"
    },
    {
      "x": -25,
      "y": 41,
      "z": 10,
      "name": "Rock_Acid_Trunk_Medium"
    },
    {
      "x": -25,
      "y": 42,
      "z": 10,
      "name": "Rock_Acid_Trunk_Medium"
    },
    {
      "x": -25,
      "y": 43,
      "z": 10,
      "name": "Rock_Acid_Trunk_Medium"
    },
    {
      "x": -25,
      "y": 44,
      "z": 10,
      "name": "Rock_Acid_Trunk_Crimson"
    },
    {
      "x": -25,
      "y": 45,
      "z": 10,
      "name": "Empty"
    },
    {
      "x": -25,
      "y": 38,
      "z": 11,
      "name": "Rock_Acid_Trunk_Bright"
    },
    {
      "x": -25,
      "y": 39,
      "z": 11,
      "name": "Rock_Acid_Trunk_Bright"
    },
    {
      "x": -25,
      "y": 40,
      "z": 11,
      "name": "Rock_Acid_Trunk_Bright"
    },
    {
      "x": -25,
      "y": 41,
      "z": 11,
      "name": "Rock_Acid_Trunk_Bright"
    },
    {
      "x": -25,
      "y": 42,
      "z": 11,
      "name": "Rock_Acid_Trunk_Medium"
    },
    {
      "x": -25,
      "y": 43,
      "z": 11,
      "name": "Rock_Acid_Trunk_Medium"
    },
    {
      "x": -25,
      "y": 44,
      "z": 11,
      "name": "Rock_Acid_Trunk_Crimson"
    },
    {
      "x": -25,
      "y": 45,
      "z": 11,
      "name": "Empty"
    },
    {
      "x": -25,
      "y": 39,
      "z": 12,
      "name": "Rock_Acid_Trunk_Bright"
    },
    {
      "x": -25,
      "y": 40,
      "z": 12,
      "name": "Rock_Acid_Trunk_Bright"
    },
    {
      "x": -25,
      "y": 41,
      "z": 12,
      "name": "Rock_Acid_Trunk_Bright"
    },
    {
      "x": -25,
      "y": 42,
      "z": 12,
      "name": "Rock_Acid_Trunk_Bright"
    },
    {
      "x": -25,
      "y": 43,
      "z": 12,
      "name": "Rock_Acid_Trunk_Medium"
    },
    {
      "x": -25,
      "y": 44,
      "z": 12,
      "name": "Rock_Acid_Trunk_Crimson"
    },
    {
      "x": -25,
      "y": 45,
      "z": 12,
      "name": "Empty"
    },
    {
      "x": -25,
      "y": 4,
      "z": 13,
      "name": "Rock_Acid_Trunk_Medium"
    },
    {
      "x": -25,
      "y": 41,
      "z": 13,
      "name": "Rock_Acid_Trunk_Bright"
    },
    {
      "x": -25,
      "y": 42,
      "z": 13,
      "name": "Rock_Acid_Trunk_Bright"
    },
    {
      "x": -25,
      "y": 43,
      "z": 13,
      "name": "Rock_Acid_Trunk_Orange"
    },
    {
      "x": -25,
      "y": 44,
      "z": 13,
      "name": "Rock_Acid_Trunk_Crimson"
    },
    {
      "x": -25,
      "y": 45,
      "z": 13,
      "name": "Rock_Acid_Trunk_Crimson"
    },
    {
      "x": -25,
      "y": 2,
      "z": 14,
      "name": "Rock_Acid_Trunk_Light"
    },
    {
      "x": -25,
      "y": 3,
      "z": 14,
      "name": "Rock_Acid_Trunk_Medium"
    },
    {
      "x": -25,
      "y": 4,
      "z": 14,
      "name": "Rock_Acid_Trunk_Medium"
    },
    {
      "x": -25,
      "y": 5,
      "z": 14,
      "name": "Rock_Acid_Trunk_Standard"
    },
    {
      "x": -25,
      "y": 45,
      "z": 14,
      "name": "Rock_Acid_Trunk_Crimson"
    },
    {
      "x": -25,
      "y": 46,
      "z": 14,
      "name": "Rock_Acid_Trunk_Magenta"
    },
    {
      "x": -25,
      "y": 1,
      "z": 15,
      "name": "Rock_Acid_Trunk_Light"
    },
    {
      "x": -25,
      "y": 2,
      "z": 15,
      "name": "Rock_Acid_Trunk_Medium"
    },
    {
      "x": -25,
      "y": 3,
      "z": 15,
      "name": "Rock_Acid_Trunk_Medium"
    },
    {
      "x": -25,
      "y": 4,
      "z": 15,
      "name": "Rock_Acid_Trunk_Standard"
    },
    {
      "x": -25,
      "y": 5,
      "z": 15,
      "name": "Rock_Acid_Trunk_Standard"
    },
    {
      "x": -25,
      "y": 2,
      "z": 16,
      "name": "Rock_Acid_Trunk_Light"
    },
    {
      "x": -25,
      "y": 3,
      "z": 16,
      "name": "Rock_Acid_Trunk_Light"
    },
    {
      "x": -25,
      "y": 4,
      "z": 27,
      "name": "Rock_Acid_Trunk_Light"
    },
    {
      "x": -25,
      "y": 4,
      "z": 28,
      "name": "Rock_Acid_Trunk_Light"
    },
    {
      "x": -25,
      "y": 5,
      "z": 28,
      "name": "Rock_Acid_Trunk_Light"
    },
    {
      "x": -25,
      "y": 12,
      "z": 45,
      "name": "Rock_Acid_Trunk_Light"
    },
    {
      "x": -25,
      "y": 13,
      "z": 45,
      "name": "Rock_Acid_Trunk_Light"
    },
    {
      "x": -24,
      "y": 33,
      "z": -6,
      "name": "Rock_Acid_Trunk_Orange"
    },
    {
      "x": -24,
      "y": 34,
      "z": -6,
      "name": "Rock_Acid_Trunk_Orange"
    },
    {
      "x": -24,
      "y": 35,
      "z": -6,
      "name": "Rock_Acid_Trunk_Orange"
    },
    {
      "x": -24,
      "y": 36,
      "z": -6,
      "name": "Rock_Acid_Trunk_Magenta"
    },
    {
      "x": -24,
      "y": 30,
      "z": -5,
      "name": "Rock_Acid_Trunk_Orange"
    },
    {
      "x": -24,
      "y": 31,
      "z": -5,
      "name": "Rock_Acid_Trunk_Orange"
    },
    {
      "x": -24,
      "y": 32,
      "z": -5,
      "name": "Rock_Acid_Trunk_Orange"
    },
    {
      "x": -24,
      "y": 33,
      "z": -5,
      "name": "Rock_Acid_Trunk_Orange"
    },
    {
      "x": -24,
      "y": 34,
      "z": -5,
      "name": "Rock_Acid_Trunk_Orange"
    },
    {
      "x": -24,
      "y": 35,
      "z": -5,
      "name": "Rock_Acid_Trunk_Crimson"
    },
    {
      "x": -24,
      "y": 36,
      "z": -5,
      "name": "Rock_Acid_Trunk_Crimson"
    },
    {
      "x": -24,
      "y": 4,
      "z": -4,
      "name": "Rock_Acid_Trunk_Light"
    },
    {
      "x": -24,
      "y": 5,
      "z": -4,
      "name": "Rock_Acid_Trunk_Medium"
    },
    {
      "x": -24,
      "y": 29,
      "z": -4,
      "name": "Rock_Acid_Trunk_Orange"
    },
    {
      "x": -24,
      "y": 30,
      "z": -4,
      "name": "Rock_Acid_Trunk_Bright"
    },
    {
      "x": -24,
      "y": 31,
      "z": -4,
      "name": "Rock_Acid_Trunk_Medium"
    },
    {
      "x": -24,
      "y": 32,
      "z": -4,
      "name": "Rock_Acid_Trunk_Medium"
    },
    {
      "x": -24,
      "y": 33,
      "z": -4,
      "name": "Rock_Acid_Trunk_Medium"
    },
    {
      "x": -24,
      "y": 34,
      "z": -4,
      "name": "Rock_Acid_Trunk_Medium"
    },
    {
      "x": -24,
      "y": 35,
      "z": -4,
      "name": "Rock_Acid_Trunk_Crimson"
    },
    {
      "x": -24,
      "y": 36,
      "z": -4,
      "name": "Empty"
    },
    {
      "x": -24,
      "y": 3,
      "z": -3,
      "name": "Rock_Acid_Trunk_Light"
    },
    {
      "x": -24,
      "y": 4,
      "z": -3,
      "name": "Rock_Acid_Trunk_Medium"
    },
    {
      "x": -24,
      "y": 5,
      "z": -3,
      "name": "Rock_Acid_Trunk_Medium"
    },
    {
      "x": -24,
      "y": 6,
      "z": -3,
      "name": "Rock_Acid_Trunk_Standard"
    },
    {
      "x": -24,
      "y": 28,
      "z": -3,
      "name": "Rock_Acid_Trunk_Medium"
    },
    {
      "x": -24,
      "y": 29,
      "z": -3,
      "name": "Rock_Acid_Trunk_Medium"
    },
    {
      "x": -24,
      "y": 30,
      "z": -3,
      "name": "Rock_Acid_Trunk_Medium"
    },
    {
      "x": -24,
      "y": 31,
      "z": -3,
      "name": "Rock_Acid_Trunk_Medium"
    },
    {
      "x": -24,
      "y": 32,
      "z": -3,
      "name": "Rock_Acid_Trunk_Medium"
    },
    {
      "x": -24,
      "y": 33,
      "z": -3,
      "name": "Rock_Acid_Trunk_Medium"
    },
    {
      "x": -24,
      "y": 34,
      "z": -3,
      "name": "Rock_Acid_Trunk_Medium"
    },
    {
      "x": -24,
      "y": 35,
      "z": -3,
      "name": "Rock_Acid_Trunk_Crimson"
    },
    {
      "x": -24,
      "y": 36,
      "z": -3,
      "name": "Empty"
    },
    {
      "x": -24,
      "y": 2,
      "z": -2,
      "name": "Rock_Acid_Trunk_Light"
    },
    {
      "x": -24,
      "y": 3,
      "z": -2,
      "name": "Rock_Acid_Trunk_Medium"
    },
    {
      "x": -24,
      "y": 4,
      "z": -2,
      "name": "Rock_Acid_Trunk_Medium"
    },
    {
      "x": -24,
      "y": 5,
      "z": -2,
      "name": "Rock_Acid_Trunk_Medium"
    },
    {
      "x": -24,
      "y": 6,
      "z": -2,
      "name": "Rock_Acid_Trunk_Standard"
    },
    {
      "x": -24,
      "y": 27,
      "z": -2,
      "name": "Rock_Acid_Trunk_Medium"
    },
    {
      "x": -24,
      "y": 28,
      "z": -2,
      "name": "Rock_Acid_Trunk_Medium"
    },
    {
      "x": -24,
      "y": 29,
      "z": -2,
      "name": "Rock_Acid_Trunk_Medium"
    },
    {
      "x": -24,
      "y": 30,
      "z": -2,
      "name": "Rock_Acid_Trunk_Medium"
    },
    {
      "x": -24,
      "y": 31,
      "z": -2,
      "name": "Rock_Acid_Trunk_Medium"
    },
    {
      "x": -24,
      "y": 32,
      "z": -2,
      "name": "Rock_Acid_Trunk_Medium"
    },
    {
      "x": -24,
      "y": 33,
      "z": -2,
      "name": "Rock_Acid_Trunk_Medium"
    },
    {
      "x": -24,
      "y": 34,
      "z": -2,
      "name": "Rock_Acid_Trunk_Medium"
    },
    {
      "x": -24,
      "y": 35,
      "z": -2,
      "name": "Rock_Acid_Trunk_Crimson"
    },
    {
      "x": -24,
      "y": 36,
      "z": -2,
      "name": "Empty"
    },
    {
      "x": -24,
      "y": 2,
      "z": -1,
      "name": "Rock_Acid_Trunk_Light"
    },
    {
      "x": -24,
      "y": 3,
      "z": -1,
      "name": "Rock_Acid_Trunk_Light"
    },
    {
      "x": -24,
      "y": 4,
      "z": -1,
      "name": "Rock_Acid_Trunk_Medium"
    },
    {
      "x": -24,
      "y": 5,
      "z": -1,
      "name": "Rock_Acid_Trunk_Standard"
    },
    {
      "x": -24,
      "y": 26,
      "z": -1,
      "name": "Rock_Acid_Trunk_Medium"
    },
    {
      "x": -24,
      "y": 27,
      "z": -1,
      "name": "Rock_Acid_Trunk_Medium"
    },
    {
      "x": -24,
      "y": 28,
      "z": -1,
      "name": "Rock_Acid_Trunk_Medium"
    },
    {
      "x": -24,
      "y": 29,
      "z": -1,
      "name": "Rock_Acid_Trunk_Medium"
    },
    {
      "x": -24,
      "y": 30,
      "z": -1,
      "name": "Rock_Acid_Trunk_Medium"
    },
    {
      "x": -24,
      "y": 31,
      "z": -1,
      "name": "Rock_Acid_Trunk_Medium"
    },
    {
      "x": -24,
      "y": 32,
      "z": -1,
      "name": "Rock_Acid_Trunk_Medium"
    },
    {
      "x": -24,
      "y": 33,
      "z": -1,
      "name": "Rock_Acid_Trunk_Medium"
    },
    {
      "x": -24,
      "y": 34,
      "z": -1,
      "name": "Rock_Acid_Trunk_Medium"
    },
    {
      "x": -24,
      "y": 35,
      "z": -1,
      "name": "Rock_Acid_Trunk_Crimson"
    },
    {
      "x": -24,
      "y": 36,
      "z": -1,
      "name": "Empty"
    },
    {
      "x": -24,
      "y": 4,
      "z": 0,
      "name": "Rock_Acid_Trunk_Medium"
    },
    {
      "x": -24,
      "y": 5,
      "z": 0,
      "name": "Rock_Acid_Trunk_Medium"
    },
    {
      "x": -24,
      "y": 26,
      "z": 0,
      "name": "Rock_Acid_Trunk_Medium"
    },
    {
      "x": -24,
      "y": 27,
      "z": 0,
      "name": "Rock_Acid_Trunk_Medium"
    },
    {
      "x": -24,
      "y": 28,
      "z": 0,
      "name": "Rock_Acid_Trunk_Medium"
    },
    {
      "x": -24,
      "y": 29,
      "z": 0,
      "name": "Rock_Acid_Trunk_Medium"
    },
    {
      "x": -24,
      "y": 30,
      "z": 0,
      "name": "Rock_Acid_Trunk_Medium"
    },
    {
      "x": -24,
      "y": 31,
      "z": 0,
      "name": "Rock_Acid_Trunk_Medium"
    },
    {
      "x": -24,
      "y": 32,
      "z": 0,
      "name": "Rock_Acid_Trunk_Medium"
    },
    {
      "x": -24,
      "y": 33,
      "z": 0,
      "name": "Rock_Acid_Trunk_Medium"
    },
    {
      "x": -24,
      "y": 34,
      "z": 0,
      "name": "Rock_Acid_Trunk_Medium"
    },
    {
      "x": -24,
      "y": 35,
      "z": 0,
      "name": "Rock_Acid_Trunk_Crimson"
    },
    {
      "x": -24,
      "y": 36,
      "z": 0,
      "name": "Empty"
    },
    {
      "x": -24,
      "y": 26,
      "z": 1,
      "name": "Rock_Acid_Trunk_Medium"
    },
    {
      "x": -24,
      "y": 27,
      "z": 1,
      "name": "Rock_Acid_Trunk_Medium"
    },
    {
      "x": -24,
      "y": 28,
      "z": 1,
      "name": "Rock_Acid_Trunk_Medium"
    },
    {
      "x": -24,
      "y": 29,
      "z": 1,
      "name": "Rock_Acid_Trunk_Medium"
    },
    {
      "x": -24,
      "y": 30,
      "z": 1,
      "name": "Rock_Acid_Trunk_Medium"
    },
    {
      "x": -24,
      "y": 31,
      "z": 1,
      "name": "Rock_Acid_Trunk_Medium"
    },
    {
      "x": -24,
      "y": 32,
      "z": 1,
      "name": "Rock_Acid_Trunk_Medium"
    },
    {
      "x": -24,
      "y": 33,
      "z": 1,
      "name": "Rock_Acid_Trunk_Medium"
    },
    {
      "x": -24,
      "y": 34,
      "z": 1,
      "name": "Rock_Acid_Trunk_Medium"
    },
    {
      "x": -24,
      "y": 35,
      "z": 1,
      "name": "Rock_Acid_Trunk_Crimson"
    },
    {
      "x": -24,
      "y": 36,
      "z": 1,
      "name": "Empty"
    },
    {
      "x": -24,
      "y": 39,
      "z": 1,
      "name": "Rock_Acid_Trunk_Bright"
    },
    {
      "x": -24,
      "y": 40,
      "z": 1,
      "name": "Rock_Acid_Trunk_Bright"
    },
    {
      "x": -24,
      "y": 41,
      "z": 1,
      "name": "Rock_Acid_Trunk_Bright"
    },
    {
      "x": -24,
      "y": 42,
      "z": 1,
      "name": "Rock_Acid_Trunk_Bright"
    },
    {
      "x": -24,
      "y": 43,
      "z": 1,
      "name": "Rock_Acid_Trunk_Orange"
    },
    {
      "x": -24,
      "y": 44,
      "z": 1,
      "name": "Rock_Acid_Trunk_Orange"
    },
    {
      "x": -24,
      "y": 45,
      "z": 1,
      "name": "Rock_Acid_Trunk_Crimson"
    },
    {
      "x": -24,
      "y": 27,
      "z": 2,
      "name": "Rock_Acid_Trunk_Medium"
    },
    {
      "x": -24,
      "y": 28,
      "z": 2,
      "name": "Rock_Acid_Trunk_Medium"
    },
    {
      "x": -24,
      "y": 29,
      "z": 2,
      "name": "Rock_Acid_Trunk_Medium"
    },
    {
      "x": -24,
      "y": 30,
      "z": 2,
      "name": "Rock_Acid_Trunk_Medium"
    },
    {
      "x": -24,
      "y": 31,
      "z": 2,
      "name": "Rock_Acid_Trunk_Medium"
    },
    {
      "x": -24,
      "y": 32,
      "z": 2,
      "name": "Rock_Acid_Trunk_Medium"
    },
    {
      "x": -24,
      "y": 33,
      "z": 2,
      "name": "Rock_Acid_Trunk_Medium"
    },
    {
      "x": -24,
      "y": 34,
      "z": 2,
      "name": "Rock_Acid_Trunk_Medium"
    },
    {
      "x": -24,
      "y": 35,
      "z": 2,
      "name": "Rock_Acid_Trunk_Medium"
    },
    {
      "x": -24,
      "y": 36,
      "z": 2,
      "name": "Rock_Acid_Trunk_Orange"
    },
    {
      "x": -24,
      "y": 37,
      "z": 2,
      "name": "Rock_Acid_Trunk_Orange"
    },
    {
      "x": -24,
      "y": 38,
      "z": 2,
      "name": "Rock_Acid_Trunk_Bright"
    },
    {
      "x": -24,
      "y": 39,
      "z": 2,
      "name": "Rock_Acid_Trunk_Bright"
    },
    {
      "x": -24,
      "y": 40,
      "z": 2,
      "name": "Rock_Acid_Trunk_Bright"
    },
    {
      "x": -24,
      "y": 41,
      "z": 2,
      "name": "Rock_Acid_Trunk_Bright"
    },
    {
      "x": -24,
      "y": 42,
      "z": 2,
      "name": "Rock_Acid_Trunk_Bright"
    },
    {
      "x": -24,
      "y": 43,
      "z": 2,
      "name": "Rock_Acid_Trunk_Orange"
    },
    {
      "x": -24,
      "y": 44,
      "z": 2,
      "name": "Rock_Acid_Trunk_Crimson"
    },
    {
      "x": -24,
      "y": 45,
      "z": 2,
      "name": "Rock_Acid_Trunk_Crimson"
    },
    {
      "x": -24,
      "y": 27,
      "z": 3,
      "name": "Rock_Acid_Trunk_Medium"
    },
    {
      "x": -24,
      "y": 28,
      "z": 3,
      "name": "Rock_Acid_Trunk_Bright"
    },
    {
      "x": -24,
      "y": 29,
      "z": 3,
      "name": "Rock_Acid_Trunk_Bright"
    },
    {
      "x": -24,
      "y": 30,
      "z": 3,
      "name": "Rock_Acid_Trunk_Bright"
    },
    {
      "x": -24,
      "y": 31,
      "z": 3,
      "name": "Rock_Acid_Trunk_Medium"
    },
    {
      "x": -24,
      "y": 32,
      "z": 3,
      "name": "Rock_Acid_Trunk_Medium"
    },
    {
      "x": -24,
      "y": 33,
      "z": 3,
      "name": "Rock_Acid_Trunk_Medium"
    },
    {
      "x": -24,
      "y": 34,
      "z": 3,
      "name": "Rock_Acid_Trunk_Medium"
    },
    {
      "x": -24,
      "y": 35,
      "z": 3,
      "name": "Rock_Acid_Trunk_Medium"
    },
    {
      "x": -24,
      "y": 36,
      "z": 3,
      "name": "Rock_Acid_Trunk_Medium"
    },
    {
      "x": -24,
      "y": 37,
      "z": 3,
      "name": "Rock_Acid_Trunk_Bright"
    },
    {
      "x": -24,
      "y": 38,
      "z": 3,
      "name": "Rock_Acid_Trunk_Bright"
    },
    {
      "x": -24,
      "y": 39,
      "z": 3,
      "name": "Rock_Acid_Trunk_Bright"
    },
    {
      "x": -24,
      "y": 40,
      "z": 3,
      "name": "Rock_Acid_Trunk_Bright"
    },
    {
      "x": -24,
      "y": 41,
      "z": 3,
      "name": "Rock_Acid_Trunk_Bright"
    },
    {
      "x": -24,
      "y": 42,
      "z": 3,
      "name": "Rock_Acid_Trunk_Medium"
    },
    {
      "x": -24,
      "y": 43,
      "z": 3,
      "name": "Rock_Acid_Trunk_Medium"
    },
    {
      "x": -24,
      "y": 44,
      "z": 3,
      "name": "Rock_Acid_Trunk_Crimson"
    },
    {
      "x": -24,
      "y": 45,
      "z": 3,
      "name": "Empty"
    },
    {
      "x": -24,
      "y": 29,
      "z": 4,
      "name": "Rock_Acid_Trunk_Bright"
    },
    {
      "x": -24,
      "y": 30,
      "z": 4,
      "name": "Rock_Acid_Trunk_Bright"
    },
    {
      "x": -24,
      "y": 31,
      "z": 4,
      "name": "Rock_Acid_Trunk_Bright"
    },
    {
      "x": -24,
      "y": 32,
      "z": 4,
      "name": "Rock_Acid_Trunk_Bright"
    },
    {
      "x": -24,
      "y": 33,
      "z": 4,
      "name": "Rock_Acid_Trunk_Bright"
    },
    {
      "x": -24,
      "y": 34,
      "z": 4,
      "name": "Rock_Acid_Trunk_Medium"
    },
    {
      "x": -24,
      "y": 35,
      "z": 4,
      "name": "Rock_Acid_Trunk_Medium"
    },
    {
      "x": -24,
      "y": 36,
      "z": 4,
      "name": "Rock_Acid_Trunk_Medium"
    },
    {
      "x": -24,
      "y": 37,
      "z": 4,
      "name": "Rock_Acid_Trunk_Bright"
    },
    {
      "x": -24,
      "y": 38,
      "z": 4,
      "name": "Rock_Acid_Trunk_Bright"
    },
    {
      "x": -24,
      "y": 39,
      "z": 4,
      "name": "Rock_Acid_Trunk_Bright"
    },
    {
      "x": -24,
      "y": 40,
      "z": 4,
      "name": "Rock_Acid_Trunk_Medium"
    },
    {
      "x": -24,
      "y": 41,
      "z": 4,
      "name": "Rock_Acid_Trunk_Medium"
    },
    {
      "x": -24,
      "y": 42,
      "z": 4,
      "name": "Rock_Acid_Trunk_Medium"
    },
    {
      "x": -24,
      "y": 43,
      "z": 4,
      "name": "Rock_Acid_Trunk_Medium"
    },
    {
      "x": -24,
      "y": 44,
      "z": 4,
      "name": "Rock_Acid_Trunk_Crimson"
    },
    {
      "x": -24,
      "y": 45,
      "z": 4,
      "name": "Empty"
    },
    {
      "x": -24,
      "y": 34,
      "z": 5,
      "name": "Rock_Acid_Trunk_Orange"
    },
    {
      "x": -24,
      "y": 35,
      "z": 5,
      "name": "Rock_Acid_Trunk_Bright"
    },
    {
      "x": -24,
      "y": 36,
      "z": 5,
      "name": "Rock_Acid_Trunk_Bright"
    },
    {
      "x": -24,
      "y": 37,
      "z": 5,
      "name": "Rock_Acid_Trunk_Bright"
    },
    {
      "x": -24,
      "y": 38,
      "z": 5,
      "name": "Rock_Acid_Trunk_Medium"
    },
    {
      "x": -24,
      "y": 39,
      "z": 5,
      "name": "Rock_Acid_Trunk_Medium"
    },
    {
      "x": -24,
      "y": 40,
      "z": 5,
      "name": "Rock_Acid_Trunk_Medium"
    },
    {
      "x": -24,
      "y": 41,
      "z": 5,
      "name": "Rock_Acid_Trunk_Medium"
    },
    {
      "x": -24,
      "y": 42,
      "z": 5,
      "name": "Rock_Acid_Trunk_Medium"
    },
    {
      "x": -24,
      "y": 43,
      "z": 5,
      "name": "Rock_Acid_Trunk_Medium"
    },
    {
      "x": -24,
      "y": 44,
      "z": 5,
      "name": "Rock_Acid_Trunk_Crimson"
    },
    {
      "x": -24,
      "y": 45,
      "z": 5,
      "name": "Empty"
    },
    {
      "x": -24,
      "y": 33,
      "z": 6,
      "name": "Rock_Acid_Trunk_Orange"
    },
    {
      "x": -24,
      "y": 34,
      "z": 6,
      "name": "Rock_Acid_Trunk_Orange"
    },
    {
      "x": -24,
      "y": 35,
      "z": 6,
      "name": "Rock_Acid_Trunk_Bright"
    },
    {
      "x": -24,
      "y": 36,
      "z": 6,
      "name": "Rock_Acid_Trunk_Bright"
    },
    {
      "x": -24,
      "y": 37,
      "z": 6,
      "name": "Rock_Acid_Trunk_Medium"
    },
    {
      "x": -24,
      "y": 38,
      "z": 6,
      "name": "Rock_Acid_Trunk_Medium"
    },
    {
      "x": -24,
      "y": 39,
      "z": 6,
      "name": "Rock_Acid_Trunk_Medium"
    },
    {
      "x": -24,
      "y": 40,
      "z": 6,
      "name": "Rock_Acid_Trunk_Medium"
    },
    {
      "x": -24,
      "y": 41,
      "z": 6,
      "name": "Rock_Acid_Trunk_Medium"
    },
    {
      "x": -24,
      "y": 42,
      "z": 6,
      "name": "Rock_Acid_Trunk_Medium"
    },
    {
      "x": -24,
      "y": 43,
      "z": 6,
      "name": "Rock_Acid_Trunk_Medium"
    },
    {
      "x": -24,
      "y": 44,
      "z": 6,
      "name": "Rock_Acid_Trunk_Crimson"
    },
    {
      "x": -24,
      "y": 45,
      "z": 6,
      "name": "Empty"
    },
    {
      "x": -24,
      "y": 33,
      "z": 7,
      "name": "Rock_Acid_Trunk_Orange"
    },
    {
      "x": -24,
      "y": 34,
      "z": 7,
      "name": "Rock_Acid_Trunk_Orange"
    },
    {
      "x": -24,
      "y": 35,
      "z": 7,
      "name": "Rock_Acid_Trunk_Orange"
    },
    {
      "x": -24,
      "y": 36,
      "z": 7,
      "name": "Rock_Acid_Trunk_Bright"
    },
    {
      "x": -24,
      "y": 37,
      "z": 7,
      "name": "Rock_Acid_Trunk_Medium"
    },
    {
      "x": -24,
      "y": 38,
      "z": 7,
      "name": "Rock_Acid_Trunk_Medium"
    },
    {
      "x": -24,
      "y": 39,
      "z": 7,
      "name": "Rock_Acid_Trunk_Medium"
    },
    {
      "x": -24,
      "y": 40,
      "z": 7,
      "name": "Rock_Acid_Trunk_Medium"
    },
    {
      "x": -24,
      "y": 41,
      "z": 7,
      "name": "Rock_Acid_Trunk_Medium"
    },
    {
      "x": -24,
      "y": 42,
      "z": 7,
      "name": "Rock_Acid_Trunk_Medium"
    },
    {
      "x": -24,
      "y": 43,
      "z": 7,
      "name": "Rock_Acid_Trunk_Medium"
    },
    {
      "x": -24,
      "y": 44,
      "z": 7,
      "name": "Rock_Acid_Trunk_Crimson"
    },
    {
      "x": -24,
      "y": 45,
      "z": 7,
      "name": "Empty"
    },
    {
      "x": -24,
      "y": 32,
      "z": 8,
      "name": "Rock_Acid_Trunk_Medium"
    },
    {
      "x": -24,
      "y": 33,
      "z": 8,
      "name": "Rock_Acid_Trunk_Bright"
    },
    {
      "x": -24,
      "y": 34,
      "z": 8,
      "name": "Rock_Acid_Trunk_Orange"
    },
    {
      "x": -24,
      "y": 35,
      "z": 8,
      "name": "Rock_Acid_Trunk_Orange"
    },
    {
      "x": -24,
      "y": 36,
      "z": 8,
      "name": "Rock_Acid_Trunk_Medium"
    },
    {
      "x": -24,
      "y": 37,
      "z": 8,
      "name": "Rock_Acid_Trunk_Medium"
    },
    {
      "x": -24,
      "y": 38,
      "z": 8,
      "name": "Rock_Acid_Trunk_Medium"
    },
    {
      "x": -24,
      "y": 39,
      "z": 8,
      "name": "Rock_Acid_Trunk_Medium"
    },
    {
      "x": -24,
      "y": 40,
      "z": 8,
      "name": "Rock_Acid_Trunk_Medium"
    },
    {
      "x": -24,
      "y": 41,
      "z": 8,
      "name": "Rock_Acid_Trunk_Medium"
    },
    {
      "x": -24,
      "y": 42,
      "z": 8,
      "name": "Rock_Acid_Trunk_Medium"
    },
    {
      "x": -24,
      "y": 43,
      "z": 8,
      "name": "Rock_Acid_Trunk_Crimson"
    },
    {
      "x": -24,
      "y": 44,
      "z": 8,
      "name": "Rock_Crystal_Green_Block",
      "rotation": 4
    },
    {
      "x": -24,
      "y": 45,
      "z": 8,
      "name": "Empty"
    },
    {
      "x": -24,
      "y": 32,
      "z": 9,
      "name": "Rock_Acid_Trunk_Medium"
    },
    {
      "x": -24,
      "y": 33,
      "z": 9,
      "name": "Rock_Acid_Trunk_Bright"
    },
    {
      "x": -24,
      "y": 34,
      "z": 9,
      "name": "Rock_Acid_Trunk_Bright"
    },
    {
      "x": -24,
      "y": 35,
      "z": 9,
      "name": "Rock_Acid_Trunk_Orange"
    },
    {
      "x": -24,
      "y": 36,
      "z": 9,
      "name": "Rock_Acid_Trunk_Medium"
    },
    {
      "x": -24,
      "y": 37,
      "z": 9,
      "name": "Rock_Acid_Trunk_Medium"
    },
    {
      "x": -24,
      "y": 38,
      "z": 9,
      "name": "Rock_Acid_Trunk_Medium"
    },
    {
      "x": -24,
      "y": 39,
      "z": 9,
      "name": "Rock_Acid_Trunk_Medium"
    },
    {
      "x": -24,
      "y": 40,
      "z": 9,
      "name": "Rock_Acid_Trunk_Medium"
    },
    {
      "x": -24,
      "y": 41,
      "z": 9,
      "name": "Rock_Acid_Trunk_Medium"
    },
    {
      "x": -24,
      "y": 42,
      "z": 9,
      "name": "Rock_Acid_Trunk_Medium"
    },
    {
      "x": -24,
      "y": 43,
      "z": 9,
      "name": "Rock_Acid_Trunk_Crimson"
    },
    {
      "x": -24,
      "y": 44,
      "z": 9,
      "name": "Rock_Crystal_Green_Block",
      "rotation": 4
    },
    {
      "x": -24,
      "y": 45,
      "z": 9,
      "name": "Empty"
    },
    {
      "x": -24,
      "y": 32,
      "z": 10,
      "name": "Rock_Acid_Trunk_Medium"
    },
    {
      "x": -24,
      "y": 33,
      "z": 10,
      "name": "Rock_Acid_Trunk_Bright"
    },
    {
      "x": -24,
      "y": 34,
      "z": 10,
      "name": "Rock_Acid_Trunk_Bright"
    },
    {
      "x": -24,
      "y": 35,
      "z": 10,
      "name": "Rock_Acid_Trunk_Orange"
    },
    {
      "x": -24,
      "y": 36,
      "z": 10,
      "name": "Rock_Acid_Trunk_Bright"
    },
    {
      "x": -24,
      "y": 37,
      "z": 10,
      "name": "Rock_Acid_Trunk_Medium"
    },
    {
      "x": -24,
      "y": 38,
      "z": 10,
      "name": "Rock_Acid_Trunk_Medium"
    },
    {
      "x": -24,
      "y": 39,
      "z": 10,
      "name": "Rock_Acid_Trunk_Medium"
    },
    {
      "x": -24,
      "y": 40,
      "z": 10,
      "name": "Rock_Acid_Trunk_Medium"
    },
    {
      "x": -24,
      "y": 41,
      "z": 10,
      "name": "Rock_Acid_Trunk_Medium"
    },
    {
      "x": -24,
      "y": 42,
      "z": 10,
      "name": "Rock_Acid_Trunk_Medium"
    },
    {
      "x": -24,
      "y": 43,
      "z": 10,
      "name": "Rock_Acid_Trunk_Crimson"
    },
    {
      "x": -24,
      "y": 44,
      "z": 10,
      "name": "Rock_Crystal_Green_Block",
      "rotation": 4
    },
    {
      "x": -24,
      "y": 45,
      "z": 10,
      "name": "Empty"
    },
    {
      "x": -24,
      "y": 33,
      "z": 11,
      "name": "Rock_Acid_Trunk_Medium"
    },
    {
      "x": -24,
      "y": 34,
      "z": 11,
      "name": "Rock_Acid_Trunk_Orange"
    },
    {
      "x": -24,
      "y": 35,
      "z": 11,
      "name": "Rock_Acid_Trunk_Bright"
    },
    {
      "x": -24,
      "y": 36,
      "z": 11,
      "name": "Rock_Acid_Trunk_Bright"
    },
    {
      "x": -24,
      "y": 37,
      "z": 11,
      "name": "Rock_Acid_Trunk_Bright"
    },
    {
      "x": -24,
      "y": 38,
      "z": 11,
      "name": "Rock_Acid_Trunk_Medium"
    },
    {
      "x": -24,
      "y": 39,
      "z": 11,
      "name": "Rock_Acid_Trunk_Medium"
    },
    {
      "x": -24,
      "y": 40,
      "z": 11,
      "name": "Rock_Acid_Trunk_Medium"
    },
    {
      "x": -24,
      "y": 41,
      "z": 11,
      "name": "Rock_Acid_Trunk_Medium"
    },
    {
      "x": -24,
      "y": 42,
