{
  "version": 8,
  "blockIdVersion": 10,
  "anchorX": 0,
  "anchorY": 8,
  "anchorZ": 0,
  "blocks": [
    {
      "x": -33,
      "y": 10,
      "z": 3,
      "name": "Rock_Acid_Trunk_Light"
    },
    {
      "x": -33,
      "y": 10,
      "z": 4,
      "name": "Rock_Acid_Trunk_Light"
    },
    {
      "x": -33,
      "y": 10,
      "z": 33,
      "name": "Rock_Acid_Trunk_Light"
    },
    {
      "x": -32,
      "y": 10,
      "z": 3,
      "name": "Rock_Acid_Trunk_Light"
    },
    {
      "x": -32,
      "y": 9,
      "z": 4,
      "name": "Rock_Acid_Trunk_Light"
    },
    {
      "x": -32,
      "y": 10,
      "z": 4,
      "name": "Rock_Acid_Trunk_Light"
    },
    {
      "x": -32,
      "y": 10,
      "z": 5,
      "name": "Rock_Acid_Trunk_Light"
    },
    {
      "x": -32,
      "y": 11,
      "z": 30,
      "name": "Rock_Acid_Trunk_Light"
    },
    {
      "x": -32,
      "y": 12,
      "z": 30,
      "name": "Rock_Acid_Trunk_Light"
    },
    {
      "x": -32,
      "y": 11,
      "z": 31,
      "name": "Rock_Acid_Trunk_Light"
    },
    {
      "x": -32,
      "y": 12,
      "z": 31,
      "name": "Rock_Acid_Trunk_Light"
    },
    {
      "x": -32,
      "y": 10,
      "z": 32,
      "name": "Rock_Acid_Trunk_Light"
    },
    {
      "x": -32,
      "y": 11,
      "z": 32,
      "name": "Rock_Acid_Trunk_Light"
    },
    {
      "x": -32,
      "y": 10,
      "z": 33,
      "name": "Rock_Acid_Trunk_Light"
    },
    {
      "x": -31,
      "y": 10,
      "z": 3,
      "name": "Rock_Acid_Trunk_Light"
    },
    {
      "x": -31,
      "y": 9,
      "z": 4,
      "name": "Rock_Acid_Trunk_Light"
    },
    {
      "x": -31,
      "y": 10,
      "z": 4,
      "name": "Rock_Acid_Trunk_Medium"
    },
    {
      "x": -31,
      "y": 11,
      "z": 4,
      "name": "Rock_Acid_Trunk_Light"
    },
    {
      "x": -31,
      "y": 9,
      "z": 5,
      "name": "Rock_Acid_Trunk_Light"
    },
    {
      "x": -31,
      "y": 10,
      "z": 5,
      "name": "Rock_Acid_Trunk_Light"
    },
    {
      "x": -31,
      "y": 11,
      "z": 5,
      "name": "Rock_Acid_Trunk_Light"
    },
    {
      "x": -31,
      "y": 13,
      "z": 26,
      "name": "Rock_Acid_Trunk_Light"
    },
    {
      "x": -31,
      "y": 14,
      "z": 26,
      "name": "Rock_Acid_Trunk_Medium"
    },
    {
      "x": -31,
      "y": 13,
      "z": 27,
      "name": "Rock_Acid_Trunk_Light"
    },
    {
      "x": -31,
      "y": 14,
      "z": 27,
      "name": "Rock_Acid_Trunk_Medium"
    },
    {
      "x": -31,
      "y": 12,
      "z": 28,
      "name": "Rock_Acid_Trunk_Light"
    },
    {
      "x": -31,
      "y": 13,
      "z": 28,
      "name": "Rock_Acid_Trunk_Light"
    },
    {
      "x": -31,
      "y": 11,
      "z": 29,
      "name": "Rock_Acid_Trunk_Light"
    },
    {
      "x": -31,
      "y": 12,
      "z": 29,
      "name": "Rock_Acid_Trunk_Light"
    },
    {
      "x": -31,
      "y": 13,
      "z": 29,
      "name": "Rock_Acid_Trunk_Light"
    },
    {
      "x": -31,
      "y": 11,
      "z": 30,
      "name": "Rock_Acid_Trunk_Light"
    },
    {
      "x": -31,
      "y": 12,
      "z": 30,
      "name": "Rock_Acid_Trunk_Light"
    },
    {
      "x": -31,
      "y": 13,
      "z": 30,
      "name": "Rock_Acid_Trunk_Light"
    },
    {
      "x": -31,
      "y": 12,
      "z": 31,
      "name": "Rock_Acid_Trunk_Light"
    },
    {
      "x": -30,
      "y": 10,
      "z": 3,
      "name": "Rock_Acid_Trunk_Light"
    },
    {
      "x": -30,
      "y": 11,
      "z": 3,
      "name": "Rock_Acid_Trunk_Light"
    },
    {
      "x": -30,
      "y": 10,
      "z": 4,
      "name": "Rock_Acid_Trunk_Light"
    },
    {
      "x": -30,
      "y": 11,
      "z": 4,
      "name": "Rock_Acid_Trunk_Light"
    },
    {
      "x": -30,
      "y": 9,
      "z": 5,
      "name": "Rock_Acid_Trunk_Light"
    },
    {
      "x": -30,
      "y": 10,
      "z": 5,
      "name": "Rock_Acid_Trunk_Light"
    },
    {
      "x": -30,
      "y": 11,
      "z": 5,
      "name": "Rock_Acid_Trunk_Light"
    },
    {
      "x": -30,
      "y": 12,
      "z": 5,
      "name": "Rock_Acid_Trunk_Light"
    },
    {
      "x": -30,
      "y": 14,
      "z": 25,
      "name": "Rock_Acid_Trunk_Medium"
    },
    {
      "x": -30,
      "y": 13,
      "z": 26,
      "name": "Rock_Acid_Trunk_Light"
    },
    {
      "x": -30,
      "y": 14,
      "z": 26,
      "name": "Rock_Acid_Trunk_Medium"
    },
    {
      "x": -30,
      "y": 15,
      "z": 26,
      "name": "Rock_Acid_Trunk_Standard"
    },
    {
      "x": -30,
      "y": 13,
      "z": 27,
      "name": "Rock_Acid_Trunk_Light"
    },
    {
      "x": -30,
      "y": 14,
      "z": 27,
      "name": "Rock_Acid_Trunk_Standard"
    },
    {
      "x": -30,
      "y": 12,
      "z": 28,
      "name": "Rock_Acid_Trunk_Light"
    },
    {
      "x": -30,
      "y": 13,
      "z": 28,
      "name": "Rock_Acid_Trunk_Medium"
    },
    {
      "x": -30,
      "y": 14,
      "z": 28,
      "name": "Rock_Acid_Trunk_Standard"
    },
    {
      "x": -30,
      "y": 12,
      "z": 29,
      "name": "Rock_Acid_Trunk_Light"
    },
    {
      "x": -30,
      "y": 13,
      "z": 29,
      "name": "Rock_Acid_Trunk_Light"
    },
    {
      "x": -29,
      "y": 6,
      "z": -8,
      "name": "Rock_Acid_Trunk_Light"
    },
    {
      "x": -29,
      "y": 11,
      "z": 3,
      "name": "Rock_Acid_Trunk_Light"
    },
    {
      "x": -29,
      "y": 10,
      "z": 4,
      "name": "Rock_Acid_Trunk_Light"
    },
    {
      "x": -29,
      "y": 11,
      "z": 4,
      "name": "Rock_Acid_Trunk_Medium"
    },
    {
      "x": -29,
      "y": 12,
      "z": 4,
      "name": "Rock_Acid_Trunk_Light"
    },
    {
      "x": -29,
      "y": 10,
      "z": 5,
      "name": "Rock_Acid_Trunk_Light"
    },
    {
      "x": -29,
      "y": 11,
      "z": 5,
      "name": "Rock_Acid_Trunk_Medium"
    },
    {
      "x": -29,
      "y": 12,
      "z": 5,
      "name": "Rock_Acid_Trunk_Light"
    },
    {
      "x": -29,
      "y": 11,
      "z": 6,
      "name": "Rock_Acid_Trunk_Light"
    },
    {
      "x": -29,
      "y": 13,
      "z": 24,
      "name": "Rock_Acid_Trunk_Light"
    },
    {
      "x": -29,
      "y": 14,
      "z": 24,
      "name": "Rock_Acid_Trunk_Medium"
    },
    {
      "x": -29,
      "y": 13,
      "z": 25,
      "name": "Rock_Acid_Trunk_Light"
    },
    {
      "x": -29,
      "y": 14,
      "z": 25,
      "name": "Rock_Acid_Trunk_Medium"
    },
    {
      "x": -29,
      "y": 15,
      "z": 25,
      "name": "Rock_Acid_Trunk_Standard"
    },
    {
      "x": -29,
      "y": 13,
      "z": 26,
      "name": "Rock_Acid_Trunk_Light"
    },
    {
      "x": -29,
      "y": 14,
      "z": 26,
      "name": "Rock_Acid_Trunk_Medium"
    },
    {
      "x": -29,
      "y": 15,
      "z": 26,
      "name": "Rock_Acid_Trunk_Standard"
    },
    {
      "x": -29,
      "y": 13,
      "z": 27,
      "name": "Rock_Acid_Trunk_Light"
    },
    {
      "x": -29,
      "y": 14,
      "z": 27,
      "name": "Rock_Acid_Trunk_Medium"
    },
    {
      "x": -29,
      "y": 15,
      "z": 27,
      "name": "Rock_Acid_Trunk_Standard"
    },
    {
      "x": -29,
      "y": 13,
      "z": 28,
      "name": "Rock_Acid_Trunk_Light"
    },
    {
      "x": -29,
      "y": 14,
      "z": 28,
      "name": "Rock_Acid_Trunk_Medium"
    },
    {
      "x": -29,
      "y": 13,
      "z": 29,
      "name": "Rock_Acid_Trunk_Light"
    },
    {
      "x": -28,
      "y": 6,
      "z": -9,
      "name": "Rock_Acid_Trunk_Light"
    },
    {
      "x": -28,
      "y": 5,
      "z": -8,
      "name": "Rock_Acid_Trunk_Light"
    },
    {
      "x": -28,
      "y": 6,
      "z": -8,
      "name": "Rock_Acid_Trunk_Light"
    },
    {
      "x": -28,
      "y": 6,
      "z": -7,
      "name": "Rock_Acid_Trunk_Light"
    },
    {
      "x": -28,
      "y": 11,
      "z": 3,
      "name": "Rock_Acid_Trunk_Light"
    },
    {
      "x": -28,
      "y": 10,
      "z": 4,
      "name": "Rock_Acid_Trunk_Light"
    },
    {
      "x": -28,
      "y": 11,
      "z": 4,
      "name": "Rock_Acid_Trunk_Medium"
    },
    {
      "x": -28,
      "y": 12,
      "z": 4,
      "name": "Rock_Acid_Trunk_Light"
    },
    {
      "x": -28,
      "y": 10,
      "z": 5,
      "name": "Rock_Acid_Trunk_Light"
    },
    {
      "x": -28,
      "y": 11,
      "z": 5,
      "name": "Rock_Acid_Trunk_Medium"
    },
    {
      "x": -28,
      "y": 12,
      "z": 5,
      "name": "Rock_Acid_Trunk_Light"
    },
    {
      "x": -28,
      "y": 11,
      "z": 6,
      "name": "Rock_Acid_Trunk_Light"
    },
    {
      "x": -28,
      "y": 12,
      "z": 6,
      "name": "Rock_Acid_Trunk_Light"
    },
    {
      "x": -28,
      "y": 11,
      "z": 23,
      "name": "Rock_Acid_Trunk_Light"
    },
    {
      "x": -28,
      "y": 11,
      "z": 24,
      "name": "Rock_Acid_Trunk_Light"
    },
    {
      "x": -28,
      "y": 12,
      "z": 24,
      "name": "Rock_Acid_Trunk_Light"
    },
    {
      "x": -28,
      "y": 13,
      "z": 24,
      "name": "Rock_Acid_Trunk_Medium"
    },
    {
      "x": -28,
      "y": 14,
      "z": 24,
      "name": "Rock_Acid_Trunk_Standard"
    },
    {
      "x": -28,
      "y": 12,
      "z": 25,
      "name": "Rock_Acid_Trunk_Light"
    },
    {
      "x": -28,
      "y": 13,
      "z": 25,
      "name": "Rock_Acid_Trunk_Medium"
    },
    {
      "x": -28,
      "y": 14,
      "z": 25,
      "name": "Rock_Acid_Trunk_Medium"
    },
    {
      "x": -28,
      "y": 15,
      "z": 25,
      "name": "Rock_Acid_Trunk_Standard"
    },
    {
      "x": -28,
      "y": 12,
      "z": 26,
      "name": "Rock_Acid_Trunk_Light"
    },
    {
      "x": -28,
      "y": 13,
      "z": 26,
      "name": "Rock_Acid_Trunk_Light"
    },
    {
      "x": -28,
      "y": 14,
      "z": 26,
      "name": "Rock_Acid_Trunk_Medium"
    },
    {
      "x": -28,
      "y": 15,
      "z": 26,
      "name": "Rock_Acid_Trunk_Standard"
    },
    {
      "x": -28,
      "y": 13,
      "z": 27,
      "name": "Rock_Acid_Trunk_Light"
    },
    {
      "x": -28,
      "y": 14,
      "z": 27,
      "name": "Rock_Acid_Trunk_Medium"
    },
    {
      "x": -27,
      "y": 6,
      "z": -8,
      "name": "Rock_Acid_Trunk_Light"
    },
    {
      "x": -27,
      "y": 5,
      "z": -7,
      "name": "Rock_Acid_Trunk_Light"
    },
    {
      "x": -27,
      "y": 6,
      "z": -7,
      "name": "Rock_Acid_Trunk_Medium"
    },
    {
      "x": -27,
      "y": 7,
      "z": -7,
      "name": "Rock_Acid_Trunk_Light"
    },
    {
      "x": -27,
      "y": 6,
      "z": -6,
      "name": "Rock_Acid_Trunk_Light"
    },
    {
      "x": -27,
      "y": 7,
      "z": -6,
      "name": "Rock_Acid_Trunk_Light"
    },
    {
      "x": -27,
      "y": 11,
      "z": 3,
      "name": "Rock_Acid_Trunk_Light"
    },
    {
      "x": -27,
      "y": 10,
      "z": 4,
      "name": "Rock_Acid_Trunk_Light"
    },
    {
      "x": -27,
      "y": 11,
      "z": 4,
      "name": "Rock_Acid_Trunk_Medium"
    },
    {
      "x": -27,
      "y": 12,
      "z": 4,
      "name": "Rock_Acid_Trunk_Standard"
    },
    {
      "x": -27,
      "y": 10,
      "z": 5,
      "name": "Rock_Acid_Trunk_Light"
    },
    {
      "x": -27,
      "y": 11,
      "z": 5,
      "name": "Rock_Acid_Trunk_Medium"
    },
    {
      "x": -27,
      "y": 12,
      "z": 5,
      "name": "Rock_Acid_Trunk_Standard"
    },
    {
      "x": -27,
      "y": 10,
      "z": 6,
      "name": "Rock_Acid_Trunk_Light"
    },
    {
      "x": -27,
      "y": 11,
      "z": 6,
      "name": "Rock_Acid_Trunk_Light"
    },
    {
      "x": -27,
      "y": 12,
      "z": 6,
      "name": "Rock_Acid_Trunk_Light"
    },
    {
      "x": -27,
      "y": 10,
      "z": 22,
      "name": "Rock_Acid_Trunk_Light"
    },
    {
      "x": -27,
      "y": 11,
      "z": 22,
      "name": "Rock_Acid_Trunk_Light"
    },
    {
      "x": -27,
      "y": 12,
      "z": 22,
      "name": "Rock_Acid_Trunk_Medium"
    },
    {
      "x": -27,
      "y": 13,
      "z": 22,
      "name": "Rock_Acid_Trunk_Standard"
    },
    {
      "x": -27,
      "y": 10,
      "z": 23,
      "name": "Rock_Acid_Trunk_Light"
    },
    {
      "x": -27,
      "y": 11,
      "z": 23,
      "name": "Rock_Acid_Trunk_Medium"
    },
    {
      "x": -27,
      "y": 12,
      "z": 23,
      "name": "Rock_Acid_Trunk_Medium"
    },
    {
      "x": -27,
      "y": 13,
      "z": 23,
      "name": "Rock_Acid_Trunk_Standard"
    },
    {
      "x": -27,
      "y": 14,
      "z": 23,
      "name": "Rock_Acid_Trunk_Standard"
    },
    {
      "x": -27,
      "y": 10,
      "z": 24,
      "name": "Rock_Acid_Trunk_Light"
    },
    {
      "x": -27,
      "y": 11,
      "z": 24,
      "name": "Rock_Acid_Trunk_Medium"
    },
    {
      "x": -27,
      "y": 12,
      "z": 24,
      "name": "Rock_Acid_Trunk_Medium"
    },
    {
      "x": -27,
      "y": 13,
      "z": 24,
      "name": "Rock_Acid_Trunk_Medium"
    },
    {
      "x": -27,
      "y": 14,
      "z": 24,
      "name": "Rock_Acid_Trunk_Standard"
    },
    {
      "x": -27,
      "y": 15,
      "z": 24,
      "name": "Rock_Acid_Trunk_Standard"
    },
    {
      "x": -27,
      "y": 11,
      "z": 25,
      "name": "Rock_Acid_Trunk_Light"
    },
    {
      "x": -27,
      "y": 12,
      "z": 25,
      "name": "Rock_Acid_Trunk_Medium"
    },
    {
      "x": -27,
      "y": 13,
      "z": 25,
      "name": "Rock_Acid_Trunk_Medium"
    },
    {
      "x": -27,
      "y": 14,
      "z": 25,
      "name": "Rock_Acid_Trunk_Standard"
    },
    {
      "x": -27,
      "y": 14,
      "z": 26,
      "name": "Rock_Acid_Trunk_Medium"
    },
    {
      "x": -26,
      "y": 6,
      "z": -8,
      "name": "Rock_Acid_Trunk_Light"
    },
    {
      "x": -26,
      "y": 7,
      "z": -8,
      "name": "Rock_Acid_Trunk_Light"
    },
    {
      "x": -26,
      "y": 6,
      "z": -7,
      "name": "Rock_Acid_Trunk_Light"
    },
    {
      "x": -26,
      "y": 7,
      "z": -7,
      "name": "Rock_Acid_Trunk_Light"
    },
    {
      "x": -26,
      "y": 5,
      "z": -6,
      "name": "Rock_Acid_Trunk_Light"
    },
    {
      "x": -26,
      "y": 6,
      "z": -6,
      "name": "Rock_Acid_Trunk_Light"
    },
    {
      "x": -26,
      "y": 7,
      "z": -6,
      "name": "Rock_Acid_Trunk_Medium"
    },
    {
      "x": -26,
      "y": 8,
      "z": -6,
      "name": "Rock_Acid_Trunk_Light"
    },
    {
      "x": -26,
      "y": 7,
      "z": -5,
      "name": "Rock_Acid_Trunk_Light"
    },
    {
      "x": -26,
      "y": 10,
      "z": 4,
      "name": "Rock_Acid_Trunk_Light"
    },
    {
      "x": -26,
      "y": 11,
      "z": 4,
      "name": "Rock_Acid_Trunk_Light"
    },
    {
      "x": -26,
      "y": 12,
      "z": 4,
      "name": "Rock_Acid_Trunk_Medium"
    },
    {
      "x": -26,
      "y": 13,
      "z": 4,
      "name": "Rock_Acid_Trunk_Standard"
    },
    {
      "x": -26,
      "y": 10,
      "z": 5,
      "name": "Rock_Acid_Trunk_Light"
    },
    {
      "x": -26,
      "y": 11,
      "z": 5,
      "name": "Rock_Acid_Trunk_Medium"
    },
    {
      "x": -26,
      "y": 12,
      "z": 5,
      "name": "Rock_Acid_Trunk_Medium"
    },
    {
      "x": -26,
      "y": 13,
      "z": 5,
      "name": "Rock_Acid_Trunk_Standard"
    },
    {
      "x": -26,
      "y": 10,
      "z": 6,
      "name": "Rock_Acid_Trunk_Light"
    },
    {
      "x": -26,
      "y": 11,
      "z": 6,
      "name": "Rock_Acid_Trunk_Light"
    },
    {
      "x": -26,
      "y": 12,
      "z": 6,
      "name": "Rock_Acid_Trunk_Medium"
    },
    {
      "x": -26,
      "y": 11,
      "z": 20,
      "name": "Rock_Acid_Trunk_Light"
    },
    {
      "x": -26,
      "y": 12,
      "z": 20,
      "name": "Rock_Acid_Trunk_Medium"
    },
    {
      "x": -26,
      "y": 10,
      "z": 21,
      "name": "Rock_Acid_Trunk_Light"
    },
    {
      "x": -26,
      "y": 11,
      "z": 21,
      "name": "Rock_Acid_Trunk_Light"
    },
    {
      "x": -26,
      "y": 12,
      "z": 21,
      "name": "Rock_Acid_Trunk_Medium"
    },
    {
      "x": -26,
      "y": 13,
      "z": 21,
      "name": "Rock_Acid_Trunk_Standard"
    },
    {
      "x": -26,
      "y": 10,
      "z": 22,
      "name": "Rock_Acid_Trunk_Light"
    },
    {
      "x": -26,
      "y": 11,
      "z": 22,
      "name": "Rock_Acid_Trunk_Medium"
    },
    {
      "x": -26,
      "y": 12,
      "z": 22,
      "name": "Rock_Acid_Trunk_Medium"
    },
    {
      "x": -26,
      "y": 13,
      "z": 22,
      "name": "Rock_Acid_Trunk_Standard"
    },
    {
      "x": -26,
      "y": 10,
      "z": 23,
      "name": "Rock_Acid_Trunk_Light"
    },
    {
      "x": -26,
      "y": 11,
      "z": 23,
      "name": "Rock_Acid_Trunk_Medium"
    },
    {
      "x": -26,
      "y": 12,
      "z": 23,
      "name": "Rock_Acid_Trunk_Medium"
    },
    {
      "x": -26,
      "y": 13,
      "z": 23,
      "name": "Rock_Acid_Trunk_Medium"
    },
    {
      "x": -26,
      "y": 14,
      "z": 23,
      "name": "Rock_Acid_Trunk_Standard"
    },
    {
      "x": -26,
      "y": 10,
      "z": 24,
      "name": "Rock_Acid_Trunk_Light"
    },
    {
      "x": -26,
      "y": 11,
      "z": 24,
      "name": "Rock_Acid_Trunk_Medium"
    },
    {
      "x": -26,
      "y": 12,
      "z": 24,
      "name": "Rock_Acid_Trunk_Medium"
    },
    {
      "x": -26,
      "y": 13,
      "z": 24,
      "name": "Rock_Acid_Trunk_Standard"
    },
    {
      "x": -26,
      "y": 10,
      "z": 25,
      "name": "Rock_Acid_Trunk_Light"
    },
    {
      "x": -26,
      "y": 11,
      "z": 25,
      "name": "Rock_Acid_Trunk_Medium"
    },
    {
      "x": -26,
      "y": 12,
      "z": 25,
      "name": "Rock_Acid_Trunk_Light"
    },
    {
      "x": -25,
      "y": 6,
      "z": -7,
      "name": "Rock_Acid_Trunk_Light"
    },
    {
      "x": -25,
      "y": 7,
      "z": -7,
      "name": "Rock_Acid_Trunk_Light"
    },
    {
      "x": -25,
      "y": 6,
      "z": -6,
      "name": "Rock_Acid_Trunk_Light"
    },
    {
      "x": -25,
      "y": 7,
      "z": -6,
      "name": "Rock_Acid_Trunk_Medium"
    },
    {
      "x": -25,
      "y": 8,
      "z": -6,
      "name": "Rock_Acid_Trunk_Light"
    },
    {
      "x": -25,
      "y": 6,
      "z": -5,
      "name": "Rock_Acid_Trunk_Light"
    },
    {
      "x": -25,
      "y": 7,
      "z": -5,
      "name": "Rock_Acid_Trunk_Medium"
    },
    {
      "x": -25,
      "y": 8,
      "z": -5,
      "name": "Rock_Acid_Trunk_Light"
    },
    {
      "x": -25,
      "y": 7,
      "z": -4,
      "name": "Rock_Acid_Trunk_Light"
    },
    {
      "x": -25,
      "y": 8,
      "z": -4,
      "name": "Rock_Acid_Trunk_Light"
    },
    {
      "x": -25,
      "y": 12,
      "z": 3,
      "name": "Rock_Acid_Trunk_Light"
    },
    {
      "x": -25,
      "y": 11,
      "z": 4,
      "name": "Rock_Acid_Trunk_Light"
    },
    {
      "x": -25,
      "y": 12,
      "z": 4,
      "name": "Rock_Acid_Trunk_Medium"
    },
    {
      "x": -25,
      "y": 13,
      "z": 4,
      "name": "Rock_Acid_Trunk_Medium"
    },
    {
      "x": -25,
      "y": 10,
      "z": 5,
      "name": "Rock_Acid_Trunk_Light"
    },
    {
      "x": -25,
      "y": 11,
      "z": 5,
      "name": "Rock_Acid_Trunk_Medium"
    },
    {
      "x": -25,
      "y": 12,
      "z": 5,
      "name": "Rock_Acid_Trunk_Medium"
    },
    {
      "x": -25,
      "y": 13,
      "z": 5,
      "name": "Rock_Acid_Trunk_Standard"
    },
    {
      "x": -25,
      "y": 10,
      "z": 6,
      "name": "Rock_Acid_Trunk_Light"
    },
    {
      "x": -25,
      "y": 11,
      "z": 6,
      "name": "Rock_Acid_Trunk_Medium"
    },
    {
      "x": -25,
      "y": 12,
      "z": 6,
      "name": "Rock_Acid_Trunk_Medium"
    },
    {
      "x": -25,
      "y": 13,
      "z": 6,
      "name": "Rock_Acid_Trunk_Medium"
    },
    {
      "x": -25,
      "y": 11,
      "z": 7,
      "name": "Rock_Acid_Trunk_Light"
    },
    {
      "x": -25,
      "y": 12,
      "z": 7,
      "name": "Rock_Acid_Trunk_Medium"
    },
    {
      "x": -25,
      "y": 10,
      "z": 20,
      "name": "Rock_Acid_Trunk_Light"
    },
    {
      "x": -25,
      "y": 11,
      "z": 20,
      "name": "Rock_Acid_Trunk_Medium"
    },
    {
      "x": -25,
      "y": 12,
      "z": 20,
      "name": "Rock_Acid_Trunk_Standard"
    },
    {
      "x": -25,
      "y": 9,
      "z": 21,
      "name": "Rock_Acid_Trunk_Light"
    },
    {
      "x": -25,
      "y": 10,
      "z": 21,
      "name": "Rock_Acid_Trunk_Medium"
    },
    {
      "x": -25,
      "y": 11,
      "z": 21,
      "name": "Rock_Acid_Trunk_Medium"
    },
    {
      "x": -25,
      "y": 12,
      "z": 21,
      "name": "Rock_Acid_Trunk_Medium"
    },
    {
      "x": -25,
      "y": 13,
      "z": 21,
      "name": "Rock_Acid_Trunk_Standard"
    },
    {
      "x": -25,
      "y": 9,
      "z": 22,
      "name": "Rock_Acid_Trunk_Light"
    },
    {
      "x": -25,
      "y": 10,
      "z": 22,
      "name": "Rock_Acid_Trunk_Medium"
    },
    {
      "x": -25,
      "y": 11,
      "z": 22,
      "name": "Rock_Acid_Trunk_Medium"
    },
    {
      "x": -25,
      "y": 12,
      "z": 22,
      "name": "Rock_Acid_Trunk_Medium"
    },
    {
      "x": -25,
      "y": 13,
      "z": 22,
      "name": "Rock_Acid_Trunk_Standard"
    },
    {
      "x": -25,
      "y": 14,
      "z": 22,
      "name": "Rock_Acid_Trunk_Standard"
    },
    {
      "x": -25,
      "y": 10,
      "z": 23,
      "name": "Rock_Acid_Trunk_Light"
    },
    {
      "x": -25,
      "y": 11,
      "z": 23,
      "name": "Rock_Acid_Trunk_Medium"
    },
    {
      "x": -25,
      "y": 12,
      "z": 23,
      "name": "Rock_Acid_Trunk_Medium"
    },
    {
      "x": -25,
      "y": 13,
      "z": 23,
      "name": "Rock_Acid_Trunk_Standard"
    },
    {
      "x": -25,
      "y": 11,
      "z": 24,
      "name": "Rock_Acid_Trunk_Light"
    },
    {
      "x": -24,
      "y": 7,
      "z": -7,
      "name": "Rock_Acid_Trunk_Light"
    },
    {
      "x": -24,
      "y": 6,
      "z": -6,
      "name": "Rock_Acid_Trunk_Light"
    },
    {
      "x": -24,
      "y": 7,
      "z": -6,
      "name": "Rock_Acid_Trunk_Medium"
    },
    {
      "x": -24,
      "y": 8,
      "z": -6,
      "name": "Rock_Acid_Trunk_Light"
    },
    {
      "x": -24,
      "y": 5,
      "z": -5,
      "name": "Rock_Acid_Trunk_Light"
    },
    {
      "x": -24,
      "y": 6,
      "z": -5,
      "name": "Rock_Acid_Trunk_Medium"
    },
    {
      "x": -24,
      "y": 7,
      "z": -5,
      "name": "Rock_Acid_Trunk_Medium"
    },
    {
      "x": -24,
      "y": 8,
      "z": -5,
      "name": "Rock_Acid_Trunk_Light"
    },
    {
      "x": -24,
      "y": 6,
      "z": -4,
      "name": "Rock_Acid_Trunk_Light"
    },
    {
      "x": -24,
      "y": 7,
      "z": -4,
      "name": "Rock_Acid_Trunk_Medium"
    },
    {
      "x": -24,
      "y": 8,
      "z": -4,
      "name": "Rock_Acid_Trunk_Standard"
    },
    {
      "x": -24,
      "y": 7,
      "z": -3,
      "name": "Rock_Acid_Trunk_Light"
    },
    {
      "x": -24,
      "y": 12,
      "z": 3,
      "name": "Rock_Acid_Trunk_Light"
    },
    {
      "x": -24,
      "y": 13,
      "z": 3,
      "name": "Rock_Acid_Trunk_Medium"
    },
    {
      "x": -24,
      "y": 11,
      "z": 4,
      "name": "Rock_Acid_Trunk_Light"
    },
    {
      "x": -24,
      "y": 12,
      "z": 4,
      "name": "Rock_Acid_Trunk_Medium"
    },
    {
      "x": -24,
      "y": 13,
      "z": 4,
      "name": "Rock_Acid_Trunk_Medium"
    },
    {
      "x": -24,
      "y": 14,
      "z": 4,
      "name": "Rock_Acid_Trunk_Standard"
    },
    {
      "x": -24,
      "y": 10,
      "z": 5,
      "name": "Rock_Acid_Trunk_Light"
    },
    {
      "x": -24,
      "y": 11,
      "z": 5,
      "name": "Rock_Acid_Trunk_Medium"
    },
    {
      "x": -24,
      "y": 12,
      "z": 5,
      "name": "Rock_Acid_Trunk_Medium"
    },
    {
      "x": -24,
      "y": 13,
      "z": 5,
      "name": "Rock_Acid_Trunk_Medium"
    },
    {
      "x": -24,
      "y": 14,
      "z": 5,
      "name": "Rock_Acid_Trunk_Standard"
    },
    {
      "x": -24,
      "y": 15,
      "z": 5,
      "name": "Rock_Acid_Trunk_Standard"
    },
    {
      "x": -24,
      "y": 11,
      "z": 6,
      "name": "Rock_Acid_Trunk_Light"
    },
    {
      "x": -24,
      "y": 12,
      "z": 6,
      "name": "Rock_Acid_Trunk_Medium"
    },
    {
      "x": -24,
      "y": 13,
      "z": 6,
      "name": "Rock_Acid_Trunk_Medium"
    },
    {
      "x": -24,
      "y": 14,
      "z": 6,
      "name": "Rock_Acid_Trunk_Standard"
    },
    {
      "x": -24,
      "y": 11,
      "z": 7,
      "name": "Rock_Acid_Trunk_Light"
    },
    {
      "x": -24,
      "y": 12,
      "z": 7,
      "name": "Rock_Acid_Trunk_Light"
    },
    {
      "x": -24,
      "y": 13,
      "z": 7,
      "name": "Rock_Acid_Trunk_Medium"
    },
    {
      "x": -24,
      "y": 11,
      "z": 18,
      "name": "Rock_Acid_Trunk_Medium"
    },
    {
      "x": -24,
      "y": 9,
      "z": 19,
      "name": "Rock_Acid_Trunk_Light"
    },
    {
      "x": -24,
      "y": 10,
      "z": 19,
      "name": "Rock_Acid_Trunk_Light"
    },
    {
      "x": -24,
      "y": 11,
      "z": 19,
      "name": "Rock_Acid_Trunk_Medium"
    },
    {
      "x": -24,
      "y": 12,
      "z": 19,
      "name": "Rock_Acid_Trunk_Standard"
    },
    {
      "x": -24,
      "y": 9,
      "z": 20,
      "name": "Rock_Acid_Trunk_Light"
    },
    {
      "x": -24,
      "y": 10,
      "z": 20,
      "name": "Rock_Acid_Trunk_Medium"
    },
    {
      "x": -24,
      "y": 11,
      "z": 20,
      "name": "Rock_Acid_Trunk_Medium"
    },
    {
      "x": -24,
      "y": 12,
      "z": 20,
      "name": "Rock_Acid_Trunk_Standard"
    },
    {
      "x": -24,
      "y": 9,
      "z": 21,
      "name": "Rock_Acid_Trunk_Light"
    },
    {
      "x": -24,
      "y": 10,
      "z": 21,
      "name": "Rock_Acid_Trunk_Medium"
    },
    {
      "x": -24,
      "y": 11,
      "z": 21,
      "name": "Rock_Acid_Trunk_Medium"
    },
    {
      "x": -24,
      "y": 12,
      "z": 21,
      "name": "Rock_Acid_Trunk_Standard"
    },
    {
      "x": -24,
      "y": 9,
      "z": 22,
      "name": "Rock_Acid_Trunk_Light"
    },
    {
      "x": -24,
      "y": 10,
      "z": 22,
      "name": "Rock_Acid_Trunk_Medium"
    },
    {
      "x": -24,
      "y": 11,
      "z": 22,
      "name": "Rock_Acid_Trunk_Medium"
    },
    {
      "x": -24,
      "y": 12,
      "z": 22,
      "name": "Rock_Acid_Trunk_Standard"
    },
    {
      "x": -24,
      "y": 10,
      "z": 23,
      "name": "Rock_Acid_Trunk_Medium"
    },
    {
      "x": -24,
      "y": 11,
      "z": 23,
      "name": "Rock_Acid_Trunk_Light"
    },
    {
      "x": -23,
      "y": 7,
      "z": -6,
      "name": "Rock_Acid_Trunk_Light"
    },
    {
      "x": -23,
      "y": 6,
      "z": -5,
      "name": "Rock_Acid_Trunk_Light"
    },
    {
      "x": -23,
      "y": 7,
      "z": -5,
      "name": "Rock_Acid_Trunk_Medium"
    },
    {
      "x": -23,
      "y": 8,
      "z": -5,
      "name": "Rock_Acid_Trunk_Standard"
    },
    {
      "x": -23,
      "y": 9,
      "z": -5,
      "name": "Rock_Acid_Trunk_Standard"
    },
    {
      "x": -23,
      "y": 6,
      "z": -4,
      "name": "Rock_Acid_Trunk_Light"
    },
    {
      "x": -23,
      "y": 7,
      "z": -4,
      "name": "Rock_Acid_Trunk_Medium"
    },
    {
      "x": -23,
      "y": 8,
      "z": -4,
      "name": "Rock_Acid_Trunk_Medium"
    },
    {
      "x": -23,
      "y": 9,
      "z": -4,
      "name": "Rock_Acid_Trunk_Standard"
    },
    {
      "x": -23,
      "y": 6,
      "z": -3,
      "name": "Rock_Acid_Trunk_Light"
    },
    {
      "x": -23,
      "y": 7,
      "z": -3,
      "name": "Rock_Acid_Trunk_Medium"
    },
    {
      "x": -23,
      "y": 8,
      "z": -3,
      "name": "Rock_Acid_Trunk_Medium"
    },
    {
      "x": -23,
      "y": 9,
      "z": -3,
      "name": "Rock_Acid_Trunk_Standard"
    },
    {
      "x": -23,
      "y": 7,
      "z": -2,
      "name": "Rock_Acid_Trunk_Light"
    },
    {
      "x": -23,
      "y": 8,
      "z": -2,
      "name": "Rock_Acid_Trunk_Light"
    },
    {
      "x": -23,
      "y": 12,
      "z": 3,
      "name": "Rock_Acid_Trunk_Light"
    },
    {
      "x": -23,
      "y": 13,
      "z": 3,
      "name": "Rock_Acid_Trunk_Light"
    },
    {
      "x": -23,
      "y": 11,
      "z": 4,
      "name": "Rock_Acid_Trunk_Light"
    },
    {
      "x": -23,
      "y": 12,
      "z": 4,
      "name": "Rock_Acid_Trunk_Medium"
    },
    {
      "x": -23,
      "y": 13,
      "z": 4,
      "name": "Rock_Acid_Trunk_Medium"
    },
    {
      "x": -23,
      "y": 14,
      "z": 4,
      "name": "Rock_Acid_Trunk_Medium"
    },
    {
      "x": -23,
      "y": 15,
      "z": 4,
      "name": "Rock_Acid_Trunk_Standard"
    },
    {
      "x": -23,
      "y": 11,
      "z": 5,
      "name": "Rock_Acid_Trunk_Light"
    },
    {
      "x": -23,
      "y": 12,
      "z": 5,
      "name": "Rock_Acid_Trunk_Medium"
    },
    {
      "x": -23,
      "y": 13,
      "z": 5,
      "name": "Rock_Acid_Trunk_Medium"
    },
    {
      "x": -23,
      "y": 14,
      "z": 5,
      "name": "Rock_Acid_Trunk_Medium"
    },
    {
      "x": -23,
      "y": 15,
      "z": 5,
      "name": "Rock_Acid_Trunk_Standard"
    },
    {
      "x": -23,
      "y": 11,
      "z": 6,
      "name": "Rock_Acid_Trunk_Light"
    },
    {
      "x": -23,
      "y": 12,
      "z": 6,
      "name": "Rock_Acid_Trunk_Medium"
    },
    {
      "x": -23,
      "y": 13,
      "z": 6,
      "name": "Rock_Acid_Trunk_Medium"
    },
    {
      "x": -23,
      "y": 14,
      "z": 6,
      "name": "Rock_Acid_Trunk_Medium"
    },
    {
      "x": -23,
      "y": 15,
      "z": 6,
      "name": "Rock_Acid_Trunk_Standard"
    },
    {
      "x": -23,
      "y": 11,
      "z": 7,
      "name": "Rock_Acid_Trunk_Light"
    },
    {
      "x": -23,
      "y": 12,
      "z": 7,
      "name": "Rock_Acid_Trunk_Medium"
    },
    {
      "x": -23,
      "y": 13,
      "z": 7,
      "name": "Rock_Acid_Trunk_Medium"
    },
    {
      "x": -23,
      "y": 14,
      "z": 7,
      "name": "Rock_Acid_Trunk_Medium"
    },
    {
      "x": -23,
      "y": 15,
      "z": 7,
      "name": "Rock_Acid_Trunk_Medium"
    },
    {
      "x": -23,
      "y": 11,
      "z": 8,
      "name": "Rock_Acid_Trunk_Light"
    },
    {
      "x": -23,
      "y": 12,
      "z": 8,
      "name": "Rock_Acid_Trunk_Light"
    },
    {
      "x": -23,
      "y": 13,
      "z": 8,
      "name": "Rock_Acid_Trunk_Medium"
    },
    {
      "x": -23,
      "y": 10,
      "z": 17,
      "name": "Rock_Acid_Trunk_Light"
    },
    {
      "x": -23,
      "y": 11,
      "z": 17,
      "name": "Rock_Acid_Trunk_Medium"
    },
    {
      "x": -23,
      "y": 9,
      "z": 18,
      "name": "Rock_Acid_Trunk_Light"
    },
    {
      "x": -23,
      "y": 10,
      "z": 18,
      "name": "Rock_Acid_Trunk_Light"
    },
    {
      "x": -23,
      "y": 11,
      "z": 18,
      "name": "Rock_Acid_Trunk_Medium"
    },
    {
      "x": -23,
      "y": 12,
      "z": 18,
      "name": "Rock_Acid_Trunk_Standard"
    },
    {
      "x": -23,
      "y": 9,
      "z": 19,
      "name": "Rock_Acid_Trunk_Light"
    },
    {
      "x": -23,
      "y": 10,
      "z": 19,
      "name": "Rock_Acid_Trunk_Medium"
    },
    {
      "x": -23,
      "y": 11,
      "z": 19,
      "name": "Rock_Acid_Trunk_Medium"
    },
    {
      "x": -23,
      "y": 12,
      "z": 19,
      "name": "Rock_Acid_Trunk_Standard"
    },
    {
      "x": -23,
      "y": 9,
      "z": 20,
      "name": "Rock_Acid_Trunk_Light"
    },
    {
      "x": -23,
      "y": 10,
      "z": 20,
      "name": "Rock_Acid_Trunk_Medium"
    },
    {
      "x": -23,
      "y": 11,
      "z": 20,
      "name": "Rock_Acid_Trunk_Medium"
    },
    {
      "x": -23,
      "y": 12,
      "z": 20,
      "name": "Rock_Acid_Trunk_Medium"
    },
    {
      "x": -23,
      "y": 13,
      "z": 20,
      "name": "Rock_Acid_Trunk_Standard"
    },
    {
      "x": -23,
      "y": 9,
      "z": 21,
      "name": "Rock_Acid_Trunk_Light"
    },
    {
      "x": -23,
      "y": 10,
      "z": 21,
      "name": "Rock_Acid_Trunk_Medium"
    },
    {
      "x": -23,
      "y": 11,
      "z": 21,
      "name": "Rock_Acid_Trunk_Medium"
    },
    {
      "x": -23,
      "y": 12,
      "z": 21,
      "name": "Rock_Acid_Trunk_Standard"
    },
    {
      "x": -23,
      "y": 9,
      "z": 22,
      "name": "Rock_Acid_Trunk_Light"
    },
    {
      "x": -23,
      "y": 10,
      "z": 22,
      "name": "Rock_Acid_Trunk_Medium"
    },
    {
      "x": -23,
      "y": 11,
      "z": 22,
      "name": "Rock_Acid_Trunk_Medium"
    },
    {
      "x": -22,
      "y": 7,
      "z": -5,
      "name": "Rock_Acid_Trunk_Light"
    },
    {
      "x": -22,
      "y": 8,
      "z": -5,
      "name": "Rock_Acid_Trunk_Medium"
    },
    {
      "x": -22,
      "y": 6,
      "z": -4,
      "name": "Rock_Acid_Trunk_Light"
    },
    {
      "x": -22,
      "y": 7,
      "z": -4,
      "name": "Rock_Acid_Trunk_Medium"
    },
    {
      "x": -22,
      "y": 8,
      "z": -4,
      "name": "Rock_Acid_Trunk_Medium"
    },
    {
      "x": -22,
      "y": 9,
      "z": -4,
      "name": "Rock_Acid_Trunk_Standard"
    },
    {
      "x": -22,
      "y": 6,
      "z": -3,
      "name": "Rock_Acid_Trunk_Light"
    },
    {
      "x": -22,
      "y": 7,
      "z": -3,
      "name": "Rock_Acid_Trunk_Medium"
    },
    {
      "x": -22,
      "y": 8,
      "z": -3,
      "name": "Rock_Acid_Trunk_Medium"
    },
    {
      "x": -22,
      "y": 9,
      "z": -3,
      "name": "Rock_Acid_Trunk_Medium"
    },
    {
      "x": -22,
      "y": 10,
      "z": -3,
      "name": "Rock_Acid_Trunk_Standard"
    },
    {
      "x": -22,
      "y": 6,
      "z": -2,
      "name": "Rock_Acid_Trunk_Light"
    },
    {
      "x": -22,
      "y": 7,
      "z": -2,
      "name": "Rock_Acid_Trunk_Light"
    },
    {
      "x": -22,
      "y": 8,
      "z": -2,
      "name": "Rock_Acid_Trunk_Medium"
    },
    {
      "x": -22,
      "y": 9,
      "z": -2,
      "name": "Rock_Acid_Trunk_Medium"
    },
    {
      "x": -22,
      "y": 10,
      "z": -2,
      "name": "Rock_Acid_Trunk_Medium"
    },
    {
      "x": -22,
      "y": 8,
      "z": -1,
      "name": "Rock_Acid_Trunk_Light"
    },
    {
      "x": -22,
      "y": 9,
      "z": -1,
      "name": "Rock_Acid_Trunk_Light"
    },
    {
      "x": -22,
      "y": 13,
      "z": 3,
      "name": "Rock_Acid_Trunk_Light"
    },
    {
      "x": -22,
      "y": 14,
      "z": 3,
      "name": "Rock_Acid_Trunk_Medium"
    },
    {
      "x": -22,
      "y": 11,
      "z": 4,
      "name": "Rock_Acid_Trunk_Light"
    },
    {
      "x": -22,
      "y": 12,
      "z": 4,
      "name": "Rock_Acid_Trunk_Light"
    },
    {
      "x": -22,
      "y": 13,
      "z": 4,
      "name": "Rock_Acid_Trunk_Medium"
    },
    {
      "x": -22,
      "y": 14,
      "z": 4,
      "name": "Rock_Acid_Trunk_Medium"
    },
    {
      "x": -22,
      "y": 10,
      "z": 5,
      "name": "Rock_Acid_Trunk_Light"
    },
    {
      "x": -22,
      "y": 11,
      "z": 5,
      "name": "Rock_Acid_Trunk_Medium"
    },
    {
      "x": -22,
      "y": 12,
      "z": 5,
      "name": "Rock_Acid_Trunk_Medium"
    },
    {
      "x": -22,
      "y": 13,
      "z": 5,
      "name": "Rock_Acid_Trunk_Medium"
    },
    {
      "x": -22,
      "y": 14,
      "z": 5,
      "name": "Rock_Acid_Trunk_Medium"
    },
    {
      "x": -22,
      "y": 15,
      "z": 5,
      "name": "Rock_Acid_Trunk_Standard"
    },
    {
      "x": -22,
      "y": 16,
      "z": 5,
      "name": "Rock_Acid_Trunk_Standard"
    },
    {
      "x": -22,
      "y": 42,
      "z": 5,
      "name": "Rock_Acid_Trunk_Orange"
    },
    {
      "x": -22,
      "y": 43,
      "z": 5,
      "name": "Rock_Acid_Trunk_Bright"
    },
    {
      "x": -22,
      "y": 44,
      "z": 5,
      "name": "Rock_Acid_Trunk_Bright"
    },
    {
      "x": -22,
      "y": 45,
      "z": 5,
      "name": "Rock_Acid_Trunk_Bright"
    },
    {
      "x": -22,
      "y": 46,
      "z": 5,
      "name": "Rock_Acid_Trunk_Orange"
    },
    {
      "x": -22,
      "y": 47,
      "z": 5,
      "name": "Rock_Acid_Trunk_Orange"
    },
    {
      "x": -22,
      "y": 10,
      "z": 6,
      "name": "Rock_Acid_Trunk_Light"
    },
    {
      "x": -22,
      "y": 11,
      "z": 6,
      "name": "Rock_Acid_Trunk_Medium"
    },
    {
      "x": -22,
      "y": 12,
      "z": 6,
      "name": "Rock_Acid_Trunk_Medium"
    },
    {
      "x": -22,
      "y": 13,
      "z": 6,
      "name": "Rock_Acid_Trunk_Medium"
    },
    {
      "x": -22,
      "y": 14,
      "z": 6,
      "name": "Rock_Acid_Trunk_Medium"
    },
    {
      "x": -22,
      "y": 15,
      "z": 6,
      "name": "Rock_Acid_Trunk_Medium"
    },
    {
      "x": -22,
      "y": 16,
      "z": 6,
      "name": "Rock_Acid_Trunk_Standard"
    },
    {
      "x": -22,
      "y": 40,
      "z": 6,
      "name": "Rock_Acid_Trunk_Bright"
    },
    {
      "x": -22,
      "y": 41,
      "z": 6,
      "name": "Rock_Acid_Trunk_Bright"
    },
    {
      "x": -22,
      "y": 42,
      "z": 6,
      "name": "Rock_Acid_Trunk_Bright"
    },
    {
      "x": -22,
      "y": 43,
      "z": 6,
      "name": "Rock_Acid_Trunk_Bright"
    },
    {
      "x": -22,
      "y": 44,
      "z": 6,
      "name": "Rock_Acid_Trunk_Bright"
    },
    {
      "x": -22,
      "y": 45,
      "z": 6,
      "name": "Rock_Acid_Trunk_Bright"
    },
    {
      "x": -22,
      "y": 46,
      "z": 6,
      "name": "Rock_Acid_Trunk_Bright"
    },
    {
      "x": -22,
      "y": 47,
      "z": 6,
      "name": "Rock_Acid_Trunk_Bright"
    },
    {
      "x": -22,
      "y": 48,
      "z": 6,
      "name": "Rock_Acid_Trunk_Orange"
    },
    {
      "x": -22,
      "y": 49,
      "z": 6,
      "name": "Rock_Acid_Trunk_Orange"
    },
    {
      "x": -22,
      "y": 11,
      "z": 7,
      "name": "Rock_Acid_Trunk_Light"
    },
    {
      "x": -22,
      "y": 12,
      "z": 7,
      "name": "Rock_Acid_Trunk_Medium"
    },
    {
      "x": -22,
      "y": 13,
      "z": 7,
      "name": "Rock_Acid_Trunk_Medium"
    },
    {
      "x": -22,
      "y": 14,
      "z": 7,
      "name": "Rock_Acid_Trunk_Medium"
    },
    {
      "x": -22,
      "y": 15,
      "z": 7,
      "name": "Rock_Acid_Trunk_Medium"
    },
    {
      "x": -22,
      "y": 16,
      "z": 7,
      "name": "Rock_Acid_Trunk_Standard"
    },
    {
      "x": -22,
      "y": 39,
      "z": 7,
      "name": "Rock_Acid_Trunk_Bright"
    },
    {
      "x": -22,
      "y": 40,
      "z": 7,
      "name": "Rock_Acid_Trunk_Orange"
    },
    {
      "x": -22,
      "y": 41,
      "z": 7,
      "name": "Rock_Acid_Trunk_Bright"
    },
    {
      "x": -22,
      "y": 42,
      "z": 7,
      "name": "Rock_Acid_Trunk_Bright"
    },
    {
      "x": -22,
      "y": 43,
      "z": 7,
      "name": "Rock_Acid_Trunk_Bright"
    },
    {
      "x": -22,
      "y": 44,
      "z": 7,
      "name": "Rock_Acid_Trunk_Bright"
    },
    {
      "x": -22,
      "y": 45,
      "z": 7,
      "name": "Rock_Acid_Trunk_Bright"
    },
    {
      "x": -22,
      "y": 46,
      "z": 7,
      "name": "Rock_Acid_Trunk_Bright"
    },
    {
      "x": -22,
      "y": 47,
      "z": 7,
      "name": "Rock_Acid_Trunk_Bright"
    },
    {
      "x": -22,
      "y": 48,
      "z": 7,
      "name": "Rock_Acid_Trunk_Orange"
    },
    {
      "x": -22,
      "y": 49,
      "z": 7,
      "name": "Rock_Acid_Trunk_Orange"
    },
    {
      "x": -22,
      "y": 50,
      "z": 7,
      "name": "Rock_Acid_Trunk_Orange"
    },
    {
      "x": -22,
      "y": 11,
      "z": 8,
      "name": "Rock_Acid_Trunk_Light"
    },
    {
      "x": -22,
      "y": 12,
      "z": 8,
      "name": "Rock_Acid_Trunk_Medium"
    },
    {
      "x": -22,
      "y": 13,
      "z": 8,
      "name": "Rock_Acid_Trunk_Medium"
    },
    {
      "x": -22,
      "y": 14,
      "z": 8,
      "name": "Rock_Acid_Trunk_Medium"
    },
    {
      "x": -22,
      "y": 15,
      "z": 8,
      "name": "Rock_Acid_Trunk_Medium"
    },
    {
      "x": -22,
      "y": 38,
      "z": 8,
      "name": "Rock_Acid_Trunk_Bright"
    },
    {
      "x": -22,
      "y": 39,
      "z": 8,
      "name": "Rock_Acid_Trunk_Bright"
    },
    {
      "x": -22,
      "y": 40,
      "z": 8,
      "name": "Rock_Acid_Trunk_Orange"
    },
    {
      "x": -22,
      "y": 41,
      "z": 8,
      "name": "Rock_Acid_Trunk_Bright"
    },
    {
      "x": -22,
      "y": 42,
      "z": 8,
      "name": "Rock_Acid_Trunk_Bright"
    },
    {
      "x": -22,
      "y": 43,
      "z": 8,
      "name": "Rock_Acid_Trunk_Bright"
    },
    {
      "x": -22,
      "y": 44,
      "z": 8,
      "name": "Rock_Acid_Trunk_Bright"
    },
    {
      "x": -22,
      "y": 45,
      "z": 8,
      "name": "Rock_Acid_Trunk_Bright"
    },
    {
      "x": -22,
      "y": 46,
      "z": 8,
      "name": "Rock_Acid_Trunk_Bright"
    },
    {
      "x": -22,
      "y": 47,
      "z": 8,
      "name": "Rock_Acid_Trunk_Bright"
    },
    {
      "x": -22,
      "y": 48,
      "z": 8,
      "name": "Rock_Acid_Trunk_Bright"
    },
    {
      "x": -22,
      "y": 49,
      "z": 8,
      "name": "Rock_Acid_Trunk_Orange"
    },
    {
      "x": -22,
      "y": 50,
      "z": 8,
      "name": "Rock_Acid_Trunk_Orange"
    },
    {
      "x": -22,
      "y": 12,
      "z": 9,
      "name": "Rock_Acid_Trunk_Light"
    },
    {
      "x": -22,
      "y": 13,
      "z": 9,
      "name": "Rock_Acid_Trunk_Light"
    },
    {
      "x": -22,
      "y": 14,
      "z": 9,
      "name": "Rock_Acid_Trunk_Medium"
    },
    {
      "x": -22,
      "y": 39,
      "z": 9,
      "name": "Rock_Acid_Trunk_Bright"
    },
    {
      "x": -22,
      "y": 40,
      "z": 9,
      "name": "Rock_Acid_Trunk_Orange"
    },
    {
      "x": -22,
      "y": 41,
      "z": 9,
      "name": "Rock_Acid_Trunk_Orange"
    },
    {
      "x": -22,
      "y": 42,
      "z": 9,
      "name": "Rock_Acid_Trunk_Bright"
    },
    {
      "x": -22,
      "y": 43,
      "z": 9,
      "name": "Rock_Acid_Trunk_Bright"
    },
    {
      "x": -22,
      "y": 44,
      "z": 9,
      "name": "Rock_Acid_Trunk_Bright"
    },
    {
      "x": -22,
      "y": 45,
      "z": 9,
      "name": "Rock_Acid_Trunk_Bright"
    },
    {
      "x": -22,
      "y": 46,
      "z": 9,
      "name": "Rock_Acid_Trunk_Bright"
    },
    {
      "x": -22,
      "y": 47,
      "z": 9,
      "name": "Rock_Acid_Trunk_Bright"
    },
    {
      "x": -22,
      "y": 48,
      "z": 9,
      "name": "Rock_Acid_Trunk_Bright"
    },
    {
      "x": -22,
      "y": 49,
      "z": 9,
      "name": "Rock_Acid_Trunk_Orange"
    },
    {
      "x": -22,
      "y": 40,
      "z": 10,
      "name": "Rock_Acid_Trunk_Orange"
    },
    {
      "x": -22,
      "y": 41,
      "z": 10,
      "name": "Rock_Acid_Trunk_Orange"
    },
    {
      "x": -22,
      "y": 42,
      "z": 10,
      "name": "Rock_Acid_Trunk_Orange"
    },
    {
      "x": -22,
      "y": 43,
      "z": 10,
      "name": "Rock_Acid_Trunk_Bright"
    },
    {
      "x": -22,
      "y": 44,
      "z": 10,
      "name": "Rock_Acid_Trunk_Bright"
    },
    {
      "x": -22,
      "y": 45,
      "z": 10,
      "name": "Rock_Acid_Trunk_Bright"
    },
    {
      "x": -22,
      "y": 46,
      "z": 10,
      "name": "Rock_Acid_Trunk_Bright"
    },
    {
      "x": -22,
      "y": 47,
      "z": 10,
      "name": "Rock_Acid_Trunk_Bright"
    },
    {
      "x": -22,
      "y": 42,
      "z": 11,
      "name": "Rock_Acid_Trunk_Orange"
    },
    {
      "x": -22,
      "y": 43,
      "z": 11,
      "name": "Rock_Acid_Trunk_Orange"
    },
    {
      "x": -22,
      "y": 44,
      "z": 11,
      "name": "Rock_Acid_Trunk_Orange"
    },
    {
      "x": -22,
      "y": 45,
      "z": 11,
      "name": "Rock_Acid_Trunk_Bright"
    },
    {
      "x": -22,
      "y": 10,
      "z": 15,
      "name": "Rock_Acid_Trunk_Light"
    },
    {
      "x": -22,
      "y": 11,
      "z": 15,
      "name": "Rock_Acid_Trunk_Light"
    },
    {
      "x": -22,
      "y": 10,
      "z": 16,
      "name": "Rock_Acid_Trunk_Light"
    },
    {
      "x": -22,
      "y": 11,
      "z": 16,
      "name": "Rock_Acid_Trunk_Light"
    },
    {
      "x": -22,
      "y": 8,
      "z": 17,
      "name": "Rock_Acid_Trunk_Light"
    },
    {
      "x": -22,
      "y": 9,
      "z": 17,
      "name": "Rock_Acid_Trunk_Light"
    },
    {
      "x": -22,
      "y": 10,
      "z": 17,
      "name": "Rock_Acid_Trunk_Medium"
    },
    {
      "x": -22,
      "y": 11,
      "z": 17,
      "name": "Rock_Acid_Trunk_Medium"
    },
    {
      "x": -22,
      "y": 12,
      "z": 17,
      "name": "Rock_Acid_Trunk_Medium"
    },
    {
      "x": -22,
      "y": 13,
      "z": 17,
      "name": "Rock_Acid_Trunk_Standard"
    },
    {
      "x": -22,
      "y": 8,
      "z": 18,
      "name": "Rock_Acid_Trunk_Light"
    },
    {
      "x": -22,
      "y": 9,
      "z": 18,
      "name": "Rock_Acid_Trunk_Medium"
    },
    {
      "x": -22,
      "y": 10,
      "z": 18,
      "name": "Rock_Acid_Trunk_Medium"
    },
    {
      "x": -22,
      "y": 11,
      "z": 18,
      "name": "Rock_Acid_Trunk_Medium"
    },
    {
      "x": -22,
      "y": 12,
      "z": 18,
      "name": "Rock_Acid_Trunk_Medium"
    },
    {
      "x": -22,
      "y": 13,
      "z": 18,
      "name": "Rock_Acid_Trunk_Standard"
    },
    {
      "x": -22,
      "y": 9,
      "z": 19,
      "name": "Rock_Acid_Trunk_Light"
    },
    {
      "x": -22,
      "y": 10,
      "z": 19,
      "name": "Rock_Acid_Trunk_Medium"
    },
    {
      "x": -22,
      "y": 11,
      "z": 19,
      "name": "Rock_Acid_Trunk_Medium"
    },
    {
      "x": -22,
      "y": 12,
      "z": 19,
      "name": "Rock_Acid_Trunk_Medium"
    },
    {
      "x": -22,
      "y": 13,
      "z": 19,
      "name": "Rock_Acid_Trunk_Standard"
    },
    {
      "x": -22,
      "y": 9,
      "z": 20,
      "name": "Rock_Acid_Trunk_Light"
    },
    {
      "x": -22,
      "y": 10,
      "z": 20,
      "name": "Rock_Acid_Trunk_Medium"
    },
    {
      "x": -22,
      "y": 11,
      "z": 20,
      "name": "Rock_Acid_Trunk_Medium"
    },
    {
      "x": -22,
      "y": 12,
      "z": 20,
      "name": "Rock_Acid_Trunk_Standard"
    },
    {
      "x": -22,
      "y": 13,
      "z": 20,
      "name": "Rock_Acid_Trunk_Standard"
    },
    {
      "x": -22,
      "y": 10,
      "z": 21,
      "name": "Rock_Acid_Trunk_Medium"
    },
    {
      "x": -22,
      "y": 11,
      "z": 21,
      "name": "Rock_Acid_Trunk_Medium"
    },
    {
      "x": -21,
      "y": 11,
      "z": -28,
      "name": "Rock_Acid_Trunk_Light"
    },
    {
      "x": -21,
      "y": 12,
      "z": -28,
      "name": "Rock_Acid_Trunk_Light"
    },
    {
      "x": -21,
      "y": 12,
      "z": -27,
      "name": "Rock_Acid_Trunk_Light"
    },
    {
      "x": -21,
      "y": 7,
      "z": -4,
      "name": "Rock_Acid_Trunk_Light"
    },
    {
      "x": -21,
      "y": 8,
      "z": -4,
      "name": "Rock_Acid_Trunk_Light"
    },
    {
      "x": -21,
      "y": 9,
      "z": -4,
      "name": "Rock_Acid_Trunk_Medium"
    },
    {
      "x": -21,
      "y": 10,
      "z": -4,
      "name": "Rock_Acid_Trunk_Medium"
    },
    {
      "x": -21,
      "y": 6,
      "z": -3,
      "name": "Rock_Acid_Trunk_Light"
    },
    {
      "x": -21,
      "y": 7,
      "z": -3,
      "name": "Rock_Acid_Trunk_Medium"
    },
    {
      "x": -21,
      "y": 8,
      "z": -3,
      "name": "Rock_Acid_Trunk_Medium"
    },
    {
      "x": -21,
      "y": 9,
      "z": -3,
      "name": "Rock_Acid_Trunk_Medium"
    },
    {
      "x": -21,
      "y": 10,
      "z": -3,
      "name": "Rock_Acid_Trunk_Medium"
    },
    {
      "x": -21,
      "y": 11,
      "z": -3,
      "name": "Rock_Acid_Trunk_Standard"
    },
    {
      "x": -21,
      "y": 7,
      "z": -2,
      "name": "Rock_Acid_Trunk_Light"
    },
    {
      "x": -21,
      "y": 8,
      "z": -2,
      "name": "Rock_Acid_Trunk_Medium"
    },
    {
      "x": -21,
      "y": 9,
      "z": -2,
      "name": "Rock_Acid_Trunk_Medium"
    },
    {
      "x": -21,
      "y": 10,
      "z": -2,
      "name": "Rock_Acid_Trunk_Medium"
    },
    {
      "x": -21,
      "y": 11,
      "z": -2,
      "name": "Rock_Acid_Trunk_Standard"
    },
    {
      "x": -21,
      "y": 7,
      "z": -1,
      "name": "Rock_Acid_Trunk_Light"
    },
    {
      "x": -21,
      "y": 8,
      "z": -1,
      "name": "Rock_Acid_Trunk_Light"
    },
    {
      "x": -21,
      "y": 9,
      "z": -1,
      "name": "Rock_Acid_Trunk_Medium"
    },
    {
      "x": -21,
      "y": 10,
      "z": -1,
      "name": "Rock_Acid_Trunk_Medium"
    },
    {
      "x": -21,
      "y": 11,
      "z": -1,
      "name": "Rock_Acid_Trunk_Medium"
    },
    {
      "x": -21,
      "y": 12,
      "z": -1,
      "name": "Rock_Acid_Trunk_Medium"
    },
    {
      "x": -21,
      "y": 9,
      "z": 0,
      "name": "Rock_Acid_Trunk_Light"
    },
    {
      "x": -21,
      "y": 10,
      "z": 0,
      "name": "Rock_Acid_Trunk_Light"
    },
    {
      "x": -21,
      "y": 11,
      "z": 0,
      "name": "Rock_Acid_Trunk_Medium"
    },
    {
      "x": -21,
      "y": 13,
      "z": 3,
      "name": "Rock_Acid_Trunk_Light"
    },
    {
      "x": -21,
      "y": 14,
      "z": 3,
      "name": "Rock_Acid_Trunk_Medium"
    },
    {
      "x": -21,
      "y": 15,
      "z": 3,
      "name": "Rock_Acid_Trunk_Medium"
    },
    {
      "x": -21,
      "y": 12,
      "z": 4,
      "name": "Rock_Acid_Trunk_Light"
    },
    {
      "x": -21,
      "y": 13,
      "z": 4,
      "name": "Rock_Acid_Trunk_Medium"
    },
    {
      "x": -21,
      "y": 14,
      "z": 4,
      "name": "Rock_Acid_Trunk_Medium"
    },
    {
      "x": -21,
      "y": 15,
      "z": 4,
      "name": "Rock_Acid_Trunk_Medium"
    },
    {
      "x": -21,
      "y": 16,
      "z": 4,
      "name": "Rock_Acid_Trunk_Standard"
    },
    {
      "x": -21,
      "y": 40,
      "z": 4,
      "name": "Rock_Acid_Trunk_Orange"
    },
    {
      "x": -21,
      "y": 41,
      "z": 4,
      "name": "Rock_Acid_Trunk_Orange"
    },
    {
      "x": -21,
      "y": 42,
      "z": 4,
      "name": "Rock_Acid_Trunk_Orange"
    },
    {
      "x": -21,
      "y": 43,
      "z": 4,
      "name": "Rock_Acid_Trunk_Orange"
    },
    {
      "x": -21,
      "y": 44,
      "z": 4,
      "name": "Rock_Acid_Trunk_Orange"
    },
    {
      "x": -21,
      "y": 45,
      "z": 4,
      "name": "Rock_Acid_Trunk_Orange"
    },
    {
      "x": -21,
      "y": 46,
      "z": 4,
      "name": "Rock_Acid_Trunk_Orange"
    },
    {
      "x": -21,
      "y": 47,
      "z": 4,
      "name": "Rock_Acid_Trunk_Orange"
    },
    {
      "x": -21,
      "y": 9,
      "z": 5,
      "name": "Rock_Acid_Trunk_Light"
    },
    {
      "x": -21,
      "y": 10,
      "z": 5,
      "name": "Rock_Acid_Trunk_Light"
    },
    {
      "x": -21,
      "y": 11,
      "z": 5,
      "name": "Rock_Acid_Trunk_Light"
    },
    {
      "x": -21,
      "y": 12,
      "z": 5,
      "name": "Rock_Acid_Trunk_Medium"
    },
    {
      "x": -21,
      "y": 13,
      "z": 5,
      "name": "Rock_Acid_Trunk_Medium"
    },
    {
      "x": -21,
      "y": 14,
      "z": 5,
      "name": "Rock_Acid_Trunk_Medium"
    },
    {
      "x": -21,
      "y": 15,
      "z": 5,
      "name": "Rock_Acid_Trunk_Medium"
    },
    {
      "x": -21,
      "y": 16,
      "z": 5,
      "name": "Rock_Acid_Trunk_Standard"
    },
    {
      "x": -21,
      "y": 37,
      "z": 5,
      "name": "Rock_Acid_Trunk_Bright"
    },
    {
      "x": -21,
      "y": 38,
      "z": 5,
      "name": "Rock_Acid_Trunk_Bright"
    },
    {
      "x": -21,
      "y": 39,
      "z": 5,
      "name": "Rock_Acid_Trunk_Bright"
    },
    {
      "x": -21,
      "y": 40,
      "z": 5,
      "name": "Rock_Acid_Trunk_Bright"
    },
    {
      "x": -21,
      "y": 41,
      "z": 5,
      "name": "Rock_Acid_Trunk_Orange"
    },
    {
      "x": -21,
      "y": 42,
      "z": 5,
      "name": "Rock_Acid_Trunk_Medium"
    },
    {
      "x": -21,
      "y": 43,
      "z": 5,
      "name": "Rock_Acid_Trunk_Medium"
    },
    {
      "x": -21,
      "y": 44,
      "z": 5,
      "name": "Rock_Acid_Trunk_Medium"
    },
    {
      "x": -21,
      "y": 45,
      "z": 5,
      "name": "Rock_Acid_Trunk_Medium"
    },
    {
      "x": -21,
      "y": 46,
      "z": 5,
      "name": "Rock_Acid_Trunk_Medium"
    },
    {
      "x": -21,
      "y": 47,
      "z": 5,
      "name": "Rock_Acid_Trunk_Medium"
    },
    {
      "x": -21,
      "y": 48,
      "z": 5,
      "name": "Rock_Acid_Trunk_Orange"
    },
    {
      "x": -21,
      "y": 49,
      "z": 5,
      "name": "Rock_Acid_Trunk_Orange"
    },
    {
      "x": -21,
      "y": 10,
      "z": 6,
      "name": "Rock_Acid_Trunk_Light"
    },
    {
      "x": -21,
      "y": 11,
      "z": 6,
      "name": "Rock_Acid_Trunk_Medium"
    },
    {
      "x": -21,
      "y": 12,
      "z": 6,
      "name": "Rock_Acid_Trunk_Medium"
    },
    {
      "x": -21,
      "y": 13,
      "z": 6,
      "name": "Rock_Acid_Trunk_Medium"
    },
    {
      "x": -21,
      "y": 14,
      "z": 6,
      "name": "Rock_Acid_Trunk_Medium"
    },
    {
      "x": -21,
      "y": 15,
      "z": 6,
      "name": "Rock_Acid_Trunk_Medium"
    },
    {
      "x": -21,
      "y": 16,
      "z": 6,
      "name": "Rock_Acid_Trunk_Medium"
    },
    {
      "x": -21,
      "y": 17,
      "z": 6,
      "name": "Rock_Acid_Trunk_Standard"
    },
    {
      "x": -21,
      "y": 35,
      "z": 6,
      "name": "Rock_Acid_Trunk_Bright"
    },
    {
      "x": -21,
      "y": 36,
      "z": 6,
      "name": "Rock_Acid_Trunk_Bright"
    },
    {
      "x": -21,
      "y": 37,
      "z": 6,
      "name": "Rock_Acid_Trunk_Bright"
    },
    {
      "x": -21,
      "y": 38,
      "z": 6,
      "name": "Rock_Acid_Trunk_Bright"
    },
    {
      "x": -21,
      "y": 39,
      "z": 6,
      "name": "Rock_Acid_Trunk_Bright"
    },
    {
      "x": -21,
      "y": 40,
      "z": 6,
      "name": "Rock_Acid_Trunk_Medium"
    },
    {
      "x": -21,
      "y": 41,
      "z": 6,
      "name": "Rock_Acid_Trunk_Medium"
    },
    {
      "x": -21,
      "y": 42,
      "z": 6,
      "name": "Rock_Acid_Trunk_Medium"
    },
    {
      "x": -21,
      "y": 43,
      "z": 6,
      "name": "Rock_Acid_Trunk_Medium"
    },
    {
      "x": -21,
      "y": 44,
      "z": 6,
      "name": "Rock_Acid_Trunk_Medium"
    },
    {
      "x": -21,
      "y": 45,
      "z": 6,
      "name": "Rock_Acid_Trunk_Medium"
    },
    {
      "x": -21,
      "y": 46,
      "z": 6,
      "name": "Rock_Acid_Trunk_Medium"
    },
    {
      "x": -21,
      "y": 47,
      "z": 6,
      "name": "Rock_Acid_Trunk_Medium"
    },
    {
      "x": -21,
      "y": 48,
      "z": 6,
      "name": "Rock_Acid_Trunk_Medium"
    },
    {
      "x": -21,
      "y": 49,
      "z": 6,
      "name": "Rock_Acid_Trunk_Medium"
    },
    {
      "x": -21,
      "y": 50,
      "z": 6,
      "name": "Rock_Acid_Trunk_Crimson"
    },
    {
      "x": -21,
      "y": 10,
      "z": 7,
      "name": "Rock_Acid_Trunk_Light"
    },
    {
      "x": -21,
      "y": 11,
      "z": 7,
      "name": "Rock_Acid_Trunk_Medium"
    },
    {
      "x": -21,
      "y": 12,
      "z": 7,
      "name": "Rock_Acid_Trunk_Medium"
    },
    {
      "x": -21,
      "y": 13,
      "z": 7,
      "name": "Rock_Acid_Trunk_Medium"
    },
    {
      "x": -21,
      "y": 14,
      "z": 7,
      "name": "Rock_Acid_Trunk_Medium"
    },
    {
      "x": -21,
      "y": 15,
      "z": 7,
      "name": "Rock_Acid_Trunk_Medium"
    },
    {
      "x": -21,
      "y": 16,
      "z": 7,
      "name": "Rock_Acid_Trunk_Medium"
    },
    {
      "x": -21,
      "y": 17,
      "z": 7,
      "name": "Rock_Acid_Trunk_Standard"
    },
    {
      "x": -21,
      "y": 33,
      "z": 7,
      "name": "Rock_Acid_Trunk_Medium"
    },
    {
      "x": -21,
      "y": 34,
      "z": 7,
      "name": "Rock_Acid_Trunk_Medium"
    },
    {
      "x": -21,
      "y": 35,
      "z": 7,
      "name": "Rock_Acid_Trunk_Medium"
    },
    {
      "x": -21,
      "y": 36,
      "z": 7,
      "name": "Rock_Acid_Trunk_Bright"
    },
    {
      "x": -21,
      "y": 37,
      "z": 7,
      "name": "Rock_Acid_Trunk_Bright"
    },
    {
      "x": -21,
      "y": 38,
      "z": 7,
      "name": "Rock_Acid_Trunk_Bright"
    },
    {
      "x": -21,
      "y": 39,
      "z": 7,
      "name": "Rock_Acid_Trunk_Medium"
    },
    {
      "x": -21,
      "y": 40,
      "z": 7,
      "name": "Rock_Acid_Trunk_Medium"
    },
    {
      "x": -21,
      "y": 41,
      "z": 7,
      "name": "Rock_Acid_Trunk_Medium"
    },
    {
      "x": -21,
      "y": 42,
      "z": 7,
      "name": "Rock_Acid_Trunk_Medium"
    },
    {
      "x": -21,
      "y": 43,
      "z": 7,
      "name": "Rock_Acid_Trunk_Medium"
    },
    {
      "x": -21,
      "y": 44,
      "z": 7,
      "name": "Rock_Acid_Trunk_Medium"
    },
    {
      "x": -21,
      "y": 45,
      "z": 7,
      "name": "Rock_Acid_Trunk_Medium"
    },
    {
      "x": -21,
      "y": 46,
      "z": 7,
      "name": "Rock_Acid_Trunk_Medium"
    },
    {
      "x": -21,
      "y": 47,
      "z": 7,
      "name": "Rock_Acid_Trunk_Medium"
    },
    {
      "x": -21,
      "y": 48,
      "z": 7,
      "name": "Rock_Acid_Trunk_Medium"
    },
    {
      "x": -21,
      "y": 49,
      "z": 7,
      "name": "Rock_Acid_Trunk_Medium"
    },
    {
      "x": -21,
      "y": 50,
      "z": 7,
      "name": "Rock_Acid_Trunk_Medium"
    },
    {
      "x": -21,
      "y": 51,
      "z": 7,
      "name": "Rock_Acid_Trunk_Crimson"
    },
    {
      "x": -21,
      "y": 52,
      "z": 7,
      "name": "Rock_Acid_Trunk_Crimson"
    },
    {
      "x": -21,
      "y": 11,
      "z": 8,
      "name": "Rock_Acid_Trunk_Light"
    },
    {
      "x": -21,
      "y": 12,
      "z": 8,
      "name": "Rock_Acid_Trunk_Medium"
    },
    {
      "x": -21,
      "y": 13,
      "z": 8,
      "name": "Rock_Acid_Trunk_Medium"
    },
    {
      "x": -21,
      "y": 14,
      "z": 8,
      "name": "Rock_Acid_Trunk_Medium"
    },
    {
      "x": -21,
      "y": 15,
      "z": 8,
      "name": "Rock_Acid_Trunk_Medium"
    },
    {
      "x": -21,
      "y": 16,
      "z": 8,
      "name": "Rock_Acid_Trunk_Medium"
    },
    {
      "x": -21,
      "y": 32,
      "z": 8,
      "name": "Rock_Acid_Trunk_Medium"
    },
    {
      "x": -21,
      "y": 33,
      "z": 8,
      "name": "Rock_Acid_Trunk_Medium"
    },
    {
      "x": -21,
      "y": 34,
      "z": 8,
      "name": "Rock_Acid_Trunk_Medium"
    },
    {
      "x": -21,
      "y": 35,
      "z": 8,
      "name": "Rock_Acid_Trunk_Medium"
    },
    {
      "x": -21,
      "y": 36,
      "z": 8,
      "name": "Rock_Acid_Trunk_Bright"
    },
    {
      "x": -21,
      "y": 37,
      "z": 8,
      "name": "Rock_Acid_Trunk_Bright"
    },
    {
      "x": -21,
      "y": 38,
      "z": 8,
      "name": "Rock_Acid_Trunk_Medium"
    },
    {
      "x": -21,
      "y": 39,
      "z": 8,
      "name": "Rock_Acid_Trunk_Medium"
    },
    {
      "x": -21,
      "y": 40,
      "z": 8,
      "name": "Rock_Acid_Trunk_Medium"
    },
    {
      "x": -21,
      "y": 41,
      "z": 8,
      "name": "Rock_Acid_Trunk_Medium"
    },
    {
      "x": -21,
      "y": 42,
      "z": 8,
      "name": "Rock_Acid_Trunk_Medium"
    },
    {
      "x": -21,
      "y": 43,
      "z": 8,
      "name": "Rock_Acid_Trunk_Medium"
    },
    {
      "x": -21,
      "y": 44,
      "z": 8,
      "name": "Rock_Acid_Trunk_Medium"
    },
    {
      "x": -21,
      "y": 45,
      "z": 8,
      "name": "Rock_Acid_Trunk_Medium"
    },
    {
      "x": -21,
      "y": 46,
      "z": 8,
      "name": "Rock_Acid_Trunk_Medium"
    },
    {
      "x": -21,
      "y": 47,
      "z": 8,
      "name": "Rock_Acid_Trunk_Medium"
    },
    {
      "x": -21,
      "y": 48,
      "z": 8,
      "name": "Rock_Acid_Trunk_Medium"
    },
    {
      "x": -21,
      "y": 49,
      "z": 8,
      "name": "Rock_Acid_Trunk_Medium"
    },
    {
      "x": -21,
      "y": 50,
      "z": 8,
      "name": "Rock_Acid_Trunk_Medium"
    },
    {
      "x": -21,
      "y": 51,
      "z": 8,
      "name": "Rock_Acid_Trunk_Magenta"
    },
    {
      "x": -21,
      "y": 12,
      "z": 9,
      "name": "Rock_Acid_Trunk_Light"
    },
    {
      "x": -21,
      "y": 13,
      "z": 9,
      "name": "Rock_Acid_Trunk_Light"
    },
    {
      "x": -21,
      "y": 14,
      "z": 9,
      "name": "Rock_Acid_Trunk_Medium"
    },
    {
      "x": -21,
      "y": 15,
      "z": 9,
      "name": "Rock_Acid_Trunk_Medium"
    },
    {
      "x": -21,
      "y": 32,
      "z": 9,
      "name": "Rock_Acid_Trunk_Bright"
    },
    {
      "x": -21,
      "y": 33,
      "z": 9,
      "name": "Rock_Acid_Trunk_Medium"
    },
    {
      "x": -21,
      "y": 34,
      "z": 9,
      "name": "Rock_Acid_Trunk_Medium"
    },
    {
      "x": -21,
      "y": 35,
      "z": 9,
      "name": "Rock_Acid_Trunk_Bright"
    },
    {
      "x": -21,
      "y": 36,
      "z": 9,
      "name": "Rock_Acid_Trunk_Bright"
    },
    {
      "x": -21,
      "y": 37,
      "z": 9,
      "name": "Rock_Acid_Trunk_Bright"
    },
    {
      "x": -21,
      "y": 38,
      "z": 9,
      "name": "Rock_Acid_Trunk_Bright"
    },
    {
      "x": -21,
      "y": 39,
      "z": 9,
      "name": "Rock_Acid_Trunk_Medium"
    },
    {
      "x": -21,
      "y": 40,
      "z": 9,
      "name": "Rock_Acid_Trunk_Medium"
    },
    {
      "x": -21,
      "y": 41,
      "z": 9,
      "name": "Rock_Acid_Trunk_Medium"
    },
    {
      "x": -21,
      "y": 42,
      "z": 9,
      "name": "Rock_Acid_Trunk_Medium"
    },
    {
      "x": -21,
      "y": 43,
      "z": 9,
      "name": "Rock_Acid_Trunk_Medium"
    },
    {
      "x": -21,
      "y": 44,
      "z": 9,
      "name": "Rock_Acid_Trunk_Medium"
    },
    {
      "x": -21,
      "y": 45,
      "z": 9,
      "name": "Rock_Acid_Trunk_Medium"
    },
    {
      "x": -21,
      "y": 46,
      "z": 9,
      "name": "Rock_Acid_Trunk_Medium"
    },
    {
      "x": -21,
      "y": 47,
      "z": 9,
      "name": "Rock_Acid_Trunk_Medium"
    },
    {
      "x": -21,
      "y": 48,
      "z": 9,
      "name": "Rock_Acid_Trunk_Medium"
    },
    {
      "x": -21,
      "y": 49,
      "z": 9,
      "name": "Rock_Acid_Trunk_Medium"
    },
    {
      "x": -21,
      "y": 50,
      "z": 9,
      "name": "Rock_Acid_Trunk_Crimson"
    },
    {
      "x": -21,
      "y": 34,
      "z": 10,
      "name": "Rock_Acid_Trunk_Bright"
    },
    {
      "x": -21,
      "y": 35,
      "z": 10,
      "name": "Rock_Acid_Trunk_Bright"
    },
    {
      "x": -21,
      "y": 36,
      "z": 10,
      "name": "Rock_Acid_Trunk_Bright"
    },
    {
      "x": -21,
      "y": 37,
      "z": 10,
      "name": "Rock_Acid_Trunk_Bright"
    },
    {
      "x": -21,
      "y": 38,
      "z": 10,
      "name": "Rock_Acid_Trunk_Bright"
    },
    {
      "x": -21,
      "y": 39,
      "z": 10,
      "name": "Rock_Acid_Trunk_Bright"
    },
    {
      "x": -21,
      "y": 40,
      "z": 10,
      "name": "Rock_Acid_Trunk_Medium"
    },
    {
      "x": -21,
      "y": 41,
      "z": 10,
      "name": "Rock_Acid_Trunk_Medium"
    },
    {
      "x": -21,
      "y": 42,
      "z": 10,
      "name": "Rock_Acid_Trunk_Medium"
    },
    {
      "x": -21,
      "y": 43,
      "z": 10,
      "name": "Rock_Acid_Trunk_Medium"
    },
    {
      "x": -21,
      "y": 44,
      "z": 10,
      "name": "Rock_Acid_Trunk_Medium"
    },
    {
      "x": -21,
      "y": 45,
      "z": 10,
      "name": "Rock_Acid_Trunk_Medium"
    },
    {
      "x": -21,
      "y": 46,
      "z": 10,
      "name": "Rock_Acid_Trunk_Medium"
    },
    {
      "x": -21,
      "y": 47,
      "z": 10,
      "name": "Rock_Acid_Trunk_Medium"
    },
    {
      "x": -21,
      "y": 48,
      "z": 10,
      "name": "Rock_Acid_Trunk_Bright"
    },
    {
      "x": -21,
      "y": 49,
      "z": 10,
      "name": "Rock_Acid_Trunk_Orange"
    },
    {
      "x": -21,
      "y": 50,
      "z": 10,
      "name": "Rock_Acid_Trunk_Crimson"
    },
    {
      "x": -21,
      "y": 37,
      "z": 11,
      "name": "Rock_Acid_Trunk_Bright"
    },
    {
      "x": -21,
      "y": 38,
      "z": 11,
      "name": "Rock_Acid_Trunk_Bright"
    },
    {
      "x": -21,
      "y": 39,
      "z": 11,
      "name": "Rock_Acid_Trunk_Orange"
    },
    {
      "x": -21,
      "y": 40,
      "z": 11,
      "name": "Rock_Acid_Trunk_Orange"
    },
    {
      "x": -21,
      "y": 41,
      "z": 11,
      "name": "Rock_Acid_Trunk_Orange"
    },
    {
      "x": -21,
      "y": 42,
      "z": 11,
      "name": "Rock_Acid_Trunk_Medium"
    },
    {
      "x": -21,
      "y": 43,
      "z": 11,
      "name": "Rock_Acid_Trunk_Medium"
    },
    {
      "x": -21,
      "y": 44,
      "z": 11,
      "name": "Rock_Acid_Trunk_Medium"
    },
    {
      "x": -21,
      "y": 45,
      "z": 11,
      "name": "Rock_Acid_Trunk_Medium"
    },
    {
      "x": -21,
      "y": 46,
      "z": 11,
      "name": "Rock_Acid_Trunk_Bright"
    },
    {
      "x": -21,
      "y": 47,
      "z": 11,
      "name": "Rock_Acid_Trunk_Bright"
    },
    {
      "x": -21,
      "y": 48,
      "z": 11,
      "name": "Rock_Acid_Trunk_Orange"
    },
    {
      "x": -21,
      "y": 49,
      "z": 11,
      "name": "Rock_Acid_Trunk_Orange"
    },
    {
      "x": -21,
      "y": 50,
      "z": 11,
      "name": "Rock_Acid_Trunk_Orange"
    },
    {
      "x": -21,
      "y": 38,
      "z": 12,
      "name": "Rock_Acid_Trunk_Orange"
    },
    {
      "x": -21,
      "y": 39,
      "z": 12,
      "name": "Rock_Acid_Trunk_Orange"
    },
    {
      "x": -21,
      "y": 40,
      "z": 12,
      "name": "Rock_Acid_Trunk_Orange"
    },
    {
      "x": -21,
      "y": 41,
      "z": 12,
      "name": "Rock_Acid_Trunk_Orange"
    },
    {
      "x": -21,
      "y": 42,
      "z": 12,
      "name": "Rock_Acid_Trunk_Orange"
    },
    {
      "x": -21,
      "y": 43,
      "z": 12,
      "name": "Rock_Acid_Trunk_Orange"
    },
    {
      "x": -21,
      "y": 44,
      "z": 12,
      "name": "Rock_Acid_Trunk_Orange"
    },
    {
      "x": -21,
      "y": 45,
      "z": 12,
      "name": "Rock_Acid_Trunk_Orange"
    },
    {
      "x": -21,
      "y": 46,
      "z": 12,
      "name": "Rock_Acid_Trunk_Orange"
    },
    {
      "x": -21,
      "y": 47,
      "z": 12,
      "name": "Rock_Acid_Trunk_Orange"
    },
    {
      "x": -21,
      "y": 48,
      "z": 12,
      "name": "Rock_Acid_Trunk_Bright"
    },
    {
      "x": -21,
      "y": 49,
      "z": 12,
      "name": "Rock_Acid_Trunk_Bright"
    },
    {
      "x": -21,
      "y": 39,
      "z": 13,
      "name": "Rock_Acid_Trunk_Orange"
    },
    {
      "x": -21,
      "y": 40,
      "z": 13,
      "name": "Rock_Acid_Trunk_Orange"
    },
    {
      "x": -21,
      "y": 41,
      "z": 13,
      "name": "Rock_Acid_Trunk_Orange"
    },
    {
      "x": -21,
      "y": 42,
      "z": 13,
      "name": "Rock_Acid_Trunk_Orange"
    },
    {
      "x": -21,
      "y": 43,
      "z": 13,
      "name": "Rock_Acid_Trunk_Bright"
    },
    {
      "x": -21,
      "y": 44,
      "z": 13,
      "name": "Rock_Acid_Trunk_Bright"
    },
    {
      "x": -21,
      "y": 45,
      "z": 13,
      "name": "Rock_Acid_Trunk_Orange"
    },
    {
      "x": -21,
      "y": 46,
      "z": 13,
      "name": "Rock_Acid_Trunk_Orange"
    },
    {
      "x": -21,
      "y": 47,
      "z": 13,
      "name": "Rock_Acid_Trunk_Bright"
    },
    {
      "x": -21,
      "y": 48,
      "z": 13,
      "name": "Rock_Acid_Trunk_Bright"
    },
    {
      "x": -21,
      "y": 10,
      "z": 14,
      "name": "Rock_Acid_Trunk_Light"
    },
    {
      "x": -21,
      "y": 11,
      "z": 14,
      "name": "Rock_Acid_Trunk_Light"
    },
    {
      "x": -21,
      "y": 12,
      "z": 14,
      "name": "Rock_Acid_Trunk_Medium"
    },
    {
      "x": -21,
      "y": 41,
      "z": 14,
      "name": "Rock_Acid_Trunk_Bright"
    },
    {
      "x": -21,
      "y": 42,
      "z": 14,
      "name": "Rock_Acid_Trunk_Bright"
    },
    {
      "x": -21,
      "y": 43,
      "z": 14,
      "name": "Rock_Acid_Trunk_Bright"
    },
    {
      "x": -21,
      "y": 44,
      "z": 14,
      "name": "Rock_Acid_Trunk_Bright"
    },
    {
      "x": -21,
      "y": 45,
      "z": 14,
      "name": "Rock_Acid_Trunk_Bright"
    },
    {
      "x": -21,
      "y": 46,
      "z": 14,
      "name": "Rock_Acid_Trunk_Orange"
    },
    {
      "x": -21,
      "y": 10,
      "z": 15,
      "name": "Rock_Acid_Trunk_Light"
    },
    {
      "x": -21,
      "y": 11,
      "z": 15,
      "name": "Rock_Acid_Trunk_Medium"
    },
    {
      "x": -21,
      "y": 12,
      "z": 15,
      "name": "Rock_Acid_Trunk_Medium"
    },
    {
      "x": -21,
      "y": 9,
      "z": 16,
      "name": "Rock_Acid_Trunk_Light"
    },
    {
      "x": -21,
      "y": 10,
      "z": 16,
      "name": "Rock_Acid_Trunk_Medium"
    },
    {
      "x": -21,
      "y": 11,
      "z": 16,
      "name": "Rock_Acid_Trunk_Medium"
    },
    {
      "x": -21,
      "y": 12,
      "z": 16,
      "name": "Rock_Acid_Trunk_Medium"
    },
    {
      "x": -21,
      "y": 13,
      "z": 16,
      "name": "Rock_Acid_Trunk_Medium"
    },
    {
      "x": -21,
      "y": 8,
      "z": 17,
      "name": "Rock_Acid_Trunk_Light"
    },
    {
      "x": -21,
      "y": 9,
      "z": 17,
      "name": "Rock_Acid_Trunk_Medium"
    },
    {
      "x": -21,
      "y": 10,
      "z": 17,
      "name": "Rock_Acid_Trunk_Medium"
    },
    {
      "x": -21,
      "y": 11,
      "z": 17,
      "name": "Rock_Acid_Trunk_Medium"
    },
    {
      "x": -21,
      "y": 12,
      "z": 17,
      "name": "Rock_Acid_Trunk_Medium"
    },
    {
      "x": -21,
      "y": 13,
      "z": 17,
      "name": "Rock_Acid_Trunk_Standard"
    },
    {
      "x": -21,
      "y": 8,
      "z": 18,
      "name": "Rock_Acid_Trunk_Light"
    },
    {
      "x": -21,
      "y": 9,
      "z": 18,
      "name": "Rock_Acid_Trunk_Medium"
    },
    {
      "x": -21,
      "y": 10,
      "z": 18,
      "name": "Rock_Acid_Trunk_Medium"
    },
    {
      "x": -21,
      "y": 11,
      "z": 18,
      "name": "Rock_Acid_Trunk_Medium"
    },
    {
      "x": -21,
      "y": 12,
      "z": 18,
      "name": "Rock_Acid_Trunk_Medium"
    },
    {
      "x": -21,
      "y": 13,
      "z": 18,
      "name": "Rock_Acid_Trunk_Medium"
    },
    {
      "x": -21,
      "y": 14,
      "z": 18,
      "name": "Rock_Acid_Trunk_Standard"
    },
    {
      "x": -21,
      "y": 9,
      "z": 19,
      "name": "Rock_Acid_Trunk_Light"
    },
    {
      "x": -21,
      "y": 10,
      "z": 19,
      "name": "Rock_Acid_Trunk_Medium"
    },
    {
      "x": -21,
      "y": 11,
      "z": 19,
      "name": "Rock_Acid_Trunk_Medium"
    },
    {
      "x": -21,
      "y": 12,
      "z": 19,
      "name": "Rock_Acid_Trunk_Medium"
    },
    {
      "x": -21,
      "y": 13,
      "z": 19,
      "name": "Rock_Acid_Trunk_Standard"
    },
    {
      "x": -21,
      "y": 10,
      "z": 20,
      "name": "Rock_Acid_Trunk_Medium"
    },
    {
      "x": -21,
      "y": 11,
      "z": 20,
      "name": "Rock_Acid_Trunk_Light"
    },
    {
      "x": -21,
      "y": 12,
      "z": 20,
      "name": "Rock_Acid_Trunk_Medium"
    },
    {
      "x": -20,
      "y": 11,
      "z": -29,
      "name": "Rock_Acid_Trunk_Light"
    },
    {
      "x": -20,
      "y": 11,
      "z": -28,
      "name": "Rock_Acid_Trunk_Light"
    },
    {
      "x": -20,
      "y": 11,
      "z": -27,
      "name": "Rock_Acid_Trunk_Light"
    },
    {
      "x": -20,
      "y": 12,
      "z": -27,
      "name": "Rock_Acid_Trunk_Light"
    },
    {
      "x": -20,
      "y": 12,
      "z": -26,
      "name": "Rock_Acid_Trunk_Light"
    },
    {
      "x": -20,
      "y": 12,
      "z": -25,
      "name": "Rock_Acid_Trunk_Light"
    },
    {
      "x": -20,
      "y": 8,
      "z": -4,
      "name": "Rock_Acid_Trunk_Light"
    },
    {
      "x": -20,
      "y": 7,
      "z": -3,
      "name": "Rock_Acid_Trunk_Light"
    },
    {
      "x": -20,
      "y": 8,
      "z": -3,
      "name": "Rock_Acid_Trunk_Medium"
    },
    {
      "x": -20,
      "y": 9,
      "z": -3,
      "name": "Rock_Acid_Trunk_Light"
    },
    {
      "x": -20,
      "y": 10,
      "z": -3,
      "name": "Rock_Acid_Trunk_Medium"
    },
    {
      "x": -20,
      "y": 11,
      "z": -3,
      "name": "Rock_Acid_Trunk_Medium"
    },
    {
      "x": -20,
      "y": 7,
      "z": -2,
      "name": "Rock_Acid_Trunk_Light"
    },
    {
      "x": -20,
      "y": 8,
      "z": -2,
      "name": "Rock_Acid_Trunk_Medium"
    },
    {
      "x": -20,
      "y": 9,
      "z": -2,
      "name": "Rock_Acid_Trunk_Medium"
    },
    {
      "x": -20,
      "y": 10,
      "z": -2,
      "name": "Rock_Acid_Trunk_Medium"
    },
    {
      "x": -20,
      "y": 11,
      "z": -2,
      "name": "Rock_Acid_Trunk_Medium"
    },
    {
      "x": -20,
      "y": 12,
      "z": -2,
      "name": "Rock_Acid_Trunk_Standard"
    },
    {
      "x": -20,
      "y": 7,
      "z": -1,
      "name": "Rock_Acid_Trunk_Light"
    },
    {
      "x": -20,
      "y": 8,
      "z": -1,
      "name": "Rock_Acid_Trunk_Medium"
    },
    {
      "x": -20,
      "y": 9,
      "z": -1,
      "name": "Rock_Acid_Trunk_Medium"
    },
    {
      "x": -20,
      "y": 10,
      "z": -1,
      "name": "Rock_Acid_Trunk_Medium"
    },
    {
      "x": -20,
      "y": 11,
      "z": -1,
      "name": "Rock_Acid_Trunk_Medium"
    },
    {
      "x": -20,
      "y": 12,
      "z": -1,
      "name": "Rock_Acid_Trunk_Standard"
    },
    {
      "x": -20,
      "y": 8,
      "z": 0,
      "name": "Rock_Acid_Trunk_Light"
    },
    {
      "x": -20,
      "y": 9,
      "z": 0,
      "name": "Rock_Acid_Trunk_Medium"
    },
    {
      "x": -20,
      "y": 10,
      "z": 0,
      "name": "Rock_Acid_Trunk_Medium"
    },
    {
      "x": -20,
      "y": 11,
      "z": 0,
      "name": "Rock_Acid_Trunk_Medium"
    },
    {
      "x": -20,
      "y": 12,
      "z": 0,
      "name": "Rock_Acid_Trunk_Medium"
    },
    {
      "x": -20,
      "y": 13,
      "z": 0,
      "name": "Rock_Acid_Trunk_Medium"
    },
    {
      "x": -20,
      "y": 9,
      "z": 1,
      "name": "Rock_Acid_Trunk_Light"
    },
    {
      "x": -20,
      "y": 10,
      "z": 1,
      "name": "Rock_Acid_Trunk_Light"
    },
    {
      "x": -20,
      "y": 11,
      "z": 1,
      "name": "Rock_Acid_Trunk_Light"
    },
    {
      "x": -20,
      "y": 12,
      "z": 1,
      "name": "Rock_Acid_Trunk_Medium"
    },
    {
      "x": -20,
      "y": 13,
      "z": 1,
      "name": "Rock_Acid_Trunk_Medium"
    },
    {
      "x": -20,
      "y": 14,
      "z": 1,
      "name": "Rock_Acid_Trunk_Medium"
    },
    {
      "x": -20,
      "y": 8,
      "z": 2,
      "name": "Rock_Acid_Trunk_Light"
    },
    {
      "x": -20,
      "y": 9,
      "z": 2,
      "name": "Rock_Acid_Trunk_Light"
    },
    {
      "x": -20,
      "y": 10,
      "z": 2,
      "name": "Rock_Acid_Trunk_Light"
    },
    {
      "x": -20,
      "y": 11,
      "z": 2,
      "name": "Rock_Acid_Trunk_Light"
    },
    {
      "x": -20,
      "y": 12,
      "z": 2,
      "name": "Rock_Acid_Trunk_Light"
    },
    {
      "x": -20,
      "y": 13,
      "z": 2,
      "name": "Rock_Acid_Trunk_Light"
    },
    {
      "x": -20,
      "y": 14,
      "z": 2,
      "name": "Rock_Acid_Trunk_Medium"
    },
    {
      "x": -20,
      "y": 15,
      "z": 2,
      "name": "Rock_Acid_Trunk_Medium"
    },
    {
      "x": -20,
      "y": 8,
      "z": 3,
      "name": "Rock_Acid_Trunk_Light"
    },
    {
      "x": -20,
      "y": 9,
      "z": 3,
      "name": "Rock_Acid_Trunk_Light"
    },
    {
      "x": -20,
      "y": 10,
      "z": 3,
      "name": "Rock_Acid_Trunk_Light"
    },
    {
      "x": -20,
      "y": 11,
      "z": 3,
      "name": "Rock_Acid_Trunk_Light"
    },
    {
      "x": -20,
      "y": 12,
      "z": 3,
      "name": "Rock_Acid_Trunk_Light"
    },
    {
      "x": -20,
      "y": 13,
      "z": 3,
      "name": "Rock_Acid_Trunk_Medium"
    },
    {
      "x": -20,
      "y": 14,
      "z": 3,
      "name": "Rock_Acid_Trunk_Medium"
    },
    {
      "x": -20,
      "y": 15,
      "z": 3,
      "name": "Rock_Acid_Trunk_Medium"
    },
    {
      "x": -20,
      "y": 16,
      "z": 3,
      "name": "Rock_Acid_Trunk_Medium"
    },
    {
      "x": -20,
      "y": 41,
      "z": 3,
      "name": "Rock_Acid_Trunk_Orange"
    },
    {
      "x": -20,
      "y": 42,
      "z": 3,
      "name": "Rock_Acid_Trunk_Bright"
    },
    {
      "x": -20,
      "y": 43,
      "z": 3,
      "name": "Rock_Acid_Trunk_Bright"
    },
    {
      "x": -20,
      "y": 44,
      "z": 3,
      "name": "Rock_Acid_Trunk_Bright"
    },
    {
      "x": -20,
      "y": 45,
      "z": 3,
      "name": "Rock_Acid_Trunk_Bright"
    },
    {
      "x": -20,
      "y": 8,
      "z": 4,
      "name": "Rock_Acid_Trunk_Light"
    },
    {
      "x": -20,
      "y": 9,
      "z": 4,
      "name": "Rock_Acid_Trunk_Light"
    },
    {
      "x": -20,
      "y": 10,
      "z": 4,
      "name": "Rock_Acid_Trunk_Light"
    },
    {
      "x": -20,
      "y": 11,
      "z": 4,
      "name": "Rock_Acid_Trunk_Light"
    },
    {
      "x": -20,
      "y": 12,
      "z": 4,
      "name": "Rock_Acid_Trunk_Medium"
    },
    {
      "x": -20,
      "y": 13,
      "z": 4,
      "name": "Rock_Acid_Trunk_Medium"
    },
    {
      "x": -20,
      "y": 14,
      "z": 4,
      "name": "Rock_Acid_Trunk_Medium"
    },
    {
      "x": -20,
      "y": 15,
      "z": 4,
      "name": "Rock_Acid_Trunk_Medium"
    },
    {
      "x": -20,
      "y": 16,
      "z": 4,
      "name": "Rock_Acid_Trunk_Medium"
    },
    {
      "x": -20,
      "y": 17,
      "z": 4,
      "name": "Rock_Acid_Trunk_Medium"
    },
    {
      "x": -20,
      "y": 34,
      "z": 4,
      "name": "Rock_Acid_Trunk_Bright"
    },
    {
      "x": -20,
      "y": 35,
      "z": 4,
      "name": "Rock_Acid_Trunk_Bright"
    },
    {
      "x": -20,
      "y": 36,
      "z": 4,
      "name": "Rock_Acid_Trunk_Bright"
    },
    {
      "x": -20,
      "y": 37,
      "z": 4,
      "name": "Rock_Acid_Trunk_Bright"
    },
    {
      "x": -20,
      "y": 38,
      "z": 4,
      "name": "Rock_Acid_Trunk_Bright"
    },
    {
      "x": -20,
      "y": 39,
      "z": 4,
      "name": "Rock_Acid_Trunk_Orange"
    },
    {
      "x": -20,
      "y": 40,
      "z": 4,
      "name": "Rock_Acid_Trunk_Orange"
    },
    {
      "x": -20,
      "y": 41,
      "z": 4,
      "name": "Rock_Acid_Trunk_Medium"
    },
    {
      "x": -20,
      "y": 42,
      "z": 4,
      "name": "Rock_Acid_Trunk_Medium"
    },
    {
      "x": -20,
      "y": 43,
      "z": 4,
      "name": "Rock_Acid_Trunk_Medium"
    },
    {
      "x": -20,
      "y": 44,
      "z": 4,
      "name": "Rock_Acid_Trunk_Medium"
    },
    {
      "x": -20,
      "y": 45,
      "z": 4,
      "name": "Rock_Acid_Trunk_Medium"
    },
    {
      "x": -20,
      "y": 46,
      "z": 4,
      "name": "Rock_Acid_Trunk_Bright"
    },
    {
      "x": -20,
      "y": 47,
      "z": 4,
      "name": "Rock_Acid_Trunk_Orange"
    },
    {
      "x": -20,
      "y": 48,
      "z": 4,
      "name": "Rock_Acid_Trunk_Orange"
    },
    {
      "x": -20,
      "y": 49,
      "z": 4,
      "name": "Rock_Acid_Trunk_Orange"
    },
    {
      "x": -20,
      "y": 8,
      "z": 5,
      "name": "Rock_Acid_Trunk_Light"
    },
    {
      "x": -20,
      "y": 9,
      "z": 5,
      "name": "Rock_Acid_Trunk_Light"
    },
    {
      "x": -20,
      "y": 10,
      "z": 5,
      "name": "Rock_Acid_Trunk_Medium"
    },
    {
      "x": -20,
      "y": 11,
      "z": 5,
      "name": "Rock_Acid_Trunk_Medium"
    },
    {
      "x": -20,
      "y": 12,
      "z": 5,
      "name": "Rock_Acid_Trunk_Medium"
    },
    {
      "x": -20,
      "y": 13,
      "z": 5,
      "name": "Rock_Acid_Trunk_Medium"
    },
    {
      "x": -20,
      "y": 14,
      "z": 5,
      "name": "Rock_Acid_Trunk_Medium"
    },
    {
      "x": -20,
      "y": 15,
      "z": 5,
      "name": "Rock_Acid_Trunk_Medium"
    },
    {
      "x": -20,
      "y": 16,
      "z": 5,
      "name": "Rock_Acid_Trunk_Medium"
    },
    {
      "x": -20,
      "y": 17,
      "z": 5,
      "name": "Rock_Acid_Trunk_Standard"
    },
    {
      "x": -20,
      "y": 31,
      "z": 5,
      "name": "Rock_Acid_Trunk_Bright"
    },
    {
      "x": -20,
      "y": 32,
      "z": 5,
      "name": "Rock_Acid_Trunk_Bright"
    },
    {
      "x": -20,
      "y": 33,
      "z": 5,
      "name": "Rock_Acid_Trunk_Bright"
    },
    {
      "x": -20,
      "y": 34,
      "z": 5,
      "name": "Rock_Acid_Trunk_Bright"
    },
    {
      "x": -20,
      "y": 35,
      "z": 5,
      "name": "Rock_Acid_Trunk_Bright"
    },
    {
      "x": -20,
      "y": 36,
      "z": 5,
      "name": "Rock_Acid_Trunk_Bright"
    },
    {
      "x": -20,
      "y": 37,
      "z": 5,
      "name": "Rock_Acid_Trunk_Medium"
    },
    {
      "x": -20,
      "y": 38,
      "z": 5,
      "name": "Rock_Acid_Trunk_Medium"
    },
    {
      "x": -20,
      "y": 39,
      "z": 5,
      "name": "Rock_Acid_Trunk_Medium"
    },
    {
      "x": -20,
      "y": 40,
      "z": 5,
      "name": "Rock_Acid_Trunk_Medium"
    },
    {
      "x": -20,
      "y": 41,
      "z": 5,
      "name": "Rock_Acid_Trunk_Medium"
    },
    {
      "x": -20,
      "y": 42,
      "z": 5,
      "name": "Rock_Acid_Trunk_Medium"
    },
    {
      "x": -20,
      "y": 43,
      "z": 5,
      "name": "Rock_Acid_Trunk_Medium"
    },
    {
      "x": -20,
      "y": 44,
      "z": 5,
      "name": "Rock_Acid_Trunk_Medium"
    },
    {
      "x": -20,
      "y": 45,
      "z": 5,
      "name": "Rock_Acid_Trunk_Medium"
    },
    {
      "x": -20,
      "y": 46,
      "z": 5,
      "name": "Rock_Acid_Trunk_Medium"
    },
    {
      "x": -20,
      "y": 47,
      "z": 5,
      "name": "Rock_Acid_Trunk_Medium"
    },
    {
      "x": -20,
      "y": 48,
      "z": 5,
      "name": "Rock_Acid_Trunk_Medium"
    },
    {
      "x": -20,
      "y": 49,
      "z": 5,
      "name": "Rock_Acid_Trunk_Medium"
    },
    {
      "x": -20,
      "y": 50,
      "z": 5,
      "name": "Rock_Acid_Trunk_Crimson"
    },
    {
      "x": -20,
      "y": 10,
      "z": 6,
      "name": "Rock_Acid_Trunk_Light"
    },
    {
      "x": -20,
      "y": 11,
      "z": 6,
      "name": "Rock_Acid_Trunk_Medium"
    },
    {
      "x": -20,
      "y": 12,
      "z": 6,
      "name": "Rock_Acid_Trunk_Medium"
    },
    {
      "x": -20,
      "y": 13,
      "z": 6,
      "name": "Rock_Acid_Trunk_Medium"
    },
    {
      "x": -20,
      "y": 14,
      "z": 6,
      "name": "Rock_Acid_Trunk_Medium"
    },
    {
      "x": -20,
      "y": 15,
      "z": 6,
      "name": "Rock_Acid_Trunk_Medium"
    },
    {
      "x": -20,
      "y": 16,
      "z": 6,
      "name": "Rock_Acid_Trunk_Medium"
    },
    {
      "x": -20,
      "y": 17,
      "z": 6,
      "name": "Rock_Acid_Trunk_Medium"
    },
    {
      "x": -20,
      "y": 18,
      "z": 6,
      "name": "Rock_Acid_Trunk_Standard"
    },
    {
      "x": -20,
      "y": 30,
      "z": 6,
      "name": "Rock_Acid_Trunk_Bright"
    },
    {
      "x": -20,
      "y": 31,
      "z": 6,
      "name": "Rock_Acid_Trunk_Bright"
    },
    {
      "x": -20,
      "y": 32,
      "z": 6,
      "name": "Rock_Acid_Trunk_Bright"
    },
    {
      "x": -20,
      "y": 33,
      "z": 6,
      "name": "Rock_Acid_Trunk_Medium"
    },
    {
      "x": -20,
      "y": 34,
      "z": 6,
      "name": "Rock_Acid_Trunk_Medium"
    },
    {
      "x": -20,
      "y": 35,
      "z": 6,
      "name": "Rock_Acid_Trunk_Medium"
    },
    {
      "x": -20,
      "y": 36,
      "z": 6,
      "name": "Rock_Acid_Trunk_Medium"
    },
    {
      "x": -20,
      "y": 37,
      "z": 6,
      "name": "Rock_Acid_Trunk_Medium"
    },
    {
      "x": -20,
      "y": 38,
      "z": 6,
      "name": "Rock_Acid_Trunk_Medium"
    },
    {
      "x": -20,
      "y": 39,
      "z": 6,
      "name": "Rock_Acid_Trunk_Medium"
    },
    {
      "x": -20,
      "y": 40,
      "z": 6,
      "name": "Rock_Acid_Trunk_Medium"
    },
    {
      "x": -20,
      "y": 41,
      "z": 6,
      "name": "Rock_Acid_Trunk_Medium"
    },
    {
      "x": -20,
      "y": 42,
      "z": 6,
      "name": "Rock_Acid_Trunk_Medium"
    },
    {
      "x": -20,
      "y": 43,
      "z": 6,
      "name": "Rock_Acid_Trunk_Medium"
    },
    {
      "x": -20,
      "y": 44,
      "z": 6,
      "name": "Rock_Acid_Trunk_Medium"
    },
    {
      "x": -20,
      "y": 45,
      "z": 6,
      "name": "Rock_Acid_Trunk_Medium"
    },
    {
      "x": -20,
      "y": 46,
      "z": 6,
      "name": "Rock_Acid_Trunk_Medium"
    },
    {
      "x": -20,
      "y": 47,
      "z": 6,
      "name": "Rock_Acid_Trunk_Medium"
    },
    {
      "x": -20,
      "y": 48,
      "z": 6,
      "name": "Rock_Acid_Trunk_Medium"
    },
    {
      "x": -20,
      "y": 49,
      "z": 6,
      "name": "Rock_Acid_Trunk_Medium"
    },
    {
      "x": -20,
      "y": 50,
      "z": 6,
      "name": "Rock_Acid_Trunk_Medium"
    },
    {
      "x": -20,
      "y": 51,
      "z": 6,
      "name": "Rock_Acid_Trunk_Crimson"
    },
    {
      "x": -20,
      "y": 52,
      "z": 6,
      "name": "Rock_Acid_Trunk_Magenta"
    },
    {
      "x": -20,
      "y": 10,
      "z": 7,
      "name": "Rock_Acid_Trunk_Light"
    },
    {
      "x": -20,
      "y": 11,
      "z": 7,
      "name": "Rock_Acid_Trunk_Medium"
    },
    {
      "x": -20,
      "y": 12,
      "z": 7,
      "name": "Rock_Acid_Trunk_Medium"
    },
    {
      "x": -20,
      "y": 13,
      "z": 7,
      "name": "Rock_Acid_Trunk_Medium"
    },
    {
      "x": -20,
      "y": 14,
      "z": 7,
      "name": "Rock_Acid_Trunk_Medium"
    },
    {
      "x": -20,
      "y": 15,
      "z": 7,
      "name": "Rock_Acid_Trunk_Medium"
    },
    {
      "x": -20,
      "y": 16,
      "z": 7,
      "name": "Rock_Acid_Trunk_Medium"
    },
    {
      "x": -20,
      "y": 17,
      "z": 7,
      "name": "Rock_Acid_Trunk_Medium"
    },
    {
      "x": -20,
      "y": 18,
      "z": 7,
      "name": "Rock_Acid_Trunk_Medium"
    },
    {
      "x": -20,
      "y": 28,
      "z": 7,
      "name": "Rock_Acid_Trunk_Medium"
    },
    {
      "x": -20,
      "y": 29,
      "z": 7,
      "name": "Rock_Acid_Trunk_Bright"
    },
    {
      "x": -20,
      "y": 30,
      "z": 7,
      "name": "Rock_Acid_Trunk_Bright"
    },
    {
      "x": -20,
      "y": 31,
      "z": 7,
      "name": "Rock_Acid_Trunk_Bright"
    },
    {
      "x": -20,
      "y": 32,
      "z": 7,
      "name": "Rock_Acid_Trunk_Medium"
    },
    {
      "x": -20,
      "y": 33,
      "z": 7,
      "name": "Rock_Acid_Trunk_Medium"
    },
    {
      "x": -20,
      "y": 34,
      "z": 7,
      "name": "Rock_Acid_Trunk_Medium"
    },
    {
      "x": -20,
      "y": 35,
      "z": 7,
      "name": "Rock_Acid_Trunk_Medium"
    },
    {
      "x": -20,
      "y": 36,
      "z": 7,
      "name": "Rock_Acid_Trunk_Medium"
    },
    {
      "x": -20,
      "y": 37,
      "z": 7,
      "name": "Rock_Acid_Trunk_Medium"
    },
    {
      "x": -20,
      "y": 38,
      "z": 7,
      "name": "Rock_Acid_Trunk_Medium"
    },
    {
      "x": -20,
      "y": 39,
      "z": 7,
      "name": "Rock_Acid_Trunk_Medium"
    },
    {
      "x": -20,
      "y": 40,
      "z": 7,
      "name": "Rock_Acid_Trunk_Medium"
    },
    {
      "x": -20,
      "y": 41,
      "z": 7,
      "name": "Rock_Acid_Trunk_Medium"
    },
    {
      "x": -20,
      "y": 42,
      "z": 7,
      "name": "Rock_Acid_Trunk_Medium"
    },
    {
      "x": -20,
      "y": 43,
      "z": 7,
      "name": "Rock_Acid_Trunk_Medium"
    },
    {
      "x": -20,
      "y": 44,
      "z": 7,
      "name": "Rock_Acid_Trunk_Medium"
    },
    {
      "x": -20,
      "y": 45,
      "z": 7,
      "name": "Rock_Acid_Trunk_Medium"
    },
    {
      "x": -20,
      "y": 46,
      "z": 7,
      "name": "Rock_Acid_Trunk_Medium"
    },
    {
      "x": -20,
      "y": 47,
      "z": 7,
      "name": "Rock_Acid_Trunk_Medium"
    },
    {
      "x": -20,
      "y": 48,
      "z": 7,
      "name": "Rock_Acid_Trunk_Medium"
    },
    {
      "x": -20,
      "y": 49,
      "z": 7,
      "name": "Rock_Acid_Trunk_Medium"
    },
    {
      "x": -20,
      "y": 50,
      "z": 7,
      "name": "Rock_Acid_Trunk_Crimson"
    },
    {
      "x": -20,
      "y": 51,
      "z": 7,
      "name": "Empty"
    },
    {
      "x": -20,
      "y": 52,
      "z": 7,
      "name": "Rock_Acid_Trunk_Crimson"
    },
    {
      "x": -20,
      "y": 53,
      "z": 7,
      "name": "Rock_Acid_Trunk_Magenta"
    },
    {
      "x": -20,
      "y": 11,
      "z": 8,
      "name": "Rock_Acid_Trunk_Light"
    },
    {
      "x": -20,
      "y": 12,
      "z": 8,
      "name": "Rock_Acid_Trunk_Medium"
    },
    {
      "x": -20,
      "y": 13,
      "z": 8,
      "name": "Rock_Acid_Trunk_Medium"
    },
    {
      "x": -20,
      "y": 14,
      "z": 8,
      "name": "Rock_Acid_Trunk_Medium"
    },
    {
      "x": -20,
      "y": 15,
      "z": 8,
      "name": "Rock_Acid_Trunk_Medium"
    },
    {
      "x": -20,
      "y": 16,
      "z": 8,
      "name": "Rock_Acid_Trunk_Medium"
    },
    {
      "x": -20,
      "y": 17,
      "z": 8,
      "name": "Rock_Acid_Trunk_Medium"
    },
    {
      "x": -20,
      "y": 27,
      "z": 8,
      "name": "Rock_Acid_Trunk_Bright"
    },
    {
      "x": -20,
      "y": 28,
      "z": 8,
      "name": "Rock_Acid_Trunk_Bright"
    },
    {
      "x": -20,
      "y": 29,
      "z": 8,
      "name": "Rock_Acid_Trunk_Bright"
    },
    {
      "x": -20,
      "y": 30,
      "z": 8,
      "name": "Rock_Acid_Trunk_Bright"
    },
    {
      "x": -20,
      "y": 31,
      "z": 8,
      "name": "Rock_Acid_Trunk_Bright"
    },
    {
      "x": -20,
      "y": 32,
      "z": 8,
      "name": "Rock_Acid_Trunk_Medium"
    },
    {
      "x": -20,
      "y": 33,
      "z": 8,
      "name": "Rock_Acid_Trunk_Medium"
    },
    {
      "x": -20,
      "y": 34,
      "z": 8,
      "name": "Rock_Acid_Trunk_Medium"
    },
    {
      "x": -20,
      "y": 35,
      "z": 8,
      "name": "Rock_Acid_Trunk_Medium"
    },
    {
      "x": -20,
      "y": 36,
      "z": 8,
      "name": "Rock_Acid_Trunk_Medium"
    },
    {
      "x": -20,
      "y": 37,
      "z": 8,
      "name": "Rock_Acid_Trunk_Medium"
    },
    {
      "x": -20,
      "y": 38,
      "z": 8,
      "name": "Rock_Acid_Trunk_Medium"
    },
    {
      "x": -20,
      "y": 39,
      "z": 8,
      "name": "Rock_Acid_Trunk_Medium"
    },
    {
      "x": -20,
      "y": 40,
      "z": 8,
      "name": "Rock_Acid_Trunk_Medium"
    },
    {
      "x": -20,
      "y": 41,
      "z": 8,
      "name": "Rock_Acid_Trunk_Medium"
    },
    {
      "x": -20,
      "y": 42,
      "z": 8,
      "name": "Rock_Acid_Trunk_Medium"
    },
    {
      "x": -20,
      "y": 43,
      "z": 8,
      "name": "Rock_Acid_Trunk_Medium"
    },
    {
      "x": -20,
      "y": 44,
      "z": 8,
      "name": "Rock_Acid_Trunk_Medium"
    },
    {
      "x": -20,
      "y": 45,
      "z": 8,
      "name": "Rock_Acid_Trunk_Medium"
    },
    {
      "x": -20,
      "y": 46,
      "z": 8,
      "name": "Rock_Acid_Trunk_Medium"
    },
    {
      "x": -20,
      "y": 47,
      "z": 8,
      "name": "Rock_Acid_Trunk_Medium"
    },
    {
      "x": -20,
      "y": 48,
      "z": 8,
      "name": "Rock_Acid_Trunk_Medium"
    },
    {
      "x": -20,
      "y": 49,
      "z": 8,
      "name": "Rock_Acid_Trunk_Medium"
    },
    {
      "x": -20,
      "y": 50,
      "z": 8,
      "name": "Rock_Acid_Trunk_Crimson"
    },
    {
      "x": -20,
      "y": 51,
      "z": 8,
      "name": "Empty"
    },
    {
      "x": -20,
      "y": 11,
      "z": 9,
      "name": "Rock_Acid_Trunk_Light"
    },
    {
      "x": -20,
      "y": 12,
      "z": 9,
      "name": "Rock_Acid_Trunk_Medium"
    },
    {
      "x": -20,
      "y": 13,
      "z": 9,
      "name": "Rock_Acid_Trunk_Medium"
    },
    {
      "x": -20,
      "y": 14,
      "z": 9,
      "name": "Rock_Acid_Trunk_Medium"
    },
    {
      "x": -20,
      "y": 15,
      "z": 9,
      "name": "Rock_Acid_Trunk_Medium"
    },
    {
      "x": -20,
      "y": 16,
      "z": 9,
      "name": "Rock_Acid_Trunk_Medium"
    },
    {
      "x": -20,
      "y": 27,
      "z": 9,
      "name": "Rock_Acid_Trunk_Bright"
    },
    {
      "x": -20,
      "y": 28,
      "z": 9,
      "name": "Rock_Acid_Trunk_Bright"
    },
    {
      "x": -20,
      "y": 29,
      "z": 9,
      "name": "Rock_Acid_Trunk_Bright"
    },
    {
      "x": -20,
      "y": 30,
      "z": 9,
      "name": "Rock_Acid_Trunk_Bright"
    },
    {
      "x": -20,
      "y": 31,
      "z": 9,
      "name": "Rock_Acid_Trunk_Bright"
    },
    {
      "x": -20,
      "y": 32,
      "z": 9,
      "name": "Rock_Acid_Trunk_Medium"
    },
    {
      "x": -20,
      "y": 33,
      "z": 9,
      "name": "Rock_Acid_Trunk_Medium"
    },
    {
      "x": -20,
      "y": 34,
      "z": 9,
      "name": "Rock_Acid_Trunk_Medium"
    },
    {
      "x": -20,
      "y": 35,
      "z": 9,
      "name": "Rock_Acid_Trunk_Medium"
    },
    {
      "x": -20,
      "y": 36,
      "z": 9,
      "name": "Rock_Acid_Trunk_Medium"
    },
    {
      "x": -20,
      "y": 37,
      "z": 9,
      "name": "Rock_Acid_Trunk_Medium"
    },
    {
      "x": -20,
      "y": 38,
      "z": 9,
      "name": "Rock_Acid_Trunk_Medium"
    },
    {
      "x": -20,
      "y": 39,
      "z": 9,
      "name": "Rock_Acid_Trunk_Medium"
    },
    {
      "x": -20,
      "y": 40,
      "z": 9,
      "name": "Rock_Acid_Trunk_Medium"
    },
    {
      "x": -20,
      "y": 41,
      "z": 9,
      "name": "Rock_Acid_Trunk_Medium"
    },
    {
      "x": -20,
      "y": 42,
      "z": 9,
      "name": "Rock_Acid_Trunk_Medium"
    },
    {
      "x": -20,
      "y": 43,
      "z": 9,
      "name": "Rock_Acid_Trunk_Medium"
    },
    {
      "x": -20,
      "y": 44,
      "z": 9,
      "name": "Rock_Acid_Trunk_Medium"
    },
    {
      "x": -20,
      "y": 45,
      "z": 9,
      "name": "Rock_Acid_Trunk_Medium"
    },
    {
      "x": -20,
      "y": 46,
      "z": 9,
      "name": "Rock_Acid_Trunk_Medium"
    },
    {
      "x": -20,
      "y": 47,
      "z": 9,
      "name": "Rock_Acid_Trunk_Medium"
    },
    {
      "x": -20,
      "y": 48,
      "z": 9,
      "name": "Rock_Acid_Trunk_Medium"
    },
    {
      "x": -20,
      "y": 49,
      "z": 9,
      "name": "Rock_Acid_Trunk_Medium"
    },
    {
      "x": -20,
      "y": 50,
      "z": 9,
      "name": "Rock_Acid_Trunk_Medium"
    },
    {
      "x": -20,
      "y": 51,
      "z": 9,
      "name": "Rock_Acid_Trunk_Magenta"
    },
    {
      "x": -20,
      "y": 11,
      "z": 10,
      "name": "Rock_Acid_Trunk_Light"
    },
    {
      "x": -20,
      "y": 12,
      "z": 10,
      "name": "Rock_Acid_Trunk_Light"
    },
    {
      "x": -20,
      "y": 13,
      "z": 10,
      "name": "Rock_Acid_Trunk_Light"
    },
    {
      "x": -20,
      "y": 14,
      "z": 10,
      "name": "Rock_Acid_Trunk_Medium"
    },
    {
      "x": -20,
      "y": 15,
      "z": 10,
      "name": "Rock_Acid_Trunk_Medium"
    },
    {
      "x": -20,
      "y": 28,
      "z": 10,
      "name": "Rock_Acid_Trunk_Bright"
    },
    {
      "x": -20,
      "y": 29,
      "z": 10,
      "name": "Rock_Acid_Trunk_Bright"
    },
    {
      "x": -20,
      "y": 30,
      "z": 10,
      "name": "Rock_Acid_Trunk_Bright"
    },
    {
      "x": -20,
      "y": 31,
      "z": 10,
      "name": "Rock_Acid_Trunk_Bright"
    },
    {
      "x": -20,
      "y": 32,
      "z": 10,
      "name": "Rock_Acid_Trunk_Bright"
    },
    {
      "x": -20,
      "y": 33,
      "z": 10,
      "name": "Rock_Acid_Trunk_Bright"
    },
    {
      "x": -20,
      "y": 34,
      "z": 10,
      "name": "Rock_Acid_Trunk_Medium"
    },
    {
      "x": -20,
      "y": 35,
      "z": 10,
      "name": "Rock_Acid_Trunk_Medium"
    },
    {
      "x": -20,
      "y": 36,
      "z": 10,
      "name": "Rock_Acid_Trunk_Medium"
    },
    {
      "x": -20,
      "y": 37,
      "z": 10,
      "name": "Rock_Acid_Trunk_Medium"
    },
    {
      "x": -20,
      "y": 38,
      "z": 10,
      "name": "Rock_Acid_Trunk_Medium"
    },
    {
      "x": -20,
      "y": 39,
      "z": 10,
      "name": "Rock_Acid_Trunk_Medium"
    },
    {
      "x": -20,
      "y": 40,
      "z": 10,
      "name": "Rock_Acid_Trunk_Medium"
    },
    {
      "x": -20,
      "y": 41,
      "z": 10,
      "name": "Rock_Acid_Trunk_Medium"
    },
    {
      "x": -20,
      "y": 42,
      "z": 10,
      "name": "Rock_Acid_Trunk_Medium"
    },
    {
      "x": -20,
      "y": 43,
      "z": 10,
      "name": "Rock_Acid_Trunk_Medium"
    },
    {
      "x": -20,
      "y": 44,
      "z": 10,
      "name": "Rock_Acid_Trunk_Medium"
    },
    {
      "x": -20,
      "y": 45,
      "z": 10,
      "name": "Rock_Acid_Trunk_Medium"
    },
    {
      "x": -20,
      "y": 46,
      "z": 10,
      "name": "Rock_Acid_Trunk_Medium"
    },
    {
      "x": -20,
      "y": 47,
      "z": 10,
      "name": "Rock_Acid_Trunk_Medium"
    },
    {
      "x": -20,
      "y": 48,
      "z": 10,
      "name": "Rock_Acid_Trunk_Medium"
    },
    {
      "x": -20,
      "y": 49,
      "z": 10,
      "name": "Rock_Acid_Trunk_Medium"
    },
    {
      "x": -20,
      "y": 50,
      "z": 10,
      "name": "Rock_Acid_Trunk_Medium"
    },
    {
      "x": -20,
      "y": 51,
      "z": 10,
      "name": "Rock_Acid_Trunk_Magenta"
    },
    {
      "x": -20,
      "y": 12,
      "z": 11,
      "name": "Rock_Acid_Trunk_Light"
    },
    {
      "x": -20,
      "y": 13,
      "z": 11,
      "name": "Rock_Acid_Trunk_Light"
    },
    {
      "x": -20,
      "y": 31,
      "z": 11,
      "name": "Rock_Acid_Trunk_Bright"
    },
    {
      "x": -20,
      "y": 32,
      "z": 11,
      "name": "Rock_Acid_Trunk_Bright"
    },
    {
      "x": -20,
      "y": 33,
      "z": 11,
      "name": "Rock_Acid_Trunk_Bright"
    },
    {
      "x": -20,
      "y": 34,
      "z": 11,
      "name": "Rock_Acid_Trunk_Bright"
    },
    {
      "x": -20,
      "y": 35,
      "z": 11,
      "name": "Rock_Acid_Trunk_Bright"
    },
    {
      "x": -20,
      "y": 36,
      "z": 11,
      "name": "Rock_Acid_Trunk_Bright"
    },
    {
      "x": -20,
      "y": 37,
      "z": 11,
      "name": "Rock_Acid_Trunk_Medium"
    },
    {
      "x": -20,
      "y": 38,
      "z": 11,
      "name": "Rock_Acid_Trunk_Medium"
    },
    {
      "x": -20,
      "y": 39,
      "z": 11,
      "name": "Rock_Acid_Trunk_Medium"
    },
    {
      "x": -20,
      "y": 40,
      "z": 11,
      "name": "Rock_Acid_Trunk_Medium"
    },
    {
      "x": -20,
      "y": 41,
      "z": 11,
      "name": "Rock_Acid_Trunk_Medium"
    },
    {
      "x": -20,
      "y": 42,
      "z": 11,
      "name": "Rock_Acid_Trunk_Medium"
    },
    {
      "x": -20,
      "y": 43,
      "z": 11,
      "name": "Rock_Acid_Trunk_Medium"
    },
    {
      "x": -20,
      "y": 44,
      "z": 11,
      "name": "Rock_Acid_Trunk_Medium"
    },
    {
      "x": -20,
      "y": 45,
      "z": 11,
      "name": "Rock_Acid_Trunk_Medium"
    },
    {
      "x": -20,
      "y": 46,
      "z": 11,
