{
  "version": 8,
  "blockIdVersion": 10,
  "anchorX": 0,
  "anchorY": 22,
  "anchorZ": 0,
  "blocks": [
    {
      "x": -38,
      "y": 0,
      "z": 25,
      "name": "Soil_Clay_Green"
    },
    {
      "x": -37,
      "y": 0,
      "z": 24,
      "name": "Soil_Clay_Green"
    },
    {
      "x": -37,
      "y": 0,
      "z": 25,
      "name": "Soil_Clay_Green"
    },
    {
      "x": -37,
      "y": 0,
      "z": 26,
      "name": "Soil_Clay_Green"
    },
    {
      "x": -37,
      "y": 32,
      "z": 31,
      "name": "Soil_Clay_Lime"
    },
    {
      "x": -37,
      "y": 33,
      "z": 31,
      "name": "Plant_Grass_Sharp"
    },
    {
      "x": -36,
      "y": 29,
      "z": 20,
      "name": "Soil_Clay_Green"
    },
    {
      "x": -36,
      "y": 30,
      "z": 20,
      "name": "Soil_Clay_Green"
    },
    {
      "x": -36,
      "y": 31,
      "z": 20,
      "name": "Soil_Seaweed_Block"
    },
    {
      "x": -36,
      "y": 0,
      "z": 23,
      "name": "Soil_Clay_Green"
    },
    {
      "x": -36,
      "y": 0,
      "z": 24,
      "name": "Soil_Clay_Green"
    },
    {
      "x": -36,
      "y": 30,
      "z": 31,
      "name": "Soil_Seaweed_Block"
    },
    {
      "x": -36,
      "y": 31,
      "z": 31,
      "name": "Soil_Clay_Lime"
    },
    {
      "x": -36,
      "y": 32,
      "z": 31,
      "name": "Plant_Grass_Sharp"
    },
    {
      "x": -35,
      "y": 30,
      "z": 21,
      "name": "Soil_Clay_Green"
    },
    {
      "x": -35,
      "y": 31,
      "z": 21,
      "name": "Soil_Clay_Green"
    },
    {
      "x": -35,
      "y": 32,
      "z": 21,
      "name": "Soil_Clay_Lime"
    },
    {
      "x": -35,
      "y": 33,
      "z": 21,
      "name": "Plant_Grass_Sharp"
    },
    {
      "x": -35,
      "y": 31,
      "z": 22,
      "name": "Soil_Clay_Green"
    },
    {
      "x": -35,
      "y": 32,
      "z": 22,
      "name": "Soil_Seaweed_Block"
    },
    {
      "x": -35,
      "y": 0,
      "z": 23,
      "name": "Soil_Clay_Green"
    },
    {
      "x": -35,
      "y": 1,
      "z": 23,
      "name": "Soil_Seaweed_Block"
    },
    {
      "x": -35,
      "y": 0,
      "z": 24,
      "name": "Soil_Clay_Green"
    },
    {
      "x": -35,
      "y": 1,
      "z": 24,
      "name": "Soil_Seaweed_Block"
    },
    {
      "x": -35,
      "y": 29,
      "z": 31,
      "name": "Soil_Clay_Green"
    },
    {
      "x": -35,
      "y": 30,
      "z": 31,
      "name": "Soil_Seaweed_Block"
    },
    {
      "x": -35,
      "y": 31,
      "z": 31,
      "name": "Soil_Clay_Lime"
    },
    {
      "x": -35,
      "y": 32,
      "z": 31,
      "name": "Plant_Grass_Sharp"
    },
    {
      "x": -35,
      "y": 29,
      "z": 32,
      "name": "Soil_Clay_Green"
    },
    {
      "x": -35,
      "y": 30,
      "z": 32,
      "name": "Soil_Seaweed_Block"
    },
    {
      "x": -35,
      "y": 31,
      "z": 32,
      "name": "Soil_Clay_Lime"
    },
    {
      "x": -35,
      "y": 32,
      "z": 32,
      "name": "Plant_Grass_Sharp"
    },
    {
      "x": -34,
      "y": 2,
      "z": 22,
      "name": "Soil_Clay_Lime"
    },
    {
      "x": -34,
      "y": 3,
      "z": 22,
      "name": "Plant_Grass_Sharp"
    },
    {
      "x": -34,
      "y": 1,
      "z": 23,
      "name": "Soil_Clay_Green"
    },
    {
      "x": -34,
      "y": 31,
      "z": 23,
      "name": "Soil_Clay_Green"
    },
    {
      "x": -34,
      "y": 32,
      "z": 23,
      "name": "Soil_Seaweed_Block"
    },
    {
      "x": -34,
      "y": 33,
      "z": 23,
      "name": "Soil_Clay_Lime"
    },
    {
      "x": -34,
      "y": 34,
      "z": 23,
      "name": "Plant_Grass_Sharp"
    },
    {
      "x": -34,
      "y": 32,
      "z": 24,
      "name": "Soil_Clay_Green"
    },
    {
      "x": -34,
      "y": 33,
      "z": 24,
      "name": "Soil_Clay_Lime"
    },
    {
      "x": -34,
      "y": 34,
      "z": 24,
      "name": "Plant_Grass_Sharp"
    },
    {
      "x": -34,
      "y": 28,
      "z": 30,
      "name": "Soil_Clay_Green"
    },
    {
      "x": -34,
      "y": 29,
      "z": 30,
      "name": "Soil_Clay_Green"
    },
    {
      "x": -34,
      "y": 30,
      "z": 30,
      "name": "Soil_Clay_Lime"
    },
    {
      "x": -34,
      "y": 31,
      "z": 30,
      "name": "Plant_Grass_Sharp"
    },
    {
      "x": -34,
      "y": 29,
      "z": 31,
      "name": "Soil_Clay_Green"
    },
    {
      "x": -34,
      "y": 30,
      "z": 31,
      "name": "Soil_Seaweed_Block"
    },
    {
      "x": -34,
      "y": 31,
      "z": 31,
      "name": "Soil_Clay_Lime"
    },
    {
      "x": -34,
      "y": 32,
      "z": 31,
      "name": "Plant_Grass_Sharp"
    },
    {
      "x": -34,
      "y": 29,
      "z": 32,
      "name": "Soil_Clay_Green"
    },
    {
      "x": -34,
      "y": 30,
      "z": 32,
      "name": "Soil_Seaweed_Block"
    },
    {
      "x": -33,
      "y": 1,
      "z": 21,
      "name": "Soil_Clay_Green"
    },
    {
      "x": -33,
      "y": 2,
      "z": 21,
      "name": "Soil_Clay_Lime"
    },
    {
      "x": -33,
      "y": 3,
      "z": 21,
      "name": "Plant_Grass_Sharp"
    },
    {
      "x": -33,
      "y": 1,
      "z": 22,
      "name": "Soil_Clay_Green"
    },
    {
      "x": -33,
      "y": 2,
      "z": 22,
      "name": "Soil_Clay_Lime"
    },
    {
      "x": -33,
      "y": 3,
      "z": 22,
      "name": "Plant_Grass_Sharp"
    },
    {
      "x": -33,
      "y": 1,
      "z": 23,
      "name": "Soil_Clay_Green"
    },
    {
      "x": -33,
      "y": 2,
      "z": 23,
      "name": "Soil_Clay_Lime"
    },
    {
      "x": -33,
      "y": 3,
      "z": 23,
      "name": "Plant_Grass_Sharp"
    },
    {
      "x": -33,
      "y": 32,
      "z": 24,
      "name": "Soil_Clay_Green"
    },
    {
      "x": -33,
      "y": 33,
      "z": 24,
      "name": "Soil_Clay_Lime"
    },
    {
      "x": -33,
      "y": 34,
      "z": 24,
      "name": "Plant_Grass_Sharp"
    },
    {
      "x": -33,
      "y": 31,
      "z": 25,
      "name": "Soil_Clay_Green"
    },
    {
      "x": -33,
      "y": 32,
      "z": 25,
      "name": "Soil_Seaweed_Block"
    },
    {
      "x": -33,
      "y": 33,
      "z": 25,
      "name": "Soil_Clay_Lime"
    },
    {
      "x": -33,
      "y": 34,
      "z": 25,
      "name": "Plant_Grass_Sharp"
    },
    {
      "x": -33,
      "y": 31,
      "z": 26,
      "name": "Soil_Clay_Green"
    },
    {
      "x": -33,
      "y": 32,
      "z": 26,
      "name": "Soil_Seaweed_Block"
    },
    {
      "x": -33,
      "y": 33,
      "z": 26,
      "name": "Soil_Clay_Lime"
    },
    {
      "x": -33,
      "y": 34,
      "z": 26,
      "name": "Plant_Grass_Sharp"
    },
    {
      "x": -33,
      "y": 30,
      "z": 27,
      "name": "Soil_Clay_Green"
    },
    {
      "x": -33,
      "y": 31,
      "z": 27,
      "name": "Soil_Seaweed_Block"
    },
    {
      "x": -33,
      "y": 29,
      "z": 28,
      "name": "Soil_Seaweed_Block"
    },
    {
      "x": -33,
      "y": 30,
      "z": 28,
      "name": "Soil_Seaweed_Block"
    },
    {
      "x": -33,
      "y": 28,
      "z": 29,
      "name": "Soil_Clay_Green"
    },
    {
      "x": -33,
      "y": 29,
      "z": 29,
      "name": "Soil_Clay_Green"
    },
    {
      "x": -33,
      "y": 30,
      "z": 29,
      "name": "Soil_Clay_Lime"
    },
    {
      "x": -33,
      "y": 31,
      "z": 29,
      "name": "Plant_Grass_Sharp"
    },
    {
      "x": -33,
      "y": 28,
      "z": 30,
      "name": "Soil_Clay_Green"
    },
    {
      "x": -33,
      "y": 29,
      "z": 30,
      "name": "Soil_Seaweed_Block"
    },
    {
      "x": -33,
      "y": 30,
      "z": 30,
      "name": "Soil_Clay_Lime"
    },
    {
      "x": -33,
      "y": 31,
      "z": 30,
      "name": "Plant_Grass_Sharp"
    },
    {
      "x": -33,
      "y": 28,
      "z": 31,
      "name": "Soil_Clay_Green"
    },
    {
      "x": -33,
      "y": 29,
      "z": 31,
      "name": "Soil_Seaweed_Block"
    },
    {
      "x": -33,
      "y": 30,
      "z": 31,
      "name": "Soil_Clay_Lime"
    },
    {
      "x": -33,
      "y": 31,
      "z": 31,
      "name": "Plant_Grass_Sharp"
    },
    {
      "x": -33,
      "y": 29,
      "z": 32,
      "name": "Soil_Clay_Green"
    },
    {
      "x": -33,
      "y": 30,
      "z": 32,
      "name": "Soil_Seaweed_Block"
    },
    {
      "x": -32,
      "y": 46,
      "z": 18,
      "name": "Soil_Seaweed_Block"
    },
    {
      "x": -32,
      "y": 1,
      "z": 19,
      "name": "Soil_Clay_Green"
    },
    {
      "x": -32,
      "y": 1,
      "z": 20,
      "name": "Soil_Clay_Green"
    },
    {
      "x": -32,
      "y": 2,
      "z": 20,
      "name": "Soil_Clay_Lime"
    },
    {
      "x": -32,
      "y": 3,
      "z": 20,
      "name": "Plant_Grass_Sharp"
    },
    {
      "x": -32,
      "y": 1,
      "z": 21,
      "name": "Soil_Clay_Green"
    },
    {
      "x": -32,
      "y": 2,
      "z": 21,
      "name": "Soil_Clay_Lime"
    },
    {
      "x": -32,
      "y": 3,
      "z": 21,
      "name": "Plant_Grass_Sharp"
    },
    {
      "x": -32,
      "y": 1,
      "z": 22,
      "name": "Soil_Clay_Green"
    },
    {
      "x": -32,
      "y": 2,
      "z": 22,
      "name": "Soil_Seaweed_Block"
    },
    {
      "x": -32,
      "y": 32,
      "z": 25,
      "name": "Soil_Seaweed_Block"
    },
    {
      "x": -32,
      "y": 33,
      "z": 25,
      "name": "Soil_Clay_Lime"
    },
    {
      "x": -32,
      "y": 34,
      "z": 25,
      "name": "Plant_Grass_Sharp"
    },
    {
      "x": -32,
      "y": 31,
      "z": 26,
      "name": "Soil_Clay_Green"
    },
    {
      "x": -32,
      "y": 32,
      "z": 26,
      "name": "Soil_Seaweed_Block"
    },
    {
      "x": -32,
      "y": 33,
      "z": 26,
      "name": "Soil_Clay_Lime"
    },
    {
      "x": -32,
      "y": 34,
      "z": 26,
      "name": "Plant_Grass_Sharp"
    },
    {
      "x": -32,
      "y": 31,
      "z": 27,
      "name": "Soil_Seaweed_Block"
    },
    {
      "x": -32,
      "y": 29,
      "z": 28,
      "name": "Soil_Seaweed_Block"
    },
    {
      "x": -32,
      "y": 30,
      "z": 28,
      "name": "Soil_Seaweed_Block"
    },
    {
      "x": -32,
      "y": 27,
      "z": 29,
      "name": "Soil_Clay_Green"
    },
    {
      "x": -32,
      "y": 28,
      "z": 29,
      "name": "Soil_Clay_Green"
    },
    {
      "x": -32,
      "y": 29,
      "z": 29,
      "name": "Soil_Seaweed_Block"
    },
    {
      "x": -32,
      "y": 30,
      "z": 29,
      "name": "Soil_Clay_Lime"
    },
    {
      "x": -32,
      "y": 31,
      "z": 29,
      "name": "Plant_Grass_Sharp"
    },
    {
      "x": -32,
      "y": 27,
      "z": 30,
      "name": "Soil_Clay_Green"
    },
    {
      "x": -32,
      "y": 28,
      "z": 30,
      "name": "Soil_Clay_Green"
    },
    {
      "x": -32,
      "y": 29,
      "z": 30,
      "name": "Soil_Clay_Lime"
    },
    {
      "x": -32,
      "y": 30,
      "z": 30,
      "name": "Soil_Clay_Lime"
    },
    {
      "x": -32,
      "y": 31,
      "z": 30,
      "name": "Plant_Grass_Sharp"
    },
    {
      "x": -32,
      "y": 29,
      "z": 31,
      "name": "Soil_Seaweed_Block"
    },
    {
      "x": -32,
      "y": 30,
      "z": 31,
      "name": "Soil_Clay_Lime"
    },
    {
      "x": -32,
      "y": 31,
      "z": 31,
      "name": "Plant_Grass_Sharp"
    },
    {
      "x": -31,
      "y": 1,
      "z": 18,
      "name": "Soil_Seaweed_Block"
    },
    {
      "x": -31,
      "y": 45,
      "z": 18,
      "name": "Soil_Seaweed_Block"
    },
    {
      "x": -31,
      "y": 46,
      "z": 18,
      "name": "Soil_Clay_Lime"
    },
    {
      "x": -31,
      "y": 47,
      "z": 18,
      "name": "Plant_Grass_Sharp"
    },
    {
      "x": -31,
      "y": 1,
      "z": 19,
      "name": "Soil_Clay_Green"
    },
    {
      "x": -31,
      "y": 2,
      "z": 19,
      "name": "Soil_Clay_Lime"
    },
    {
      "x": -31,
      "y": 3,
      "z": 19,
      "name": "Plant_Grass_Sharp"
    },
    {
      "x": -31,
      "y": 45,
      "z": 19,
      "name": "Soil_Seaweed_Block"
    },
    {
      "x": -31,
      "y": 0,
      "z": 20,
      "name": "Soil_Clay_Green"
    },
    {
      "x": -31,
      "y": 1,
      "z": 20,
      "name": "Soil_Seaweed_Block"
    },
    {
      "x": -31,
      "y": 2,
      "z": 20,
      "name": "Soil_Clay_Lime"
    },
    {
      "x": -31,
      "y": 3,
      "z": 20,
      "name": "Plant_Grass_Sharp"
    },
    {
      "x": -31,
      "y": 1,
      "z": 21,
      "name": "Soil_Clay_Green"
    },
    {
      "x": -31,
      "y": 2,
      "z": 21,
      "name": "Soil_Clay_Lime"
    },
    {
      "x": -31,
      "y": 3,
      "z": 21,
      "name": "Plant_Grass_Sharp"
    },
    {
      "x": -31,
      "y": 1,
      "z": 22,
      "name": "Soil_Clay_Green"
    },
    {
      "x": -31,
      "y": 2,
      "z": 22,
      "name": "Soil_Seaweed_Block"
    },
    {
      "x": -31,
      "y": 27,
      "z": 28,
      "name": "Soil_Clay_Green"
    },
    {
      "x": -31,
      "y": 26,
      "z": 29,
      "name": "Soil_Clay_Green"
    },
    {
      "x": -31,
      "y": 27,
      "z": 29,
      "name": "Soil_Seaweed_Block"
    },
    {
      "x": -31,
      "y": 28,
      "z": 29,
      "name": "Soil_Seaweed_Block"
    },
    {
      "x": -31,
      "y": 26,
      "z": 30,
      "name": "Soil_Clay_Green"
    },
    {
      "x": -31,
      "y": 27,
      "z": 30,
      "name": "Soil_Clay_Green"
    },
    {
      "x": -31,
      "y": 28,
      "z": 30,
      "name": "Soil_Seaweed_Block"
    },
    {
      "x": -30,
      "y": 1,
      "z": 18,
      "name": "Soil_Seaweed_Block"
    },
    {
      "x": -30,
      "y": 45,
      "z": 18,
      "name": "Soil_Clay_Lime"
    },
    {
      "x": -30,
      "y": 46,
      "z": 18,
      "name": "Plant_Grass_Sharp"
    },
    {
      "x": -30,
      "y": 0,
      "z": 19,
      "name": "Soil_Clay_Green"
    },
    {
      "x": -30,
      "y": 1,
      "z": 19,
      "name": "Soil_Seaweed_Block"
    },
    {
      "x": -30,
      "y": 2,
      "z": 19,
      "name": "Soil_Clay_Lime"
    },
    {
      "x": -30,
      "y": 3,
      "z": 19,
      "name": "Plant_Grass_Sharp"
    },
    {
      "x": -30,
      "y": 45,
      "z": 19,
      "name": "Soil_Clay_Lime"
    },
    {
      "x": -30,
      "y": 46,
      "z": 19,
      "name": "Plant_Grass_Sharp"
    },
    {
      "x": -30,
      "y": 0,
      "z": 20,
      "name": "Soil_Clay_Green"
    },
    {
      "x": -30,
      "y": 1,
      "z": 20,
      "name": "Soil_Seaweed_Block"
    },
    {
      "x": -30,
      "y": 2,
      "z": 20,
      "name": "Soil_Clay_Lime"
    },
    {
      "x": -30,
      "y": 3,
      "z": 20,
      "name": "Plant_Grass_Sharp"
    },
    {
      "x": -30,
      "y": 0,
      "z": 21,
      "name": "Soil_Clay_Green"
    },
    {
      "x": -30,
      "y": 1,
      "z": 21,
      "name": "Soil_Clay_Green"
    },
    {
      "x": -30,
      "y": 2,
      "z": 21,
      "name": "Soil_Clay_Lime"
    },
    {
      "x": -30,
      "y": 3,
      "z": 21,
      "name": "Plant_Grass_Sharp"
    },
    {
      "x": -30,
      "y": 27,
      "z": 28,
      "name": "Soil_Clay_Green"
    },
    {
      "x": -30,
      "y": 26,
      "z": 29,
      "name": "Soil_Clay_Green"
    },
    {
      "x": -30,
      "y": 27,
      "z": 29,
      "name": "Soil_Seaweed_Block"
    },
    {
      "x": -30,
      "y": 28,
      "z": 29,
      "name": "Soil_Clay_Lime"
    },
    {
      "x": -30,
      "y": 29,
      "z": 29,
      "name": "Plant_Grass_Sharp"
    },
    {
      "x": -30,
      "y": 26,
      "z": 30,
      "name": "Soil_Clay_Green"
    },
    {
      "x": -30,
      "y": 27,
      "z": 30,
      "name": "Soil_Seaweed_Block"
    },
    {
      "x": -30,
      "y": 28,
      "z": 30,
      "name": "Soil_Clay_Lime"
    },
    {
      "x": -30,
      "y": 29,
      "z": 30,
      "name": "Plant_Grass_Sharp"
    },
    {
      "x": -30,
      "y": 26,
      "z": 31,
      "name": "Soil_Clay_Green"
    },
    {
      "x": -30,
      "y": 27,
      "z": 31,
      "name": "Soil_Seaweed_Block"
    },
    {
      "x": -29,
      "y": 0,
      "z": 18,
      "name": "Soil_Clay_Green"
    },
    {
      "x": -29,
      "y": 1,
      "z": 18,
      "name": "Soil_Clay_Green"
    },
    {
      "x": -29,
      "y": 43,
      "z": 18,
      "name": "Soil_Clay_Green"
    },
    {
      "x": -29,
      "y": 44,
      "z": 18,
      "name": "Soil_Clay_Lime"
    },
    {
      "x": -29,
      "y": 45,
      "z": 18,
      "name": "Plant_Grass_Sharp"
    },
    {
      "x": -29,
      "y": 0,
      "z": 19,
      "name": "Soil_Clay_Green"
    },
    {
      "x": -29,
      "y": 1,
      "z": 19,
      "name": "Soil_Clay_Green"
    },
    {
      "x": -29,
      "y": 44,
      "z": 19,
      "name": "Soil_Seaweed_Block"
    },
    {
      "x": -29,
      "y": 0,
      "z": 20,
      "name": "Soil_Clay_Green"
    },
    {
      "x": -29,
      "y": 1,
      "z": 20,
      "name": "Soil_Clay_Green"
    },
    {
      "x": -29,
      "y": 26,
      "z": 28,
      "name": "Soil_Clay_Green"
    },
    {
      "x": -29,
      "y": 27,
      "z": 28,
      "name": "Soil_Seaweed_Block"
    },
    {
      "x": -29,
      "y": 26,
      "z": 29,
      "name": "Soil_Clay_Green"
    },
    {
      "x": -29,
      "y": 27,
      "z": 29,
      "name": "Soil_Seaweed_Block"
    },
    {
      "x": -29,
      "y": 28,
      "z": 29,
      "name": "Soil_Clay_Lime"
    },
    {
      "x": -29,
      "y": 29,
      "z": 29,
      "name": "Plant_Grass_Sharp"
    },
    {
      "x": -29,
      "y": 25,
      "z": 30,
      "name": "Soil_Clay_Green"
    },
    {
      "x": -29,
      "y": 26,
      "z": 30,
      "name": "Soil_Seaweed_Block"
    },
    {
      "x": -29,
      "y": 27,
      "z": 30,
      "name": "Soil_Seaweed_Block"
    },
    {
      "x": -29,
      "y": 28,
      "z": 30,
      "name": "Soil_Clay_Lime"
    },
    {
      "x": -29,
      "y": 29,
      "z": 30,
      "name": "Plant_Grass_Sharp"
    },
    {
      "x": -29,
      "y": 26,
      "z": 31,
      "name": "Soil_Clay_Green"
    },
    {
      "x": -29,
      "y": 27,
      "z": 31,
      "name": "Soil_Seaweed_Block"
    },
    {
      "x": -29,
      "y": 11,
      "z": 36,
      "name": "Soil_Clay_Green"
    },
    {
      "x": -29,
      "y": 10,
      "z": 38,
      "name": "Soil_Clay_Green"
    },
    {
      "x": -28,
      "y": 42,
      "z": 17,
      "name": "Soil_Clay_Green"
    },
    {
      "x": -28,
      "y": 43,
      "z": 17,
      "name": "Soil_Seaweed_Block"
    },
    {
      "x": -28,
      "y": 0,
      "z": 18,
      "name": "Soil_Clay_Green"
    },
    {
      "x": -28,
      "y": 42,
      "z": 18,
      "name": "Soil_Clay_Green"
    },
    {
      "x": -28,
      "y": 43,
      "z": 18,
      "name": "Soil_Seaweed_Block"
    },
    {
      "x": -28,
      "y": 44,
      "z": 18,
      "name": "Soil_Clay_Lime"
    },
    {
      "x": -28,
      "y": 45,
      "z": 18,
      "name": "Plant_Grass_Sharp"
    },
    {
      "x": -28,
      "y": 0,
      "z": 19,
      "name": "Soil_Clay_Green"
    },
    {
      "x": -28,
      "y": 1,
      "z": 19,
      "name": "Soil_Clay_Green"
    },
    {
      "x": -28,
      "y": 43,
      "z": 19,
      "name": "Soil_Clay_Green"
    },
    {
      "x": -28,
      "y": 44,
      "z": 19,
      "name": "Soil_Clay_Lime"
    },
    {
      "x": -28,
      "y": 45,
      "z": 19,
      "name": "Plant_Grass_Sharp"
    },
    {
      "x": -28,
      "y": 0,
      "z": 20,
      "name": "Soil_Clay_Green"
    },
    {
      "x": -28,
      "y": 1,
      "z": 20,
      "name": "Soil_Clay_Green"
    },
    {
      "x": -28,
      "y": 25,
      "z": 29,
      "name": "Soil_Clay_Green"
    },
    {
      "x": -28,
      "y": 26,
      "z": 29,
      "name": "Soil_Clay_Green"
    },
    {
      "x": -28,
      "y": 27,
      "z": 29,
      "name": "Soil_Clay_Lime"
    },
    {
      "x": -28,
      "y": 28,
      "z": 29,
      "name": "Soil_Clay_Lime"
    },
    {
      "x": -28,
      "y": 29,
      "z": 29,
      "name": "Plant_Grass_Sharp"
    },
    {
      "x": -28,
      "y": 25,
      "z": 30,
      "name": "Soil_Clay_Green"
    },
    {
      "x": -28,
      "y": 26,
      "z": 30,
      "name": "Soil_Seaweed_Block"
    },
    {
      "x": -28,
      "y": 27,
      "z": 30,
      "name": "Soil_Clay_Lime"
    },
    {
      "x": -28,
      "y": 28,
      "z": 30,
      "name": "Plant_Grass_Sharp"
    },
    {
      "x": -28,
      "y": 26,
      "z": 31,
      "name": "Soil_Clay_Green"
    },
    {
      "x": -28,
      "y": 27,
      "z": 31,
      "name": "Soil_Seaweed_Block"
    },
    {
      "x": -28,
      "y": 12,
      "z": 36,
      "name": "Soil_Seaweed_Block"
    },
    {
      "x": -28,
      "y": 10,
      "z": 37,
      "name": "Soil_Clay_Green"
    },
    {
      "x": -28,
      "y": 11,
      "z": 37,
      "name": "Soil_Clay_Green"
    },
    {
      "x": -28,
      "y": 10,
      "z": 38,
      "name": "Soil_Clay_Green"
    },
    {
      "x": -27,
      "y": 42,
      "z": 16,
      "name": "Soil_Clay_Green"
    },
    {
      "x": -27,
      "y": 42,
      "z": 17,
      "name": "Soil_Clay_Green"
    },
    {
      "x": -27,
      "y": 43,
      "z": 17,
      "name": "Soil_Clay_Lime"
    },
    {
      "x": -27,
      "y": 44,
      "z": 17,
      "name": "Plant_Grass_Sharp"
    },
    {
      "x": -27,
      "y": 1,
      "z": 18,
      "name": "Soil_Clay_Green"
    },
    {
      "x": -27,
      "y": 2,
      "z": 18,
      "name": "Soil_Clay_Green"
    },
    {
      "x": -27,
      "y": 3,
      "z": 18,
      "name": "Soil_Seaweed_Block"
    },
    {
      "x": -27,
      "y": 42,
      "z": 18,
      "name": "Soil_Clay_Green"
    },
    {
      "x": -27,
      "y": 43,
      "z": 18,
      "name": "Soil_Clay_Lime"
    },
    {
      "x": -27,
      "y": 44,
      "z": 18,
      "name": "Plant_Grass_Sharp"
    },
    {
      "x": -27,
      "y": 0,
      "z": 19,
      "name": "Soil_Clay_Green"
    },
    {
      "x": -27,
      "y": 1,
      "z": 19,
      "name": "Soil_Clay_Green"
    },
    {
      "x": -27,
      "y": 2,
      "z": 19,
      "name": "Soil_Clay_Green"
    },
    {
      "x": -27,
      "y": 3,
      "z": 19,
      "name": "Soil_Seaweed_Block"
    },
    {
      "x": -27,
      "y": 4,
      "z": 19,
      "name": "Soil_Seaweed_Block"
    },
    {
      "x": -27,
      "y": 5,
      "z": 19,
      "name": "Soil_Seaweed_Block"
    },
    {
      "x": -27,
      "y": 43,
      "z": 19,
      "name": "Soil_Seaweed_Block"
    },
    {
      "x": -27,
      "y": 44,
      "z": 19,
      "name": "Soil_Clay_Lime"
    },
    {
      "x": -27,
      "y": 45,
      "z": 19,
      "name": "Plant_Grass_Sharp"
    },
    {
      "x": -27,
      "y": 3,
      "z": 20,
      "name": "Soil_Seaweed_Block"
    },
    {
      "x": -27,
      "y": 4,
      "z": 20,
      "name": "Soil_Seaweed_Block"
    },
    {
      "x": -27,
      "y": 5,
      "z": 20,
      "name": "Soil_Seaweed_Block"
    },
    {
      "x": -27,
      "y": 23,
      "z": 27,
      "name": "Soil_Clay_Green"
    },
    {
      "x": -27,
      "y": 23,
      "z": 28,
      "name": "Soil_Clay_Green"
    },
    {
      "x": -27,
      "y": 24,
      "z": 28,
      "name": "Soil_Clay_Green"
    },
    {
      "x": -27,
      "y": 25,
      "z": 28,
      "name": "Soil_Clay_Green"
    },
    {
      "x": -27,
      "y": 26,
      "z": 28,
      "name": "Soil_Seaweed_Block"
    },
    {
      "x": -27,
      "y": 27,
      "z": 28,
      "name": "Soil_Seaweed_Block"
    },
    {
      "x": -27,
      "y": 24,
      "z": 29,
      "name": "Soil_Clay_Green"
    },
    {
      "x": -27,
      "y": 25,
      "z": 29,
      "name": "Soil_Seaweed_Block"
    },
    {
      "x": -27,
      "y": 26,
      "z": 29,
      "name": "Soil_Seaweed_Block"
    },
    {
      "x": -27,
      "y": 27,
      "z": 29,
      "name": "Soil_Clay_Lime"
    },
    {
      "x": -27,
      "y": 28,
      "z": 29,
      "name": "Plant_Grass_Sharp"
    },
    {
      "x": -27,
      "y": 25,
      "z": 30,
      "name": "Soil_Clay_Green"
    },
    {
      "x": -27,
      "y": 26,
      "z": 30,
      "name": "Soil_Seaweed_Block"
    },
    {
      "x": -27,
      "y": 27,
      "z": 30,
      "name": "Soil_Clay_Lime"
    },
    {
      "x": -27,
      "y": 28,
      "z": 30,
      "name": "Plant_Grass_Sharp"
    },
    {
      "x": -27,
      "y": 26,
      "z": 31,
      "name": "Soil_Seaweed_Block"
    },
    {
      "x": -27,
      "y": 27,
      "z": 31,
      "name": "Soil_Seaweed_Block"
    },
    {
      "x": -27,
      "y": 12,
      "z": 35,
      "name": "Soil_Clay_Green"
    },
    {
      "x": -27,
      "y": 13,
      "z": 35,
      "name": "Soil_Clay_Green"
    },
    {
      "x": -27,
      "y": 12,
      "z": 36,
      "name": "Soil_Clay_Green"
    },
    {
      "x": -27,
      "y": 11,
      "z": 37,
      "name": "Soil_Clay_Green"
    },
    {
      "x": -27,
      "y": 12,
      "z": 37,
      "name": "Soil_Seaweed_Block"
    },
    {
      "x": -26,
      "y": 41,
      "z": 14,
      "name": "Soil_Clay_Green"
    },
    {
      "x": -26,
      "y": 42,
      "z": 14,
      "name": "Soil_Seaweed_Block"
    },
    {
      "x": -26,
      "y": 41,
      "z": 15,
      "name": "Soil_Clay_Green"
    },
    {
      "x": -26,
      "y": 42,
      "z": 15,
      "name": "Soil_Clay_Lime"
    },
    {
      "x": -26,
      "y": 43,
      "z": 15,
      "name": "Plant_Grass_Sharp"
    },
    {
      "x": -26,
      "y": 41,
      "z": 16,
      "name": "Soil_Clay_Green"
    },
    {
      "x": -26,
      "y": 42,
      "z": 16,
      "name": "Soil_Seaweed_Block"
    },
    {
      "x": -26,
      "y": 43,
      "z": 16,
      "name": "Soil_Clay_Lime"
    },
    {
      "x": -26,
      "y": 44,
      "z": 16,
      "name": "Plant_Grass_Sharp"
    },
    {
      "x": -26,
      "y": 2,
      "z": 17,
      "name": "Soil_Clay_Green"
    },
    {
      "x": -26,
      "y": 3,
      "z": 17,
      "name": "Soil_Seaweed_Block"
    },
    {
      "x": -26,
      "y": 42,
      "z": 17,
      "name": "Soil_Clay_Green"
    },
    {
      "x": -26,
      "y": 43,
      "z": 17,
      "name": "Soil_Clay_Lime"
    },
    {
      "x": -26,
      "y": 44,
      "z": 17,
      "name": "Plant_Grass_Sharp"
    },
    {
      "x": -26,
      "y": 1,
      "z": 18,
      "name": "Soil_Clay_Green"
    },
    {
      "x": -26,
      "y": 2,
      "z": 18,
      "name": "Soil_Seaweed_Block"
    },
    {
      "x": -26,
      "y": 3,
      "z": 18,
      "name": "Soil_Clay_Green"
    },
    {
      "x": -26,
      "y": 42,
      "z": 18,
      "name": "Soil_Clay_Green"
    },
    {
      "x": -26,
      "y": 43,
      "z": 18,
      "name": "Soil_Seaweed_Block"
    },
    {
      "x": -26,
      "y": 1,
      "z": 19,
      "name": "Soil_Clay_Green"
    },
    {
      "x": -26,
      "y": 2,
      "z": 19,
      "name": "Soil_Clay_Green"
    },
    {
      "x": -26,
      "y": 3,
      "z": 19,
      "name": "Soil_Seaweed_Block"
    },
    {
      "x": -26,
      "y": 4,
      "z": 19,
      "name": "Soil_Clay_Green"
    },
    {
      "x": -26,
      "y": 5,
      "z": 19,
      "name": "Soil_Seaweed_Block"
    },
    {
      "x": -26,
      "y": 6,
      "z": 19,
      "name": "Soil_Seaweed_Block"
    },
    {
      "x": -26,
      "y": 42,
      "z": 19,
      "name": "Soil_Clay_Green"
    },
    {
      "x": -26,
      "y": 43,
      "z": 19,
      "name": "Soil_Seaweed_Block"
    },
    {
      "x": -26,
      "y": 3,
      "z": 20,
      "name": "Soil_Clay_Green"
    },
    {
      "x": -26,
      "y": 4,
      "z": 20,
      "name": "Soil_Clay_Green"
    },
    {
      "x": -26,
      "y": 5,
      "z": 20,
      "name": "Soil_Seaweed_Block"
    },
    {
      "x": -26,
      "y": 6,
      "z": 20,
      "name": "Soil_Seaweed_Block"
    },
    {
      "x": -26,
      "y": 23,
      "z": 27,
      "name": "Soil_Clay_Green"
    },
    {
      "x": -26,
      "y": 22,
      "z": 28,
      "name": "Soil_Clay_Green"
    },
    {
      "x": -26,
      "y": 23,
      "z": 28,
      "name": "Soil_Seaweed_Block"
    },
    {
      "x": -26,
      "y": 24,
      "z": 28,
      "name": "Soil_Clay_Green"
    },
    {
      "x": -26,
      "y": 25,
      "z": 28,
      "name": "Soil_Seaweed_Block"
    },
    {
      "x": -26,
      "y": 23,
      "z": 29,
      "name": "Soil_Clay_Green"
    },
    {
      "x": -26,
      "y": 24,
      "z": 29,
      "name": "Soil_Seaweed_Block"
    },
    {
      "x": -26,
      "y": 25,
      "z": 29,
      "name": "Soil_Seaweed_Block"
    },
    {
      "x": -26,
      "y": 26,
      "z": 29,
      "name": "Soil_Clay_Lime"
    },
    {
      "x": -26,
      "y": 27,
      "z": 29,
      "name": "Soil_Clay_Lime"
    },
    {
      "x": -26,
      "y": 28,
      "z": 29,
      "name": "Plant_Grass_Sharp"
    },
    {
      "x": -26,
      "y": 23,
      "z": 30,
      "name": "Soil_Clay_Green"
    },
    {
      "x": -26,
      "y": 24,
      "z": 30,
      "name": "Soil_Clay_Green"
    },
    {
      "x": -26,
      "y": 25,
      "z": 30,
      "name": "Soil_Seaweed_Block"
    },
    {
      "x": -26,
      "y": 26,
      "z": 30,
      "name": "Soil_Clay_Lime"
    },
    {
      "x": -26,
      "y": 27,
      "z": 30,
      "name": "Soil_Clay_Lime"
    },
    {
      "x": -26,
      "y": 28,
      "z": 30,
      "name": "Plant_Grass_Sharp"
    },
    {
      "x": -26,
      "y": 13,
      "z": 34,
      "name": "Soil_Clay_Green"
    },
    {
      "x": -26,
      "y": 14,
      "z": 34,
      "name": "Soil_Clay_Green"
    },
    {
      "x": -26,
      "y": 15,
      "z": 34,
      "name": "Soil_Seaweed_Block"
    },
    {
      "x": -26,
      "y": 12,
      "z": 35,
      "name": "Soil_Clay_Green"
    },
    {
      "x": -26,
      "y": 13,
      "z": 35,
      "name": "Soil_Clay_Green"
    },
    {
      "x": -26,
      "y": 14,
      "z": 35,
      "name": "Soil_Clay_Green"
    },
    {
      "x": -25,
      "y": 40,
      "z": 11,
      "name": "Soil_Clay_Green"
    },
    {
      "x": -25,
      "y": 41,
      "z": 11,
      "name": "Soil_Seaweed_Block"
    },
    {
      "x": -25,
      "y": 42,
      "z": 11,
      "name": "Soil_Clay_Lime"
    },
    {
      "x": -25,
      "y": 43,
      "z": 11,
      "name": "Plant_Grass_Sharp"
    },
    {
      "x": -25,
      "y": 41,
      "z": 12,
      "name": "Soil_Seaweed_Block"
    },
    {
      "x": -25,
      "y": 42,
      "z": 12,
      "name": "Soil_Clay_Lime"
    },
    {
      "x": -25,
      "y": 43,
      "z": 12,
      "name": "Plant_Grass_Sharp"
    },
    {
      "x": -25,
      "y": 40,
      "z": 13,
      "name": "Soil_Clay_Green"
    },
    {
      "x": -25,
      "y": 41,
      "z": 13,
      "name": "Soil_Seaweed_Block"
    },
    {
      "x": -25,
      "y": 42,
      "z": 13,
      "name": "Soil_Clay_Lime"
    },
    {
      "x": -25,
      "y": 43,
      "z": 13,
      "name": "Plant_Grass_Sharp"
    },
    {
      "x": -25,
      "y": 40,
      "z": 14,
      "name": "Soil_Clay_Green"
    },
    {
      "x": -25,
      "y": 41,
      "z": 14,
      "name": "Soil_Seaweed_Block"
    },
    {
      "x": -25,
      "y": 42,
      "z": 14,
      "name": "Soil_Clay_Lime"
    },
    {
      "x": -25,
      "y": 43,
      "z": 14,
      "name": "Plant_Grass_Sharp"
    },
    {
      "x": -25,
      "y": 40,
      "z": 15,
      "name": "Soil_Clay_Green"
    },
    {
      "x": -25,
      "y": 41,
      "z": 15,
      "name": "Soil_Clay_Green"
    },
    {
      "x": -25,
      "y": 42,
      "z": 15,
      "name": "Soil_Clay_Lime"
    },
    {
      "x": -25,
      "y": 43,
      "z": 15,
      "name": "Plant_Grass_Sharp"
    },
    {
      "x": -25,
      "y": 41,
      "z": 16,
      "name": "Soil_Clay_Green"
    },
    {
      "x": -25,
      "y": 42,
      "z": 16,
      "name": "Soil_Seaweed_Block"
    },
    {
      "x": -25,
      "y": 41,
      "z": 17,
      "name": "Soil_Clay_Green"
    },
    {
      "x": -25,
      "y": 42,
      "z": 17,
      "name": "Soil_Clay_Green"
    },
    {
      "x": -25,
      "y": 1,
      "z": 18,
      "name": "Soil_Clay_Green"
    },
    {
      "x": -25,
      "y": 2,
      "z": 18,
      "name": "Soil_Clay_Green"
    },
    {
      "x": -25,
      "y": 3,
      "z": 18,
      "name": "Soil_Clay_Green"
    },
    {
      "x": -25,
      "y": 4,
      "z": 18,
      "name": "Soil_Clay_Green"
    },
    {
      "x": -25,
      "y": 5,
      "z": 18,
      "name": "Soil_Seaweed_Block"
    },
    {
      "x": -25,
      "y": 6,
      "z": 18,
      "name": "Soil_Seaweed_Block"
    },
    {
      "x": -25,
      "y": 2,
      "z": 19,
      "name": "Soil_Clay_Green"
    },
    {
      "x": -25,
      "y": 3,
      "z": 19,
      "name": "Soil_Seaweed_Block"
    },
    {
      "x": -25,
      "y": 4,
      "z": 19,
      "name": "Soil_Seaweed_Block"
    },
    {
      "x": -25,
      "y": 5,
      "z": 19,
      "name": "Soil_Seaweed_Block"
    },
    {
      "x": -25,
      "y": 6,
      "z": 19,
      "name": "Soil_Seaweed_Block"
    },
    {
      "x": -25,
      "y": 7,
      "z": 19,
      "name": "Soil_Seaweed_Block"
    },
    {
      "x": -25,
      "y": 3,
      "z": 20,
      "name": "Soil_Clay_Green"
    },
    {
      "x": -25,
      "y": 4,
      "z": 20,
      "name": "Soil_Clay_Green"
    },
    {
      "x": -25,
      "y": 5,
      "z": 20,
      "name": "Soil_Seaweed_Block"
    },
    {
      "x": -25,
      "y": 6,
      "z": 20,
      "name": "Soil_Seaweed_Block"
    },
    {
      "x": -25,
      "y": 7,
      "z": 20,
      "name": "Soil_Seaweed_Block"
    },
    {
      "x": -25,
      "y": 22,
      "z": 27,
      "name": "Soil_Clay_Green"
    },
    {
      "x": -25,
      "y": 23,
      "z": 27,
      "name": "Soil_Clay_Green"
    },
    {
      "x": -25,
      "y": 24,
      "z": 27,
      "name": "Soil_Seaweed_Block"
    },
    {
      "x": -25,
      "y": 22,
      "z": 28,
      "name": "Soil_Clay_Green"
    },
    {
      "x": -25,
      "y": 23,
      "z": 28,
      "name": "Soil_Seaweed_Block"
    },
    {
      "x": -25,
      "y": 24,
      "z": 28,
      "name": "Soil_Seaweed_Block"
    },
    {
      "x": -25,
      "y": 25,
      "z": 28,
      "name": "Soil_Seaweed_Block"
    },
    {
      "x": -25,
      "y": 22,
      "z": 29,
      "name": "Soil_Clay_Green"
    },
    {
      "x": -25,
      "y": 23,
      "z": 29,
      "name": "Soil_Seaweed_Block"
    },
    {
      "x": -25,
      "y": 24,
      "z": 29,
      "name": "Soil_Seaweed_Block"
    },
    {
      "x": -25,
      "y": 25,
      "z": 29,
      "name": "Soil_Seaweed_Block"
    },
    {
      "x": -25,
      "y": 26,
      "z": 29,
      "name": "Soil_Clay_Lime"
    },
    {
      "x": -25,
      "y": 27,
      "z": 29,
      "name": "Plant_Grass_Sharp"
    },
    {
      "x": -25,
      "y": 23,
      "z": 30,
      "name": "Soil_Clay_Green"
    },
    {
      "x": -25,
      "y": 24,
      "z": 30,
      "name": "Soil_Seaweed_Block"
    },
    {
      "x": -25,
      "y": 25,
      "z": 30,
      "name": "Soil_Seaweed_Block"
    },
    {
      "x": -25,
      "y": 26,
      "z": 30,
      "name": "Soil_Clay_Lime"
    },
    {
      "x": -25,
      "y": 27,
      "z": 30,
      "name": "Plant_Grass_Sharp"
    },
    {
      "x": -25,
      "y": 24,
      "z": 31,
      "name": "Soil_Clay_Green"
    },
    {
      "x": -25,
      "y": 25,
      "z": 31,
      "name": "Soil_Seaweed_Block"
    },
    {
      "x": -25,
      "y": 26,
      "z": 31,
      "name": "Soil_Clay_Lime"
    },
    {
      "x": -25,
      "y": 27,
      "z": 31,
      "name": "Plant_Grass_Sharp"
    },
    {
      "x": -25,
      "y": 17,
      "z": 32,
      "name": "Soil_Seaweed_Block"
    },
    {
      "x": -25,
      "y": 14,
      "z": 33,
      "name": "Soil_Clay_Green"
    },
    {
      "x": -25,
      "y": 15,
      "z": 33,
      "name": "Soil_Clay_Green"
    },
    {
      "x": -25,
      "y": 16,
      "z": 33,
      "name": "Soil_Seaweed_Block"
    },
    {
      "x": -25,
      "y": 17,
      "z": 33,
      "name": "Soil_Seaweed_Block"
    },
    {
      "x": -25,
      "y": 13,
      "z": 34,
      "name": "Soil_Clay_Green"
    },
    {
      "x": -25,
      "y": 14,
      "z": 34,
      "name": "Soil_Seaweed_Block"
    },
    {
      "x": -25,
      "y": 15,
      "z": 34,
      "name": "Soil_Seaweed_Block"
    },
    {
      "x": -25,
      "y": 16,
      "z": 34,
      "name": "Soil_Seaweed_Block"
    },
    {
      "x": -25,
      "y": 13,
      "z": 35,
      "name": "Soil_Clay_Green"
    },
    {
      "x": -25,
      "y": 14,
      "z": 35,
      "name": "Soil_Clay_Green"
    },
    {
      "x": -25,
      "y": 15,
      "z": 35,
      "name": "Soil_Seaweed_Block"
    },
    {
      "x": -24,
      "y": 40,
      "z": 9,
      "name": "Soil_Seaweed_Block"
    },
    {
      "x": -24,
      "y": 41,
      "z": 9,
      "name": "Soil_Seaweed_Block"
    },
    {
      "x": -24,
      "y": 39,
      "z": 10,
      "name": "Soil_Clay_Green"
    },
    {
      "x": -24,
      "y": 40,
      "z": 10,
      "name": "Soil_Clay_Green"
    },
    {
      "x": -24,
      "y": 41,
      "z": 10,
      "name": "Soil_Clay_Lime"
    },
    {
      "x": -24,
      "y": 42,
      "z": 10,
      "name": "Plant_Grass_Sharp"
    },
    {
      "x": -24,
      "y": 39,
      "z": 11,
      "name": "Soil_Clay_Green"
    },
    {
      "x": -24,
      "y": 40,
      "z": 11,
      "name": "Soil_Seaweed_Block"
    },
    {
      "x": -24,
      "y": 41,
      "z": 11,
      "name": "Soil_Seaweed_Block"
    },
    {
      "x": -24,
      "y": 42,
      "z": 11,
      "name": "Soil_Clay_Lime"
    },
    {
      "x": -24,
      "y": 43,
      "z": 11,
      "name": "Plant_Grass_Sharp"
    },
    {
      "x": -24,
      "y": 40,
      "z": 12,
      "name": "Soil_Clay_Green"
    },
    {
      "x": -24,
      "y": 41,
      "z": 12,
      "name": "Soil_Seaweed_Block"
    },
    {
      "x": -24,
      "y": 42,
      "z": 12,
      "name": "Soil_Clay_Lime"
    },
    {
      "x": -24,
      "y": 43,
      "z": 12,
      "name": "Plant_Grass_Sharp"
    },
    {
      "x": -24,
      "y": 40,
      "z": 13,
      "name": "Soil_Clay_Green"
    },
    {
      "x": -24,
      "y": 41,
      "z": 13,
      "name": "Soil_Seaweed_Block"
    },
    {
      "x": -24,
      "y": 42,
      "z": 13,
      "name": "Soil_Clay_Lime"
    },
    {
      "x": -24,
      "y": 43,
      "z": 13,
      "name": "Plant_Grass_Sharp"
    },
    {
      "x": -24,
      "y": 40,
      "z": 14,
      "name": "Soil_Clay_Green"
    },
    {
      "x": -24,
      "y": 41,
      "z": 14,
      "name": "Soil_Clay_Green"
    },
    {
      "x": -24,
      "y": 42,
      "z": 14,
      "name": "Soil_Clay_Lime"
    },
    {
      "x": -24,
      "y": 43,
      "z": 14,
      "name": "Plant_Grass_Sharp"
    },
    {
      "x": -24,
      "y": 3,
      "z": 18,
      "name": "Soil_Clay_Green"
    },
    {
      "x": -24,
      "y": 4,
      "z": 18,
      "name": "Soil_Clay_Green"
    },
    {
      "x": -24,
      "y": 5,
      "z": 18,
      "name": "Soil_Clay_Green"
    },
    {
      "x": -24,
      "y": 6,
      "z": 18,
      "name": "Soil_Seaweed_Block"
    },
    {
      "x": -24,
      "y": 3,
      "z": 19,
      "name": "Soil_Clay_Green"
    },
    {
      "x": -24,
      "y": 4,
      "z": 19,
      "name": "Soil_Clay_Green"
    },
    {
      "x": -24,
      "y": 5,
      "z": 19,
      "name": "Soil_Seaweed_Block"
    },
    {
      "x": -24,
      "y": 6,
      "z": 19,
      "name": "Soil_Seaweed_Block"
    },
    {
      "x": -24,
      "y": 7,
      "z": 19,
      "name": "Soil_Seaweed_Block"
    },
    {
      "x": -24,
      "y": 3,
      "z": 20,
      "name": "Soil_Clay_Green"
    },
    {
      "x": -24,
      "y": 4,
      "z": 20,
      "name": "Soil_Clay_Green"
    },
    {
      "x": -24,
      "y": 5,
      "z": 20,
      "name": "Soil_Clay_Green"
    },
    {
      "x": -24,
      "y": 6,
      "z": 20,
      "name": "Soil_Seaweed_Block"
    },
    {
      "x": -24,
      "y": 7,
      "z": 20,
      "name": "Soil_Seaweed_Block"
    },
    {
      "x": -24,
      "y": 8,
      "z": 20,
      "name": "Soil_Seaweed_Block"
    },
    {
      "x": -24,
      "y": 9,
      "z": 20,
      "name": "Soil_Seaweed_Block"
    },
    {
      "x": -24,
      "y": 6,
      "z": 21,
      "name": "Soil_Clay_Green"
    },
    {
      "x": -24,
      "y": 7,
      "z": 21,
      "name": "Soil_Clay_Green"
    },
    {
      "x": -24,
      "y": 8,
      "z": 21,
      "name": "Soil_Seaweed_Block"
    },
    {
      "x": -24,
      "y": 9,
      "z": 21,
      "name": "Soil_Seaweed_Block"
    },
    {
      "x": -24,
      "y": 18,
      "z": 25,
      "name": "Soil_Clay_Green"
    },
    {
      "x": -24,
      "y": 19,
      "z": 25,
      "name": "Soil_Seaweed_Block"
    },
    {
      "x": -24,
      "y": 18,
      "z": 26,
      "name": "Soil_Clay_Green"
    },
    {
      "x": -24,
      "y": 19,
      "z": 26,
      "name": "Soil_Clay_Green"
    },
    {
      "x": -24,
      "y": 21,
      "z": 27,
      "name": "Soil_Clay_Green"
    },
    {
      "x": -24,
      "y": 22,
      "z": 27,
      "name": "Soil_Clay_Green"
    },
    {
      "x": -24,
      "y": 23,
      "z": 27,
      "name": "Soil_Seaweed_Block"
    },
    {
      "x": -24,
      "y": 24,
      "z": 27,
      "name": "Soil_Seaweed_Block"
    },
    {
      "x": -24,
      "y": 22,
      "z": 28,
      "name": "Soil_Clay_Green"
    },
    {
      "x": -24,
      "y": 23,
      "z": 28,
      "name": "Soil_Seaweed_Block"
    },
    {
      "x": -24,
      "y": 24,
      "z": 28,
      "name": "Soil_Seaweed_Block"
    },
    {
      "x": -24,
      "y": 25,
      "z": 28,
      "name": "Soil_Clay_Lime"
    },
    {
      "x": -24,
      "y": 26,
      "z": 28,
      "name": "Plant_Grass_Sharp"
    },
    {
      "x": -24,
      "y": 21,
      "z": 29,
      "name": "Soil_Clay_Green"
    },
    {
      "x": -24,
      "y": 22,
      "z": 29,
      "name": "Soil_Clay_Green"
    },
    {
      "x": -24,
      "y": 23,
      "z": 29,
      "name": "Soil_Seaweed_Block"
    },
    {
      "x": -24,
      "y": 24,
      "z": 29,
      "name": "Soil_Seaweed_Block"
    },
    {
      "x": -24,
      "y": 25,
      "z": 29,
      "name": "Soil_Clay_Lime"
    },
    {
      "x": -24,
      "y": 26,
      "z": 29,
      "name": "Plant_Grass_Sharp"
    },
    {
      "x": -24,
      "y": 18,
      "z": 30,
      "name": "Soil_Clay_Green"
    },
    {
      "x": -24,
      "y": 23,
      "z": 30,
      "name": "Soil_Clay_Green"
    },
    {
      "x": -24,
      "y": 24,
      "z": 30,
      "name": "Soil_Seaweed_Block"
    },
    {
      "x": -24,
      "y": 25,
      "z": 30,
      "name": "Soil_Seaweed_Block"
    },
    {
      "x": -24,
      "y": 26,
      "z": 30,
      "name": "Soil_Clay_Lime"
    },
    {
      "x": -24,
      "y": 27,
      "z": 30,
      "name": "Plant_Grass_Sharp"
    },
    {
      "x": -24,
      "y": 17,
      "z": 31,
      "name": "Soil_Clay_Green"
    },
    {
      "x": -24,
      "y": 18,
      "z": 31,
      "name": "Soil_Clay_Green"
    },
    {
      "x": -24,
      "y": 19,
      "z": 31,
      "name": "Soil_Seaweed_Block"
    },
    {
      "x": -24,
      "y": 24,
      "z": 31,
      "name": "Soil_Clay_Green"
    },
    {
      "x": -24,
      "y": 25,
      "z": 31,
      "name": "Soil_Seaweed_Block"
    },
    {
      "x": -24,
      "y": 26,
      "z": 31,
      "name": "Soil_Clay_Lime"
    },
    {
      "x": -24,
      "y": 27,
      "z": 31,
      "name": "Plant_Grass_Sharp"
    },
    {
      "x": -24,
      "y": 16,
      "z": 32,
      "name": "Soil_Clay_Green"
    },
    {
      "x": -24,
      "y": 17,
      "z": 32,
      "name": "Soil_Seaweed_Block"
    },
    {
      "x": -24,
      "y": 18,
      "z": 32,
      "name": "Soil_Seaweed_Block"
    },
    {
      "x": -24,
      "y": 15,
      "z": 33,
      "name": "Soil_Clay_Green"
    },
    {
      "x": -24,
      "y": 16,
      "z": 33,
      "name": "Soil_Seaweed_Block"
    },
    {
      "x": -24,
      "y": 17,
      "z": 33,
      "name": "Soil_Clay_Lime"
    },
    {
      "x": -24,
      "y": 18,
      "z": 33,
      "name": "Plant_Grass_Sharp"
    },
    {
      "x": -24,
      "y": 14,
      "z": 34,
      "name": "Soil_Clay_Green"
    },
    {
      "x": -24,
      "y": 15,
      "z": 34,
      "name": "Soil_Seaweed_Block"
    },
    {
      "x": -24,
      "y": 16,
      "z": 34,
      "name": "Soil_Seaweed_Block"
    },
    {
      "x": -24,
      "y": 17,
      "z": 34,
      "name": "Soil_Clay_Lime"
    },
    {
      "x": -24,
      "y": 18,
      "z": 34,
      "name": "Plant_Grass_Sharp"
    },
    {
      "x": -24,
      "y": 27,
      "z": 34,
      "name": "Soil_Seaweed_Block"
    },
    {
      "x": -24,
      "y": 14,
      "z": 35,
      "name": "Soil_Clay_Green"
    },
    {
      "x": -24,
      "y": 15,
      "z": 35,
      "name": "Soil_Clay_Green"
    },
    {
      "x": -24,
      "y": 27,
      "z": 35,
      "name": "Soil_Clay_Green"
    },
    {
      "x": -24,
      "y": 28,
      "z": 35,
      "name": "Soil_Clay_Lime"
    },
    {
      "x": -24,
      "y": 29,
      "z": 35,
      "name": "Plant_Grass_Sharp"
    },
    {
      "x": -24,
      "y": 28,
      "z": 36,
      "name": "Soil_Seaweed_Block"
    },
    {
      "x": -24,
      "y": 28,
      "z": 37,
      "name": "Soil_Seaweed_Block"
    },
    {
      "x": -23,
      "y": 36,
      "z": 4,
      "name": "Soil_Clay_Green"
    },
    {
      "x": -23,
      "y": 37,
      "z": 4,
      "name": "Soil_Clay_Green"
    },
    {
      "x": -23,
      "y": 37,
      "z": 5,
      "name": "Soil_Clay_Green"
    },
    {
      "x": -23,
      "y": 38,
      "z": 5,
      "name": "Soil_Seaweed_Block"
    },
    {
      "x": -23,
      "y": 37,
      "z": 8,
      "name": "Soil_Clay_Green"
    },
    {
      "x": -23,
      "y": 38,
      "z": 8,
      "name": "Soil_Clay_Green"
    },
    {
      "x": -23,
      "y": 39,
      "z": 8,
      "name": "Soil_Seaweed_Block"
    },
    {
      "x": -23,
      "y": 38,
      "z": 9,
      "name": "Soil_Clay_Green"
    },
    {
      "x": -23,
      "y": 39,
      "z": 9,
      "name": "Soil_Clay_Green"
    },
    {
      "x": -23,
      "y": 40,
      "z": 9,
      "name": "Soil_Seaweed_Block"
    },
    {
      "x": -23,
      "y": 41,
      "z": 9,
      "name": "Soil_Clay_Lime"
    },
    {
      "x": -23,
      "y": 42,
      "z": 9,
      "name": "Plant_Grass_Sharp"
    },
    {
      "x": -23,
      "y": 39,
      "z": 10,
      "name": "Soil_Clay_Green"
    },
    {
      "x": -23,
      "y": 40,
      "z": 10,
      "name": "Soil_Seaweed_Block"
    },
    {
      "x": -23,
      "y": 41,
      "z": 10,
      "name": "Soil_Clay_Lime"
    },
    {
      "x": -23,
      "y": 42,
      "z": 10,
      "name": "Plant_Grass_Sharp"
    },
    {
      "x": -23,
      "y": 39,
      "z": 11,
      "name": "Soil_Clay_Green"
    },
    {
      "x": -23,
      "y": 40,
      "z": 11,
      "name": "Soil_Seaweed_Block"
    },
    {
      "x": -23,
      "y": 41,
      "z": 11,
      "name": "Soil_Clay_Lime"
    },
    {
      "x": -23,
      "y": 42,
      "z": 11,
      "name": "Plant_Grass_Sharp"
    },
    {
      "x": -23,
      "y": 40,
      "z": 12,
      "name": "Soil_Clay_Green"
    },
    {
      "x": -23,
      "y": 41,
      "z": 12,
      "name": "Soil_Clay_Lime"
    },
    {
      "x": -23,
      "y": 42,
      "z": 12,
      "name": "Plant_Grass_Sharp"
    },
    {
      "x": -23,
      "y": 40,
      "z": 13,
      "name": "Soil_Clay_Green"
    },
    {
      "x": -23,
      "y": 41,
      "z": 13,
      "name": "Soil_Seaweed_Block"
    },
    {
      "x": -23,
      "y": 40,
      "z": 14,
      "name": "Soil_Clay_Green"
    },
    {
      "x": -23,
      "y": 41,
      "z": 14,
      "name": "Soil_Seaweed_Block"
    },
    {
      "x": -23,
      "y": 5,
      "z": 18,
      "name": "Soil_Clay_Green"
    },
    {
      "x": -23,
      "y": 6,
      "z": 18,
      "name": "Soil_Clay_Green"
    },
    {
      "x": -23,
      "y": 7,
      "z": 18,
      "name": "Soil_Seaweed_Block"
    },
    {
      "x": -23,
      "y": 8,
      "z": 18,
      "name": "Soil_Seaweed_Block"
    },
    {
      "x": -23,
      "y": 9,
      "z": 18,
      "name": "Soil_Seaweed_Block"
    },
    {
      "x": -23,
      "y": 5,
      "z": 19,
      "name": "Soil_Clay_Green"
    },
    {
      "x": -23,
      "y": 6,
      "z": 19,
      "name": "Soil_Seaweed_Block"
    },
    {
      "x": -23,
      "y": 7,
      "z": 19,
      "name": "Soil_Seaweed_Block"
    },
    {
      "x": -23,
      "y": 8,
      "z": 19,
      "name": "Soil_Seaweed_Block"
    },
    {
      "x": -23,
      "y": 9,
      "z": 19,
      "name": "Soil_Seaweed_Block"
    },
    {
      "x": -23,
      "y": 4,
      "z": 20,
      "name": "Soil_Clay_Green"
    },
    {
      "x": -23,
      "y": 5,
      "z": 20,
      "name": "Soil_Clay_Green"
    },
    {
      "x": -23,
      "y": 6,
      "z": 20,
      "name": "Soil_Seaweed_Block"
    },
    {
      "x": -23,
      "y": 7,
      "z": 20,
      "name": "Soil_Seaweed_Block"
    },
    {
      "x": -23,
      "y": 8,
      "z": 20,
      "name": "Soil_Seaweed_Block"
    },
    {
      "x": -23,
      "y": 9,
      "z": 20,
      "name": "Soil_Seaweed_Block"
    },
    {
      "x": -23,
      "y": 10,
      "z": 20,
      "name": "Soil_Seaweed_Block"
    },
    {
      "x": -23,
      "y": 6,
      "z": 21,
      "name": "Soil_Clay_Green"
    },
    {
      "x": -23,
      "y": 7,
      "z": 21,
      "name": "Soil_Seaweed_Block"
    },
    {
      "x": -23,
      "y": 8,
      "z": 21,
      "name": "Soil_Seaweed_Block"
    },
    {
      "x": -23,
      "y": 9,
      "z": 21,
      "name": "Soil_Seaweed_Block"
    },
    {
      "x": -23,
      "y": 10,
      "z": 21,
      "name": "Soil_Seaweed_Block"
    },
    {
      "x": -23,
      "y": 7,
      "z": 22,
      "name": "Soil_Clay_Green"
    },
    {
      "x": -23,
      "y": 8,
      "z": 22,
      "name": "Soil_Clay_Green"
    },
    {
      "x": -23,
      "y": 9,
      "z": 22,
      "name": "Soil_Seaweed_Block"
    },
    {
      "x": -23,
      "y": 9,
      "z": 23,
      "name": "Soil_Clay_Green"
    },
    {
      "x": -23,
      "y": 10,
      "z": 23,
      "name": "Soil_Seaweed_Block"
    },
    {
      "x": -23,
      "y": 16,
      "z": 25,
      "name": "Soil_Clay_Green"
    },
    {
      "x": -23,
      "y": 17,
      "z": 25,
      "name": "Soil_Clay_Green"
    },
    {
      "x": -23,
      "y": 18,
      "z": 25,
      "name": "Soil_Seaweed_Block"
    },
    {
      "x": -23,
      "y": 19,
      "z": 25,
      "name": "Soil_Seaweed_Block"
    },
    {
      "x": -23,
      "y": 18,
      "z": 26,
      "name": "Soil_Clay_Green"
    },
    {
      "x": -23,
      "y": 19,
      "z": 26,
      "name": "Soil_Seaweed_Block"
    },
    {
      "x": -23,
      "y": 20,
      "z": 26,
      "name": "Soil_Seaweed_Block"
    },
    {
      "x": -23,
      "y": 21,
      "z": 26,
      "name": "Soil_Seaweed_Block"
    },
    {
      "x": -23,
      "y": 22,
      "z": 26,
      "name": "Soil_Seaweed_Block"
    },
    {
      "x": -23,
      "y": 23,
      "z": 26,
      "name": "Soil_Seaweed_Block"
    },
    {
      "x": -23,
      "y": 18,
      "z": 27,
      "name": "Soil_Clay_Green"
    },
    {
      "x": -23,
      "y": 19,
      "z": 27,
      "name": "Soil_Clay_Green"
    },
    {
      "x": -23,
      "y": 20,
      "z": 27,
      "name": "Soil_Seaweed_Block"
    },
    {
      "x": -23,
      "y": 21,
      "z": 27,
      "name": "Soil_Seaweed_Block"
    },
    {
      "x": -23,
      "y": 22,
      "z": 27,
      "name": "Soil_Seaweed_Block"
    },
    {
      "x": -23,
      "y": 23,
      "z": 27,
      "name": "Soil_Seaweed_Block"
    },
    {
      "x": -23,
      "y": 18,
      "z": 28,
      "name": "Soil_Clay_Green"
    },
    {
      "x": -23,
      "y": 19,
      "z": 28,
      "name": "Soil_Clay_Green"
    },
    {
      "x": -23,
      "y": 20,
      "z": 28,
      "name": "Soil_Clay_Green"
    },
    {
      "x": -23,
      "y": 21,
      "z": 28,
      "name": "Soil_Clay_Green"
    },
    {
      "x": -23,
      "y": 22,
      "z": 28,
      "name": "Soil_Seaweed_Block"
    },
    {
      "x": -23,
      "y": 23,
      "z": 28,
      "name": "Soil_Seaweed_Block"
    },
    {
      "x": -23,
      "y": 24,
      "z": 28,
      "name": "Soil_Clay_Lime"
    },
    {
      "x": -23,
      "y": 25,
      "z": 28,
      "name": "Plant_Grass_Sharp"
    },
    {
      "x": -23,
      "y": 18,
      "z": 29,
      "name": "Soil_Clay_Green"
    },
    {
      "x": -23,
      "y": 19,
      "z": 29,
      "name": "Soil_Clay_Green"
    },
    {
      "x": -23,
      "y": 20,
      "z": 29,
      "name": "Soil_Seaweed_Block"
    },
    {
      "x": -23,
      "y": 21,
      "z": 29,
      "name": "Soil_Clay_Green"
    },
    {
      "x": -23,
      "y": 22,
      "z": 29,
      "name": "Soil_Seaweed_Block"
    },
    {
      "x": -23,
      "y": 23,
      "z": 29,
      "name": "Soil_Seaweed_Block"
    },
    {
      "x": -23,
      "y": 24,
      "z": 29,
      "name": "Soil_Seaweed_Block"
    },
    {
      "x": -23,
      "y": 18,
      "z": 30,
      "name": "Soil_Clay_Green"
    },
    {
      "x": -23,
      "y": 19,
      "z": 30,
      "name": "Soil_Clay_Green"
    },
    {
      "x": -23,
      "y": 20,
      "z": 30,
      "name": "Soil_Seaweed_Block"
    },
    {
      "x": -23,
      "y": 22,
      "z": 30,
      "name": "Soil_Clay_Green"
    },
    {
      "x": -23,
      "y": 23,
      "z": 30,
      "name": "Soil_Clay_Green"
    },
    {
      "x": -23,
      "y": 24,
      "z": 30,
      "name": "Soil_Seaweed_Block"
    },
    {
      "x": -23,
      "y": 25,
      "z": 30,
      "name": "Soil_Seaweed_Block"
    },
    {
      "x": -23,
      "y": 17,
      "z": 31,
      "name": "Soil_Clay_Green"
    },
    {
      "x": -23,
      "y": 18,
      "z": 31,
      "name": "Soil_Seaweed_Block"
    },
    {
      "x": -23,
      "y": 19,
      "z": 31,
      "name": "Soil_Seaweed_Block"
    },
    {
      "x": -23,
      "y": 20,
      "z": 31,
      "name": "Soil_Seaweed_Block"
    },
    {
      "x": -23,
      "y": 24,
      "z": 31,
      "name": "Soil_Clay_Green"
    },
    {
      "x": -23,
      "y": 25,
      "z": 31,
      "name": "Soil_Seaweed_Block"
    },
    {
      "x": -23,
      "y": 16,
      "z": 32,
      "name": "Soil_Clay_Green"
    },
    {
      "x": -23,
      "y": 17,
      "z": 32,
      "name": "Soil_Clay_Green"
    },
    {
      "x": -23,
      "y": 18,
      "z": 32,
      "name": "Soil_Seaweed_Block"
    },
    {
      "x": -23,
      "y": 19,
      "z": 32,
      "name": "Soil_Seaweed_Block"
    },
    {
      "x": -23,
      "y": 25,
      "z": 32,
      "name": "Soil_Clay_Green"
    },
    {
      "x": -23,
      "y": 26,
      "z": 32,
      "name": "Soil_Seaweed_Block"
    },
    {
      "x": -23,
      "y": 27,
      "z": 32,
      "name": "Soil_Clay_Lime"
    },
    {
      "x": -23,
      "y": 28,
      "z": 32,
      "name": "Plant_Grass_Sharp"
    },
    {
      "x": -23,
      "y": 15,
      "z": 33,
      "name": "Soil_Clay_Green"
    },
    {
      "x": -23,
      "y": 16,
      "z": 33,
      "name": "Soil_Clay_Green"
    },
    {
      "x": -23,
      "y": 17,
      "z": 33,
      "name": "Soil_Seaweed_Block"
    },
    {
      "x": -23,
      "y": 26,
      "z": 33,
      "name": "Soil_Clay_Green"
    },
    {
      "x": -23,
      "y": 27,
      "z": 33,
      "name": "Soil_Clay_Lime"
    },
    {
      "x": -23,
      "y": 28,
      "z": 33,
      "name": "Plant_Grass_Sharp"
    },
    {
      "x": -23,
      "y": 15,
      "z": 34,
      "name": "Soil_Clay_Green"
    },
    {
      "x": -23,
      "y": 16,
      "z": 34,
      "name": "Soil_Seaweed_Block"
    },
    {
      "x": -23,
      "y": 17,
      "z": 34,
      "name": "Soil_Seaweed_Block"
    },
    {
      "x": -23,
      "y": 26,
      "z": 34,
      "name": "Soil_Clay_Green"
    },
    {
      "x": -23,
      "y": 27,
      "z": 34,
      "name": "Soil_Seaweed_Block"
    },
    {
      "x": -23,
      "y": 27,
      "z": 35,
      "name": "Soil_Clay_Green"
    },
    {
      "x": -23,
      "y": 28,
      "z": 35,
      "name": "Soil_Clay_Lime"
    },
    {
      "x": -23,
      "y": 29,
      "z": 35,
      "name": "Plant_Grass_Sharp"
    },
    {
      "x": -23,
      "y": 28,
      "z": 36,
      "name": "Soil_Clay_Lime"
    },
    {
      "x": -23,
      "y": 29,
      "z": 36,
      "name": "Plant_Grass_Sharp"
    },
    {
      "x": -23,
      "y": 28,
      "z": 37,
      "name": "Soil_Seaweed_Block"
    },
    {
      "x": -23,
      "y": 28,
      "z": 38,
      "name": "Soil_Clay_Lime"
    },
    {
      "x": -23,
      "y": 29,
      "z": 38,
      "name": "Soil_Clay_Lime"
    },
    {
      "x": -23,
      "y": 30,
      "z": 38,
      "name": "Plant_Grass_Sharp"
    },
    {
      "x": -23,
      "y": 28,
      "z": 39,
      "name": "Soil_Clay_Lime"
    },
    {
      "x": -23,
      "y": 29,
      "z": 39,
      "name": "Soil_Clay_Lime"
    },
    {
      "x": -23,
      "y": 30,
      "z": 39,
      "name": "Plant_Grass_Sharp"
    },
    {
      "x": -22,
      "y": 37,
      "z": 5,
      "name": "Soil_Clay_Green"
    },
    {
      "x": -22,
      "y": 38,
      "z": 5,
      "name": "Soil_Seaweed_Block"
    },
    {
      "x": -22,
      "y": 37,
      "z": 6,
      "name": "Soil_Clay_Green"
    },
    {
      "x": -22,
      "y": 38,
      "z": 6,
      "name": "Soil_Seaweed_Block"
    },
    {
      "x": -22,
      "y": 37,
      "z": 7,
      "name": "Soil_Clay_Green"
    },
    {
      "x": -22,
      "y": 38,
      "z": 7,
      "name": "Soil_Seaweed_Block"
    },
    {
      "x": -22,
      "y": 39,
      "z": 7,
      "name": "Soil_Clay_Lime"
    },
    {
      "x": -22,
      "y": 40,
      "z": 7,
      "name": "Plant_Grass_Sharp"
    },
    {
      "x": -22,
      "y": 36,
      "z": 8,
      "name": "Soil_Clay_Green"
    },
    {
      "x": -22,
      "y": 37,
      "z": 8,
      "name": "Soil_Clay_Green"
    },
    {
      "x": -22,
      "y": 38,
      "z": 8,
      "name": "Soil_Seaweed_Block"
    },
    {
      "x": -22,
      "y": 39,
      "z": 8,
      "name": "Soil_Clay_Lime"
    },
    {
      "x": -22,
      "y": 40,
      "z": 8,
      "name": "Plant_Grass_Sharp"
    },
    {
      "x": -22,
      "y": 38,
      "z": 9,
      "name": "Soil_Clay_Green"
    },
    {
      "x": -22,
      "y": 39,
      "z": 9,
      "name": "Soil_Seaweed_Block"
    },
    {
      "x": -22,
      "y": 40,
      "z": 9,
      "name": "Soil_Clay_Lime"
    },
    {
      "x": -22,
      "y": 41,
      "z": 9,
      "name": "Soil_Clay_Lime"
    },
    {
      "x": -22,
      "y": 42,
      "z": 9,
      "name": "Plant_Grass_Sharp"
    },
    {
      "x": -22,
      "y": 39,
      "z": 10,
      "name": "Soil_Clay_Green"
    },
    {
      "x": -22,
      "y": 40,
      "z": 10,
      "name": "Soil_Seaweed_Block"
    },
    {
      "x": -22,
      "y": 41,
      "z": 10,
      "name": "Soil_Clay_Lime"
    },
    {
      "x": -22,
      "y": 42,
      "z": 10,
      "name": "Plant_Grass_Sharp"
    },
    {
      "x": -22,
      "y": 39,
      "z": 11,
      "name": "Soil_Clay_Green"
    },
    {
      "x": -22,
      "y": 40,
      "z": 11,
      "name": "Soil_Clay_Green"
    },
    {
      "x": -22,
      "y": 41,
      "z": 11,
      "name": "Soil_Seaweed_Block"
    },
    {
      "x": -22,
      "y": 40,
      "z": 13,
      "name": "Soil_Clay_Green"
    },
    {
      "x": -22,
      "y": 39,
      "z": 14,
      "name": "Soil_Clay_Green"
    },
    {
      "x": -22,
      "y": 40,
      "z": 14,
      "name": "Soil_Clay_Green"
    },
    {
      "x": -22,
      "y": 6,
      "z": 19,
      "name": "Soil_Clay_Green"
    },
    {
      "x": -22,
      "y": 7,
      "z": 19,
      "name": "Soil_Clay_Green"
    },
    {
      "x": -22,
      "y": 8,
      "z": 19,
      "name": "Soil_Seaweed_Block"
    },
    {
      "x": -22,
      "y": 9,
      "z": 19,
      "name": "Soil_Seaweed_Block"
    },
    {
      "x": -22,
      "y": 10,
      "z": 19,
      "name": "Soil_Seaweed_Block"
    },
    {
      "x": -22,
      "y": 6,
      "z": 20,
      "name": "Soil_Clay_Green"
    },
    {
      "x": -22,
      "y": 7,
      "z": 20,
      "name": "Soil_Seaweed_Block"
    },
    {
      "x": -22,
      "y": 8,
      "z": 20,
      "name": "Soil_Seaweed_Block"
    },
    {
      "x": -22,
      "y": 9,
      "z": 20,
      "name": "Soil_Seaweed_Block"
    },
    {
      "x": -22,
      "y": 10,
      "z": 20,
      "name": "Soil_Seaweed_Block"
    },
    {
      "x": -22,
      "y": 11,
      "z": 20,
      "name": "Soil_Clay_Lime"
    },
    {
      "x": -22,
      "y": 12,
      "z": 20,
      "name": "Plant_Grass_Sharp"
    },
    {
      "x": -22,
      "y": 6,
      "z": 21,
      "name": "Soil_Clay_Green"
    },
    {
      "x": -22,
      "y": 7,
      "z": 21,
      "name": "Soil_Seaweed_Block"
    },
    {
      "x": -22,
      "y": 8,
      "z": 21,
      "name": "Soil_Seaweed_Block"
    },
    {
      "x": -22,
      "y": 9,
      "z": 21,
      "name": "Soil_Seaweed_Block"
    },
    {
      "x": -22,
      "y": 10,
      "z": 21,
      "name": "Soil_Seaweed_Block"
    },
    {
      "x": -22,
      "y": 11,
      "z": 21,
      "name": "Soil_Clay_Lime"
    },
    {
      "x": -22,
      "y": 12,
      "z": 21,
      "name": "Plant_Grass_Sharp"
    },
    {
      "x": -22,
      "y": 7,
      "z": 22,
      "name": "Soil_Clay_Green"
    },
    {
      "x": -22,
      "y": 8,
      "z": 22,
      "name": "Soil_Seaweed_Block"
    },
    {
      "x": -22,
      "y": 9,
      "z": 22,
      "name": "Soil_Seaweed_Block"
    },
    {
      "x": -22,
      "y": 10,
      "z": 22,
      "name": "Soil_Seaweed_Block"
    },
    {
      "x": -22,
      "y": 11,
      "z": 22,
      "name": "Soil_Seaweed_Block"
    },
    {
      "x": -22,
      "y": 12,
      "z": 22,
      "name": "Soil_Seaweed_Block"
    },
    {
      "x": -22,
      "y": 8,
      "z": 23,
      "name": "Soil_Clay_Green"
    },
    {
      "x": -22,
      "y": 9,
      "z": 23,
      "name": "Soil_Seaweed_Block"
    },
    {
      "x": -22,
      "y": 10,
      "z": 23,
      "name": "Soil_Seaweed_Block"
    },
    {
      "x": -22,
      "y": 11,
      "z": 23,
      "name": "Soil_Seaweed_Block"
    },
    {
      "x": -22,
      "y": 9,
      "z": 24,
      "name": "Soil_Clay_Green"
    },
    {
      "x": -22,
      "y": 10,
      "z": 24,
      "name": "Soil_Clay_Green"
    },
    {
      "x": -22,
      "y": 11,
      "z": 24,
      "name": "Soil_Seaweed_Block"
    },
    {
      "x": -22,
      "y": 12,
      "z": 24,
      "name": "Soil_Seaweed_Block"
    },
    {
      "x": -22,
      "y": 16,
      "z": 24,
      "name": "Soil_Clay_Green"
    },
    {
      "x": -22,
      "y": 17,
      "z": 24,
      "name": "Soil_Clay_Green"
    },
    {
      "x": -22,
      "y": 18,
      "z": 24,
      "name": "Soil_Seaweed_Block"
    },
    {
      "x": -22,
      "y": 15,
      "z": 25,
      "name": "Soil_Clay_Green"
    },
    {
      "x": -22,
      "y": 16,
      "z": 25,
      "name": "Soil_Seaweed_Block"
    },
    {
      "x": -22,
      "y": 17,
      "z": 25,
      "name": "Soil_Seaweed_Block"
    },
    {
      "x": -22,
      "y": 18,
      "z": 25,
      "name": "Soil_Seaweed_Block"
    },
    {
      "x": -22,
      "y": 19,
      "z": 25,
      "name": "Soil_Seaweed_Block"
    },
    {
      "x": -22,
      "y": 15,
      "z": 26,
      "name": "Soil_Clay_Green"
    },
    {
      "x": -22,
      "y": 16,
      "z": 26,
      "name": "Soil_Clay_Green"
    },
    {
      "x": -22,
      "y": 17,
      "z": 26,
      "name": "Soil_Clay_Green"
    },
    {
      "x": -22,
      "y": 18,
      "z": 26,
      "name": "Soil_Seaweed_Block"
    },
    {
      "x": -22,
      "y": 19,
      "z": 26,
      "name": "Soil_Seaweed_Block"
    },
    {
      "x": -22,
      "y": 20,
      "z": 26,
      "name": "Soil_Seaweed_Block"
    },
    {
      "x": -22,
      "y": 21,
      "z": 26,
      "name": "Soil_Seaweed_Block"
    },
    {
      "x": -22,
      "y": 18,
      "z": 27,
      "name": "Soil_Clay_Green"
    },
    {
      "x": -22,
      "y": 19,
      "z": 27,
      "name": "Soil_Seaweed_Block"
    },
    {
      "x": -22,
      "y": 20,
      "z": 27,
      "name": "Soil_Seaweed_Block"
    },
    {
      "x": -22,
      "y": 21,
      "z": 27,
      "name": "Soil_Seaweed_Block"
    },
    {
      "x": -22,
      "y": 22,
      "z": 27,
      "name": "Soil_Seaweed_Block"
    },
    {
      "x": -22,
      "y": 23,
      "z": 27,
      "name": "Soil_Seaweed_Block"
    },
    {
      "x": -22,
      "y": 18,
      "z": 28,
      "name": "Soil_Clay_Green"
    },
    {
      "x": -22,
      "y": 19,
      "z": 28,
      "name": "Soil_Seaweed_Block"
    },
    {
      "x": -22,
      "y": 20,
      "z": 28,
      "name": "Soil_Seaweed_Block"
    },
    {
      "x": -22,
      "y": 21,
      "z": 28,
      "name": "Soil_Seaweed_Block"
    },
    {
      "x": -22,
      "y": 22,
      "z": 28,
      "name": "Soil_Seaweed_Block"
    },
    {
      "x": -22,
      "y": 23,
      "z": 28,
      "name": "Soil_Clay_Lime"
    },
    {
      "x": -22,
      "y": 24,
      "z": 28,
      "name": "Soil_Clay_Lime"
    },
    {
      "x": -22,
      "y": 25,
      "z": 28,
      "name": "Plant_Grass_Sharp"
    },
    {
      "x": -22,
      "y": 18,
      "z": 29,
      "name": "Soil_Clay_Green"
    },
    {
      "x": -22,
      "y": 19,
      "z": 29,
      "name": "Soil_Seaweed_Block"
    },
    {
      "x": -22,
      "y": 20,
      "z": 29,
      "name": "Soil_Seaweed_Block"
    },
    {
      "x": -22,
      "y": 21,
      "z": 29,
      "name": "Soil_Seaweed_Block"
    },
    {
      "x": -22,
      "y": 22,
      "z": 29,
      "name": "Soil_Seaweed_Block"
    },
    {
      "x": -22,
      "y": 23,
      "z": 29,
      "name": "Soil_Seaweed_Block"
    },
    {
      "x": -22,
      "y": 24,
      "z": 29,
      "name": "Soil_Seaweed_Block"
    },
    {
      "x": -22,
      "y": 18,
      "z": 30,
      "name": "Soil_Clay_Green"
    },
    {
      "x": -22,
      "y": 19,
      "z": 30,
      "name": "Soil_Seaweed_Block"
    },
    {
      "x": -22,
      "y": 20,
      "z": 30,
      "name": "Soil_Seaweed_Block"
    },
    {
      "x": -22,
      "y": 21,
      "z": 30,
      "name": "Soil_Seaweed_Block"
    },
    {
      "x": -22,
      "y": 17,
      "z": 31,
      "name": "Soil_Clay_Green"
    },
    {
      "x": -22,
      "y": 18,
      "z": 31,
      "name": "Soil_Clay_Green"
    },
    {
      "x": -22,
      "y": 19,
      "z": 31,
      "name": "Soil_Seaweed_Block"
    },
    {
      "x": -22,
      "y": 20,
      "z": 31,
      "name": "Soil_Seaweed_Block"
    },
    {
      "x": -22,
      "y": 28,
      "z": 37,
      "name": "Soil_Seaweed_Block"
    },
    {
      "x": -22,
      "y": 27,
      "z": 39,
      "name": "Soil_Clay_Green"
    },
    {
      "x": -22,
      "y": 26,
      "z": 40,
      "name": "Soil_Clay_Green"
    },
    {
      "x": -22,
      "y": 27,
      "z": 40,
      "name": "Soil_Clay_Green"
    },
    {
      "x": -22,
      "y": 26,
      "z": 41,
      "name": "Soil_Clay_Green"
    },
    {
      "x": -22,
      "y": 27,
      "z": 41,
      "name": "Soil_Seaweed_Block"
    },
    {
      "x": -22,
      "y": 25,
      "z": 42,
      "name": "Soil_Clay_Green"
    },
    {
      "x": -22,
      "y": 26,
      "z": 42,
      "name": "Soil_Clay_Green"
    },
    {
      "x": -22,
      "y": 27,
      "z": 42,
      "name": "Soil_Seaweed_Block"
    },
    {
      "x": -21,
      "y": 37,
      "z": 6,
      "name": "Soil_Clay_Green"
    },
    {
      "x": -21,
      "y": 36,
      "z": 7,
      "name": "Soil_Clay_Green"
    },
    {
      "x": -21,
      "y": 37,
      "z": 7,
      "name": "Soil_Seaweed_Block"
    },
    {
      "x": -21,
      "y": 38,
      "z": 7,
      "name": "Soil_Seaweed_Block"
    },
    {
      "x": -21,
      "y": 36,
      "z": 8,
      "name": "Soil_Clay_Green"
    },
    {
      "x": -21,
      "y": 37,
      "z": 8,
      "name": "Soil_Seaweed_Block"
    },
    {
      "x": -21,
      "y": 38,
      "z": 8,
      "name": "Soil_Seaweed_Block"
    },
    {
      "x": -21,
      "y": 39,
      "z": 8,
      "name": "Soil_Clay_Lime"
    },
    {
      "x": -21,
      "y": 40,
      "z": 8,
      "name": "Plant_Grass_Sharp"
    },
    {
      "x": -21,
      "y": 36,
      "z": 9,
      "name": "Soil_Clay_Green"
    },
    {
      "x": -21,
      "y": 37,
      "z": 9,
      "name": "Soil_Clay_Green"
    },
    {
      "x": -21,
      "y": 38,
      "z": 9,
      "name": "Soil_Seaweed_Block"
    },
    {
      "x": -21,
      "y": 39,
      "z": 9,
      "name": "Soil_Seaweed_Block"
    },
    {
      "x": -21,
      "y": 38,
      "z": 15,
      "name": "Soil_Clay_Green"
    },
    {
      "x": -21,
      "y": 39,
      "z": 15,
      "name": "Soil_Seaweed_Block"
    },
    {
      "x": -21,
      "y": 7,
      "z": 18,
      "name": "Soil_Clay_Green"
    },
    {
      "x": -21,
      "y": 8,
      "z": 18,
      "name": "Soil_Clay_Green"
    },
    {
      "x": -21,
      "y": 9,
      "z": 18,
      "name": "Soil_Seaweed_Block"
    },
    {
      "x": -21,
      "y": 6,
      "z": 19,
      "name": "Soil_Clay_Green"
    },
    {
      "x": -21,
      "y": 7,
      "z": 19,
      "name": "Soil_Seaweed_Block"
    },
    {
      "x": -21,
      "y": 8,
      "z": 19,
      "name": "Soil_Seaweed_Block"
    },
    {
      "x": -21,
      "y": 9,
      "z": 19,
      "name": "Soil_Seaweed_Block"
    },
    {
      "x": -21,
      "y": 10,
      "z": 19,
      "name": "Soil_Seaweed_Block"
    },
    {
      "x": -21,
      "y": 11,
      "z": 19,
      "name": "Soil_Seaweed_Block"
    },
    {
      "x": -21,
      "y": 7,
      "z": 20,
      "name": "Soil_Clay_Green"
    },
    {
      "x": -21,
      "y": 8,
      "z": 20,
      "name": "Soil_Seaweed_Block"
    },
    {
      "x": -21,
      "y": 9,
      "z": 20,
      "name": "Soil_Seaweed_Block"
    },
    {
      "x": -21,
      "y": 10,
      "z": 20,
      "name": "Soil_Seaweed_Block"
    },
    {
      "x": -21,
      "y": 11,
      "z": 20,
      "name": "Soil_Seaweed_Block"
    },
    {
      "x": -21,
      "y": 12,
      "z": 20,
      "name": "Soil_Seaweed_Block"
    },
    {
      "x": -21,
      "y": 7,
      "z": 21,
      "name": "Soil_Clay_Green"
    },
    {
      "x": -21,
      "y": 8,
      "z": 21,
      "name": "Soil_Seaweed_Block"
    },
    {
      "x": -21,
      "y": 9,
      "z": 21,
      "name": "Soil_Seaweed_Block"
    },
    {
      "x": -21,
      "y": 10,
      "z": 21,
      "name": "Soil_Seaweed_Block"
    },
    {
      "x": -21,
      "y": 11,
      "z": 21,
      "name": "Soil_Seaweed_Block"
    },
    {
      "x": -21,
      "y": 12,
      "z": 21,
      "name": "Soil_Seaweed_Block"
    },
    {
      "x": -21,
      "y": 7,
      "z": 22,
      "name": "Soil_Clay_Green"
    },
    {
      "x": -21,
      "y": 8,
      "z": 22,
      "name": "Soil_Seaweed_Block"
    },
    {
      "x": -21,
      "y": 9,
      "z": 22,
      "name": "Soil_Seaweed_Block"
    },
    {
      "x": -21,
      "y": 10,
      "z": 22,
      "name": "Soil_Seaweed_Block"
    },
    {
      "x": -21,
      "y": 11,
      "z": 22,
      "name": "Soil_Seaweed_Block"
    },
    {
      "x": -21,
      "y": 12,
      "z": 22,
      "name": "Soil_Seaweed_Block"
    },
    {
      "x": -21,
      "y": 8,
      "z": 23,
      "name": "Soil_Clay_Green"
    },
    {
      "x": -21,
      "y": 9,
      "z": 23,
      "name": "Soil_Seaweed_Block"
    },
    {
      "x": -21,
      "y": 10,
      "z": 23,
      "name": "Soil_Seaweed_Block"
    },
    {
      "x": -21,
      "y": 11,
      "z": 23,
      "name": "Soil_Seaweed_Block"
    },
    {
      "x": -21,
      "y": 12,
      "z": 23,
      "name": "Soil_Seaweed_Block"
    },
    {
      "x": -21,
      "y": 13,
      "z": 23,
      "name": "Soil_Seaweed_Block"
    },
    {
      "x": -21,
      "y": 14,
      "z": 23,
      "name": "Soil_Seaweed_Block"
    },
    {
      "x": -21,
      "y": 15,
      "z": 23,
      "name": "Soil_Seaweed_Block"
    },
    {
      "x": -21,
      "y": 9,
      "z": 24,
      "name": "Soil_Clay_Green"
    },
    {
      "x": -21,
      "y": 10,
      "z": 24,
      "name": "Soil_Clay_Green"
    },
    {
      "x": -21,
      "y": 11,
      "z": 24,
      "name": "Soil_Seaweed_Block"
    },
    {
      "x": -21,
      "y": 12,
      "z": 24,
      "name": "Soil_Seaweed_Block"
    },
    {
      "x": -21,
      "y": 13,
      "z": 24,
      "name": "Soil_Seaweed_Block"
    },
    {
      "x": -21,
      "y": 14,
      "z": 24,
      "name": "Soil_Clay_Green"
    },
    {
      "x": -21,
      "y": 15,
      "z": 24,
      "name": "Soil_Clay_Green"
    },
    {
      "x": -21,
      "y": 16,
      "z": 24,
      "name": "Soil_Seaweed_Block"
    },
    {
      "x": -21,
      "y": 17,
      "z": 24,
      "name": "Soil_Seaweed_Block"
    },
    {
      "x": -21,
      "y": 18,
      "z": 24,
      "name": "Soil_Seaweed_Block"
    },
    {
      "x": -21,
      "y": 14,
      "z": 25,
      "name": "Soil_Clay_Green"
    },
    {
      "x": -21,
      "y": 15,
      "z": 25,
      "name": "Soil_Seaweed_Block"
    },
    {
      "x": -21,
      "y": 16,
      "z": 25,
      "name": "Soil_Seaweed_Block"
    },
    {
      "x": -21,
      "y": 17,
      "z": 25,
      "name": "Soil_Seaweed_Block"
    },
    {
      "x": -21,
      "y": 18,
      "z": 25,
      "name": "Soil_Seaweed_Block"
    },
    {
      "x": -21,
      "y": 19,
      "z": 25,
      "name": "Soil_Seaweed_Block"
    },
    {
      "x": -21,
      "y": 14,
      "z": 26,
      "name": "Soil_Clay_Green"
    },
    {
      "x": -21,
      "y": 15,
      "z": 26,
      "name": "Soil_Seaweed_Block"
    },
    {
      "x": -21,
      "y": 16,
      "z": 26,
      "name": "Soil_Seaweed_Block"
    },
    {
      "x": -21,
      "y": 17,
      "z": 26,
      "name": "Soil_Seaweed_Block"
    },
    {
      "x": -21,
      "y": 18,
      "z": 26,
      "name": "Soil_Seaweed_Block"
    },
    {
      "x": -21,
      "y": 19,
      "z": 26,
      "name": "Soil_Seaweed_Block"
    },
    {
      "x": -21,
      "y": 20,
      "z": 26,
      "name": "Soil_Clay_Lime"
    },
    {
      "x": -21,
      "y": 21,
      "z": 26,
      "name": "Plant_Grass_Sharp"
    },
    {
      "x": -21,
      "y": 15,
      "z": 27,
      "name": "Soil_Clay_Green"
    },
    {
      "x": -21,
      "y": 16,
      "z": 27,
      "name": "Soil_Clay_Green"
    },
    {
      "x": -21,
      "y": 17,
      "z": 27,
      "name": "Soil_Clay_Green"
    },
    {
      "x": -21,
      "y": 18,
      "z": 27,
      "name": "Soil_Seaweed_Block"
    },
    {
      "x": -21,
      "y": 19,
      "z": 27,
      "name": "Soil_Seaweed_Block"
    },
    {
      "x": -21,
      "y": 20,
      "z": 27,
      "name": "Soil_Seaweed_Block"
    },
    {
      "x": -21,
      "y": 21,
      "z": 27,
      "name": "Soil_Clay_Lime"
    },
    {
      "x": -21,
      "y": 22,
      "z": 27,
      "name": "Soil_Seaweed_Block"
    },
    {
      "x": -21,
      "y": 15,
      "z": 28,
      "name": "Soil_Clay_Green"
    },
    {
      "x": -21,
      "y": 16,
      "z": 28,
      "name": "Soil_Clay_Green"
    },
    {
      "x": -21,
      "y": 17,
      "z": 28,
      "name": "Soil_Clay_Green"
    },
    {
      "x": -21,
      "y": 18,
      "z": 28,
      "name": "Soil_Seaweed_Block"
    },
    {
      "x": -21,
      "y": 19,
      "z": 28,
      "name": "Soil_Seaweed_Block"
    },
    {
      "x": -21,
      "y": 20,
      "z": 28,
      "name": "Soil_Seaweed_Block"
    },
    {
      "x": -21,
      "y": 21,
      "z": 28,
      "name": "Soil_Seaweed_Block"
    },
    {
      "x": -21,
      "y": 22,
      "z": 28,
      "name": "Soil_Clay_Lime"
    },
    {
      "x": -21,
      "y": 23,
      "z": 28,
      "name": "Plant_Grass_Sharp"
    },
    {
      "x": -21,
      "y": 18,
      "z": 29,
      "name": "Soil_Clay_Green"
    },
    {
      "x": -21,
      "y": 19,
      "z": 29,
      "name": "Soil_Seaweed_Block"
    },
    {
      "x": -21,
      "y": 20,
      "z": 29,
      "name": "Soil_Seaweed_Block"
    },
    {
      "x": -21,
      "y": 21,
      "z": 29,
      "name": "Soil_Seaweed_Block"
    },
    {
      "x": -21,
      "y": 22,
      "z": 29,
      "name": "Soil_Seaweed_Block"
    },
    {
      "x": -21,
      "y": 18,
      "z": 30,
      "name": "Soil_Clay_Green"
    },
    {
      "x": -21,
      "y": 19,
      "z": 30,
      "name": "Soil_Clay_Green"
    },
    {
      "x": -21,
      "y": 20,
      "z": 30,
      "name": "Soil_Seaweed_Block"
    },
    {
      "x": -21,
      "y": 21,
      "z": 30,
      "name": "Soil_Seaweed_Block"
    },
    {
      "x": -21,
      "y": 22,
      "z": 30,
      "name": "Soil_Seaweed_Block"
    },
    {
      "x": -21,
      "y": 19,
      "z": 31,
      "name": "Soil_Clay_Green"
    },
    {
      "x": -21,
      "y": 20,
      "z": 31,
      "name": "Soil_Seaweed_Block"
    },
    {
      "x": -21,
      "y": 26,
      "z": 41,
      "name": "Soil_Clay_Green"
    },
    {
      "x": -21,
      "y": 27,
      "z": 41,
      "name": "Soil_Seaweed_Block"
    },
    {
      "x": -20,
      "y": 35,
      "z": 7,
      "name": "Soil_Clay_Green"
    },
    {
      "x": -20,
      "y": 36,
      "z": 7,
      "name": "Soil_Clay_Green"
    },
    {
      "x": -20,
      "y": 37,
      "z": 7,
      "name": "Soil_Seaweed_Block"
    },
    {
      "x": -20,
      "y": 38,
      "z": 7,
      "name": "Soil_Clay_Lime"
    },
    {
      "x": -20,
      "y": 39,
      "z": 7,
      "name": "Soil_Clay_Lime"
    },
    {
      "x": -20,
      "y": 40,
      "z": 7,
      "name": "Plant_Grass_Sharp"
    },
    {
      "x": -20,
      "y": 34,
      "z": 8,
      "name": "Soil_Clay_Green"
    },
    {
      "x": -20,
      "y": 35,
      "z": 8,
      "name": "Soil_Clay_Green"
    },
    {
      "x": -20,
      "y": 36,
      "z": 8,
      "name": "Soil_Seaweed_Block"
    },
    {
      "x": -20,
      "y": 37,
      "z": 8,
      "name": "Soil_Seaweed_Block"
    },
    {
      "x": -20,
      "y": 38,
      "z": 8,
      "name": "Soil_Clay_Lime"
    },
    {
      "x": -20,
      "y": 39,
      "z": 8,
      "name": "Soil_Clay_Lime"
    },
    {
      "x": -20,
      "y": 40,
      "z": 8,
      "name": "Plant_Grass_Sharp"
    },
    {
      "x": -20,
      "y": 35,
      "z": 9,
      "name": "Soil_Clay_Green"
    },
    {
      "x": -20,
      "y": 36,
      "z": 9,
      "name": "Soil_Clay_Green"
    },
    {
      "x": -20,
      "y": 37,
      "z": 9,
      "name": "Soil_Seaweed_Block"
    },
    {
      "x": -20,
      "y": 37,
      "z": 14,
      "name": "Soil_Clay_Green"
    },
    {
      "x": -20,
      "y": 38,
      "z": 14,
      "name": "Soil_Seaweed_Block"
    },
    {
      "x": -20,
      "y": 37,
      "z": 15,
      "name": "Soil_Clay_Green"
    },
    {
      "x": -20,
      "y": 38,
      "z": 15,
      "name": "Soil_Clay_Lime"
    },
    {
      "x": -20,
      "y": 39,
      "z": 15,
      "name": "Plant_Grass_Sharp"
    },
    {
      "x": -20,
      "y": 8,
      "z": 18,
      "name": "Soil_Clay_Green"
    },
    {
      "x": -20,
      "y": 9,
      "z": 18,
      "name": "Soil_Seaweed_Block"
    },
    {
      "x": -20,
      "y": 7,
      "z": 19,
      "name": "Soil_Clay_Green"
    },
    {
      "x": -20,
      "y": 8,
      "z": 19,
      "name": "Soil_Seaweed_Block"
    },
    {
      "x": -20,
      "y": 9,
      "z": 19,
      "name": "Soil_Seaweed_Block"
    },
    {
      "x": -20,
      "y": 10,
      "z": 19,
      "name": "Soil_Seaweed_Block"
    },
    {
      "x": -20,
      "y": 11,
      "z": 19,
      "name": "Soil_Seaweed_Block"
    },
    {
      "x": -20,
      "y": 7,
      "z": 20,
      "name": "Soil_Clay_Green"
    },
    {
      "x": -20,
      "y": 8,
      "z": 20,
      "name": "Soil_Seaweed_Block"
    },
    {
      "x": -20,
      "y": 9,
      "z": 20,
      "name": "Soil_Seaweed_Block"
    },
    {
      "x": -20,
      "y": 10,
      "z": 20,
      "name": "Soil_Seaweed_Block"
    },
    {
      "x": -20,
      "y": 11,
      "z": 20,
      "name": "Soil_Seaweed_Block"
    },
    {
      "x": -20,
      "y": 12,
      "z": 20,
      "name": "Soil_Seaweed_Block"
    },
    {
      "x": -20,
      "y": 13,
      "z": 20,
      "name": "Soil_Seaweed_Block"
    },
    {
      "x": -20,
      "y": 7,
      "z": 21,
      "name": "Soil_Clay_Green"
    },
    {
      "x": -20,
      "y": 8,
      "z": 21,
      "name": "Soil_Seaweed_Block"
    },
    {
      "x": -20,
      "y": 9,
      "z": 21,
      "name": "Soil_Seaweed_Block"
    },
    {
      "x": -20,
      "y": 10,
      "z": 21,
      "name": "Soil_Seaweed_Block"
    },
    {
      "x": -20,
      "y": 11,
      "z": 21,
      "name": "Soil_Seaweed_Block"
    },
    {
      "x": -20,
      "y": 12,
      "z": 21,
      "name": "Soil_Seaweed_Block"
    },
    {
      "x": -20,
      "y": 13,
      "z": 21,
      "name": "Soil_Seaweed_Block"
    },
    {
      "x": -20,
      "y": 14,
      "z": 21,
      "name": "Soil_Seaweed_Block"
    },
    {
      "x": -20,
      "y": 8,
      "z": 22,
      "name": "Soil_Clay_Green"
    },
    {
      "x": -20,
      "y": 9,
      "z": 22,
      "name": "Soil_Seaweed_Block"
    },
    {
      "x": -20,
      "y": 10,
      "z": 22,
      "name": "Soil_Seaweed_Block"
    },
    {
      "x": -20,
      "y": 11,
      "z": 22,
      "name": "Soil_Seaweed_Block"
    },
    {
      "x": -20,
      "y": 12,
      "z": 22,
      "name": "Soil_Seaweed_Block"
    },
    {
      "x": -20,
      "y": 13,
      "z": 22,
      "name": "Soil_Seaweed_Block"
    },
    {
      "x": -20,
      "y": 14,
      "z": 22,
      "name": "Soil_Seaweed_Block"
    },
    {
      "x": -20,
      "y": 15,
      "z": 22,
      "name": "Soil_Seaweed_Block"
    },
    {
      "x": -20,
      "y": 8,
      "z": 23,
      "name": "Soil_Clay_Green"
    },
    {
      "x": -20,
      "y": 9,
      "z": 23,
      "name": "Soil_Seaweed_Block"
    },
    {
      "x": -20,
      "y": 10,
      "z": 23,
      "name": "Soil_Seaweed_Block"
    },
    {
      "x": -20,
      "y": 11,
      "z": 23,
      "name": "Soil_Seaweed_Block"
    },
    {
      "x": -20,
      "y": 12,
      "z": 23,
      "name": "Soil_Seaweed_Block"
    },
    {
      "x": -20,
      "y": 13,
      "z": 23,
      "name": "Soil_Seaweed_Block"
    },
    {
      "x": -20,
      "y": 14,
      "z": 23,
      "name": "Soil_Seaweed_Block"
    },
    {
      "x": -20,
      "y": 15,
      "z": 23,
      "name": "Soil_Seaweed_Block"
    },
    {
      "x": -20,
      "y": 16,
      "z": 23,
      "name": "Soil_Seaweed_Block"
    },
    {
      "x": -20,
      "y": 17,
      "z": 23,
      "name": "Soil_Seaweed_Block"
    },
    {
      "x": -20,
      "y": 9,
      "z": 24,
      "name": "Soil_Clay_Green"
    },
    {
      "x": -20,
      "y": 10,
      "z": 24,
      "name": "Soil_Seaweed_Block"
    },
    {
      "x": -20,
      "y": 11,
      "z": 24,
      "name": "Soil_Seaweed_Block"
    },
    {
      "x": -20,
      "y": 12,
      "z": 24,
      "name": "Soil_Seaweed_Block"
    },
    {
      "x": -20,
      "y": 13,
      "z": 24,
      "name": "Soil_Seaweed_Block"
    },
    {
      "x": -20,
      "y": 14,
      "z": 24,
      "name": "Soil_Seaweed_Block"
    },
    {
      "x": -20,
      "y": 15,
      "z": 24,
      "name": "Soil_Seaweed_Block"
    },
    {
      "x": -20,
      "y": 16,
      "z": 24,
      "name": "Soil_Seaweed_Block"
    },
    {
      "x": -20,
      "y": 17,
      "z": 24,
      "name": "Soil_Seaweed_Block"
    },
    {
      "x": -20,
      "y": 18,
      "z": 24,
      "name": "Soil_Clay_Lime"
    },
    {
      "x": -20,
      "y": 19,
      "z": 24,
      "name": "Plant_Grass_Sharp"
    },
    {
      "x": -20,
      "y": 9,
      "z": 25,
      "name": "Soil_Clay_Green"
    },
    {
      "x": -20,
      "y": 10,
      "z": 25,
      "name": "Soil_Clay_Green"
    },
    {
      "x": -20,
      "y": 11,
      "z": 25,
      "name": "Soil_Clay_Green"
    },
    {
      "x": -20,
      "y": 12,
      "z": 25,
      "name": "Soil_Clay_Green"
    },
    {
      "x": -20,
      "y": 13,
      "z": 25,
      "name": "Soil_Clay_Green"
    },
    {
      "x": -20,
      "y": 14,
      "z": 25,
      "name": "Soil_Seaweed_Block"
    },
    {
      "x": -20,
      "y": 15,
      "z": 25,
      "name": "Soil_Seaweed_Block"
    },
    {
      "x": -20,
      "y": 16,
      "z": 25,
      "name": "Soil_Seaweed_Block"
    },
    {
      "x": -20,
      "y": 17,
      "z": 25,
      "name": "Soil_Seaweed_Block"
    },
    {
      "x": -20,
      "y": 18,
      "z": 25,
      "name": "Soil_Seaweed_Block"
    },
    {
      "x": -20,
      "y": 19,
      "z": 25,
      "name": "Soil_Clay_Lime"
    },
    {
      "x": -20,
      "y": 20,
      "z": 25,
      "name": "Plant_Grass_Sharp"
    },
    {
      "x": -20,
      "y": 10,
      "z": 26,
      "name": "Soil_Clay_Green"
    },
    {
      "x": -20,
      "y": 11,
      "z": 26,
      "name": "Soil_Clay_Green"
    },
    {
      "x": -20,
      "y": 12,
      "z": 26,
      "name": "Soil_Clay_Green"
    },
    {
      "x": -20,
      "y": 13,
      "z": 26,
      "name": "Soil_Clay_Green"
    },
    {
      "x": -20,
      "y": 14,
      "z": 26,
      "name": "Soil_Seaweed_Block"
    },
    {
      "x": -20,
      "y": 15,
      "z": 26,
      "name": "Soil_Seaweed_Block"
    },
    {
      "x": -20,
      "y": 16,
      "z": 26,
      "name": "Soil_Seaweed_Block"
    },
    {
      "x": -20,
      "y": 17,
      "z": 26,
      "name": "Soil_Seaweed_Block"
    },
    {
      "x": -20,
      "y": 18,
      "z": 26,
      "name": "Soil_Seaweed_Block"
    },
    {
      "x": -20,
      "y": 19,
      "z": 26,
      "name": "Soil_Seaweed_Block"
    },
    {
      "x": -20,
      "y": 20,
      "z": 26,
      "name": "Soil_Clay_Lime"
    },
    {
      "x": -20,
      "y": 21,
      "z": 26,
      "name": "Plant_Grass_Sharp"
    },
    {
      "x": -20,
      "y": 14,
      "z": 27,
      "name": "Soil_Clay_Green"
    },
    {
      "x": -20,
      "y": 15,
      "z": 27,
      "name": "Soil_Seaweed_Block"
    },
    {
      "x": -20,
      "y": 16,
      "z": 27,
      "name": "Soil_Seaweed_Block"
    },
    {
      "x": -20,
      "y": 17,
      "z": 27,
      "name": "Soil_Seaweed_Block"
    },
    {
      "x": -20,
      "y": 18,
      "z": 27,
      "name": "Soil_Seaweed_Block"
    },
    {
      "x": -20,
      "y": 19,
      "z": 27,
      "name": "Soil_Seaweed_Block"
    },
    {
      "x": -20,
      "y": 20,
      "z": 27,
      "name": "Soil_Clay_Lime"
    },
    {
      "x": -20,
      "y": 21,
      "z": 27,
      "name": "Plant_Grass_Sharp"
    },
    {
      "x": -20,
      "y": 15,
      "z": 28,
      "name": "Soil_Clay_Green"
    },
    {
      "x": -20,
      "y": 16,
      "z": 28,
      "name": "Soil_Clay_Green"
    },
    {
      "x": -20,
      "y": 17,
      "z": 28,
      "name": "Soil_Clay_Green"
    },
    {
      "x": -20,
      "y": 18,
      "z": 28,
      "name": "Soil_Seaweed_Block"
    },
    {
      "x": -20,
      "y": 19,
      "z": 28,
      "name": "Soil_Seaweed_Block"
    },
    {
      "x": -20,
      "y": 20,
      "z": 28,
      "name": "Soil_Seaweed_Block"
    },
    {
      "x": -20,
      "y": 21,
      "z": 28,
      "name": "Soil_Seaweed_Block"
    },
    {
      "x": -20,
      "y": 18,
      "z": 29,
      "name": "Soil_Clay_Green"
    },
    {
      "x": -20,
      "y": 19,
      "z": 29,
      "name": "Soil_Seaweed_Block"
    },
    {
      "x": -20,
      "y": 20,
      "z": 29,
      "name": "Soil_Seaweed_Block"
    },
    {
      "x": -20,
      "y": 21,
      "z": 29,
      "name": "Soil_Seaweed_Block"
    },
    {
      "x": -19,
      "y": 35,
      "z": 6,
      "name": "Soil_Clay_Green"
    },
    {
      "x": -19,
      "y": 36,
      "z": 6,
      "name": "Soil_Seaweed_Block"
    },
    {
      "x": -19,
      "y": 34,
      "z": 7,
      "name": "Soil_Clay_Green"
    },
    {
      "x": -19,
      "y": 35,
      "z": 7,
      "name": "Soil_Seaweed_Block"
    },
    {
      "x": -19,
      "y": 36,
      "z": 7,
      "name": "Soil_Seaweed_Block"
    },
    {
      "x": -19,
      "y": 37,
      "z": 7,
      "name": "Soil_Clay_Lime"
    },
    {
      "x": -19,
      "y": 38,
      "z": 7,
      "name": "Soil_Clay_Lime"
    },
    {
      "x": -19,
      "y": 39,
      "z": 7,
      "name": "Plant_Grass_Sharp"
    },
    {
      "x": -19,
      "y": 34,
      "z": 8,
      "name": "Soil_Clay_Green"
    },
    {
      "x": -19,
      "y": 35,
      "z": 8,
      "name": "Soil_Seaweed_Block"
    },
    {
      "x": -19,
      "y": 36,
      "z": 8,
      "name": "Soil_Seaweed_Block"
    },
    {
      "x": -19,
      "y": 37,
      "z": 8,
      "name": "Soil_Clay_Lime"
    },
    {
      "x": -19,
      "y": 38,
      "z": 8,
      "name": "Plant_Grass_Sharp"
    },
    {
      "x": -19,
      "y": 34,
      "z": 9,
      "name": "Soil_Clay_Green"
    },
    {
      "x": -19,
      "y": 35,
      "z": 9,
      "name": "Soil_Clay_Green"
    },
    {
      "x": -19,
      "y": 36,
      "z": 9,
      "name": "Soil_Seaweed_Block"
    },
    {
      "x": -19,
      "y": 37,
      "z": 9,
      "name": "Soil_Seaweed_Block"
    },
    {
      "x": -19,
      "y": 37,
      "z": 14,
      "name": "Soil_Seaweed_Block"
    },
    {
      "x": -19,
      "y": 36,
      "z": 15,
      "name": "Soil_Clay_Green"
    },
    {
      "x": -19,
      "y": 37,
      "z": 15,
      "name": "Soil_Clay_Lime"
    },
    {
      "x": -19,
      "y": 38,
      "z": 15,
      "name": "Soil_Clay_Lime"
    },
    {
      "x": -19,
      "y": 39,
      "z": 15,
      "name": "Plant_Grass_Sharp"
    },
    {
      "x": -19,
      "y": 9,
      "z": 18,
      "name": "Soil_Seaweed_Block"
    },
    {
      "x": -19,
      "y": 7,
      "z": 19,
      "name": "Soil_Clay_Green"
    },
    {
      "x": -19,
      "y": 8,
      "z": 19,
      "name": "Soil_Clay_Green"
    },
    {
      "x": -19,
      "y": 9,
      "z": 19,
      "name": "Soil_Seaweed_Block"
    },
    {
      "x": -19,
      "y": 10,
      "z": 19,
      "name": "Soil_Seaweed_Block"
    },
    {
      "x": -19,
      "y": 11,
      "z": 19,
      "name": "Soil_Seaweed_Block"
    },
    {
      "x": -19,
      "y": 12,
      "z": 19,
      "name": "Soil_Seaweed_Block"
    },
    {
      "x": -19,
      "y": 7,
      "z": 20,
      "name": "Soil_Clay_Green"
    },
    {
      "x": -19,
      "y": 8,
      "z": 20,
      "name": "Soil_Seaweed_Block"
    },
    {
      "x": -19,
      "y": 9,
      "z": 20,
      "name": "Soil_Seaweed_Block"
    },
    {
      "x": -19,
      "y": 10,
      "z": 20,
      "name": "Soil_Seaweed_Block"
    },
    {
      "x": -19,
      "y": 11,
      "z": 20,
      "name": "Soil_Seaweed_Block"
    },
    {
      "x": -19,
      "y": 12,
      "z": 20,
      "name": "Soil_Seaweed_Block"
    },
    {
      "x": -19,
      "y": 13,
      "z": 20,
      "name": "Soil_Seaweed_Block"
    },
    {
      "x": -19,
      "y": 14,
      "z": 20,
      "name": "Soil_Seaweed_Block"
    },
    {
      "x": -19,
      "y": 8,
      "z": 21,
      "name": "Soil_Clay_Green"
    },
    {
      "x": -19,
      "y": 9,
      "z": 21,
      "name": "Soil_Seaweed_Block"
    },
    {
      "x": -19,
      "y": 10,
      "z": 21,
      "name": "Soil_Seaweed_Block"
    },
    {
      "x": -19,
      "y": 11,
      "z": 21,
      "name": "Soil_Seaweed_Block"
    },
    {
      "x": -19,
      "y": 12,
      "z": 21,
      "name": "Soil_Seaweed_Block"
    },
    {
      "x": -19,
      "y": 13,
      "z": 21,
      "name": "Soil_Seaweed_Block"
    },
    {
      "x": -19,
      "y": 14,
      "z": 21,
      "name": "Soil_Seaweed_Block"
    },
    {
      "x": -19,
      "y": 15,
      "z": 21,
      "name": "Soil_Seaweed_Block"
    },
    {
      "x": -19,
      "y": 8,
      "z": 22,
      "name": "Soil_Clay_Green"
    },
    {
      "x": -19,
      "y": 9,
      "z": 22,
      "name": "Soil_Seaweed_Block"
    },
    {
      "x": -19,
      "y": 10,
      "z": 22,
      "name": "Soil_Seaweed_Block"
    },
    {
      "x": -19,
      "y": 11,
      "z": 22,
      "name": "Soil_Seaweed_Block"
    },
    {
      "x": -19,
      "y": 12,
      "z": 22,
      "name": "Soil_Seaweed_Block"
    },
    {
      "x": -19,
      "y": 13,
      "z": 22,
      "name": "Soil_Seaweed_Block"
    },
    {
      "x": -19,
      "y": 14,
      "z": 22,
      "name": "Soil_Seaweed_Block"
    },
    {
      "x": -19,
      "y": 15,
      "z": 22,
      "name": "Soil_Seaweed_Block"
    },
    {
      "x": -19,
      "y": 8,
      "z": 23,
      "name": "Soil_Clay_Green"
    },
    {
      "x": -19,
      "y": 9,
      "z": 23,
      "name": "Soil_Seaweed_Block"
    },
    {
      "x": -19,
      "y": 10,
      "z": 23,
      "name": "Soil_Seaweed_Block"
    },
    {
      "x": -19,
      "y": 11,
      "z": 23,
      "name": "Soil_Seaweed_Block"
    },
    {
      "x": -19,
      "y": 12,
      "z": 23,
      "name": "Soil_Seaweed_Block"
    },
    {
      "x": -19,
      "y": 13,
      "z": 23,
      "name": "Soil_Seaweed_Block"
    },
    {
      "x": -19,
      "y": 14,
      "z": 23,
      "name": "Soil_Seaweed_Block"
    },
    {
      "x": -19,
      "y": 15,
      "z": 23,
      "name": "Soil_Seaweed_Block"
    },
    {
      "x": -19,
      "y": 16,
      "z": 23,
      "name": "Soil_Clay_Lime"
    },
    {
      "x": -19,
      "y": 17,
      "z": 23,
      "name": "Soil_Clay_Lime"
    },
    {
      "x": -19,
      "y": 18,
      "z": 23,
      "name": "Plant_Grass_Sharp"
    },
    {
      "x": -19,
      "y": 8,
      "z": 24,
      "name": "Soil_Clay_Green"
    },
    {
      "x": -19,
      "y": 9,
      "z": 24,
      "name": "Soil_Seaweed_Block"
    },
    {
      "x": -19,
      "y": 10,
      "z": 24,
      "name": "Soil_Seaweed_Block"
    },
    {
      "x": -19,
      "y": 11,
      "z": 24,
      "name": "Soil_Seaweed_Block"
    },
    {
      "x": -19,
      "y": 12,
      "z": 24,
      "name": "Soil_Seaweed_Block"
    },
    {
      "x": -19,
      "y": 13,
      "z": 24,
      "name": "Soil_Seaweed_Block"
    },
    {
      "x": -19,
      "y": 14,
      "z": 24,
      "name": "Soil_Seaweed_Block"
    },
    {
      "x": -19,
      "y": 15,
      "z": 24,
      "name": "Soil_Seaweed_Block"
    },
    {
      "x": -19,
      "y": 16,
      "z": 24,
      "name": "Soil_Seaweed_Block"
    },
    {
      "x": -19,
      "y": 17,
      "z": 24,
      "name": "Soil_Clay_Lime"
    },
    {
      "x": -19,
      "y": 18,
      "z": 24,
      "name": "Plant_Grass_Sharp"
    },
    {
      "x": -19,
      "y": 9,
      "z": 25,
      "name": "Soil_Clay_Green"
    },
    {
      "x": -19,
      "y": 10,
      "z": 25,
      "name": "Soil_Seaweed_Block"
    },
    {
      "x": -19,
      "y": 11,
      "z": 25,
      "name": "Soil_Seaweed_Block"
    },
    {
      "x": -19,
      "y": 12,
      "z": 25,
      "name": "Soil_Seaweed_Block"
    },
    {
      "x": -19,
      "y": 13,
      "z": 25,
      "name": "Soil_Seaweed_Block"
    },
    {
      "x": -19,
      "y": 14,
      "z": 25,
      "name": "Soil_Seaweed_Block"
    },
    {
      "x": -19,
      "y": 15,
      "z": 25,
      "name": "Soil_Seaweed_Block"
    },
    {
      "x": -19,
      "y": 16,
      "z": 25,
      "name": "Soil_Seaweed_Block"
    },
    {
      "x": -19,
      "y": 17,
      "z": 25,
      "name": "Soil_Seaweed_Block"
    },
    {
      "x": -19,
      "y": 18,
      "z": 25,
      "name": "Soil_Clay_Lime"
    },
    {
      "x": -19,
      "y": 19,
      "z": 25,
      "name": "Soil_Clay_Lime"
    },
    {
      "x": -19,
      "y": 20,
      "z": 25,
      "name": "Plant_Grass_Sharp"
    },
    {
      "x": -19,
      "y": 9,
      "z": 26,
      "name": "Soil_Clay_Green"
    },
    {
      "x": -19,
      "y": 10,
      "z": 26,
      "name": "Soil_Clay_Green"
    },
    {
      "x": -19,
      "y": 11,
      "z": 26,
      "name": "Soil_Clay_Green"
    },
    {
      "x": -19,
      "y": 12,
      "z": 26,
      "name": "Soil_Clay_Green"
    },
    {
      "x": -19,
      "y": 13,
      "z": 26,
      "name": "Soil_Clay_Green"
    },
    {
      "x": -19,
      "y": 14,
      "z": 26,
      "name": "Soil_Seaweed_Block"
    },
    {
      "x": -19,
      "y": 15,
      "z": 26,
      "name": "Soil_Seaweed_Block"
    },
    {
      "x": -19,
      "y": 16,
      "z": 26,
      "name": "Soil_Seaweed_Block"
    },
    {
      "x": -19,
      "y": 17,
      "z": 26,
      "name": "Soil_Seaweed_Block"
    },
    {
      "x": -19,
      "y": 18,
      "z": 26,
      "name": "Soil_Seaweed_Block"
    },
    {
      "x": -19,
      "y": 19,
      "z": 26,
      "name": "Soil_Clay_Lime"
    },
    {
      "x": -19,
      "y": 20,
      "z": 26,
      "name": "Plant_Grass_Sharp"
    },
    {
      "x": -19,
      "y": 14,
      "z": 27,
      "name": "Soil_Clay_Green"
    },
    {
      "x": -19,
      "y": 15,
      "z": 27,
      "name": "Soil_Seaweed_Block"
    },
    {
      "x": -19,
      "y": 16,
      "z": 27,
      "name": "Soil_Seaweed_Block"
    },
    {
      "x": -19,
      "y": 17,
      "z": 27,
      "name": "Soil_Seaweed_Block"
    },
    {
      "x": -19,
      "y": 18,
      "z": 27,
      "name": "Soil_Seaweed_Block"
    },
    {
      "x": -19,
      "y": 19,
      "z": 27,
      "name": "Soil_Seaweed_Block"
    },
    {
      "x": -19,
      "y": 20,
      "z": 27,
      "name": "Soil_Clay_Lime"
    },
    {
      "x": -19,
      "y": 21,
      "z": 27,
      "name": "Plant_Grass_Sharp"
    },
    {
      "x": -19,
      "y": 15,
      "z": 28,
      "name": "Soil_Clay_Green"
    },
    {
      "x": -19,
      "y": 16,
      "z": 28,
      "name": "Soil_Seaweed_Block"
    },
    {
      "x": -19,
      "y": 17,
      "z": 28,
      "name": "Soil_Seaweed_Block"
    },
    {
      "x": -19,
      "y": 18,
      "z": 28,
      "name": "Soil_Seaweed_Block"
    },
    {
      "x": -19,
      "y": 19,
      "z": 28,
      "name": "Soil_Seaweed_Block"
    },
    {
      "x": -19,
      "y": 20,
      "z": 28,
      "name": "Soil_Seaweed_Block"
    },
    {
      "x": -19,
      "y": 15,
      "z": 29,
      "name": "Soil_Clay_Green"
    },
    {
      "x": -19,
      "y": 16,
      "z": 29,
      "name": "Soil_Clay_Green"
    },
    {
      "x": -19,
      "y": 17,
      "z": 29,
      "name": "Soil_Clay_Green"
    },
    {
      "x": -19,
      "y": 18,
      "z": 29,
      "name": "Soil_Clay_Green"
    },
    {
      "x": -19,
      "y": 19,
      "z": 29,
      "name": "Soil_Seaweed_Block"
    },
    {
      "x": -19,
      "y": 20,
      "z": 29,
      "name": "Soil_Seaweed_Block"
    },
    {
      "x": -18,
      "y": 35,
      "z": 6,
      "name": "Soil_Seaweed_Block"
    },
    {
      "x": -18,
      "y": 36,
      "z": 6,
      "name": "Soil_Seaweed_Block"
    },
    {
      "x": -18,
      "y": 33,
      "z": 7,
      "name": "Soil_Clay_Green"
    },
    {
      "x": -18,
      "y": 34,
      "z": 7,
      "name": "Soil_Clay_Green"
    },
    {
      "x": -18,
      "y": 35,
      "z": 7,
      "name": "Soil_Seaweed_Block"
    },
    {
      "x": -18,
      "y": 36,
      "z": 7,
      "name": "Soil_Clay_Lime"
    },
    {
