{
  "version": 8,
  "blockIdVersion": 10,
  "anchorX": 0,
  "anchorY": 26,
  "anchorZ": 0,
  "blocks": [
    {
      "x": -52,
      "y": 23,
      "z": -25,
      "name": "Soil_Clay_Green"
    },
    {
      "x": -52,
      "y": 23,
      "z": -24,
      "name": "Soil_Clay_Green"
    },
    {
      "x": -52,
      "y": 23,
      "z": -23,
      "name": "Soil_Clay_Green"
    },
    {
      "x": -51,
      "y": 23,
      "z": -24,
      "name": "Soil_Clay_Green"
    },
    {
      "x": -51,
      "y": 24,
      "z": -24,
      "name": "Soil_Seaweed_Block"
    },
    {
      "x": -51,
      "y": 23,
      "z": -23,
      "name": "Soil_Clay_Green"
    },
    {
      "x": -51,
      "y": 24,
      "z": -23,
      "name": "Soil_Seaweed_Block"
    },
    {
      "x": -51,
      "y": 23,
      "z": -22,
      "name": "Soil_Clay_Green"
    },
    {
      "x": -51,
      "y": 28,
      "z": -19,
      "name": "Soil_Clay_Green"
    },
    {
      "x": -51,
      "y": 29,
      "z": -19,
      "name": "Soil_Seaweed_Block"
    },
    {
      "x": -51,
      "y": 28,
      "z": -18,
      "name": "Soil_Clay_Green"
    },
    {
      "x": -51,
      "y": 29,
      "z": -18,
      "name": "Soil_Clay_Lime"
    },
    {
      "x": -51,
      "y": 30,
      "z": -18,
      "name": "Plant_Grass_Sharp"
    },
    {
      "x": -50,
      "y": 23,
      "z": -24,
      "name": "Soil_Clay_Green"
    },
    {
      "x": -50,
      "y": 24,
      "z": -24,
      "name": "Soil_Seaweed_Block"
    },
    {
      "x": -50,
      "y": 23,
      "z": -23,
      "name": "Soil_Clay_Green"
    },
    {
      "x": -50,
      "y": 24,
      "z": -23,
      "name": "Soil_Seaweed_Block"
    },
    {
      "x": -50,
      "y": 23,
      "z": -22,
      "name": "Soil_Clay_Green"
    },
    {
      "x": -50,
      "y": 24,
      "z": -22,
      "name": "Soil_Seaweed_Block"
    },
    {
      "x": -50,
      "y": 28,
      "z": -19,
      "name": "Soil_Clay_Green"
    },
    {
      "x": -50,
      "y": 29,
      "z": -19,
      "name": "Soil_Clay_Lime"
    },
    {
      "x": -50,
      "y": 30,
      "z": -19,
      "name": "Plant_Grass_Sharp"
    },
    {
      "x": -50,
      "y": 28,
      "z": -18,
      "name": "Soil_Clay_Green"
    },
    {
      "x": -50,
      "y": 29,
      "z": -18,
      "name": "Soil_Clay_Lime"
    },
    {
      "x": -50,
      "y": 30,
      "z": -18,
      "name": "Plant_Grass_Sharp"
    },
    {
      "x": -49,
      "y": 24,
      "z": -24,
      "name": "Soil_Seaweed_Block"
    },
    {
      "x": -49,
      "y": 23,
      "z": -23,
      "name": "Soil_Clay_Green"
    },
    {
      "x": -49,
      "y": 24,
      "z": -23,
      "name": "Soil_Seaweed_Block"
    },
    {
      "x": -49,
      "y": 25,
      "z": -23,
      "name": "Soil_Clay_Lime"
    },
    {
      "x": -49,
      "y": 26,
      "z": -23,
      "name": "Plant_Grass_Sharp"
    },
    {
      "x": -49,
      "y": 23,
      "z": -22,
      "name": "Soil_Clay_Green"
    },
    {
      "x": -49,
      "y": 24,
      "z": -22,
      "name": "Soil_Seaweed_Block"
    },
    {
      "x": -49,
      "y": 23,
      "z": -21,
      "name": "Soil_Clay_Green"
    },
    {
      "x": -49,
      "y": 24,
      "z": -21,
      "name": "Soil_Seaweed_Block"
    },
    {
      "x": -49,
      "y": 27,
      "z": -18,
      "name": "Soil_Clay_Green"
    },
    {
      "x": -49,
      "y": 28,
      "z": -18,
      "name": "Soil_Clay_Green"
    },
    {
      "x": -48,
      "y": 24,
      "z": -24,
      "name": "Soil_Clay_Green"
    },
    {
      "x": -48,
      "y": 25,
      "z": -24,
      "name": "Soil_Seaweed_Block"
    },
    {
      "x": -48,
      "y": 24,
      "z": -23,
      "name": "Soil_Clay_Green"
    },
    {
      "x": -48,
      "y": 25,
      "z": -23,
      "name": "Soil_Clay_Lime"
    },
    {
      "x": -48,
      "y": 26,
      "z": -23,
      "name": "Plant_Grass_Sharp"
    },
    {
      "x": -48,
      "y": 24,
      "z": -22,
      "name": "Soil_Clay_Green"
    },
    {
      "x": -48,
      "y": 25,
      "z": -22,
      "name": "Soil_Clay_Lime"
    },
    {
      "x": -48,
      "y": 26,
      "z": -22,
      "name": "Plant_Grass_Sharp"
    },
    {
      "x": -48,
      "y": 24,
      "z": -21,
      "name": "Soil_Clay_Green"
    },
    {
      "x": -48,
      "y": 27,
      "z": -18,
      "name": "Soil_Clay_Green"
    },
    {
      "x": -48,
      "y": 28,
      "z": -18,
      "name": "Soil_Clay_Green"
    },
    {
      "x": -48,
      "y": 29,
      "z": -18,
      "name": "Soil_Clay_Lime"
    },
    {
      "x": -48,
      "y": 30,
      "z": -18,
      "name": "Plant_Grass_Sharp"
    },
    {
      "x": -47,
      "y": 24,
      "z": -24,
      "name": "Soil_Clay_Green"
    },
    {
      "x": -47,
      "y": 25,
      "z": -24,
      "name": "Soil_Seaweed_Block"
    },
    {
      "x": -47,
      "y": 24,
      "z": -23,
      "name": "Soil_Clay_Green"
    },
    {
      "x": -47,
      "y": 25,
      "z": -23,
      "name": "Soil_Clay_Lime"
    },
    {
      "x": -47,
      "y": 26,
      "z": -23,
      "name": "Plant_Grass_Sharp"
    },
    {
      "x": -47,
      "y": 24,
      "z": -22,
      "name": "Soil_Clay_Green"
    },
    {
      "x": -47,
      "y": 25,
      "z": -22,
      "name": "Soil_Seaweed_Block"
    },
    {
      "x": -47,
      "y": 28,
      "z": -18,
      "name": "Soil_Clay_Green"
    },
    {
      "x": -47,
      "y": 29,
      "z": -18,
      "name": "Soil_Clay_Lime"
    },
    {
      "x": -47,
      "y": 30,
      "z": -18,
      "name": "Plant_Grass_Sharp"
    },
    {
      "x": -47,
      "y": 22,
      "z": -16,
      "name": "Soil_Clay_Green"
    },
    {
      "x": -47,
      "y": 23,
      "z": -16,
      "name": "Soil_Seaweed_Block"
    },
    {
      "x": -46,
      "y": 25,
      "z": -23,
      "name": "Soil_Clay_Green"
    },
    {
      "x": -46,
      "y": 26,
      "z": -23,
      "name": "Soil_Clay_Lime"
    },
    {
      "x": -46,
      "y": 27,
      "z": -23,
      "name": "Plant_Grass_Sharp"
    },
    {
      "x": -46,
      "y": 24,
      "z": -22,
      "name": "Soil_Clay_Green"
    },
    {
      "x": -46,
      "y": 25,
      "z": -22,
      "name": "Soil_Clay_Green"
    },
    {
      "x": -46,
      "y": 26,
      "z": -22,
      "name": "Soil_Seaweed_Block"
    },
    {
      "x": -46,
      "y": 28,
      "z": -18,
      "name": "Soil_Clay_Green"
    },
    {
      "x": -46,
      "y": 29,
      "z": -18,
      "name": "Soil_Clay_Lime"
    },
    {
      "x": -46,
      "y": 30,
      "z": -18,
      "name": "Plant_Grass_Sharp"
    },
    {
      "x": -46,
      "y": 22,
      "z": -16,
      "name": "Soil_Clay_Green"
    },
    {
      "x": -46,
      "y": 23,
      "z": -16,
      "name": "Soil_Seaweed_Block"
    },
    {
      "x": -45,
      "y": 26,
      "z": -30,
      "name": "Soil_Clay_Green"
    },
    {
      "x": -45,
      "y": 26,
      "z": -29,
      "name": "Soil_Clay_Green"
    },
    {
      "x": -45,
      "y": 34,
      "z": -26,
      "name": "Soil_Seaweed_Block"
    },
    {
      "x": -45,
      "y": 25,
      "z": -23,
      "name": "Soil_Clay_Green"
    },
    {
      "x": -45,
      "y": 26,
      "z": -23,
      "name": "Soil_Clay_Green"
    },
    {
      "x": -45,
      "y": 25,
      "z": -22,
      "name": "Soil_Clay_Green"
    },
    {
      "x": -45,
      "y": 26,
      "z": -22,
      "name": "Soil_Clay_Green"
    },
    {
      "x": -45,
      "y": 27,
      "z": -22,
      "name": "Soil_Seaweed_Block"
    },
    {
      "x": -45,
      "y": 28,
      "z": -19,
      "name": "Soil_Seaweed_Block"
    },
    {
      "x": -45,
      "y": 29,
      "z": -19,
      "name": "Soil_Clay_Lime"
    },
    {
      "x": -45,
      "y": 30,
      "z": -19,
      "name": "Soil_Clay_Lime"
    },
    {
      "x": -45,
      "y": 31,
      "z": -19,
      "name": "Plant_Grass_Sharp"
    },
    {
      "x": -45,
      "y": 29,
      "z": -18,
      "name": "Soil_Seaweed_Block"
    },
    {
      "x": -45,
      "y": 23,
      "z": -16,
      "name": "Soil_Clay_Lime"
    },
    {
      "x": -45,
      "y": 24,
      "z": -16,
      "name": "Plant_Grass_Sharp"
    },
    {
      "x": -45,
      "y": 23,
      "z": -15,
      "name": "Soil_Seaweed_Block"
    },
    {
      "x": -44,
      "y": 17,
      "z": -29,
      "name": "Soil_Clay_Green"
    },
    {
      "x": -44,
      "y": 17,
      "z": -28,
      "name": "Soil_Clay_Green"
    },
    {
      "x": -44,
      "y": 18,
      "z": -28,
      "name": "Soil_Seaweed_Block"
    },
    {
      "x": -44,
      "y": 26,
      "z": -28,
      "name": "Soil_Clay_Green"
    },
    {
      "x": -44,
      "y": 34,
      "z": -26,
      "name": "Soil_Seaweed_Block"
    },
    {
      "x": -44,
      "y": 33,
      "z": -25,
      "name": "Soil_Clay_Green"
    },
    {
      "x": -44,
      "y": 25,
      "z": -24,
      "name": "Soil_Clay_Green"
    },
    {
      "x": -44,
      "y": 26,
      "z": -24,
      "name": "Soil_Clay_Green"
    },
    {
      "x": -44,
      "y": 27,
      "z": -24,
      "name": "Soil_Seaweed_Block"
    },
    {
      "x": -44,
      "y": 25,
      "z": -23,
      "name": "Soil_Clay_Green"
    },
    {
      "x": -44,
      "y": 26,
      "z": -23,
      "name": "Soil_Seaweed_Block"
    },
    {
      "x": -44,
      "y": 27,
      "z": -23,
      "name": "Soil_Seaweed_Block"
    },
    {
      "x": -44,
      "y": 26,
      "z": -22,
      "name": "Soil_Clay_Green"
    },
    {
      "x": -44,
      "y": 27,
      "z": -22,
      "name": "Soil_Seaweed_Block"
    },
    {
      "x": -44,
      "y": 28,
      "z": -22,
      "name": "Soil_Seaweed_Block"
    },
    {
      "x": -44,
      "y": 26,
      "z": -21,
      "name": "Soil_Clay_Green"
    },
    {
      "x": -44,
      "y": 27,
      "z": -21,
      "name": "Soil_Clay_Green"
    },
    {
      "x": -44,
      "y": 28,
      "z": -21,
      "name": "Soil_Seaweed_Block"
    },
    {
      "x": -44,
      "y": 26,
      "z": -20,
      "name": "Soil_Clay_Green"
    },
    {
      "x": -44,
      "y": 27,
      "z": -20,
      "name": "Soil_Clay_Green"
    },
    {
      "x": -44,
      "y": 28,
      "z": -20,
      "name": "Soil_Seaweed_Block"
    },
    {
      "x": -44,
      "y": 27,
      "z": -19,
      "name": "Soil_Clay_Green"
    },
    {
      "x": -44,
      "y": 28,
      "z": -19,
      "name": "Soil_Seaweed_Block"
    },
    {
      "x": -44,
      "y": 29,
      "z": -19,
      "name": "Soil_Clay_Lime"
    },
    {
      "x": -44,
      "y": 30,
      "z": -19,
      "name": "Plant_Grass_Sharp"
    },
    {
      "x": -44,
      "y": 23,
      "z": -16,
      "name": "Soil_Seaweed_Block"
    },
    {
      "x": -44,
      "y": 22,
      "z": -15,
      "name": "Soil_Clay_Green"
    },
    {
      "x": -44,
      "y": 23,
      "z": -15,
      "name": "Soil_Seaweed_Block"
    },
    {
      "x": -43,
      "y": 17,
      "z": -28,
      "name": "Soil_Clay_Green"
    },
    {
      "x": -43,
      "y": 26,
      "z": -28,
      "name": "Soil_Clay_Green"
    },
    {
      "x": -43,
      "y": 26,
      "z": -27,
      "name": "Soil_Clay_Green"
    },
    {
      "x": -43,
      "y": 27,
      "z": -27,
      "name": "Soil_Clay_Lime"
    },
    {
      "x": -43,
      "y": 28,
      "z": -27,
      "name": "Plant_Grass_Sharp"
    },
    {
      "x": -43,
      "y": 27,
      "z": -24,
      "name": "Soil_Clay_Green"
    },
    {
      "x": -43,
      "y": 34,
      "z": -24,
      "name": "Soil_Seaweed_Block"
    },
    {
      "x": -43,
      "y": 26,
      "z": -23,
      "name": "Soil_Clay_Green"
    },
    {
      "x": -43,
      "y": 27,
      "z": -23,
      "name": "Soil_Seaweed_Block"
    },
    {
      "x": -43,
      "y": 28,
      "z": -23,
      "name": "Soil_Seaweed_Block"
    },
    {
      "x": -43,
      "y": 29,
      "z": -23,
      "name": "Soil_Clay_Lime"
    },
    {
      "x": -43,
      "y": 30,
      "z": -23,
      "name": "Plant_Grass_Sharp"
    },
    {
      "x": -43,
      "y": 34,
      "z": -23,
      "name": "Soil_Seaweed_Block"
    },
    {
      "x": -43,
      "y": 26,
      "z": -22,
      "name": "Soil_Clay_Green"
    },
    {
      "x": -43,
      "y": 27,
      "z": -22,
      "name": "Soil_Seaweed_Block"
    },
    {
      "x": -43,
      "y": 28,
      "z": -22,
      "name": "Soil_Seaweed_Block"
    },
    {
      "x": -43,
      "y": 29,
      "z": -22,
      "name": "Soil_Clay_Lime"
    },
    {
      "x": -43,
      "y": 30,
      "z": -22,
      "name": "Plant_Grass_Sharp"
    },
    {
      "x": -43,
      "y": 26,
      "z": -21,
      "name": "Soil_Clay_Green"
    },
    {
      "x": -43,
      "y": 27,
      "z": -21,
      "name": "Soil_Seaweed_Block"
    },
    {
      "x": -43,
      "y": 28,
      "z": -21,
      "name": "Soil_Seaweed_Block"
    },
    {
      "x": -43,
      "y": 29,
      "z": -21,
      "name": "Soil_Clay_Lime"
    },
    {
      "x": -43,
      "y": 30,
      "z": -21,
      "name": "Plant_Grass_Sharp"
    },
    {
      "x": -43,
      "y": 27,
      "z": -20,
      "name": "Soil_Clay_Green"
    },
    {
      "x": -43,
      "y": 28,
      "z": -20,
      "name": "Soil_Seaweed_Block"
    },
    {
      "x": -43,
      "y": 29,
      "z": -20,
      "name": "Soil_Clay_Lime"
    },
    {
      "x": -43,
      "y": 30,
      "z": -20,
      "name": "Plant_Grass_Sharp"
    },
    {
      "x": -43,
      "y": 22,
      "z": -16,
      "name": "Soil_Clay_Green"
    },
    {
      "x": -43,
      "y": 23,
      "z": -16,
      "name": "Soil_Clay_Green"
    },
    {
      "x": -42,
      "y": 23,
      "z": -31,
      "name": "Soil_Clay_Green"
    },
    {
      "x": -42,
      "y": 24,
      "z": -31,
      "name": "Soil_Seaweed_Block"
    },
    {
      "x": -42,
      "y": 17,
      "z": -28,
      "name": "Soil_Clay_Green"
    },
    {
      "x": -42,
      "y": 16,
      "z": -27,
      "name": "Soil_Clay_Green"
    },
    {
      "x": -42,
      "y": 17,
      "z": -27,
      "name": "Soil_Clay_Green"
    },
    {
      "x": -42,
      "y": 18,
      "z": -27,
      "name": "Soil_Clay_Green"
    },
    {
      "x": -42,
      "y": 27,
      "z": -27,
      "name": "Soil_Seaweed_Block"
    },
    {
      "x": -42,
      "y": 27,
      "z": -24,
      "name": "Soil_Clay_Green"
    },
    {
      "x": -42,
      "y": 28,
      "z": -24,
      "name": "Soil_Seaweed_Block"
    },
    {
      "x": -42,
      "y": 34,
      "z": -24,
      "name": "Soil_Clay_Lime"
    },
    {
      "x": -42,
      "y": 35,
      "z": -24,
      "name": "Plant_Grass_Sharp"
    },
    {
      "x": -42,
      "y": 27,
      "z": -23,
      "name": "Soil_Clay_Green"
    },
    {
      "x": -42,
      "y": 28,
      "z": -23,
      "name": "Soil_Seaweed_Block"
    },
    {
      "x": -42,
      "y": 29,
      "z": -23,
      "name": "Soil_Clay_Lime"
    },
    {
      "x": -42,
      "y": 30,
      "z": -23,
      "name": "Plant_Grass_Sharp"
    },
    {
      "x": -42,
      "y": 33,
      "z": -23,
      "name": "Soil_Clay_Green"
    },
    {
      "x": -42,
      "y": 34,
      "z": -23,
      "name": "Soil_Clay_Lime"
    },
    {
      "x": -42,
      "y": 35,
      "z": -23,
      "name": "Plant_Grass_Sharp"
    },
    {
      "x": -42,
      "y": 27,
      "z": -22,
      "name": "Soil_Clay_Green"
    },
    {
      "x": -42,
      "y": 28,
      "z": -22,
      "name": "Soil_Seaweed_Block"
    },
    {
      "x": -42,
      "y": 29,
      "z": -22,
      "name": "Soil_Seaweed_Block"
    },
    {
      "x": -42,
      "y": 30,
      "z": -22,
      "name": "Soil_Clay_Lime"
    },
    {
      "x": -42,
      "y": 31,
      "z": -22,
      "name": "Plant_Grass_Sharp"
    },
    {
      "x": -42,
      "y": 33,
      "z": -22,
      "name": "Soil_Clay_Green"
    },
    {
      "x": -42,
      "y": 27,
      "z": -21,
      "name": "Soil_Clay_Green"
    },
    {
      "x": -42,
      "y": 28,
      "z": -21,
      "name": "Soil_Seaweed_Block"
    },
    {
      "x": -42,
      "y": 29,
      "z": -21,
      "name": "Soil_Clay_Lime"
    },
    {
      "x": -42,
      "y": 30,
      "z": -21,
      "name": "Soil_Clay_Lime"
    },
    {
      "x": -42,
      "y": 31,
      "z": -21,
      "name": "Plant_Grass_Sharp"
    },
    {
      "x": -42,
      "y": 28,
      "z": -20,
      "name": "Soil_Clay_Green"
    },
    {
      "x": -42,
      "y": 23,
      "z": -16,
      "name": "Soil_Clay_Green"
    },
    {
      "x": -42,
      "y": 23,
      "z": -15,
      "name": "Soil_Clay_Green"
    },
    {
      "x": -41,
      "y": 23,
      "z": -32,
      "name": "Soil_Seaweed_Block"
    },
    {
      "x": -41,
      "y": 24,
      "z": -32,
      "name": "Soil_Seaweed_Block"
    },
    {
      "x": -41,
      "y": 23,
      "z": -31,
      "name": "Soil_Seaweed_Block"
    },
    {
      "x": -41,
      "y": 23,
      "z": -30,
      "name": "Soil_Seaweed_Block"
    },
    {
      "x": -41,
      "y": 36,
      "z": -30,
      "name": "Soil_Clay_Green"
    },
    {
      "x": -41,
      "y": 37,
      "z": -30,
      "name": "Soil_Clay_Green"
    },
    {
      "x": -41,
      "y": 36,
      "z": -29,
      "name": "Soil_Clay_Green"
    },
    {
      "x": -41,
      "y": 37,
      "z": -29,
      "name": "Soil_Clay_Green"
    },
    {
      "x": -41,
      "y": 18,
      "z": -28,
      "name": "Soil_Clay_Green"
    },
    {
      "x": -41,
      "y": 18,
      "z": -27,
      "name": "Soil_Clay_Green"
    },
    {
      "x": -41,
      "y": 17,
      "z": -26,
      "name": "Soil_Clay_Green"
    },
    {
      "x": -41,
      "y": 27,
      "z": -26,
      "name": "Soil_Clay_Green"
    },
    {
      "x": -41,
      "y": 27,
      "z": -24,
      "name": "Soil_Clay_Green"
    },
    {
      "x": -41,
      "y": 28,
      "z": -24,
      "name": "Soil_Clay_Green"
    },
    {
      "x": -41,
      "y": 27,
      "z": -23,
      "name": "Soil_Clay_Green"
    },
    {
      "x": -41,
      "y": 28,
      "z": -23,
      "name": "Soil_Seaweed_Block"
    },
    {
      "x": -41,
      "y": 29,
      "z": -23,
      "name": "Soil_Clay_Lime"
    },
    {
      "x": -41,
      "y": 30,
      "z": -23,
      "name": "Plant_Grass_Sharp"
    },
    {
      "x": -41,
      "y": 33,
      "z": -23,
      "name": "Soil_Clay_Green"
    },
    {
      "x": -41,
      "y": 34,
      "z": -23,
      "name": "Soil_Clay_Lime"
    },
    {
      "x": -41,
      "y": 35,
      "z": -23,
      "name": "Plant_Grass_Sharp"
    },
    {
      "x": -41,
      "y": 27,
      "z": -22,
      "name": "Soil_Clay_Green"
    },
    {
      "x": -41,
      "y": 28,
      "z": -22,
      "name": "Soil_Seaweed_Block"
    },
    {
      "x": -41,
      "y": 29,
      "z": -22,
      "name": "Soil_Seaweed_Block"
    },
    {
      "x": -41,
      "y": 30,
      "z": -22,
      "name": "Soil_Clay_Lime"
    },
    {
      "x": -41,
      "y": 31,
      "z": -22,
      "name": "Plant_Grass_Sharp"
    },
    {
      "x": -41,
      "y": 33,
      "z": -22,
      "name": "Soil_Clay_Green"
    },
    {
      "x": -41,
      "y": 27,
      "z": -21,
      "name": "Soil_Clay_Green"
    },
    {
      "x": -41,
      "y": 28,
      "z": -21,
      "name": "Soil_Seaweed_Block"
    },
    {
      "x": -41,
      "y": 29,
      "z": -21,
      "name": "Soil_Seaweed_Block"
    },
    {
      "x": -41,
      "y": 30,
      "z": -21,
      "name": "Soil_Clay_Lime"
    },
    {
      "x": -41,
      "y": 31,
      "z": -21,
      "name": "Plant_Grass_Sharp"
    },
    {
      "x": -41,
      "y": 28,
      "z": -20,
      "name": "Soil_Clay_Green"
    },
    {
      "x": -41,
      "y": 29,
      "z": -20,
      "name": "Soil_Seaweed_Block"
    },
    {
      "x": -41,
      "y": 30,
      "z": -20,
      "name": "Soil_Clay_Lime"
    },
    {
      "x": -41,
      "y": 31,
      "z": -20,
      "name": "Plant_Grass_Sharp"
    },
    {
      "x": -41,
      "y": 23,
      "z": -17,
      "name": "Soil_Clay_Green"
    },
    {
      "x": -41,
      "y": 24,
      "z": -17,
      "name": "Soil_Clay_Green"
    },
    {
      "x": -41,
      "y": 25,
      "z": -17,
      "name": "Soil_Seaweed_Block"
    },
    {
      "x": -41,
      "y": 23,
      "z": -16,
      "name": "Soil_Clay_Green"
    },
    {
      "x": -41,
      "y": 24,
      "z": -16,
      "name": "Soil_Seaweed_Block"
    },
    {
      "x": -41,
      "y": 23,
      "z": -15,
      "name": "Soil_Clay_Green"
    },
    {
      "x": -40,
      "y": 23,
      "z": -42,
      "name": "Soil_Clay_Green"
    },
    {
      "x": -40,
      "y": 22,
      "z": -41,
      "name": "Soil_Clay_Green"
    },
    {
      "x": -40,
      "y": 30,
      "z": -36,
      "name": "Soil_Clay_Green"
    },
    {
      "x": -40,
      "y": 31,
      "z": -36,
      "name": "Soil_Clay_Green"
    },
    {
      "x": -40,
      "y": 31,
      "z": -35,
      "name": "Soil_Clay_Green"
    },
    {
      "x": -40,
      "y": 32,
      "z": -35,
      "name": "Soil_Seaweed_Block"
    },
    {
      "x": -40,
      "y": 23,
      "z": -31,
      "name": "Soil_Seaweed_Block"
    },
    {
      "x": -40,
      "y": 20,
      "z": -30,
      "name": "Soil_Seaweed_Block"
    },
    {
      "x": -40,
      "y": 23,
      "z": -30,
      "name": "Soil_Clay_Lime"
    },
    {
      "x": -40,
      "y": 24,
      "z": -30,
      "name": "Plant_Grass_Sharp"
    },
    {
      "x": -40,
      "y": 19,
      "z": -29,
      "name": "Soil_Clay_Green"
    },
    {
      "x": -40,
      "y": 20,
      "z": -29,
      "name": "Soil_Seaweed_Block"
    },
    {
      "x": -40,
      "y": 37,
      "z": -29,
      "name": "Soil_Clay_Green"
    },
    {
      "x": -40,
      "y": 38,
      "z": -29,
      "name": "Soil_Clay_Lime"
    },
    {
      "x": -40,
      "y": 39,
      "z": -29,
      "name": "Plant_Grass_Sharp"
    },
    {
      "x": -40,
      "y": 18,
      "z": -28,
      "name": "Soil_Clay_Green"
    },
    {
      "x": -40,
      "y": 19,
      "z": -28,
      "name": "Soil_Seaweed_Block"
    },
    {
      "x": -40,
      "y": 20,
      "z": -28,
      "name": "Soil_Clay_Lime"
    },
    {
      "x": -40,
      "y": 21,
      "z": -28,
      "name": "Plant_Grass_Sharp"
    },
    {
      "x": -40,
      "y": 18,
      "z": -27,
      "name": "Soil_Clay_Green"
    },
    {
      "x": -40,
      "y": 19,
      "z": -27,
      "name": "Soil_Seaweed_Block"
    },
    {
      "x": -40,
      "y": 20,
      "z": -27,
      "name": "Soil_Clay_Lime"
    },
    {
      "x": -40,
      "y": 21,
      "z": -27,
      "name": "Plant_Grass_Sharp"
    },
    {
      "x": -40,
      "y": 27,
      "z": -25,
      "name": "Soil_Clay_Green"
    },
    {
      "x": -40,
      "y": 28,
      "z": -25,
      "name": "Soil_Seaweed_Block"
    },
    {
      "x": -40,
      "y": 27,
      "z": -24,
      "name": "Soil_Clay_Green"
    },
    {
      "x": -40,
      "y": 28,
      "z": -24,
      "name": "Soil_Seaweed_Block"
    },
    {
      "x": -40,
      "y": 29,
      "z": -24,
      "name": "Soil_Seaweed_Block"
    },
    {
      "x": -40,
      "y": 27,
      "z": -23,
      "name": "Soil_Clay_Green"
    },
    {
      "x": -40,
      "y": 28,
      "z": -23,
      "name": "Soil_Seaweed_Block"
    },
    {
      "x": -40,
      "y": 29,
      "z": -23,
      "name": "Soil_Clay_Lime"
    },
    {
      "x": -40,
      "y": 30,
      "z": -23,
      "name": "Plant_Grass_Sharp"
    },
    {
      "x": -40,
      "y": 33,
      "z": -23,
      "name": "Soil_Clay_Green"
    },
    {
      "x": -40,
      "y": 28,
      "z": -22,
      "name": "Soil_Clay_Green"
    },
    {
      "x": -40,
      "y": 29,
      "z": -22,
      "name": "Soil_Seaweed_Block"
    },
    {
      "x": -40,
      "y": 30,
      "z": -22,
      "name": "Soil_Clay_Lime"
    },
    {
      "x": -40,
      "y": 31,
      "z": -22,
      "name": "Plant_Grass_Sharp"
    },
    {
      "x": -40,
      "y": 27,
      "z": -21,
      "name": "Soil_Clay_Green"
    },
    {
      "x": -40,
      "y": 28,
      "z": -21,
      "name": "Soil_Seaweed_Block"
    },
    {
      "x": -40,
      "y": 29,
      "z": -21,
      "name": "Soil_Seaweed_Block"
    },
    {
      "x": -40,
      "y": 30,
      "z": -21,
      "name": "Soil_Clay_Lime"
    },
    {
      "x": -40,
      "y": 31,
      "z": -21,
      "name": "Plant_Grass_Sharp"
    },
    {
      "x": -40,
      "y": 28,
      "z": -20,
      "name": "Soil_Clay_Green"
    },
    {
      "x": -40,
      "y": 29,
      "z": -20,
      "name": "Soil_Seaweed_Block"
    },
    {
      "x": -40,
      "y": 28,
      "z": -19,
      "name": "Soil_Clay_Green"
    },
    {
      "x": -40,
      "y": 24,
      "z": -18,
      "name": "Soil_Clay_Green"
    },
    {
      "x": -40,
      "y": 25,
      "z": -18,
      "name": "Soil_Clay_Green"
    },
    {
      "x": -40,
      "y": 24,
      "z": -17,
      "name": "Soil_Clay_Green"
    },
    {
      "x": -40,
      "y": 25,
      "z": -17,
      "name": "Soil_Seaweed_Block"
    },
    {
      "x": -39,
      "y": 29,
      "z": -46,
      "name": "Soil_Clay_Green"
    },
    {
      "x": -39,
      "y": 29,
      "z": -45,
      "name": "Soil_Clay_Green"
    },
    {
      "x": -39,
      "y": 23,
      "z": -42,
      "name": "Soil_Clay_Green"
    },
    {
      "x": -39,
      "y": 24,
      "z": -42,
      "name": "Soil_Seaweed_Block"
    },
    {
      "x": -39,
      "y": 22,
      "z": -41,
      "name": "Soil_Clay_Green"
    },
    {
      "x": -39,
      "y": 23,
      "z": -41,
      "name": "Soil_Clay_Green"
    },
    {
      "x": -39,
      "y": 24,
      "z": -41,
      "name": "Soil_Seaweed_Block"
    },
    {
      "x": -39,
      "y": 23,
      "z": -40,
      "name": "Soil_Clay_Green"
    },
    {
      "x": -39,
      "y": 31,
      "z": -35,
      "name": "Soil_Clay_Green"
    },
    {
      "x": -39,
      "y": 32,
      "z": -35,
      "name": "Soil_Clay_Green"
    },
    {
      "x": -39,
      "y": 33,
      "z": -34,
      "name": "Soil_Clay_Lime"
    },
    {
      "x": -39,
      "y": 34,
      "z": -34,
      "name": "Plant_Grass_Sharp"
    },
    {
      "x": -39,
      "y": 20,
      "z": -30,
      "name": "Soil_Seaweed_Block"
    },
    {
      "x": -39,
      "y": 21,
      "z": -30,
      "name": "Soil_Seaweed_Block"
    },
    {
      "x": -39,
      "y": 22,
      "z": -30,
      "name": "Soil_Seaweed_Block"
    },
    {
      "x": -39,
      "y": 23,
      "z": -30,
      "name": "Soil_Seaweed_Block"
    },
    {
      "x": -39,
      "y": 19,
      "z": -29,
      "name": "Soil_Clay_Green"
    },
    {
      "x": -39,
      "y": 20,
      "z": -29,
      "name": "Soil_Seaweed_Block"
    },
    {
      "x": -39,
      "y": 21,
      "z": -29,
      "name": "Soil_Clay_Lime"
    },
    {
      "x": -39,
      "y": 22,
      "z": -29,
      "name": "Soil_Clay_Lime"
    },
    {
      "x": -39,
      "y": 23,
      "z": -29,
      "name": "Plant_Grass_Sharp"
    },
    {
      "x": -39,
      "y": 37,
      "z": -29,
      "name": "Soil_Clay_Green"
    },
    {
      "x": -39,
      "y": 38,
      "z": -29,
      "name": "Soil_Clay_Lime"
    },
    {
      "x": -39,
      "y": 39,
      "z": -29,
      "name": "Plant_Grass_Sharp"
    },
    {
      "x": -39,
      "y": 18,
      "z": -28,
      "name": "Soil_Clay_Green"
    },
    {
      "x": -39,
      "y": 19,
      "z": -28,
      "name": "Soil_Seaweed_Block"
    },
    {
      "x": -39,
      "y": 20,
      "z": -28,
      "name": "Soil_Clay_Lime"
    },
    {
      "x": -39,
      "y": 21,
      "z": -28,
      "name": "Soil_Clay_Lime"
    },
    {
      "x": -39,
      "y": 22,
      "z": -28,
      "name": "Plant_Grass_Sharp"
    },
    {
      "x": -39,
      "y": 38,
      "z": -28,
      "name": "Soil_Seaweed_Block"
    },
    {
      "x": -39,
      "y": 18,
      "z": -27,
      "name": "Soil_Clay_Green"
    },
    {
      "x": -39,
      "y": 19,
      "z": -27,
      "name": "Soil_Seaweed_Block"
    },
    {
      "x": -39,
      "y": 20,
      "z": -27,
      "name": "Soil_Clay_Lime"
    },
    {
      "x": -39,
      "y": 21,
      "z": -27,
      "name": "Plant_Grass_Sharp"
    },
    {
      "x": -39,
      "y": 18,
      "z": -26,
      "name": "Soil_Clay_Green"
    },
    {
      "x": -39,
      "y": 19,
      "z": -26,
      "name": "Soil_Seaweed_Block"
    },
    {
      "x": -39,
      "y": 18,
      "z": -25,
      "name": "Soil_Clay_Green"
    },
    {
      "x": -39,
      "y": 19,
      "z": -25,
      "name": "Soil_Seaweed_Block"
    },
    {
      "x": -39,
      "y": 28,
      "z": -25,
      "name": "Soil_Seaweed_Block"
    },
    {
      "x": -39,
      "y": 28,
      "z": -24,
      "name": "Soil_Clay_Green"
    },
    {
      "x": -39,
      "y": 28,
      "z": -23,
      "name": "Soil_Clay_Green"
    },
    {
      "x": -39,
      "y": 33,
      "z": -23,
      "name": "Soil_Clay_Green"
    },
    {
      "x": -39,
      "y": 28,
      "z": -22,
      "name": "Soil_Clay_Green"
    },
    {
      "x": -39,
      "y": 29,
      "z": -22,
      "name": "Soil_Clay_Lime"
    },
    {
      "x": -39,
      "y": 30,
      "z": -22,
      "name": "Soil_Clay_Lime"
    },
    {
      "x": -39,
      "y": 31,
      "z": -22,
      "name": "Plant_Grass_Sharp"
    },
    {
      "x": -39,
      "y": 27,
      "z": -21,
      "name": "Soil_Clay_Green"
    },
    {
      "x": -39,
      "y": 28,
      "z": -21,
      "name": "Soil_Seaweed_Block"
    },
    {
      "x": -39,
      "y": 29,
      "z": -21,
      "name": "Soil_Seaweed_Block"
    },
    {
      "x": -39,
      "y": 30,
      "z": -21,
      "name": "Soil_Clay_Lime"
    },
    {
      "x": -39,
      "y": 31,
      "z": -21,
      "name": "Plant_Grass_Sharp"
    },
    {
      "x": -39,
      "y": 27,
      "z": -20,
      "name": "Soil_Clay_Green"
    },
    {
      "x": -39,
      "y": 28,
      "z": -20,
      "name": "Soil_Seaweed_Block"
    },
    {
      "x": -39,
      "y": 29,
      "z": -20,
      "name": "Soil_Clay_Lime"
    },
    {
      "x": -39,
      "y": 30,
      "z": -20,
      "name": "Soil_Clay_Lime"
    },
    {
      "x": -39,
      "y": 31,
      "z": -20,
      "name": "Plant_Grass_Sharp"
    },
    {
      "x": -39,
      "y": 24,
      "z": -19,
      "name": "Soil_Clay_Green"
    },
    {
      "x": -39,
      "y": 25,
      "z": -19,
      "name": "Soil_Clay_Green"
    },
    {
      "x": -39,
      "y": 26,
      "z": -19,
      "name": "Soil_Clay_Green"
    },
    {
      "x": -39,
      "y": 27,
      "z": -19,
      "name": "Soil_Clay_Green"
    },
    {
      "x": -39,
      "y": 28,
      "z": -19,
      "name": "Soil_Seaweed_Block"
    },
    {
      "x": -39,
      "y": 24,
      "z": -18,
      "name": "Soil_Clay_Green"
    },
    {
      "x": -39,
      "y": 25,
      "z": -18,
      "name": "Soil_Clay_Green"
    },
    {
      "x": -39,
      "y": 26,
      "z": -18,
      "name": "Soil_Clay_Green"
    },
    {
      "x": -39,
      "y": 27,
      "z": -18,
      "name": "Soil_Seaweed_Block"
    },
    {
      "x": -38,
      "y": 29,
      "z": -46,
      "name": "Soil_Seaweed_Block"
    },
    {
      "x": -38,
      "y": 29,
      "z": -45,
      "name": "Soil_Seaweed_Block"
    },
    {
      "x": -38,
      "y": 23,
      "z": -42,
      "name": "Soil_Clay_Green"
    },
    {
      "x": -38,
      "y": 24,
      "z": -42,
      "name": "Soil_Seaweed_Block"
    },
    {
      "x": -38,
      "y": 22,
      "z": -41,
      "name": "Soil_Clay_Green"
    },
    {
      "x": -38,
      "y": 23,
      "z": -41,
      "name": "Soil_Seaweed_Block"
    },
    {
      "x": -38,
      "y": 24,
      "z": -41,
      "name": "Soil_Seaweed_Block"
    },
    {
      "x": -38,
      "y": 25,
      "z": -41,
      "name": "Soil_Clay_Lime"
    },
    {
      "x": -38,
      "y": 26,
      "z": -41,
      "name": "Plant_Grass_Sharp"
    },
    {
      "x": -38,
      "y": 23,
      "z": -40,
      "name": "Soil_Clay_Green"
    },
    {
      "x": -38,
      "y": 24,
      "z": -40,
      "name": "Soil_Seaweed_Block"
    },
    {
      "x": -38,
      "y": 24,
      "z": -39,
      "name": "Soil_Seaweed_Block"
    },
    {
      "x": -38,
      "y": 22,
      "z": -35,
      "name": "Soil_Seaweed_Block"
    },
    {
      "x": -38,
      "y": 33,
      "z": -34,
      "name": "Soil_Clay_Lime"
    },
    {
      "x": -38,
      "y": 34,
      "z": -34,
      "name": "Plant_Grass_Sharp"
    },
    {
      "x": -38,
      "y": 32,
      "z": -33,
      "name": "Soil_Clay_Green"
    },
    {
      "x": -38,
      "y": 38,
      "z": -29,
      "name": "Soil_Clay_Green"
    },
    {
      "x": -38,
      "y": 18,
      "z": -28,
      "name": "Soil_Clay_Green"
    },
    {
      "x": -38,
      "y": 19,
      "z": -28,
      "name": "Soil_Clay_Green"
    },
    {
      "x": -38,
      "y": 38,
      "z": -28,
      "name": "Soil_Clay_Green"
    },
    {
      "x": -38,
      "y": 18,
      "z": -27,
      "name": "Soil_Clay_Green"
    },
    {
      "x": -38,
      "y": 19,
      "z": -27,
      "name": "Soil_Seaweed_Block"
    },
    {
      "x": -38,
      "y": 20,
      "z": -27,
      "name": "Soil_Clay_Lime"
    },
    {
      "x": -38,
      "y": 21,
      "z": -27,
      "name": "Plant_Grass_Sharp"
    },
    {
      "x": -38,
      "y": 17,
      "z": -26,
      "name": "Soil_Clay_Green"
    },
    {
      "x": -38,
      "y": 18,
      "z": -26,
      "name": "Soil_Seaweed_Block"
    },
    {
      "x": -38,
      "y": 19,
      "z": -26,
      "name": "Soil_Clay_Green"
    },
    {
      "x": -38,
      "y": 17,
      "z": -25,
      "name": "Soil_Clay_Green"
    },
    {
      "x": -38,
      "y": 18,
      "z": -25,
      "name": "Soil_Seaweed_Block"
    },
    {
      "x": -38,
      "y": 19,
      "z": -25,
      "name": "Soil_Clay_Green"
    },
    {
      "x": -38,
      "y": 20,
      "z": -25,
      "name": "Soil_Clay_Lime"
    },
    {
      "x": -38,
      "y": 21,
      "z": -25,
      "name": "Plant_Grass_Sharp"
    },
    {
      "x": -38,
      "y": 18,
      "z": -24,
      "name": "Soil_Clay_Green"
    },
    {
      "x": -38,
      "y": 20,
      "z": -24,
      "name": "Soil_Seaweed_Block"
    },
    {
      "x": -38,
      "y": 34,
      "z": -24,
      "name": "Soil_Seaweed_Block"
    },
    {
      "x": -38,
      "y": 33,
      "z": -23,
      "name": "Soil_Clay_Green"
    },
    {
      "x": -38,
      "y": 34,
      "z": -23,
      "name": "Soil_Seaweed_Block"
    },
    {
      "x": -38,
      "y": 28,
      "z": -22,
      "name": "Soil_Clay_Green"
    },
    {
      "x": -38,
      "y": 29,
      "z": -22,
      "name": "Soil_Seaweed_Block"
    },
    {
      "x": -38,
      "y": 30,
      "z": -22,
      "name": "Soil_Clay_Lime"
    },
    {
      "x": -38,
      "y": 31,
      "z": -22,
      "name": "Plant_Grass_Sharp"
    },
    {
      "x": -38,
      "y": 27,
      "z": -21,
      "name": "Soil_Clay_Green"
    },
    {
      "x": -38,
      "y": 28,
      "z": -21,
      "name": "Soil_Seaweed_Block"
    },
    {
      "x": -38,
      "y": 29,
      "z": -21,
      "name": "Soil_Seaweed_Block"
    },
    {
      "x": -38,
      "y": 30,
      "z": -21,
      "name": "Soil_Clay_Lime"
    },
    {
      "x": -38,
      "y": 31,
      "z": -21,
      "name": "Plant_Grass_Sharp"
    },
    {
      "x": -38,
      "y": 25,
      "z": -20,
      "name": "Soil_Clay_Green"
    },
    {
      "x": -38,
      "y": 26,
      "z": -20,
      "name": "Soil_Clay_Green"
    },
    {
      "x": -38,
      "y": 27,
      "z": -20,
      "name": "Soil_Seaweed_Block"
    },
    {
      "x": -38,
      "y": 28,
      "z": -20,
      "name": "Soil_Seaweed_Block"
    },
    {
      "x": -38,
      "y": 29,
      "z": -20,
      "name": "Soil_Clay_Lime"
    },
    {
      "x": -38,
      "y": 30,
      "z": -20,
      "name": "Soil_Clay_Lime"
    },
    {
      "x": -38,
      "y": 31,
      "z": -20,
      "name": "Plant_Grass_Sharp"
    },
    {
      "x": -38,
      "y": 24,
      "z": -19,
      "name": "Soil_Clay_Green"
    },
    {
      "x": -38,
      "y": 25,
      "z": -19,
      "name": "Soil_Clay_Green"
    },
    {
      "x": -38,
      "y": 26,
      "z": -19,
      "name": "Soil_Clay_Green"
    },
    {
      "x": -38,
      "y": 27,
      "z": -19,
      "name": "Soil_Seaweed_Block"
    },
    {
      "x": -38,
      "y": 28,
      "z": -19,
      "name": "Soil_Seaweed_Block"
    },
    {
      "x": -38,
      "y": 27,
      "z": -18,
      "name": "Soil_Seaweed_Block"
    },
    {
      "x": -37,
      "y": 29,
      "z": -45,
      "name": "Soil_Clay_Lime"
    },
    {
      "x": -37,
      "y": 30,
      "z": -45,
      "name": "Plant_Grass_Sharp"
    },
    {
      "x": -37,
      "y": 29,
      "z": -44,
      "name": "Soil_Clay_Lime"
    },
    {
      "x": -37,
      "y": 30,
      "z": -44,
      "name": "Plant_Grass_Sharp"
    },
    {
      "x": -37,
      "y": 22,
      "z": -41,
      "name": "Soil_Clay_Green"
    },
    {
      "x": -37,
      "y": 23,
      "z": -41,
      "name": "Soil_Clay_Green"
    },
    {
      "x": -37,
      "y": 24,
      "z": -41,
      "name": "Soil_Seaweed_Block"
    },
    {
      "x": -37,
      "y": 23,
      "z": -40,
      "name": "Soil_Clay_Green"
    },
    {
      "x": -37,
      "y": 24,
      "z": -40,
      "name": "Soil_Seaweed_Block"
    },
    {
      "x": -37,
      "y": 25,
      "z": -40,
      "name": "Soil_Clay_Lime"
    },
    {
      "x": -37,
      "y": 26,
      "z": -40,
      "name": "Plant_Grass_Sharp"
    },
    {
      "x": -37,
      "y": 24,
      "z": -39,
      "name": "Soil_Seaweed_Block"
    },
    {
      "x": -37,
      "y": 25,
      "z": -39,
      "name": "Soil_Clay_Lime"
    },
    {
      "x": -37,
      "y": 26,
      "z": -39,
      "name": "Plant_Grass_Sharp"
    },
    {
      "x": -37,
      "y": 21,
      "z": -35,
      "name": "Soil_Clay_Green"
    },
    {
      "x": -37,
      "y": 22,
      "z": -35,
      "name": "Soil_Seaweed_Block"
    },
    {
      "x": -37,
      "y": 21,
      "z": -34,
      "name": "Soil_Clay_Green"
    },
    {
      "x": -37,
      "y": 33,
      "z": -34,
      "name": "Soil_Clay_Green"
    },
    {
      "x": -37,
      "y": 33,
      "z": -33,
      "name": "Soil_Clay_Green"
    },
    {
      "x": -37,
      "y": 34,
      "z": -33,
      "name": "Soil_Seaweed_Block"
    },
    {
      "x": -37,
      "y": 38,
      "z": -28,
      "name": "Soil_Clay_Green"
    },
    {
      "x": -37,
      "y": 39,
      "z": -28,
      "name": "Soil_Clay_Lime"
    },
    {
      "x": -37,
      "y": 40,
      "z": -28,
      "name": "Plant_Grass_Sharp"
    },
    {
      "x": -37,
      "y": 19,
      "z": -27,
      "name": "Soil_Clay_Green"
    },
    {
      "x": -37,
      "y": 38,
      "z": -27,
      "name": "Soil_Seaweed_Block"
    },
    {
      "x": -37,
      "y": 39,
      "z": -27,
      "name": "Soil_Clay_Lime"
    },
    {
      "x": -37,
      "y": 40,
      "z": -27,
      "name": "Plant_Grass_Sharp"
    },
    {
      "x": -37,
      "y": 18,
      "z": -26,
      "name": "Soil_Clay_Green"
    },
    {
      "x": -37,
      "y": 19,
      "z": -26,
      "name": "Soil_Seaweed_Block"
    },
    {
      "x": -37,
      "y": 20,
      "z": -26,
      "name": "Soil_Clay_Lime"
    },
    {
      "x": -37,
      "y": 21,
      "z": -26,
      "name": "Plant_Grass_Sharp"
    },
    {
      "x": -37,
      "y": 39,
      "z": -26,
      "name": "Soil_Seaweed_Block"
    },
    {
      "x": -37,
      "y": 18,
      "z": -25,
      "name": "Soil_Clay_Green"
    },
    {
      "x": -37,
      "y": 19,
      "z": -25,
      "name": "Soil_Seaweed_Block"
    },
    {
      "x": -37,
      "y": 20,
      "z": -25,
      "name": "Soil_Seaweed_Block"
    },
    {
      "x": -37,
      "y": 21,
      "z": -25,
      "name": "Soil_Clay_Lime"
    },
    {
      "x": -37,
      "y": 22,
      "z": -25,
      "name": "Plant_Grass_Sharp"
    },
    {
      "x": -37,
      "y": 17,
      "z": -24,
      "name": "Soil_Clay_Green"
    },
    {
      "x": -37,
      "y": 18,
      "z": -24,
      "name": "Soil_Seaweed_Block"
    },
    {
      "x": -37,
      "y": 19,
      "z": -24,
      "name": "Soil_Clay_Green"
    },
    {
      "x": -37,
      "y": 20,
      "z": -24,
      "name": "Soil_Seaweed_Block"
    },
    {
      "x": -37,
      "y": 21,
      "z": -24,
      "name": "Soil_Seaweed_Block"
    },
    {
      "x": -37,
      "y": 34,
      "z": -24,
      "name": "Soil_Seaweed_Block"
    },
    {
      "x": -37,
      "y": 17,
      "z": -23,
      "name": "Soil_Clay_Green"
    },
    {
      "x": -37,
      "y": 18,
      "z": -23,
      "name": "Soil_Clay_Green"
    },
    {
      "x": -37,
      "y": 19,
      "z": -23,
      "name": "Soil_Clay_Green"
    },
    {
      "x": -37,
      "y": 20,
      "z": -23,
      "name": "Soil_Seaweed_Block"
    },
    {
      "x": -37,
      "y": 33,
      "z": -23,
      "name": "Soil_Clay_Green"
    },
    {
      "x": -37,
      "y": 34,
      "z": -23,
      "name": "Soil_Seaweed_Block"
    },
    {
      "x": -37,
      "y": 22,
      "z": -21,
      "name": "Soil_Clay_Green"
    },
    {
      "x": -37,
      "y": 23,
      "z": -21,
      "name": "Soil_Clay_Green"
    },
    {
      "x": -37,
      "y": 24,
      "z": -21,
      "name": "Soil_Clay_Green"
    },
    {
      "x": -37,
      "y": 25,
      "z": -21,
      "name": "Soil_Clay_Green"
    },
    {
      "x": -37,
      "y": 26,
      "z": -21,
      "name": "Soil_Clay_Green"
    },
    {
      "x": -37,
      "y": 27,
      "z": -21,
      "name": "Soil_Seaweed_Block"
    },
    {
      "x": -37,
      "y": 28,
      "z": -21,
      "name": "Soil_Seaweed_Block"
    },
    {
      "x": -37,
      "y": 29,
      "z": -21,
      "name": "Soil_Clay_Lime"
    },
    {
      "x": -37,
      "y": 30,
      "z": -21,
      "name": "Plant_Grass_Sharp"
    },
    {
      "x": -37,
      "y": 21,
      "z": -20,
      "name": "Soil_Clay_Green"
    },
    {
      "x": -37,
      "y": 22,
      "z": -20,
      "name": "Soil_Clay_Green"
    },
    {
      "x": -37,
      "y": 23,
      "z": -20,
      "name": "Soil_Clay_Green"
    },
    {
      "x": -37,
      "y": 24,
      "z": -20,
      "name": "Soil_Clay_Green"
    },
    {
      "x": -37,
      "y": 25,
      "z": -20,
      "name": "Soil_Seaweed_Block"
    },
    {
      "x": -37,
      "y": 26,
      "z": -20,
      "name": "Soil_Seaweed_Block"
    },
    {
      "x": -37,
      "y": 27,
      "z": -20,
      "name": "Soil_Seaweed_Block"
    },
    {
      "x": -37,
      "y": 28,
      "z": -20,
      "name": "Soil_Seaweed_Block"
    },
    {
      "x": -37,
      "y": 29,
      "z": -20,
      "name": "Soil_Clay_Lime"
    },
    {
      "x": -37,
      "y": 30,
      "z": -20,
      "name": "Plant_Grass_Sharp"
    },
    {
      "x": -37,
      "y": 24,
      "z": -19,
      "name": "Soil_Clay_Green"
    },
    {
      "x": -37,
      "y": 25,
      "z": -19,
      "name": "Soil_Clay_Green"
    },
    {
      "x": -37,
      "y": 26,
      "z": -19,
      "name": "Soil_Seaweed_Block"
    },
    {
      "x": -37,
      "y": 27,
      "z": -19,
      "name": "Soil_Seaweed_Block"
    },
    {
      "x": -37,
      "y": 28,
      "z": -19,
      "name": "Soil_Seaweed_Block"
    },
    {
      "x": -37,
      "y": 27,
      "z": -18,
      "name": "Soil_Seaweed_Block"
    },
    {
      "x": -36,
      "y": 28,
      "z": -45,
      "name": "Soil_Clay_Green"
    },
    {
      "x": -36,
      "y": 23,
      "z": -40,
      "name": "Soil_Clay_Green"
    },
    {
      "x": -36,
      "y": 24,
      "z": -40,
      "name": "Soil_Clay_Green"
    },
    {
      "x": -36,
      "y": 25,
      "z": -40,
      "name": "Soil_Clay_Lime"
    },
    {
      "x": -36,
      "y": 26,
      "z": -40,
      "name": "Plant_Grass_Sharp"
    },
    {
      "x": -36,
      "y": 24,
      "z": -39,
      "name": "Soil_Clay_Green"
    },
    {
      "x": -36,
      "y": 25,
      "z": -39,
      "name": "Soil_Clay_Lime"
    },
    {
      "x": -36,
      "y": 26,
      "z": -39,
      "name": "Plant_Grass_Sharp"
    },
    {
      "x": -36,
      "y": 24,
      "z": -38,
      "name": "Soil_Clay_Green"
    },
    {
      "x": -36,
      "y": 25,
      "z": -38,
      "name": "Soil_Seaweed_Block"
    },
    {
      "x": -36,
      "y": 21,
      "z": -35,
      "name": "Soil_Clay_Green"
    },
    {
      "x": -36,
      "y": 22,
      "z": -35,
      "name": "Soil_Seaweed_Block"
    },
    {
      "x": -36,
      "y": 21,
      "z": -34,
      "name": "Soil_Clay_Green"
    },
    {
      "x": -36,
      "y": 33,
      "z": -33,
      "name": "Soil_Clay_Green"
    },
    {
      "x": -36,
      "y": 34,
      "z": -33,
      "name": "Soil_Seaweed_Block"
    },
    {
      "x": -36,
      "y": 33,
      "z": -32,
      "name": "Soil_Clay_Green"
    },
    {
      "x": -36,
      "y": 34,
      "z": -32,
      "name": "Soil_Clay_Lime"
    },
    {
      "x": -36,
      "y": 35,
      "z": -32,
      "name": "Plant_Grass_Sharp"
    },
    {
      "x": -36,
      "y": 33,
      "z": -31,
      "name": "Soil_Clay_Green"
    },
    {
      "x": -36,
      "y": 34,
      "z": -31,
      "name": "Soil_Seaweed_Block"
    },
    {
      "x": -36,
      "y": 35,
      "z": -31,
      "name": "Soil_Clay_Lime"
    },
    {
      "x": -36,
      "y": 36,
      "z": -31,
      "name": "Plant_Grass_Sharp"
    },
    {
      "x": -36,
      "y": 35,
      "z": -30,
      "name": "Soil_Clay_Lime"
    },
    {
      "x": -36,
      "y": 36,
      "z": -30,
      "name": "Plant_Grass_Sharp"
    },
    {
      "x": -36,
      "y": 38,
      "z": -28,
      "name": "Soil_Seaweed_Block"
    },
    {
      "x": -36,
      "y": 39,
      "z": -28,
      "name": "Soil_Seaweed_Block"
    },
    {
      "x": -36,
      "y": 20,
      "z": -27,
      "name": "Soil_Seaweed_Block"
    },
    {
      "x": -36,
      "y": 38,
      "z": -27,
      "name": "Soil_Seaweed_Block"
    },
    {
      "x": -36,
      "y": 39,
      "z": -27,
      "name": "Soil_Clay_Lime"
    },
    {
      "x": -36,
      "y": 40,
      "z": -27,
      "name": "Plant_Grass_Sharp"
    },
    {
      "x": -36,
      "y": 19,
      "z": -26,
      "name": "Soil_Clay_Green"
    },
    {
      "x": -36,
      "y": 20,
      "z": -26,
      "name": "Soil_Seaweed_Block"
    },
    {
      "x": -36,
      "y": 21,
      "z": -26,
      "name": "Soil_Seaweed_Block"
    },
    {
      "x": -36,
      "y": 38,
      "z": -26,
      "name": "Soil_Seaweed_Block"
    },
    {
      "x": -36,
      "y": 39,
      "z": -26,
      "name": "Soil_Clay_Lime"
    },
    {
      "x": -36,
      "y": 40,
      "z": -26,
      "name": "Plant_Grass_Sharp"
    },
    {
      "x": -36,
      "y": 18,
      "z": -25,
      "name": "Soil_Clay_Green"
    },
    {
      "x": -36,
      "y": 19,
      "z": -25,
      "name": "Soil_Seaweed_Block"
    },
    {
      "x": -36,
      "y": 20,
      "z": -25,
      "name": "Soil_Seaweed_Block"
    },
    {
      "x": -36,
      "y": 21,
      "z": -25,
      "name": "Soil_Seaweed_Block"
    },
    {
      "x": -36,
      "y": 22,
      "z": -25,
      "name": "Soil_Clay_Lime"
    },
    {
      "x": -36,
      "y": 23,
      "z": -25,
      "name": "Plant_Grass_Sharp"
    },
    {
      "x": -36,
      "y": 34,
      "z": -25,
      "name": "Soil_Clay_Green"
    },
    {
      "x": -36,
      "y": 35,
      "z": -25,
      "name": "Soil_Seaweed_Block"
    },
    {
      "x": -36,
      "y": 18,
      "z": -24,
      "name": "Soil_Clay_Green"
    },
    {
      "x": -36,
      "y": 19,
      "z": -24,
      "name": "Soil_Seaweed_Block"
    },
    {
      "x": -36,
      "y": 20,
      "z": -24,
      "name": "Soil_Seaweed_Block"
    },
    {
      "x": -36,
      "y": 21,
      "z": -24,
      "name": "Soil_Seaweed_Block"
    },
    {
      "x": -36,
      "y": 22,
      "z": -24,
      "name": "Soil_Clay_Lime"
    },
    {
      "x": -36,
      "y": 23,
      "z": -24,
      "name": "Plant_Grass_Sharp"
    },
    {
      "x": -36,
      "y": 33,
      "z": -24,
      "name": "Soil_Clay_Green"
    },
    {
      "x": -36,
      "y": 34,
      "z": -24,
      "name": "Soil_Seaweed_Block"
    },
    {
      "x": -36,
      "y": 35,
      "z": -24,
      "name": "Soil_Seaweed_Block"
    },
    {
      "x": -36,
      "y": 19,
      "z": -23,
      "name": "Soil_Clay_Green"
    },
    {
      "x": -36,
      "y": 20,
      "z": -23,
      "name": "Soil_Seaweed_Block"
    },
    {
      "x": -36,
      "y": 21,
      "z": -23,
      "name": "Soil_Seaweed_Block"
    },
    {
      "x": -36,
      "y": 22,
      "z": -23,
      "name": "Soil_Seaweed_Block"
    },
    {
      "x": -36,
      "y": 23,
      "z": -23,
      "name": "Soil_Seaweed_Block"
    },
    {
      "x": -36,
      "y": 19,
      "z": -22,
      "name": "Soil_Clay_Green"
    },
    {
      "x": -36,
      "y": 20,
      "z": -22,
      "name": "Soil_Clay_Green"
    },
    {
      "x": -36,
      "y": 21,
      "z": -22,
      "name": "Soil_Clay_Green"
    },
    {
      "x": -36,
      "y": 22,
      "z": -22,
      "name": "Soil_Seaweed_Block"
    },
    {
      "x": -36,
      "y": 23,
      "z": -22,
      "name": "Soil_Seaweed_Block"
    },
    {
      "x": -36,
      "y": 24,
      "z": -22,
      "name": "Soil_Seaweed_Block"
    },
    {
      "x": -36,
      "y": 25,
      "z": -22,
      "name": "Soil_Seaweed_Block"
    },
    {
      "x": -36,
      "y": 26,
      "z": -22,
      "name": "Soil_Seaweed_Block"
    },
    {
      "x": -36,
      "y": 20,
      "z": -21,
      "name": "Soil_Clay_Green"
    },
    {
      "x": -36,
      "y": 21,
      "z": -21,
      "name": "Soil_Clay_Green"
    },
    {
      "x": -36,
      "y": 22,
      "z": -21,
      "name": "Soil_Seaweed_Block"
    },
    {
      "x": -36,
      "y": 23,
      "z": -21,
      "name": "Soil_Seaweed_Block"
    },
    {
      "x": -36,
      "y": 24,
      "z": -21,
      "name": "Soil_Seaweed_Block"
    },
    {
      "x": -36,
      "y": 25,
      "z": -21,
      "name": "Soil_Seaweed_Block"
    },
    {
      "x": -36,
      "y": 26,
      "z": -21,
      "name": "Soil_Seaweed_Block"
    },
    {
      "x": -36,
      "y": 27,
      "z": -21,
      "name": "Soil_Seaweed_Block"
    },
    {
      "x": -36,
      "y": 28,
      "z": -21,
      "name": "Soil_Seaweed_Block"
    },
    {
      "x": -36,
      "y": 20,
      "z": -20,
      "name": "Soil_Clay_Green"
    },
    {
      "x": -36,
      "y": 21,
      "z": -20,
      "name": "Soil_Seaweed_Block"
    },
    {
      "x": -36,
      "y": 22,
      "z": -20,
      "name": "Soil_Seaweed_Block"
    },
    {
      "x": -36,
      "y": 23,
      "z": -20,
      "name": "Soil_Seaweed_Block"
    },
    {
      "x": -36,
      "y": 24,
      "z": -20,
      "name": "Soil_Seaweed_Block"
    },
    {
      "x": -36,
      "y": 25,
      "z": -20,
      "name": "Soil_Seaweed_Block"
    },
    {
      "x": -36,
      "y": 26,
      "z": -20,
      "name": "Soil_Seaweed_Block"
    },
    {
      "x": -36,
      "y": 27,
      "z": -20,
      "name": "Soil_Seaweed_Block"
    },
    {
      "x": -36,
      "y": 28,
      "z": -20,
      "name": "Soil_Clay_Lime"
    },
    {
      "x": -36,
      "y": 29,
      "z": -20,
      "name": "Plant_Grass_Sharp"
    },
    {
      "x": -36,
      "y": 19,
      "z": -19,
      "name": "Soil_Clay_Green"
    },
    {
      "x": -36,
      "y": 20,
      "z": -19,
      "name": "Soil_Clay_Green"
    },
    {
      "x": -36,
      "y": 21,
      "z": -19,
      "name": "Soil_Clay_Green"
    },
    {
      "x": -36,
      "y": 22,
      "z": -19,
      "name": "Soil_Clay_Green"
    },
    {
      "x": -36,
      "y": 23,
      "z": -19,
      "name": "Soil_Clay_Green"
    },
    {
      "x": -36,
      "y": 24,
      "z": -19,
      "name": "Soil_Seaweed_Block"
    },
    {
      "x": -36,
      "y": 25,
      "z": -19,
      "name": "Soil_Seaweed_Block"
    },
    {
      "x": -36,
      "y": 26,
      "z": -19,
      "name": "Soil_Seaweed_Block"
    },
    {
      "x": -36,
      "y": 27,
      "z": -19,
      "name": "Soil_Clay_Lime"
    },
    {
      "x": -36,
      "y": 28,
      "z": -19,
      "name": "Plant_Grass_Sharp"
    },
    {
      "x": -36,
      "y": 20,
      "z": -18,
      "name": "Soil_Clay_Green"
    },
    {
      "x": -36,
      "y": 21,
      "z": -18,
      "name": "Soil_Clay_Green"
    },
    {
      "x": -36,
      "y": 22,
      "z": -18,
      "name": "Soil_Clay_Green"
    },
    {
      "x": -36,
      "y": 23,
      "z": -18,
      "name": "Soil_Clay_Green"
    },
    {
      "x": -36,
      "y": 24,
      "z": -18,
      "name": "Soil_Clay_Green"
    },
    {
      "x": -36,
      "y": 25,
      "z": -18,
      "name": "Soil_Seaweed_Block"
    },
    {
      "x": -36,
      "y": 26,
      "z": -18,
      "name": "Soil_Seaweed_Block"
    },
    {
      "x": -35,
      "y": 27,
      "z": -45,
      "name": "Soil_Clay_Green"
    },
    {
      "x": -35,
      "y": 28,
      "z": -45,
      "name": "Soil_Seaweed_Block"
    },
    {
      "x": -35,
      "y": 27,
      "z": -44,
      "name": "Soil_Clay_Green"
    },
    {
      "x": -35,
      "y": 28,
      "z": -44,
      "name": "Soil_Clay_Lime"
    },
    {
      "x": -35,
      "y": 29,
      "z": -44,
      "name": "Plant_Grass_Sharp"
    },
    {
      "x": -35,
      "y": 27,
      "z": -43,
      "name": "Soil_Clay_Green"
    },
    {
      "x": -35,
      "y": 28,
      "z": -43,
      "name": "Soil_Clay_Lime"
    },
    {
      "x": -35,
      "y": 29,
      "z": -43,
      "name": "Plant_Grass_Sharp"
    },
    {
      "x": -35,
      "y": 24,
      "z": -40,
      "name": "Soil_Clay_Green"
    },
    {
      "x": -35,
      "y": 25,
      "z": -40,
      "name": "Soil_Seaweed_Block"
    },
    {
      "x": -35,
      "y": 24,
      "z": -39,
      "name": "Soil_Clay_Green"
    },
    {
      "x": -35,
      "y": 25,
      "z": -39,
      "name": "Soil_Clay_Lime"
    },
    {
      "x": -35,
      "y": 26,
      "z": -39,
      "name": "Plant_Grass_Sharp"
    },
    {
      "x": -35,
      "y": 24,
      "z": -38,
      "name": "Soil_Clay_Green"
    },
    {
      "x": -35,
      "y": 25,
      "z": -38,
      "name": "Soil_Seaweed_Block"
    },
    {
      "x": -35,
      "y": 24,
      "z": -37,
      "name": "Soil_Clay_Green"
    },
    {
      "x": -35,
      "y": 25,
      "z": -37,
      "name": "Soil_Seaweed_Block"
    },
    {
      "x": -35,
      "y": 22,
      "z": -34,
      "name": "Soil_Seaweed_Block"
    },
    {
      "x": -35,
      "y": 22,
      "z": -33,
      "name": "Soil_Seaweed_Block"
    },
    {
      "x": -35,
      "y": 33,
      "z": -33,
      "name": "Soil_Clay_Green"
    },
    {
      "x": -35,
      "y": 34,
      "z": -33,
      "name": "Soil_Seaweed_Block"
    },
    {
      "x": -35,
      "y": 33,
      "z": -32,
      "name": "Soil_Clay_Green"
    },
    {
      "x": -35,
      "y": 34,
      "z": -32,
      "name": "Soil_Seaweed_Block"
    },
    {
      "x": -35,
      "y": 33,
      "z": -31,
      "name": "Soil_Clay_Green"
    },
    {
      "x": -35,
      "y": 34,
      "z": -31,
      "name": "Soil_Seaweed_Block"
    },
    {
      "x": -35,
      "y": 35,
      "z": -31,
      "name": "Soil_Clay_Lime"
    },
    {
      "x": -35,
      "y": 36,
      "z": -31,
      "name": "Plant_Grass_Sharp"
    },
    {
      "x": -35,
      "y": 35,
      "z": -30,
      "name": "Soil_Clay_Lime"
    },
    {
      "x": -35,
      "y": 36,
      "z": -30,
      "name": "Plant_Grass_Sharp"
    },
    {
      "x": -35,
      "y": 24,
      "z": -29,
      "name": "Soil_Seaweed_Block"
    },
    {
      "x": -35,
      "y": 23,
      "z": -28,
      "name": "Soil_Clay_Green"
    },
    {
      "x": -35,
      "y": 24,
      "z": -28,
      "name": "Soil_Clay_Lime"
    },
    {
      "x": -35,
      "y": 25,
      "z": -28,
      "name": "Plant_Grass_Sharp"
    },
    {
      "x": -35,
      "y": 34,
      "z": -28,
      "name": "Soil_Clay_Green"
    },
    {
      "x": -35,
      "y": 35,
      "z": -28,
      "name": "Soil_Seaweed_Block"
    },
    {
      "x": -35,
      "y": 23,
      "z": -27,
      "name": "Soil_Clay_Lime"
    },
    {
      "x": -35,
      "y": 24,
      "z": -27,
      "name": "Plant_Grass_Sharp"
    },
    {
      "x": -35,
      "y": 33,
      "z": -27,
      "name": "Soil_Clay_Green"
    },
    {
      "x": -35,
      "y": 34,
      "z": -27,
      "name": "Soil_Clay_Green"
    },
    {
      "x": -35,
      "y": 35,
      "z": -27,
      "name": "Soil_Seaweed_Block"
    },
    {
      "x": -35,
      "y": 36,
      "z": -27,
      "name": "Soil_Clay_Lime"
    },
    {
      "x": -35,
      "y": 37,
      "z": -27,
      "name": "Plant_Grass_Sharp"
    },
    {
      "x": -35,
      "y": 39,
      "z": -27,
      "name": "Soil_Seaweed_Block"
    },
    {
      "x": -35,
      "y": 19,
      "z": -26,
      "name": "Soil_Clay_Green"
    },
    {
      "x": -35,
      "y": 20,
      "z": -26,
      "name": "Soil_Seaweed_Block"
    },
    {
      "x": -35,
      "y": 22,
      "z": -26,
      "name": "Soil_Clay_Lime"
    },
    {
      "x": -35,
      "y": 23,
      "z": -26,
      "name": "Plant_Grass_Sharp"
    },
    {
      "x": -35,
      "y": 33,
      "z": -26,
      "name": "Soil_Clay_Green"
    },
    {
      "x": -35,
      "y": 34,
      "z": -26,
      "name": "Soil_Seaweed_Block"
    },
    {
      "x": -35,
      "y": 35,
      "z": -26,
      "name": "Soil_Clay_Lime"
    },
    {
      "x": -35,
      "y": 36,
      "z": -26,
      "name": "Soil_Clay_Lime"
    },
    {
      "x": -35,
      "y": 37,
      "z": -26,
      "name": "Soil_Clay_Lime"
    },
    {
      "x": -35,
      "y": 38,
      "z": -26,
      "name": "Soil_Seaweed_Block"
    },
    {
      "x": -35,
      "y": 39,
      "z": -26,
      "name": "Soil_Seaweed_Block"
    },
    {
      "x": -35,
      "y": 19,
      "z": -25,
      "name": "Soil_Clay_Green"
    },
    {
      "x": -35,
      "y": 20,
      "z": -25,
      "name": "Soil_Seaweed_Block"
    },
    {
      "x": -35,
      "y": 21,
      "z": -25,
      "name": "Soil_Seaweed_Block"
    },
    {
      "x": -35,
      "y": 22,
      "z": -25,
      "name": "Soil_Clay_Lime"
    },
    {
      "x": -35,
      "y": 23,
      "z": -25,
      "name": "Plant_Grass_Sharp"
    },
    {
      "x": -35,
      "y": 31,
      "z": -25,
      "name": "Soil_Clay_Green"
    },
    {
      "x": -35,
      "y": 32,
      "z": -25,
      "name": "Soil_Clay_Green"
    },
    {
      "x": -35,
      "y": 33,
      "z": -25,
      "name": "Soil_Clay_Green"
    },
    {
      "x": -35,
      "y": 34,
      "z": -25,
      "name": "Soil_Seaweed_Block"
    },
    {
      "x": -35,
      "y": 35,
      "z": -25,
      "name": "Soil_Seaweed_Block"
    },
    {
      "x": -35,
      "y": 36,
      "z": -25,
      "name": "Soil_Clay_Lime"
    },
    {
      "x": -35,
      "y": 37,
      "z": -25,
      "name": "Soil_Seaweed_Block"
    },
    {
      "x": -35,
      "y": 18,
      "z": -24,
      "name": "Soil_Clay_Green"
    },
    {
      "x": -35,
      "y": 19,
      "z": -24,
      "name": "Soil_Seaweed_Block"
    },
    {
      "x": -35,
      "y": 20,
      "z": -24,
      "name": "Soil_Seaweed_Block"
    },
    {
      "x": -35,
      "y": 21,
      "z": -24,
      "name": "Soil_Seaweed_Block"
    },
    {
      "x": -35,
      "y": 22,
      "z": -24,
      "name": "Soil_Seaweed_Block"
    },
    {
      "x": -35,
      "y": 23,
      "z": -24,
      "name": "Soil_Clay_Lime"
    },
    {
      "x": -35,
      "y": 24,
      "z": -24,
      "name": "Plant_Grass_Sharp"
    },
    {
      "x": -35,
      "y": 30,
      "z": -24,
      "name": "Soil_Clay_Green"
    },
    {
      "x": -35,
      "y": 31,
      "z": -24,
      "name": "Soil_Clay_Green"
    },
    {
      "x": -35,
      "y": 32,
      "z": -24,
      "name": "Soil_Seaweed_Block"
    },
    {
      "x": -35,
      "y": 33,
      "z": -24,
      "name": "Soil_Seaweed_Block"
    },
    {
      "x": -35,
      "y": 35,
      "z": -24,
      "name": "Soil_Seaweed_Block"
    },
    {
      "x": -35,
      "y": 18,
      "z": -23,
      "name": "Soil_Clay_Green"
    },
    {
      "x": -35,
      "y": 19,
      "z": -23,
      "name": "Soil_Seaweed_Block"
    },
    {
      "x": -35,
      "y": 20,
      "z": -23,
      "name": "Soil_Seaweed_Block"
    },
    {
      "x": -35,
      "y": 21,
      "z": -23,
      "name": "Soil_Seaweed_Block"
    },
    {
      "x": -35,
      "y": 22,
      "z": -23,
      "name": "Soil_Seaweed_Block"
    },
    {
      "x": -35,
      "y": 23,
      "z": -23,
      "name": "Soil_Seaweed_Block"
    },
    {
      "x": -35,
      "y": 24,
      "z": -23,
      "name": "Soil_Clay_Lime"
    },
    {
      "x": -35,
      "y": 25,
      "z": -23,
      "name": "Plant_Grass_Sharp"
    },
    {
      "x": -35,
      "y": 30,
      "z": -23,
      "name": "Soil_Clay_Green"
    },
    {
      "x": -35,
      "y": 31,
      "z": -23,
      "name": "Soil_Clay_Green"
    },
    {
      "x": -35,
      "y": 18,
      "z": -22,
      "name": "Soil_Clay_Green"
    },
    {
      "x": -35,
      "y": 19,
      "z": -22,
      "name": "Soil_Seaweed_Block"
    },
    {
      "x": -35,
      "y": 20,
      "z": -22,
      "name": "Soil_Seaweed_Block"
    },
    {
      "x": -35,
      "y": 21,
      "z": -22,
      "name": "Soil_Seaweed_Block"
    },
    {
      "x": -35,
      "y": 22,
      "z": -22,
      "name": "Soil_Seaweed_Block"
    },
    {
      "x": -35,
      "y": 23,
      "z": -22,
      "name": "Soil_Seaweed_Block"
    },
    {
      "x": -35,
      "y": 24,
      "z": -22,
      "name": "Soil_Clay_Lime"
    },
    {
      "x": -35,
      "y": 25,
      "z": -22,
      "name": "Plant_Grass_Sharp"
    },
    {
      "x": -35,
      "y": 18,
      "z": -21,
      "name": "Soil_Clay_Green"
    },
    {
      "x": -35,
      "y": 19,
      "z": -21,
      "name": "Soil_Clay_Green"
    },
    {
      "x": -35,
      "y": 20,
      "z": -21,
      "name": "Soil_Seaweed_Block"
    },
    {
      "x": -35,
      "y": 21,
      "z": -21,
      "name": "Soil_Seaweed_Block"
    },
    {
      "x": -35,
      "y": 22,
      "z": -21,
      "name": "Soil_Seaweed_Block"
    },
    {
      "x": -35,
      "y": 23,
      "z": -21,
      "name": "Soil_Seaweed_Block"
    },
    {
      "x": -35,
      "y": 24,
      "z": -21,
      "name": "Soil_Seaweed_Block"
    },
    {
      "x": -35,
      "y": 25,
      "z": -21,
      "name": "Soil_Clay_Lime"
    },
    {
      "x": -35,
      "y": 26,
      "z": -21,
      "name": "Soil_Seaweed_Block"
    },
    {
      "x": -35,
      "y": 27,
      "z": -21,
      "name": "Soil_Seaweed_Block"
    },
    {
      "x": -35,
      "y": 28,
      "z": -21,
      "name": "Soil_Clay_Lime"
    },
    {
      "x": -35,
      "y": 29,
      "z": -21,
      "name": "Plant_Grass_Sharp"
    },
    {
      "x": -35,
      "y": 18,
      "z": -20,
      "name": "Soil_Clay_Green"
    },
    {
      "x": -35,
      "y": 19,
      "z": -20,
      "name": "Soil_Clay_Green"
    },
    {
      "x": -35,
      "y": 20,
      "z": -20,
      "name": "Soil_Seaweed_Block"
    },
    {
      "x": -35,
      "y": 21,
      "z": -20,
      "name": "Soil_Seaweed_Block"
    },
    {
      "x": -35,
      "y": 22,
      "z": -20,
      "name": "Soil_Seaweed_Block"
    },
    {
      "x": -35,
      "y": 23,
      "z": -20,
      "name": "Soil_Seaweed_Block"
    },
    {
      "x": -35,
      "y": 24,
      "z": -20,
      "name": "Soil_Seaweed_Block"
    },
    {
      "x": -35,
      "y": 25,
      "z": -20,
      "name": "Soil_Seaweed_Block"
    },
    {
      "x": -35,
      "y": 26,
      "z": -20,
      "name": "Soil_Clay_Lime"
    },
    {
      "x": -35,
      "y": 27,
      "z": -20,
      "name": "Soil_Clay_Lime"
    },
    {
      "x": -35,
      "y": 28,
      "z": -20,
      "name": "Plant_Grass_Sharp"
    },
    {
      "x": -35,
      "y": 19,
      "z": -19,
      "name": "Soil_Clay_Green"
    },
    {
      "x": -35,
      "y": 20,
      "z": -19,
      "name": "Soil_Seaweed_Block"
    },
    {
      "x": -35,
      "y": 21,
      "z": -19,
      "name": "Soil_Seaweed_Block"
    },
    {
      "x": -35,
      "y": 22,
      "z": -19,
      "name": "Soil_Seaweed_Block"
    },
    {
      "x": -35,
      "y": 23,
      "z": -19,
      "name": "Soil_Seaweed_Block"
    },
    {
      "x": -35,
      "y": 24,
      "z": -19,
      "name": "Soil_Seaweed_Block"
    },
    {
      "x": -35,
      "y": 25,
      "z": -19,
      "name": "Soil_Seaweed_Block"
    },
    {
      "x": -35,
      "y": 26,
      "z": -19,
      "name": "Soil_Clay_Lime"
    },
    {
      "x": -35,
      "y": 27,
      "z": -19,
      "name": "Plant_Grass_Sharp"
    },
    {
      "x": -35,
      "y": 20,
      "z": -18,
      "name": "Soil_Clay_Green"
    },
    {
      "x": -35,
      "y": 21,
      "z": -18,
      "name": "Soil_Seaweed_Block"
    },
    {
      "x": -35,
      "y": 22,
      "z": -18,
      "name": "Soil_Seaweed_Block"
    },
    {
      "x": -35,
      "y": 23,
      "z": -18,
      "name": "Soil_Seaweed_Block"
    },
    {
      "x": -35,
      "y": 24,
      "z": -18,
      "name": "Soil_Seaweed_Block"
    },
    {
      "x": -35,
      "y": 25,
      "z": -18,
      "name": "Soil_Seaweed_Block"
    },
    {
      "x": -35,
      "y": 26,
      "z": -18,
      "name": "Soil_Clay_Lime"
    },
    {
      "x": -35,
      "y": 27,
      "z": -18,
      "name": "Plant_Grass_Sharp"
    },
    {
      "x": -35,
      "y": 20,
      "z": -17,
      "name": "Soil_Clay_Green"
    },
    {
      "x": -35,
      "y": 21,
      "z": -17,
      "name": "Soil_Clay_Green"
    },
    {
      "x": -35,
      "y": 22,
      "z": -17,
      "name": "Soil_Seaweed_Block"
    },
    {
      "x": -35,
      "y": 23,
      "z": -17,
      "name": "Soil_Seaweed_Block"
    },
    {
      "x": -35,
      "y": 20,
      "z": -16,
      "name": "Soil_Clay_Green"
    },
    {
      "x": -34,
      "y": 27,
      "z": -43,
      "name": "Soil_Seaweed_Block"
    },
    {
      "x": -34,
      "y": 28,
      "z": -43,
      "name": "Soil_Clay_Lime"
    },
    {
      "x": -34,
      "y": 29,
      "z": -43,
      "name": "Plant_Grass_Sharp"
    },
    {
      "x": -34,
      "y": 25,
      "z": -42,
      "name": "Soil_Clay_Green"
    },
    {
      "x": -34,
      "y": 26,
      "z": -42,
      "name": "Soil_Seaweed_Block"
    },
    {
      "x": -34,
      "y": 27,
      "z": -42,
      "name": "Soil_Clay_Lime"
    },
    {
      "x": -34,
      "y": 28,
      "z": -42,
      "name": "Plant_Grass_Sharp"
    },
    {
      "x": -34,
      "y": 25,
      "z": -41,
      "name": "Soil_Clay_Green"
    },
    {
      "x": -34,
      "y": 26,
      "z": -41,
      "name": "Soil_Clay_Lime"
    },
    {
      "x": -34,
      "y": 27,
      "z": -41,
      "name": "Soil_Clay_Lime"
    },
    {
      "x": -34,
      "y": 28,
      "z": -41,
      "name": "Plant_Grass_Sharp"
    },
    {
      "x": -34,
      "y": 24,
      "z": -40,
      "name": "Soil_Clay_Green"
    },
    {
      "x": -34,
      "y": 25,
      "z": -40,
      "name": "Soil_Seaweed_Block"
    },
    {
      "x": -34,
      "y": 26,
      "z": -40,
      "name": "Soil_Clay_Lime"
    },
    {
      "x": -34,
      "y": 27,
      "z": -40,
      "name": "Plant_Grass_Sharp"
    },
    {
      "x": -34,
      "y": 23,
      "z": -39,
      "name": "Soil_Clay_Green"
    },
    {
      "x": -34,
      "y": 24,
      "z": -39,
      "name": "Soil_Seaweed_Block"
    },
    {
      "x": -34,
      "y": 25,
      "z": -39,
      "name": "Soil_Seaweed_Block"
    },
    {
      "x": -34,
      "y": 26,
      "z": -39,
      "name": "Soil_Clay_Lime"
    },
    {
      "x": -34,
      "y": 27,
      "z": -39,
      "name": "Plant_Grass_Sharp"
    },
    {
      "x": -34,
      "y": 23,
      "z": -38,
      "name": "Soil_Clay_Green"
    },
    {
      "x": -34,
      "y": 24,
      "z": -38,
      "name": "Soil_Clay_Green"
    },
    {
      "x": -34,
      "y": 25,
      "z": -38,
      "name": "Soil_Seaweed_Block"
    },
    {
      "x": -34,
      "y": 26,
      "z": -38,
      "name": "Soil_Clay_Lime"
    },
    {
      "x": -34,
      "y": 27,
      "z": -38,
      "name": "Plant_Grass_Sharp"
    },
    {
      "x": -34,
      "y": 23,
      "z": -34,
      "name": "Soil_Clay_Lime"
    },
    {
      "x": -34,
      "y": 24,
      "z": -34,
      "name": "Plant_Grass_Sharp"
    },
    {
      "x": -34,
      "y": 22,
      "z": -33,
      "name": "Soil_Clay_Green"
    },
    {
      "x": -34,
      "y": 33,
      "z": -30,
      "name": "Soil_Clay_Green"
    },
    {
      "x": -34,
      "y": 34,
      "z": -30,
      "name": "Soil_Clay_Green"
    },
    {
      "x": -34,
      "y": 35,
      "z": -30,
      "name": "Soil_Clay_Lime"
    },
    {
      "x": -34,
      "y": 36,
      "z": -30,
      "name": "Plant_Grass_Sharp"
    },
    {
      "x": -34,
      "y": 24,
      "z": -29,
      "name": "Soil_Seaweed_Block"
    },
    {
      "x": -34,
      "y": 34,
      "z": -29,
      "name": "Soil_Clay_Green"
    },
    {
      "x": -34,
      "y": 35,
      "z": -29,
      "name": "Soil_Clay_Lime"
    },
    {
      "x": -34,
      "y": 36,
      "z": -29,
      "name": "Plant_Grass_Sharp"
    },
    {
      "x": -34,
      "y": 34,
      "z": -28,
      "name": "Soil_Clay_Green"
    },
    {
      "x": -34,
      "y": 35,
      "z": -28,
      "name": "Soil_Clay_Lime"
    },
    {
      "x": -34,
      "y": 36,
      "z": -28,
      "name": "Plant_Grass_Sharp"
    },
    {
      "x": -34,
      "y": 23,
      "z": -27,
      "name": "Soil_Clay_Lime"
    },
    {
      "x": -34,
      "y": 24,
      "z": -27,
      "name": "Plant_Grass_Sharp"
    },
    {
      "x": -34,
      "y": 33,
      "z": -27,
      "name": "Soil_Clay_Green"
    },
    {
      "x": -34,
      "y": 34,
      "z": -27,
      "name": "Soil_Seaweed_Block"
    },
    {
      "x": -34,
      "y": 35,
      "z": -27,
      "name": "Soil_Seaweed_Block"
    },
    {
      "x": -34,
      "y": 36,
      "z": -27,
      "name": "Soil_Clay_Lime"
    },
    {
      "x": -34,
      "y": 37,
      "z": -27,
      "name": "Plant_Grass_Sharp"
    },
    {
      "x": -34,
      "y": 19,
      "z": -26,
      "name": "Soil_Clay_Green"
    },
    {
      "x": -34,
      "y": 20,
      "z": -26,
      "name": "Soil_Clay_Green"
    },
    {
      "x": -34,
      "y": 31,
      "z": -26,
      "name": "Soil_Clay_Green"
    },
    {
      "x": -34,
      "y": 32,
      "z": -26,
      "name": "Soil_Clay_Green"
    },
    {
      "x": -34,
      "y": 33,
      "z": -26,
      "name": "Soil_Seaweed_Block"
    },
    {
      "x": -34,
      "y": 34,
      "z": -26,
      "name": "Soil_Seaweed_Block"
    },
    {
      "x": -34,
      "y": 35,
      "z": -26,
      "name": "Soil_Clay_Lime"
    },
    {
      "x": -34,
      "y": 36,
      "z": -26,
      "name": "Soil_Clay_Lime"
    },
    {
      "x": -34,
      "y": 37,
      "z": -26,
      "name": "Soil_Seaweed_Block"
    },
    {
      "x": -34,
      "y": 19,
      "z": -25,
      "name": "Soil_Clay_Green"
    },
    {
      "x": -34,
      "y": 20,
      "z": -25,
      "name": "Soil_Clay_Green"
    },
    {
      "x": -34,
      "y": 21,
      "z": -25,
      "name": "Soil_Seaweed_Block"
    },
    {
      "x": -34,
      "y": 22,
      "z": -25,
      "name": "Soil_Seaweed_Block"
    },
    {
      "x": -34,
      "y": 30,
      "z": -25,
      "name": "Soil_Clay_Green"
    },
    {
      "x": -34,
      "y": 31,
      "z": -25,
      "name": "Soil_Seaweed_Block"
    },
    {
      "x": -34,
      "y": 32,
      "z": -25,
      "name": "Soil_Seaweed_Block"
    },
    {
      "x": -34,
      "y": 33,
      "z": -25,
      "name": "Soil_Seaweed_Block"
    },
    {
      "x": -34,
      "y": 34,
      "z": -25,
      "name": "Soil_Seaweed_Block"
    },
    {
      "x": -34,
      "y": 35,
      "z": -25,
      "name": "Soil_Clay_Lime"
    },
    {
      "x": -34,
      "y": 36,
      "z": -25,
      "name": "Soil_Seaweed_Block"
    },
    {
      "x": -34,
      "y": 18,
      "z": -24,
      "name": "Soil_Clay_Green"
    },
    {
      "x": -34,
      "y": 19,
      "z": -24,
      "name": "Soil_Seaweed_Block"
    },
    {
      "x": -34,
      "y": 20,
      "z": -24,
      "name": "Soil_Seaweed_Block"
    },
    {
      "x": -34,
      "y": 21,
      "z": -24,
      "name": "Soil_Seaweed_Block"
    },
    {
      "x": -34,
      "y": 22,
      "z": -24,
      "name": "Soil_Seaweed_Block"
    },
    {
      "x": -34,
      "y": 23,
      "z": -24,
      "name": "Soil_Clay_Lime"
    },
    {
      "x": -34,
      "y": 24,
      "z": -24,
      "name": "Plant_Grass_Sharp"
    },
    {
      "x": -34,
      "y": 30,
      "z": -24,
      "name": "Soil_Clay_Green"
    },
    {
      "x": -34,
      "y": 31,
      "z": -24,
      "name": "Soil_Seaweed_Block"
    },
    {
      "x": -34,
      "y": 32,
      "z": -24,
      "name": "Soil_Seaweed_Block"
    },
    {
      "x": -34,
      "y": 33,
      "z": -24,
      "name": "Soil_Seaweed_Block"
    },
    {
      "x": -34,
      "y": 35,
      "z": -24,
      "name": "Soil_Seaweed_Block"
    },
    {
      "x": -34,
      "y": 18,
      "z": -23,
      "name": "Soil_Clay_Green"
    },
    {
      "x": -34,
      "y": 19,
      "z": -23,
      "name": "Soil_Seaweed_Block"
    },
    {
      "x": -34,
      "y": 20,
      "z": -23,
      "name": "Soil_Seaweed_Block"
    },
    {
      "x": -34,
      "y": 21,
      "z": -23,
      "name": "Soil_Seaweed_Block"
    },
    {
      "x": -34,
      "y": 22,
      "z": -23,
      "name": "Soil_Seaweed_Block"
    },
    {
      "x": -34,
      "y": 23,
      "z": -23,
      "name": "Soil_Clay_Lime"
    },
    {
      "x": -34,
      "y": 24,
      "z": -23,
      "name": "Plant_Grass_Sharp"
    },
    {
      "x": -34,
      "y": 30,
      "z": -23,
      "name": "Soil_Clay_Green"
    },
    {
      "x": -34,
      "y": 31,
      "z": -23,
      "name": "Soil_Seaweed_Block"
    },
    {
      "x": -34,
      "y": 17,
      "z": -22,
      "name": "Soil_Clay_Green"
    },
    {
      "x": -34,
      "y": 18,
      "z": -22,
      "name": "Soil_Seaweed_Block"
    },
    {
      "x": -34,
      "y": 19,
      "z": -22,
      "name": "Soil_Seaweed_Block"
    },
    {
      "x": -34,
      "y": 20,
      "z": -22,
      "name": "Soil_Seaweed_Block"
    },
    {
      "x": -34,
      "y": 21,
      "z": -22,
      "name": "Soil_Seaweed_Block"
    },
    {
      "x": -34,
      "y": 22,
      "z": -22,
      "name": "Soil_Seaweed_Block"
    },
    {
      "x": -34,
      "y": 23,
      "z": -22,
      "name": "Soil_Seaweed_Block"
    },
    {
      "x": -34,
      "y": 24,
      "z": -22,
      "name": "Soil_Clay_Lime"
    },
    {
      "x": -34,
      "y": 25,
      "z": -22,
      "name": "Plant_Grass_Sharp"
    },
    {
      "x": -34,
      "y": 16,
      "z": -21,
      "name": "Soil_Clay_Green"
    },
    {
      "x": -34,
      "y": 17,
      "z": -21,
      "name": "Soil_Clay_Green"
    },
    {
      "x": -34,
      "y": 18,
      "z": -21,
      "name": "Soil_Seaweed_Block"
    },
    {
      "x": -34,
      "y": 19,
      "z": -21,
      "name": "Soil_Seaweed_Block"
    },
    {
      "x": -34,
      "y": 20,
      "z": -21,
      "name": "Soil_Seaweed_Block"
    },
    {
      "x": -34,
      "y": 21,
      "z": -21,
      "name": "Soil_Seaweed_Block"
    },
    {
      "x": -34,
      "y": 22,
      "z": -21,
      "name": "Soil_Seaweed_Block"
    },
    {
      "x": -34,
      "y": 23,
      "z": -21,
      "name": "Soil_Seaweed_Block"
    },
    {
      "x": -34,
      "y": 24,
      "z": -21,
      "name": "Soil_Clay_Lime"
    },
    {
      "x": -34,
      "y": 25,
      "z": -21,
      "name": "Plant_Grass_Sharp"
    },
    {
      "x": -34,
      "y": 18,
      "z": -20,
      "name": "Soil_Clay_Green"
    },
    {
      "x": -34,
      "y": 19,
      "z": -20,
      "name": "Soil_Seaweed_Block"
    },
    {
      "x": -34,
      "y": 20,
      "z": -20,
      "name": "Soil_Seaweed_Block"
    },
    {
      "x": -34,
      "y": 21,
      "z": -20,
      "name": "Soil_Seaweed_Block"
    },
    {
      "x": -34,
      "y": 22,
      "z": -20,
      "name": "Soil_Seaweed_Block"
    },
    {
      "x": -34,
      "y": 23,
      "z": -20,
      "name": "Soil_Seaweed_Block"
    },
    {
      "x": -34,
      "y": 24,
      "z": -20,
      "name": "Soil_Seaweed_Block"
    },
    {
      "x": -34,
      "y": 25,
      "z": -20,
      "name": "Soil_Clay_Lime"
    },
    {
      "x": -34,
      "y": 26,
      "z": -20,
      "name": "Plant_Grass_Sharp"
    },
    {
      "x": -34,
      "y": 16,
      "z": -19,
      "name": "Soil_Clay_Green"
    },
    {
      "x": -34,
      "y": 17,
      "z": -19,
      "name": "Soil_Clay_Green"
    },
    {
      "x": -34,
      "y": 18,
      "z": -19,
      "name": "Soil_Clay_Green"
    },
    {
      "x": -34,
      "y": 19,
      "z": -19,
      "name": "Soil_Seaweed_Block"
    },
    {
      "x": -34,
      "y": 20,
      "z": -19,
      "name": "Soil_Seaweed_Block"
    },
    {
      "x": -34,
      "y": 21,
      "z": -19,
      "name": "Soil_Seaweed_Block"
    },
    {
      "x": -34,
      "y": 22,
      "z": -19,
      "name": "Soil_Seaweed_Block"
    },
    {
      "x": -34,
      "y": 23,
      "z": -19,
      "name": "Soil_Seaweed_Block"
    },
    {
      "x": -34,
      "y": 24,
      "z": -19,
      "name": "Soil_Seaweed_Block"
    },
    {
      "x": -34,
      "y": 25,
      "z": -19,
      "name": "Soil_Seaweed_Block"
    },
    {
      "x": -34,
      "y": 26,
      "z": -19,
      "name": "Soil_Clay_Lime"
    },
    {
      "x": -34,
      "y": 27,
      "z": -19,
      "name": "Plant_Grass_Sharp"
    },
    {
      "x": -34,
      "y": 19,
      "z": -18,
      "name": "Soil_Clay_Green"
    },
    {
      "x": -34,
      "y": 20,
      "z": -18,
      "name": "Soil_Seaweed_Block"
    },
    {
      "x": -34,
      "y": 21,
      "z": -18,
      "name": "Soil_Seaweed_Block"
    },
    {
      "x": -34,
      "y": 22,
      "z": -18,
      "name": "Soil_Seaweed_Block"
    },
    {
      "x": -34,
      "y": 23,
      "z": -18,
      "name": "Soil_Seaweed_Block"
    },
    {
      "x": -34,
      "y": 24,
      "z": -18,
      "name": "Soil_Seaweed_Block"
    },
    {
      "x": -34,
      "y": 25,
      "z": -18,
      "name": "Soil_Seaweed_Block"
    },
    {
      "x": -34,
      "y": 26,
      "z": -18,
      "name": "Soil_Clay_Lime"
    },
    {
      "x": -34,
      "y": 27,
      "z": -18,
      "name": "Plant_Grass_Sharp"
    },
    {
      "x": -34,
      "y": 19,
      "z": -17,
      "name": "Soil_Clay_Green"
    },
    {
      "x": -34,
      "y": 20,
      "z": -17,
      "name": "Soil_Seaweed_Block"
    },
    {
      "x": -34,
      "y": 21,
      "z": -17,
      "name": "Soil_Clay_Green"
    },
    {
      "x": -34,
      "y": 22,
      "z": -17,
      "name": "Soil_Seaweed_Block"
    },
    {
      "x": -34,
      "y": 23,
      "z": -17,
      "name": "Soil_Seaweed_Block"
    },
    {
      "x": -34,
      "y": 24,
      "z": -17,
      "name": "Soil_Seaweed_Block"
    },
    {
      "x": -34,
      "y": 25,
      "z": -17,
      "name": "Soil_Seaweed_Block"
    },
    {
      "x": -34,
      "y": 26,
      "z": -17,
      "name": "Soil_Clay_Lime"
    },
    {
      "x": -34,
      "y": 27,
      "z": -17,
      "name": "Plant_Grass_Sharp"
    },
    {
      "x": -34,
      "y": 20,
      "z": -16,
      "name": "Soil_Clay_Green"
    },
    {
      "x": -33,
      "y": 25,
      "z": -40,
      "name": "Soil_Seaweed_Block"
    },
    {
      "x": -33,
      "y": 23,
      "z": -39,
      "name": "Soil_Clay_Green"
    },
    {
      "x": -33,
      "y": 24,
      "z": -39,
      "name": "Soil_Clay_Green"
    },
    {
      "x": -33,
      "y": 25,
      "z": -39,
      "name": "Soil_Seaweed_Block"
    },
    {
      "x": -33,
      "y": 26,
      "z": -39,
      "name": "Soil_Clay_Lime"
    },
    {
      "x": -33,
      "y": 27,
      "z": -39,
      "name": "Plant_Grass_Sharp"
    },
    {
      "x": -33,
      "y": 23,
      "z": -38,
      "name": "Soil_Clay_Green"
    },
    {
      "x": -33,
      "y": 24,
      "z": -38,
      "name": "Soil_Clay_Green"
    },
    {
      "x": -33,
      "y": 25,
      "z": -38,
      "name": "Soil_Seaweed_Block"
    },
    {
      "x": -33,
      "y": 26,
      "z": -38,
      "name": "Soil_Clay_Lime"
    },
    {
      "x": -33,
      "y": 27,
      "z": -38,
      "name": "Plant_Grass_Sharp"
    },
    {
      "x": -33,
      "y": 25,
      "z": -37,
      "name": "Soil_Seaweed_Block"
    },
    {
      "x": -33,
      "y": 26,
      "z": -37,
      "name": "Soil_Clay_Lime"
    },
    {
      "x": -33,
      "y": 27,
      "z": -37,
      "name": "Plant_Grass_Sharp"
    },
    {
      "x": -33,
      "y": 23,
      "z": -34,
      "name": "Soil_Clay_Green"
    },
    {
      "x": -33,
      "y": 22,
      "z": -33,
      "name": "Soil_Clay_Green"
    },
    {
      "x": -33,
      "y": 34,
      "z": -30,
      "name": "Soil_Clay_Green"
    },
    {
      "x": -33,
      "y": 35,
      "z": -29,
      "name": "Soil_Seaweed_Block"
    },
    {
      "x": -33,
      "y": 35,
      "z": -28,
      "name": "Soil_Seaweed_Block"
    },
    {
      "x": -33,
      "y": 36,
      "z": -28,
      "name": "Soil_Seaweed_Block"
    },
    {
      "x": -33,
      "y": 32,
      "z": -27,
      "name": "Soil_Clay_Green"
    },
    {
      "x": -33,
      "y": 33,
      "z": -27,
      "name": "Soil_Clay_Green"
    },
    {
      "x": -33,
      "y": 34,
      "z": -27,
      "name": "Soil_Seaweed_Block"
    },
    {
      "x": -33,
      "y": 35,
      "z": -27,
      "name": "Soil_Seaweed_Block"
    },
    {
      "x": -33,
      "y": 30,
      "z": -26,
      "name": "Soil_Clay_Green"
    },
    {
      "x": -33,
      "y": 31,
      "z": -26,
      "name": "Soil_Clay_Green"
    },
    {
      "x": -33,
      "y": 32,
      "z": -26,
      "name": "Soil_Seaweed_Block"
    },
    {
      "x": -33,
      "y": 33,
      "z": -26,
      "name": "Soil_Seaweed_Block"
    },
    {
      "x": -33,
      "y": 34,
      "z": -26,
      "name": "Soil_Seaweed_Block"
    },
    {
      "x": -33,
      "y": 29,
      "z": -25,
      "name": "Soil_Clay_Green"
    },
    {
      "x": -33,
      "y": 30,
      "z": -25,
      "name": "Soil_Seaweed_Block"
    },
    {
      "x": -33,
      "y": 31,
      "z": -25,
      "name": "Soil_Seaweed_Block"
    },
    {
      "x": -33,
      "y": 32,
      "z": -25,
      "name": "Soil_Seaweed_Block"
    },
    {
      "x": -33,
      "y": 33,
      "z": -25,
      "name": "Soil_Seaweed_Block"
    },
    {
      "x": -33,
      "y": 34,
      "z": -25,
      "name": "Soil_Seaweed_Block"
    },
    {
      "x": -33,
      "y": 18,
      "z": -24,
      "name": "Soil_Clay_Green"
    },
    {
      "x": -33,
      "y": 19,
      "z": -24,
      "name": "Soil_Clay_Green"
    },
    {
      "x": -33,
      "y": 20,
      "z": -24,
      "name": "Soil_Clay_Green"
    },
    {
      "x": -33,
      "y": 21,
      "z": -24,
      "name": "Soil_Seaweed_Block"
    },
    {
      "x": -33,
      "y": 22,
      "z": -24,
      "name": "Soil_Seaweed_Block"
    },
    {
      "x": -33,
      "y": 29,
      "z": -24,
      "name": "Soil_Clay_Green"
    },
    {
      "x": -33,
      "y": 30,
      "z": -24,
      "name": "Soil_Seaweed_Block"
    },
    {
      "x": -33,
      "y": 31,
      "z": -24,
      "name": "Soil_Seaweed_Block"
    },
    {
      "x": -33,
      "y": 32,
      "z": -24,
      "name": "Soil_Seaweed_Block"
    },
    {
      "x": -33,
      "y": 33,
      "z": -24,
      "name": "Soil_Seaweed_Block"
    },
    {
      "x": -33,
      "y": 17,
      "z": -23,
      "name": "Soil_Clay_Green"
    },
    {
      "x": -33,
      "y": 18,
      "z": -23,
      "name": "Soil_Seaweed_Block"
    },
    {
      "x": -33,
      "y": 19,
      "z": -23,
      "name": "Soil_Seaweed_Block"
    },
    {
      "x": -33,
      "y": 20,
      "z": -23,
      "name": "Soil_Seaweed_Block"
    },
    {
      "x": -33,
      "y": 21,
      "z": -23,
      "name": "Soil_Seaweed_Block"
    },
    {
      "x": -33,
      "y": 22,
      "z": -23,
      "name": "Soil_Seaweed_Block"
    },
    {
      "x": -33,
      "y": 23,
      "z": -23,
      "name": "Soil_Clay_Lime"
    },
    {
      "x": -33,
      "y": 24,
      "z": -23,
      "name": "Plant_Grass_Sharp"
    },
    {
      "x": -33,
      "y": 29,
      "z": -23,
      "name": "Soil_Clay_Green"
    },
    {
      "x": -33,
      "y": 30,
      "z": -23,
      "name": "Soil_Seaweed_Block"
    },
    {
      "x": -33,
      "y": 31,
      "z": -23,
      "name": "Soil_Seaweed_Block"
    },
    {
      "x": -33,
      "y": 32,
      "z": -23,
      "name": "Soil_Seaweed_Block"
    },
    {
      "x": -33,
      "y": 15,
      "z": -22,
      "name": "Soil_Clay_Green"
    },
    {
      "x": -33,
      "y": 16,
      "z": -22,
      "name": "Soil_Clay_Green"
    },
    {
      "x": -33,
      "y": 17,
      "z": -22,
      "name": "Soil_Seaweed_Block"
    },
    {
      "x": -33,
      "y": 18,
      "z": -22,
      "name": "Soil_Seaweed_Block"
    },
    {
      "x": -33,
      "y": 19,
      "z": -22,
      "name": "Soil_Seaweed_Block"
    },
    {
      "x": -33,
      "y": 20,
      "z": -22,
      "name": "Soil_Seaweed_Block"
    },
    {
      "x": -33,
      "y": 21,
      "z": -22,
      "name": "Soil_Seaweed_Block"
    },
    {
      "x": -33,
      "y": 22,
      "z": -22,
      "name": "Soil_Seaweed_Block"
    },
    {
      "x": -33,
      "y": 23,
      "z": -22,
      "name": "Soil_Seaweed_Block"
    },
    {
      "x": -33,
      "y": 24,
      "z": -22,
      "name": "Soil_Clay_Lime"
    },
    {
      "x": -33,
      "y": 25,
      "z": -22,
      "name": "Plant_Grass_Sharp"
    },
    {
      "x": -33,
      "y": 29,
      "z": -22,
      "name": "Soil_Clay_Green"
    },
    {
      "x": -33,
      "y": 30,
      "z": -22,
      "name": "Soil_Seaweed_Block"
    },
    {
      "x": -33,
      "y": 31,
      "z": -22,
      "name": "Soil_Seaweed_Block"
    },
    {
      "x": -33,
      "y": 15,
      "z": -21,
      "name": "Soil_Clay_Green"
    },
    {
      "x": -33,
      "y": 16,
      "z": -21,
      "name": "Soil_Seaweed_Block"
    },
    {
      "x": -33,
      "y": 17,
      "z": -21,
      "name": "Soil_Seaweed_Block"
    },
    {
      "x": -33,
      "y": 18,
      "z": -21,
      "name": "Soil_Seaweed_Block"
    },
    {
      "x": -33,
      "y": 19,
      "z": -21,
      "name": "Soil_Seaweed_Block"
    },
    {
      "x": -33,
      "y": 20,
      "z": -21,
      "name": "Soil_Seaweed_Block"
    },
    {
      "x": -33,
      "y": 21,
      "z": -21,
      "name": "Soil_Seaweed_Block"
    },
    {
      "x": -33,
      "y": 22,
      "z": -21,
      "name": "Soil_Seaweed_Block"
    },
    {
      "x": -33,
      "y": 23,
      "z": -21,
      "name": "Soil_Seaweed_Block"
    },
    {
      "x": -33,
      "y": 24,
      "z": -21,
      "name": "Soil_Clay_Lime"
    },
    {
      "x": -33,
      "y": 25,
      "z": -21,
      "name": "Plant_Grass_Sharp"
    },
    {
      "x": -33,
      "y": 15,
      "z": -20,
      "name": "Soil_Clay_Green"
    },
    {
      "x": -33,
      "y": 16,
      "z": -20,
      "name": "Soil_Clay_Green"
    },
    {
      "x": -33,
      "y": 17,
      "z": -20,
      "name": "Soil_Clay_Green"
    },
    {
      "x": -33,
      "y": 18,
      "z": -20,
      "name": "Soil_Seaweed_Block"
    },
    {
      "x": -33,
      "y": 19,
      "z": -20,
      "name": "Soil_Seaweed_Block"
    },
    {
      "x": -33,
      "y": 20,
      "z": -20,
      "name": "Soil_Seaweed_Block"
    },
    {
      "x": -33,
      "y": 21,
      "z": -20,
      "name": "Soil_Seaweed_Block"
    },
    {
      "x": -33,
      "y": 22,
      "z": -20,
      "name": "Soil_Seaweed_Block"
    },
    {
      "x": -33,
      "y": 23,
      "z": -20,
      "name": "Soil_Seaweed_Block"
    },
    {
      "x": -33,
      "y": 24,
      "z": -20,
      "name": "Soil_Seaweed_Block"
    },
    {
      "x": -33,
      "y": 25,
      "z": -20,
      "name": "Soil_Clay_Lime"
    },
    {
      "x": -33,
      "y": 26,
      "z": -20,
      "name": "Soil_Clay_Lime"
    },
    {
      "x": -33,
      "y": 27,
      "z": -20,
      "name": "Plant_Grass_Sharp"
    },
    {
      "x": -33,
      "y": 15,
      "z": -19,
      "name": "Soil_Clay_Green"
    },
    {
      "x": -33,
      "y": 16,
      "z": -19,
      "name": "Soil_Clay_Green"
    },
    {
      "x": -33,
      "y": 17,
      "z": -19,
      "name": "Soil_Clay_Green"
    },
    {
      "x": -33,
      "y": 18,
      "z": -19,
      "name": "Soil_Seaweed_Block"
    },
    {
      "x": -33,
      "y": 19,
      "z": -19,
      "name": "Soil_Seaweed_Block"
    },
    {
      "x": -33,
      "y": 20,
      "z": -19,
      "name": "Soil_Seaweed_Block"
    },
    {
      "x": -33,
      "y": 21,
      "z": -19,
      "name": "Soil_Seaweed_Block"
    },
    {
      "x": -33,
      "y": 22,
      "z": -19,
      "name": "Soil_Seaweed_Block"
    },
    {
      "x": -33,
      "y": 23,
      "z": -19,
      "name": "Soil_Seaweed_Block"
    },
    {
      "x": -33,
      "y": 24,
      "z": -19,
      "name": "Soil_Seaweed_Block"
    },
    {
      "x": -33,
      "y": 25,
      "z": -19,
      "name": "Soil_Seaweed_Block"
    },
    {
      "x": -33,
      "y": 26,
      "z": -19,
      "name": "Soil_Clay_Lime"
    },
    {
      "x": -33,
      "y": 27,
      "z": -19,
      "name": "Plant_Grass_Sharp"
    },
    {
      "x": -33,
      "y": 18,
      "z": -18,
      "name": "Soil_Clay_Green"
    },
    {
      "x": -33,
      "y": 19,
      "z": -18,
      "name": "Soil_Seaweed_Block"
    },
    {
      "x": -33,
      "y": 20,
      "z": -18,
      "name": "Soil_Seaweed_Block"
    },
    {
      "x": -33,
      "y": 21,
      "z": -18,
      "name": "Soil_Seaweed_Block"
    },
    {
      "x": -33,
      "y": 22,
      "z": -18,
      "name": "Soil_Seaweed_Block"
    },
    {
      "x": -33,
      "y": 23,
      "z": -18,
      "name": "Soil_Seaweed_Block"
    },
    {
      "x": -33,
      "y": 24,
      "z": -18,
      "name": "Soil_Seaweed_Block"
    },
    {
      "x": -33,
      "y": 25,
      "z": -18,
      "name": "Soil_Seaweed_Block"
    },
    {
      "x": -33,
      "y": 26,
      "z": -18,
      "name": "Soil_Clay_Lime"
    },
    {
      "x": -33,
      "y": 27,
      "z": -18,
      "name": "Plant_Grass_Sharp"
    },
    {
      "x": -33,
      "y": 19,
      "z": -17,
      "name": "Soil_Clay_Green"
    },
    {
      "x": -33,
      "y": 20,
      "z": -17,
      "name": "Soil_Seaweed_Block"
    },
    {
      "x": -33,
      "y": 21,
      "z": -17,
      "name": "Soil_Seaweed_Block"
    },
    {
      "x": -33,
      "y": 22,
      "z": -17,
      "name": "Soil_Seaweed_Block"
    },
    {
      "x": -33,
      "y": 23,
      "z": -17,
      "name": "Soil_Seaweed_Block"
    },
    {
      "x": -33,
      "y": 24,
      "z": -17,
      "name": "Soil_Seaweed_Block"
    },
    {
      "x": -33,
      "y": 25,
      "z": -17,
      "name": "Soil_Seaweed_Block"
    },
    {
      "x": -33,
      "y": 26,
      "z": -17,
      "name": "Soil_Clay_Lime"
    },
    {
      "x": -33,
      "y": 27,
      "z": -17,
      "name": "Plant_Grass_Sharp"
    },
    {
      "x": -33,
      "y": 20,
      "z": -16,
      "name": "Soil_Clay_Green"
    },
    {
      "x": -33,
      "y": 21,
      "z": -16,
      "name": "Soil_Clay_Green"
    },
    {
      "x": -33,
      "y": 22,
      "z": -16,
      "name": "Soil_Seaweed_Block"
    },
    {
      "x": -33,
      "y": 23,
      "z": -16,
      "name": "Soil_Seaweed_Block"
    },
    {
      "x": -33,
      "y": 24,
      "z": -16,
      "name": "Soil_Seaweed_Block"
    },
    {
      "x": -33,
      "y": 25,
      "z": -16,
      "name": "Soil_Seaweed_Block"
    },
    {
      "x": -33,
      "y": 21,
      "z": -15,
      "name": "Soil_Clay_Green"
    },
    {
      "x": -33,
      "y": 22,
      "z": -15,
      "name": "Soil_Seaweed_Block"
    },
    {
      "x": -32,
      "y": 25,
      "z": -40,
      "name": "Soil_Clay_Green"
    },
    {
      "x": -32,
      "y": 24,
      "z": -39,
      "name": "Soil_Clay_Green"
    },
    {
      "x": -32,
      "y": 25,
      "z": -39,
      "name": "Soil_Seaweed_Block"
    },
    {
      "x": -32,
      "y": 26,
      "z": -39,
      "name": "Soil_Clay_Lime"
    },
    {
      "x": -32,
      "y": 27,
      "z": -39,
      "name": "Plant_Grass_Sharp"
    },
    {
      "x": -32,
      "y": 24,
      "z": -38,
      "name": "Soil_Clay_Green"
    },
    {
      "x": -32,
      "y": 25,
      "z": -38,
      "name": "Soil_Seaweed_Block"
    },
    {
      "x": -32,
      "y": 26,
      "z": -38,
      "name": "Soil_Clay_Lime"
    },
    {
      "x": -32,
      "y": 27,
      "z": -38,
      "name": "Plant_Grass_Sharp"
    },
    {
      "x": -32,
      "y": 25,
      "z": -37,
      "name": "Soil_Clay_Green"
    },
    {
      "x": -32,
      "y": 26,
      "z": -37,
      "name": "Soil_Clay_Lime"
    },
    {
      "x": -32,
      "y": 27,
      "z": -37,
      "name": "Plant_Grass_Sharp"
    },
    {
      "x": -32,
      "y": 25,
      "z": -36,
      "name": "Soil_Clay_Green"
    },
    {
      "x": -32,
      "y": 26,
      "z": -36,
      "name": "Soil_Clay_Lime"
    },
    {
      "x": -32,
      "y": 27,
      "z": -36,
      "name": "Plant_Grass_Sharp"
    },
    {
      "x": -32,
      "y": 23,
      "z": -33,
      "name": "Soil_Clay_Green"
    },
    {
      "x": -32,
      "y": 23,
      "z": -32,
      "name": "Soil_Clay_Green"
    },
    {
      "x": -32,
      "y": 31,
      "z": -26,
      "name": "Soil_Clay_Green"
    },
    {
      "x": -32,
      "y": 32,
      "z": -26,
      "name": "Soil_Seaweed_Block"
    },
    {
      "x": -32,
      "y": 33,
      "z": -26,
      "name": "Soil_Seaweed_Block"
    },
    {
      "x": -32,
      "y": 19,
      "z": -25,
      "name": "Soil_Clay_Green"
    },
    {
      "x": -32,
      "y": 20,
      "z": -25,
      "name": "Soil_Clay_Green"
    },
    {
      "x": -32,
      "y": 21,
      "z": -25,
      "name": "Soil_Seaweed_Block"
    },
    {
      "x": -32,
      "y": 22,
      "z": -25,
      "name": "Soil_Seaweed_Block"
    },
    {
      "x": -32,
      "y": 29,
      "z": -25,
      "name": "Soil_Clay_Green"
    },
    {
      "x": -32,
      "y": 30,
      "z": -25,
      "name": "Soil_Clay_Green"
    },
    {
      "x": -32,
      "y": 31,
      "z": -25,
      "name": "Soil_Seaweed_Block"
    },
    {
      "x": -32,
      "y": 32,
      "z": -25,
      "name": "Soil_Seaweed_Block"
    },
    {
      "x": -32,
      "y": 33,
      "z": -25,
      "name": "Soil_Seaweed_Block"
    },
    {
      "x": -32,
      "y": 16,
      "z": -24,
      "name": "Soil_Clay_Green"
    },
    {
      "x": -32,
      "y": 17,
      "z": -24,
      "name": "Soil_Clay_Green"
    },
    {
      "x": -32,
      "y": 18,
      "z": -24,
      "name": "Soil_Clay_Green"
    },
    {
      "x": -32,
      "y": 19,
      "z": -24,
      "name": "Soil_Seaweed_Block"
    },
    {
      "x": -32,
      "y": 20,
      "z": -24,
      "name": "Soil_Seaweed_Block"
    },
    {
      "x": -32,
      "y": 21,
      "z": -24,
      "name": "Soil_Seaweed_Block"
    },
    {
      "x": -32,
      "y": 22,
      "z": -24,
      "name": "Soil_Seaweed_Block"
    },
    {
      "x": -32,
      "y": 29,
      "z": -24,
      "name": "Soil_Clay_Green"
    },
    {
      "x": -32,
      "y": 30,
      "z": -24,
      "name": "Soil_Seaweed_Block"
    },
    {
      "x": -32,
      "y": 31,
      "z": -24,
      "name": "Soil_Seaweed_Block"
    },
    {
      "x": -32,
      "y": 32,
      "z": -24,
      "name": "Soil_Seaweed_Block"
    },
    {
      "x": -32,
      "y": 15,
      "z": -23,
      "name": "Soil_Clay_Green"
    },
    {
      "x": -32,
      "y": 16,
      "z": -23,
      "name": "Soil_Clay_Green"
    },
    {
      "x": -32,
      "y": 17,
      "z": -23,
      "name": "Soil_Seaweed_Block"
    },
    {
      "x": -32,
      "y": 18,
      "z": -23,
      "name": "Soil_Seaweed_Block"
    },
    {
      "x": -32,
      "y": 19,
      "z": -23,
      "name": "Soil_Seaweed_Block"
    },
    {
      "x": -32,
      "y": 20,
      "z": -23,
      "name": "Soil_Seaweed_Block"
    },
    {
      "x": -32,
      "y": 21,
      "z": -23,
      "name": "Soil_Seaweed_Block"
    },
    {
      "x": -32,
      "y": 22,
      "z": -23,
      "name": "Soil_Seaweed_Block"
    },
    {
      "x": -32,
      "y": 23,
      "z": -23,
      "name": "Soil_Clay_Lime"
    },
    {
      "x": -32,
      "y": 24,
      "z": -23,
      "name": "Soil_Seaweed_Block"
    },
    {
      "x": -32,
      "y": 28,
      "z": -23,
      "name": "Soil_Clay_Green"
    },
    {
      "x": -32,
      "y": 29,
      "z": -23,
      "name": "Soil_Seaweed_Block"
    },
    {
      "x": -32,
      "y": 30,
      "z": -23,
      "name": "Soil_Seaweed_Block"
    },
    {
      "x": -32,
      "y": 31,
      "z": -23,
      "name": "Soil_Clay_Lime"
    },
    {
      "x": -32,
      "y": 32,
      "z": -23,
      "name": "Plant_Grass_Sharp"
    },
    {
      "x": -32,
      "y": 15,
      "z": -22,
      "name": "Soil_Clay_Green"
    },
    {
      "x": -32,
      "y": 16,
      "z": -22,
      "name": "Soil_Seaweed_Block"
    },
    {
      "x": -32,
      "y": 17,
      "z": -22,
      "name": "Soil_Seaweed_Block"
    },
    {
      "x": -32,
      "y": 18,
      "z": -22,
      "name": "Soil_Seaweed_Block"
    },
    {
      "x": -32,
      "y": 19,
      "z": -22,
      "name": "Soil_Seaweed_Block"
    },
    {
      "x": -32,
      "y": 20,
      "z": -22,
      "name": "Soil_Seaweed_Block"
    },
    {
      "x": -32,
      "y": 21,
      "z": -22,
      "name": "Soil_Seaweed_Block"
    },
    {
      "x": -32,
      "y": 22,
      "z": -22,
      "name": "Soil_Seaweed_Block"
    },
    {
      "x": -32,
      "y": 23,
      "z": -22,
      "name": "Soil_Seaweed_Block"
    },
    {
      "x": -32,
      "y": 24,
      "z": -22,
      "name": "Soil_Seaweed_Block"
    },
    {
      "x": -32,
      "y": 25,
      "z": -22,
      "name": "Soil_Seaweed_Block"
    },
    {
      "x": -32,
      "y": 26,
      "z": -22,
      "name": "Soil_Seaweed_Block"
    },
    {
      "x": -32,
      "y": 28,
      "z": -22,
      "name": "Soil_Seaweed_Block"
    },
    {
      "x": -32,
      "y": 29,
      "z": -22,
      "name": "Soil_Seaweed_Block"
    },
    {
      "x": -32,
      "y": 30,
      "z": -22,
      "name": "Soil_Seaweed_Block"
    },
    {
      "x": -32,
      "y": 14,
      "z": -21,
      "name": "Soil_Clay_Green"
    },
    {
      "x": -32,
      "y": 15,
      "z": -21,
      "name": "Soil_Seaweed_Block"
    },
    {
      "x": -32,
      "y": 16,
      "z": -21,
      "name": "Soil_Seaweed_Block"
    },
    {
      "x": -32,
      "y": 17,
      "z": -21,
      "name": "Soil_Seaweed_Block"
    },
    {
      "x": -32,
      "y": 18,
      "z": -21,
      "name": "Soil_Seaweed_Block"
    },
    {
      "x": -32,
      "y": 19,
      "z": -21,
      "name": "Soil_Seaweed_Block"
    },
    {
      "x": -32,
      "y": 20,
      "z": -21,
      "name": "Soil_Seaweed_Block"
    },
    {
      "x": -32,
      "y": 21,
      "z": -21,
      "name": "Soil_Seaweed_Block"
    },
    {
      "x": -32,
      "y": 22,
      "z": -21,
      "name": "Soil_Seaweed_Block"
    },
    {
      "x": -32,
      "y": 23,
      "z": -21,
      "name": "Soil_Seaweed_Block"
