{
  "version": 8,
  "blockIdVersion": 10,
  "anchorX": 0,
  "anchorY": 25,
  "anchorZ": 0,
  "blocks": [
    {
      "x": -43,
      "y": 11,
      "z": -30,
      "name": "Soil_Clay_Green"
    },
    {
      "x": -42,
      "y": 5,
      "z": -35,
      "name": "Soil_Clay_Green"
    },
    {
      "x": -42,
      "y": 6,
      "z": -35,
      "name": "Soil_Clay_Green"
    },
    {
      "x": -42,
      "y": 6,
      "z": -34,
      "name": "Soil_Clay_Green"
    },
    {
      "x": -42,
      "y": 11,
      "z": -30,
      "name": "Soil_Clay_Green"
    },
    {
      "x": -42,
      "y": 11,
      "z": -29,
      "name": "Soil_Clay_Green"
    },
    {
      "x": -41,
      "y": 6,
      "z": -34,
      "name": "Soil_Clay_Green"
    },
    {
      "x": -41,
      "y": 7,
      "z": -34,
      "name": "Soil_Seaweed_Block"
    },
    {
      "x": -41,
      "y": 6,
      "z": -33,
      "name": "Soil_Clay_Green"
    },
    {
      "x": -41,
      "y": 7,
      "z": -33,
      "name": "Soil_Seaweed_Block"
    },
    {
      "x": -41,
      "y": 6,
      "z": -32,
      "name": "Soil_Clay_Green"
    },
    {
      "x": -41,
      "y": 11,
      "z": -29,
      "name": "Soil_Clay_Green"
    },
    {
      "x": -41,
      "y": 11,
      "z": -28,
      "name": "Soil_Clay_Green"
    },
    {
      "x": -40,
      "y": 6,
      "z": -34,
      "name": "Soil_Clay_Green"
    },
    {
      "x": -40,
      "y": 7,
      "z": -34,
      "name": "Soil_Clay_Green"
    },
    {
      "x": -40,
      "y": 6,
      "z": -33,
      "name": "Soil_Clay_Green"
    },
    {
      "x": -40,
      "y": 7,
      "z": -33,
      "name": "Soil_Seaweed_Block"
    },
    {
      "x": -40,
      "y": 8,
      "z": -33,
      "name": "Soil_Clay_Lime"
    },
    {
      "x": -40,
      "y": 9,
      "z": -33,
      "name": "Plant_Grass_Sharp"
    },
    {
      "x": -40,
      "y": 6,
      "z": -32,
      "name": "Soil_Clay_Green"
    },
    {
      "x": -40,
      "y": 7,
      "z": -32,
      "name": "Soil_Clay_Green"
    },
    {
      "x": -40,
      "y": 8,
      "z": -32,
      "name": "Soil_Clay_Lime"
    },
    {
      "x": -40,
      "y": 9,
      "z": -32,
      "name": "Plant_Grass_Sharp"
    },
    {
      "x": -40,
      "y": 6,
      "z": -31,
      "name": "Soil_Clay_Green"
    },
    {
      "x": -40,
      "y": 7,
      "z": -31,
      "name": "Soil_Clay_Green"
    },
    {
      "x": -40,
      "y": 11,
      "z": -28,
      "name": "Soil_Clay_Green"
    },
    {
      "x": -40,
      "y": 12,
      "z": -28,
      "name": "Soil_Seaweed_Block"
    },
    {
      "x": -39,
      "y": 7,
      "z": -34,
      "name": "Soil_Clay_Green"
    },
    {
      "x": -39,
      "y": 6,
      "z": -33,
      "name": "Soil_Clay_Green"
    },
    {
      "x": -39,
      "y": 7,
      "z": -33,
      "name": "Soil_Seaweed_Block"
    },
    {
      "x": -39,
      "y": 8,
      "z": -33,
      "name": "Soil_Clay_Lime"
    },
    {
      "x": -39,
      "y": 9,
      "z": -33,
      "name": "Plant_Grass_Sharp"
    },
    {
      "x": -39,
      "y": 6,
      "z": -32,
      "name": "Soil_Clay_Green"
    },
    {
      "x": -39,
      "y": 7,
      "z": -32,
      "name": "Soil_Seaweed_Block"
    },
    {
      "x": -39,
      "y": 8,
      "z": -32,
      "name": "Soil_Seaweed_Block"
    },
    {
      "x": -39,
      "y": 9,
      "z": -32,
      "name": "Soil_Clay_Lime"
    },
    {
      "x": -39,
      "y": 10,
      "z": -32,
      "name": "Plant_Grass_Sharp"
    },
    {
      "x": -39,
      "y": 6,
      "z": -31,
      "name": "Soil_Clay_Green"
    },
    {
      "x": -39,
      "y": 7,
      "z": -31,
      "name": "Soil_Clay_Green"
    },
    {
      "x": -39,
      "y": 8,
      "z": -31,
      "name": "Soil_Seaweed_Block"
    },
    {
      "x": -39,
      "y": 12,
      "z": -28,
      "name": "Soil_Clay_Green"
    },
    {
      "x": -39,
      "y": 13,
      "z": -28,
      "name": "Soil_Clay_Lime"
    },
    {
      "x": -39,
      "y": 14,
      "z": -28,
      "name": "Plant_Grass_Sharp"
    },
    {
      "x": -39,
      "y": 6,
      "z": -25,
      "name": "Soil_Clay_Green"
    },
    {
      "x": -39,
      "y": 7,
      "z": -25,
      "name": "Soil_Seaweed_Block"
    },
    {
      "x": -38,
      "y": 7,
      "z": -33,
      "name": "Soil_Clay_Green"
    },
    {
      "x": -38,
      "y": 8,
      "z": -33,
      "name": "Soil_Seaweed_Block"
    },
    {
      "x": -38,
      "y": 9,
      "z": -33,
      "name": "Soil_Clay_Lime"
    },
    {
      "x": -38,
      "y": 10,
      "z": -33,
      "name": "Plant_Grass_Sharp"
    },
    {
      "x": -38,
      "y": 7,
      "z": -32,
      "name": "Soil_Clay_Green"
    },
    {
      "x": -38,
      "y": 8,
      "z": -32,
      "name": "Soil_Seaweed_Block"
    },
    {
      "x": -38,
      "y": 9,
      "z": -32,
      "name": "Soil_Clay_Lime"
    },
    {
      "x": -38,
      "y": 10,
      "z": -32,
      "name": "Plant_Grass_Sharp"
    },
    {
      "x": -38,
      "y": 7,
      "z": -31,
      "name": "Soil_Clay_Green"
    },
    {
      "x": -38,
      "y": 8,
      "z": -31,
      "name": "Soil_Seaweed_Block"
    },
    {
      "x": -38,
      "y": 9,
      "z": -31,
      "name": "Soil_Seaweed_Block"
    },
    {
      "x": -38,
      "y": 13,
      "z": -28,
      "name": "Soil_Clay_Lime"
    },
    {
      "x": -38,
      "y": 14,
      "z": -28,
      "name": "Plant_Grass_Sharp"
    },
    {
      "x": -38,
      "y": 7,
      "z": -25,
      "name": "Soil_Clay_Green"
    },
    {
      "x": -38,
      "y": 7,
      "z": -24,
      "name": "Soil_Clay_Green"
    },
    {
      "x": -37,
      "y": 17,
      "z": -36,
      "name": "Soil_Clay_Green"
    },
    {
      "x": -37,
      "y": 17,
      "z": -35,
      "name": "Soil_Clay_Green"
    },
    {
      "x": -37,
      "y": 7,
      "z": -33,
      "name": "Soil_Clay_Green"
    },
    {
      "x": -37,
      "y": 8,
      "z": -33,
      "name": "Soil_Clay_Green"
    },
    {
      "x": -37,
      "y": 7,
      "z": -32,
      "name": "Soil_Clay_Green"
    },
    {
      "x": -37,
      "y": 8,
      "z": -32,
      "name": "Soil_Seaweed_Block"
    },
    {
      "x": -37,
      "y": 9,
      "z": -32,
      "name": "Soil_Seaweed_Block"
    },
    {
      "x": -37,
      "y": 8,
      "z": -31,
      "name": "Soil_Clay_Green"
    },
    {
      "x": -37,
      "y": 9,
      "z": -31,
      "name": "Soil_Seaweed_Block"
    },
    {
      "x": -37,
      "y": 10,
      "z": -31,
      "name": "Soil_Seaweed_Block"
    },
    {
      "x": -37,
      "y": 9,
      "z": -30,
      "name": "Soil_Clay_Green"
    },
    {
      "x": -37,
      "y": 13,
      "z": -29,
      "name": "Soil_Seaweed_Block"
    },
    {
      "x": -37,
      "y": 13,
      "z": -28,
      "name": "Soil_Seaweed_Block"
    },
    {
      "x": -37,
      "y": 7,
      "z": -24,
      "name": "Soil_Clay_Green"
    },
    {
      "x": -36,
      "y": 17,
      "z": -35,
      "name": "Soil_Clay_Green"
    },
    {
      "x": -36,
      "y": 17,
      "z": -34,
      "name": "Soil_Clay_Green"
    },
    {
      "x": -36,
      "y": 18,
      "z": -34,
      "name": "Soil_Clay_Lime"
    },
    {
      "x": -36,
      "y": 19,
      "z": -34,
      "name": "Plant_Grass_Sharp"
    },
    {
      "x": -36,
      "y": 18,
      "z": -33,
      "name": "Soil_Seaweed_Block"
    },
    {
      "x": -36,
      "y": 8,
      "z": -32,
      "name": "Soil_Clay_Green"
    },
    {
      "x": -36,
      "y": 9,
      "z": -32,
      "name": "Soil_Clay_Green"
    },
    {
      "x": -36,
      "y": 10,
      "z": -32,
      "name": "Soil_Seaweed_Block"
    },
    {
      "x": -36,
      "y": 11,
      "z": -32,
      "name": "Soil_Seaweed_Block"
    },
    {
      "x": -36,
      "y": 8,
      "z": -31,
      "name": "Soil_Clay_Green"
    },
    {
      "x": -36,
      "y": 9,
      "z": -31,
      "name": "Soil_Seaweed_Block"
    },
    {
      "x": -36,
      "y": 10,
      "z": -31,
      "name": "Soil_Seaweed_Block"
    },
    {
      "x": -36,
      "y": 11,
      "z": -31,
      "name": "Soil_Seaweed_Block"
    },
    {
      "x": -36,
      "y": 12,
      "z": -31,
      "name": "Soil_Seaweed_Block"
    },
    {
      "x": -36,
      "y": 9,
      "z": -30,
      "name": "Soil_Clay_Green"
    },
    {
      "x": -36,
      "y": 10,
      "z": -30,
      "name": "Soil_Clay_Green"
    },
    {
      "x": -36,
      "y": 11,
      "z": -30,
      "name": "Soil_Clay_Green"
    },
    {
      "x": -36,
      "y": 12,
      "z": -30,
      "name": "Soil_Seaweed_Block"
    },
    {
      "x": -36,
      "y": 13,
      "z": -30,
      "name": "Soil_Seaweed_Block"
    },
    {
      "x": -36,
      "y": 11,
      "z": -29,
      "name": "Soil_Clay_Green"
    },
    {
      "x": -36,
      "y": 12,
      "z": -29,
      "name": "Soil_Clay_Green"
    },
    {
      "x": -36,
      "y": 13,
      "z": -29,
      "name": "Soil_Seaweed_Block"
    },
    {
      "x": -36,
      "y": 7,
      "z": -24,
      "name": "Soil_Clay_Green"
    },
    {
      "x": -36,
      "y": 8,
      "z": -24,
      "name": "Soil_Clay_Green"
    },
    {
      "x": -35,
      "y": 18,
      "z": -33,
      "name": "Soil_Seaweed_Block"
    },
    {
      "x": -35,
      "y": 9,
      "z": -32,
      "name": "Soil_Clay_Green"
    },
    {
      "x": -35,
      "y": 10,
      "z": -32,
      "name": "Soil_Clay_Green"
    },
    {
      "x": -35,
      "y": 11,
      "z": -32,
      "name": "Soil_Seaweed_Block"
    },
    {
      "x": -35,
      "y": 18,
      "z": -32,
      "name": "Soil_Seaweed_Block"
    },
    {
      "x": -35,
      "y": 9,
      "z": -31,
      "name": "Soil_Clay_Green"
    },
    {
      "x": -35,
      "y": 10,
      "z": -31,
      "name": "Soil_Seaweed_Block"
    },
    {
      "x": -35,
      "y": 11,
      "z": -31,
      "name": "Soil_Seaweed_Block"
    },
    {
      "x": -35,
      "y": 12,
      "z": -31,
      "name": "Soil_Seaweed_Block"
    },
    {
      "x": -35,
      "y": 13,
      "z": -31,
      "name": "Soil_Seaweed_Block"
    },
    {
      "x": -35,
      "y": 18,
      "z": -31,
      "name": "Soil_Seaweed_Block"
    },
    {
      "x": -35,
      "y": 10,
      "z": -30,
      "name": "Soil_Clay_Green"
    },
    {
      "x": -35,
      "y": 11,
      "z": -30,
      "name": "Soil_Seaweed_Block"
    },
    {
      "x": -35,
      "y": 12,
      "z": -30,
      "name": "Soil_Seaweed_Block"
    },
    {
      "x": -35,
      "y": 13,
      "z": -30,
      "name": "Soil_Seaweed_Block"
    },
    {
      "x": -35,
      "y": 14,
      "z": -30,
      "name": "Soil_Clay_Lime"
    },
    {
      "x": -35,
      "y": 15,
      "z": -30,
      "name": "Plant_Grass_Sharp"
    },
    {
      "x": -35,
      "y": 11,
      "z": -29,
      "name": "Soil_Clay_Green"
    },
    {
      "x": -35,
      "y": 12,
      "z": -29,
      "name": "Soil_Clay_Green"
    },
    {
      "x": -35,
      "y": 13,
      "z": -29,
      "name": "Soil_Seaweed_Block"
    },
    {
      "x": -35,
      "y": 14,
      "z": -29,
      "name": "Soil_Clay_Lime"
    },
    {
      "x": -35,
      "y": 15,
      "z": -29,
      "name": "Plant_Grass_Sharp"
    },
    {
      "x": -35,
      "y": 13,
      "z": -28,
      "name": "Soil_Seaweed_Block"
    },
    {
      "x": -35,
      "y": 8,
      "z": -24,
      "name": "Soil_Clay_Green"
    },
    {
      "x": -35,
      "y": 9,
      "z": -24,
      "name": "Soil_Clay_Lime"
    },
    {
      "x": -35,
      "y": 10,
      "z": -24,
      "name": "Plant_Grass_Sharp"
    },
    {
      "x": -35,
      "y": 8,
      "z": -23,
      "name": "Soil_Clay_Green"
    },
    {
      "x": -34,
      "y": 9,
      "z": -38,
      "name": "Soil_Clay_Green"
    },
    {
      "x": -34,
      "y": 9,
      "z": -37,
      "name": "Soil_Clay_Green"
    },
    {
      "x": -34,
      "y": 9,
      "z": -36,
      "name": "Soil_Clay_Green"
    },
    {
      "x": -34,
      "y": 10,
      "z": -36,
      "name": "Soil_Clay_Green"
    },
    {
      "x": -34,
      "y": 10,
      "z": -31,
      "name": "Soil_Clay_Green"
    },
    {
      "x": -34,
      "y": 11,
      "z": -31,
      "name": "Soil_Clay_Green"
    },
    {
      "x": -34,
      "y": 12,
      "z": -31,
      "name": "Soil_Clay_Green"
    },
    {
      "x": -34,
      "y": 13,
      "z": -31,
      "name": "Soil_Seaweed_Block"
    },
    {
      "x": -34,
      "y": 18,
      "z": -31,
      "name": "Soil_Clay_Lime"
    },
    {
      "x": -34,
      "y": 19,
      "z": -31,
      "name": "Plant_Grass_Sharp"
    },
    {
      "x": -34,
      "y": 10,
      "z": -30,
      "name": "Soil_Clay_Green"
    },
    {
      "x": -34,
      "y": 11,
      "z": -30,
      "name": "Soil_Clay_Green"
    },
    {
      "x": -34,
      "y": 12,
      "z": -30,
      "name": "Soil_Seaweed_Block"
    },
    {
      "x": -34,
      "y": 13,
      "z": -30,
      "name": "Soil_Seaweed_Block"
    },
    {
      "x": -34,
      "y": 14,
      "z": -30,
      "name": "Soil_Clay_Lime"
    },
    {
      "x": -34,
      "y": 15,
      "z": -30,
      "name": "Plant_Grass_Sharp"
    },
    {
      "x": -34,
      "y": 17,
      "z": -30,
      "name": "Soil_Seaweed_Block"
    },
    {
      "x": -34,
      "y": 18,
      "z": -30,
      "name": "Soil_Seaweed_Block"
    },
    {
      "x": -34,
      "y": 11,
      "z": -29,
      "name": "Soil_Clay_Green"
    },
    {
      "x": -34,
      "y": 12,
      "z": -29,
      "name": "Soil_Seaweed_Block"
    },
    {
      "x": -34,
      "y": 13,
      "z": -29,
      "name": "Soil_Seaweed_Block"
    },
    {
      "x": -34,
      "y": 14,
      "z": -29,
      "name": "Soil_Clay_Lime"
    },
    {
      "x": -34,
      "y": 15,
      "z": -29,
      "name": "Plant_Grass_Sharp"
    },
    {
      "x": -34,
      "y": 12,
      "z": -28,
      "name": "Soil_Clay_Green"
    },
    {
      "x": -34,
      "y": 13,
      "z": -28,
      "name": "Soil_Seaweed_Block"
    },
    {
      "x": -34,
      "y": 14,
      "z": -28,
      "name": "Soil_Clay_Lime"
    },
    {
      "x": -34,
      "y": 15,
      "z": -28,
      "name": "Plant_Grass_Sharp"
    },
    {
      "x": -34,
      "y": 13,
      "z": -27,
      "name": "Soil_Clay_Green"
    },
    {
      "x": -34,
      "y": 10,
      "z": -25,
      "name": "Soil_Clay_Green"
    },
    {
      "x": -34,
      "y": 8,
      "z": -24,
      "name": "Soil_Clay_Green"
    },
    {
      "x": -34,
      "y": 9,
      "z": -24,
      "name": "Soil_Clay_Green"
    },
    {
      "x": -34,
      "y": 10,
      "z": -24,
      "name": "Soil_Seaweed_Block"
    },
    {
      "x": -33,
      "y": 9,
      "z": -38,
      "name": "Soil_Clay_Green"
    },
    {
      "x": -33,
      "y": 10,
      "z": -36,
      "name": "Soil_Clay_Green"
    },
    {
      "x": -33,
      "y": 10,
      "z": -35,
      "name": "Soil_Clay_Green"
    },
    {
      "x": -33,
      "y": 13,
      "z": -31,
      "name": "Soil_Seaweed_Block"
    },
    {
      "x": -33,
      "y": 12,
      "z": -30,
      "name": "Soil_Clay_Green"
    },
    {
      "x": -33,
      "y": 13,
      "z": -30,
      "name": "Soil_Seaweed_Block"
    },
    {
      "x": -33,
      "y": 14,
      "z": -30,
      "name": "Soil_Clay_Lime"
    },
    {
      "x": -33,
      "y": 15,
      "z": -30,
      "name": "Plant_Grass_Sharp"
    },
    {
      "x": -33,
      "y": 17,
      "z": -30,
      "name": "Soil_Clay_Green"
    },
    {
      "x": -33,
      "y": 18,
      "z": -30,
      "name": "Soil_Clay_Green"
    },
    {
      "x": -33,
      "y": 12,
      "z": -29,
      "name": "Soil_Clay_Green"
    },
    {
      "x": -33,
      "y": 13,
      "z": -29,
      "name": "Soil_Seaweed_Block"
    },
    {
      "x": -33,
      "y": 14,
      "z": -29,
      "name": "Soil_Seaweed_Block"
    },
    {
      "x": -33,
      "y": 15,
      "z": -29,
      "name": "Soil_Clay_Lime"
    },
    {
      "x": -33,
      "y": 16,
      "z": -29,
      "name": "Plant_Grass_Sharp"
    },
    {
      "x": -33,
      "y": 12,
      "z": -28,
      "name": "Soil_Clay_Green"
    },
    {
      "x": -33,
      "y": 13,
      "z": -28,
      "name": "Soil_Seaweed_Block"
    },
    {
      "x": -33,
      "y": 14,
      "z": -28,
      "name": "Soil_Seaweed_Block"
    },
    {
      "x": -33,
      "y": 15,
      "z": -28,
      "name": "Soil_Clay_Lime"
    },
    {
      "x": -33,
      "y": 16,
      "z": -28,
      "name": "Plant_Grass_Sharp"
    },
    {
      "x": -33,
      "y": 12,
      "z": -27,
      "name": "Soil_Clay_Green"
    },
    {
      "x": -33,
      "y": 13,
      "z": -27,
      "name": "Soil_Seaweed_Block"
    },
    {
      "x": -33,
      "y": 14,
      "z": -27,
      "name": "Soil_Clay_Lime"
    },
    {
      "x": -33,
      "y": 15,
      "z": -27,
      "name": "Plant_Grass_Sharp"
    },
    {
      "x": -33,
      "y": 13,
      "z": -26,
      "name": "Soil_Clay_Green"
    },
    {
      "x": -33,
      "y": 14,
      "z": -26,
      "name": "Soil_Seaweed_Block"
    },
    {
      "x": -33,
      "y": 10,
      "z": -25,
      "name": "Soil_Clay_Green"
    },
    {
      "x": -32,
      "y": 20,
      "z": -38,
      "name": "Soil_Clay_Green"
    },
    {
      "x": -32,
      "y": 21,
      "z": -38,
      "name": "Soil_Seaweed_Block"
    },
    {
      "x": -32,
      "y": 20,
      "z": -37,
      "name": "Soil_Clay_Green"
    },
    {
      "x": -32,
      "y": 21,
      "z": -37,
      "name": "Soil_Clay_Green"
    },
    {
      "x": -32,
      "y": 1,
      "z": -36,
      "name": "Soil_Clay_Green"
    },
    {
      "x": -32,
      "y": 1,
      "z": -35,
      "name": "Soil_Clay_Green"
    },
    {
      "x": -32,
      "y": 10,
      "z": -35,
      "name": "Soil_Clay_Green"
    },
    {
      "x": -32,
      "y": 11,
      "z": -35,
      "name": "Soil_Seaweed_Block"
    },
    {
      "x": -32,
      "y": 11,
      "z": -34,
      "name": "Soil_Clay_Green"
    },
    {
      "x": -32,
      "y": 12,
      "z": -34,
      "name": "Soil_Clay_Lime"
    },
    {
      "x": -32,
      "y": 13,
      "z": -34,
      "name": "Plant_Grass_Sharp"
    },
    {
      "x": -32,
      "y": 12,
      "z": -33,
      "name": "Soil_Seaweed_Block"
    },
    {
      "x": -32,
      "y": 13,
      "z": -31,
      "name": "Soil_Seaweed_Block"
    },
    {
      "x": -32,
      "y": 12,
      "z": -30,
      "name": "Soil_Clay_Green"
    },
    {
      "x": -32,
      "y": 13,
      "z": -30,
      "name": "Soil_Seaweed_Block"
    },
    {
      "x": -32,
      "y": 14,
      "z": -30,
      "name": "Soil_Clay_Lime"
    },
    {
      "x": -32,
      "y": 15,
      "z": -30,
      "name": "Plant_Grass_Sharp"
    },
    {
      "x": -32,
      "y": 18,
      "z": -30,
      "name": "Soil_Clay_Green"
    },
    {
      "x": -32,
      "y": 13,
      "z": -29,
      "name": "Soil_Clay_Green"
    },
    {
      "x": -32,
      "y": 14,
      "z": -29,
      "name": "Soil_Seaweed_Block"
    },
    {
      "x": -32,
      "y": 15,
      "z": -29,
      "name": "Soil_Clay_Lime"
    },
    {
      "x": -32,
      "y": 16,
      "z": -29,
      "name": "Plant_Grass_Sharp"
    },
    {
      "x": -32,
      "y": 12,
      "z": -28,
      "name": "Soil_Clay_Green"
    },
    {
      "x": -32,
      "y": 13,
      "z": -28,
      "name": "Soil_Seaweed_Block"
    },
    {
      "x": -32,
      "y": 14,
      "z": -28,
      "name": "Soil_Seaweed_Block"
    },
    {
      "x": -32,
      "y": 15,
      "z": -28,
      "name": "Soil_Clay_Lime"
    },
    {
      "x": -32,
      "y": 16,
      "z": -28,
      "name": "Plant_Grass_Sharp"
    },
    {
      "x": -32,
      "y": 12,
      "z": -27,
      "name": "Soil_Clay_Green"
    },
    {
      "x": -32,
      "y": 13,
      "z": -27,
      "name": "Soil_Seaweed_Block"
    },
    {
      "x": -32,
      "y": 14,
      "z": -27,
      "name": "Soil_Seaweed_Block"
    },
    {
      "x": -32,
      "y": 15,
      "z": -27,
      "name": "Soil_Clay_Lime"
    },
    {
      "x": -32,
      "y": 16,
      "z": -27,
      "name": "Plant_Grass_Sharp"
    },
    {
      "x": -32,
      "y": 11,
      "z": -26,
      "name": "Soil_Clay_Green"
    },
    {
      "x": -32,
      "y": 12,
      "z": -26,
      "name": "Soil_Clay_Green"
    },
    {
      "x": -32,
      "y": 13,
      "z": -26,
      "name": "Soil_Seaweed_Block"
    },
    {
      "x": -32,
      "y": 14,
      "z": -26,
      "name": "Soil_Clay_Lime"
    },
    {
      "x": -32,
      "y": 15,
      "z": -26,
      "name": "Plant_Grass_Sharp"
    },
    {
      "x": -32,
      "y": 10,
      "z": -25,
      "name": "Soil_Clay_Green"
    },
    {
      "x": -32,
      "y": 11,
      "z": -25,
      "name": "Soil_Clay_Green"
    },
    {
      "x": -32,
      "y": 12,
      "z": -25,
      "name": "Soil_Clay_Green"
    },
    {
      "x": -31,
      "y": 20,
      "z": -38,
      "name": "Soil_Clay_Green"
    },
    {
      "x": -31,
      "y": 21,
      "z": -38,
      "name": "Soil_Seaweed_Block"
    },
    {
      "x": -31,
      "y": 19,
      "z": -37,
      "name": "Soil_Clay_Green"
    },
    {
      "x": -31,
      "y": 20,
      "z": -37,
      "name": "Soil_Clay_Green"
    },
    {
      "x": -31,
      "y": 21,
      "z": -37,
      "name": "Soil_Clay_Green"
    },
    {
      "x": -31,
      "y": 22,
      "z": -37,
      "name": "Soil_Seaweed_Block"
    },
    {
      "x": -31,
      "y": 21,
      "z": -36,
      "name": "Soil_Clay_Green"
    },
    {
      "x": -31,
      "y": 22,
      "z": -36,
      "name": "Soil_Clay_Green"
    },
    {
      "x": -31,
      "y": 1,
      "z": -35,
      "name": "Soil_Clay_Green"
    },
    {
      "x": -31,
      "y": 1,
      "z": -34,
      "name": "Soil_Clay_Green"
    },
    {
      "x": -31,
      "y": 12,
      "z": -33,
      "name": "Soil_Seaweed_Block"
    },
    {
      "x": -31,
      "y": 12,
      "z": -32,
      "name": "Soil_Clay_Green"
    },
    {
      "x": -31,
      "y": 13,
      "z": -32,
      "name": "Soil_Seaweed_Block"
    },
    {
      "x": -31,
      "y": 13,
      "z": -31,
      "name": "Soil_Clay_Green"
    },
    {
      "x": -31,
      "y": 18,
      "z": -31,
      "name": "Soil_Clay_Green"
    },
    {
      "x": -31,
      "y": 19,
      "z": -31,
      "name": "Soil_Seaweed_Block"
    },
    {
      "x": -31,
      "y": 13,
      "z": -30,
      "name": "Soil_Clay_Green"
    },
    {
      "x": -31,
      "y": 18,
      "z": -30,
      "name": "Soil_Clay_Green"
    },
    {
      "x": -31,
      "y": 19,
      "z": -30,
      "name": "Soil_Seaweed_Block"
    },
    {
      "x": -31,
      "y": 13,
      "z": -29,
      "name": "Soil_Clay_Green"
    },
    {
      "x": -31,
      "y": 14,
      "z": -29,
      "name": "Soil_Seaweed_Block"
    },
    {
      "x": -31,
      "y": 15,
      "z": -29,
      "name": "Soil_Clay_Lime"
    },
    {
      "x": -31,
      "y": 16,
      "z": -29,
      "name": "Plant_Grass_Sharp"
    },
    {
      "x": -31,
      "y": 12,
      "z": -28,
      "name": "Soil_Clay_Green"
    },
    {
      "x": -31,
      "y": 13,
      "z": -28,
      "name": "Soil_Seaweed_Block"
    },
    {
      "x": -31,
      "y": 14,
      "z": -28,
      "name": "Soil_Seaweed_Block"
    },
    {
      "x": -31,
      "y": 15,
      "z": -28,
      "name": "Soil_Clay_Lime"
    },
    {
      "x": -31,
      "y": 16,
      "z": -28,
      "name": "Plant_Grass_Sharp"
    },
    {
      "x": -31,
      "y": 12,
      "z": -27,
      "name": "Soil_Clay_Green"
    },
    {
      "x": -31,
      "y": 13,
      "z": -27,
      "name": "Soil_Seaweed_Block"
    },
    {
      "x": -31,
      "y": 14,
      "z": -27,
      "name": "Soil_Seaweed_Block"
    },
    {
      "x": -31,
      "y": 15,
      "z": -27,
      "name": "Soil_Clay_Lime"
    },
    {
      "x": -31,
      "y": 16,
      "z": -27,
      "name": "Plant_Grass_Sharp"
    },
    {
      "x": -31,
      "y": 10,
      "z": -26,
      "name": "Soil_Clay_Green"
    },
    {
      "x": -31,
      "y": 11,
      "z": -26,
      "name": "Soil_Clay_Green"
    },
    {
      "x": -31,
      "y": 12,
      "z": -26,
      "name": "Soil_Seaweed_Block"
    },
    {
      "x": -31,
      "y": 13,
      "z": -26,
      "name": "Soil_Seaweed_Block"
    },
    {
      "x": -31,
      "y": 14,
      "z": -26,
      "name": "Soil_Clay_Lime"
    },
    {
      "x": -31,
      "y": 15,
      "z": -26,
      "name": "Plant_Grass_Sharp"
    },
    {
      "x": -31,
      "y": 10,
      "z": -25,
      "name": "Soil_Clay_Green"
    },
    {
      "x": -31,
      "y": 11,
      "z": -25,
      "name": "Soil_Clay_Green"
    },
    {
      "x": -31,
      "y": 12,
      "z": -25,
      "name": "Soil_Clay_Green"
    },
    {
      "x": -31,
      "y": 13,
      "z": -25,
      "name": "Soil_Seaweed_Block"
    },
    {
      "x": -30,
      "y": 22,
      "z": -36,
      "name": "Soil_Clay_Green"
    },
    {
      "x": -30,
      "y": 23,
      "z": -36,
      "name": "Soil_Clay_Lime"
    },
    {
      "x": -30,
      "y": 24,
      "z": -36,
      "name": "Plant_Grass_Sharp"
    },
    {
      "x": -30,
      "y": 22,
      "z": -35,
      "name": "Soil_Clay_Green"
    },
    {
      "x": -30,
      "y": 23,
      "z": -35,
      "name": "Soil_Seaweed_Block"
    },
    {
      "x": -30,
      "y": 24,
      "z": -35,
      "name": "Soil_Clay_Lime"
    },
    {
      "x": -30,
      "y": 25,
      "z": -35,
      "name": "Plant_Grass_Sharp"
    },
    {
      "x": -30,
      "y": 1,
      "z": -34,
      "name": "Soil_Clay_Green"
    },
    {
      "x": -30,
      "y": 2,
      "z": -34,
      "name": "Soil_Clay_Green"
    },
    {
      "x": -30,
      "y": 23,
      "z": -34,
      "name": "Soil_Seaweed_Block"
    },
    {
      "x": -30,
      "y": 24,
      "z": -34,
      "name": "Soil_Clay_Lime"
    },
    {
      "x": -30,
      "y": 25,
      "z": -34,
      "name": "Plant_Grass_Sharp"
    },
    {
      "x": -30,
      "y": 1,
      "z": -33,
      "name": "Soil_Clay_Green"
    },
    {
      "x": -30,
      "y": 2,
      "z": -33,
      "name": "Soil_Clay_Green"
    },
    {
      "x": -30,
      "y": 18,
      "z": -31,
      "name": "Soil_Clay_Green"
    },
    {
      "x": -30,
      "y": 19,
      "z": -31,
      "name": "Soil_Clay_Green"
    },
    {
      "x": -30,
      "y": 18,
      "z": -30,
      "name": "Soil_Clay_Green"
    },
    {
      "x": -30,
      "y": 19,
      "z": -30,
      "name": "Soil_Clay_Green"
    },
    {
      "x": -30,
      "y": 12,
      "z": -28,
      "name": "Soil_Clay_Green"
    },
    {
      "x": -30,
      "y": 13,
      "z": -28,
      "name": "Soil_Seaweed_Block"
    },
    {
      "x": -30,
      "y": 14,
      "z": -28,
      "name": "Soil_Clay_Lime"
    },
    {
      "x": -30,
      "y": 15,
      "z": -28,
      "name": "Plant_Grass_Sharp"
    },
    {
      "x": -30,
      "y": 11,
      "z": -27,
      "name": "Soil_Clay_Green"
    },
    {
      "x": -30,
      "y": 12,
      "z": -27,
      "name": "Soil_Seaweed_Block"
    },
    {
      "x": -30,
      "y": 13,
      "z": -27,
      "name": "Soil_Seaweed_Block"
    },
    {
      "x": -30,
      "y": 14,
      "z": -27,
      "name": "Soil_Clay_Lime"
    },
    {
      "x": -30,
      "y": 15,
      "z": -27,
      "name": "Plant_Grass_Sharp"
    },
    {
      "x": -30,
      "y": 10,
      "z": -26,
      "name": "Soil_Clay_Green"
    },
    {
      "x": -30,
      "y": 11,
      "z": -26,
      "name": "Soil_Seaweed_Block"
    },
    {
      "x": -30,
      "y": 12,
      "z": -26,
      "name": "Soil_Seaweed_Block"
    },
    {
      "x": -30,
      "y": 13,
      "z": -26,
      "name": "Soil_Seaweed_Block"
    },
    {
      "x": -30,
      "y": 14,
      "z": -26,
      "name": "Soil_Clay_Lime"
    },
    {
      "x": -30,
      "y": 15,
      "z": -26,
      "name": "Plant_Grass_Sharp"
    },
    {
      "x": -30,
      "y": 10,
      "z": -25,
      "name": "Soil_Clay_Green"
    },
    {
      "x": -30,
      "y": 11,
      "z": -25,
      "name": "Soil_Clay_Green"
    },
    {
      "x": -30,
      "y": 12,
      "z": -25,
      "name": "Soil_Seaweed_Block"
    },
    {
      "x": -30,
      "y": 13,
      "z": -25,
      "name": "Soil_Clay_Lime"
    },
    {
      "x": -30,
      "y": 14,
      "z": -25,
      "name": "Plant_Grass_Sharp"
    },
    {
      "x": -29,
      "y": 8,
      "z": -38,
      "name": "Soil_Seaweed_Block"
    },
    {
      "x": -29,
      "y": 7,
      "z": -37,
      "name": "Soil_Seaweed_Block"
    },
    {
      "x": -29,
      "y": 8,
      "z": -37,
      "name": "Soil_Clay_Lime"
    },
    {
      "x": -29,
      "y": 9,
      "z": -37,
      "name": "Plant_Grass_Sharp"
    },
    {
      "x": -29,
      "y": 7,
      "z": -36,
      "name": "Soil_Seaweed_Block"
    },
    {
      "x": -29,
      "y": 23,
      "z": -35,
      "name": "Soil_Seaweed_Block"
    },
    {
      "x": -29,
      "y": 24,
      "z": -35,
      "name": "Soil_Clay_Lime"
    },
    {
      "x": -29,
      "y": 25,
      "z": -35,
      "name": "Plant_Grass_Sharp"
    },
    {
      "x": -29,
      "y": 23,
      "z": -34,
      "name": "Soil_Clay_Lime"
    },
    {
      "x": -29,
      "y": 24,
      "z": -34,
      "name": "Soil_Clay_Lime"
    },
    {
      "x": -29,
      "y": 25,
      "z": -34,
      "name": "Plant_Grass_Sharp"
    },
    {
      "x": -29,
      "y": 2,
      "z": -33,
      "name": "Soil_Clay_Green"
    },
    {
      "x": -29,
      "y": 3,
      "z": -33,
      "name": "Soil_Clay_Green"
    },
    {
      "x": -29,
      "y": 4,
      "z": -33,
      "name": "Soil_Seaweed_Block"
    },
    {
      "x": -29,
      "y": 22,
      "z": -33,
      "name": "Soil_Seaweed_Block"
    },
    {
      "x": -29,
      "y": 23,
      "z": -33,
      "name": "Soil_Seaweed_Block"
    },
    {
      "x": -29,
      "y": 24,
      "z": -33,
      "name": "Soil_Clay_Lime"
    },
    {
      "x": -29,
      "y": 25,
      "z": -33,
      "name": "Plant_Grass_Sharp"
    },
    {
      "x": -29,
      "y": 2,
      "z": -32,
      "name": "Soil_Clay_Green"
    },
    {
      "x": -29,
      "y": 3,
      "z": -32,
      "name": "Soil_Clay_Green"
    },
    {
      "x": -29,
      "y": 4,
      "z": -32,
      "name": "Soil_Seaweed_Block"
    },
    {
      "x": -29,
      "y": 20,
      "z": -32,
      "name": "Soil_Seaweed_Block"
    },
    {
      "x": -29,
      "y": 21,
      "z": -32,
      "name": "Soil_Seaweed_Block"
    },
    {
      "x": -29,
      "y": 3,
      "z": -31,
      "name": "Soil_Clay_Green"
    },
    {
      "x": -29,
      "y": 4,
      "z": -31,
      "name": "Soil_Seaweed_Block"
    },
    {
      "x": -29,
      "y": 19,
      "z": -31,
      "name": "Soil_Clay_Green"
    },
    {
      "x": -29,
      "y": 20,
      "z": -31,
      "name": "Soil_Seaweed_Block"
    },
    {
      "x": -29,
      "y": 13,
      "z": -28,
      "name": "Soil_Seaweed_Block"
    },
    {
      "x": -29,
      "y": 14,
      "z": -28,
      "name": "Soil_Seaweed_Block"
    },
    {
      "x": -29,
      "y": 10,
      "z": -27,
      "name": "Soil_Clay_Green"
    },
    {
      "x": -29,
      "y": 11,
      "z": -27,
      "name": "Soil_Clay_Green"
    },
    {
      "x": -29,
      "y": 12,
      "z": -27,
      "name": "Soil_Seaweed_Block"
    },
    {
      "x": -29,
      "y": 13,
      "z": -27,
      "name": "Soil_Seaweed_Block"
    },
    {
      "x": -29,
      "y": 14,
      "z": -27,
      "name": "Soil_Clay_Lime"
    },
    {
      "x": -29,
      "y": 15,
      "z": -27,
      "name": "Plant_Grass_Sharp"
    },
    {
      "x": -29,
      "y": 9,
      "z": -26,
      "name": "Soil_Clay_Green"
    },
    {
      "x": -29,
      "y": 10,
      "z": -26,
      "name": "Soil_Seaweed_Block"
    },
    {
      "x": -29,
      "y": 11,
      "z": -26,
      "name": "Soil_Seaweed_Block"
    },
    {
      "x": -29,
      "y": 12,
      "z": -26,
      "name": "Soil_Seaweed_Block"
    },
    {
      "x": -29,
      "y": 13,
      "z": -26,
      "name": "Soil_Seaweed_Block"
    },
    {
      "x": -29,
      "y": 14,
      "z": -26,
      "name": "Soil_Clay_Lime"
    },
    {
      "x": -29,
      "y": 15,
      "z": -26,
      "name": "Plant_Grass_Sharp"
    },
    {
      "x": -29,
      "y": 7,
      "z": -25,
      "name": "Soil_Clay_Green"
    },
    {
      "x": -29,
      "y": 8,
      "z": -25,
      "name": "Soil_Clay_Green"
    },
    {
      "x": -29,
      "y": 9,
      "z": -25,
      "name": "Soil_Clay_Green"
    },
    {
      "x": -29,
      "y": 10,
      "z": -25,
      "name": "Soil_Seaweed_Block"
    },
    {
      "x": -29,
      "y": 11,
      "z": -25,
      "name": "Soil_Seaweed_Block"
    },
    {
      "x": -29,
      "y": 12,
      "z": -25,
      "name": "Soil_Seaweed_Block"
    },
    {
      "x": -29,
      "y": 13,
      "z": -25,
      "name": "Soil_Clay_Lime"
    },
    {
      "x": -29,
      "y": 14,
      "z": -25,
      "name": "Plant_Grass_Sharp"
    },
    {
      "x": -29,
      "y": 7,
      "z": -24,
      "name": "Soil_Clay_Green"
    },
    {
      "x": -29,
      "y": 8,
      "z": -24,
      "name": "Soil_Clay_Green"
    },
    {
      "x": -29,
      "y": 9,
      "z": -24,
      "name": "Soil_Clay_Green"
    },
    {
      "x": -29,
      "y": 10,
      "z": -24,
      "name": "Soil_Clay_Green"
    },
    {
      "x": -29,
      "y": 11,
      "z": -24,
      "name": "Soil_Clay_Green"
    },
    {
      "x": -29,
      "y": 12,
      "z": -24,
      "name": "Soil_Seaweed_Block"
    },
    {
      "x": -29,
      "y": 13,
      "z": -24,
      "name": "Soil_Clay_Lime"
    },
    {
      "x": -29,
      "y": 14,
      "z": -24,
      "name": "Plant_Grass_Sharp"
    },
    {
      "x": -29,
      "y": 12,
      "z": -23,
      "name": "Soil_Seaweed_Block"
    },
    {
      "x": -28,
      "y": 14,
      "z": -43,
      "name": "Soil_Clay_Green"
    },
    {
      "x": -28,
      "y": 15,
      "z": -43,
      "name": "Soil_Clay_Green"
    },
    {
      "x": -28,
      "y": 15,
      "z": -42,
      "name": "Soil_Clay_Green"
    },
    {
      "x": -28,
      "y": 7,
      "z": -36,
      "name": "Soil_Seaweed_Block"
    },
    {
      "x": -28,
      "y": 5,
      "z": -35,
      "name": "Soil_Seaweed_Block"
    },
    {
      "x": -28,
      "y": 6,
      "z": -35,
      "name": "Soil_Clay_Lime"
    },
    {
      "x": -28,
      "y": 7,
      "z": -35,
      "name": "Soil_Clay_Lime"
    },
    {
      "x": -28,
      "y": 8,
      "z": -35,
      "name": "Plant_Grass_Sharp"
    },
    {
      "x": -28,
      "y": 4,
      "z": -34,
      "name": "Soil_Seaweed_Block"
    },
    {
      "x": -28,
      "y": 5,
      "z": -34,
      "name": "Soil_Seaweed_Block"
    },
    {
      "x": -28,
      "y": 24,
      "z": -34,
      "name": "Soil_Clay_Lime"
    },
    {
      "x": -28,
      "y": 25,
      "z": -34,
      "name": "Plant_Grass_Sharp"
    },
    {
      "x": -28,
      "y": 3,
      "z": -33,
      "name": "Soil_Clay_Green"
    },
    {
      "x": -28,
      "y": 4,
      "z": -33,
      "name": "Soil_Seaweed_Block"
    },
    {
      "x": -28,
      "y": 5,
      "z": -33,
      "name": "Soil_Clay_Lime"
    },
    {
      "x": -28,
      "y": 6,
      "z": -33,
      "name": "Plant_Grass_Sharp"
    },
    {
      "x": -28,
      "y": 20,
      "z": -33,
      "name": "Soil_Clay_Green"
    },
    {
      "x": -28,
      "y": 21,
      "z": -33,
      "name": "Soil_Seaweed_Block"
    },
    {
      "x": -28,
      "y": 22,
      "z": -33,
      "name": "Soil_Clay_Lime"
    },
    {
      "x": -28,
      "y": 23,
      "z": -33,
      "name": "Soil_Clay_Lime"
    },
    {
      "x": -28,
      "y": 24,
      "z": -33,
      "name": "Soil_Clay_Lime"
    },
    {
      "x": -28,
      "y": 25,
      "z": -33,
      "name": "Plant_Grass_Sharp"
    },
    {
      "x": -28,
      "y": 3,
      "z": -32,
      "name": "Soil_Clay_Green"
    },
    {
      "x": -28,
      "y": 4,
      "z": -32,
      "name": "Soil_Seaweed_Block"
    },
    {
      "x": -28,
      "y": 5,
      "z": -32,
      "name": "Soil_Clay_Lime"
    },
    {
      "x": -28,
      "y": 6,
      "z": -32,
      "name": "Plant_Grass_Sharp"
    },
    {
      "x": -28,
      "y": 19,
      "z": -32,
      "name": "Soil_Clay_Green"
    },
    {
      "x": -28,
      "y": 20,
      "z": -32,
      "name": "Soil_Seaweed_Block"
    },
    {
      "x": -28,
      "y": 21,
      "z": -32,
      "name": "Soil_Seaweed_Block"
    },
    {
      "x": -28,
      "y": 22,
      "z": -32,
      "name": "Soil_Seaweed_Block"
    },
    {
      "x": -28,
      "y": 23,
      "z": -32,
      "name": "Soil_Clay_Lime"
    },
    {
      "x": -28,
      "y": 24,
      "z": -32,
      "name": "Plant_Grass_Sharp"
    },
    {
      "x": -28,
      "y": 3,
      "z": -31,
      "name": "Soil_Clay_Green"
    },
    {
      "x": -28,
      "y": 4,
      "z": -31,
      "name": "Soil_Seaweed_Block"
    },
    {
      "x": -28,
      "y": 5,
      "z": -31,
      "name": "Soil_Clay_Lime"
    },
    {
      "x": -28,
      "y": 6,
      "z": -31,
      "name": "Plant_Grass_Sharp"
    },
    {
      "x": -28,
      "y": 18,
      "z": -31,
      "name": "Soil_Clay_Green"
    },
    {
      "x": -28,
      "y": 19,
      "z": -31,
      "name": "Soil_Clay_Green"
    },
    {
      "x": -28,
      "y": 20,
      "z": -31,
      "name": "Soil_Seaweed_Block"
    },
    {
      "x": -28,
      "y": 21,
      "z": -31,
      "name": "Soil_Seaweed_Block"
    },
    {
      "x": -28,
      "y": 3,
      "z": -30,
      "name": "Soil_Clay_Green"
    },
    {
      "x": -28,
      "y": 4,
      "z": -30,
      "name": "Soil_Clay_Green"
    },
    {
      "x": -28,
      "y": 5,
      "z": -30,
      "name": "Soil_Seaweed_Block"
    },
    {
      "x": -28,
      "y": 3,
      "z": -29,
      "name": "Soil_Clay_Green"
    },
    {
      "x": -28,
      "y": 4,
      "z": -29,
      "name": "Soil_Clay_Green"
    },
    {
      "x": -28,
      "y": 5,
      "z": -29,
      "name": "Soil_Seaweed_Block"
    },
    {
      "x": -28,
      "y": 8,
      "z": -27,
      "name": "Soil_Clay_Green"
    },
    {
      "x": -28,
      "y": 9,
      "z": -27,
      "name": "Soil_Clay_Green"
    },
    {
      "x": -28,
      "y": 10,
      "z": -27,
      "name": "Soil_Seaweed_Block"
    },
    {
      "x": -28,
      "y": 11,
      "z": -27,
      "name": "Soil_Seaweed_Block"
    },
    {
      "x": -28,
      "y": 12,
      "z": -27,
      "name": "Soil_Seaweed_Block"
    },
    {
      "x": -28,
      "y": 13,
      "z": -27,
      "name": "Soil_Seaweed_Block"
    },
    {
      "x": -28,
      "y": 14,
      "z": -27,
      "name": "Soil_Clay_Lime"
    },
    {
      "x": -28,
      "y": 15,
      "z": -27,
      "name": "Plant_Grass_Sharp"
    },
    {
      "x": -28,
      "y": 6,
      "z": -26,
      "name": "Soil_Clay_Green"
    },
    {
      "x": -28,
      "y": 7,
      "z": -26,
      "name": "Soil_Clay_Green"
    },
    {
      "x": -28,
      "y": 8,
      "z": -26,
      "name": "Soil_Clay_Green"
    },
    {
      "x": -28,
      "y": 9,
      "z": -26,
      "name": "Soil_Seaweed_Block"
    },
    {
      "x": -28,
      "y": 10,
      "z": -26,
      "name": "Soil_Seaweed_Block"
    },
    {
      "x": -28,
      "y": 11,
      "z": -26,
      "name": "Soil_Seaweed_Block"
    },
    {
      "x": -28,
      "y": 12,
      "z": -26,
      "name": "Soil_Seaweed_Block"
    },
    {
      "x": -28,
      "y": 13,
      "z": -26,
      "name": "Soil_Clay_Lime"
    },
    {
      "x": -28,
      "y": 14,
      "z": -26,
      "name": "Plant_Grass_Sharp"
    },
    {
      "x": -28,
      "y": 6,
      "z": -25,
      "name": "Soil_Clay_Green"
    },
    {
      "x": -28,
      "y": 7,
      "z": -25,
      "name": "Soil_Seaweed_Block"
    },
    {
      "x": -28,
      "y": 8,
      "z": -25,
      "name": "Soil_Seaweed_Block"
    },
    {
      "x": -28,
      "y": 9,
      "z": -25,
      "name": "Soil_Seaweed_Block"
    },
    {
      "x": -28,
      "y": 10,
      "z": -25,
      "name": "Soil_Seaweed_Block"
    },
    {
      "x": -28,
      "y": 11,
      "z": -25,
      "name": "Soil_Seaweed_Block"
    },
    {
      "x": -28,
      "y": 12,
      "z": -25,
      "name": "Soil_Seaweed_Block"
    },
    {
      "x": -28,
      "y": 13,
      "z": -25,
      "name": "Soil_Clay_Lime"
    },
    {
      "x": -28,
      "y": 14,
      "z": -25,
      "name": "Plant_Grass_Sharp"
    },
    {
      "x": -28,
      "y": 6,
      "z": -24,
      "name": "Soil_Clay_Green"
    },
    {
      "x": -28,
      "y": 7,
      "z": -24,
      "name": "Soil_Seaweed_Block"
    },
    {
      "x": -28,
      "y": 8,
      "z": -24,
      "name": "Soil_Seaweed_Block"
    },
    {
      "x": -28,
      "y": 9,
      "z": -24,
      "name": "Soil_Seaweed_Block"
    },
    {
      "x": -28,
      "y": 10,
      "z": -24,
      "name": "Soil_Seaweed_Block"
    },
    {
      "x": -28,
      "y": 11,
      "z": -24,
      "name": "Soil_Seaweed_Block"
    },
    {
      "x": -28,
      "y": 12,
      "z": -24,
      "name": "Soil_Seaweed_Block"
    },
    {
      "x": -28,
      "y": 13,
      "z": -24,
      "name": "Soil_Clay_Lime"
    },
    {
      "x": -28,
      "y": 14,
      "z": -24,
      "name": "Plant_Grass_Sharp"
    },
    {
      "x": -28,
      "y": 6,
      "z": -23,
      "name": "Soil_Clay_Green"
    },
    {
      "x": -28,
      "y": 7,
      "z": -23,
      "name": "Soil_Clay_Green"
    },
    {
      "x": -28,
      "y": 8,
      "z": -23,
      "name": "Soil_Clay_Green"
    },
    {
      "x": -28,
      "y": 9,
      "z": -23,
      "name": "Soil_Clay_Green"
    },
    {
      "x": -28,
      "y": 10,
      "z": -23,
      "name": "Soil_Clay_Green"
    },
    {
      "x": -28,
      "y": 11,
      "z": -23,
      "name": "Soil_Seaweed_Block"
    },
    {
      "x": -28,
      "y": 12,
      "z": -23,
      "name": "Soil_Seaweed_Block"
    },
    {
      "x": -28,
      "y": 13,
      "z": -23,
      "name": "Soil_Clay_Lime"
    },
    {
      "x": -28,
      "y": 14,
      "z": -23,
      "name": "Plant_Grass_Sharp"
    },
    {
      "x": -28,
      "y": 7,
      "z": -22,
      "name": "Soil_Clay_Green"
    },
    {
      "x": -28,
      "y": 8,
      "z": -22,
      "name": "Soil_Clay_Green"
    },
    {
      "x": -28,
      "y": 9,
      "z": -22,
      "name": "Soil_Clay_Green"
    },
    {
      "x": -28,
      "y": 10,
      "z": -22,
      "name": "Soil_Clay_Green"
    },
    {
      "x": -28,
      "y": 11,
      "z": -22,
      "name": "Soil_Seaweed_Block"
    },
    {
      "x": -28,
      "y": 12,
      "z": -22,
      "name": "Soil_Seaweed_Block"
    },
    {
      "x": -28,
      "y": 13,
      "z": -22,
      "name": "Soil_Seaweed_Block"
    },
    {
      "x": -28,
      "y": 7,
      "z": -21,
      "name": "Soil_Clay_Green"
    },
    {
      "x": -28,
      "y": 8,
      "z": -21,
      "name": "Soil_Clay_Green"
    },
    {
      "x": -28,
      "y": 9,
      "z": -21,
      "name": "Soil_Clay_Green"
    },
    {
      "x": -28,
      "y": 10,
      "z": -21,
      "name": "Soil_Clay_Green"
    },
    {
      "x": -28,
      "y": 11,
      "z": -21,
      "name": "Soil_Seaweed_Block"
    },
    {
      "x": -28,
      "y": 12,
      "z": -21,
      "name": "Soil_Seaweed_Block"
    },
    {
      "x": -27,
      "y": 15,
      "z": -42,
      "name": "Soil_Clay_Green"
    },
    {
      "x": -27,
      "y": 16,
      "z": -42,
      "name": "Soil_Clay_Green"
    },
    {
      "x": -27,
      "y": 16,
      "z": -41,
      "name": "Soil_Clay_Green"
    },
    {
      "x": -27,
      "y": 17,
      "z": -41,
      "name": "Soil_Clay_Lime"
    },
    {
      "x": -27,
      "y": 18,
      "z": -41,
      "name": "Plant_Grass_Sharp"
    },
    {
      "x": -27,
      "y": 17,
      "z": -40,
      "name": "Soil_Clay_Green"
    },
    {
      "x": -27,
      "y": 20,
      "z": -34,
      "name": "Soil_Clay_Green"
    },
    {
      "x": -27,
      "y": 21,
      "z": -34,
      "name": "Soil_Seaweed_Block"
    },
    {
      "x": -27,
      "y": 3,
      "z": -33,
      "name": "Soil_Clay_Green"
    },
    {
      "x": -27,
      "y": 4,
      "z": -33,
      "name": "Soil_Seaweed_Block"
    },
    {
      "x": -27,
      "y": 19,
      "z": -33,
      "name": "Soil_Clay_Green"
    },
    {
      "x": -27,
      "y": 20,
      "z": -33,
      "name": "Soil_Seaweed_Block"
    },
    {
      "x": -27,
      "y": 21,
      "z": -33,
      "name": "Soil_Seaweed_Block"
    },
    {
      "x": -27,
      "y": 22,
      "z": -33,
      "name": "Soil_Clay_Lime"
    },
    {
      "x": -27,
      "y": 23,
      "z": -33,
      "name": "Soil_Clay_Lime"
    },
    {
      "x": -27,
      "y": 24,
      "z": -33,
      "name": "Soil_Clay_Lime"
    },
    {
      "x": -27,
      "y": 25,
      "z": -33,
      "name": "Plant_Grass_Sharp"
    },
    {
      "x": -27,
      "y": 3,
      "z": -32,
      "name": "Soil_Clay_Green"
    },
    {
      "x": -27,
      "y": 4,
      "z": -32,
      "name": "Soil_Seaweed_Block"
    },
    {
      "x": -27,
      "y": 5,
      "z": -32,
      "name": "Soil_Clay_Lime"
    },
    {
      "x": -27,
      "y": 6,
      "z": -32,
      "name": "Plant_Grass_Sharp"
    },
    {
      "x": -27,
      "y": 17,
      "z": -32,
      "name": "Soil_Clay_Green"
    },
    {
      "x": -27,
      "y": 18,
      "z": -32,
      "name": "Soil_Clay_Green"
    },
    {
      "x": -27,
      "y": 19,
      "z": -32,
      "name": "Soil_Seaweed_Block"
    },
    {
      "x": -27,
      "y": 20,
      "z": -32,
      "name": "Soil_Seaweed_Block"
    },
    {
      "x": -27,
      "y": 21,
      "z": -32,
      "name": "Soil_Seaweed_Block"
    },
    {
      "x": -27,
      "y": 22,
      "z": -32,
      "name": "Soil_Clay_Lime"
    },
    {
      "x": -27,
      "y": 23,
      "z": -32,
      "name": "Plant_Grass_Sharp"
    },
    {
      "x": -27,
      "y": 3,
      "z": -31,
      "name": "Soil_Clay_Green"
    },
    {
      "x": -27,
      "y": 4,
      "z": -31,
      "name": "Soil_Seaweed_Block"
    },
    {
      "x": -27,
      "y": 5,
      "z": -31,
      "name": "Soil_Clay_Lime"
    },
    {
      "x": -27,
      "y": 6,
      "z": -31,
      "name": "Plant_Grass_Sharp"
    },
    {
      "x": -27,
      "y": 16,
      "z": -31,
      "name": "Soil_Clay_Green"
    },
    {
      "x": -27,
      "y": 17,
      "z": -31,
      "name": "Soil_Clay_Green"
    },
    {
      "x": -27,
      "y": 18,
      "z": -31,
      "name": "Soil_Seaweed_Block"
    },
    {
      "x": -27,
      "y": 19,
      "z": -31,
      "name": "Soil_Seaweed_Block"
    },
    {
      "x": -27,
      "y": 20,
      "z": -31,
      "name": "Soil_Seaweed_Block"
    },
    {
      "x": -27,
      "y": 21,
      "z": -31,
      "name": "Soil_Seaweed_Block"
    },
    {
      "x": -27,
      "y": 3,
      "z": -30,
      "name": "Soil_Clay_Green"
    },
    {
      "x": -27,
      "y": 4,
      "z": -30,
      "name": "Soil_Seaweed_Block"
    },
    {
      "x": -27,
      "y": 5,
      "z": -30,
      "name": "Soil_Seaweed_Block"
    },
    {
      "x": -27,
      "y": 6,
      "z": -30,
      "name": "Soil_Seaweed_Block"
    },
    {
      "x": -27,
      "y": 16,
      "z": -30,
      "name": "Soil_Clay_Green"
    },
    {
      "x": -27,
      "y": 17,
      "z": -30,
      "name": "Soil_Clay_Green"
    },
    {
      "x": -27,
      "y": 18,
      "z": -30,
      "name": "Soil_Seaweed_Block"
    },
    {
      "x": -27,
      "y": 19,
      "z": -30,
      "name": "Soil_Seaweed_Block"
    },
    {
      "x": -27,
      "y": 3,
      "z": -29,
      "name": "Soil_Clay_Green"
    },
    {
      "x": -27,
      "y": 4,
      "z": -29,
      "name": "Soil_Seaweed_Block"
    },
    {
      "x": -27,
      "y": 5,
      "z": -29,
      "name": "Soil_Seaweed_Block"
    },
    {
      "x": -27,
      "y": 6,
      "z": -29,
      "name": "Soil_Seaweed_Block"
    },
    {
      "x": -27,
      "y": 7,
      "z": -29,
      "name": "Soil_Seaweed_Block"
    },
    {
      "x": -27,
      "y": 8,
      "z": -29,
      "name": "Soil_Seaweed_Block"
    },
    {
      "x": -27,
      "y": 16,
      "z": -29,
      "name": "Soil_Clay_Green"
    },
    {
      "x": -27,
      "y": 17,
      "z": -29,
      "name": "Soil_Clay_Green"
    },
    {
      "x": -27,
      "y": 18,
      "z": -29,
      "name": "Soil_Seaweed_Block"
    },
    {
      "x": -27,
      "y": 3,
      "z": -28,
      "name": "Soil_Clay_Green"
    },
    {
      "x": -27,
      "y": 4,
      "z": -28,
      "name": "Soil_Clay_Green"
    },
    {
      "x": -27,
      "y": 5,
      "z": -28,
      "name": "Soil_Clay_Green"
    },
    {
      "x": -27,
      "y": 6,
      "z": -28,
      "name": "Soil_Clay_Green"
    },
    {
      "x": -27,
      "y": 7,
      "z": -28,
      "name": "Soil_Seaweed_Block"
    },
    {
      "x": -27,
      "y": 8,
      "z": -28,
      "name": "Soil_Seaweed_Block"
    },
    {
      "x": -27,
      "y": 9,
      "z": -28,
      "name": "Soil_Seaweed_Block"
    },
    {
      "x": -27,
      "y": 5,
      "z": -27,
      "name": "Soil_Clay_Green"
    },
    {
      "x": -27,
      "y": 6,
      "z": -27,
      "name": "Soil_Clay_Green"
    },
    {
      "x": -27,
      "y": 7,
      "z": -27,
      "name": "Soil_Clay_Green"
    },
    {
      "x": -27,
      "y": 8,
      "z": -27,
      "name": "Soil_Seaweed_Block"
    },
    {
      "x": -27,
      "y": 9,
      "z": -27,
      "name": "Soil_Seaweed_Block"
    },
    {
      "x": -27,
      "y": 10,
      "z": -27,
      "name": "Soil_Seaweed_Block"
    },
    {
      "x": -27,
      "y": 6,
      "z": -26,
      "name": "Soil_Clay_Green"
    },
    {
      "x": -27,
      "y": 7,
      "z": -26,
      "name": "Soil_Seaweed_Block"
    },
    {
      "x": -27,
      "y": 8,
      "z": -26,
      "name": "Soil_Seaweed_Block"
    },
    {
      "x": -27,
      "y": 9,
      "z": -26,
      "name": "Soil_Seaweed_Block"
    },
    {
      "x": -27,
      "y": 10,
      "z": -26,
      "name": "Soil_Seaweed_Block"
    },
    {
      "x": -27,
      "y": 11,
      "z": -26,
      "name": "Soil_Seaweed_Block"
    },
    {
      "x": -27,
      "y": 12,
      "z": -26,
      "name": "Soil_Seaweed_Block"
    },
    {
      "x": -27,
      "y": 5,
      "z": -25,
      "name": "Soil_Clay_Green"
    },
    {
      "x": -27,
      "y": 6,
      "z": -25,
      "name": "Soil_Seaweed_Block"
    },
    {
      "x": -27,
      "y": 7,
      "z": -25,
      "name": "Soil_Seaweed_Block"
    },
    {
      "x": -27,
      "y": 8,
      "z": -25,
      "name": "Soil_Seaweed_Block"
    },
    {
      "x": -27,
      "y": 9,
      "z": -25,
      "name": "Soil_Seaweed_Block"
    },
    {
      "x": -27,
      "y": 10,
      "z": -25,
      "name": "Soil_Seaweed_Block"
    },
    {
      "x": -27,
      "y": 11,
      "z": -25,
      "name": "Soil_Seaweed_Block"
    },
    {
      "x": -27,
      "y": 12,
      "z": -25,
      "name": "Soil_Clay_Lime"
    },
    {
      "x": -27,
      "y": 13,
      "z": -25,
      "name": "Plant_Grass_Sharp"
    },
    {
      "x": -27,
      "y": 6,
      "z": -24,
      "name": "Soil_Clay_Green"
    },
    {
      "x": -27,
      "y": 7,
      "z": -24,
      "name": "Soil_Seaweed_Block"
    },
    {
      "x": -27,
      "y": 8,
      "z": -24,
      "name": "Soil_Seaweed_Block"
    },
    {
      "x": -27,
      "y": 9,
      "z": -24,
      "name": "Soil_Seaweed_Block"
    },
    {
      "x": -27,
      "y": 10,
      "z": -24,
      "name": "Soil_Seaweed_Block"
    },
    {
      "x": -27,
      "y": 11,
      "z": -24,
      "name": "Soil_Seaweed_Block"
    },
    {
      "x": -27,
      "y": 12,
      "z": -24,
      "name": "Soil_Seaweed_Block"
    },
    {
      "x": -27,
      "y": 13,
      "z": -24,
      "name": "Soil_Clay_Lime"
    },
    {
      "x": -27,
      "y": 14,
      "z": -24,
      "name": "Plant_Grass_Sharp"
    },
    {
      "x": -27,
      "y": 6,
      "z": -23,
      "name": "Soil_Clay_Green"
    },
    {
      "x": -27,
      "y": 7,
      "z": -23,
      "name": "Soil_Seaweed_Block"
    },
    {
      "x": -27,
      "y": 8,
      "z": -23,
      "name": "Soil_Seaweed_Block"
    },
    {
      "x": -27,
      "y": 9,
      "z": -23,
      "name": "Soil_Seaweed_Block"
    },
    {
      "x": -27,
      "y": 10,
      "z": -23,
      "name": "Soil_Seaweed_Block"
    },
    {
      "x": -27,
      "y": 11,
      "z": -23,
      "name": "Soil_Seaweed_Block"
    },
    {
      "x": -27,
      "y": 12,
      "z": -23,
      "name": "Soil_Seaweed_Block"
    },
    {
      "x": -27,
      "y": 13,
      "z": -23,
      "name": "Soil_Clay_Lime"
    },
    {
      "x": -27,
      "y": 14,
      "z": -23,
      "name": "Plant_Grass_Sharp"
    },
    {
      "x": -27,
      "y": 6,
      "z": -22,
      "name": "Soil_Clay_Green"
    },
    {
      "x": -27,
      "y": 7,
      "z": -22,
      "name": "Soil_Seaweed_Block"
    },
    {
      "x": -27,
      "y": 8,
      "z": -22,
      "name": "Soil_Seaweed_Block"
    },
    {
      "x": -27,
      "y": 9,
      "z": -22,
      "name": "Soil_Seaweed_Block"
    },
    {
      "x": -27,
      "y": 10,
      "z": -22,
      "name": "Soil_Seaweed_Block"
    },
    {
      "x": -27,
      "y": 11,
      "z": -22,
      "name": "Soil_Seaweed_Block"
    },
    {
      "x": -27,
      "y": 12,
      "z": -22,
      "name": "Soil_Seaweed_Block"
    },
    {
      "x": -27,
      "y": 13,
      "z": -22,
      "name": "Soil_Seaweed_Block"
    },
    {
      "x": -27,
      "y": 14,
      "z": -22,
      "name": "Soil_Clay_Lime"
    },
    {
      "x": -27,
      "y": 15,
      "z": -22,
      "name": "Plant_Grass_Sharp"
    },
    {
      "x": -27,
      "y": 6,
      "z": -21,
      "name": "Soil_Clay_Green"
    },
    {
      "x": -27,
      "y": 7,
      "z": -21,
      "name": "Soil_Seaweed_Block"
    },
    {
      "x": -27,
      "y": 8,
      "z": -21,
      "name": "Soil_Seaweed_Block"
    },
    {
      "x": -27,
      "y": 9,
      "z": -21,
      "name": "Soil_Seaweed_Block"
    },
    {
      "x": -27,
      "y": 10,
      "z": -21,
      "name": "Soil_Seaweed_Block"
    },
    {
      "x": -27,
      "y": 11,
      "z": -21,
      "name": "Soil_Seaweed_Block"
    },
    {
      "x": -27,
      "y": 12,
      "z": -21,
      "name": "Soil_Seaweed_Block"
    },
    {
      "x": -27,
      "y": 13,
      "z": -21,
      "name": "Soil_Seaweed_Block"
    },
    {
      "x": -27,
      "y": 14,
      "z": -21,
      "name": "Soil_Clay_Lime"
    },
    {
      "x": -27,
      "y": 15,
      "z": -21,
      "name": "Plant_Grass_Sharp"
    },
    {
      "x": -27,
      "y": 7,
      "z": -20,
      "name": "Soil_Clay_Green"
    },
    {
      "x": -27,
      "y": 8,
      "z": -20,
      "name": "Soil_Clay_Green"
    },
    {
      "x": -27,
      "y": 9,
      "z": -20,
      "name": "Soil_Clay_Green"
    },
    {
      "x": -27,
      "y": 10,
      "z": -20,
      "name": "Soil_Clay_Green"
    },
    {
      "x": -27,
      "y": 11,
      "z": -20,
      "name": "Soil_Seaweed_Block"
    },
    {
      "x": -27,
      "y": 12,
      "z": -20,
      "name": "Soil_Seaweed_Block"
    },
    {
      "x": -27,
      "y": 13,
      "z": -20,
      "name": "Soil_Seaweed_Block"
    },
    {
      "x": -27,
      "y": 14,
      "z": -20,
      "name": "Soil_Seaweed_Block"
    },
    {
      "x": -26,
      "y": 17,
      "z": -41,
      "name": "Soil_Seaweed_Block"
    },
    {
      "x": -26,
      "y": 17,
      "z": -40,
      "name": "Soil_Clay_Green"
    },
    {
      "x": -26,
      "y": 18,
      "z": -40,
      "name": "Soil_Seaweed_Block"
    },
    {
      "x": -26,
      "y": 18,
      "z": -39,
      "name": "Soil_Clay_Green"
    },
    {
      "x": -26,
      "y": 19,
      "z": -39,
      "name": "Soil_Clay_Lime"
    },
    {
      "x": -26,
      "y": 20,
      "z": -39,
      "name": "Plant_Grass_Sharp"
    },
    {
      "x": -26,
      "y": 19,
      "z": -38,
      "name": "Soil_Clay_Green"
    },
    {
      "x": -26,
      "y": 20,
      "z": -38,
      "name": "Soil_Clay_Lime"
    },
    {
      "x": -26,
      "y": 21,
      "z": -38,
      "name": "Plant_Grass_Sharp"
    },
    {
      "x": -26,
      "y": 19,
      "z": -37,
      "name": "Soil_Clay_Green"
    },
    {
      "x": -26,
      "y": 20,
      "z": -37,
      "name": "Soil_Seaweed_Block"
    },
    {
      "x": -26,
      "y": 19,
      "z": -36,
      "name": "Soil_Clay_Green"
    },
    {
      "x": -26,
      "y": 20,
      "z": -36,
      "name": "Soil_Clay_Green"
    },
    {
      "x": -26,
      "y": 20,
      "z": -35,
      "name": "Soil_Clay_Green"
    },
    {
      "x": -26,
      "y": 21,
      "z": -35,
      "name": "Soil_Seaweed_Block"
    },
    {
      "x": -26,
      "y": 20,
      "z": -34,
      "name": "Soil_Clay_Green"
    },
    {
      "x": -26,
      "y": 21,
      "z": -34,
      "name": "Soil_Seaweed_Block"
    },
    {
      "x": -26,
      "y": 22,
      "z": -34,
      "name": "Soil_Clay_Lime"
    },
    {
      "x": -26,
      "y": 23,
      "z": -34,
      "name": "Plant_Grass_Sharp"
    },
    {
      "x": -26,
      "y": 18,
      "z": -33,
      "name": "Soil_Clay_Green"
    },
    {
      "x": -26,
      "y": 19,
      "z": -33,
      "name": "Soil_Clay_Green"
    },
    {
      "x": -26,
      "y": 20,
      "z": -33,
      "name": "Soil_Seaweed_Block"
    },
    {
      "x": -26,
      "y": 21,
      "z": -33,
      "name": "Soil_Seaweed_Block"
    },
    {
      "x": -26,
      "y": 22,
      "z": -33,
      "name": "Soil_Clay_Lime"
    },
    {
      "x": -26,
      "y": 23,
      "z": -33,
      "name": "Plant_Grass_Sharp"
    },
    {
      "x": -26,
      "y": 4,
      "z": -32,
      "name": "Soil_Clay_Green"
    },
    {
      "x": -26,
      "y": 17,
      "z": -32,
      "name": "Soil_Clay_Green"
    },
    {
      "x": -26,
      "y": 18,
      "z": -32,
      "name": "Soil_Seaweed_Block"
    },
    {
      "x": -26,
      "y": 19,
      "z": -32,
      "name": "Soil_Seaweed_Block"
    },
    {
      "x": -26,
      "y": 20,
      "z": -32,
      "name": "Soil_Seaweed_Block"
    },
    {
      "x": -26,
      "y": 21,
      "z": -32,
      "name": "Soil_Clay_Lime"
    },
    {
      "x": -26,
      "y": 22,
      "z": -32,
      "name": "Soil_Clay_Lime"
    },
    {
      "x": -26,
      "y": 23,
      "z": -32,
      "name": "Plant_Grass_Sharp"
    },
    {
      "x": -26,
      "y": 4,
      "z": -31,
      "name": "Soil_Clay_Green"
    },
    {
      "x": -26,
      "y": 5,
      "z": -31,
      "name": "Soil_Seaweed_Block"
    },
    {
      "x": -26,
      "y": 16,
      "z": -31,
      "name": "Soil_Clay_Green"
    },
    {
      "x": -26,
      "y": 17,
      "z": -31,
      "name": "Soil_Seaweed_Block"
    },
    {
      "x": -26,
      "y": 18,
      "z": -31,
      "name": "Soil_Seaweed_Block"
    },
    {
      "x": -26,
      "y": 19,
      "z": -31,
      "name": "Soil_Seaweed_Block"
    },
    {
      "x": -26,
      "y": 20,
      "z": -31,
      "name": "Soil_Seaweed_Block"
    },
    {
      "x": -26,
      "y": 4,
      "z": -30,
      "name": "Soil_Clay_Green"
    },
    {
      "x": -26,
      "y": 5,
      "z": -30,
      "name": "Soil_Seaweed_Block"
    },
    {
      "x": -26,
      "y": 6,
      "z": -30,
      "name": "Soil_Seaweed_Block"
    },
    {
      "x": -26,
      "y": 7,
      "z": -30,
      "name": "Soil_Seaweed_Block"
    },
    {
      "x": -26,
      "y": 8,
      "z": -30,
      "name": "Soil_Seaweed_Block"
    },
    {
      "x": -26,
      "y": 16,
      "z": -30,
      "name": "Soil_Clay_Green"
    },
    {
      "x": -26,
      "y": 17,
      "z": -30,
      "name": "Soil_Seaweed_Block"
    },
    {
      "x": -26,
      "y": 18,
      "z": -30,
      "name": "Soil_Seaweed_Block"
    },
    {
      "x": -26,
      "y": 19,
      "z": -30,
      "name": "Soil_Clay_Lime"
    },
    {
      "x": -26,
      "y": 20,
      "z": -30,
      "name": "Plant_Grass_Sharp"
    },
    {
      "x": -26,
      "y": 4,
      "z": -29,
      "name": "Soil_Clay_Green"
    },
    {
      "x": -26,
      "y": 5,
      "z": -29,
      "name": "Soil_Seaweed_Block"
    },
    {
      "x": -26,
      "y": 6,
      "z": -29,
      "name": "Soil_Seaweed_Block"
    },
    {
      "x": -26,
      "y": 7,
      "z": -29,
      "name": "Soil_Seaweed_Block"
    },
    {
      "x": -26,
      "y": 8,
      "z": -29,
      "name": "Soil_Seaweed_Block"
    },
    {
      "x": -26,
      "y": 9,
      "z": -29,
      "name": "Soil_Seaweed_Block"
    },
    {
      "x": -26,
      "y": 16,
      "z": -29,
      "name": "Soil_Clay_Green"
    },
    {
      "x": -26,
      "y": 17,
      "z": -29,
      "name": "Soil_Seaweed_Block"
    },
    {
      "x": -26,
      "y": 18,
      "z": -29,
      "name": "Soil_Seaweed_Block"
    },
    {
      "x": -26,
      "y": 4,
      "z": -28,
      "name": "Soil_Clay_Green"
    },
    {
      "x": -26,
      "y": 5,
      "z": -28,
      "name": "Soil_Seaweed_Block"
    },
    {
      "x": -26,
      "y": 6,
      "z": -28,
      "name": "Soil_Seaweed_Block"
    },
    {
      "x": -26,
      "y": 7,
      "z": -28,
      "name": "Soil_Seaweed_Block"
    },
    {
      "x": -26,
      "y": 8,
      "z": -28,
      "name": "Soil_Seaweed_Block"
    },
    {
      "x": -26,
      "y": 9,
      "z": -28,
      "name": "Soil_Seaweed_Block"
    },
    {
      "x": -26,
      "y": 15,
      "z": -28,
      "name": "Soil_Clay_Green"
    },
    {
      "x": -26,
      "y": 16,
      "z": -28,
      "name": "Soil_Clay_Green"
    },
    {
      "x": -26,
      "y": 17,
      "z": -28,
      "name": "Soil_Seaweed_Block"
    },
    {
      "x": -26,
      "y": 4,
      "z": -27,
      "name": "Soil_Clay_Green"
    },
    {
      "x": -26,
      "y": 5,
      "z": -27,
      "name": "Soil_Seaweed_Block"
    },
    {
      "x": -26,
      "y": 6,
      "z": -27,
      "name": "Soil_Seaweed_Block"
    },
    {
      "x": -26,
      "y": 7,
      "z": -27,
      "name": "Soil_Seaweed_Block"
    },
    {
      "x": -26,
      "y": 8,
      "z": -27,
      "name": "Soil_Seaweed_Block"
    },
    {
      "x": -26,
      "y": 9,
      "z": -27,
      "name": "Soil_Seaweed_Block"
    },
    {
      "x": -26,
      "y": 10,
      "z": -27,
      "name": "Soil_Seaweed_Block"
    },
    {
      "x": -26,
      "y": 5,
      "z": -26,
      "name": "Soil_Clay_Green"
    },
    {
      "x": -26,
      "y": 6,
      "z": -26,
      "name": "Soil_Seaweed_Block"
    },
    {
      "x": -26,
      "y": 7,
      "z": -26,
      "name": "Soil_Seaweed_Block"
    },
    {
      "x": -26,
      "y": 8,
      "z": -26,
      "name": "Soil_Seaweed_Block"
    },
    {
      "x": -26,
      "y": 9,
      "z": -26,
      "name": "Soil_Seaweed_Block"
    },
    {
      "x": -26,
      "y": 10,
      "z": -26,
      "name": "Soil_Seaweed_Block"
    },
    {
      "x": -26,
      "y": 11,
      "z": -26,
      "name": "Soil_Seaweed_Block"
    },
    {
      "x": -26,
      "y": 5,
      "z": -25,
      "name": "Soil_Clay_Green"
    },
    {
      "x": -26,
      "y": 6,
      "z": -25,
      "name": "Soil_Seaweed_Block"
    },
    {
      "x": -26,
      "y": 7,
      "z": -25,
      "name": "Soil_Seaweed_Block"
    },
    {
      "x": -26,
      "y": 8,
      "z": -25,
      "name": "Soil_Seaweed_Block"
    },
    {
      "x": -26,
      "y": 9,
      "z": -25,
      "name": "Soil_Seaweed_Block"
    },
    {
      "x": -26,
      "y": 10,
      "z": -25,
      "name": "Soil_Seaweed_Block"
    },
    {
      "x": -26,
      "y": 11,
      "z": -25,
      "name": "Soil_Seaweed_Block"
    },
    {
      "x": -26,
      "y": 12,
      "z": -25,
      "name": "Soil_Clay_Lime"
    },
    {
      "x": -26,
      "y": 13,
      "z": -25,
      "name": "Plant_Grass_Sharp"
    },
    {
      "x": -26,
      "y": 5,
      "z": -24,
      "name": "Soil_Clay_Green"
    },
    {
      "x": -26,
      "y": 6,
      "z": -24,
      "name": "Soil_Seaweed_Block"
    },
    {
      "x": -26,
      "y": 7,
      "z": -24,
      "name": "Soil_Seaweed_Block"
    },
    {
      "x": -26,
      "y": 8,
      "z": -24,
      "name": "Soil_Seaweed_Block"
    },
    {
      "x": -26,
      "y": 9,
      "z": -24,
      "name": "Soil_Seaweed_Block"
    },
    {
      "x": -26,
      "y": 10,
      "z": -24,
      "name": "Soil_Seaweed_Block"
    },
    {
      "x": -26,
      "y": 11,
      "z": -24,
      "name": "Soil_Seaweed_Block"
    },
    {
      "x": -26,
      "y": 12,
      "z": -24,
      "name": "Soil_Seaweed_Block"
    },
    {
      "x": -26,
      "y": 13,
      "z": -24,
      "name": "Soil_Clay_Lime"
    },
    {
      "x": -26,
      "y": 14,
      "z": -24,
      "name": "Plant_Grass_Sharp"
    },
    {
      "x": -26,
      "y": 5,
      "z": -23,
      "name": "Soil_Clay_Green"
    },
    {
      "x": -26,
      "y": 6,
      "z": -23,
      "name": "Soil_Seaweed_Block"
    },
    {
      "x": -26,
      "y": 7,
      "z": -23,
      "name": "Soil_Seaweed_Block"
    },
    {
      "x": -26,
      "y": 8,
      "z": -23,
      "name": "Soil_Seaweed_Block"
    },
    {
      "x": -26,
      "y": 9,
      "z": -23,
      "name": "Soil_Seaweed_Block"
    },
    {
      "x": -26,
      "y": 10,
      "z": -23,
      "name": "Soil_Seaweed_Block"
    },
    {
      "x": -26,
      "y": 11,
      "z": -23,
      "name": "Soil_Seaweed_Block"
    },
    {
      "x": -26,
      "y": 12,
      "z": -23,
      "name": "Soil_Seaweed_Block"
    },
    {
      "x": -26,
      "y": 13,
      "z": -23,
      "name": "Soil_Seaweed_Block"
    },
    {
      "x": -26,
      "y": 14,
      "z": -23,
      "name": "Soil_Clay_Lime"
    },
    {
      "x": -26,
      "y": 15,
      "z": -23,
      "name": "Plant_Grass_Sharp"
    },
    {
      "x": -26,
      "y": 5,
      "z": -22,
      "name": "Soil_Clay_Green"
    },
    {
      "x": -26,
      "y": 6,
      "z": -22,
      "name": "Soil_Seaweed_Block"
    },
    {
      "x": -26,
      "y": 7,
      "z": -22,
      "name": "Soil_Seaweed_Block"
    },
    {
      "x": -26,
      "y": 8,
      "z": -22,
      "name": "Soil_Seaweed_Block"
    },
    {
      "x": -26,
      "y": 9,
      "z": -22,
      "name": "Soil_Seaweed_Block"
    },
    {
      "x": -26,
      "y": 10,
      "z": -22,
      "name": "Soil_Seaweed_Block"
    },
    {
      "x": -26,
      "y": 11,
      "z": -22,
      "name": "Soil_Seaweed_Block"
    },
    {
      "x": -26,
      "y": 12,
      "z": -22,
      "name": "Soil_Seaweed_Block"
    },
    {
      "x": -26,
      "y": 13,
      "z": -22,
      "name": "Soil_Seaweed_Block"
    },
    {
      "x": -26,
      "y": 14,
      "z": -22,
      "name": "Soil_Clay_Lime"
    },
    {
      "x": -26,
      "y": 15,
      "z": -22,
      "name": "Plant_Grass_Sharp"
    },
    {
      "x": -26,
      "y": 6,
      "z": -21,
      "name": "Soil_Clay_Green"
    },
    {
      "x": -26,
      "y": 7,
      "z": -21,
      "name": "Soil_Seaweed_Block"
    },
    {
      "x": -26,
      "y": 8,
      "z": -21,
      "name": "Soil_Seaweed_Block"
    },
    {
      "x": -26,
      "y": 9,
      "z": -21,
      "name": "Soil_Seaweed_Block"
    },
    {
      "x": -26,
      "y": 10,
      "z": -21,
      "name": "Soil_Seaweed_Block"
    },
    {
      "x": -26,
      "y": 11,
      "z": -21,
      "name": "Soil_Seaweed_Block"
    },
    {
      "x": -26,
      "y": 12,
      "z": -21,
      "name": "Soil_Seaweed_Block"
    },
    {
      "x": -26,
      "y": 13,
      "z": -21,
      "name": "Soil_Seaweed_Block"
    },
    {
      "x": -26,
      "y": 14,
      "z": -21,
      "name": "Soil_Seaweed_Block"
    },
    {
      "x": -26,
      "y": 15,
      "z": -21,
      "name": "Soil_Clay_Lime"
    },
    {
      "x": -26,
      "y": 16,
      "z": -21,
      "name": "Plant_Grass_Sharp"
    },
    {
      "x": -26,
      "y": 6,
      "z": -20,
      "name": "Soil_Clay_Green"
    },
    {
      "x": -26,
      "y": 7,
      "z": -20,
      "name": "Soil_Clay_Green"
    },
    {
      "x": -26,
      "y": 8,
      "z": -20,
      "name": "Soil_Seaweed_Block"
    },
    {
      "x": -26,
      "y": 9,
      "z": -20,
      "name": "Soil_Seaweed_Block"
    },
    {
      "x": -26,
      "y": 10,
      "z": -20,
      "name": "Soil_Seaweed_Block"
    },
    {
      "x": -26,
      "y": 11,
      "z": -20,
      "name": "Soil_Seaweed_Block"
    },
    {
      "x": -26,
      "y": 12,
      "z": -20,
      "name": "Soil_Seaweed_Block"
    },
    {
      "x": -26,
      "y": 13,
      "z": -20,
      "name": "Soil_Seaweed_Block"
    },
    {
      "x": -26,
      "y": 14,
      "z": -20,
      "name": "Soil_Seaweed_Block"
    },
    {
      "x": -26,
      "y": 15,
      "z": -20,
      "name": "Soil_Clay_Lime"
    },
    {
      "x": -26,
      "y": 16,
      "z": -20,
      "name": "Plant_Grass_Sharp"
    },
    {
      "x": -26,
      "y": 8,
      "z": -19,
      "name": "Soil_Clay_Green"
    },
    {
      "x": -26,
      "y": 9,
      "z": -19,
      "name": "Soil_Clay_Green"
    },
    {
      "x": -26,
      "y": 10,
      "z": -19,
      "name": "Soil_Clay_Green"
    },
    {
      "x": -26,
      "y": 11,
      "z": -19,
      "name": "Soil_Seaweed_Block"
    },
    {
      "x": -26,
      "y": 12,
      "z": -19,
      "name": "Soil_Seaweed_Block"
    },
    {
      "x": -26,
      "y": 13,
      "z": -19,
      "name": "Soil_Seaweed_Block"
    },
    {
      "x": -26,
      "y": 14,
      "z": -19,
      "name": "Soil_Seaweed_Block"
    },
    {
      "x": -26,
      "y": 15,
      "z": -19,
      "name": "Soil_Clay_Lime"
    },
    {
      "x": -26,
      "y": 16,
      "z": -19,
      "name": "Plant_Grass_Sharp"
    },
    {
      "x": -25,
      "y": 13,
      "z": -52,
      "name": "Soil_Clay_Green"
    },
    {
      "x": -25,
      "y": 6,
      "z": -48,
      "name": "Soil_Clay_Green"
    },
    {
      "x": -25,
      "y": 6,
      "z": -47,
      "name": "Soil_Clay_Green"
    },
    {
      "x": -25,
      "y": 6,
      "z": -40,
      "name": "Soil_Clay_Green"
    },
    {
      "x": -25,
      "y": 19,
      "z": -38,
      "name": "Soil_Clay_Green"
    },
    {
      "x": -25,
      "y": 19,
      "z": -37,
      "name": "Soil_Clay_Green"
    },
    {
      "x": -25,
      "y": 20,
      "z": -37,
      "name": "Soil_Seaweed_Block"
    },
    {
      "x": -25,
      "y": 19,
      "z": -36,
      "name": "Soil_Clay_Green"
    },
    {
      "x": -25,
      "y": 20,
      "z": -36,
      "name": "Soil_Clay_Green"
    },
    {
      "x": -25,
      "y": 21,
      "z": -36,
      "name": "Soil_Clay_Lime"
    },
    {
      "x": -25,
      "y": 22,
      "z": -36,
      "name": "Plant_Grass_Sharp"
    },
    {
      "x": -25,
      "y": 20,
      "z": -35,
      "name": "Soil_Clay_Green"
    },
    {
      "x": -25,
      "y": 21,
      "z": -35,
      "name": "Soil_Seaweed_Block"
    },
    {
      "x": -25,
      "y": 20,
      "z": -34,
      "name": "Soil_Clay_Green"
    },
    {
      "x": -25,
      "y": 21,
      "z": -34,
      "name": "Soil_Seaweed_Block"
    },
    {
      "x": -25,
      "y": 19,
      "z": -33,
      "name": "Soil_Clay_Green"
    },
    {
      "x": -25,
      "y": 20,
      "z": -33,
      "name": "Soil_Seaweed_Block"
    },
    {
      "x": -25,
      "y": 21,
      "z": -33,
      "name": "Soil_Seaweed_Block"
    },
    {
      "x": -25,
      "y": 8,
      "z": -32,
      "name": "Soil_Seaweed_Block"
    },
    {
      "x": -25,
      "y": 17,
      "z": -32,
      "name": "Soil_Clay_Green"
    },
    {
      "x": -25,
      "y": 18,
      "z": -32,
      "name": "Soil_Clay_Green"
    },
    {
      "x": -25,
      "y": 19,
      "z": -32,
      "name": "Soil_Seaweed_Block"
    },
    {
      "x": -25,
      "y": 20,
      "z": -32,
      "name": "Soil_Seaweed_Block"
    },
    {
      "x": -25,
      "y": 8,
      "z": -31,
      "name": "Soil_Seaweed_Block"
    },
    {
      "x": -25,
      "y": 16,
      "z": -31,
      "name": "Soil_Clay_Green"
    },
    {
      "x": -25,
      "y": 17,
      "z": -31,
      "name": "Soil_Seaweed_Block"
    },
    {
      "x": -25,
      "y": 18,
      "z": -31,
      "name": "Soil_Seaweed_Block"
    },
    {
      "x": -25,
      "y": 19,
      "z": -31,
      "name": "Soil_Seaweed_Block"
    },
    {
      "x": -25,
      "y": 20,
      "z": -31,
      "name": "Soil_Seaweed_Block"
    },
    {
      "x": -25,
      "y": 5,
      "z": -30,
      "name": "Soil_Clay_Green"
    },
    {
      "x": -25,
      "y": 6,
      "z": -30,
      "name": "Soil_Clay_Green"
    },
    {
      "x": -25,
      "y": 7,
      "z": -30,
      "name": "Soil_Seaweed_Block"
    },
    {
      "x": -25,
      "y": 8,
      "z": -30,
      "name": "Soil_Seaweed_Block"
    },
    {
      "x": -25,
      "y": 16,
      "z": -30,
      "name": "Soil_Clay_Green"
    },
    {
      "x": -25,
      "y": 17,
      "z": -30,
      "name": "Soil_Seaweed_Block"
    },
    {
      "x": -25,
      "y": 18,
      "z": -30,
      "name": "Soil_Seaweed_Block"
    },
    {
      "x": -25,
      "y": 19,
      "z": -30,
      "name": "Soil_Clay_Lime"
    },
    {
      "x": -25,
      "y": 20,
      "z": -30,
      "name": "Plant_Grass_Sharp"
    },
    {
      "x": -25,
      "y": 5,
      "z": -29,
      "name": "Soil_Clay_Green"
    },
    {
      "x": -25,
      "y": 6,
      "z": -29,
      "name": "Soil_Seaweed_Block"
    },
    {
      "x": -25,
      "y": 7,
      "z": -29,
      "name": "Soil_Seaweed_Block"
    },
    {
      "x": -25,
      "y": 8,
      "z": -29,
      "name": "Soil_Seaweed_Block"
    },
    {
      "x": -25,
      "y": 9,
      "z": -29,
      "name": "Soil_Clay_Lime"
    },
    {
      "x": -25,
      "y": 10,
      "z": -29,
      "name": "Plant_Grass_Sharp"
    },
    {
      "x": -25,
      "y": 15,
      "z": -29,
      "name": "Soil_Clay_Green"
    },
    {
      "x": -25,
      "y": 16,
      "z": -29,
      "name": "Soil_Seaweed_Block"
    },
    {
      "x": -25,
      "y": 17,
      "z": -29,
      "name": "Soil_Seaweed_Block"
    },
    {
      "x": -25,
      "y": 18,
      "z": -29,
      "name": "Soil_Clay_Lime"
    },
    {
      "x": -25,
      "y": 19,
      "z": -29,
      "name": "Plant_Grass_Sharp"
    },
    {
      "x": -25,
      "y": 4,
      "z": -28,
      "name": "Soil_Clay_Green"
    },
    {
      "x": -25,
      "y": 5,
      "z": -28,
      "name": "Soil_Seaweed_Block"
    },
    {
      "x": -25,
      "y": 6,
      "z": -28,
      "name": "Soil_Seaweed_Block"
    },
    {
      "x": -25,
      "y": 7,
      "z": -28,
      "name": "Soil_Seaweed_Block"
    },
    {
      "x": -25,
      "y": 8,
      "z": -28,
      "name": "Soil_Seaweed_Block"
    },
    {
      "x": -25,
      "y": 9,
      "z": -28,
      "name": "Soil_Clay_Lime"
    },
    {
      "x": -25,
      "y": 10,
      "z": -28,
      "name": "Plant_Grass_Sharp"
    },
    {
      "x": -25,
      "y": 15,
      "z": -28,
      "name": "Soil_Clay_Green"
    },
    {
      "x": -25,
      "y": 16,
      "z": -28,
      "name": "Soil_Seaweed_Block"
    },
    {
      "x": -25,
      "y": 17,
      "z": -28,
      "name": "Soil_Seaweed_Block"
    },
    {
      "x": -25,
      "y": 18,
      "z": -28,
      "name": "Soil_Clay_Lime"
    },
    {
      "x": -25,
      "y": 19,
      "z": -28,
      "name": "Plant_Grass_Sharp"
    },
    {
      "x": -25,
      "y": 4,
      "z": -27,
      "name": "Soil_Clay_Green"
    },
    {
      "x": -25,
      "y": 5,
      "z": -27,
      "name": "Soil_Seaweed_Block"
    },
    {
      "x": -25,
      "y": 6,
      "z": -27,
      "name": "Soil_Seaweed_Block"
    },
    {
      "x": -25,
      "y": 7,
      "z": -27,
      "name": "Soil_Seaweed_Block"
    },
    {
      "x": -25,
      "y": 8,
      "z": -27,
      "name": "Soil_Seaweed_Block"
    },
    {
      "x": -25,
      "y": 9,
      "z": -27,
      "name": "Soil_Seaweed_Block"
    },
    {
      "x": -25,
      "y": 10,
      "z": -27,
      "name": "Soil_Clay_Lime"
    },
    {
      "x": -25,
      "y": 11,
      "z": -27,
      "name": "Plant_Grass_Sharp"
    },
    {
      "x": -25,
      "y": 15,
      "z": -27,
      "name": "Soil_Clay_Green"
    },
    {
      "x": -25,
      "y": 16,
      "z": -27,
      "name": "Soil_Seaweed_Block"
    },
    {
      "x": -25,
      "y": 17,
      "z": -27,
      "name": "Soil_Clay_Lime"
    },
    {
      "x": -25,
      "y": 18,
      "z": -27,
      "name": "Plant_Grass_Sharp"
    },
    {
      "x": -25,
      "y": 4,
      "z": -26,
      "name": "Soil_Clay_Green"
    },
    {
      "x": -25,
      "y": 5,
      "z": -26,
      "name": "Soil_Seaweed_Block"
    },
    {
      "x": -25,
      "y": 6,
      "z": -26,
      "name": "Soil_Seaweed_Block"
    },
    {
      "x": -25,
      "y": 7,
      "z": -26,
      "name": "Soil_Seaweed_Block"
    },
    {
      "x": -25,
      "y": 8,
      "z": -26,
      "name": "Soil_Seaweed_Block"
    },
    {
      "x": -25,
      "y": 9,
      "z": -26,
      "name": "Soil_Seaweed_Block"
    },
    {
      "x": -25,
      "y": 10,
      "z": -26,
      "name": "Soil_Seaweed_Block"
    },
    {
      "x": -25,
      "y": 11,
      "z": -26,
      "name": "Soil_Seaweed_Block"
    },
    {
      "x": -25,
      "y": 15,
      "z": -26,
      "name": "Soil_Seaweed_Block"
    },
    {
      "x": -25,
      "y": 4,
      "z": -25,
      "name": "Soil_Clay_Green"
    },
    {
      "x": -25,
      "y": 5,
      "z": -25,
      "name": "Soil_Seaweed_Block"
    },
    {
      "x": -25,
      "y": 6,
      "z": -25,
      "name": "Soil_Seaweed_Block"
    },
    {
      "x": -25,
      "y": 7,
      "z": -25,
      "name": "Soil_Seaweed_Block"
    },
    {
      "x": -25,
      "y": 8,
      "z": -25,
      "name": "Soil_Seaweed_Block"
    },
    {
      "x": -25,
      "y": 9,
      "z": -25,
      "name": "Soil_Seaweed_Block"
    },
    {
      "x": -25,
      "y": 10,
      "z": -25,
      "name": "Soil_Seaweed_Block"
    },
    {
      "x": -25,
      "y": 11,
      "z": -25,
      "name": "Soil_Seaweed_Block"
    },
    {
      "x": -25,
      "y": 12,
      "z": -25,
      "name": "Soil_Seaweed_Block"
    },
    {
      "x": -25,
      "y": 13,
      "z": -25,
      "name": "Soil_Seaweed_Block"
    },
    {
      "x": -25,
      "y": 3,
      "z": -24,
      "name": "Soil_Clay_Green"
    },
    {
      "x": -25,
      "y": 4,
      "z": -24,
      "name": "Soil_Clay_Green"
    },
    {
      "x": -25,
      "y": 5,
      "z": -24,
      "name": "Soil_Seaweed_Block"
    },
    {
      "x": -25,
      "y": 6,
      "z": -24,
      "name": "Soil_Seaweed_Block"
    },
    {
      "x": -25,
      "y": 7,
      "z": -24,
      "name": "Soil_Seaweed_Block"
    },
    {
      "x": -25,
      "y": 8,
      "z": -24,
      "name": "Soil_Seaweed_Block"
    },
    {
      "x": -25,
      "y": 9,
      "z": -24,
      "name": "Soil_Seaweed_Block"
    },
    {
      "x": -25,
      "y": 10,
      "z": -24,
      "name": "Soil_Seaweed_Block"
    },
    {
      "x": -25,
      "y": 11,
      "z": -24,
      "name": "Soil_Seaweed_Block"
    },
    {
      "x": -25,
      "y": 12,
      "z": -24,
      "name": "Soil_Seaweed_Block"
    },
    {
      "x": -25,
      "y": 13,
      "z": -24,
      "name": "Soil_Seaweed_Block"
    },
    {
      "x": -25,
      "y": 14,
      "z": -24,
      "name": "Soil_Clay_Lime"
    },
    {
      "x": -25,
      "y": 15,
      "z": -24,
      "name": "Plant_Grass_Sharp"
    },
    {
      "x": -25,
      "y": 3,
      "z": -23,
      "name": "Soil_Clay_Green"
    },
    {
      "x": -25,
      "y": 4,
      "z": -23,
      "name": "Soil_Clay_Green"
    },
    {
      "x": -25,
      "y": 5,
      "z": -23,
      "name": "Soil_Seaweed_Block"
    },
    {
      "x": -25,
      "y": 6,
      "z": -23,
      "name": "Soil_Seaweed_Block"
    },
    {
      "x": -25,
      "y": 7,
      "z": -23,
      "name": "Soil_Seaweed_Block"
    },
    {
      "x": -25,
      "y": 8,
      "z": -23,
      "name": "Soil_Seaweed_Block"
    },
    {
      "x": -25,
      "y": 9,
      "z": -23,
      "name": "Soil_Seaweed_Block"
    },
    {
      "x": -25,
      "y": 10,
      "z": -23,
      "name": "Soil_Seaweed_Block"
    },
    {
      "x": -25,
      "y": 11,
      "z": -23,
      "name": "Soil_Seaweed_Block"
    },
    {
      "x": -25,
      "y": 12,
      "z": -23,
      "name": "Soil_Seaweed_Block"
    },
    {
      "x": -25,
      "y": 13,
      "z": -23,
      "name": "Soil_Seaweed_Block"
    },
    {
      "x": -25,
      "y": 14,
      "z": -23,
      "name": "Soil_Clay_Lime"
    },
    {
      "x": -25,
      "y": 15,
      "z": -23,
      "name": "Plant_Grass_Sharp"
    },
    {
      "x": -25,
      "y": 4,
      "z": -22,
      "name": "Soil_Clay_Green"
    },
    {
      "x": -25,
      "y": 5,
      "z": -22,
      "name": "Soil_Seaweed_Block"
    },
    {
      "x": -25,
      "y": 6,
      "z": -22,
      "name": "Soil_Seaweed_Block"
    },
    {
      "x": -25,
      "y": 7,
      "z": -22,
      "name": "Soil_Seaweed_Block"
    },
    {
      "x": -25,
      "y": 8,
      "z": -22,
      "name": "Soil_Seaweed_Block"
    },
    {
      "x": -25,
      "y": 9,
      "z": -22,
      "name": "Soil_Seaweed_Block"
    },
    {
      "x": -25,
      "y": 10,
      "z": -22,
      "name": "Soil_Seaweed_Block"
    },
    {
      "x": -25,
      "y": 11,
      "z": -22,
      "name": "Soil_Seaweed_Block"
    },
    {
      "x": -25,
      "y": 12,
      "z": -22,
      "name": "Soil_Seaweed_Block"
    },
    {
      "x": -25,
      "y": 13,
      "z": -22,
      "name": "Soil_Seaweed_Block"
    },
    {
      "x": -25,
      "y": 14,
      "z": -22,
      "name": "Soil_Clay_Lime"
    },
    {
      "x": -25,
      "y": 15,
      "z": -22,
      "name": "Plant_Grass_Sharp"
    },
    {
      "x": -25,
      "y": 5,
      "z": -21,
      "name": "Soil_Clay_Green"
    },
    {
      "x": -25,
      "y": 6,
      "z": -21,
      "name": "Soil_Seaweed_Block"
    },
    {
      "x": -25,
      "y": 7,
      "z": -21,
      "name": "Soil_Seaweed_Block"
    },
    {
      "x": -25,
      "y": 8,
      "z": -21,
      "name": "Soil_Seaweed_Block"
    },
    {
      "x": -25,
      "y": 9,
      "z": -21,
      "name": "Soil_Seaweed_Block"
    },
    {
      "x": -25,
      "y": 10,
      "z": -21,
      "name": "Soil_Seaweed_Block"
    },
    {
      "x": -25,
      "y": 11,
      "z": -21,
      "name": "Soil_Seaweed_Block"
    },
    {
      "x": -25,
      "y": 12,
      "z": -21,
      "name": "Soil_Seaweed_Block"
    },
    {
      "x": -25,
      "y": 13,
      "z": -21,
      "name": "Soil_Seaweed_Block"
    },
    {
      "x": -25,
      "y": 14,
      "z": -21,
      "name": "Soil_Seaweed_Block"
    },
    {
      "x": -25,
      "y": 15,
      "z": -21,
      "name": "Soil_Clay_Lime"
    },
    {
      "x": -25,
      "y": 16,
      "z": -21,
      "name": "Plant_Grass_Sharp"
    },
    {
      "x": -25,
      "y": 6,
      "z": -20,
      "name": "Soil_Clay_Green"
    },
    {
      "x": -25,
      "y": 7,
      "z": -20,
      "name": "Soil_Seaweed_Block"
    },
    {
      "x": -25,
      "y": 8,
      "z": -20,
      "name": "Soil_Seaweed_Block"
    },
    {
      "x": -25,
      "y": 9,
      "z": -20,
      "name": "Soil_Seaweed_Block"
    },
    {
      "x": -25,
      "y": 10,
      "z": -20,
      "name": "Soil_Seaweed_Block"
    },
    {
      "x": -25,
      "y": 11,
      "z": -20,
      "name": "Soil_Seaweed_Block"
    },
    {
      "x": -25,
      "y": 12,
      "z": -20,
      "name": "Soil_Seaweed_Block"
    },
    {
      "x": -25,
      "y": 13,
      "z": -20,
      "name": "Soil_Seaweed_Block"
    },
    {
      "x": -25,
      "y": 14,
      "z": -20,
      "name": "Soil_Seaweed_Block"
    },
    {
      "x": -25,
      "y": 15,
      "z": -20,
      "name": "Soil_Clay_Lime"
    },
    {
      "x": -25,
      "y": 16,
      "z": -20,
      "name": "Plant_Grass_Sharp"
    },
    {
      "x": -25,
      "y": 6,
      "z": -19,
      "name": "Soil_Clay_Green"
    },
    {
      "x": -25,
      "y": 7,
      "z": -19,
      "name": "Soil_Clay_Green"
    },
    {
      "x": -25,
      "y": 8,
      "z": -19,
      "name": "Soil_Seaweed_Block"
    },
    {
      "x": -25,
      "y": 9,
      "z": -19,
      "name": "Soil_Seaweed_Block"
    },
    {
      "x": -25,
      "y": 10,
      "z": -19,
      "name": "Soil_Seaweed_Block"
    },
    {
      "x": -25,
      "y": 11,
      "z": -19,
      "name": "Soil_Seaweed_Block"
    },
    {
      "x": -25,
      "y": 12,
      "z": -19,
      "name": "Soil_Seaweed_Block"
    },
    {
      "x": -25,
      "y": 13,
      "z": -19,
      "name": "Soil_Seaweed_Block"
    },
    {
      "x": -25,
      "y": 14,
      "z": -19,
      "name": "Soil_Seaweed_Block"
    },
    {
      "x": -25,
      "y": 15,
      "z": -19,
      "name": "Soil_Clay_Lime"
    },
    {
      "x": -25,
      "y": 16,
      "z": -19,
      "name": "Plant_Grass_Sharp"
    },
    {
      "x": -25,
      "y": 8,
      "z": -18,
      "name": "Soil_Clay_Green"
    },
    {
      "x": -25,
      "y": 9,
      "z": -18,
      "name": "Soil_Clay_Green"
    },
    {
      "x": -25,
      "y": 10,
      "z": -18,
      "name": "Soil_Clay_Green"
    },
    {
      "x": -25,
      "y": 11,
      "z": -18,
      "name": "Soil_Clay_Green"
    },
    {
      "x": -25,
      "y": 12,
      "z": -18,
      "name": "Soil_Clay_Green"
    },
    {
      "x": -25,
      "y": 13,
      "z": -18,
      "name": "Soil_Seaweed_Block"
    },
    {
      "x": -25,
      "y": 14,
      "z": -18,
      "name": "Soil_Seaweed_Block"
    },
    {
      "x": -24,
      "y": 13,
      "z": -52,
      "name": "Soil_Clay_Green"
    },
    {
      "x": -24,
      "y": 6,
      "z": -47,
      "name": "Soil_Clay_Green"
    },
    {
      "x": -24,
      "y": 7,
      "z": -47,
      "name": "Soil_Clay_Green"
    },
    {
      "x": -24,
      "y": 6,
      "z": -46,
      "name": "Soil_Clay_Green"
    },
    {
      "x": -24,
      "y": 7,
      "z": -46,
      "name": "Soil_Clay_Green"
    },
    {
      "x": -24,
      "y": 8,
      "z": -46,
      "name": "Soil_Seaweed_Block"
    },
    {
      "x": -24,
      "y": 6,
      "z": -40,
      "name": "Soil_Clay_Green"
    },
    {
      "x": -24,
      "y": 6,
      "z": -39,
      "name": "Soil_Clay_Green"
    },
    {
      "x": -24,
      "y": 10,
      "z": -35,
      "name": "Soil_Seaweed_Block"
    },
    {
      "x": -24,
      "y": 9,
      "z": -34,
      "name": "Soil_Clay_Green"
    },
    {
      "x": -24,
      "y": 10,
      "z": -34,
      "name": "Soil_Clay_Lime"
    },
    {
      "x": -24,
      "y": 11,
      "z": -34,
      "name": "Plant_Grass_Sharp"
    },
    {
      "x": -24,
      "y": 9,
      "z": -33,
      "name": "Soil_Seaweed_Block"
    },
    {
      "x": -24,
      "y": 8,
      "z": -32,
      "name": "Soil_Seaweed_Block"
    },
    {
      "x": -24,
      "y": 9,
      "z": -32,
      "name": "Soil_Clay_Lime"
    },
    {
      "x": -24,
      "y": 10,
      "z": -32,
      "name": "Plant_Grass_Sharp"
    },
    {
      "x": -24,
      "y": 16,
      "z": -31,
      "name": "Soil_Clay_Green"
    },
    {
      "x": -24,
      "y": 17,
      "z": -31,
      "name": "Soil_Clay_Green"
    },
    {
      "x": -24,
      "y": 18,
      "z": -31,
      "name": "Soil_Seaweed_Block"
    },
    {
      "x": -24,
      "y": 19,
      "z": -31,
      "name": "Soil_Seaweed_Block"
    },
    {
      "x": -24,
      "y": 16,
      "z": -30,
      "name": "Soil_Clay_Green"
    },
    {
      "x": -24,
      "y": 17,
      "z": -30,
      "name": "Soil_Seaweed_Block"
    },
    {
      "x": -24,
      "y": 18,
      "z": -30,
      "name": "Soil_Clay_Lime"
    },
    {
      "x": -24,
      "y": 19,
      "z": -30,
      "name": "Plant_Grass_Sharp"
    },
    {
      "x": -24,
      "y": 5,
      "z": -29,
      "name": "Soil_Clay_Green"
    },
    {
      "x": -24,
      "y": 6,
      "z": -29,
      "name": "Soil_Clay_Green"
    },
    {
      "x": -24,
      "y": 7,
      "z": -29,
      "name": "Soil_Seaweed_Block"
    },
    {
      "x": -24,
      "y": 8,
      "z": -29,
      "name": "Soil_Seaweed_Block"
    },
    {
      "x": -24,
      "y": 15,
      "z": -29,
      "name": "Soil_Clay_Green"
    },
    {
      "x": -24,
      "y": 16,
      "z": -29,
      "name": "Soil_Seaweed_Block"
    },
    {
      "x": -24,
      "y": 17,
      "z": -29,
      "name": "Soil_Seaweed_Block"
    },
    {
      "x": -24,
      "y": 18,
      "z": -29,
      "name": "Soil_Clay_Lime"
    },
    {
      "x": -24,
      "y": 19,
      "z": -29,
      "name": "Plant_Grass_Sharp"
    },
    {
      "x": -24,
      "y": 5,
      "z": -28,
      "name": "Soil_Clay_Green"
    },
    {
      "x": -24,
      "y": 6,
      "z": -28,
      "name": "Soil_Seaweed_Block"
    },
    {
      "x": -24,
      "y": 7,
      "z": -28,
      "name": "Soil_Seaweed_Block"
    },
    {
      "x": -24,
      "y": 8,
      "z": -28,
      "name": "Soil_Seaweed_Block"
    },
    {
      "x": -24,
      "y": 9,
      "z": -28,
      "name": "Soil_Seaweed_Block"
    },
    {
      "x": -24,
      "y": 14,
      "z": -28,
      "name": "Soil_Clay_Green"
    },
    {
      "x": -24,
      "y": 15,
      "z": -28,
      "name": "Soil_Seaweed_Block"
    },
    {
      "x": -24,
      "y": 16,
      "z": -28,
      "name": "Soil_Seaweed_Block"
    },
    {
      "x": -24,
      "y": 17,
      "z": -28,
      "name": "Soil_Clay_Lime"
    },
    {
      "x": -24,
      "y": 18,
      "z": -28,
      "name": "Plant_Grass_Sharp"
    },
    {
      "x": -24,
      "y": 4,
      "z": -27,
      "name": "Soil_Clay_Green"
    },
    {
      "x": -24,
      "y": 5,
      "z": -27,
      "name": "Soil_Seaweed_Block"
    },
    {
      "x": -24,
      "y": 6,
      "z": -27,
      "name": "Soil_Seaweed_Block"
    },
    {
      "x": -24,
      "y": 7,
      "z": -27,
      "name": "Soil_Seaweed_Block"
    },
    {
      "x": -24,
      "y": 8,
      "z": -27,
      "name": "Soil_Seaweed_Block"
    },
    {
      "x": -24,
      "y": 9,
      "z": -27,
      "name": "Soil_Seaweed_Block"
    },
    {
      "x": -24,
      "y": 10,
      "z": -27,
      "name": "Soil_Clay_Lime"
    },
    {
      "x": -24,
      "y": 11,
      "z": -27,
      "name": "Plant_Grass_Sharp"
    },
    {
      "x": -24,
      "y": 14,
      "z": -27,
      "name": "Soil_Clay_Green"
    },
    {
      "x": -24,
      "y": 15,
      "z": -27,
      "name": "Soil_Seaweed_Block"
    },
    {
      "x": -24,
      "y": 16,
      "z": -27,
      "name": "Soil_Seaweed_Block"
    },
    {
      "x": -24,
      "y": 17,
      "z": -27,
      "name": "Soil_Clay_Lime"
    },
    {
      "x": -24,
      "y": 18,
      "z": -27,
      "name": "Plant_Grass_Sharp"
    },
    {
      "x": -24,
      "y": 3,
      "z": -26,
      "name": "Soil_Clay_Green"
    },
    {
      "x": -24,
      "y": 4,
      "z": -26,
      "name": "Soil_Seaweed_Block"
    },
    {
      "x": -24,
      "y": 5,
      "z": -26,
      "name": "Soil_Seaweed_Block"
    },
    {
      "x": -24,
      "y": 6,
      "z": -26,
      "name": "Soil_Seaweed_Block"
    },
    {
      "x": -24,
      "y": 7,
      "z": -26,
      "name": "Soil_Seaweed_Block"
    },
    {
      "x": -24,
      "y": 8,
      "z": -26,
      "name": "Soil_Seaweed_Block"
    },
    {
      "x": -24,
      "y": 9,
      "z": -26,
      "name": "Soil_Seaweed_Block"
    },
    {
      "x": -24,
      "y": 10,
      "z": -26,
      "name": "Soil_Seaweed_Block"
    },
    {
      "x": -24,
      "y": 11,
      "z": -26,
      "name": "Soil_Seaweed_Block"
    },
    {
      "x": -24,
      "y": 12,
      "z": -26,
      "name": "Soil_Seaweed_Block"
    },
    {
      "x": -24,
      "y": 13,
      "z": -26,
      "name": "Soil_Clay_Green"
    },
    {
      "x": -24,
      "y": 14,
      "z": -26,
      "name": "Soil_Clay_Green"
    },
    {
      "x": -24,
      "y": 15,
      "z": -26,
      "name": "Soil_Seaweed_Block"
    },
    {
      "x": -24,
      "y": 16,
      "z": -26,
      "name": "Soil_Clay_Lime"
    },
    {
      "x": -24,
      "y": 17,
      "z": -26,
      "name": "Plant_Grass_Sharp"
    },
    {
      "x": -24,
      "y": 2,
      "z": -25,
      "name": "Soil_Clay_Green"
    },
    {
      "x": -24,
      "y": 3,
      "z": -25,
      "name": "Soil_Clay_Green"
    },
    {
      "x": -24,
      "y": 4,
      "z": -25,
      "name": "Soil_Seaweed_Block"
    },
    {
      "x": -24,
      "y": 5,
      "z": -25,
      "name": "Soil_Seaweed_Block"
    },
    {
      "x": -24,
      "y": 6,
      "z": -25,
      "name": "Soil_Seaweed_Block"
    },
    {
      "x": -24,
      "y": 7,
      "z": -25,
      "name": "Soil_Seaweed_Block"
    },
    {
      "x": -24,
      "y": 8,
      "z": -25,
      "name": "Soil_Seaweed_Block"
    },
    {
      "x": -24,
      "y": 9,
      "z": -25,
      "name": "Soil_Seaweed_Block"
    },
    {
      "x": -24,
      "y": 10,
      "z": -25,
      "name": "Soil_Seaweed_Block"
    },
    {
      "x": -24,
      "y": 11,
      "z": -25,
      "name": "Soil_Seaweed_Block"
    },
    {
      "x": -24,
      "y": 12,
      "z": -25,
      "name": "Soil_Seaweed_Block"
    },
    {
      "x": -24,
      "y": 13,
      "z": -25,
      "name": "Soil_Seaweed_Block"
    },
    {
      "x": -24,
      "y": 14,
      "z": -25,
      "name": "Soil_Seaweed_Block"
    },
    {
      "x": -24,
      "y": 15,
      "z": -25,
      "name": "Soil_Clay_Lime"
    },
    {
      "x": -24,
      "y": 16,
      "z": -25,
      "name": "Plant_Grass_Sharp"
    },
    {
      "x": -24,
      "y": 2,
      "z": -24,
      "name": "Soil_Clay_Green"
    },
    {
      "x": -24,
      "y": 3,
      "z": -24,
      "name": "Soil_Seaweed_Block"
    },
    {
      "x": -24,
      "y": 4,
      "z": -24,
      "name": "Soil_Seaweed_Block"
    },
    {
      "x": -24,
      "y": 5,
      "z": -24,
      "name": "Soil_Seaweed_Block"
    },
    {
      "x": -24,
      "y": 6,
      "z": -24,
      "name": "Soil_Seaweed_Block"
    },
    {
      "x": -24,
      "y": 7,
      "z": -24,
      "name": "Soil_Seaweed_Block"
    },
    {
      "x": -24,
      "y": 8,
      "z": -24,
      "name": "Soil_Seaweed_Block"
    },
    {
      "x": -24,
      "y": 9,
      "z": -24,
      "name": "Soil_Seaweed_Block"
    },
    {
      "x": -24,
      "y": 10,
      "z": -24,
      "name": "Soil_Seaweed_Block"
    },
    {
      "x": -24,
      "y": 11,
      "z": -24,
      "name": "Soil_Seaweed_Block"
    },
    {
      "x": -24,
      "y": 12,
      "z": -24,
      "name": "Soil_Seaweed_Block"
    },
    {
      "x": -24,
      "y": 13,
      "z": -24,
      "name": "Soil_Seaweed_Block"
    },
    {
      "x": -24,
      "y": 14,
      "z": -24,
      "name": "Soil_Seaweed_Block"
    },
    {
      "x": -24,
      "y": 15,
      "z": -24,
      "name": "Soil_Clay_Lime"
    },
    {
      "x": -24,
      "y": 16,
      "z": -24,
      "name": "Plant_Grass_Sharp"
    },
    {
      "x": -24,
      "y": 2,
      "z": -23,
      "name": "Soil_Clay_Green"
    },
    {
      "x": -24,
      "y": 3,
      "z": -23,
      "name": "Soil_Seaweed_Block"
    },
    {
      "x": -24,
      "y": 4,
      "z": -23,
      "name": "Soil_Seaweed_Block"
    },
    {
      "x": -24,
      "y": 5,
      "z": -23,
      "name": "Soil_Seaweed_Block"
    },
    {
      "x": -24,
      "y": 6,
      "z": -23,
      "name": "Soil_Seaweed_Block"
    },
    {
      "x": -24,
      "y": 7,
      "z": -23,
      "name": "Soil_Seaweed_Block"
    },
    {
      "x": -24,
      "y": 8,
      "z": -23,
      "name": "Soil_Seaweed_Block"
    },
    {
      "x": -24,
      "y": 9,
      "z": -23,
      "name": "Soil_Seaweed_Block"
    },
    {
      "x": -24,
      "y": 10,
      "z": -23,
      "name": "Soil_Seaweed_Block"
    },
    {
      "x": -24,
      "y": 11,
      "z": -23,
      "name": "Soil_Seaweed_Block"
    },
    {
      "x": -24,
      "y": 12,
      "z": -23,
      "name": "Soil_Seaweed_Block"
    },
    {
      "x": -24,
      "y": 13,
      "z": -23,
      "name": "Soil_Seaweed_Block"
    },
    {
      "x": -24,
      "y": 14,
      "z": -23,
      "name": "Soil_Seaweed_Block"
    },
    {
      "x": -24,
      "y": 15,
      "z": -23,
      "name": "Soil_Clay_Lime"
    },
    {
      "x": -24,
      "y": 16,
      "z": -23,
      "name": "Plant_Grass_Sharp"
    },
    {
      "x": -24,
      "y": 2,
      "z": -22,
      "name": "Soil_Clay_Green"
    },
    {
      "x": -24,
      "y": 3,
      "z": -22,
      "name": "Soil_Clay_Green"
    },
    {
      "x": -24,
      "y": 4,
      "z": -22,
      "name": "Soil_Seaweed_Block"
    },
    {
      "x": -24,
      "y": 5,
      "z": -22,
      "name": "Soil_Seaweed_Block"
    },
    {
      "x": -24,
      "y": 6,
      "z": -22,
      "name": "Soil_Seaweed_Block"
    },
    {
      "x": -24,
      "y": 7,
      "z": -22,
      "name": "Soil_Seaweed_Block"
    },
    {
      "x": -24,
      "y": 8,
      "z": -22,
      "name": "Soil_Seaweed_Block"
    },
    {
      "x": -24,
      "y": 9,
      "z": -22,
      "name": "Soil_Seaweed_Block"
    },
    {
      "x": -24,
      "y": 10,
      "z": -22,
      "name": "Soil_Seaweed_Block"
    },
    {
      "x": -24,
      "y": 11,
      "z": -22,
      "name": "Soil_Seaweed_Block"
    },
    {
      "x": -24,
      "y": 12,
      "z": -22,
      "name": "Soil_Seaweed_Block"
    },
    {
      "x": -24,
      "y": 13,
      "z": -22,
      "name": "Soil_Seaweed_Block"
    },
    {
      "x": -24,
      "y": 14,
      "z": -22,
      "name": "Soil_Seaweed_Block"
    },
    {
      "x": -24,
      "y": 15,
      "z": -22,
      "name": "Soil_Clay_Lime"
    },
    {
      "x": -24,
      "y": 16,
      "z": -22,
      "name": "Plant_Grass_Sharp"
    },
    {
      "x": -24,
      "y": 2,
      "z": -21,
      "name": "Soil_Clay_Green"
    },
    {
      "x": -24,
      "y": 3,
      "z": -21,
      "name": "Soil_Clay_Green"
    },
    {
      "x": -24,
      "y": 4,
      "z": -21,
      "name": "Soil_Clay_Green"
    },
    {
      "x": -24,
      "y": 5,
      "z": -21,
      "name": "Soil_Seaweed_Block"
    },
    {
      "x": -24,
      "y": 6,
      "z": -21,
      "name": "Soil_Seaweed_Block"
    },
    {
      "x": -24,
      "y": 7,
      "z": -21,
      "name": "Soil_Seaweed_Block"
    },
    {
      "x": -24,
      "y": 8,
      "z": -21,
      "name": "Soil_Seaweed_Block"
    },
    {
      "x": -24,
      "y": 9,
      "z": -21,
      "name": "Soil_Seaweed_Block"
    },
    {
      "x": -24,
      "y": 10,
      "z": -21,
      "name": "Soil_Seaweed_Block"
    },
    {
      "x": -24,
      "y": 11,
      "z": -21,
      "name": "Soil_Seaweed_Block"
    },
    {
      "x": -24,
      "y": 12,
      "z": -21,
      "name": "Soil_Seaweed_Block"
    },
    {
      "x": -24,
      "y": 13,
      "z": -21,
      "name": "Soil_Seaweed_Block"
    },
    {
      "x": -24,
      "y": 14,
      "z": -21,
      "name": "Soil_Seaweed_Block"
    },
    {
      "x": -24,
      "y": 15,
      "z": -21,
      "name": "Soil_Clay_Lime"
    },
    {
      "x": -24,
      "y": 16,
      "z": -21,
      "name": "Plant_Grass_Sharp"
    },
    {
      "x": -24,
      "y": 4,
      "z": -20,
      "name": "Soil_Clay_Green"
    },
    {
      "x": -24,
      "y": 5,
      "z": -20,
      "name": "Soil_Clay_Green"
    },
    {
      "x": -24,
      "y": 6,
      "z": -20,
      "name": "Soil_Seaweed_Block"
    },
    {
      "x": -24,
      "y": 7,
      "z": -20,
      "name": "Soil_Seaweed_Block"
    },
    {
      "x": -24,
