{
  "version": 8,
  "blockIdVersion": 10,
  "anchorX": 0,
  "anchorY": 2,
  "anchorZ": 0,
  "blocks": [
    {
      "x": -8,
      "y": 4,
      "z": -2,
      "name": "Rock_Stone_Mossy"
    },
    {
      "x": -8,
      "y": 5,
      "z": -2,
      "name": "Rock_Stone_Mossy"
    },
    {
      "x": -8,
      "y": 6,
      "z": -2,
      "name": "Rock_Stone_Mossy"
    },
    {
      "x": -8,
      "y": 7,
      "z": -2,
      "name": "Soil_Clay_Lime"
    },
    {
      "x": -8,
      "y": 8,
      "z": -2,
      "name": "Soil_Clay_Lime"
    },
    {
      "x": -8,
      "y": 9,
      "z": -2,
      "name": "Soil_Clay_Lime"
    },
    {
      "x": -8,
      "y": 10,
      "z": -2,
      "name": "Soil_Clay_Lime"
    },
    {
      "x": -8,
      "y": 14,
      "z": -2,
      "name": "Plant_Moss_Block_Yellow"
    },
    {
      "x": -8,
      "y": 15,
      "z": -2,
      "name": "Plant_Moss_Block_Yellow"
    },
    {
      "x": -8,
      "y": 2,
      "z": -1,
      "name": "Plant_Moss_Block_Yellow"
    },
    {
      "x": -8,
      "y": 3,
      "z": -1,
      "name": "Soil_Clay_Lime"
    },
    {
      "x": -8,
      "y": 4,
      "z": -1,
      "name": "Rock_Stone_Mossy"
    },
    {
      "x": -8,
      "y": 5,
      "z": -1,
      "name": "Rock_Stone_Mossy"
    },
    {
      "x": -8,
      "y": 6,
      "z": -1,
      "name": "Soil_Clay_Lime"
    },
    {
      "x": -8,
      "y": 7,
      "z": -1,
      "name": "Plant_Moss_Block_Yellow"
    },
    {
      "x": -8,
      "y": 8,
      "z": -1,
      "name": "Plant_Moss_Block_Yellow"
    },
    {
      "x": -8,
      "y": 9,
      "z": -1,
      "name": "Plant_Moss_Block_Yellow"
    },
    {
      "x": -8,
      "y": 10,
      "z": -1,
      "name": "Soil_Clay_Lime"
    },
    {
      "x": -8,
      "y": 11,
      "z": -1,
      "name": "Soil_Clay_Lime"
    },
    {
      "x": -8,
      "y": 14,
      "z": -1,
      "name": "Plant_Moss_Block_Yellow"
    },
    {
      "x": -8,
      "y": 15,
      "z": -1,
      "name": "Plant_Moss_Block_Yellow"
    },
    {
      "x": -8,
      "y": 2,
      "z": 0,
      "name": "Plant_Moss_Block_Yellow"
    },
    {
      "x": -8,
      "y": 3,
      "z": 0,
      "name": "Soil_Clay_Lime"
    },
    {
      "x": -8,
      "y": 4,
      "z": 0,
      "name": "Soil_Clay_Lime"
    },
    {
      "x": -8,
      "y": 5,
      "z": 0,
      "name": "Soil_Clay_Lime"
    },
    {
      "x": -8,
      "y": 6,
      "z": 0,
      "name": "Plant_Moss_Block_Yellow"
    },
    {
      "x": -8,
      "y": 7,
      "z": 0,
      "name": "Plant_Moss_Block_Yellow"
    },
    {
      "x": -8,
      "y": 8,
      "z": 0,
      "name": "Plant_Moss_Block_Yellow"
    },
    {
      "x": -8,
      "y": 9,
      "z": 0,
      "name": "Plant_Moss_Block_Yellow"
    },
    {
      "x": -8,
      "y": 10,
      "z": 0,
      "name": "Soil_Clay_Lime"
    },
    {
      "x": -8,
      "y": 14,
      "z": 0,
      "name": "Plant_Moss_Block_Yellow"
    },
    {
      "x": -8,
      "y": 15,
      "z": 0,
      "name": "Plant_Moss_Block_Yellow"
    },
    {
      "x": -8,
      "y": 2,
      "z": 1,
      "name": "Plant_Moss_Block_Yellow"
    },
    {
      "x": -8,
      "y": 3,
      "z": 1,
      "name": "Soil_Clay_Lime"
    },
    {
      "x": -8,
      "y": 4,
      "z": 1,
      "name": "Soil_Clay_Lime"
    },
    {
      "x": -8,
      "y": 5,
      "z": 1,
      "name": "Soil_Clay_Lime"
    },
    {
      "x": -8,
      "y": 6,
      "z": 1,
      "name": "Plant_Moss_Block_Yellow"
    },
    {
      "x": -8,
      "y": 7,
      "z": 1,
      "name": "Plant_Moss_Block_Yellow"
    },
    {
      "x": -8,
      "y": 8,
      "z": 1,
      "name": "Plant_Moss_Block_Yellow"
    },
    {
      "x": -8,
      "y": 9,
      "z": 1,
      "name": "Plant_Moss_Block_Yellow"
    },
    {
      "x": -8,
      "y": 10,
      "z": 1,
      "name": "Soil_Clay_Lime"
    },
    {
      "x": -8,
      "y": 14,
      "z": 1,
      "name": "Plant_Moss_Block_Yellow"
    },
    {
      "x": -8,
      "y": 15,
      "z": 1,
      "name": "Plant_Moss_Block_Yellow"
    },
    {
      "x": -8,
      "y": 3,
      "z": 2,
      "name": "Soil_Clay_Lime"
    },
    {
      "x": -8,
      "y": 4,
      "z": 2,
      "name": "Soil_Clay_Lime"
    },
    {
      "x": -8,
      "y": 5,
      "z": 2,
      "name": "Soil_Clay_Lime"
    },
    {
      "x": -8,
      "y": 6,
      "z": 2,
      "name": "Plant_Moss_Block_Yellow"
    },
    {
      "x": -8,
      "y": 7,
      "z": 2,
      "name": "Plant_Moss_Block_Yellow"
    },
    {
      "x": -8,
      "y": 8,
      "z": 2,
      "name": "Plant_Moss_Block_Yellow"
    },
    {
      "x": -8,
      "y": 9,
      "z": 2,
      "name": "Soil_Clay_Lime"
    },
    {
      "x": -8,
      "y": 10,
      "z": 2,
      "name": "Soil_Clay_Lime"
    },
    {
      "x": -7,
      "y": 4,
      "z": -4,
      "name": "Soil_Clay_Lime"
    },
    {
      "x": -7,
      "y": 5,
      "z": -4,
      "name": "Rock_Stone_Mossy"
    },
    {
      "x": -7,
      "y": 6,
      "z": -4,
      "name": "Rock_Stone_Mossy"
    },
    {
      "x": -7,
      "y": 7,
      "z": -4,
      "name": "Rock_Stone_Mossy"
    },
    {
      "x": -7,
      "y": 8,
      "z": -4,
      "name": "Soil_Clay_Lime"
    },
    {
      "x": -7,
      "y": 9,
      "z": -4,
      "name": "Soil_Clay_Lime"
    },
    {
      "x": -7,
      "y": 2,
      "z": -3,
      "name": "Soil_Clay_Lime"
    },
    {
      "x": -7,
      "y": 3,
      "z": -3,
      "name": "Soil_Clay_Lime"
    },
    {
      "x": -7,
      "y": 4,
      "z": -3,
      "name": "Rock_Stone_Mossy"
    },
    {
      "x": -7,
      "y": 5,
      "z": -3,
      "name": "Rock_Stone_Mossy"
    },
    {
      "x": -7,
      "y": 6,
      "z": -3,
      "name": "Rock_Stone_Mossy"
    },
    {
      "x": -7,
      "y": 7,
      "z": -3,
      "name": "Soil_Clay_Lime"
    },
    {
      "x": -7,
      "y": 8,
      "z": -3,
      "name": "Soil_Clay_Lime"
    },
    {
      "x": -7,
      "y": 9,
      "z": -3,
      "name": "Soil_Clay_Lime"
    },
    {
      "x": -7,
      "y": 10,
      "z": -3,
      "name": "Soil_Clay_Lime"
    },
    {
      "x": -7,
      "y": 13,
      "z": -3,
      "name": "Soil_Clay_Lime"
    },
    {
      "x": -7,
      "y": 14,
      "z": -3,
      "name": "Soil_Clay_Lime"
    },
    {
      "x": -7,
      "y": 15,
      "z": -3,
      "name": "Plant_Moss_Block_Yellow"
    },
    {
      "x": -7,
      "y": 2,
      "z": -2,
      "name": "Soil_Clay_Lime"
    },
    {
      "x": -7,
      "y": 3,
      "z": -2,
      "name": "Soil_Clay_Lime"
    },
    {
      "x": -7,
      "y": 4,
      "z": -2,
      "name": "Soil_Sand"
    },
    {
      "x": -7,
      "y": 5,
      "z": -2,
      "name": "Soil_Sand"
    },
    {
      "x": -7,
      "y": 6,
      "z": -2,
      "name": "Soil_Sand"
    },
    {
      "x": -7,
      "y": 7,
      "z": -2,
      "name": "Soil_Sand"
    },
    {
      "x": -7,
      "y": 8,
      "z": -2,
      "name": "Soil_Sand"
    },
    {
      "x": -7,
      "y": 9,
      "z": -2,
      "name": "Soil_Sand"
    },
    {
      "x": -7,
      "y": 10,
      "z": -2,
      "name": "Soil_Clay_Lime"
    },
    {
      "x": -7,
      "y": 13,
      "z": -2,
      "name": "Soil_Clay_Lime"
    },
    {
      "x": -7,
      "y": 14,
      "z": -2,
      "name": "Soil_Sand"
    },
    {
      "x": -7,
      "y": 15,
      "z": -2,
      "name": "Soil_Sand"
    },
    {
      "x": -7,
      "y": 16,
      "z": -2,
      "name": "Plant_Flower_Bushy_Yellow"
    },
    {
      "x": -7,
      "y": 1,
      "z": -1,
      "name": "Soil_Clay_Lime"
    },
    {
      "x": -7,
      "y": 2,
      "z": -1,
      "name": "Soil_Sand"
    },
    {
      "x": -7,
      "y": 3,
      "z": -1,
      "name": "Soil_Sand"
    },
    {
      "x": -7,
      "y": 4,
      "z": -1,
      "name": "Soil_Sand"
    },
    {
      "x": -7,
      "y": 5,
      "z": -1,
      "name": "Soil_Sand"
    },
    {
      "x": -7,
      "y": 6,
      "z": -1,
      "name": "Soil_Sand"
    },
    {
      "x": -7,
      "y": 7,
      "z": -1,
      "name": "Soil_Sand"
    },
    {
      "x": -7,
      "y": 8,
      "z": -1,
      "name": "Soil_Sand"
    },
    {
      "x": -7,
      "y": 9,
      "z": -1,
      "name": "Soil_Sand"
    },
    {
      "x": -7,
      "y": 10,
      "z": -1,
      "name": "Soil_Sand"
    },
    {
      "x": -7,
      "y": 11,
      "z": -1,
      "name": "Soil_Clay_Lime"
    },
    {
      "x": -7,
      "y": 13,
      "z": -1,
      "name": "Plant_Moss_Block_Yellow"
    },
    {
      "x": -7,
      "y": 14,
      "z": -1,
      "name": "Soil_Sand"
    },
    {
      "x": -7,
      "y": 15,
      "z": -1,
      "name": "Soil_Sand"
    },
    {
      "x": -7,
      "y": 16,
      "z": -1,
      "name": "Plant_Flower_Bushy_Yellow"
    },
    {
      "x": -7,
      "y": 1,
      "z": 0,
      "name": "Plant_Moss_Block_Yellow"
    },
    {
      "x": -7,
      "y": 2,
      "z": 0,
      "name": "Soil_Sand"
    },
    {
      "x": -7,
      "y": 3,
      "z": 0,
      "name": "Soil_Sand"
    },
    {
      "x": -7,
      "y": 4,
      "z": 0,
      "name": "Soil_Sand"
    },
    {
      "x": -7,
      "y": 5,
      "z": 0,
      "name": "Soil_Sand"
    },
    {
      "x": -7,
      "y": 6,
      "z": 0,
      "name": "Soil_Sand"
    },
    {
      "x": -7,
      "y": 7,
      "z": 0,
      "name": "Soil_Sand"
    },
    {
      "x": -7,
      "y": 8,
      "z": 0,
      "name": "Soil_Sand"
    },
    {
      "x": -7,
      "y": 9,
      "z": 0,
      "name": "Soil_Sand"
    },
    {
      "x": -7,
      "y": 10,
      "z": 0,
      "name": "Plant_Moss_Block_Yellow"
    },
    {
      "x": -7,
      "y": 13,
      "z": 0,
      "name": "Plant_Moss_Block_Yellow"
    },
    {
      "x": -7,
      "y": 14,
      "z": 0,
      "name": "Soil_Sand"
    },
    {
      "x": -7,
      "y": 15,
      "z": 0,
      "name": "Soil_Sand"
    },
    {
      "x": -7,
      "y": 16,
      "z": 0,
      "name": "Plant_Flower_Bushy_Yellow"
    },
    {
      "x": -7,
      "y": 2,
      "z": 1,
      "name": "Plant_Moss_Block_Yellow"
    },
    {
      "x": -7,
      "y": 3,
      "z": 1,
      "name": "Soil_Sand"
    },
    {
      "x": -7,
      "y": 4,
      "z": 1,
      "name": "Soil_Sand"
    },
    {
      "x": -7,
      "y": 5,
      "z": 1,
      "name": "Soil_Sand"
    },
    {
      "x": -7,
      "y": 6,
      "z": 1,
      "name": "Soil_Sand"
    },
    {
      "x": -7,
      "y": 7,
      "z": 1,
      "name": "Soil_Sand"
    },
    {
      "x": -7,
      "y": 8,
      "z": 1,
      "name": "Soil_Sand"
    },
    {
      "x": -7,
      "y": 9,
      "z": 1,
      "name": "Soil_Sand"
    },
    {
      "x": -7,
      "y": 10,
      "z": 1,
      "name": "Plant_Moss_Block_Yellow"
    },
    {
      "x": -7,
      "y": 13,
      "z": 1,
      "name": "Plant_Moss_Block_Yellow"
    },
    {
      "x": -7,
      "y": 14,
      "z": 1,
      "name": "Soil_Sand"
    },
    {
      "x": -7,
      "y": 15,
      "z": 1,
      "name": "Soil_Sand"
    },
    {
      "x": -7,
      "y": 16,
      "z": 1,
      "name": "Plant_Leaves_Palm_Arid"
    },
    {
      "x": -7,
      "y": 2,
      "z": 2,
      "name": "Plant_Moss_Block_Yellow"
    },
    {
      "x": -7,
      "y": 3,
      "z": 2,
      "name": "Soil_Sand"
    },
    {
      "x": -7,
      "y": 4,
      "z": 2,
      "name": "Soil_Sand"
    },
    {
      "x": -7,
      "y": 5,
      "z": 2,
      "name": "Soil_Sand"
    },
    {
      "x": -7,
      "y": 6,
      "z": 2,
      "name": "Soil_Sand"
    },
    {
      "x": -7,
      "y": 7,
      "z": 2,
      "name": "Soil_Sand"
    },
    {
      "x": -7,
      "y": 8,
      "z": 2,
      "name": "Soil_Sand"
    },
    {
      "x": -7,
      "y": 9,
      "z": 2,
      "name": "Soil_Sand"
    },
    {
      "x": -7,
      "y": 10,
      "z": 2,
      "name": "Soil_Sand"
    },
    {
      "x": -7,
      "y": 11,
      "z": 2,
      "name": "Plant_Moss_Block_Yellow"
    },
    {
      "x": -7,
      "y": 13,
      "z": 2,
      "name": "Plant_Moss_Block_Yellow"
    },
    {
      "x": -7,
      "y": 14,
      "z": 2,
      "name": "Plant_Moss_Block_Yellow"
    },
    {
      "x": -7,
      "y": 15,
      "z": 2,
      "name": "Plant_Moss_Block_Yellow"
    },
    {
      "x": -7,
      "y": 2,
      "z": 3,
      "name": "Plant_Moss_Block_Yellow"
    },
    {
      "x": -7,
      "y": 3,
      "z": 3,
      "name": "Plant_Moss_Block_Yellow"
    },
    {
      "x": -7,
      "y": 4,
      "z": 3,
      "name": "Soil_Clay_Lime"
    },
    {
      "x": -7,
      "y": 5,
      "z": 3,
      "name": "Soil_Clay_Lime"
    },
    {
      "x": -7,
      "y": 6,
      "z": 3,
      "name": "Soil_Clay_Lime"
    },
    {
      "x": -7,
      "y": 7,
      "z": 3,
      "name": "Soil_Clay_Lime"
    },
    {
      "x": -7,
      "y": 8,
      "z": 3,
      "name": "Rock_Stone_Mossy"
    },
    {
      "x": -7,
      "y": 9,
      "z": 3,
      "name": "Soil_Clay_Lime"
    },
    {
      "x": -7,
      "y": 10,
      "z": 3,
      "name": "Soil_Clay_Lime"
    },
    {
      "x": -7,
      "y": 11,
      "z": 3,
      "name": "Soil_Clay_Lime"
    },
    {
      "x": -7,
      "y": 3,
      "z": 4,
      "name": "Plant_Moss_Block_Yellow"
    },
    {
      "x": -7,
      "y": 4,
      "z": 4,
      "name": "Plant_Moss_Block_Yellow"
    },
    {
      "x": -7,
      "y": 5,
      "z": 4,
      "name": "Soil_Clay_Lime"
    },
    {
      "x": -7,
      "y": 6,
      "z": 4,
      "name": "Soil_Clay_Lime"
    },
    {
      "x": -7,
      "y": 7,
      "z": 4,
      "name": "Soil_Clay_Lime"
    },
    {
      "x": -7,
      "y": 8,
      "z": 4,
      "name": "Rock_Stone_Mossy"
    },
    {
      "x": -7,
      "y": 9,
      "z": 4,
      "name": "Rock_Stone_Mossy"
    },
    {
      "x": -7,
      "y": 10,
      "z": 4,
      "name": "Soil_Clay_Lime"
    },
    {
      "x": -6,
      "y": 3,
      "z": -5,
      "name": "Soil_Clay_Lime"
    },
    {
      "x": -6,
      "y": 4,
      "z": -5,
      "name": "Soil_Clay_Lime"
    },
    {
      "x": -6,
      "y": 5,
      "z": -5,
      "name": "Soil_Clay_Lime"
    },
    {
      "x": -6,
      "y": 6,
      "z": -5,
      "name": "Soil_Clay_Lime"
    },
    {
      "x": -6,
      "y": 7,
      "z": -5,
      "name": "Soil_Clay_Lime"
    },
    {
      "x": -6,
      "y": 8,
      "z": -5,
      "name": "Soil_Clay_Lime"
    },
    {
      "x": -6,
      "y": 9,
      "z": -5,
      "name": "Soil_Clay_Lime"
    },
    {
      "x": -6,
      "y": 10,
      "z": -5,
      "name": "Soil_Clay_Lime"
    },
    {
      "x": -6,
      "y": 2,
      "z": -4,
      "name": "Soil_Clay_Lime"
    },
    {
      "x": -6,
      "y": 3,
      "z": -4,
      "name": "Soil_Clay_Lime"
    },
    {
      "x": -6,
      "y": 4,
      "z": -4,
      "name": "Soil_Sand"
    },
    {
      "x": -6,
      "y": 5,
      "z": -4,
      "name": "Soil_Sand"
    },
    {
      "x": -6,
      "y": 6,
      "z": -4,
      "name": "Soil_Sand"
    },
    {
      "x": -6,
      "y": 7,
      "z": -4,
      "name": "Soil_Sand"
    },
    {
      "x": -6,
      "y": 8,
      "z": -4,
      "name": "Soil_Sand"
    },
    {
      "x": -6,
      "y": 9,
      "z": -4,
      "name": "Soil_Sand"
    },
    {
      "x": -6,
      "y": 10,
      "z": -4,
      "name": "Soil_Clay_Lime"
    },
    {
      "x": -6,
      "y": 13,
      "z": -4,
      "name": "Rock_Stone_Mossy"
    },
    {
      "x": -6,
      "y": 14,
      "z": -4,
      "name": "Soil_Clay_Lime"
    },
    {
      "x": -6,
      "y": 15,
      "z": -4,
      "name": "Plant_Moss_Block_Yellow"
    },
    {
      "x": -6,
      "y": 2,
      "z": -3,
      "name": "Soil_Clay_Lime"
    },
    {
      "x": -6,
      "y": 3,
      "z": -3,
      "name": "Soil_Sand"
    },
    {
      "x": -6,
      "y": 4,
      "z": -3,
      "name": "Soil_Sand"
    },
    {
      "x": -6,
      "y": 5,
      "z": -3,
      "name": "Soil_Sand"
    },
    {
      "x": -6,
      "y": 6,
      "z": -3,
      "name": "Soil_Sand"
    },
    {
      "x": -6,
      "y": 7,
      "z": -3,
      "name": "Soil_Sand"
    },
    {
      "x": -6,
      "y": 8,
      "z": -3,
      "name": "Soil_Sand"
    },
    {
      "x": -6,
      "y": 9,
      "z": -3,
      "name": "Soil_Sand"
    },
    {
      "x": -6,
      "y": 10,
      "z": -3,
      "name": "Soil_Clay_Lime"
    },
    {
      "x": -6,
      "y": 12,
      "z": -3,
      "name": "Rock_Stone_Mossy"
    },
    {
      "x": -6,
      "y": 13,
      "z": -3,
      "name": "Soil_Sand"
    },
    {
      "x": -6,
      "y": 14,
      "z": -3,
      "name": "Soil_Sand"
    },
    {
      "x": -6,
      "y": 15,
      "z": -3,
      "name": "Soil_Sand"
    },
    {
      "x": -6,
      "y": 16,
      "z": -3,
      "name": "Plant_Flower_Bushy_Yellow"
    },
    {
      "x": -6,
      "y": 1,
      "z": -2,
      "name": "Soil_Clay_Lime"
    },
    {
      "x": -6,
      "y": 2,
      "z": -2,
      "name": "Soil_Sand"
    },
    {
      "x": -6,
      "y": 3,
      "z": -2,
      "name": "Soil_Sand"
    },
    {
      "x": -6,
      "y": 4,
      "z": -2,
      "name": "Soil_Sand"
    },
    {
      "x": -6,
      "y": 5,
      "z": -2,
      "name": "Soil_Sand"
    },
    {
      "x": -6,
      "y": 6,
      "z": -2,
      "name": "Soil_Sand"
    },
    {
      "x": -6,
      "y": 7,
      "z": -2,
      "name": "Soil_Sand"
    },
    {
      "x": -6,
      "y": 8,
      "z": -2,
      "name": "Soil_Sand"
    },
    {
      "x": -6,
      "y": 9,
      "z": -2,
      "name": "Soil_Sand"
    },
    {
      "x": -6,
      "y": 10,
      "z": -2,
      "name": "Soil_Sand"
    },
    {
      "x": -6,
      "y": 11,
      "z": -2,
      "name": "Soil_Clay_Lime"
    },
    {
      "x": -6,
      "y": 12,
      "z": -2,
      "name": "Rock_Stone_Mossy"
    },
    {
      "x": -6,
      "y": 13,
      "z": -2,
      "name": "Soil_Sand"
    },
    {
      "x": -6,
      "y": 14,
      "z": -2,
      "name": "Soil_Sand"
    },
    {
      "x": -6,
      "y": 15,
      "z": -2,
      "name": "Soil_Sand"
    },
    {
      "x": -6,
      "y": 16,
      "z": -2,
      "name": "Plant_Flower_Bushy_Yellow"
    },
    {
      "x": -6,
      "y": 1,
      "z": -1,
      "name": "Soil_Clay_Lime"
    },
    {
      "x": -6,
      "y": 2,
      "z": -1,
      "name": "Soil_Sand"
    },
    {
      "x": -6,
      "y": 3,
      "z": -1,
      "name": "Soil_Sand"
    },
    {
      "x": -6,
      "y": 4,
      "z": -1,
      "name": "Soil_Sand"
    },
    {
      "x": -6,
      "y": 5,
      "z": -1,
      "name": "Soil_Sand"
    },
    {
      "x": -6,
      "y": 6,
      "z": -1,
      "name": "Soil_Sand"
    },
    {
      "x": -6,
      "y": 7,
      "z": -1,
      "name": "Soil_Sand"
    },
    {
      "x": -6,
      "y": 8,
      "z": -1,
      "name": "Soil_Sand"
    },
    {
      "x": -6,
      "y": 9,
      "z": -1,
      "name": "Soil_Sand"
    },
    {
      "x": -6,
      "y": 10,
      "z": -1,
      "name": "Soil_Sand"
    },
    {
      "x": -6,
      "y": 11,
      "z": -1,
      "name": "Soil_Sand"
    },
    {
      "x": -6,
      "y": 12,
      "z": -1,
      "name": "Soil_Clay_Lime"
    },
    {
      "x": -6,
      "y": 13,
      "z": -1,
      "name": "Soil_Sand"
    },
    {
      "x": -6,
      "y": 14,
      "z": -1,
      "name": "Soil_Sand"
    },
    {
      "x": -6,
      "y": 15,
      "z": -1,
      "name": "Soil_Sand"
    },
    {
      "x": -6,
      "y": 16,
      "z": -1,
      "name": "Soil_Sand"
    },
    {
      "x": -6,
      "y": 17,
      "z": -1,
      "name": "Plant_Flower_Bushy_Yellow"
    },
    {
      "x": -6,
      "y": 1,
      "z": 0,
      "name": "Soil_Clay_Lime"
    },
    {
      "x": -6,
      "y": 2,
      "z": 0,
      "name": "Soil_Sand"
    },
    {
      "x": -6,
      "y": 3,
      "z": 0,
      "name": "Soil_Sand"
    },
    {
      "x": -6,
      "y": 4,
      "z": 0,
      "name": "Soil_Sand"
    },
    {
      "x": -6,
      "y": 5,
      "z": 0,
      "name": "Soil_Sand"
    },
    {
      "x": -6,
      "y": 6,
      "z": 0,
      "name": "Soil_Sand"
    },
    {
      "x": -6,
      "y": 7,
      "z": 0,
      "name": "Soil_Sand"
    },
    {
      "x": -6,
      "y": 8,
      "z": 0,
      "name": "Soil_Sand"
    },
    {
      "x": -6,
      "y": 9,
      "z": 0,
      "name": "Soil_Sand"
    },
    {
      "x": -6,
      "y": 10,
      "z": 0,
      "name": "Soil_Sand"
    },
    {
      "x": -6,
      "y": 11,
      "z": 0,
      "name": "Plant_Moss_Block_Yellow"
    },
    {
      "x": -6,
      "y": 12,
      "z": 0,
      "name": "Plant_Moss_Block_Yellow"
    },
    {
      "x": -6,
      "y": 13,
      "z": 0,
      "name": "Soil_Sand"
    },
    {
      "x": -6,
      "y": 14,
      "z": 0,
      "name": "Soil_Sand"
    },
    {
      "x": -6,
      "y": 15,
      "z": 0,
      "name": "Soil_Sand"
    },
    {
      "x": -6,
      "y": 16,
      "z": 0,
      "name": "Soil_Sand"
    },
    {
      "x": -6,
      "y": 17,
      "z": 0,
      "name": "Plant_Flower_Bushy_Yellow"
    },
    {
      "x": -6,
      "y": 1,
      "z": 1,
      "name": "Soil_Clay_Lime"
    },
    {
      "x": -6,
      "y": 2,
      "z": 1,
      "name": "Soil_Sand"
    },
    {
      "x": -6,
      "y": 3,
      "z": 1,
      "name": "Soil_Sand"
    },
    {
      "x": -6,
      "y": 4,
      "z": 1,
      "name": "Soil_Sand"
    },
    {
      "x": -6,
      "y": 5,
      "z": 1,
      "name": "Soil_Sand"
    },
    {
      "x": -6,
      "y": 6,
      "z": 1,
      "name": "Soil_Sand"
    },
    {
      "x": -6,
      "y": 7,
      "z": 1,
      "name": "Soil_Sand"
    },
    {
      "x": -6,
      "y": 8,
      "z": 1,
      "name": "Soil_Sand"
    },
    {
      "x": -6,
      "y": 9,
      "z": 1,
      "name": "Soil_Sand"
    },
    {
      "x": -6,
      "y": 10,
      "z": 1,
      "name": "Soil_Sand"
    },
    {
      "x": -6,
      "y": 11,
      "z": 1,
      "name": "Plant_Moss_Block_Yellow"
    },
    {
      "x": -6,
      "y": 12,
      "z": 1,
      "name": "Plant_Moss_Block_Yellow"
    },
    {
      "x": -6,
      "y": 13,
      "z": 1,
      "name": "Soil_Sand"
    },
    {
      "x": -6,
      "y": 14,
      "z": 1,
      "name": "Soil_Sand"
    },
    {
      "x": -6,
      "y": 15,
      "z": 1,
      "name": "Soil_Sand"
    },
    {
      "x": -6,
      "y": 16,
      "z": 1,
      "name": "Plant_Leaves_Palm_Arid"
    },
    {
      "x": -6,
      "y": 1,
      "z": 2,
      "name": "Soil_Clay_Lime"
    },
    {
      "x": -6,
      "y": 2,
      "z": 2,
      "name": "Soil_Sand"
    },
    {
      "x": -6,
      "y": 3,
      "z": 2,
      "name": "Soil_Sand"
    },
    {
      "x": -6,
      "y": 4,
      "z": 2,
      "name": "Soil_Sand"
    },
    {
      "x": -6,
      "y": 5,
      "z": 2,
      "name": "Soil_Sand"
    },
    {
      "x": -6,
      "y": 6,
      "z": 2,
      "name": "Soil_Sand"
    },
    {
      "x": -6,
      "y": 7,
      "z": 2,
      "name": "Soil_Sand"
    },
    {
      "x": -6,
      "y": 8,
      "z": 2,
      "name": "Soil_Sand"
    },
    {
      "x": -6,
      "y": 9,
      "z": 2,
      "name": "Soil_Sand"
    },
    {
      "x": -6,
      "y": 10,
      "z": 2,
      "name": "Soil_Sand"
    },
    {
      "x": -6,
      "y": 11,
      "z": 2,
      "name": "Soil_Sand"
    },
    {
      "x": -6,
      "y": 12,
      "z": 2,
      "name": "Plant_Moss_Block_Yellow"
    },
    {
      "x": -6,
      "y": 13,
      "z": 2,
      "name": "Soil_Sand"
    },
    {
      "x": -6,
      "y": 14,
      "z": 2,
      "name": "Soil_Sand"
    },
    {
      "x": -6,
      "y": 15,
      "z": 2,
      "name": "Soil_Sand"
    },
    {
      "x": -6,
      "y": 16,
      "z": 2,
      "name": "Plant_Leaves_Palm_Arid"
    },
    {
      "x": -6,
      "y": 1,
      "z": 3,
      "name": "Plant_Moss_Block_Yellow"
    },
    {
      "x": -6,
      "y": 2,
      "z": 3,
      "name": "Soil_Sand"
    },
    {
      "x": -6,
      "y": 3,
      "z": 3,
      "name": "Soil_Sand"
    },
    {
      "x": -6,
      "y": 4,
      "z": 3,
      "name": "Soil_Sand"
    },
    {
      "x": -6,
      "y": 5,
      "z": 3,
      "name": "Soil_Sand"
    },
    {
      "x": -6,
      "y": 6,
      "z": 3,
      "name": "Soil_Sand"
    },
    {
      "x": -6,
      "y": 7,
      "z": 3,
      "name": "Soil_Sand"
    },
    {
      "x": -6,
      "y": 8,
      "z": 3,
      "name": "Soil_Sand"
    },
    {
      "x": -6,
      "y": 9,
      "z": 3,
      "name": "Soil_Sand"
    },
    {
      "x": -6,
      "y": 10,
      "z": 3,
      "name": "Soil_Sand"
    },
    {
      "x": -6,
      "y": 11,
      "z": 3,
      "name": "Plant_Moss_Block_Yellow"
    },
    {
      "x": -6,
      "y": 13,
      "z": 3,
      "name": "Plant_Moss_Block_Yellow"
    },
    {
      "x": -6,
      "y": 14,
      "z": 3,
      "name": "Plant_Moss_Block_Yellow"
    },
    {
      "x": -6,
      "y": 15,
      "z": 3,
      "name": "Soil_Sand"
    },
    {
      "x": -6,
      "y": 16,
      "z": 3,
      "name": "Plant_Leaves_Palm_Arid"
    },
    {
      "x": -6,
      "y": 2,
      "z": 4,
      "name": "Plant_Moss_Block_Yellow"
    },
    {
      "x": -6,
      "y": 3,
      "z": 4,
      "name": "Soil_Sand"
    },
    {
      "x": -6,
      "y": 4,
      "z": 4,
      "name": "Soil_Sand"
    },
    {
      "x": -6,
      "y": 5,
      "z": 4,
      "name": "Soil_Sand"
    },
    {
      "x": -6,
      "y": 6,
      "z": 4,
      "name": "Soil_Sand"
    },
    {
      "x": -6,
      "y": 7,
      "z": 4,
      "name": "Soil_Sand"
    },
    {
      "x": -6,
      "y": 8,
      "z": 4,
      "name": "Soil_Sand"
    },
    {
      "x": -6,
      "y": 9,
      "z": 4,
      "name": "Soil_Sand"
    },
    {
      "x": -6,
      "y": 10,
      "z": 4,
      "name": "Soil_Sand"
    },
    {
      "x": -6,
      "y": 11,
      "z": 4,
      "name": "Soil_Clay_Lime"
    },
    {
      "x": -6,
      "y": 12,
      "z": 4,
      "name": "Soil_Clay_Lime"
    },
    {
      "x": -6,
      "y": 13,
      "z": 4,
      "name": "Soil_Clay_Lime"
    },
    {
      "x": -6,
      "y": 2,
      "z": 5,
      "name": "Plant_Moss_Block_Yellow"
    },
    {
      "x": -6,
      "y": 3,
      "z": 5,
      "name": "Plant_Moss_Block_Yellow"
    },
    {
      "x": -6,
      "y": 4,
      "z": 5,
      "name": "Plant_Moss_Block_Yellow"
    },
    {
      "x": -6,
      "y": 5,
      "z": 5,
      "name": "Soil_Clay_Lime"
    },
    {
      "x": -6,
      "y": 6,
      "z": 5,
      "name": "Soil_Clay_Lime"
    },
    {
      "x": -6,
      "y": 7,
      "z": 5,
      "name": "Rock_Stone_Mossy"
    },
    {
      "x": -6,
      "y": 8,
      "z": 5,
      "name": "Rock_Stone_Mossy"
    },
    {
      "x": -6,
      "y": 9,
      "z": 5,
      "name": "Rock_Stone_Mossy"
    },
    {
      "x": -6,
      "y": 10,
      "z": 5,
      "name": "Rock_Stone_Mossy"
    },
    {
      "x": -6,
      "y": 11,
      "z": 5,
      "name": "Soil_Clay_Lime"
    },
    {
      "x": -6,
      "y": 12,
      "z": 5,
      "name": "Soil_Clay_Lime"
    },
    {
      "x": -5,
      "y": 4,
      "z": -6,
      "name": "Soil_Clay_Lime"
    },
    {
      "x": -5,
      "y": 5,
      "z": -6,
      "name": "Soil_Clay_Lime"
    },
    {
      "x": -5,
      "y": 6,
      "z": -6,
      "name": "Soil_Clay_Lime"
    },
    {
      "x": -5,
      "y": 7,
      "z": -6,
      "name": "Soil_Clay_Lime"
    },
    {
      "x": -5,
      "y": 2,
      "z": -5,
      "name": "Soil_Clay_Lime"
    },
    {
      "x": -5,
      "y": 3,
      "z": -5,
      "name": "Soil_Clay_Lime"
    },
    {
      "x": -5,
      "y": 4,
      "z": -5,
      "name": "Soil_Sand"
    },
    {
      "x": -5,
      "y": 5,
      "z": -5,
      "name": "Soil_Sand"
    },
    {
      "x": -5,
      "y": 6,
      "z": -5,
      "name": "Soil_Sand"
    },
    {
      "x": -5,
      "y": 7,
      "z": -5,
      "name": "Soil_Sand"
    },
    {
      "x": -5,
      "y": 8,
      "z": -5,
      "name": "Soil_Clay_Lime"
    },
    {
      "x": -5,
      "y": 9,
      "z": -5,
      "name": "Soil_Clay_Lime"
    },
    {
      "x": -5,
      "y": 10,
      "z": -5,
      "name": "Soil_Clay_Lime"
    },
    {
      "x": -5,
      "y": 13,
      "z": -5,
      "name": "Rock_Stone_Mossy"
    },
    {
      "x": -5,
      "y": 14,
      "z": -5,
      "name": "Soil_Clay_Lime"
    },
    {
      "x": -5,
      "y": 15,
      "z": -5,
      "name": "Soil_Clay_Lime"
    },
    {
      "x": -5,
      "y": 2,
      "z": -4,
      "name": "Soil_Clay_Lime"
    },
    {
      "x": -5,
      "y": 3,
      "z": -4,
      "name": "Soil_Sand"
    },
    {
      "x": -5,
      "y": 4,
      "z": -4,
      "name": "Soil_Sand"
    },
    {
      "x": -5,
      "y": 5,
      "z": -4,
      "name": "Soil_Sand"
    },
    {
      "x": -5,
      "y": 6,
      "z": -4,
      "name": "Soil_Sand"
    },
    {
      "x": -5,
      "y": 7,
      "z": -4,
      "name": "Soil_Sand"
    },
    {
      "x": -5,
      "y": 8,
      "z": -4,
      "name": "Soil_Sand"
    },
    {
      "x": -5,
      "y": 9,
      "z": -4,
      "name": "Soil_Sand"
    },
    {
      "x": -5,
      "y": 10,
      "z": -4,
      "name": "Soil_Clay_Lime"
    },
    {
      "x": -5,
      "y": 12,
      "z": -4,
      "name": "Rock_Stone_Mossy"
    },
    {
      "x": -5,
      "y": 13,
      "z": -4,
      "name": "Soil_Sand"
    },
    {
      "x": -5,
      "y": 14,
      "z": -4,
      "name": "Soil_Sand"
    },
    {
      "x": -5,
      "y": 15,
      "z": -4,
      "name": "Soil_Sand"
    },
    {
      "x": -5,
      "y": 16,
      "z": -4,
      "name": "Plant_Bush_Arid_Sharp"
    },
    {
      "x": -5,
      "y": 1,
      "z": -3,
      "name": "Soil_Clay_Lime"
    },
    {
      "x": -5,
      "y": 2,
      "z": -3,
      "name": "Soil_Sand"
    },
    {
      "x": -5,
      "y": 3,
      "z": -3,
      "name": "Soil_Sand"
    },
    {
      "x": -5,
      "y": 4,
      "z": -3,
      "name": "Soil_Sand"
    },
    {
      "x": -5,
      "y": 5,
      "z": -3,
      "name": "Soil_Sand"
    },
    {
      "x": -5,
      "y": 6,
      "z": -3,
      "name": "Soil_Sand"
    },
    {
      "x": -5,
      "y": 7,
      "z": -3,
      "name": "Soil_Sand"
    },
    {
      "x": -5,
      "y": 8,
      "z": -3,
      "name": "Soil_Sand"
    },
    {
      "x": -5,
      "y": 9,
      "z": -3,
      "name": "Soil_Sand"
    },
    {
      "x": -5,
      "y": 10,
      "z": -3,
      "name": "Soil_Sand"
    },
    {
      "x": -5,
      "y": 11,
      "z": -3,
      "name": "Rock_Stone_Mossy"
    },
    {
      "x": -5,
      "y": 12,
      "z": -3,
      "name": "Soil_Sand"
    },
    {
      "x": -5,
      "y": 13,
      "z": -3,
      "name": "Soil_Sand"
    },
    {
      "x": -5,
      "y": 14,
      "z": -3,
      "name": "Soil_Sand"
    },
    {
      "x": -5,
      "y": 15,
      "z": -3,
      "name": "Soil_Sand"
    },
    {
      "x": -5,
      "y": 16,
      "z": -3,
      "name": "Plant_Bush_Arid_Sharp"
    },
    {
      "x": -5,
      "y": 1,
      "z": -2,
      "name": "Soil_Clay_Lime"
    },
    {
      "x": -5,
      "y": 2,
      "z": -2,
      "name": "Soil_Sand"
    },
    {
      "x": -5,
      "y": 3,
      "z": -2,
      "name": "Soil_Sand"
    },
    {
      "x": -5,
      "y": 4,
      "z": -2,
      "name": "Soil_Sand"
    },
    {
      "x": -5,
      "y": 5,
      "z": -2,
      "name": "Soil_Sand"
    },
    {
      "x": -5,
      "y": 6,
      "z": -2,
      "name": "Soil_Sand"
    },
    {
      "x": -5,
      "y": 7,
      "z": -2,
      "name": "Soil_Sand"
    },
    {
      "x": -5,
      "y": 8,
      "z": -2,
      "name": "Soil_Sand"
    },
    {
      "x": -5,
      "y": 9,
      "z": -2,
      "name": "Soil_Sand"
    },
    {
      "x": -5,
      "y": 10,
      "z": -2,
      "name": "Soil_Sand"
    },
    {
      "x": -5,
      "y": 11,
      "z": -2,
      "name": "Soil_Sand"
    },
    {
      "x": -5,
      "y": 12,
      "z": -2,
      "name": "Soil_Sand"
    },
    {
      "x": -5,
      "y": 13,
      "z": -2,
      "name": "Soil_Sand"
    },
    {
      "x": -5,
      "y": 14,
      "z": -2,
      "name": "Soil_Sand"
    },
    {
      "x": -5,
      "y": 15,
      "z": -2,
      "name": "Soil_Sand"
    },
    {
      "x": -5,
      "y": 16,
      "z": -2,
      "name": "Soil_Sand"
    },
    {
      "x": -5,
      "y": 17,
      "z": -2,
      "name": "Plant_Flower_Bushy_Yellow"
    },
    {
      "x": -5,
      "y": 1,
      "z": -1,
      "name": "Soil_Clay_Lime"
    },
    {
      "x": -5,
      "y": 2,
      "z": -1,
      "name": "Soil_Sand"
    },
    {
      "x": -5,
      "y": 3,
      "z": -1,
      "name": "Soil_Sand"
    },
    {
      "x": -5,
      "y": 4,
      "z": -1,
      "name": "Soil_Sand"
    },
    {
      "x": -5,
      "y": 5,
      "z": -1,
      "name": "Soil_Sand"
    },
    {
      "x": -5,
      "y": 6,
      "z": -1,
      "name": "Soil_Sand"
    },
    {
      "x": -5,
      "y": 7,
      "z": -1,
      "name": "Soil_Sand"
    },
    {
      "x": -5,
      "y": 8,
      "z": -1,
      "name": "Soil_Sand"
    },
    {
      "x": -5,
      "y": 9,
      "z": -1,
      "name": "Soil_Sand"
    },
    {
      "x": -5,
      "y": 10,
      "z": -1,
      "name": "Soil_Sand"
    },
    {
      "x": -5,
      "y": 11,
      "z": -1,
      "name": "Soil_Sand"
    },
    {
      "x": -5,
      "y": 12,
      "z": -1,
      "name": "Soil_Sand"
    },
    {
      "x": -5,
      "y": 13,
      "z": -1,
      "name": "Soil_Sand"
    },
    {
      "x": -5,
      "y": 14,
      "z": -1,
      "name": "Soil_Sand"
    },
    {
      "x": -5,
      "y": 15,
      "z": -1,
      "name": "Soil_Sand"
    },
    {
      "x": -5,
      "y": 16,
      "z": -1,
      "name": "Soil_Sand"
    },
    {
      "x": -5,
      "y": 17,
      "z": -1,
      "name": "Plant_Flower_Bushy_Yellow"
    },
    {
      "x": -5,
      "y": 1,
      "z": 0,
      "name": "Soil_Clay_Lime"
    },
    {
      "x": -5,
      "y": 2,
      "z": 0,
      "name": "Soil_Sand"
    },
    {
      "x": -5,
      "y": 3,
      "z": 0,
      "name": "Soil_Sand"
    },
    {
      "x": -5,
      "y": 4,
      "z": 0,
      "name": "Soil_Sand"
    },
    {
      "x": -5,
      "y": 5,
      "z": 0,
      "name": "Soil_Sand"
    },
    {
      "x": -5,
      "y": 6,
      "z": 0,
      "name": "Soil_Sand"
    },
    {
      "x": -5,
      "y": 7,
      "z": 0,
      "name": "Soil_Sand"
    },
    {
      "x": -5,
      "y": 8,
      "z": 0,
      "name": "Soil_Sand"
    },
    {
      "x": -5,
      "y": 9,
      "z": 0,
      "name": "Soil_Sand"
    },
    {
      "x": -5,
      "y": 10,
      "z": 0,
      "name": "Soil_Sand"
    },
    {
      "x": -5,
      "y": 11,
      "z": 0,
      "name": "Soil_Sand"
    },
    {
      "x": -5,
      "y": 12,
      "z": 0,
      "name": "Soil_Sand"
    },
    {
      "x": -5,
      "y": 13,
      "z": 0,
      "name": "Soil_Sand"
    },
    {
      "x": -5,
      "y": 14,
      "z": 0,
      "name": "Soil_Sand"
    },
    {
      "x": -5,
      "y": 15,
      "z": 0,
      "name": "Soil_Sand"
    },
    {
      "x": -5,
      "y": 16,
      "z": 0,
      "name": "Soil_Sand"
    },
    {
      "x": -5,
      "y": 17,
      "z": 0,
      "name": "Plant_Flower_Bushy_Yellow"
    },
    {
      "x": -5,
      "y": 1,
      "z": 1,
      "name": "Soil_Clay_Lime"
    },
    {
      "x": -5,
      "y": 2,
      "z": 1,
      "name": "Soil_Sand"
    },
    {
      "x": -5,
      "y": 3,
      "z": 1,
      "name": "Soil_Sand"
    },
    {
      "x": -5,
      "y": 4,
      "z": 1,
      "name": "Soil_Sand"
    },
    {
      "x": -5,
      "y": 5,
      "z": 1,
      "name": "Soil_Sand"
    },
    {
      "x": -5,
      "y": 6,
      "z": 1,
      "name": "Soil_Sand"
    },
    {
      "x": -5,
      "y": 7,
      "z": 1,
      "name": "Soil_Sand"
    },
    {
      "x": -5,
      "y": 8,
      "z": 1,
      "name": "Soil_Sand"
    },
    {
      "x": -5,
      "y": 9,
      "z": 1,
      "name": "Soil_Sand"
    },
    {
      "x": -5,
      "y": 10,
      "z": 1,
      "name": "Soil_Sand"
    },
    {
      "x": -5,
      "y": 11,
      "z": 1,
      "name": "Soil_Sand"
    },
    {
      "x": -5,
      "y": 12,
      "z": 1,
      "name": "Soil_Sand"
    },
    {
      "x": -5,
      "y": 13,
      "z": 1,
      "name": "Soil_Sand"
    },
    {
      "x": -5,
      "y": 14,
      "z": 1,
      "name": "Soil_Sand"
    },
    {
      "x": -5,
      "y": 15,
      "z": 1,
      "name": "Soil_Sand"
    },
    {
      "x": -5,
      "y": 16,
      "z": 1,
      "name": "Soil_Sand"
    },
    {
      "x": -5,
      "y": 17,
      "z": 1,
      "name": "Plant_Leaves_Palm_Arid"
    },
    {
      "x": -5,
      "y": 1,
      "z": 2,
      "name": "Soil_Clay_Lime"
    },
    {
      "x": -5,
      "y": 2,
      "z": 2,
      "name": "Soil_Sand"
    },
    {
      "x": -5,
      "y": 3,
      "z": 2,
      "name": "Soil_Sand"
    },
    {
      "x": -5,
      "y": 4,
      "z": 2,
      "name": "Soil_Sand"
    },
    {
      "x": -5,
      "y": 5,
      "z": 2,
      "name": "Soil_Sand"
    },
    {
      "x": -5,
      "y": 6,
      "z": 2,
      "name": "Soil_Sand"
    },
    {
      "x": -5,
      "y": 7,
      "z": 2,
      "name": "Soil_Sand"
    },
    {
      "x": -5,
      "y": 8,
      "z": 2,
      "name": "Soil_Sand"
    },
    {
      "x": -5,
      "y": 9,
      "z": 2,
      "name": "Soil_Sand"
    },
    {
      "x": -5,
      "y": 10,
      "z": 2,
      "name": "Soil_Sand"
    },
    {
      "x": -5,
      "y": 11,
      "z": 2,
      "name": "Soil_Sand"
    },
    {
      "x": -5,
      "y": 12,
      "z": 2,
      "name": "Soil_Sand"
    },
    {
      "x": -5,
      "y": 13,
      "z": 2,
      "name": "Soil_Sand"
    },
    {
      "x": -5,
      "y": 14,
      "z": 2,
      "name": "Soil_Sand"
    },
    {
      "x": -5,
      "y": 15,
      "z": 2,
      "name": "Soil_Sand"
    },
    {
      "x": -5,
      "y": 16,
      "z": 2,
      "name": "Plant_Leaves_Palm_Arid"
    },
    {
      "x": -5,
      "y": 1,
      "z": 3,
      "name": "Plant_Moss_Block_Yellow"
    },
    {
      "x": -5,
      "y": 2,
      "z": 3,
      "name": "Soil_Sand"
    },
    {
      "x": -5,
      "y": 3,
      "z": 3,
      "name": "Soil_Sand"
    },
    {
      "x": -5,
      "y": 4,
      "z": 3,
      "name": "Soil_Sand"
    },
    {
      "x": -5,
      "y": 5,
      "z": 3,
      "name": "Soil_Sand"
    },
    {
      "x": -5,
      "y": 6,
      "z": 3,
      "name": "Soil_Sand"
    },
    {
      "x": -5,
      "y": 7,
      "z": 3,
      "name": "Soil_Sand"
    },
    {
      "x": -5,
      "y": 8,
      "z": 3,
      "name": "Soil_Sand"
    },
    {
      "x": -5,
      "y": 9,
      "z": 3,
      "name": "Soil_Sand"
    },
    {
      "x": -5,
      "y": 10,
      "z": 3,
      "name": "Soil_Sand"
    },
    {
      "x": -5,
      "y": 11,
      "z": 3,
      "name": "Soil_Sand"
    },
    {
      "x": -5,
      "y": 12,
      "z": 3,
      "name": "Plant_Moss_Block_Yellow"
    },
    {
      "x": -5,
      "y": 13,
      "z": 3,
      "name": "Soil_Sand"
    },
    {
      "x": -5,
      "y": 14,
      "z": 3,
      "name": "Soil_Sand"
    },
    {
      "x": -5,
      "y": 15,
      "z": 3,
      "name": "Soil_Sand"
    },
    {
      "x": -5,
      "y": 16,
      "z": 3,
      "name": "Plant_Leaves_Palm_Arid"
    },
    {
      "x": -5,
      "y": 2,
      "z": 4,
      "name": "Plant_Moss_Block_Yellow"
    },
    {
      "x": -5,
      "y": 3,
      "z": 4,
      "name": "Soil_Sand"
    },
    {
      "x": -5,
      "y": 4,
      "z": 4,
      "name": "Soil_Sand"
    },
    {
      "x": -5,
      "y": 5,
      "z": 4,
      "name": "Soil_Sand"
    },
    {
      "x": -5,
      "y": 6,
      "z": 4,
      "name": "Soil_Sand"
    },
    {
      "x": -5,
      "y": 7,
      "z": 4,
      "name": "Soil_Sand"
    },
    {
      "x": -5,
      "y": 8,
      "z": 4,
      "name": "Soil_Sand"
    },
    {
      "x": -5,
      "y": 9,
      "z": 4,
      "name": "Soil_Sand"
    },
    {
      "x": -5,
      "y": 10,
      "z": 4,
      "name": "Soil_Sand"
    },
    {
      "x": -5,
      "y": 11,
      "z": 4,
      "name": "Soil_Sand"
    },
    {
      "x": -5,
      "y": 12,
      "z": 4,
      "name": "Soil_Sand"
    },
    {
      "x": -5,
      "y": 13,
      "z": 4,
      "name": "Soil_Sand"
    },
    {
      "x": -5,
      "y": 14,
      "z": 4,
      "name": "Soil_Clay_Lime"
    },
    {
      "x": -5,
      "y": 15,
      "z": 4,
      "name": "Soil_Sand"
    },
    {
      "x": -5,
      "y": 16,
      "z": 4,
      "name": "Plant_Leaves_Palm_Arid"
    },
    {
      "x": -5,
      "y": 2,
      "z": 5,
      "name": "Plant_Moss_Block_Yellow"
    },
    {
      "x": -5,
      "y": 3,
      "z": 5,
      "name": "Soil_Sand"
    },
    {
      "x": -5,
      "y": 4,
      "z": 5,
      "name": "Soil_Sand"
    },
    {
      "x": -5,
      "y": 5,
      "z": 5,
      "name": "Soil_Sand"
    },
    {
      "x": -5,
      "y": 6,
      "z": 5,
      "name": "Soil_Sand"
    },
    {
      "x": -5,
      "y": 7,
      "z": 5,
      "name": "Soil_Sand"
    },
    {
      "x": -5,
      "y": 8,
      "z": 5,
      "name": "Soil_Sand"
    },
    {
      "x": -5,
      "y": 9,
      "z": 5,
      "name": "Soil_Sand"
    },
    {
      "x": -5,
      "y": 10,
      "z": 5,
      "name": "Soil_Sand"
    },
    {
      "x": -5,
      "y": 11,
      "z": 5,
      "name": "Soil_Sand"
    },
    {
      "x": -5,
      "y": 12,
      "z": 5,
      "name": "Soil_Sand"
    },
    {
      "x": -5,
      "y": 13,
      "z": 5,
      "name": "Soil_Clay_Lime"
    },
    {
      "x": -5,
      "y": 3,
      "z": 6,
      "name": "Plant_Moss_Block_Yellow"
    },
    {
      "x": -5,
      "y": 4,
      "z": 6,
      "name": "Soil_Clay_Lime"
    },
    {
      "x": -5,
      "y": 5,
      "z": 6,
      "name": "Soil_Clay_Lime"
    },
    {
      "x": -5,
      "y": 6,
      "z": 6,
      "name": "Soil_Clay_Lime"
    },
    {
      "x": -5,
      "y": 7,
      "z": 6,
      "name": "Soil_Clay_Lime"
    },
    {
      "x": -5,
      "y": 8,
      "z": 6,
      "name": "Soil_Clay_Lime"
    },
    {
      "x": -5,
      "y": 9,
      "z": 6,
      "name": "Rock_Stone_Mossy"
    },
    {
      "x": -5,
      "y": 10,
      "z": 6,
      "name": "Soil_Clay_Lime"
    },
    {
      "x": -5,
      "y": 11,
      "z": 6,
      "name": "Soil_Clay_Lime"
    },
    {
      "x": -5,
      "y": 12,
      "z": 6,
      "name": "Soil_Clay_Lime"
    },
    {
      "x": -5,
      "y": 3,
      "z": 7,
      "name": "Plant_Moss_Block_Yellow"
    },
    {
      "x": -5,
      "y": 4,
      "z": 7,
      "name": "Soil_Clay_Lime"
    },
    {
      "x": -5,
      "y": 5,
      "z": 7,
      "name": "Soil_Clay_Lime"
    },
    {
      "x": -5,
      "y": 6,
      "z": 7,
      "name": "Soil_Clay_Lime"
    },
    {
      "x": -5,
      "y": 7,
      "z": 7,
      "name": "Soil_Clay_Lime"
    },
    {
      "x": -5,
      "y": 8,
      "z": 7,
      "name": "Soil_Clay_Lime"
    },
    {
      "x": -5,
      "y": 9,
      "z": 7,
      "name": "Soil_Clay_Lime"
    },
    {
      "x": -5,
      "y": 10,
      "z": 7,
      "name": "Soil_Clay_Lime"
    },
    {
      "x": -5,
      "y": 11,
      "z": 7,
      "name": "Soil_Clay_Lime"
    },
    {
      "x": -5,
      "y": 12,
      "z": 7,
      "name": "Soil_Clay_Lime"
    },
    {
      "x": -5,
      "y": 6,
      "z": 8,
      "name": "Soil_Clay_Lime"
    },
    {
      "x": -5,
      "y": 7,
      "z": 8,
      "name": "Soil_Clay_Lime"
    },
    {
      "x": -5,
      "y": 8,
      "z": 8,
      "name": "Soil_Clay_Lime"
    },
    {
      "x": -5,
      "y": 9,
      "z": 8,
      "name": "Plant_Moss_Block_Yellow"
    },
    {
      "x": -5,
      "y": 10,
      "z": 8,
      "name": "Plant_Moss_Block_Yellow"
    },
    {
      "x": -5,
      "y": 11,
      "z": 8,
      "name": "Plant_Moss_Block_Yellow"
    },
    {
      "x": -5,
      "y": 12,
      "z": 8,
      "name": "Plant_Moss_Block_Yellow"
    },
    {
      "x": -4,
      "y": 2,
      "z": -6,
      "name": "Soil_Clay_Lime"
    },
    {
      "x": -4,
      "y": 3,
      "z": -6,
      "name": "Soil_Clay_Lime"
    },
    {
      "x": -4,
      "y": 4,
      "z": -6,
      "name": "Soil_Clay_Lime"
    },
    {
      "x": -4,
      "y": 5,
      "z": -6,
      "name": "Soil_Clay_Lime"
    },
    {
      "x": -4,
      "y": 6,
      "z": -6,
      "name": "Soil_Clay_Lime"
    },
    {
      "x": -4,
      "y": 7,
      "z": -6,
      "name": "Soil_Clay_Lime"
    },
    {
      "x": -4,
      "y": 8,
      "z": -6,
      "name": "Soil_Clay_Lime"
    },
    {
      "x": -4,
      "y": 9,
      "z": -6,
      "name": "Plant_Moss_Block_Yellow"
    },
    {
      "x": -4,
      "y": 10,
      "z": -6,
      "name": "Soil_Clay_Lime"
    },
    {
      "x": -4,
      "y": 11,
      "z": -6,
      "name": "Soil_Clay_Lime"
    },
    {
      "x": -4,
      "y": 2,
      "z": -5,
      "name": "Soil_Clay_Lime"
    },
    {
      "x": -4,
      "y": 3,
      "z": -5,
      "name": "Soil_Sand"
    },
    {
      "x": -4,
      "y": 4,
      "z": -5,
      "name": "Soil_Sand"
    },
    {
      "x": -4,
      "y": 5,
      "z": -5,
      "name": "Soil_Sand"
    },
    {
      "x": -4,
      "y": 6,
      "z": -5,
      "name": "Soil_Sand"
    },
    {
      "x": -4,
      "y": 7,
      "z": -5,
      "name": "Soil_Sand"
    },
    {
      "x": -4,
      "y": 8,
      "z": -5,
      "name": "Soil_Sand"
    },
    {
      "x": -4,
      "y": 9,
      "z": -5,
      "name": "Soil_Sand"
    },
    {
      "x": -4,
      "y": 10,
      "z": -5,
      "name": "Soil_Sand"
    },
    {
      "x": -4,
      "y": 11,
      "z": -5,
      "name": "Soil_Clay_Lime"
    },
    {
      "x": -4,
      "y": 12,
      "z": -5,
      "name": "Rock_Stone_Mossy"
    },
    {
      "x": -4,
      "y": 13,
      "z": -5,
      "name": "Rock_Stone_Mossy"
    },
    {
      "x": -4,
      "y": 14,
      "z": -5,
      "name": "Rock_Stone_Mossy"
    },
    {
      "x": -4,
      "y": 15,
      "z": -5,
      "name": "Soil_Sand"
    },
    {
      "x": -4,
      "y": 16,
      "z": -5,
      "name": "Plant_Flower_Bushy_Yellow"
    },
    {
      "x": -4,
      "y": 1,
      "z": -4,
      "name": "Soil_Clay_Lime"
    },
    {
      "x": -4,
      "y": 2,
      "z": -4,
      "name": "Soil_Sand"
    },
    {
      "x": -4,
      "y": 3,
      "z": -4,
      "name": "Soil_Sand"
    },
    {
      "x": -4,
      "y": 4,
      "z": -4,
      "name": "Soil_Sand"
    },
    {
      "x": -4,
      "y": 5,
      "z": -4,
      "name": "Soil_Sand"
    },
    {
      "x": -4,
      "y": 6,
      "z": -4,
      "name": "Soil_Sand"
    },
    {
      "x": -4,
      "y": 7,
      "z": -4,
      "name": "Soil_Sand"
    },
    {
      "x": -4,
      "y": 8,
      "z": -4,
      "name": "Soil_Sand"
    },
    {
      "x": -4,
      "y": 9,
      "z": -4,
      "name": "Soil_Sand"
    },
    {
      "x": -4,
      "y": 10,
      "z": -4,
      "name": "Soil_Sand"
    },
    {
      "x": -4,
      "y": 11,
      "z": -4,
      "name": "Soil_Clay_Lime"
    },
    {
      "x": -4,
      "y": 12,
      "z": -4,
      "name": "Soil_Sand"
    },
    {
      "x": -4,
      "y": 13,
      "z": -4,
      "name": "Soil_Sand"
    },
    {
      "x": -4,
      "y": 14,
      "z": -4,
      "name": "Soil_Sand"
    },
    {
      "x": -4,
      "y": 15,
      "z": -4,
      "name": "Soil_Sand"
    },
    {
      "x": -4,
      "y": 16,
      "z": -4,
      "name": "Plant_Bush_Arid_Sharp"
    },
    {
      "x": -4,
      "y": 1,
      "z": -3,
      "name": "Soil_Clay_Lime"
    },
    {
      "x": -4,
      "y": 2,
      "z": -3,
      "name": "Soil_Sand"
    },
    {
      "x": -4,
      "y": 3,
      "z": -3,
      "name": "Soil_Sand"
    },
    {
      "x": -4,
      "y": 4,
      "z": -3,
      "name": "Soil_Sand"
    },
    {
      "x": -4,
      "y": 5,
      "z": -3,
      "name": "Soil_Sand"
    },
    {
      "x": -4,
      "y": 6,
      "z": -3,
      "name": "Soil_Sand"
    },
    {
      "x": -4,
      "y": 7,
      "z": -3,
      "name": "Soil_Sand"
    },
    {
      "x": -4,
      "y": 8,
      "z": -3,
      "name": "Soil_Sand"
    },
    {
      "x": -4,
      "y": 9,
      "z": -3,
      "name": "Soil_Sand"
    },
    {
      "x": -4,
      "y": 10,
      "z": -3,
      "name": "Soil_Sand"
    },
    {
      "x": -4,
      "y": 11,
      "z": -3,
      "name": "Soil_Sand"
    },
    {
      "x": -4,
      "y": 12,
      "z": -3,
      "name": "Soil_Sand"
    },
    {
      "x": -4,
      "y": 13,
      "z": -3,
      "name": "Soil_Sand"
    },
    {
      "x": -4,
      "y": 14,
      "z": -3,
      "name": "Soil_Sand"
    },
    {
      "x": -4,
      "y": 15,
      "z": -3,
      "name": "Soil_Sand"
    },
    {
      "x": -4,
      "y": 16,
      "z": -3,
      "name": "Soil_Sand"
    },
    {
      "x": -4,
      "y": 17,
      "z": -3,
      "name": "Plant_Bush_Arid_Sharp"
    },
    {
      "x": -4,
      "y": 1,
      "z": -2,
      "name": "Soil_Clay_Lime"
    },
    {
      "x": -4,
      "y": 2,
      "z": -2,
      "name": "Soil_Sand"
    },
    {
      "x": -4,
      "y": 3,
      "z": -2,
      "name": "Soil_Sand"
    },
    {
      "x": -4,
      "y": 4,
      "z": -2,
      "name": "Soil_Sand"
    },
    {
      "x": -4,
      "y": 5,
      "z": -2,
      "name": "Soil_Sand"
    },
    {
      "x": -4,
      "y": 6,
      "z": -2,
      "name": "Soil_Sand"
    },
    {
      "x": -4,
      "y": 7,
      "z": -2,
      "name": "Soil_Sand"
    },
    {
      "x": -4,
      "y": 8,
      "z": -2,
      "name": "Soil_Sand"
    },
    {
      "x": -4,
      "y": 9,
      "z": -2,
      "name": "Soil_Sand"
    },
    {
      "x": -4,
      "y": 10,
      "z": -2,
      "name": "Soil_Sand"
    },
    {
      "x": -4,
      "y": 11,
      "z": -2,
      "name": "Soil_Sand"
    },
    {
      "x": -4,
      "y": 12,
      "z": -2,
      "name": "Soil_Sand"
    },
    {
      "x": -4,
      "y": 13,
      "z": -2,
      "name": "Soil_Sand"
    },
    {
      "x": -4,
      "y": 14,
      "z": -2,
      "name": "Soil_Sand"
    },
    {
      "x": -4,
      "y": 15,
      "z": -2,
      "name": "Soil_Sand"
    },
    {
      "x": -4,
      "y": 16,
      "z": -2,
      "name": "Soil_Sand"
    },
    {
      "x": -4,
      "y": 17,
      "z": -2,
      "name": "Plant_Flower_Bushy_Yellow"
    },
    {
      "x": -4,
      "y": 1,
      "z": -1,
      "name": "Soil_Clay_Lime"
    },
    {
      "x": -4,
      "y": 2,
      "z": -1,
      "name": "Soil_Sand"
    },
    {
      "x": -4,
      "y": 3,
      "z": -1,
      "name": "Soil_Sand"
    },
    {
      "x": -4,
      "y": 4,
      "z": -1,
      "name": "Soil_Sand"
    },
    {
      "x": -4,
      "y": 5,
      "z": -1,
      "name": "Soil_Sand"
    },
    {
      "x": -4,
      "y": 6,
      "z": -1,
      "name": "Soil_Sand"
    },
    {
      "x": -4,
      "y": 7,
      "z": -1,
      "name": "Soil_Sand"
    },
    {
      "x": -4,
      "y": 8,
      "z": -1,
      "name": "Soil_Sand"
    },
    {
      "x": -4,
      "y": 9,
      "z": -1,
      "name": "Soil_Sand"
    },
    {
      "x": -4,
      "y": 10,
      "z": -1,
      "name": "Soil_Sand"
    },
    {
      "x": -4,
      "y": 11,
      "z": -1,
      "name": "Soil_Sand"
    },
    {
      "x": -4,
      "y": 12,
      "z": -1,
      "name": "Soil_Sand"
    },
    {
      "x": -4,
      "y": 13,
      "z": -1,
      "name": "Soil_Sand"
    },
    {
      "x": -4,
      "y": 14,
      "z": -1,
      "name": "Soil_Sand"
    },
    {
      "x": -4,
      "y": 15,
      "z": -1,
      "name": "Soil_Sand"
    },
    {
      "x": -4,
      "y": 16,
      "z": -1,
      "name": "Soil_Sand"
    },
    {
      "x": -4,
      "y": 17,
      "z": -1,
      "name": "Plant_Flower_Bushy_Yellow"
    },
    {
      "x": -4,
      "y": 1,
      "z": 0,
      "name": "Soil_Clay_Lime"
    },
    {
      "x": -4,
      "y": 2,
      "z": 0,
      "name": "Soil_Sand"
    },
    {
      "x": -4,
      "y": 3,
      "z": 0,
      "name": "Soil_Sand"
    },
    {
      "x": -4,
      "y": 4,
      "z": 0,
      "name": "Soil_Sand"
    },
    {
      "x": -4,
      "y": 5,
      "z": 0,
      "name": "Soil_Sand"
    },
    {
      "x": -4,
      "y": 6,
      "z": 0,
      "name": "Soil_Sand"
    },
    {
      "x": -4,
      "y": 7,
      "z": 0,
      "name": "Soil_Sand"
    },
    {
      "x": -4,
      "y": 8,
      "z": 0,
      "name": "Soil_Sand"
    },
    {
      "x": -4,
      "y": 9,
      "z": 0,
      "name": "Soil_Sand"
    },
    {
      "x": -4,
      "y": 10,
      "z": 0,
      "name": "Soil_Sand"
    },
    {
      "x": -4,
      "y": 11,
      "z": 0,
      "name": "Soil_Sand"
    },
    {
      "x": -4,
      "y": 12,
      "z": 0,
      "name": "Soil_Sand"
    },
    {
      "x": -4,
      "y": 13,
      "z": 0,
      "name": "Soil_Sand"
    },
    {
      "x": -4,
      "y": 14,
      "z": 0,
      "name": "Soil_Sand"
    },
    {
      "x": -4,
      "y": 15,
      "z": 0,
      "name": "Soil_Sand"
    },
    {
      "x": -4,
      "y": 16,
      "z": 0,
      "name": "Soil_Sand"
    },
    {
      "x": -4,
      "y": 17,
      "z": 0,
      "name": "Plant_Leaves_Palm_Arid"
    },
    {
      "x": -4,
      "y": 1,
      "z": 1,
      "name": "Soil_Clay_Lime"
    },
    {
      "x": -4,
      "y": 2,
      "z": 1,
      "name": "Soil_Sand"
    },
    {
      "x": -4,
      "y": 3,
      "z": 1,
      "name": "Soil_Sand"
    },
    {
      "x": -4,
      "y": 4,
      "z": 1,
      "name": "Soil_Sand"
    },
    {
      "x": -4,
      "y": 5,
      "z": 1,
      "name": "Soil_Sand"
    },
    {
      "x": -4,
      "y": 6,
      "z": 1,
      "name": "Soil_Sand"
    },
    {
      "x": -4,
      "y": 7,
      "z": 1,
      "name": "Soil_Sand"
    },
    {
      "x": -4,
      "y": 8,
      "z": 1,
      "name": "Soil_Sand"
    },
    {
      "x": -4,
      "y": 9,
      "z": 1,
      "name": "Soil_Sand"
    },
    {
      "x": -4,
      "y": 10,
      "z": 1,
      "name": "Soil_Sand"
    },
    {
      "x": -4,
      "y": 11,
      "z": 1,
      "name": "Soil_Sand"
    },
    {
      "x": -4,
      "y": 12,
      "z": 1,
      "name": "Soil_Sand"
    },
    {
      "x": -4,
      "y": 13,
      "z": 1,
      "name": "Soil_Sand"
    },
    {
      "x": -4,
      "y": 14,
      "z": 1,
      "name": "Soil_Sand"
    },
    {
      "x": -4,
      "y": 15,
      "z": 1,
      "name": "Soil_Sand"
    },
    {
      "x": -4,
      "y": 16,
      "z": 1,
      "name": "Soil_Sand"
    },
    {
      "x": -4,
      "y": 17,
      "z": 1,
      "name": "Plant_Leaves_Palm_Arid"
    },
    {
      "x": -4,
      "y": 1,
      "z": 2,
      "name": "Soil_Clay_Lime"
    },
    {
      "x": -4,
      "y": 2,
      "z": 2,
      "name": "Soil_Sand"
    },
    {
      "x": -4,
      "y": 3,
      "z": 2,
      "name": "Soil_Sand"
    },
    {
      "x": -4,
      "y": 4,
      "z": 2,
      "name": "Soil_Sand"
    },
    {
      "x": -4,
      "y": 5,
      "z": 2,
      "name": "Soil_Sand"
    },
    {
      "x": -4,
      "y": 6,
      "z": 2,
      "name": "Soil_Sand"
    },
    {
      "x": -4,
      "y": 7,
      "z": 2,
      "name": "Soil_Sand"
    },
    {
      "x": -4,
      "y": 8,
      "z": 2,
      "name": "Soil_Sand"
    },
    {
      "x": -4,
      "y": 9,
      "z": 2,
      "name": "Soil_Sand"
    },
    {
      "x": -4,
      "y": 10,
      "z": 2,
      "name": "Soil_Sand"
    },
    {
      "x": -4,
      "y": 11,
      "z": 2,
      "name": "Soil_Sand"
    },
    {
      "x": -4,
      "y": 12,
      "z": 2,
      "name": "Soil_Sand"
    },
    {
      "x": -4,
      "y": 13,
      "z": 2,
      "name": "Soil_Sand"
    },
    {
      "x": -4,
      "y": 14,
      "z": 2,
      "name": "Soil_Sand"
    },
    {
      "x": -4,
      "y": 15,
      "z": 2,
      "name": "Soil_Sand"
    },
    {
      "x": -4,
      "y": 16,
      "z": 2,
      "name": "Soil_Sand"
    },
    {
      "x": -4,
      "y": 17,
      "z": 2,
      "name": "Plant_Leaves_Palm_Arid"
    },
    {
      "x": -4,
      "y": 1,
      "z": 3,
      "name": "Plant_Moss_Block_Yellow"
    },
    {
      "x": -4,
      "y": 2,
      "z": 3,
      "name": "Soil_Sand"
    },
    {
      "x": -4,
      "y": 3,
      "z": 3,
      "name": "Soil_Sand"
    },
    {
      "x": -4,
      "y": 4,
      "z": 3,
      "name": "Soil_Sand"
    },
    {
      "x": -4,
      "y": 5,
      "z": 3,
      "name": "Soil_Sand"
    },
    {
      "x": -4,
      "y": 6,
      "z": 3,
      "name": "Soil_Sand"
    },
    {
      "x": -4,
      "y": 7,
      "z": 3,
      "name": "Soil_Sand"
    },
    {
      "x": -4,
      "y": 8,
      "z": 3,
      "name": "Soil_Sand"
    },
    {
      "x": -4,
      "y": 9,
      "z": 3,
      "name": "Soil_Sand"
    },
    {
      "x": -4,
      "y": 10,
      "z": 3,
      "name": "Soil_Sand"
    },
    {
      "x": -4,
      "y": 11,
      "z": 3,
      "name": "Soil_Sand"
    },
    {
      "x": -4,
      "y": 12,
      "z": 3,
      "name": "Soil_Sand"
    },
    {
      "x": -4,
      "y": 13,
      "z": 3,
      "name": "Soil_Sand"
    },
    {
      "x": -4,
      "y": 14,
      "z": 3,
      "name": "Soil_Sand"
    },
    {
      "x": -4,
      "y": 15,
      "z": 3,
      "name": "Soil_Sand"
    },
    {
      "x": -4,
      "y": 16,
      "z": 3,
      "name": "Plant_Leaves_Palm_Arid"
    },
    {
      "x": -4,
      "y": 2,
      "z": 4,
      "name": "Plant_Moss_Block_Yellow"
    },
    {
      "x": -4,
      "y": 3,
      "z": 4,
      "name": "Soil_Sand"
    },
    {
      "x": -4,
      "y": 4,
      "z": 4,
      "name": "Soil_Sand"
    },
    {
      "x": -4,
      "y": 5,
      "z": 4,
      "name": "Soil_Sand"
    },
    {
      "x": -4,
      "y": 6,
      "z": 4,
      "name": "Soil_Sand"
    },
    {
      "x": -4,
      "y": 7,
      "z": 4,
      "name": "Soil_Sand"
    },
    {
      "x": -4,
      "y": 8,
      "z": 4,
      "name": "Soil_Sand"
    },
    {
      "x": -4,
      "y": 9,
      "z": 4,
      "name": "Soil_Sand"
    },
    {
      "x": -4,
      "y": 10,
      "z": 4,
      "name": "Soil_Sand"
    },
    {
      "x": -4,
      "y": 11,
      "z": 4,
      "name": "Soil_Sand"
    },
    {
      "x": -4,
      "y": 12,
      "z": 4,
      "name": "Soil_Sand"
    },
    {
      "x": -4,
      "y": 13,
      "z": 4,
      "name": "Soil_Sand"
    },
    {
      "x": -4,
      "y": 14,
      "z": 4,
      "name": "Soil_Sand"
    },
    {
      "x": -4,
      "y": 15,
      "z": 4,
      "name": "Soil_Sand"
    },
    {
      "x": -4,
      "y": 16,
      "z": 4,
      "name": "Plant_Flower_Bushy_Yellow"
    },
    {
      "x": -4,
      "y": 2,
      "z": 5,
      "name": "Plant_Moss_Block_Yellow"
    },
    {
      "x": -4,
      "y": 3,
      "z": 5,
      "name": "Soil_Sand"
    },
    {
      "x": -4,
      "y": 4,
      "z": 5,
      "name": "Soil_Sand"
    },
    {
      "x": -4,
      "y": 5,
      "z": 5,
      "name": "Soil_Sand"
    },
    {
      "x": -4,
      "y": 6,
      "z": 5,
      "name": "Soil_Sand"
    },
    {
      "x": -4,
      "y": 7,
      "z": 5,
      "name": "Soil_Sand"
    },
    {
      "x": -4,
      "y": 8,
      "z": 5,
      "name": "Soil_Sand"
    },
    {
      "x": -4,
      "y": 9,
      "z": 5,
      "name": "Soil_Sand"
    },
    {
      "x": -4,
      "y": 10,
      "z": 5,
      "name": "Soil_Sand"
    },
    {
      "x": -4,
      "y": 11,
      "z": 5,
      "name": "Soil_Sand"
    },
    {
      "x": -4,
      "y": 12,
      "z": 5,
      "name": "Soil_Sand"
    },
    {
      "x": -4,
      "y": 13,
      "z": 5,
      "name": "Soil_Sand"
    },
    {
      "x": -4,
      "y": 14,
      "z": 5,
      "name": "Soil_Sand"
    },
    {
      "x": -4,
      "y": 15,
      "z": 5,
      "name": "Soil_Sand"
    },
    {
      "x": -4,
      "y": 16,
      "z": 5,
      "name": "Plant_Flower_Bushy_Yellow"
    },
    {
      "x": -4,
      "y": 3,
      "z": 6,
      "name": "Soil_Clay_Lime"
    },
    {
      "x": -4,
      "y": 4,
      "z": 6,
      "name": "Soil_Sand"
    },
    {
      "x": -4,
      "y": 5,
      "z": 6,
      "name": "Soil_Sand"
    },
    {
      "x": -4,
      "y": 6,
      "z": 6,
      "name": "Soil_Sand"
    },
    {
      "x": -4,
      "y": 7,
      "z": 6,
      "name": "Soil_Sand"
    },
    {
      "x": -4,
      "y": 8,
      "z": 6,
      "name": "Soil_Sand"
    },
    {
      "x": -4,
      "y": 9,
      "z": 6,
      "name": "Soil_Sand"
    },
    {
      "x": -4,
      "y": 10,
      "z": 6,
      "name": "Soil_Sand"
    },
    {
      "x": -4,
      "y": 11,
      "z": 6,
      "name": "Soil_Sand"
    },
    {
      "x": -4,
      "y": 12,
      "z": 6,
      "name": "Soil_Sand"
    },
    {
      "x": -4,
      "y": 13,
      "z": 6,
      "name": "Rock_Stone_Mossy"
    },
    {
      "x": -4,
      "y": 3,
      "z": 7,
      "name": "Soil_Clay_Lime"
    },
    {
      "x": -4,
      "y": 4,
      "z": 7,
      "name": "Soil_Sand"
    },
    {
      "x": -4,
      "y": 5,
      "z": 7,
      "name": "Soil_Sand"
    },
    {
      "x": -4,
      "y": 6,
      "z": 7,
      "name": "Soil_Sand"
    },
    {
      "x": -4,
      "y": 7,
      "z": 7,
      "name": "Soil_Sand"
    },
    {
      "x": -4,
      "y": 8,
      "z": 7,
      "name": "Soil_Sand"
    },
    {
      "x": -4,
      "y": 9,
      "z": 7,
      "name": "Soil_Sand"
    },
    {
      "x": -4,
      "y": 10,
      "z": 7,
      "name": "Soil_Sand"
    },
    {
      "x": -4,
      "y": 11,
      "z": 7,
      "name": "Soil_Sand"
    },
    {
      "x": -4,
      "y": 12,
      "z": 7,
      "name": "Soil_Clay_Lime"
    },
    {
      "x": -4,
      "y": 3,
      "z": 8,
      "name": "Soil_Clay_Lime"
    },
    {
      "x": -4,
      "y": 4,
      "z": 8,
      "name": "Soil_Clay_Lime"
    },
    {
      "x": -4,
      "y": 5,
      "z": 8,
      "name": "Soil_Clay_Lime"
    },
    {
      "x": -4,
      "y": 6,
      "z": 8,
      "name": "Soil_Clay_Lime"
    },
    {
      "x": -4,
      "y": 7,
      "z": 8,
      "name": "Soil_Clay_Lime"
    },
    {
      "x": -4,
      "y": 8,
      "z": 8,
      "name": "Soil_Clay_Lime"
    },
    {
      "x": -4,
      "y": 9,
      "z": 8,
      "name": "Plant_Moss_Block_Yellow"
    },
    {
      "x": -4,
      "y": 10,
      "z": 8,
      "name": "Plant_Moss_Block_Yellow"
    },
    {
      "x": -4,
      "y": 11,
      "z": 8,
      "name": "Soil_Clay_Lime"
    },
    {
      "x": -4,
      "y": 12,
      "z": 8,
      "name": "Soil_Clay_Lime"
    },
    {
      "x": -3,
      "y": 3,
      "z": -7,
      "name": "Plant_Moss_Block_Yellow"
    },
    {
      "x": -3,
      "y": 4,
      "z": -7,
      "name": "Plant_Moss_Block_Yellow"
    },
    {
      "x": -3,
      "y": 5,
      "z": -7,
      "name": "Plant_Moss_Block_Yellow"
    },
    {
      "x": -3,
      "y": 6,
      "z": -7,
      "name": "Plant_Moss_Block_Yellow"
    },
    {
      "x": -3,
      "y": 7,
      "z": -7,
      "name": "Soil_Clay_Lime"
    },
    {
      "x": -3,
      "y": 8,
      "z": -7,
      "name": "Soil_Clay_Lime"
    },
    {
      "x": -3,
      "y": 9,
      "z": -7,
      "name": "Soil_Clay_Lime"
    },
    {
      "x": -3,
      "y": 10,
      "z": -7,
      "name": "Soil_Clay_Lime"
    },
    {
      "x": -3,
      "y": 11,
      "z": -7,
      "name": "Soil_Clay_Lime"
    },
    {
      "x": -3,
      "y": 2,
      "z": -6,
      "name": "Soil_Clay_Lime"
    },
    {
      "x": -3,
      "y": 3,
      "z": -6,
      "name": "Soil_Sand"
    },
    {
      "x": -3,
      "y": 4,
      "z": -6,
      "name": "Soil_Sand"
    },
    {
      "x": -3,
      "y": 5,
      "z": -6,
      "name": "Soil_Sand"
    },
    {
      "x": -3,
      "y": 6,
      "z": -6,
      "name": "Soil_Sand"
    },
    {
      "x": -3,
      "y": 7,
      "z": -6,
      "name": "Soil_Sand"
    },
    {
      "x": -3,
      "y": 8,
      "z": -6,
      "name": "Soil_Sand"
    },
    {
      "x": -3,
      "y": 9,
      "z": -6,
      "name": "Soil_Sand"
    },
    {
      "x": -3,
      "y": 10,
      "z": -6,
      "name": "Soil_Sand"
    },
    {
      "x": -3,
      "y": 11,
      "z": -6,
      "name": "Soil_Clay_Lime"
    },
    {
      "x": -3,
      "y": 13,
      "z": -6,
      "name": "Soil_Clay_Lime"
    },
    {
      "x": -3,
      "y": 14,
      "z": -6,
      "name": "Soil_Clay_Lime"
    },
    {
      "x": -3,
      "y": 15,
      "z": -6,
      "name": "Soil_Clay_Lime"
    },
    {
      "x": -3,
      "y": 1,
      "z": -5,
      "name": "Soil_Clay_Lime"
    },
    {
      "x": -3,
      "y": 2,
      "z": -5,
      "name": "Soil_Sand"
    },
    {
      "x": -3,
      "y": 3,
      "z": -5,
      "name": "Soil_Sand"
    },
    {
      "x": -3,
      "y": 4,
      "z": -5,
      "name": "Soil_Sand"
    },
    {
      "x": -3,
      "y": 5,
      "z": -5,
      "name": "Soil_Sand"
    },
    {
      "x": -3,
      "y": 6,
      "z": -5,
      "name": "Soil_Sand"
    },
    {
      "x": -3,
      "y": 7,
      "z": -5,
      "name": "Soil_Sand"
    },
    {
      "x": -3,
      "y": 8,
      "z": -5,
      "name": "Soil_Sand"
    },
    {
      "x": -3,
      "y": 9,
      "z": -5,
      "name": "Soil_Sand"
    },
    {
      "x": -3,
      "y": 10,
      "z": -5,
      "name": "Soil_Sand"
    },
    {
      "x": -3,
      "y": 11,
      "z": -5,
      "name": "Soil_Sand"
    },
    {
      "x": -3,
      "y": 12,
      "z": -5,
      "name": "Soil_Clay_Lime"
    },
    {
      "x": -3,
      "y": 13,
      "z": -5,
      "name": "Soil_Sand"
    },
    {
      "x": -3,
      "y": 14,
      "z": -5,
      "name": "Soil_Sand"
    },
    {
      "x": -3,
      "y": 15,
      "z": -5,
      "name": "Soil_Sand"
    },
    {
      "x": -3,
      "y": 16,
      "z": -5,
      "name": "Plant_Flower_Bushy_Yellow"
    },
    {
      "x": -3,
      "y": 1,
      "z": -4,
      "name": "Soil_Clay_Lime"
    },
    {
      "x": -3,
      "y": 2,
      "z": -4,
      "name": "Soil_Sand"
    },
    {
      "x": -3,
      "y": 3,
      "z": -4,
      "name": "Soil_Sand"
    },
    {
      "x": -3,
      "y": 4,
      "z": -4,
      "name": "Soil_Sand"
    },
    {
      "x": -3,
      "y": 5,
      "z": -4,
      "name": "Soil_Sand"
    },
    {
      "x": -3,
      "y": 6,
      "z": -4,
      "name": "Soil_Sand"
    },
    {
      "x": -3,
      "y": 7,
      "z": -4,
      "name": "Soil_Sand"
    },
    {
      "x": -3,
      "y": 8,
      "z": -4,
      "name": "Soil_Sand"
    },
    {
      "x": -3,
      "y": 9,
      "z": -4,
      "name": "Soil_Sand"
    },
    {
      "x": -3,
      "y": 10,
      "z": -4,
      "name": "Soil_Sand"
    },
    {
      "x": -3,
      "y": 11,
      "z": -4,
      "name": "Soil_Sand"
    },
    {
      "x": -3,
      "y": 12,
      "z": -4,
      "name": "Soil_Sand"
    },
    {
      "x": -3,
      "y": 13,
      "z": -4,
      "name": "Soil_Sand"
    },
    {
      "x": -3,
      "y": 14,
      "z": -4,
      "name": "Soil_Sand"
    },
    {
      "x": -3,
      "y": 15,
      "z": -4,
      "name": "Soil_Sand"
    },
    {
      "x": -3,
      "y": 16,
      "z": -4,
      "name": "Plant_Flower_Bushy_Yellow"
    },
    {
      "x": -3,
      "y": 1,
      "z": -3,
      "name": "Soil_Clay_Lime"
    },
    {
      "x": -3,
      "y": 2,
      "z": -3,
      "name": "Soil_Sand"
    },
    {
      "x": -3,
      "y": 3,
      "z": -3,
      "name": "Soil_Sand"
    },
    {
      "x": -3,
      "y": 4,
      "z": -3,
      "name": "Soil_Sand"
    },
    {
      "x": -3,
      "y": 5,
      "z": -3,
      "name": "Soil_Sand"
    },
    {
      "x": -3,
      "y": 6,
      "z": -3,
      "name": "Soil_Sand"
    },
    {
      "x": -3,
      "y": 7,
      "z": -3,
      "name": "Soil_Sand"
    },
    {
      "x": -3,
      "y": 8,
      "z": -3,
      "name": "Soil_Sand"
    },
    {
      "x": -3,
      "y": 9,
      "z": -3,
      "name": "Soil_Sand"
    },
    {
      "x": -3,
      "y": 10,
      "z": -3,
      "name": "Soil_Sand"
    },
    {
      "x": -3,
      "y": 11,
      "z": -3,
      "name": "Soil_Sand"
    },
    {
      "x": -3,
      "y": 12,
      "z": -3,
      "name": "Soil_Sand"
    },
    {
      "x": -3,
      "y": 13,
      "z": -3,
      "name": "Soil_Sand"
    },
    {
      "x": -3,
      "y": 14,
      "z": -3,
      "name": "Soil_Sand"
    },
    {
      "x": -3,
      "y": 15,
      "z": -3,
      "name": "Soil_Sand"
    },
    {
      "x": -3,
      "y": 16,
      "z": -3,
      "name": "Soil_Sand"
    },
    {
      "x": -3,
      "y": 17,
      "z": -3,
      "name": "Plant_Flower_Bushy_Yellow"
    },
    {
      "x": -3,
      "y": 1,
      "z": -2,
      "name": "Soil_Clay_Lime"
    },
    {
      "x": -3,
      "y": 2,
      "z": -2,
      "name": "Soil_Sand"
    },
    {
      "x": -3,
      "y": 3,
      "z": -2,
      "name": "Soil_Sand"
    },
    {
      "x": -3,
      "y": 4,
      "z": -2,
      "name": "Soil_Sand"
    },
    {
      "x": -3,
      "y": 5,
      "z": -2,
      "name": "Soil_Sand"
    },
    {
      "x": -3,
      "y": 6,
      "z": -2,
      "name": "Soil_Sand"
    },
    {
      "x": -3,
      "y": 7,
      "z": -2,
      "name": "Soil_Sand"
    },
    {
      "x": -3,
      "y": 8,
      "z": -2,
      "name": "Soil_Sand"
    },
    {
      "x": -3,
      "y": 9,
      "z": -2,
      "name": "Soil_Sand"
    },
    {
      "x": -3,
      "y": 10,
      "z": -2,
      "name": "Soil_Sand"
    },
    {
      "x": -3,
      "y": 11,
      "z": -2,
      "name": "Soil_Sand"
    },
    {
      "x": -3,
      "y": 12,
      "z": -2,
      "name": "Soil_Sand"
    },
    {
      "x": -3,
      "y": 13,
      "z": -2,
      "name": "Soil_Sand"
    },
    {
      "x": -3,
      "y": 14,
      "z": -2,
      "name": "Soil_Sand"
    },
    {
      "x": -3,
      "y": 15,
      "z": -2,
      "name": "Soil_Sand"
    },
    {
      "x": -3,
      "y": 16,
      "z": -2,
      "name": "Soil_Sand"
    },
    {
      "x": -3,
      "y": 17,
      "z": -2,
      "name": "Plant_Flower_Bushy_Yellow"
    },
    {
      "x": -3,
      "y": 0,
      "z": -1,
      "name": "Rock_Stone_Mossy"
    },
    {
      "x": -3,
      "y": 1,
      "z": -1,
      "name": "Soil_Sand"
    },
    {
      "x": -3,
      "y": 2,
      "z": -1,
      "name": "Soil_Sand"
    },
    {
      "x": -3,
      "y": 3,
      "z": -1,
      "name": "Soil_Sand"
    },
    {
      "x": -3,
      "y": 4,
      "z": -1,
      "name": "Soil_Sand"
    },
    {
      "x": -3,
      "y": 5,
      "z": -1,
      "name": "Soil_Sand"
    },
    {
      "x": -3,
      "y": 6,
      "z": -1,
      "name": "Soil_Sand"
    },
    {
      "x": -3,
      "y": 7,
      "z": -1,
      "name": "Soil_Sand"
    },
    {
      "x": -3,
      "y": 8,
      "z": -1,
      "name": "Soil_Sand"
    },
    {
      "x": -3,
      "y": 9,
      "z": -1,
      "name": "Soil_Sand"
    },
    {
      "x": -3,
      "y": 10,
      "z": -1,
      "name": "Soil_Sand"
    },
    {
      "x": -3,
      "y": 11,
      "z": -1,
      "name": "Soil_Sand"
    },
    {
      "x": -3,
      "y": 12,
      "z": -1,
      "name": "Soil_Sand"
    },
    {
      "x": -3,
      "y": 13,
      "z": -1,
      "name": "Soil_Sand"
    },
    {
      "x": -3,
      "y": 14,
      "z": -1,
      "name": "Soil_Sand"
    },
    {
      "x": -3,
      "y": 15,
      "z": -1,
      "name": "Soil_Sand"
    },
    {
      "x": -3,
      "y": 16,
      "z": -1,
      "name": "Soil_Sand"
    },
    {
      "x": -3,
      "y": 17,
      "z": -1,
      "name": "Plant_Flower_Bushy_Yellow"
    },
    {
      "x": -3,
      "y": 0,
      "z": 0,
      "name": "Soil_Clay_Lime"
    },
    {
      "x": -3,
      "y": 1,
      "z": 0,
      "name": "Soil_Sand"
    },
    {
      "x": -3,
      "y": 2,
      "z": 0,
      "name": "Soil_Sand"
    },
    {
      "x": -3,
      "y": 3,
      "z": 0,
      "name": "Soil_Sand"
    },
    {
      "x": -3,
      "y": 4,
      "z": 0,
      "name": "Soil_Sand"
    },
    {
      "x": -3,
      "y": 5,
      "z": 0,
      "name": "Soil_Sand"
    },
    {
      "x": -3,
      "y": 6,
      "z": 0,
      "name": "Soil_Sand"
    },
    {
      "x": -3,
      "y": 7,
      "z": 0,
      "name": "Soil_Sand"
    },
    {
      "x": -3,
      "y": 8,
      "z": 0,
      "name": "Soil_Sand"
    },
    {
      "x": -3,
      "y": 9,
      "z": 0,
      "name": "Soil_Sand"
    },
    {
      "x": -3,
      "y": 10,
      "z": 0,
      "name": "Soil_Sand"
    },
    {
      "x": -3,
      "y": 11,
      "z": 0,
      "name": "Soil_Sand"
    },
    {
      "x": -3,
      "y": 12,
      "z": 0,
      "name": "Soil_Sand"
    },
    {
      "x": -3,
      "y": 13,
      "z": 0,
      "name": "Soil_Sand"
    },
    {
      "x": -3,
      "y": 14,
      "z": 0,
      "name": "Soil_Sand"
    },
    {
      "x": -3,
      "y": 15,
      "z": 0,
      "name": "Soil_Sand"
    },
    {
      "x": -3,
      "y": 16,
      "z": 0,
      "name": "Soil_Sand"
    },
    {
      "x": -3,
      "y": 17,
      "z": 0,
      "name": "Plant_Leaves_Palm_Arid"
    },
    {
      "x": -3,
      "y": 0,
      "z": 1,
      "name": "Soil_Clay_Lime"
    },
    {
      "x": -3,
      "y": 1,
      "z": 1,
      "name": "Soil_Sand"
    },
    {
      "x": -3,
      "y": 2,
      "z": 1,
      "name": "Soil_Sand"
    },
    {
      "x": -3,
      "y": 3,
      "z": 1,
      "name": "Soil_Sand"
    },
    {
      "x": -3,
      "y": 4,
      "z": 1,
      "name": "Soil_Sand"
    },
    {
      "x": -3,
      "y": 5,
      "z": 1,
      "name": "Soil_Sand"
    },
    {
      "x": -3,
      "y": 6,
      "z": 1,
      "name": "Soil_Sand"
    },
    {
      "x": -3,
      "y": 7,
      "z": 1,
      "name": "Soil_Sand"
    },
    {
      "x": -3,
      "y": 8,
      "z": 1,
      "name": "Soil_Sand"
    },
    {
      "x": -3,
      "y": 9,
      "z": 1,
      "name": "Soil_Sand"
    },
    {
      "x": -3,
      "y": 10,
      "z": 1,
      "name": "Soil_Sand"
    },
    {
      "x": -3,
      "y": 11,
      "z": 1,
      "name": "Soil_Sand"
    },
    {
      "x": -3,
      "y": 12,
      "z": 1,
      "name": "Soil_Sand"
    },
    {
      "x": -3,
      "y": 13,
      "z": 1,
      "name": "Soil_Sand"
    },
    {
      "x": -3,
      "y": 14,
      "z": 1,
      "name": "Soil_Sand"
    },
    {
      "x": -3,
      "y": 15,
      "z": 1,
      "name": "Soil_Sand"
    },
    {
      "x": -3,
      "y": 16,
      "z": 1,
      "name": "Soil_Sand"
    },
    {
      "x": -3,
      "y": 17,
      "z": 1,
      "name": "Plant_Leaves_Palm_Arid"
    },
    {
      "x": -3,
      "y": 0,
      "z": 2,
      "name": "Soil_Clay_Lime"
    },
    {
      "x": -3,
      "y": 1,
      "z": 2,
      "name": "Soil_Sand"
    },
    {
      "x": -3,
      "y": 2,
      "z": 2,
      "name": "Soil_Sand"
    },
    {
      "x": -3,
      "y": 3,
      "z": 2,
      "name": "Soil_Sand"
    },
    {
      "x": -3,
      "y": 4,
      "z": 2,
      "name": "Soil_Sand"
    },
    {
      "x": -3,
      "y": 5,
      "z": 2,
      "name": "Soil_Sand"
    },
    {
      "x": -3,
      "y": 6,
      "z": 2,
      "name": "Soil_Sand"
    },
    {
      "x": -3,
      "y": 7,
      "z": 2,
      "name": "Soil_Sand"
    },
    {
      "x": -3,
      "y": 8,
      "z": 2,
      "name": "Soil_Sand"
    },
    {
      "x": -3,
      "y": 9,
      "z": 2,
      "name": "Soil_Sand"
    },
    {
      "x": -3,
      "y": 10,
      "z": 2,
      "name": "Soil_Sand"
    },
    {
      "x": -3,
      "y": 11,
      "z": 2,
      "name": "Soil_Sand"
    },
    {
      "x": -3,
      "y": 12,
      "z": 2,
      "name": "Soil_Sand"
    },
    {
      "x": -3,
      "y": 13,
      "z": 2,
      "name": "Soil_Sand"
    },
    {
      "x": -3,
      "y": 14,
      "z": 2,
      "name": "Soil_Sand"
    },
    {
      "x": -3,
      "y": 15,
      "z": 2,
      "name": "Soil_Sand"
    },
    {
      "x": -3,
      "y": 16,
      "z": 2,
      "name": "Soil_Sand"
    },
    {
      "x": -3,
      "y": 17,
      "z": 2,
      "name": "Plant_Leaves_Palm_Arid"
    },
    {
      "x": -3,
      "y": 1,
      "z": 3,
      "name": "Plant_Moss_Block_Yellow"
    },
    {
      "x": -3,
      "y": 2,
      "z": 3,
      "name": "Soil_Sand"
    },
    {
      "x": -3,
      "y": 3,
      "z": 3,
      "name": "Soil_Sand"
    },
    {
      "x": -3,
      "y": 4,
      "z": 3,
      "name": "Soil_Sand"
    },
    {
      "x": -3,
      "y": 5,
      "z": 3,
      "name": "Soil_Sand"
    },
    {
      "x": -3,
      "y": 6,
      "z": 3,
      "name": "Soil_Sand"
    },
    {
      "x": -3,
      "y": 7,
      "z": 3,
      "name": "Soil_Sand"
    },
    {
      "x": -3,
      "y": 8,
      "z": 3,
      "name": "Soil_Sand"
    },
    {
      "x": -3,
      "y": 9,
      "z": 3,
      "name": "Soil_Sand"
    },
    {
      "x": -3,
      "y": 10,
      "z": 3,
      "name": "Soil_Sand"
    },
    {
      "x": -3,
      "y": 11,
      "z": 3,
      "name": "Soil_Sand"
    },
    {
      "x": -3,
      "y": 12,
      "z": 3,
      "name": "Soil_Sand"
    },
    {
      "x": -3,
      "y": 13,
      "z": 3,
      "name": "Soil_Sand"
    },
    {
      "x": -3,
      "y": 14,
      "z": 3,
      "name": "Soil_Sand"
    },
    {
      "x": -3,
      "y": 15,
      "z": 3,
      "name": "Soil_Sand"
    },
    {
      "x": -3,
      "y": 16,
      "z": 3,
      "name": "Soil_Sand"
    },
    {
      "x": -3,
      "y": 17,
      "z": 3,
      "name": "Plant_Leaves_Palm_Arid"
    },
    {
      "x": -3,
      "y": 2,
      "z": 4,
      "name": "Soil_Clay_Lime"
    },
    {
      "x": -3,
      "y": 3,
      "z": 4,
      "name": "Soil_Sand"
    },
    {
      "x": -3,
      "y": 4,
      "z": 4,
      "name": "Soil_Sand"
    },
    {
      "x": -3,
      "y": 5,
      "z": 4,
      "name": "Soil_Sand"
    },
    {
      "x": -3,
      "y": 6,
      "z": 4,
      "name": "Soil_Sand"
    },
    {
      "x": -3,
      "y": 7,
      "z": 4,
      "name": "Soil_Sand"
    },
    {
      "x": -3,
      "y": 8,
      "z": 4,
      "name": "Soil_Sand"
    },
    {
      "x": -3,
      "y": 9,
      "z": 4,
      "name": "Soil_Sand"
    },
    {
      "x": -3,
      "y": 10,
      "z": 4,
      "name": "Soil_Sand"
    },
    {
      "x": -3,
      "y": 11,
      "z": 4,
      "name": "Soil_Sand"
    },
    {
      "x": -3,
      "y": 12,
      "z": 4,
      "name": "Soil_Sand"
    },
    {
      "x": -3,
      "y": 13,
      "z": 4,
      "name": "Soil_Sand"
    },
    {
      "x": -3,
      "y": 14,
      "z": 4,
      "name": "Soil_Sand"
    },
    {
      "x": -3,
      "y": 15,
      "z": 4,
      "name": "Soil_Sand"
    },
    {
      "x": -3,
      "y": 16,
      "z": 4,
      "name": "Plant_Flower_Bushy_Yellow"
    },
    {
      "x": -3,
      "y": 2,
      "z": 5,
      "name": "Soil_Clay_Lime"
    },
    {
      "x": -3,
      "y": 3,
      "z": 5,
      "name": "Soil_Sand"
    },
    {
      "x": -3,
      "y": 4,
      "z": 5,
      "name": "Soil_Sand"
    },
    {
      "x": -3,
      "y": 5,
      "z": 5,
      "name": "Soil_Sand"
    },
    {
      "x": -3,
      "y": 6,
      "z": 5,
      "name": "Soil_Sand"
    },
    {
      "x": -3,
      "y": 7,
      "z": 5,
      "name": "Soil_Sand"
    },
    {
      "x": -3,
      "y": 8,
      "z": 5,
      "name": "Soil_Sand"
    },
    {
      "x": -3,
      "y": 9,
      "z": 5,
      "name": "Soil_Sand"
    },
    {
      "x": -3,
      "y": 10,
      "z": 5,
      "name": "Soil_Sand"
    },
    {
      "x": -3,
      "y": 11,
      "z": 5,
      "name": "Soil_Sand"
    },
    {
      "x": -3,
      "y": 12,
      "z": 5,
      "name": "Soil_Sand"
    },
    {
      "x": -3,
      "y": 13,
      "z": 5,
      "name": "Soil_Sand"
    },
    {
      "x": -3,
      "y": 14,
      "z": 5,
      "name": "Soil_Sand"
    },
    {
      "x": -3,
      "y": 15,
      "z": 5,
      "name": "Soil_Sand"
    },
    {
      "x": -3,
      "y": 16,
      "z": 5,
      "name": "Plant_Flower_Bushy_Yellow"
    },
    {
      "x": -3,
      "y": 3,
      "z": 6,
      "name": "Soil_Clay_Lime"
    },
    {
      "x": -3,
      "y": 4,
      "z": 6,
      "name": "Soil_Sand"
    },
    {
      "x": -3,
      "y": 5,
      "z": 6,
      "name": "Soil_Sand"
    },
    {
      "x": -3,
      "y": 6,
      "z": 6,
      "name": "Soil_Sand"
    },
    {
      "x": -3,
      "y": 7,
      "z": 6,
      "name": "Soil_Sand"
    },
    {
      "x": -3,
      "y": 8,
      "z": 6,
      "name": "Soil_Sand"
    },
    {
      "x": -3,
      "y": 9,
      "z": 6,
      "name": "Soil_Sand"
    },
    {
      "x": -3,
      "y": 10,
      "z": 6,
      "name": "Soil_Sand"
    },
    {
      "x": -3,
      "y": 11,
      "z": 6,
      "name": "Soil_Sand"
    },
    {
      "x": -3,
      "y": 12,
      "z": 6,
      "name": "Soil_Sand"
    },
    {
      "x": -3,
      "y": 13,
      "z": 6,
      "name": "Soil_Sand"
    },
    {
      "x": -3,
      "y": 14,
      "z": 6,
      "name": "Soil_Sand"
    },
    {
      "x": -3,
      "y": 15,
      "z": 6,
      "name": "Soil_Sand"
    },
    {
      "x": -3,
      "y": 16,
      "z": 6,
      "name": "Plant_Flower_Bushy_Yellow"
    },
    {
      "x": -3,
      "y": 3,
      "z": 7,
      "name": "Soil_Clay_Lime"
    },
    {
      "x": -3,
      "y": 4,
      "z": 7,
      "name": "Soil_Sand"
    },
    {
      "x": -3,
      "y": 5,
      "z": 7,
      "name": "Soil_Sand"
    },
    {
      "x": -3,
      "y": 6,
      "z": 7,
      "name": "Soil_Sand"
    },
    {
      "x": -3,
      "y": 7,
      "z": 7,
      "name": "Soil_Sand"
    },
    {
      "x": -3,
      "y": 8,
      "z": 7,
      "name": "Soil_Sand"
    },
    {
      "x": -3,
      "y": 9,
      "z": 7,
      "name": "Soil_Sand"
    },
    {
      "x": -3,
      "y": 10,
      "z": 7,
      "name": "Soil_Sand"
    },
    {
      "x": -3,
      "y": 11,
      "z": 7,
      "name": "Soil_Clay_Lime"
    },
    {
      "x": -3,
      "y": 3,
      "z": 8,
      "name": "Soil_Clay_Lime"
    },
    {
      "x": -3,
      "y": 4,
      "z": 8,
      "name": "Soil_Clay_Lime"
    },
    {
      "x": -3,
      "y": 5,
      "z": 8,
      "name": "Soil_Clay_Lime"
    },
    {
      "x": -3,
      "y": 6,
      "z": 8,
      "name": "Soil_Clay_Lime"
    },
    {
      "x": -3,
      "y": 7,
      "z": 8,
      "name": "Plant_Moss_Block_Yellow"
    },
    {
      "x": -3,
      "y": 8,
      "z": 8,
      "name": "Plant_Moss_Block_Yellow"
    },
    {
      "x": -3,
      "y": 9,
      "z": 8,
      "name": "Plant_Moss_Block_Yellow"
    },
    {
      "x": -3,
      "y": 10,
      "z": 8,
      "name": "Soil_Clay_Lime"
    },
    {
      "x": -3,
      "y": 11,
      "z": 8,
      "name": "Soil_Clay_Lime"
    },
    {
      "x": -2,
      "y": 2,
      "z": -7,
      "name": "Soil_Clay_Lime"
    },
    {
      "x": -2,
      "y": 3,
      "z": -7,
      "name": "Soil_Clay_Lime"
    },
    {
      "x": -2,
      "y": 4,
      "z": -7,
      "name": "Plant_Moss_Block_Yellow"
    },
    {
      "x": -2,
      "y": 5,
      "z": -7,
      "name": "Plant_Moss_Block_Yellow"
    },
    {
      "x": -2,
      "y": 6,
      "z": -7,
      "name": "Soil_Clay_Lime"
    },
    {
      "x": -2,
      "y": 7,
      "z": -7,
      "name": "Soil_Clay_Lime"
    },
    {
      "x": -2,
      "y": 8,
      "z": -7,
      "name": "Soil_Clay_Lime"
    },
    {
      "x": -2,
      "y": 9,
      "z": -7,
      "name": "Soil_Clay_Lime"
    },
    {
      "x": -2,
      "y": 10,
      "z": -7,
      "name": "Soil_Clay_Lime"
    },
    {
      "x": -2,
      "y": 11,
      "z": -7,
      "name": "Soil_Clay_Lime"
    },
    {
      "x": -2,
      "y": 12,
      "z": -7,
      "name": "Rock_Stone_Mossy"
    },
    {
      "x": -2,
      "y": 2,
      "z": -6,
      "name": "Rock_Stone_Mossy"
    },
    {
      "x": -2,
      "y": 3,
      "z": -6,
      "name": "Soil_Sand"
    },
    {
      "x": -2,
      "y": 4,
      "z": -6,
      "name": "Soil_Sand"
    },
    {
      "x": -2,
      "y": 5,
      "z": -6,
      "name": "Soil_Sand"
    },
    {
      "x": -2,
      "y": 6,
      "z": -6,
      "name": "Soil_Sand"
    },
    {
      "x": -2,
      "y": 7,
      "z": -6,
      "name": "Soil_Sand"
    },
    {
      "x": -2,
      "y": 8,
      "z": -6,
      "name": "Soil_Sand"
    },
    {
      "x": -2,
      "y": 9,
      "z": -6,
      "name": "Soil_Sand"
    },
    {
      "x": -2,
      "y": 10,
      "z": -6,
      "name": "Soil_Sand"
    },
    {
      "x": -2,
      "y": 11,
      "z": -6,
      "name": "Soil_Sand"
    },
    {
      "x": -2,
      "y": 12,
      "z": -6,
      "name": "Soil_Clay_Lime"
    },
    {
      "x": -2,
      "y": 13,
      "z": -6,
      "name": "Soil_Clay_Lime"
    },
    {
      "x": -2,
      "y": 14,
      "z": -6,
      "name": "Soil_Clay_Lime"
    },
    {
      "x": -2,
      "y": 15,
      "z": -6,
      "name": "Soil_Clay_Lime"
    },
    {
      "x": -2,
      "y": 1,
      "z": -5,
      "name": "Rock_Stone_Mossy"
    },
    {
      "x": -2,
      "y": 2,
      "z": -5,
      "name": "Soil_Sand"
    },
    {
      "x": -2,
      "y": 3,
      "z": -5,
      "name": "Soil_Sand"
    },
    {
      "x": -2,
      "y": 4,
      "z": -5,
      "name": "Soil_Sand"
    },
    {
      "x": -2,
      "y": 5,
      "z": -5,
      "name": "Soil_Sand"
    },
    {
      "x": -2,
      "y": 6,
      "z": -5,
      "name": "Soil_Sand"
    },
    {
      "x": -2,
      "y": 7,
      "z": -5,
      "name": "Soil_Sand"
    },
    {
      "x": -2,
      "y": 8,
      "z": -5,
      "name": "Soil_Sand"
    },
    {
      "x": -2,
      "y": 9,
      "z": -5,
      "name": "Soil_Sand"
    },
    {
      "x": -2,
      "y": 10,
      "z": -5,
      "name": "Soil_Sand"
    },
    {
      "x": -2,
      "y": 11,
      "z": -5,
      "name": "Soil_Sand"
    },
    {
      "x": -2,
      "y": 12,
      "z": -5,
      "name": "Soil_Sand"
    },
    {
      "x": -2,
      "y": 13,
      "z": -5,
      "name": "Soil_Sand"
    },
    {
      "x": -2,
      "y": 14,
      "z": -5,
      "name": "Soil_Sand"
    },
    {
      "x": -2,
      "y": 15,
      "z": -5,
      "name": "Soil_Sand"
    },
    {
      "x": -2,
      "y": 16,
      "z": -5,
      "name": "Plant_Flower_Bushy_Yellow"
    },
    {
      "x": -2,
      "y": 1,
      "z": -4,
      "name": "Rock_Stone_Mossy"
    },
    {
      "x": -2,
      "y": 2,
      "z": -4,
      "name": "Soil_Sand"
    },
    {
      "x": -2,
      "y": 3,
      "z": -4,
      "name": "Soil_Sand"
    },
    {
      "x": -2,
      "y": 4,
      "z": -4,
      "name": "Soil_Sand"
    },
    {
      "x": -2,
      "y": 5,
      "z": -4,
      "name": "Soil_Sand"
    },
    {
      "x": -2,
      "y": 6,
      "z": -4,
      "name": "Soil_Sand"
    },
    {
      "x": -2,
      "y": 7,
      "z": -4,
      "name": "Soil_Sand"
    },
    {
      "x": -2,
      "y": 8,
      "z": -4,
      "name": "Soil_Sand"
    },
    {
      "x": -2,
      "y": 9,
      "z": -4,
      "name": "Soil_Sand"
    },
    {
      "x": -2,
      "y": 10,
      "z": -4,
      "name": "Soil_Sand"
    },
    {
      "x": -2,
      "y": 11,
      "z": -4,
      "name": "Soil_Sand"
    },
    {
      "x": -2,
      "y": 12,
      "z": -4,
      "name": "Soil_Sand"
    },
    {
      "x": -2,
      "y": 13,
      "z": -4,
      "name": "Soil_Sand"
    },
    {
      "x": -2,
      "y": 14,
      "z": -4,
      "name": "Soil_Sand"
    },
    {
      "x": -2,
      "y": 15,
      "z": -4,
      "name": "Soil_Sand"
    },
    {
      "x": -2,
      "y": 16,
      "z": -4,
      "name": "Soil_Sand"
    },
    {
      "x": -2,
      "y": 17,
      "z": -4,
      "name": "Plant_Flower_Bushy_Yellow"
    },
    {
      "x": -2,
      "y": 1,
      "z": -3,
      "name": "Rock_Stone_Mossy"
    },
    {
      "x": -2,
      "y": 2,
      "z": -3,
      "name": "Soil_Sand"
    },
    {
      "x": -2,
      "y": 3,
      "z": -3,
      "name": "Soil_Sand"
    },
    {
      "x": -2,
      "y": 4,
      "z": -3,
      "name": "Soil_Sand"
    },
    {
      "x": -2,
      "y": 5,
      "z": -3,
      "name": "Soil_Sand"
    },
    {
      "x": -2,
      "y": 6,
      "z": -3,
      "name": "Soil_Sand"
    },
    {
      "x": -2,
      "y": 7,
      "z": -3,
      "name": "Soil_Sand"
    },
    {
      "x": -2,
      "y": 8,
      "z": -3,
      "name": "Soil_Sand"
    },
    {
      "x": -2,
      "y": 9,
      "z": -3,
      "name": "Soil_Sand"
    },
    {
      "x": -2,
      "y": 10,
      "z": -3,
      "name": "Soil_Sand"
    },
    {
      "x": -2,
      "y": 11,
      "z": -3,
      "name": "Soil_Sand"
    },
    {
      "x": -2,
      "y": 12,
      "z": -3,
      "name": "Soil_Sand"
    },
    {
      "x": -2,
      "y": 13,
      "z": -3,
      "name": "Soil_Sand"
    },
    {
      "x": -2,
      "y": 14,
      "z": -3,
      "name": "Soil_Sand"
    },
    {
      "x": -2,
      "y": 15,
      "z": -3,
      "name": "Soil_Sand"
    },
    {
      "x": -2,
      "y": 16,
      "z": -3,
      "name": "Soil_Sand"
    },
    {
      "x": -2,
      "y": 17,
      "z": -3,
      "name": "Plant_Flower_Bushy_Yellow"
    },
    {
      "x": -2,
      "y": 0,
      "z": -2,
      "name": "Rock_Stone_Mossy"
    },
    {
      "x": -2,
      "y": 1,
      "z": -2,
      "name": "Soil_Sand"
    },
    {
      "x": -2,
      "y": 2,
      "z": -2,
      "name": "Soil_Sand"
    },
    {
      "x": -2,
      "y": 3,
      "z": -2,
      "name": "Soil_Sand"
    },
    {
      "x": -2,
      "y": 4,
      "z": -2,
      "name": "Soil_Sand"
    },
    {
      "x": -2,
      "y": 5,
      "z": -2,
      "name": "Soil_Sand"
    },
    {
      "x": -2,
      "y": 6,
      "z": -2,
      "name": "Soil_Sand"
    },
    {
      "x": -2,
      "y": 7,
      "z": -2,
      "name": "Soil_Sand"
    },
    {
      "x": -2,
      "y": 8,
      "z": -2,
      "name": "Soil_Sand"
    },
    {
      "x": -2,
      "y": 9,
      "z": -2,
      "name": "Soil_Sand"
    },
    {
      "x": -2,
      "y": 10,
      "z": -2,
      "name": "Soil_Sand"
    },
    {
      "x": -2,
      "y": 11,
      "z": -2,
      "name": "Soil_Sand"
    },
    {
      "x": -2,
      "y": 12,
      "z": -2,
      "name": "Soil_Sand"
    },
    {
      "x": -2,
      "y": 13,
      "z": -2,
      "name": "Soil_Sand"
    },
    {
      "x": -2,
      "y": 14,
      "z": -2,
      "name": "Soil_Sand"
    },
    {
      "x": -2,
      "y": 15,
      "z": -2,
      "name": "Soil_Sand"
    },
    {
      "x": -2,
      "y": 16,
      "z": -2,
      "name": "Soil_Sand"
    },
    {
      "x": -2,
      "y": 17,
      "z": -2,
      "name": "Plant_Flower_Bushy_Yellow"
    },
    {
      "x": -2,
      "y": 0,
      "z": -1,
      "name": "Soil_Sand"
    },
    {
      "x": -2,
      "y": 1,
      "z": -1,
      "name": "Soil_Sand"
    },
    {
      "x": -2,
      "y": 2,
      "z": -1,
      "name": "Soil_Sand"
    },
    {
      "x": -2,
      "y": 3,
      "z": -1,
      "name": "Soil_Sand"
    },
    {
      "x": -2,
      "y": 4,
      "z": -1,
      "name": "Soil_Sand"
    },
    {
      "x": -2,
      "y": 5,
      "z": -1,
      "name": "Soil_Sand"
    },
    {
      "x": -2,
      "y": 6,
      "z": -1,
      "name": "Soil_Sand"
    },
    {
      "x": -2,
      "y": 7,
      "z": -1,
      "name": "Soil_Sand"
    },
    {
      "x": -2,
      "y": 8,
      "z": -1,
      "name": "Soil_Sand"
    },
    {
      "x": -2,
      "y": 9,
      "z": -1,
      "name": "Soil_Sand"
    },
    {
      "x": -2,
      "y": 10,
      "z": -1,
      "name": "Soil_Sand"
    },
    {
      "x": -2,
      "y": 11,
      "z": -1,
      "name": "Soil_Sand"
    },
    {
      "x": -2,
      "y": 12,
      "z": -1,
      "name": "Soil_Sand"
    },
    {
      "x": -2,
      "y": 13,
      "z": -1,
      "name": "Soil_Sand"
    },
    {
      "x": -2,
      "y": 14,
      "z": -1,
      "name": "Soil_Sand"
    },
    {
      "x": -2,
      "y": 15,
      "z": -1,
      "name": "Soil_Sand"
    },
    {
      "x": -2,
      "y": 16,
      "z": -1,
      "name": "Soil_Sand"
    },
    {
      "x": -2,
      "y": 17,
      "z": -1,
      "name": "Plant_Flower_Bushy_Yellow"
    },
    {
      "x": -2,
      "y": 0,
      "z": 0,
      "name": "Soil_Sand"
    },
    {
      "x": -2,
      "y": 1,
      "z": 0,
      "name": "Soil_Sand"
    },
    {
      "x": -2,
      "y": 2,
      "z": 0,
      "name": "Soil_Sand"
    },
    {
      "x": -2,
      "y": 3,
      "z": 0,
      "name": "Soil_Sand"
    },
    {
      "x": -2,
      "y": 4,
      "z": 0,
      "name": "Soil_Sand"
    },
    {
      "x": -2,
      "y": 5,
      "z": 0,
      "name": "Soil_Sand"
    },
    {
      "x": -2,
      "y": 6,
      "z": 0,
      "name": "Soil_Sand"
    },
    {
      "x": -2,
      "y": 7,
      "z": 0,
      "name": "Soil_Sand"
    },
    {
      "x": -2,
      "y": 8,
      "z": 0,
      "name": "Soil_Sand"
    },
    {
      "x": -2,
      "y": 9,
      "z": 0,
      "name": "Soil_Sand"
    },
    {
      "x": -2,
      "y": 10,
      "z": 0,
      "name": "Soil_Sand"
    },
    {
      "x": -2,
      "y": 11,
      "z": 0,
      "name": "Soil_Sand"
    },
    {
      "x": -2,
      "y": 12,
      "z": 0,
      "name": "Soil_Sand"
    },
    {
      "x": -2,
      "y": 13,
      "z": 0,
      "name": "Soil_Sand"
    },
    {
      "x": -2,
      "y": 14,
      "z": 0,
      "name": "Soil_Sand"
    },
    {
      "x": -2,
      "y": 15,
      "z": 0,
      "name": "Soil_Sand"
    },
    {
      "x": -2,
      "y": 16,
      "z": 0,
      "name": "Soil_Sand"
    },
    {
      "x": -2,
      "y": 17,
      "z": 0,
      "name": "Plant_Leaves_Palm_Arid"
    },
    {
      "x": -2,
      "y": 0,
      "z": 1,
      "name": "Soil_Clay_Lime"
    },
    {
      "x": -2,
      "y": 1,
      "z": 1,
      "name": "Soil_Sand"
    },
    {
      "x": -2,
      "y": 2,
      "z": 1,
      "name": "Soil_Sand"
    },
    {
      "x": -2,
      "y": 3,
      "z": 1,
      "name": "Soil_Sand"
    },
    {
      "x": -2,
      "y": 4,
      "z": 1,
      "name": "Soil_Sand"
    },
    {
      "x": -2,
      "y": 5,
      "z": 1,
      "name": "Soil_Sand"
    },
    {
      "x": -2,
      "y": 6,
      "z": 1,
      "name": "Soil_Sand"
    },
    {
      "x": -2,
      "y": 7,
      "z": 1,
      "name": "Soil_Sand"
    },
    {
      "x": -2,
      "y": 8,
      "z": 1,
      "name": "Soil_Sand"
    },
    {
      "x": -2,
      "y": 9,
      "z": 1,
      "name": "Soil_Sand"
    },
    {
      "x": -2,
      "y": 10,
      "z": 1,
      "name": "Soil_Sand"
    },
    {
      "x": -2,
      "y": 11,
      "z": 1,
      "name": "Soil_Sand"
    },
    {
      "x": -2,
      "y": 12,
      "z": 1,
      "name": "Soil_Sand"
    },
    {
      "x": -2,
      "y": 13,
      "z": 1,
      "name": "Soil_Sand"
    },
    {
      "x": -2,
      "y": 14,
      "z": 1,
      "name": "Soil_Sand"
    },
    {
      "x": -2,
      "y": 15,
      "z": 1,
      "name": "Soil_Sand"
    },
    {
      "x": -2,
      "y": 16,
      "z": 1,
      "name": "Soil_Sand"
    },
    {
      "x": -2,
      "y": 17,
      "z": 1,
      "name": "Plant_Leaves_Palm_Arid"
    },
    {
      "x": -2,
      "y": 1,
      "z": 2,
      "name": "Soil_Clay_Lime"
    },
    {
      "x": -2,
      "y": 2,
      "z": 2,
      "name": "Soil_Sand"
    },
    {
      "x": -2,
      "y": 3,
      "z": 2,
      "name": "Soil_Sand"
    },
    {
      "x": -2,
      "y": 4,
      "z": 2,
      "name": "Soil_Sand"
    },
    {
      "x": -2,
      "y": 5,
      "z": 2,
      "name": "Soil_Sand"
    },
    {
      "x": -2,
      "y": 6,
      "z": 2,
      "name": "Soil_Sand"
    },
    {
      "x": -2,
      "y": 7,
      "z": 2,
      "name": "Soil_Sand"
    },
    {
      "x": -2,
      "y": 8,
      "z": 2,
      "name": "Soil_Sand"
    },
    {
      "x": -2,
      "y": 9,
      "z": 2,
      "name": "Soil_Sand"
    },
    {
      "x": -2,
      "y": 10,
      "z": 2,
      "name": "Soil_Sand"
    },
    {
      "x": -2,
      "y": 11,
      "z": 2,
      "name": "Soil_Sand"
    },
    {
      "x": -2,
      "y": 12,
      "z": 2,
      "name": "Soil_Sand"
    },
    {
      "x": -2,
      "y": 13,
      "z": 2,
      "name": "Soil_Sand"
    },
    {
      "x": -2,
      "y": 14,
      "z": 2,
      "name": "Soil_Sand"
    },
    {
      "x": -2,
      "y": 15,
      "z": 2,
      "name": "Soil_Sand"
    },
    {
      "x": -2,
      "y": 16,
      "z": 2,
      "name": "Soil_Sand"
    },
    {
      "x": -2,
      "y": 17,
      "z": 2,
      "name": "Plant_Leaves_Palm_Arid"
    },
    {
      "x": -2,
      "y": 1,
      "z": 3,
      "name": "Soil_Clay_Lime"
    },
    {
      "x": -2,
      "y": 2,
      "z": 3,
      "name": "Soil_Sand"
    },
    {
      "x": -2,
      "y": 3,
      "z": 3,
      "name": "Soil_Sand"
    },
    {
      "x": -2,
      "y": 4,
      "z": 3,
      "name": "Soil_Sand"
    },
    {
      "x": -2,
      "y": 5,
      "z": 3,
      "name": "Soil_Sand"
    },
    {
      "x": -2,
      "y": 6,
      "z": 3,
      "name": "Soil_Sand"
    },
    {
      "x": -2,
      "y": 7,
      "z": 3,
      "name": "Soil_Sand"
    },
    {
      "x": -2,
      "y": 8,
      "z": 3,
      "name": "Soil_Sand"
    },
    {
      "x": -2,
      "y": 9,
      "z": 3,
      "name": "Soil_Sand"
    },
    {
      "x": -2,
      "y": 10,
      "z": 3,
      "name": "Soil_Sand"
    },
    {
      "x": -2,
      "y": 11,
      "z": 3,
      "name": "Soil_Sand"
    },
    {
      "x": -2,
      "y": 12,
      "z": 3,
      "name": "Soil_Sand"
    },
    {
      "x": -2,
      "y": 13,
      "z": 3,
      "name": "Soil_Sand"
    },
    {
      "x": -2,
      "y": 14,
      "z": 3,
      "name": "Soil_Sand"
    },
    {
      "x": -2,
      "y": 15,
      "z": 3,
      "name": "Soil_Sand"
    },
    {
      "x": -2,
      "y": 16,
      "z": 3,
      "name": "Soil_Sand"
    },
    {
      "x": -2,
      "y": 17,
      "z": 3,
      "name": "Plant_Flower_Bushy_Yellow"
    },
    {
      "x": -2,
      "y": 2,
      "z": 4,
      "name": "Soil_Clay_Lime"
    },
    {
      "x": -2,
      "y": 3,
      "z": 4,
      "name": "Soil_Sand"
    },
    {
      "x": -2,
      "y": 4,
      "z": 4,
      "name": "Soil_Sand"
    },
    {
      "x": -2,
      "y": 5,
      "z": 4,
      "name": "Soil_Sand"
    },
    {
      "x": -2,
      "y": 6,
      "z": 4,
      "name": "Soil_Sand"
    },
    {
      "x": -2,
      "y": 7,
      "z": 4,
      "name": "Soil_Sand"
    },
    {
      "x": -2,
      "y": 8,
      "z": 4,
      "name": "Soil_Sand"
    },
    {
      "x": -2,
      "y": 9,
      "z": 4,
      "name": "Soil_Sand"
    },
    {
      "x": -2,
      "y": 10,
      "z": 4,
      "name": "Soil_Sand"
    },
    {
      "x": -2,
      "y": 11,
      "z": 4,
      "name": "Soil_Sand"
    },
    {
      "x": -2,
      "y": 12,
      "z": 4,
      "name": "Soil_Sand"
    },
    {
      "x": -2,
      "y": 13,
      "z": 4,
      "name": "Soil_Sand"
    },
    {
      "x": -2,
      "y": 14,
      "z": 4,
      "name": "Soil_Sand"
    },
    {
      "x": -2,
      "y": 15,
      "z": 4,
      "name": "Soil_Sand"
    },
    {
      "x": -2,
      "y": 16,
      "z": 4,
      "name": "Plant_Flower_Bushy_Yellow"
    },
    {
      "x": -2,
      "y": 2,
      "z": 5,
      "name": "Soil_Clay_Lime"
    },
    {
      "x": -2,
      "y": 3,
      "z": 5,
      "name": "Soil_Sand"
    },
    {
      "x": -2,
      "y": 4,
      "z": 5,
      "name": "Soil_Sand"
    },
    {
      "x": -2,
      "y": 5,
      "z": 5,
