{
  "version": 8,
  "blockIdVersion": 10,
  "anchorX": 0,
  "anchorY": 8,
  "anchorZ": 0,
  "blocks": [
    {
      "x": -8,
      "y": 6,
      "z": 0,
      "name": "Plant_Moss_Block_Yellow"
    },
    {
      "x": -8,
      "y": 7,
      "z": 0,
      "name": "Plant_Moss_Block_Yellow"
    },
    {
      "x": -8,
      "y": 8,
      "z": 0,
      "name": "Plant_Moss_Block_Yellow"
    },
    {
      "x": -8,
      "y": 9,
      "z": 0,
      "name": "Soil_Clay_Lime"
    },
    {
      "x": -8,
      "y": 10,
      "z": 0,
      "name": "Plant_Moss_Block_Yellow"
    },
    {
      "x": -8,
      "y": 11,
      "z": 0,
      "name": "Soil_Sand"
    },
    {
      "x": -8,
      "y": 12,
      "z": 0,
      "name": "Plant_Leaves_Palm_Arid"
    },
    {
      "x": -8,
      "y": 6,
      "z": 1,
      "name": "Plant_Moss_Block_Yellow"
    },
    {
      "x": -8,
      "y": 7,
      "z": 1,
      "name": "Soil_Clay_Lime"
    },
    {
      "x": -8,
      "y": 8,
      "z": 1,
      "name": "Soil_Clay_Lime"
    },
    {
      "x": -8,
      "y": 9,
      "z": 1,
      "name": "Soil_Clay_Lime"
    },
    {
      "x": -8,
      "y": 10,
      "z": 1,
      "name": "Soil_Clay_Lime"
    },
    {
      "x": -8,
      "y": 11,
      "z": 1,
      "name": "Soil_Sand"
    },
    {
      "x": -8,
      "y": 12,
      "z": 1,
      "name": "Soil_Sand"
    },
    {
      "x": -8,
      "y": 13,
      "z": 1,
      "name": "Plant_Flower_Bushy_Yellow"
    },
    {
      "x": -8,
      "y": 7,
      "z": 2,
      "name": "Soil_Clay_Lime"
    },
    {
      "x": -8,
      "y": 8,
      "z": 2,
      "name": "Rock_Stone_Mossy"
    },
    {
      "x": -8,
      "y": 9,
      "z": 2,
      "name": "Rock_Stone_Mossy"
    },
    {
      "x": -8,
      "y": 10,
      "z": 2,
      "name": "Rock_Stone_Mossy"
    },
    {
      "x": -8,
      "y": 11,
      "z": 2,
      "name": "Soil_Sand"
    },
    {
      "x": -8,
      "y": 12,
      "z": 2,
      "name": "Soil_Sand"
    },
    {
      "x": -8,
      "y": 13,
      "z": 2,
      "name": "Plant_Flower_Bushy_Yellow"
    },
    {
      "x": -8,
      "y": 7,
      "z": 3,
      "name": "Soil_Clay_Lime"
    },
    {
      "x": -8,
      "y": 8,
      "z": 3,
      "name": "Rock_Stone_Mossy"
    },
    {
      "x": -8,
      "y": 9,
      "z": 3,
      "name": "Rock_Stone_Mossy"
    },
    {
      "x": -8,
      "y": 10,
      "z": 3,
      "name": "Rock_Stone_Mossy"
    },
    {
      "x": -8,
      "y": 11,
      "z": 3,
      "name": "Soil_Sand"
    },
    {
      "x": -8,
      "y": 12,
      "z": 3,
      "name": "Soil_Sand"
    },
    {
      "x": -8,
      "y": 13,
      "z": 3,
      "name": "Plant_Flower_Bushy_Yellow"
    },
    {
      "x": -8,
      "y": 7,
      "z": 4,
      "name": "Soil_Clay_Lime"
    },
    {
      "x": -8,
      "y": 8,
      "z": 4,
      "name": "Rock_Stone_Mossy"
    },
    {
      "x": -8,
      "y": 9,
      "z": 4,
      "name": "Rock_Stone_Mossy"
    },
    {
      "x": -8,
      "y": 10,
      "z": 4,
      "name": "Rock_Stone_Mossy"
    },
    {
      "x": -8,
      "y": 11,
      "z": 4,
      "name": "Soil_Sand"
    },
    {
      "x": -8,
      "y": 12,
      "z": 4,
      "name": "Plant_Flower_Bushy_Yellow"
    },
    {
      "x": -7,
      "y": 6,
      "z": -3,
      "name": "Soil_Clay_Lime"
    },
    {
      "x": -7,
      "y": 7,
      "z": -3,
      "name": "Soil_Clay_Lime"
    },
    {
      "x": -7,
      "y": 8,
      "z": -3,
      "name": "Soil_Clay_Lime"
    },
    {
      "x": -7,
      "y": 9,
      "z": -3,
      "name": "Soil_Clay_Lime"
    },
    {
      "x": -7,
      "y": 10,
      "z": -3,
      "name": "Soil_Clay_Lime"
    },
    {
      "x": -7,
      "y": 11,
      "z": -3,
      "name": "Plant_Moss_Block_Yellow"
    },
    {
      "x": -7,
      "y": 5,
      "z": -2,
      "name": "Soil_Clay_Lime"
    },
    {
      "x": -7,
      "y": 6,
      "z": -2,
      "name": "Plant_Moss_Block_Yellow"
    },
    {
      "x": -7,
      "y": 7,
      "z": -2,
      "name": "Plant_Moss_Block_Yellow"
    },
    {
      "x": -7,
      "y": 8,
      "z": -2,
      "name": "Plant_Moss_Block_Yellow"
    },
    {
      "x": -7,
      "y": 9,
      "z": -2,
      "name": "Plant_Moss_Block_Yellow"
    },
    {
      "x": -7,
      "y": 10,
      "z": -2,
      "name": "Soil_Clay_Lime"
    },
    {
      "x": -7,
      "y": 11,
      "z": -2,
      "name": "Soil_Sand"
    },
    {
      "x": -7,
      "y": 12,
      "z": -2,
      "name": "Soil_Sand"
    },
    {
      "x": -7,
      "y": 13,
      "z": -2,
      "name": "Plant_Leaves_Palm_Arid"
    },
    {
      "x": -7,
      "y": 5,
      "z": -1,
      "name": "Plant_Moss_Block_Yellow"
    },
    {
      "x": -7,
      "y": 6,
      "z": -1,
      "name": "Plant_Moss_Block_Yellow"
    },
    {
      "x": -7,
      "y": 7,
      "z": -1,
      "name": "Plant_Moss_Block_Yellow"
    },
    {
      "x": -7,
      "y": 8,
      "z": -1,
      "name": "Plant_Moss_Block_Yellow"
    },
    {
      "x": -7,
      "y": 9,
      "z": -1,
      "name": "Plant_Moss_Block_Yellow"
    },
    {
      "x": -7,
      "y": 10,
      "z": -1,
      "name": "Plant_Moss_Block_Yellow"
    },
    {
      "x": -7,
      "y": 11,
      "z": -1,
      "name": "Soil_Sand"
    },
    {
      "x": -7,
      "y": 12,
      "z": -1,
      "name": "Soil_Sand"
    },
    {
      "x": -7,
      "y": 13,
      "z": -1,
      "name": "Plant_Leaves_Palm_Arid"
    },
    {
      "x": -7,
      "y": 5,
      "z": 0,
      "name": "Plant_Moss_Block_Yellow"
    },
    {
      "x": -7,
      "y": 6,
      "z": 0,
      "name": "Soil_Sand"
    },
    {
      "x": -7,
      "y": 7,
      "z": 0,
      "name": "Soil_Sand"
    },
    {
      "x": -7,
      "y": 8,
      "z": 0,
      "name": "Soil_Sand"
    },
    {
      "x": -7,
      "y": 9,
      "z": 0,
      "name": "Soil_Sand"
    },
    {
      "x": -7,
      "y": 10,
      "z": 0,
      "name": "Soil_Sand"
    },
    {
      "x": -7,
      "y": 11,
      "z": 0,
      "name": "Soil_Sand"
    },
    {
      "x": -7,
      "y": 12,
      "z": 0,
      "name": "Soil_Sand"
    },
    {
      "x": -7,
      "y": 13,
      "z": 0,
      "name": "Plant_Leaves_Palm_Arid"
    },
    {
      "x": -7,
      "y": 5,
      "z": 1,
      "name": "Plant_Moss_Block_Yellow"
    },
    {
      "x": -7,
      "y": 6,
      "z": 1,
      "name": "Soil_Sand"
    },
    {
      "x": -7,
      "y": 7,
      "z": 1,
      "name": "Soil_Sand"
    },
    {
      "x": -7,
      "y": 8,
      "z": 1,
      "name": "Soil_Sand"
    },
    {
      "x": -7,
      "y": 9,
      "z": 1,
      "name": "Soil_Sand"
    },
    {
      "x": -7,
      "y": 10,
      "z": 1,
      "name": "Soil_Sand"
    },
    {
      "x": -7,
      "y": 11,
      "z": 1,
      "name": "Soil_Sand"
    },
    {
      "x": -7,
      "y": 12,
      "z": 1,
      "name": "Soil_Sand"
    },
    {
      "x": -7,
      "y": 13,
      "z": 1,
      "name": "Plant_Leaves_Palm_Arid"
    },
    {
      "x": -7,
      "y": 5,
      "z": 2,
      "name": "Plant_Moss_Block_Yellow"
    },
    {
      "x": -7,
      "y": 6,
      "z": 2,
      "name": "Plant_Moss_Block_Yellow"
    },
    {
      "x": -7,
      "y": 7,
      "z": 2,
      "name": "Soil_Sand"
    },
    {
      "x": -7,
      "y": 8,
      "z": 2,
      "name": "Soil_Sand"
    },
    {
      "x": -7,
      "y": 9,
      "z": 2,
      "name": "Soil_Sand"
    },
    {
      "x": -7,
      "y": 10,
      "z": 2,
      "name": "Soil_Sand"
    },
    {
      "x": -7,
      "y": 11,
      "z": 2,
      "name": "Soil_Sand"
    },
    {
      "x": -7,
      "y": 12,
      "z": 2,
      "name": "Soil_Sand"
    },
    {
      "x": -7,
      "y": 13,
      "z": 2,
      "name": "Plant_Flower_Bushy_Yellow"
    },
    {
      "x": -7,
      "y": 5,
      "z": 3,
      "name": "Plant_Moss_Block_Yellow"
    },
    {
      "x": -7,
      "y": 6,
      "z": 3,
      "name": "Plant_Moss_Block_Yellow"
    },
    {
      "x": -7,
      "y": 7,
      "z": 3,
      "name": "Soil_Sand"
    },
    {
      "x": -7,
      "y": 8,
      "z": 3,
      "name": "Soil_Sand"
    },
    {
      "x": -7,
      "y": 9,
      "z": 3,
      "name": "Soil_Sand"
    },
    {
      "x": -7,
      "y": 10,
      "z": 3,
      "name": "Soil_Sand"
    },
    {
      "x": -7,
      "y": 11,
      "z": 3,
      "name": "Soil_Sand"
    },
    {
      "x": -7,
      "y": 12,
      "z": 3,
      "name": "Soil_Sand"
    },
    {
      "x": -7,
      "y": 13,
      "z": 3,
      "name": "Plant_Flower_Bushy_Yellow"
    },
    {
      "x": -7,
      "y": 6,
      "z": 4,
      "name": "Plant_Moss_Block_Yellow"
    },
    {
      "x": -7,
      "y": 7,
      "z": 4,
      "name": "Soil_Sand"
    },
    {
      "x": -7,
      "y": 8,
      "z": 4,
      "name": "Soil_Sand"
    },
    {
      "x": -7,
      "y": 9,
      "z": 4,
      "name": "Soil_Sand"
    },
    {
      "x": -7,
      "y": 10,
      "z": 4,
      "name": "Soil_Sand"
    },
    {
      "x": -7,
      "y": 11,
      "z": 4,
      "name": "Soil_Sand"
    },
    {
      "x": -7,
      "y": 12,
      "z": 4,
      "name": "Soil_Sand"
    },
    {
      "x": -7,
      "y": 13,
      "z": 4,
      "name": "Plant_Flower_Bushy_Yellow"
    },
    {
      "x": -7,
      "y": 7,
      "z": 5,
      "name": "Soil_Clay_Lime"
    },
    {
      "x": -7,
      "y": 8,
      "z": 5,
      "name": "Soil_Clay_Lime"
    },
    {
      "x": -7,
      "y": 9,
      "z": 5,
      "name": "Soil_Clay_Lime"
    },
    {
      "x": -7,
      "y": 10,
      "z": 5,
      "name": "Rock_Stone_Mossy"
    },
    {
      "x": -7,
      "y": 11,
      "z": 5,
      "name": "Rock_Stone_Mossy"
    },
    {
      "x": -6,
      "y": 6,
      "z": -5,
      "name": "Soil_Clay_Lime"
    },
    {
      "x": -6,
      "y": 7,
      "z": -5,
      "name": "Soil_Clay_Lime"
    },
    {
      "x": -6,
      "y": 8,
      "z": -5,
      "name": "Soil_Clay_Lime"
    },
    {
      "x": -6,
      "y": 9,
      "z": -5,
      "name": "Soil_Clay_Lime"
    },
    {
      "x": -6,
      "y": 10,
      "z": -5,
      "name": "Soil_Clay_Lime"
    },
    {
      "x": -6,
      "y": 11,
      "z": -5,
      "name": "Soil_Clay_Lime"
    },
    {
      "x": -6,
      "y": 4,
      "z": -4,
      "name": "Soil_Clay_Lime"
    },
    {
      "x": -6,
      "y": 5,
      "z": -4,
      "name": "Soil_Clay_Lime"
    },
    {
      "x": -6,
      "y": 6,
      "z": -4,
      "name": "Soil_Clay_Lime"
    },
    {
      "x": -6,
      "y": 7,
      "z": -4,
      "name": "Soil_Clay_Lime"
    },
    {
      "x": -6,
      "y": 8,
      "z": -4,
      "name": "Soil_Clay_Lime"
    },
    {
      "x": -6,
      "y": 9,
      "z": -4,
      "name": "Soil_Clay_Lime"
    },
    {
      "x": -6,
      "y": 10,
      "z": -4,
      "name": "Soil_Clay_Lime"
    },
    {
      "x": -6,
      "y": 11,
      "z": -4,
      "name": "Soil_Sand"
    },
    {
      "x": -6,
      "y": 12,
      "z": -4,
      "name": "Soil_Sand"
    },
    {
      "x": -6,
      "y": 13,
      "z": -4,
      "name": "Plant_Flower_Bushy_Yellow"
    },
    {
      "x": -6,
      "y": 4,
      "z": -3,
      "name": "Soil_Clay_Lime"
    },
    {
      "x": -6,
      "y": 5,
      "z": -3,
      "name": "Soil_Clay_Lime"
    },
    {
      "x": -6,
      "y": 6,
      "z": -3,
      "name": "Soil_Sand"
    },
    {
      "x": -6,
      "y": 7,
      "z": -3,
      "name": "Soil_Sand"
    },
    {
      "x": -6,
      "y": 8,
      "z": -3,
      "name": "Soil_Sand"
    },
    {
      "x": -6,
      "y": 9,
      "z": -3,
      "name": "Soil_Sand"
    },
    {
      "x": -6,
      "y": 10,
      "z": -3,
      "name": "Soil_Sand"
    },
    {
      "x": -6,
      "y": 11,
      "z": -3,
      "name": "Soil_Sand"
    },
    {
      "x": -6,
      "y": 12,
      "z": -3,
      "name": "Soil_Sand"
    },
    {
      "x": -6,
      "y": 13,
      "z": -3,
      "name": "Plant_Flower_Bushy_Yellow"
    },
    {
      "x": -6,
      "y": 3,
      "z": -2,
      "name": "Soil_Clay_Lime"
    },
    {
      "x": -6,
      "y": 4,
      "z": -2,
      "name": "Soil_Clay_Lime"
    },
    {
      "x": -6,
      "y": 5,
      "z": -2,
      "name": "Soil_Sand"
    },
    {
      "x": -6,
      "y": 6,
      "z": -2,
      "name": "Soil_Sand"
    },
    {
      "x": -6,
      "y": 7,
      "z": -2,
      "name": "Soil_Sand"
    },
    {
      "x": -6,
      "y": 8,
      "z": -2,
      "name": "Soil_Sand"
    },
    {
      "x": -6,
      "y": 9,
      "z": -2,
      "name": "Soil_Sand"
    },
    {
      "x": -6,
      "y": 10,
      "z": -2,
      "name": "Soil_Sand"
    },
    {
      "x": -6,
      "y": 11,
      "z": -2,
      "name": "Soil_Sand"
    },
    {
      "x": -6,
      "y": 12,
      "z": -2,
      "name": "Soil_Sand"
    },
    {
      "x": -6,
      "y": 13,
      "z": -2,
      "name": "Plant_Leaves_Palm_Arid"
    },
    {
      "x": -6,
      "y": 15,
      "z": -2,
      "name": "Plant_Moss_Block_Yellow"
    },
    {
      "x": -6,
      "y": 16,
      "z": -2,
      "name": "Plant_Moss_Block_Yellow"
    },
    {
      "x": -6,
      "y": 17,
      "z": -2,
      "name": "Plant_Moss_Block_Yellow"
    },
    {
      "x": -6,
      "y": 18,
      "z": -2,
      "name": "Plant_Moss_Block_Yellow"
    },
    {
      "x": -6,
      "y": 21,
      "z": -2,
      "name": "Rock_Stone_Mossy"
    },
    {
      "x": -6,
      "y": 22,
      "z": -2,
      "name": "Rock_Stone_Mossy"
    },
    {
      "x": -6,
      "y": 23,
      "z": -2,
      "name": "Rock_Stone_Mossy"
    },
    {
      "x": -6,
      "y": 24,
      "z": -2,
      "name": "Rock_Stone_Mossy"
    },
    {
      "x": -6,
      "y": 25,
      "z": -2,
      "name": "Soil_Clay_Lime"
    },
    {
      "x": -6,
      "y": 26,
      "z": -2,
      "name": "Soil_Clay_Lime"
    },
    {
      "x": -6,
      "y": 27,
      "z": -2,
      "name": "Soil_Clay_Lime"
    },
    {
      "x": -6,
      "y": 28,
      "z": -2,
      "name": "Soil_Clay_Lime"
    },
    {
      "x": -6,
      "y": 29,
      "z": -2,
      "name": "Plant_Moss_Block_Yellow"
    },
    {
      "x": -6,
      "y": 3,
      "z": -1,
      "name": "Soil_Clay_Lime"
    },
    {
      "x": -6,
      "y": 4,
      "z": -1,
      "name": "Soil_Clay_Lime"
    },
    {
      "x": -6,
      "y": 5,
      "z": -1,
      "name": "Soil_Sand"
    },
    {
      "x": -6,
      "y": 6,
      "z": -1,
      "name": "Soil_Sand"
    },
    {
      "x": -6,
      "y": 7,
      "z": -1,
      "name": "Soil_Sand"
    },
    {
      "x": -6,
      "y": 8,
      "z": -1,
      "name": "Soil_Sand"
    },
    {
      "x": -6,
      "y": 9,
      "z": -1,
      "name": "Soil_Sand"
    },
    {
      "x": -6,
      "y": 10,
      "z": -1,
      "name": "Soil_Sand"
    },
    {
      "x": -6,
      "y": 11,
      "z": -1,
      "name": "Soil_Sand"
    },
    {
      "x": -6,
      "y": 12,
      "z": -1,
      "name": "Soil_Sand"
    },
    {
      "x": -6,
      "y": 13,
      "z": -1,
      "name": "Plant_Leaves_Palm_Arid"
    },
    {
      "x": -6,
      "y": 14,
      "z": -1,
      "name": "Plant_Moss_Block_Yellow"
    },
    {
      "x": -6,
      "y": 15,
      "z": -1,
      "name": "Plant_Moss_Block_Yellow"
    },
    {
      "x": -6,
      "y": 16,
      "z": -1,
      "name": "Plant_Moss_Block_Yellow"
    },
    {
      "x": -6,
      "y": 17,
      "z": -1,
      "name": "Plant_Moss_Block_Yellow"
    },
    {
      "x": -6,
      "y": 18,
      "z": -1,
      "name": "Plant_Moss_Block_Yellow"
    },
    {
      "x": -6,
      "y": 21,
      "z": -1,
      "name": "Rock_Stone_Mossy"
    },
    {
      "x": -6,
      "y": 22,
      "z": -1,
      "name": "Rock_Stone_Mossy"
    },
    {
      "x": -6,
      "y": 23,
      "z": -1,
      "name": "Rock_Stone_Mossy"
    },
    {
      "x": -6,
      "y": 24,
      "z": -1,
      "name": "Rock_Stone_Mossy"
    },
    {
      "x": -6,
      "y": 25,
      "z": -1,
      "name": "Soil_Clay_Lime"
    },
    {
      "x": -6,
      "y": 26,
      "z": -1,
      "name": "Plant_Moss_Block_Yellow"
    },
    {
      "x": -6,
      "y": 27,
      "z": -1,
      "name": "Plant_Moss_Block_Yellow"
    },
    {
      "x": -6,
      "y": 28,
      "z": -1,
      "name": "Plant_Moss_Block_Yellow"
    },
    {
      "x": -6,
      "y": 29,
      "z": -1,
      "name": "Plant_Moss_Block_Yellow"
    },
    {
      "x": -6,
      "y": 30,
      "z": -1,
      "name": "Plant_Moss_Block_Yellow"
    },
    {
      "x": -6,
      "y": 3,
      "z": 0,
      "name": "Soil_Clay_Lime"
    },
    {
      "x": -6,
      "y": 4,
      "z": 0,
      "name": "Plant_Moss_Block_Yellow"
    },
    {
      "x": -6,
      "y": 5,
      "z": 0,
      "name": "Soil_Sand"
    },
    {
      "x": -6,
      "y": 6,
      "z": 0,
      "name": "Soil_Sand"
    },
    {
      "x": -6,
      "y": 7,
      "z": 0,
      "name": "Soil_Sand"
    },
    {
      "x": -6,
      "y": 8,
      "z": 0,
      "name": "Soil_Sand"
    },
    {
      "x": -6,
      "y": 9,
      "z": 0,
      "name": "Soil_Sand"
    },
    {
      "x": -6,
      "y": 10,
      "z": 0,
      "name": "Soil_Sand"
    },
    {
      "x": -6,
      "y": 11,
      "z": 0,
      "name": "Soil_Sand"
    },
    {
      "x": -6,
      "y": 12,
      "z": 0,
      "name": "Soil_Sand"
    },
    {
      "x": -6,
      "y": 13,
      "z": 0,
      "name": "Plant_Leaves_Palm_Arid"
    },
    {
      "x": -6,
      "y": 14,
      "z": 0,
      "name": "Plant_Moss_Block_Yellow"
    },
    {
      "x": -6,
      "y": 15,
      "z": 0,
      "name": "Plant_Moss_Block_Yellow"
    },
    {
      "x": -6,
      "y": 16,
      "z": 0,
      "name": "Plant_Moss_Block_Yellow"
    },
    {
      "x": -6,
      "y": 17,
      "z": 0,
      "name": "Plant_Moss_Block_Yellow"
    },
    {
      "x": -6,
      "y": 18,
      "z": 0,
      "name": "Soil_Clay_Lime"
    },
    {
      "x": -6,
      "y": 19,
      "z": 0,
      "name": "Soil_Clay_Lime"
    },
    {
      "x": -6,
      "y": 21,
      "z": 0,
      "name": "Rock_Stone_Mossy"
    },
    {
      "x": -6,
      "y": 22,
      "z": 0,
      "name": "Rock_Stone_Mossy"
    },
    {
      "x": -6,
      "y": 23,
      "z": 0,
      "name": "Soil_Clay_Lime"
    },
    {
      "x": -6,
      "y": 24,
      "z": 0,
      "name": "Soil_Clay_Lime"
    },
    {
      "x": -6,
      "y": 25,
      "z": 0,
      "name": "Plant_Moss_Block_Yellow"
    },
    {
      "x": -6,
      "y": 26,
      "z": 0,
      "name": "Plant_Moss_Block_Yellow"
    },
    {
      "x": -6,
      "y": 27,
      "z": 0,
      "name": "Plant_Moss_Block_Yellow"
    },
    {
      "x": -6,
      "y": 28,
      "z": 0,
      "name": "Plant_Moss_Block_Yellow"
    },
    {
      "x": -6,
      "y": 29,
      "z": 0,
      "name": "Plant_Moss_Block_Yellow"
    },
    {
      "x": -6,
      "y": 30,
      "z": 0,
      "name": "Soil_Sand"
    },
    {
      "x": -6,
      "y": 31,
      "z": 0,
      "name": "Plant_Flower_Bushy_Yellow"
    },
    {
      "x": -6,
      "y": 3,
      "z": 1,
      "name": "Plant_Moss_Block_Yellow"
    },
    {
      "x": -6,
      "y": 4,
      "z": 1,
      "name": "Plant_Moss_Block_Yellow"
    },
    {
      "x": -6,
      "y": 5,
      "z": 1,
      "name": "Soil_Sand"
    },
    {
      "x": -6,
      "y": 6,
      "z": 1,
      "name": "Soil_Sand"
    },
    {
      "x": -6,
      "y": 7,
      "z": 1,
      "name": "Soil_Sand"
    },
    {
      "x": -6,
      "y": 8,
      "z": 1,
      "name": "Soil_Sand"
    },
    {
      "x": -6,
      "y": 9,
      "z": 1,
      "name": "Soil_Sand"
    },
    {
      "x": -6,
      "y": 10,
      "z": 1,
      "name": "Soil_Sand"
    },
    {
      "x": -6,
      "y": 11,
      "z": 1,
      "name": "Soil_Sand"
    },
    {
      "x": -6,
      "y": 12,
      "z": 1,
      "name": "Soil_Sand"
    },
    {
      "x": -6,
      "y": 13,
      "z": 1,
      "name": "Plant_Leaves_Palm_Arid"
    },
    {
      "x": -6,
      "y": 14,
      "z": 1,
      "name": "Plant_Moss_Block_Yellow"
    },
    {
      "x": -6,
      "y": 15,
      "z": 1,
      "name": "Plant_Moss_Block_Yellow"
    },
    {
      "x": -6,
      "y": 16,
      "z": 1,
      "name": "Plant_Moss_Block_Yellow"
    },
    {
      "x": -6,
      "y": 17,
      "z": 1,
      "name": "Soil_Clay_Lime"
    },
    {
      "x": -6,
      "y": 18,
      "z": 1,
      "name": "Soil_Clay_Lime"
    },
    {
      "x": -6,
      "y": 19,
      "z": 1,
      "name": "Rock_Stone_Mossy"
    },
    {
      "x": -6,
      "y": 21,
      "z": 1,
      "name": "Rock_Stone_Mossy"
    },
    {
      "x": -6,
      "y": 22,
      "z": 1,
      "name": "Soil_Clay_Lime"
    },
    {
      "x": -6,
      "y": 23,
      "z": 1,
      "name": "Soil_Clay_Lime"
    },
    {
      "x": -6,
      "y": 24,
      "z": 1,
      "name": "Plant_Moss_Block_Yellow"
    },
    {
      "x": -6,
      "y": 25,
      "z": 1,
      "name": "Plant_Moss_Block_Yellow"
    },
    {
      "x": -6,
      "y": 26,
      "z": 1,
      "name": "Plant_Moss_Block_Yellow"
    },
    {
      "x": -6,
      "y": 27,
      "z": 1,
      "name": "Plant_Moss_Block_Yellow"
    },
    {
      "x": -6,
      "y": 28,
      "z": 1,
      "name": "Plant_Moss_Block_Yellow"
    },
    {
      "x": -6,
      "y": 29,
      "z": 1,
      "name": "Plant_Moss_Block_Yellow"
    },
    {
      "x": -6,
      "y": 4,
      "z": 2,
      "name": "Plant_Moss_Block_Yellow"
    },
    {
      "x": -6,
      "y": 5,
      "z": 2,
      "name": "Soil_Sand"
    },
    {
      "x": -6,
      "y": 6,
      "z": 2,
      "name": "Soil_Sand"
    },
    {
      "x": -6,
      "y": 7,
      "z": 2,
      "name": "Soil_Sand"
    },
    {
      "x": -6,
      "y": 8,
      "z": 2,
      "name": "Soil_Sand"
    },
    {
      "x": -6,
      "y": 9,
      "z": 2,
      "name": "Soil_Sand"
    },
    {
      "x": -6,
      "y": 10,
      "z": 2,
      "name": "Soil_Sand"
    },
    {
      "x": -6,
      "y": 11,
      "z": 2,
      "name": "Soil_Sand"
    },
    {
      "x": -6,
      "y": 12,
      "z": 2,
      "name": "Soil_Sand"
    },
    {
      "x": -6,
      "y": 13,
      "z": 2,
      "name": "Plant_Flower_Bushy_Yellow"
    },
    {
      "x": -6,
      "y": 15,
      "z": 2,
      "name": "Soil_Clay_Lime"
    },
    {
      "x": -6,
      "y": 16,
      "z": 2,
      "name": "Soil_Clay_Lime"
    },
    {
      "x": -6,
      "y": 17,
      "z": 2,
      "name": "Soil_Clay_Lime"
    },
    {
      "x": -6,
      "y": 18,
      "z": 2,
      "name": "Rock_Stone_Mossy"
    },
    {
      "x": -6,
      "y": 21,
      "z": 2,
      "name": "Soil_Clay_Lime"
    },
    {
      "x": -6,
      "y": 22,
      "z": 2,
      "name": "Soil_Clay_Lime"
    },
    {
      "x": -6,
      "y": 23,
      "z": 2,
      "name": "Plant_Moss_Block_Yellow"
    },
    {
      "x": -6,
      "y": 24,
      "z": 2,
      "name": "Plant_Moss_Block_Yellow"
    },
    {
      "x": -6,
      "y": 25,
      "z": 2,
      "name": "Plant_Moss_Block_Yellow"
    },
    {
      "x": -6,
      "y": 26,
      "z": 2,
      "name": "Plant_Moss_Block_Yellow"
    },
    {
      "x": -6,
      "y": 27,
      "z": 2,
      "name": "Soil_Clay_Lime"
    },
    {
      "x": -6,
      "y": 28,
      "z": 2,
      "name": "Soil_Clay_Lime"
    },
    {
      "x": -6,
      "y": 29,
      "z": 2,
      "name": "Soil_Clay_Lime"
    },
    {
      "x": -6,
      "y": 5,
      "z": 3,
      "name": "Plant_Moss_Block_Yellow"
    },
    {
      "x": -6,
      "y": 6,
      "z": 3,
      "name": "Soil_Sand"
    },
    {
      "x": -6,
      "y": 7,
      "z": 3,
      "name": "Soil_Sand"
    },
    {
      "x": -6,
      "y": 8,
      "z": 3,
      "name": "Soil_Sand"
    },
    {
      "x": -6,
      "y": 9,
      "z": 3,
      "name": "Soil_Sand"
    },
    {
      "x": -6,
      "y": 10,
      "z": 3,
      "name": "Soil_Sand"
    },
    {
      "x": -6,
      "y": 11,
      "z": 3,
      "name": "Soil_Sand"
    },
    {
      "x": -6,
      "y": 12,
      "z": 3,
      "name": "Soil_Sand"
    },
    {
      "x": -6,
      "y": 13,
      "z": 3,
      "name": "Plant_Flower_Bushy_Yellow"
    },
    {
      "x": -6,
      "y": 6,
      "z": 4,
      "name": "Plant_Moss_Block_Yellow"
    },
    {
      "x": -6,
      "y": 7,
      "z": 4,
      "name": "Soil_Sand"
    },
    {
      "x": -6,
      "y": 8,
      "z": 4,
      "name": "Soil_Sand"
    },
    {
      "x": -6,
      "y": 9,
      "z": 4,
      "name": "Soil_Sand"
    },
    {
      "x": -6,
      "y": 10,
      "z": 4,
      "name": "Soil_Sand"
    },
    {
      "x": -6,
      "y": 11,
      "z": 4,
      "name": "Soil_Sand"
    },
    {
      "x": -6,
      "y": 12,
      "z": 4,
      "name": "Soil_Sand"
    },
    {
      "x": -6,
      "y": 13,
      "z": 4,
      "name": "Plant_Flower_Bushy_Yellow"
    },
    {
      "x": -6,
      "y": 7,
      "z": 5,
      "name": "Soil_Clay_Lime"
    },
    {
      "x": -6,
      "y": 8,
      "z": 5,
      "name": "Soil_Clay_Lime"
    },
    {
      "x": -6,
      "y": 9,
      "z": 5,
      "name": "Soil_Clay_Lime"
    },
    {
      "x": -6,
      "y": 10,
      "z": 5,
      "name": "Soil_Clay_Lime"
    },
    {
      "x": -6,
      "y": 11,
      "z": 5,
      "name": "Soil_Clay_Lime"
    },
    {
      "x": -5,
      "y": 5,
      "z": -5,
      "name": "Soil_Clay_Lime"
    },
    {
      "x": -5,
      "y": 6,
      "z": -5,
      "name": "Rock_Stone_Mossy"
    },
    {
      "x": -5,
      "y": 7,
      "z": -5,
      "name": "Rock_Stone_Mossy"
    },
    {
      "x": -5,
      "y": 8,
      "z": -5,
      "name": "Rock_Stone_Mossy"
    },
    {
      "x": -5,
      "y": 9,
      "z": -5,
      "name": "Rock_Stone_Mossy"
    },
    {
      "x": -5,
      "y": 10,
      "z": -5,
      "name": "Rock_Stone_Mossy"
    },
    {
      "x": -5,
      "y": 11,
      "z": -5,
      "name": "Soil_Sand"
    },
    {
      "x": -5,
      "y": 12,
      "z": -5,
      "name": "Soil_Sand"
    },
    {
      "x": -5,
      "y": 13,
      "z": -5,
      "name": "Plant_Flower_Bushy_Yellow"
    },
    {
      "x": -5,
      "y": 3,
      "z": -4,
      "name": "Soil_Clay_Lime"
    },
    {
      "x": -5,
      "y": 4,
      "z": -4,
      "name": "Soil_Clay_Lime"
    },
    {
      "x": -5,
      "y": 5,
      "z": -4,
      "name": "Soil_Sand"
    },
    {
      "x": -5,
      "y": 6,
      "z": -4,
      "name": "Soil_Sand"
    },
    {
      "x": -5,
      "y": 7,
      "z": -4,
      "name": "Soil_Sand"
    },
    {
      "x": -5,
      "y": 8,
      "z": -4,
      "name": "Soil_Sand"
    },
    {
      "x": -5,
      "y": 9,
      "z": -4,
      "name": "Soil_Sand"
    },
    {
      "x": -5,
      "y": 10,
      "z": -4,
      "name": "Soil_Sand"
    },
    {
      "x": -5,
      "y": 11,
      "z": -4,
      "name": "Soil_Sand"
    },
    {
      "x": -5,
      "y": 12,
      "z": -4,
      "name": "Soil_Sand"
    },
    {
      "x": -5,
      "y": 13,
      "z": -4,
      "name": "Plant_Flower_Bushy_Yellow"
    },
    {
      "x": -5,
      "y": 15,
      "z": -4,
      "name": "Plant_Moss_Block_Yellow"
    },
    {
      "x": -5,
      "y": 16,
      "z": -4,
      "name": "Plant_Moss_Block_Yellow"
    },
    {
      "x": -5,
      "y": 17,
      "z": -4,
      "name": "Plant_Moss_Block_Yellow"
    },
    {
      "x": -5,
      "y": 18,
      "z": -4,
      "name": "Soil_Clay_Lime"
    },
    {
      "x": -5,
      "y": 21,
      "z": -4,
      "name": "Rock_Stone_Mossy"
    },
    {
      "x": -5,
      "y": 22,
      "z": -4,
      "name": "Rock_Stone_Mossy"
    },
    {
      "x": -5,
      "y": 23,
      "z": -4,
      "name": "Rock_Stone_Mossy"
    },
    {
      "x": -5,
      "y": 24,
      "z": -4,
      "name": "Rock_Stone_Mossy"
    },
    {
      "x": -5,
      "y": 25,
      "z": -4,
      "name": "Rock_Stone_Mossy"
    },
    {
      "x": -5,
      "y": 26,
      "z": -4,
      "name": "Soil_Clay_Lime"
    },
    {
      "x": -5,
      "y": 27,
      "z": -4,
      "name": "Soil_Clay_Lime"
    },
    {
      "x": -5,
      "y": 28,
      "z": -4,
      "name": "Soil_Clay_Lime"
    },
    {
      "x": -5,
      "y": 29,
      "z": -4,
      "name": "Rock_Stone_Mossy"
    },
    {
      "x": -5,
      "y": 3,
      "z": -3,
      "name": "Soil_Clay_Lime"
    },
    {
      "x": -5,
      "y": 4,
      "z": -3,
      "name": "Soil_Sand"
    },
    {
      "x": -5,
      "y": 5,
      "z": -3,
      "name": "Soil_Sand"
    },
    {
      "x": -5,
      "y": 6,
      "z": -3,
      "name": "Soil_Sand"
    },
    {
      "x": -5,
      "y": 7,
      "z": -3,
      "name": "Soil_Sand"
    },
    {
      "x": -5,
      "y": 8,
      "z": -3,
      "name": "Soil_Sand"
    },
    {
      "x": -5,
      "y": 9,
      "z": -3,
      "name": "Soil_Sand"
    },
    {
      "x": -5,
      "y": 10,
      "z": -3,
      "name": "Soil_Sand"
    },
    {
      "x": -5,
      "y": 11,
      "z": -3,
      "name": "Soil_Sand"
    },
    {
      "x": -5,
      "y": 12,
      "z": -3,
      "name": "Soil_Sand"
    },
    {
      "x": -5,
      "y": 13,
      "z": -3,
      "name": "Plant_Flower_Bushy_Yellow"
    },
    {
      "x": -5,
      "y": 15,
      "z": -3,
      "name": "Plant_Moss_Block_Yellow"
    },
    {
      "x": -5,
      "y": 16,
      "z": -3,
      "name": "Plant_Moss_Block_Yellow"
    },
    {
      "x": -5,
      "y": 17,
      "z": -3,
      "name": "Plant_Moss_Block_Yellow"
    },
    {
      "x": -5,
      "y": 18,
      "z": -3,
      "name": "Soil_Clay_Lime"
    },
    {
      "x": -5,
      "y": 21,
      "z": -3,
      "name": "Rock_Stone_Mossy"
    },
    {
      "x": -5,
      "y": 22,
      "z": -3,
      "name": "Rock_Stone_Mossy"
    },
    {
      "x": -5,
      "y": 23,
      "z": -3,
      "name": "Rock_Stone_Mossy"
    },
    {
      "x": -5,
      "y": 24,
      "z": -3,
      "name": "Rock_Stone_Mossy"
    },
    {
      "x": -5,
      "y": 25,
      "z": -3,
      "name": "Rock_Stone_Mossy"
    },
    {
      "x": -5,
      "y": 26,
      "z": -3,
      "name": "Soil_Clay_Lime"
    },
    {
      "x": -5,
      "y": 27,
      "z": -3,
      "name": "Soil_Clay_Lime"
    },
    {
      "x": -5,
      "y": 28,
      "z": -3,
      "name": "Soil_Clay_Lime"
    },
    {
      "x": -5,
      "y": 29,
      "z": -3,
      "name": "Soil_Clay_Lime"
    },
    {
      "x": -5,
      "y": 30,
      "z": -3,
      "name": "Rock_Stone_Mossy"
    },
    {
      "x": -5,
      "y": 2,
      "z": -2,
      "name": "Soil_Clay_Lime"
    },
    {
      "x": -5,
      "y": 3,
      "z": -2,
      "name": "Soil_Sand"
    },
    {
      "x": -5,
      "y": 4,
      "z": -2,
      "name": "Soil_Sand"
    },
    {
      "x": -5,
      "y": 5,
      "z": -2,
      "name": "Soil_Sand"
    },
    {
      "x": -5,
      "y": 6,
      "z": -2,
      "name": "Soil_Sand"
    },
    {
      "x": -5,
      "y": 7,
      "z": -2,
      "name": "Soil_Sand"
    },
    {
      "x": -5,
      "y": 8,
      "z": -2,
      "name": "Soil_Sand"
    },
    {
      "x": -5,
      "y": 9,
      "z": -2,
      "name": "Soil_Sand"
    },
    {
      "x": -5,
      "y": 10,
      "z": -2,
      "name": "Soil_Sand"
    },
    {
      "x": -5,
      "y": 11,
      "z": -2,
      "name": "Soil_Sand"
    },
    {
      "x": -5,
      "y": 12,
      "z": -2,
      "name": "Soil_Sand"
    },
    {
      "x": -5,
      "y": 13,
      "z": -2,
      "name": "Plant_Leaves_Palm_Arid"
    },
    {
      "x": -5,
      "y": 14,
      "z": -2,
      "name": "Plant_Moss_Block_Yellow"
    },
    {
      "x": -5,
      "y": 15,
      "z": -2,
      "name": "Soil_Sand"
    },
    {
      "x": -5,
      "y": 16,
      "z": -2,
      "name": "Soil_Sand"
    },
    {
      "x": -5,
      "y": 17,
      "z": -2,
      "name": "Soil_Sand"
    },
    {
      "x": -5,
      "y": 18,
      "z": -2,
      "name": "Soil_Sand"
    },
    {
      "x": -5,
      "y": 19,
      "z": -2,
      "name": "Soil_Clay_Lime"
    },
    {
      "x": -5,
      "y": 21,
      "z": -2,
      "name": "Rock_Stone_Mossy"
    },
    {
      "x": -5,
      "y": 22,
      "z": -2,
      "name": "Soil_Sand"
    },
    {
      "x": -5,
      "y": 23,
      "z": -2,
      "name": "Soil_Sand"
    },
    {
      "x": -5,
      "y": 24,
      "z": -2,
      "name": "Soil_Sand"
    },
    {
      "x": -5,
      "y": 25,
      "z": -2,
      "name": "Soil_Sand"
    },
    {
      "x": -5,
      "y": 26,
      "z": -2,
      "name": "Soil_Sand"
    },
    {
      "x": -5,
      "y": 27,
      "z": -2,
      "name": "Soil_Sand"
    },
    {
      "x": -5,
      "y": 28,
      "z": -2,
      "name": "Soil_Sand"
    },
    {
      "x": -5,
      "y": 29,
      "z": -2,
      "name": "Soil_Sand"
    },
    {
      "x": -5,
      "y": 30,
      "z": -2,
      "name": "Soil_Clay_Lime"
    },
    {
      "x": -5,
      "y": 2,
      "z": -1,
      "name": "Soil_Clay_Lime"
    },
    {
      "x": -5,
      "y": 3,
      "z": -1,
      "name": "Soil_Sand"
    },
    {
      "x": -5,
      "y": 4,
      "z": -1,
      "name": "Soil_Sand"
    },
    {
      "x": -5,
      "y": 5,
      "z": -1,
      "name": "Soil_Sand"
    },
    {
      "x": -5,
      "y": 6,
      "z": -1,
      "name": "Soil_Sand"
    },
    {
      "x": -5,
      "y": 7,
      "z": -1,
      "name": "Soil_Sand"
    },
    {
      "x": -5,
      "y": 8,
      "z": -1,
      "name": "Soil_Sand"
    },
    {
      "x": -5,
      "y": 9,
      "z": -1,
      "name": "Soil_Sand"
    },
    {
      "x": -5,
      "y": 10,
      "z": -1,
      "name": "Soil_Sand"
    },
    {
      "x": -5,
      "y": 11,
      "z": -1,
      "name": "Soil_Sand"
    },
    {
      "x": -5,
      "y": 12,
      "z": -1,
      "name": "Soil_Sand"
    },
    {
      "x": -5,
      "y": 13,
      "z": -1,
      "name": "Plant_Leaves_Palm_Arid"
    },
    {
      "x": -5,
      "y": 14,
      "z": -1,
      "name": "Plant_Moss_Block_Yellow"
    },
    {
      "x": -5,
      "y": 15,
      "z": -1,
      "name": "Soil_Sand"
    },
    {
      "x": -5,
      "y": 16,
      "z": -1,
      "name": "Soil_Sand"
    },
    {
      "x": -5,
      "y": 17,
      "z": -1,
      "name": "Soil_Sand"
    },
    {
      "x": -5,
      "y": 18,
      "z": -1,
      "name": "Soil_Sand"
    },
    {
      "x": -5,
      "y": 19,
      "z": -1,
      "name": "Soil_Clay_Lime"
    },
    {
      "x": -5,
      "y": 21,
      "z": -1,
      "name": "Rock_Stone_Mossy"
    },
    {
      "x": -5,
      "y": 22,
      "z": -1,
      "name": "Soil_Sand"
    },
    {
      "x": -5,
      "y": 23,
      "z": -1,
      "name": "Soil_Sand"
    },
    {
      "x": -5,
      "y": 24,
      "z": -1,
      "name": "Soil_Sand"
    },
    {
      "x": -5,
      "y": 25,
      "z": -1,
      "name": "Soil_Sand"
    },
    {
      "x": -5,
      "y": 26,
      "z": -1,
      "name": "Soil_Sand"
    },
    {
      "x": -5,
      "y": 27,
      "z": -1,
      "name": "Soil_Sand"
    },
    {
      "x": -5,
      "y": 28,
      "z": -1,
      "name": "Soil_Sand"
    },
    {
      "x": -5,
      "y": 29,
      "z": -1,
      "name": "Soil_Sand"
    },
    {
      "x": -5,
      "y": 30,
      "z": -1,
      "name": "Plant_Moss_Block_Yellow"
    },
    {
      "x": -5,
      "y": 31,
      "z": -1,
      "name": "Soil_Sand"
    },
    {
      "x": -5,
      "y": 32,
      "z": -1,
      "name": "Plant_Flower_Bushy_Yellow"
    },
    {
      "x": -5,
      "y": 2,
      "z": 0,
      "name": "Plant_Moss_Block_Yellow"
    },
    {
      "x": -5,
      "y": 3,
      "z": 0,
      "name": "Soil_Sand"
    },
    {
      "x": -5,
      "y": 4,
      "z": 0,
      "name": "Soil_Sand"
    },
    {
      "x": -5,
      "y": 5,
      "z": 0,
      "name": "Soil_Sand"
    },
    {
      "x": -5,
      "y": 6,
      "z": 0,
      "name": "Soil_Sand"
    },
    {
      "x": -5,
      "y": 7,
      "z": 0,
      "name": "Soil_Sand"
    },
    {
      "x": -5,
      "y": 8,
      "z": 0,
      "name": "Soil_Sand"
    },
    {
      "x": -5,
      "y": 9,
      "z": 0,
      "name": "Soil_Sand"
    },
    {
      "x": -5,
      "y": 10,
      "z": 0,
      "name": "Soil_Sand"
    },
    {
      "x": -5,
      "y": 11,
      "z": 0,
      "name": "Soil_Sand"
    },
    {
      "x": -5,
      "y": 12,
      "z": 0,
      "name": "Soil_Sand"
    },
    {
      "x": -5,
      "y": 13,
      "z": 0,
      "name": "Plant_Leaves_Palm_Arid"
    },
    {
      "x": -5,
      "y": 14,
      "z": 0,
      "name": "Soil_Clay_Lime"
    },
    {
      "x": -5,
      "y": 15,
      "z": 0,
      "name": "Soil_Sand"
    },
    {
      "x": -5,
      "y": 16,
      "z": 0,
      "name": "Soil_Sand"
    },
    {
      "x": -5,
      "y": 17,
      "z": 0,
      "name": "Soil_Sand"
    },
    {
      "x": -5,
      "y": 18,
      "z": 0,
      "name": "Soil_Sand"
    },
    {
      "x": -5,
      "y": 19,
      "z": 0,
      "name": "Soil_Clay_Lime"
    },
    {
      "x": -5,
      "y": 21,
      "z": 0,
      "name": "Soil_Clay_Lime"
    },
    {
      "x": -5,
      "y": 22,
      "z": 0,
      "name": "Soil_Sand"
    },
    {
      "x": -5,
      "y": 23,
      "z": 0,
      "name": "Soil_Sand"
    },
    {
      "x": -5,
      "y": 24,
      "z": 0,
      "name": "Soil_Sand"
    },
    {
      "x": -5,
      "y": 25,
      "z": 0,
      "name": "Soil_Sand"
    },
    {
      "x": -5,
      "y": 26,
      "z": 0,
      "name": "Soil_Sand"
    },
    {
      "x": -5,
      "y": 27,
      "z": 0,
      "name": "Soil_Sand"
    },
    {
      "x": -5,
      "y": 28,
      "z": 0,
      "name": "Soil_Sand"
    },
    {
      "x": -5,
      "y": 29,
      "z": 0,
      "name": "Plant_Moss_Block_Yellow"
    },
    {
      "x": -5,
      "y": 30,
      "z": 0,
      "name": "Soil_Sand"
    },
    {
      "x": -5,
      "y": 31,
      "z": 0,
      "name": "Plant_Flower_Bushy_Yellow"
    },
    {
      "x": -5,
      "y": 2,
      "z": 1,
      "name": "Plant_Moss_Block_Yellow"
    },
    {
      "x": -5,
      "y": 3,
      "z": 1,
      "name": "Soil_Sand"
    },
    {
      "x": -5,
      "y": 4,
      "z": 1,
      "name": "Soil_Sand"
    },
    {
      "x": -5,
      "y": 5,
      "z": 1,
      "name": "Soil_Sand"
    },
    {
      "x": -5,
      "y": 6,
      "z": 1,
      "name": "Soil_Sand"
    },
    {
      "x": -5,
      "y": 7,
      "z": 1,
      "name": "Soil_Sand"
    },
    {
      "x": -5,
      "y": 8,
      "z": 1,
      "name": "Soil_Sand"
    },
    {
      "x": -5,
      "y": 9,
      "z": 1,
      "name": "Soil_Sand"
    },
    {
      "x": -5,
      "y": 10,
      "z": 1,
      "name": "Soil_Sand"
    },
    {
      "x": -5,
      "y": 11,
      "z": 1,
      "name": "Soil_Sand"
    },
    {
      "x": -5,
      "y": 12,
      "z": 1,
      "name": "Soil_Sand"
    },
    {
      "x": -5,
      "y": 13,
      "z": 1,
      "name": "Plant_Leaves_Palm_Arid"
    },
    {
      "x": -5,
      "y": 14,
      "z": 1,
      "name": "Soil_Clay_Lime"
    },
    {
      "x": -5,
      "y": 15,
      "z": 1,
      "name": "Soil_Sand"
    },
    {
      "x": -5,
      "y": 16,
      "z": 1,
      "name": "Soil_Sand"
    },
    {
      "x": -5,
      "y": 17,
      "z": 1,
      "name": "Soil_Sand"
    },
    {
      "x": -5,
      "y": 18,
      "z": 1,
      "name": "Soil_Sand"
    },
    {
      "x": -5,
      "y": 19,
      "z": 1,
      "name": "Soil_Clay_Lime"
    },
    {
      "x": -5,
      "y": 21,
      "z": 1,
      "name": "Soil_Clay_Lime"
    },
    {
      "x": -5,
      "y": 22,
      "z": 1,
      "name": "Soil_Sand"
    },
    {
      "x": -5,
      "y": 23,
      "z": 1,
      "name": "Soil_Sand"
    },
    {
      "x": -5,
      "y": 24,
      "z": 1,
      "name": "Soil_Sand"
    },
    {
      "x": -5,
      "y": 25,
      "z": 1,
      "name": "Soil_Sand"
    },
    {
      "x": -5,
      "y": 26,
      "z": 1,
      "name": "Soil_Sand"
    },
    {
      "x": -5,
      "y": 27,
      "z": 1,
      "name": "Soil_Sand"
    },
    {
      "x": -5,
      "y": 28,
      "z": 1,
      "name": "Soil_Sand"
    },
    {
      "x": -5,
      "y": 29,
      "z": 1,
      "name": "Soil_Clay_Lime"
    },
    {
      "x": -5,
      "y": 30,
      "z": 1,
      "name": "Soil_Sand"
    },
    {
      "x": -5,
      "y": 31,
      "z": 1,
      "name": "Plant_Bush_Arid_Sharp"
    },
    {
      "x": -5,
      "y": 2,
      "z": 2,
      "name": "Plant_Moss_Block_Yellow"
    },
    {
      "x": -5,
      "y": 3,
      "z": 2,
      "name": "Plant_Moss_Block_Yellow"
    },
    {
      "x": -5,
      "y": 4,
      "z": 2,
      "name": "Soil_Sand"
    },
    {
      "x": -5,
      "y": 5,
      "z": 2,
      "name": "Soil_Sand"
    },
    {
      "x": -5,
      "y": 6,
      "z": 2,
      "name": "Soil_Sand"
    },
    {
      "x": -5,
      "y": 7,
      "z": 2,
      "name": "Soil_Sand"
    },
    {
      "x": -5,
      "y": 8,
      "z": 2,
      "name": "Soil_Sand"
    },
    {
      "x": -5,
      "y": 9,
      "z": 2,
      "name": "Soil_Sand"
    },
    {
      "x": -5,
      "y": 10,
      "z": 2,
      "name": "Soil_Sand"
    },
    {
      "x": -5,
      "y": 11,
      "z": 2,
      "name": "Soil_Sand"
    },
    {
      "x": -5,
      "y": 12,
      "z": 2,
      "name": "Soil_Sand"
    },
    {
      "x": -5,
      "y": 13,
      "z": 2,
      "name": "Plant_Flower_Bushy_Yellow"
    },
    {
      "x": -5,
      "y": 15,
      "z": 2,
      "name": "Soil_Sand"
    },
    {
      "x": -5,
      "y": 16,
      "z": 2,
      "name": "Soil_Sand"
    },
    {
      "x": -5,
      "y": 17,
      "z": 2,
      "name": "Soil_Sand"
    },
    {
      "x": -5,
      "y": 18,
      "z": 2,
      "name": "Soil_Sand"
    },
    {
      "x": -5,
      "y": 19,
      "z": 2,
      "name": "Rock_Stone_Mossy"
    },
    {
      "x": -5,
      "y": 21,
      "z": 2,
      "name": "Soil_Clay_Lime"
    },
    {
      "x": -5,
      "y": 22,
      "z": 2,
      "name": "Soil_Sand"
    },
    {
      "x": -5,
      "y": 23,
      "z": 2,
      "name": "Soil_Sand"
    },
    {
      "x": -5,
      "y": 24,
      "z": 2,
      "name": "Soil_Sand"
    },
    {
      "x": -5,
      "y": 25,
      "z": 2,
      "name": "Soil_Sand"
    },
    {
      "x": -5,
      "y": 26,
      "z": 2,
      "name": "Soil_Sand"
    },
    {
      "x": -5,
      "y": 27,
      "z": 2,
      "name": "Soil_Sand"
    },
    {
      "x": -5,
      "y": 28,
      "z": 2,
      "name": "Soil_Sand"
    },
    {
      "x": -5,
      "y": 29,
      "z": 2,
      "name": "Soil_Clay_Lime"
    },
    {
      "x": -5,
      "y": 30,
      "z": 2,
      "name": "Soil_Sand"
    },
    {
      "x": -5,
      "y": 31,
      "z": 2,
      "name": "Plant_Bush_Arid_Sharp"
    },
    {
      "x": -5,
      "y": 2,
      "z": 3,
      "name": "Plant_Moss_Block_Yellow"
    },
    {
      "x": -5,
      "y": 3,
      "z": 3,
      "name": "Plant_Moss_Block_Yellow"
    },
    {
      "x": -5,
      "y": 4,
      "z": 3,
      "name": "Plant_Moss_Block_Yellow"
    },
    {
      "x": -5,
      "y": 5,
      "z": 3,
      "name": "Soil_Sand"
    },
    {
      "x": -5,
      "y": 6,
      "z": 3,
      "name": "Soil_Sand"
    },
    {
      "x": -5,
      "y": 7,
      "z": 3,
      "name": "Soil_Sand"
    },
    {
      "x": -5,
      "y": 8,
      "z": 3,
      "name": "Soil_Sand"
    },
    {
      "x": -5,
      "y": 9,
      "z": 3,
      "name": "Soil_Sand"
    },
    {
      "x": -5,
      "y": 10,
      "z": 3,
      "name": "Soil_Sand"
    },
    {
      "x": -5,
      "y": 11,
      "z": 3,
      "name": "Soil_Sand"
    },
    {
      "x": -5,
      "y": 12,
      "z": 3,
      "name": "Soil_Sand"
    },
    {
      "x": -5,
      "y": 13,
      "z": 3,
      "name": "Plant_Flower_Bushy_Yellow"
    },
    {
      "x": -5,
      "y": 15,
      "z": 3,
      "name": "Soil_Clay_Lime"
    },
    {
      "x": -5,
      "y": 16,
      "z": 3,
      "name": "Soil_Clay_Lime"
    },
    {
      "x": -5,
      "y": 17,
      "z": 3,
      "name": "Soil_Clay_Lime"
    },
    {
      "x": -5,
      "y": 18,
      "z": 3,
      "name": "Rock_Stone_Mossy"
    },
    {
      "x": -5,
      "y": 19,
      "z": 3,
      "name": "Soil_Clay_Lime"
    },
    {
      "x": -5,
      "y": 21,
      "z": 3,
      "name": "Soil_Clay_Lime"
    },
    {
      "x": -5,
      "y": 22,
      "z": 3,
      "name": "Plant_Moss_Block_Yellow"
    },
    {
      "x": -5,
      "y": 23,
      "z": 3,
      "name": "Plant_Moss_Block_Yellow"
    },
    {
      "x": -5,
      "y": 24,
      "z": 3,
      "name": "Plant_Moss_Block_Yellow"
    },
    {
      "x": -5,
      "y": 25,
      "z": 3,
      "name": "Plant_Moss_Block_Yellow"
    },
    {
      "x": -5,
      "y": 26,
      "z": 3,
      "name": "Soil_Clay_Lime"
    },
    {
      "x": -5,
      "y": 27,
      "z": 3,
      "name": "Rock_Stone_Mossy"
    },
    {
      "x": -5,
      "y": 28,
      "z": 3,
      "name": "Rock_Stone_Mossy"
    },
    {
      "x": -5,
      "y": 29,
      "z": 3,
      "name": "Rock_Stone_Mossy"
    },
    {
      "x": -5,
      "y": 5,
      "z": 4,
      "name": "Plant_Moss_Block_Yellow"
    },
    {
      "x": -5,
      "y": 6,
      "z": 4,
      "name": "Plant_Moss_Block_Yellow"
    },
    {
      "x": -5,
      "y": 7,
      "z": 4,
      "name": "Soil_Clay_Lime"
    },
    {
      "x": -5,
      "y": 8,
      "z": 4,
      "name": "Soil_Clay_Lime"
    },
    {
      "x": -5,
      "y": 9,
      "z": 4,
      "name": "Soil_Clay_Lime"
    },
    {
      "x": -5,
      "y": 10,
      "z": 4,
      "name": "Soil_Clay_Lime"
    },
    {
      "x": -5,
      "y": 11,
      "z": 4,
      "name": "Soil_Sand"
    },
    {
      "x": -5,
      "y": 12,
      "z": 4,
      "name": "Soil_Clay_Lime"
    },
    {
      "x": -5,
      "y": 15,
      "z": 4,
      "name": "Soil_Clay_Lime"
    },
    {
      "x": -5,
      "y": 16,
      "z": 4,
      "name": "Soil_Clay_Lime"
    },
    {
      "x": -5,
      "y": 17,
      "z": 4,
      "name": "Soil_Clay_Lime"
    },
    {
      "x": -5,
      "y": 18,
      "z": 4,
      "name": "Soil_Clay_Lime"
    },
    {
      "x": -5,
      "y": 21,
      "z": 4,
      "name": "Plant_Moss_Block_Yellow"
    },
    {
      "x": -5,
      "y": 22,
      "z": 4,
      "name": "Plant_Moss_Block_Yellow"
    },
    {
      "x": -5,
      "y": 23,
      "z": 4,
      "name": "Plant_Moss_Block_Yellow"
    },
    {
      "x": -5,
      "y": 24,
      "z": 4,
      "name": "Plant_Moss_Block_Yellow"
    },
    {
      "x": -5,
      "y": 25,
      "z": 4,
      "name": "Plant_Moss_Block_Yellow"
    },
    {
      "x": -5,
      "y": 26,
      "z": 4,
      "name": "Soil_Clay_Lime"
    },
    {
      "x": -5,
      "y": 27,
      "z": 4,
      "name": "Rock_Stone_Mossy"
    },
    {
      "x": -5,
      "y": 28,
      "z": 4,
      "name": "Rock_Stone_Mossy"
    },
    {
      "x": -5,
      "y": 29,
      "z": 4,
      "name": "Rock_Stone_Mossy"
    },
    {
      "x": -4,
      "y": 8,
      "z": -6,
      "name": "Rock_Stone_Mossy"
    },
    {
      "x": -4,
      "y": 9,
      "z": -6,
      "name": "Rock_Stone_Mossy"
    },
    {
      "x": -4,
      "y": 10,
      "z": -6,
      "name": "Soil_Clay_Lime"
    },
    {
      "x": -4,
      "y": 11,
      "z": -6,
      "name": "Soil_Sand"
    },
    {
      "x": -4,
      "y": 12,
      "z": -6,
      "name": "Plant_Flower_Bushy_Yellow"
    },
    {
      "x": -4,
      "y": 4,
      "z": -5,
      "name": "Soil_Clay_Lime"
    },
    {
      "x": -4,
      "y": 5,
      "z": -5,
      "name": "Soil_Clay_Lime"
    },
    {
      "x": -4,
      "y": 6,
      "z": -5,
      "name": "Rock_Stone_Mossy"
    },
    {
      "x": -4,
      "y": 7,
      "z": -5,
      "name": "Rock_Stone_Mossy"
    },
    {
      "x": -4,
      "y": 8,
      "z": -5,
      "name": "Soil_Sand"
    },
    {
      "x": -4,
      "y": 9,
      "z": -5,
      "name": "Soil_Sand"
    },
    {
      "x": -4,
      "y": 10,
      "z": -5,
      "name": "Soil_Sand"
    },
    {
      "x": -4,
      "y": 11,
      "z": -5,
      "name": "Soil_Sand"
    },
    {
      "x": -4,
      "y": 12,
      "z": -5,
      "name": "Soil_Sand"
    },
    {
      "x": -4,
      "y": 13,
      "z": -5,
      "name": "Plant_Flower_Bushy_Yellow"
    },
    {
      "x": -4,
      "y": 15,
      "z": -5,
      "name": "Plant_Moss_Block_Yellow"
    },
    {
      "x": -4,
      "y": 16,
      "z": -5,
      "name": "Plant_Moss_Block_Yellow"
    },
    {
      "x": -4,
      "y": 17,
      "z": -5,
      "name": "Plant_Moss_Block_Yellow"
    },
    {
      "x": -4,
      "y": 18,
      "z": -5,
      "name": "Soil_Clay_Lime"
    },
    {
      "x": -4,
      "y": 21,
      "z": -5,
      "name": "Rock_Stone_Mossy"
    },
    {
      "x": -4,
      "y": 22,
      "z": -5,
      "name": "Rock_Stone_Mossy"
    },
    {
      "x": -4,
      "y": 23,
      "z": -5,
      "name": "Rock_Stone_Mossy"
    },
    {
      "x": -4,
      "y": 24,
      "z": -5,
      "name": "Rock_Stone_Mossy"
    },
    {
      "x": -4,
      "y": 25,
      "z": -5,
      "name": "Rock_Stone_Mossy"
    },
    {
      "x": -4,
      "y": 26,
      "z": -5,
      "name": "Rock_Stone_Mossy"
    },
    {
      "x": -4,
      "y": 27,
      "z": -5,
      "name": "Soil_Clay_Lime"
    },
    {
      "x": -4,
      "y": 28,
      "z": -5,
      "name": "Soil_Clay_Lime"
    },
    {
      "x": -4,
      "y": 29,
      "z": -5,
      "name": "Soil_Clay_Lime"
    },
    {
      "x": -4,
      "y": 2,
      "z": -4,
      "name": "Soil_Clay_Lime"
    },
    {
      "x": -4,
      "y": 3,
      "z": -4,
      "name": "Soil_Clay_Lime"
    },
    {
      "x": -4,
      "y": 4,
      "z": -4,
      "name": "Soil_Sand"
    },
    {
      "x": -4,
      "y": 5,
      "z": -4,
      "name": "Soil_Sand"
    },
    {
      "x": -4,
      "y": 6,
      "z": -4,
      "name": "Soil_Sand"
    },
    {
      "x": -4,
      "y": 7,
      "z": -4,
      "name": "Soil_Sand"
    },
    {
      "x": -4,
      "y": 8,
      "z": -4,
      "name": "Soil_Sand"
    },
    {
      "x": -4,
      "y": 9,
      "z": -4,
      "name": "Soil_Sand"
    },
    {
      "x": -4,
      "y": 10,
      "z": -4,
      "name": "Soil_Sand"
    },
    {
      "x": -4,
      "y": 11,
      "z": -4,
      "name": "Soil_Sand"
    },
    {
      "x": -4,
      "y": 12,
      "z": -4,
      "name": "Soil_Sand"
    },
    {
      "x": -4,
      "y": 13,
      "z": -4,
      "name": "Plant_Flower_Bushy_Yellow"
    },
    {
      "x": -4,
      "y": 15,
      "z": -4,
      "name": "Soil_Sand"
    },
    {
      "x": -4,
      "y": 16,
      "z": -4,
      "name": "Soil_Sand"
    },
    {
      "x": -4,
      "y": 17,
      "z": -4,
      "name": "Soil_Sand"
    },
    {
      "x": -4,
      "y": 18,
      "z": -4,
      "name": "Soil_Sand"
    },
    {
      "x": -4,
      "y": 19,
      "z": -4,
      "name": "Soil_Clay_Lime"
    },
    {
      "x": -4,
      "y": 21,
      "z": -4,
      "name": "Rock_Stone_Mossy"
    },
    {
      "x": -4,
      "y": 22,
      "z": -4,
      "name": "Soil_Sand"
    },
    {
      "x": -4,
      "y": 23,
      "z": -4,
      "name": "Soil_Sand"
    },
    {
      "x": -4,
      "y": 24,
      "z": -4,
      "name": "Soil_Sand"
    },
    {
      "x": -4,
      "y": 25,
      "z": -4,
      "name": "Soil_Sand"
    },
    {
      "x": -4,
      "y": 26,
      "z": -4,
      "name": "Soil_Sand"
    },
    {
      "x": -4,
      "y": 27,
      "z": -4,
      "name": "Soil_Sand"
    },
    {
      "x": -4,
      "y": 28,
      "z": -4,
      "name": "Soil_Sand"
    },
    {
      "x": -4,
      "y": 29,
      "z": -4,
      "name": "Soil_Sand"
    },
    {
      "x": -4,
      "y": 30,
      "z": -4,
      "name": "Rock_Stone_Mossy"
    },
    {
      "x": -4,
      "y": 31,
      "z": -4,
      "name": "Soil_Sand"
    },
    {
      "x": -4,
      "y": 32,
      "z": -4,
      "name": "Plant_Leaves_Palm_Arid"
    },
    {
      "x": -4,
      "y": 2,
      "z": -3,
      "name": "Soil_Clay_Lime"
    },
    {
      "x": -4,
      "y": 3,
      "z": -3,
      "name": "Soil_Sand"
    },
    {
      "x": -4,
      "y": 4,
      "z": -3,
      "name": "Soil_Sand"
    },
    {
      "x": -4,
      "y": 5,
      "z": -3,
      "name": "Soil_Sand"
    },
    {
      "x": -4,
      "y": 6,
      "z": -3,
      "name": "Soil_Sand"
    },
    {
      "x": -4,
      "y": 7,
      "z": -3,
      "name": "Soil_Sand"
    },
    {
      "x": -4,
      "y": 8,
      "z": -3,
      "name": "Soil_Sand"
    },
    {
      "x": -4,
      "y": 9,
      "z": -3,
      "name": "Soil_Sand"
    },
    {
      "x": -4,
      "y": 10,
      "z": -3,
      "name": "Soil_Sand"
    },
    {
      "x": -4,
      "y": 11,
      "z": -3,
      "name": "Soil_Sand"
    },
    {
      "x": -4,
      "y": 12,
      "z": -3,
      "name": "Soil_Sand"
    },
    {
      "x": -4,
      "y": 13,
      "z": -3,
      "name": "Plant_Flower_Bushy_Yellow"
    },
    {
      "x": -4,
      "y": 15,
      "z": -3,
      "name": "Soil_Sand"
    },
    {
      "x": -4,
      "y": 16,
      "z": -3,
      "name": "Soil_Sand"
    },
    {
      "x": -4,
      "y": 17,
      "z": -3,
      "name": "Soil_Sand"
    },
    {
      "x": -4,
      "y": 18,
      "z": -3,
      "name": "Soil_Sand"
    },
    {
      "x": -4,
      "y": 19,
      "z": -3,
      "name": "Soil_Clay_Lime"
    },
    {
      "x": -4,
      "y": 21,
      "z": -3,
      "name": "Rock_Stone_Mossy"
    },
    {
      "x": -4,
      "y": 22,
      "z": -3,
      "name": "Soil_Sand"
    },
    {
      "x": -4,
      "y": 23,
      "z": -3,
      "name": "Soil_Sand"
    },
    {
      "x": -4,
      "y": 24,
      "z": -3,
      "name": "Soil_Sand"
    },
    {
      "x": -4,
      "y": 25,
      "z": -3,
      "name": "Soil_Sand"
    },
    {
      "x": -4,
      "y": 26,
      "z": -3,
      "name": "Soil_Sand"
    },
    {
      "x": -4,
      "y": 27,
      "z": -3,
      "name": "Soil_Sand"
    },
    {
      "x": -4,
      "y": 28,
      "z": -3,
      "name": "Soil_Sand"
    },
    {
      "x": -4,
      "y": 29,
      "z": -3,
      "name": "Soil_Sand"
    },
    {
      "x": -4,
      "y": 30,
      "z": -3,
      "name": "Soil_Sand"
    },
    {
      "x": -4,
      "y": 31,
      "z": -3,
      "name": "Soil_Sand"
    },
    {
      "x": -4,
      "y": 32,
      "z": -3,
      "name": "Plant_Flower_Bushy_Yellow"
    },
    {
      "x": -4,
      "y": 1,
      "z": -2,
      "name": "Soil_Clay_Lime"
    },
    {
      "x": -4,
      "y": 2,
      "z": -2,
      "name": "Soil_Sand"
    },
    {
      "x": -4,
      "y": 3,
      "z": -2,
      "name": "Soil_Sand"
    },
    {
      "x": -4,
      "y": 4,
      "z": -2,
      "name": "Soil_Sand"
    },
    {
      "x": -4,
      "y": 5,
      "z": -2,
      "name": "Soil_Sand"
    },
    {
      "x": -4,
      "y": 6,
      "z": -2,
      "name": "Soil_Sand"
    },
    {
      "x": -4,
      "y": 7,
      "z": -2,
      "name": "Soil_Sand"
    },
    {
      "x": -4,
      "y": 8,
      "z": -2,
      "name": "Soil_Sand"
    },
    {
      "x": -4,
      "y": 9,
      "z": -2,
      "name": "Soil_Sand"
    },
    {
      "x": -4,
      "y": 10,
      "z": -2,
      "name": "Soil_Sand"
    },
    {
      "x": -4,
      "y": 11,
      "z": -2,
      "name": "Soil_Sand"
    },
    {
      "x": -4,
      "y": 12,
      "z": -2,
      "name": "Soil_Sand"
    },
    {
      "x": -4,
      "y": 13,
      "z": -2,
      "name": "Plant_Leaves_Palm_Arid"
    },
    {
      "x": -4,
      "y": 14,
      "z": -2,
      "name": "Soil_Clay_Lime"
    },
    {
      "x": -4,
      "y": 15,
      "z": -2,
      "name": "Soil_Sand"
    },
    {
      "x": -4,
      "y": 16,
      "z": -2,
      "name": "Soil_Sand"
    },
    {
      "x": -4,
      "y": 17,
      "z": -2,
      "name": "Soil_Sand"
    },
    {
      "x": -4,
      "y": 18,
      "z": -2,
      "name": "Soil_Sand"
    },
    {
      "x": -4,
      "y": 19,
      "z": -2,
      "name": "Soil_Clay_Lime"
    },
    {
      "x": -4,
      "y": 21,
      "z": -2,
      "name": "Rock_Stone_Mossy"
    },
    {
      "x": -4,
      "y": 22,
      "z": -2,
      "name": "Soil_Sand"
    },
    {
      "x": -4,
      "y": 23,
      "z": -2,
      "name": "Soil_Sand"
    },
    {
      "x": -4,
      "y": 24,
      "z": -2,
      "name": "Soil_Sand"
    },
    {
      "x": -4,
      "y": 25,
      "z": -2,
      "name": "Soil_Sand"
    },
    {
      "x": -4,
      "y": 26,
      "z": -2,
      "name": "Soil_Sand"
    },
    {
      "x": -4,
      "y": 27,
      "z": -2,
      "name": "Soil_Sand"
    },
    {
      "x": -4,
      "y": 28,
      "z": -2,
      "name": "Soil_Sand"
    },
    {
      "x": -4,
      "y": 29,
      "z": -2,
      "name": "Soil_Sand"
    },
    {
      "x": -4,
      "y": 30,
      "z": -2,
      "name": "Soil_Sand"
    },
    {
      "x": -4,
      "y": 31,
      "z": -2,
      "name": "Soil_Sand"
    },
    {
      "x": -4,
      "y": 32,
      "z": -2,
      "name": "Plant_Flower_Bushy_Yellow"
    },
    {
      "x": -4,
      "y": 1,
      "z": -1,
      "name": "Plant_Moss_Block_Yellow"
    },
    {
      "x": -4,
      "y": 2,
      "z": -1,
      "name": "Soil_Sand"
    },
    {
      "x": -4,
      "y": 3,
      "z": -1,
      "name": "Soil_Sand"
    },
    {
      "x": -4,
      "y": 4,
      "z": -1,
      "name": "Soil_Sand"
    },
    {
      "x": -4,
      "y": 5,
      "z": -1,
      "name": "Soil_Sand"
    },
    {
      "x": -4,
      "y": 6,
      "z": -1,
      "name": "Soil_Sand"
    },
    {
      "x": -4,
      "y": 7,
      "z": -1,
      "name": "Soil_Sand"
    },
    {
      "x": -4,
      "y": 8,
      "z": -1,
      "name": "Soil_Sand"
    },
    {
      "x": -4,
      "y": 9,
      "z": -1,
      "name": "Soil_Sand"
    },
    {
      "x": -4,
      "y": 10,
      "z": -1,
      "name": "Soil_Sand"
    },
    {
      "x": -4,
      "y": 11,
      "z": -1,
      "name": "Soil_Sand"
    },
    {
      "x": -4,
      "y": 12,
      "z": -1,
      "name": "Soil_Clay_Lime"
    },
    {
      "x": -4,
      "y": 13,
      "z": -1,
      "name": "Soil_Clay_Lime"
    },
    {
      "x": -4,
      "y": 14,
      "z": -1,
      "name": "Soil_Sand"
    },
    {
      "x": -4,
      "y": 15,
      "z": -1,
      "name": "Soil_Sand"
    },
    {
      "x": -4,
      "y": 16,
      "z": -1,
      "name": "Soil_Sand"
    },
    {
      "x": -4,
      "y": 17,
      "z": -1,
      "name": "Soil_Sand"
    },
    {
      "x": -4,
      "y": 18,
      "z": -1,
      "name": "Soil_Sand"
    },
    {
      "x": -4,
      "y": 19,
      "z": -1,
      "name": "Soil_Clay_Lime"
    },
    {
      "x": -4,
      "y": 21,
      "z": -1,
      "name": "Soil_Clay_Lime"
    },
    {
      "x": -4,
      "y": 22,
      "z": -1,
      "name": "Soil_Sand"
    },
    {
      "x": -4,
      "y": 23,
      "z": -1,
      "name": "Soil_Sand"
    },
    {
      "x": -4,
      "y": 24,
      "z": -1,
      "name": "Soil_Sand"
    },
    {
      "x": -4,
      "y": 25,
      "z": -1,
      "name": "Soil_Sand"
    },
    {
      "x": -4,
      "y": 26,
      "z": -1,
      "name": "Soil_Sand"
    },
    {
      "x": -4,
      "y": 27,
      "z": -1,
      "name": "Soil_Sand"
    },
    {
      "x": -4,
      "y": 28,
      "z": -1,
      "name": "Soil_Sand"
    },
    {
      "x": -4,
      "y": 29,
      "z": -1,
      "name": "Soil_Sand"
    },
    {
      "x": -4,
      "y": 30,
      "z": -1,
      "name": "Soil_Sand"
    },
    {
      "x": -4,
      "y": 31,
      "z": -1,
      "name": "Soil_Sand"
    },
    {
      "x": -4,
      "y": 32,
      "z": -1,
      "name": "Plant_Flower_Bushy_Yellow"
    },
    {
      "x": -4,
      "y": 1,
      "z": 0,
      "name": "Plant_Moss_Block_Yellow"
    },
    {
      "x": -4,
      "y": 2,
      "z": 0,
      "name": "Soil_Sand"
    },
    {
      "x": -4,
      "y": 3,
      "z": 0,
      "name": "Soil_Sand"
    },
    {
      "x": -4,
      "y": 4,
      "z": 0,
      "name": "Soil_Sand"
    },
    {
      "x": -4,
      "y": 5,
      "z": 0,
      "name": "Soil_Sand"
    },
    {
      "x": -4,
      "y": 6,
      "z": 0,
      "name": "Soil_Sand"
    },
    {
      "x": -4,
      "y": 7,
      "z": 0,
      "name": "Soil_Sand"
    },
    {
      "x": -4,
      "y": 8,
      "z": 0,
      "name": "Soil_Sand"
    },
    {
      "x": -4,
      "y": 9,
      "z": 0,
      "name": "Soil_Sand"
    },
    {
      "x": -4,
      "y": 10,
      "z": 0,
      "name": "Soil_Sand"
    },
    {
      "x": -4,
      "y": 11,
      "z": 0,
      "name": "Soil_Sand"
    },
    {
      "x": -4,
      "y": 12,
      "z": 0,
      "name": "Soil_Sand"
    },
    {
      "x": -4,
      "y": 13,
      "z": 0,
      "name": "Soil_Clay_Lime"
    },
    {
      "x": -4,
      "y": 14,
      "z": 0,
      "name": "Soil_Sand"
    },
    {
      "x": -4,
      "y": 15,
      "z": 0,
      "name": "Soil_Sand"
    },
    {
      "x": -4,
      "y": 16,
      "z": 0,
      "name": "Soil_Sand"
    },
    {
      "x": -4,
      "y": 17,
      "z": 0,
      "name": "Soil_Sand"
    },
    {
      "x": -4,
      "y": 18,
      "z": 0,
      "name": "Soil_Sand"
    },
    {
      "x": -4,
      "y": 19,
      "z": 0,
      "name": "Soil_Clay_Lime"
    },
    {
      "x": -4,
      "y": 21,
      "z": 0,
      "name": "Soil_Clay_Lime"
    },
    {
      "x": -4,
      "y": 22,
      "z": 0,
      "name": "Soil_Sand"
    },
    {
      "x": -4,
      "y": 23,
      "z": 0,
      "name": "Soil_Sand"
    },
    {
      "x": -4,
      "y": 24,
      "z": 0,
      "name": "Soil_Sand"
    },
    {
      "x": -4,
      "y": 25,
      "z": 0,
      "name": "Soil_Sand"
    },
    {
      "x": -4,
      "y": 26,
      "z": 0,
      "name": "Soil_Sand"
    },
    {
      "x": -4,
      "y": 27,
      "z": 0,
      "name": "Soil_Sand"
    },
    {
      "x": -4,
      "y": 28,
      "z": 0,
      "name": "Soil_Sand"
    },
    {
      "x": -4,
      "y": 29,
      "z": 0,
      "name": "Soil_Sand"
    },
    {
      "x": -4,
      "y": 30,
      "z": 0,
      "name": "Soil_Sand"
    },
    {
      "x": -4,
      "y": 31,
      "z": 0,
      "name": "Soil_Sand"
    },
    {
      "x": -4,
      "y": 32,
      "z": 0,
      "name": "Plant_Flower_Bushy_Yellow"
    },
    {
      "x": -4,
      "y": 1,
      "z": 1,
      "name": "Plant_Moss_Block_Yellow"
    },
    {
      "x": -4,
      "y": 2,
      "z": 1,
      "name": "Soil_Sand"
    },
    {
      "x": -4,
      "y": 3,
      "z": 1,
      "name": "Soil_Sand"
    },
    {
      "x": -4,
      "y": 4,
      "z": 1,
      "name": "Soil_Sand"
    },
    {
      "x": -4,
      "y": 5,
      "z": 1,
      "name": "Soil_Sand"
    },
    {
      "x": -4,
      "y": 6,
      "z": 1,
      "name": "Soil_Sand"
    },
    {
      "x": -4,
      "y": 7,
      "z": 1,
      "name": "Soil_Sand"
    },
    {
      "x": -4,
      "y": 8,
      "z": 1,
      "name": "Soil_Sand"
    },
    {
      "x": -4,
      "y": 9,
      "z": 1,
      "name": "Soil_Sand"
    },
    {
      "x": -4,
      "y": 10,
      "z": 1,
      "name": "Soil_Sand"
    },
    {
      "x": -4,
      "y": 11,
      "z": 1,
      "name": "Soil_Sand"
    },
    {
      "x": -4,
      "y": 12,
      "z": 1,
      "name": "Soil_Sand"
    },
    {
      "x": -4,
      "y": 13,
      "z": 1,
      "name": "Soil_Clay_Lime"
    },
    {
      "x": -4,
      "y": 14,
      "z": 1,
      "name": "Soil_Sand"
    },
    {
      "x": -4,
      "y": 15,
      "z": 1,
      "name": "Soil_Sand"
    },
    {
      "x": -4,
      "y": 16,
      "z": 1,
      "name": "Soil_Sand"
    },
    {
      "x": -4,
      "y": 17,
      "z": 1,
      "name": "Soil_Sand"
    },
    {
      "x": -4,
      "y": 18,
      "z": 1,
      "name": "Soil_Sand"
    },
    {
      "x": -4,
      "y": 19,
      "z": 1,
      "name": "Soil_Clay_Lime"
    },
    {
      "x": -4,
      "y": 21,
      "z": 1,
      "name": "Soil_Clay_Lime"
    },
    {
      "x": -4,
      "y": 22,
      "z": 1,
      "name": "Soil_Sand"
    },
    {
      "x": -4,
      "y": 23,
      "z": 1,
      "name": "Soil_Sand"
    },
    {
      "x": -4,
      "y": 24,
      "z": 1,
      "name": "Soil_Sand"
    },
    {
      "x": -4,
      "y": 25,
      "z": 1,
      "name": "Soil_Sand"
    },
    {
      "x": -4,
      "y": 26,
      "z": 1,
      "name": "Soil_Sand"
    },
    {
      "x": -4,
      "y": 27,
      "z": 1,
      "name": "Soil_Sand"
    },
    {
      "x": -4,
      "y": 28,
      "z": 1,
      "name": "Soil_Sand"
    },
    {
      "x": -4,
      "y": 29,
      "z": 1,
      "name": "Soil_Sand"
    },
    {
      "x": -4,
      "y": 30,
      "z": 1,
      "name": "Soil_Sand"
    },
    {
      "x": -4,
      "y": 31,
      "z": 1,
      "name": "Soil_Sand"
    },
    {
      "x": -4,
      "y": 32,
      "z": 1,
      "name": "Plant_Flower_Bushy_Yellow"
    },
    {
      "x": -4,
      "y": 1,
      "z": 2,
      "name": "Plant_Moss_Block_Yellow"
    },
    {
      "x": -4,
      "y": 2,
      "z": 2,
      "name": "Soil_Sand"
    },
    {
      "x": -4,
      "y": 3,
      "z": 2,
      "name": "Soil_Sand"
    },
    {
      "x": -4,
      "y": 4,
      "z": 2,
      "name": "Soil_Sand"
    },
    {
      "x": -4,
      "y": 5,
      "z": 2,
      "name": "Soil_Sand"
    },
    {
      "x": -4,
      "y": 6,
      "z": 2,
      "name": "Soil_Sand"
    },
    {
      "x": -4,
      "y": 7,
      "z": 2,
      "name": "Soil_Sand"
    },
    {
      "x": -4,
      "y": 8,
      "z": 2,
      "name": "Soil_Sand"
    },
    {
      "x": -4,
      "y": 9,
      "z": 2,
      "name": "Soil_Sand"
    },
    {
      "x": -4,
      "y": 10,
      "z": 2,
      "name": "Soil_Sand"
    },
    {
      "x": -4,
      "y": 11,
      "z": 2,
      "name": "Soil_Sand"
    },
    {
      "x": -4,
      "y": 12,
      "z": 2,
      "name": "Soil_Sand"
    },
    {
      "x": -4,
      "y": 13,
      "z": 2,
      "name": "Soil_Clay_Lime"
    },
    {
      "x": -4,
      "y": 14,
      "z": 2,
      "name": "Soil_Sand"
    },
    {
      "x": -4,
      "y": 15,
      "z": 2,
      "name": "Soil_Sand"
    },
    {
      "x": -4,
      "y": 16,
      "z": 2,
      "name": "Soil_Sand"
    },
    {
      "x": -4,
      "y": 17,
      "z": 2,
      "name": "Soil_Sand"
    },
    {
      "x": -4,
      "y": 18,
      "z": 2,
      "name": "Soil_Sand"
    },
    {
      "x": -4,
      "y": 19,
      "z": 2,
      "name": "Soil_Clay_Lime"
    },
    {
      "x": -4,
      "y": 21,
      "z": 2,
      "name": "Soil_Clay_Lime"
    },
    {
      "x": -4,
      "y": 22,
      "z": 2,
      "name": "Soil_Sand"
    },
    {
      "x": -4,
      "y": 23,
      "z": 2,
      "name": "Soil_Sand"
    },
    {
      "x": -4,
      "y": 24,
      "z": 2,
      "name": "Soil_Sand"
    },
    {
      "x": -4,
      "y": 25,
      "z": 2,
      "name": "Soil_Sand"
    },
    {
      "x": -4,
      "y": 26,
      "z": 2,
      "name": "Soil_Sand"
    },
    {
      "x": -4,
      "y": 27,
      "z": 2,
      "name": "Soil_Sand"
    },
    {
      "x": -4,
      "y": 28,
      "z": 2,
      "name": "Soil_Sand"
    },
    {
      "x": -4,
      "y": 29,
      "z": 2,
      "name": "Soil_Sand"
    },
    {
      "x": -4,
      "y": 30,
      "z": 2,
      "name": "Soil_Sand"
    },
    {
      "x": -4,
      "y": 31,
      "z": 2,
      "name": "Plant_Bush_Arid_Sharp"
    },
    {
      "x": -4,
      "y": 2,
      "z": 3,
      "name": "Plant_Moss_Block_Yellow"
    },
    {
      "x": -4,
      "y": 3,
      "z": 3,
      "name": "Soil_Sand"
    },
    {
      "x": -4,
      "y": 4,
      "z": 3,
      "name": "Soil_Sand"
    },
    {
      "x": -4,
      "y": 5,
      "z": 3,
      "name": "Soil_Sand"
    },
    {
      "x": -4,
      "y": 6,
      "z": 3,
      "name": "Soil_Sand"
    },
    {
      "x": -4,
      "y": 7,
      "z": 3,
      "name": "Soil_Sand"
    },
    {
      "x": -4,
      "y": 8,
      "z": 3,
      "name": "Soil_Sand"
    },
    {
      "x": -4,
      "y": 9,
      "z": 3,
      "name": "Soil_Sand"
    },
    {
      "x": -4,
      "y": 10,
      "z": 3,
      "name": "Soil_Sand"
    },
    {
      "x": -4,
      "y": 11,
      "z": 3,
      "name": "Soil_Sand"
    },
    {
      "x": -4,
      "y": 12,
      "z": 3,
      "name": "Soil_Sand"
    },
    {
      "x": -4,
      "y": 13,
      "z": 3,
      "name": "Plant_Bush_Arid_Sharp"
    },
    {
      "x": -4,
      "y": 14,
      "z": 3,
      "name": "Rock_Stone_Mossy"
    },
    {
      "x": -4,
      "y": 15,
      "z": 3,
      "name": "Soil_Sand"
    },
    {
      "x": -4,
      "y": 16,
      "z": 3,
      "name": "Soil_Sand"
    },
    {
      "x": -4,
      "y": 17,
      "z": 3,
      "name": "Soil_Sand"
    },
    {
      "x": -4,
      "y": 18,
      "z": 3,
      "name": "Soil_Sand"
    },
    {
      "x": -4,
      "y": 19,
      "z": 3,
      "name": "Soil_Clay_Lime"
    },
    {
      "x": -4,
      "y": 21,
      "z": 3,
      "name": "Plant_Moss_Block_Yellow"
    },
    {
      "x": -4,
      "y": 22,
      "z": 3,
      "name": "Soil_Sand"
    },
    {
      "x": -4,
      "y": 23,
      "z": 3,
      "name": "Soil_Sand"
    },
    {
      "x": -4,
      "y": 24,
      "z": 3,
      "name": "Soil_Sand"
    },
    {
      "x": -4,
      "y": 25,
      "z": 3,
      "name": "Soil_Sand"
    },
    {
      "x": -4,
      "y": 26,
      "z": 3,
      "name": "Soil_Sand"
    },
    {
      "x": -4,
      "y": 27,
      "z": 3,
      "name": "Soil_Sand"
    },
    {
      "x": -4,
      "y": 28,
      "z": 3,
      "name": "Soil_Sand"
    },
    {
      "x": -4,
      "y": 29,
      "z": 3,
      "name": "Soil_Sand"
    },
    {
      "x": -4,
      "y": 30,
      "z": 3,
      "name": "Soil_Sand"
    },
    {
      "x": -4,
      "y": 31,
      "z": 3,
      "name": "Plant_Flower_Bushy_Yellow"
    },
    {
      "x": -4,
      "y": 2,
      "z": 4,
      "name": "Plant_Moss_Block_Yellow"
    },
    {
      "x": -4,
      "y": 3,
      "z": 4,
      "name": "Plant_Moss_Block_Yellow"
    },
    {
      "x": -4,
      "y": 4,
      "z": 4,
      "name": "Plant_Moss_Block_Yellow"
    },
    {
      "x": -4,
      "y": 5,
      "z": 4,
      "name": "Plant_Moss_Block_Yellow"
    },
    {
      "x": -4,
      "y": 6,
      "z": 4,
      "name": "Soil_Sand"
    },
    {
      "x": -4,
      "y": 7,
      "z": 4,
      "name": "Soil_Sand"
    },
    {
      "x": -4,
      "y": 8,
      "z": 4,
      "name": "Soil_Sand"
    },
    {
      "x": -4,
      "y": 9,
      "z": 4,
      "name": "Soil_Sand"
    },
    {
      "x": -4,
      "y": 10,
      "z": 4,
      "name": "Soil_Sand"
    },
    {
      "x": -4,
      "y": 11,
      "z": 4,
      "name": "Soil_Clay_Lime"
    },
    {
      "x": -4,
      "y": 12,
      "z": 4,
      "name": "Soil_Clay_Lime"
    },
    {
      "x": -4,
      "y": 14,
      "z": 4,
      "name": "Rock_Stone_Mossy"
    },
    {
      "x": -4,
      "y": 15,
      "z": 4,
      "name": "Soil_Sand"
    },
    {
      "x": -4,
      "y": 16,
      "z": 4,
      "name": "Soil_Sand"
    },
    {
      "x": -4,
      "y": 17,
      "z": 4,
      "name": "Soil_Sand"
    },
    {
      "x": -4,
      "y": 18,
      "z": 4,
      "name": "Soil_Sand"
    },
    {
      "x": -4,
      "y": 19,
      "z": 4,
      "name": "Soil_Clay_Lime"
    },
    {
      "x": -4,
      "y": 21,
      "z": 4,
      "name": "Plant_Moss_Block_Yellow"
    },
    {
      "x": -4,
      "y": 22,
      "z": 4,
      "name": "Soil_Sand"
    },
    {
      "x": -4,
      "y": 23,
      "z": 4,
      "name": "Soil_Sand"
    },
    {
      "x": -4,
      "y": 24,
      "z": 4,
      "name": "Soil_Sand"
    },
    {
      "x": -4,
      "y": 25,
      "z": 4,
      "name": "Soil_Sand"
    },
    {
      "x": -4,
      "y": 26,
      "z": 4,
      "name": "Soil_Sand"
    },
    {
      "x": -4,
      "y": 27,
      "z": 4,
      "name": "Soil_Sand"
    },
    {
      "x": -4,
      "y": 28,
      "z": 4,
      "name": "Soil_Sand"
    },
    {
      "x": -4,
      "y": 29,
      "z": 4,
      "name": "Soil_Sand"
    },
    {
      "x": -4,
      "y": 30,
      "z": 4,
      "name": "Soil_Sand"
    },
    {
      "x": -4,
      "y": 31,
      "z": 4,
      "name": "Plant_Flower_Bushy_Yellow"
    },
    {
      "x": -4,
      "y": 6,
      "z": 5,
      "name": "Soil_Clay_Lime"
    },
    {
      "x": -4,
      "y": 7,
      "z": 5,
      "name": "Rock_Stone_Mossy"
    },
    {
      "x": -4,
      "y": 8,
      "z": 5,
      "name": "Rock_Stone_Mossy"
    },
    {
      "x": -4,
      "y": 9,
      "z": 5,
      "name": "Soil_Clay_Lime"
    },
    {
      "x": -4,
      "y": 10,
      "z": 5,
      "name": "Soil_Clay_Lime"
    },
    {
      "x": -4,
      "y": 15,
      "z": 5,
      "name": "Soil_Clay_Lime"
    },
    {
      "x": -4,
      "y": 16,
      "z": 5,
      "name": "Soil_Clay_Lime"
    },
    {
      "x": -4,
      "y": 17,
      "z": 5,
      "name": "Soil_Clay_Lime"
    },
    {
      "x": -4,
      "y": 18,
      "z": 5,
      "name": "Soil_Clay_Lime"
    },
    {
      "x": -4,
      "y": 21,
      "z": 5,
      "name": "Plant_Moss_Block_Yellow"
    },
    {
      "x": -4,
      "y": 22,
      "z": 5,
      "name": "Plant_Moss_Block_Yellow"
    },
    {
      "x": -4,
      "y": 23,
      "z": 5,
      "name": "Plant_Moss_Block_Yellow"
    },
    {
      "x": -4,
      "y": 24,
      "z": 5,
      "name": "Plant_Moss_Block_Yellow"
    },
    {
      "x": -4,
      "y": 25,
      "z": 5,
      "name": "Plant_Moss_Block_Yellow"
    },
    {
      "x": -4,
      "y": 26,
      "z": 5,
      "name": "Soil_Clay_Lime"
    },
    {
      "x": -4,
      "y": 27,
      "z": 5,
      "name": "Rock_Stone_Mossy"
    },
    {
      "x": -4,
      "y": 28,
      "z": 5,
      "name": "Rock_Stone_Mossy"
    },
    {
      "x": -4,
      "y": 29,
      "z": 5,
      "name": "Rock_Stone_Mossy"
    },
    {
      "x": -3,
      "y": 5,
      "z": -6,
      "name": "Plant_Moss_Block_Yellow"
    },
    {
      "x": -3,
      "y": 6,
      "z": -6,
      "name": "Soil_Clay_Lime"
    },
    {
      "x": -3,
      "y": 7,
      "z": -6,
      "name": "Soil_Clay_Lime"
    },
    {
      "x": -3,
      "y": 8,
      "z": -6,
      "name": "Soil_Clay_Lime"
    },
    {
      "x": -3,
      "y": 9,
      "z": -6,
      "name": "Soil_Clay_Lime"
    },
    {
      "x": -3,
      "y": 10,
      "z": -6,
      "name": "Soil_Clay_Lime"
    },
    {
      "x": -3,
      "y": 11,
      "z": -6,
      "name": "Soil_Sand"
    },
    {
      "x": -3,
      "y": 12,
      "z": -6,
      "name": "Soil_Sand"
    },
    {
      "x": -3,
      "y": 13,
      "z": -6,
      "name": "Plant_Flower_Bushy_Yellow"
    },
    {
      "x": -3,
      "y": 3,
      "z": -5,
      "name": "Soil_Clay_Lime"
    },
    {
      "x": -3,
      "y": 4,
      "z": -5,
      "name": "Soil_Clay_Lime"
    },
    {
      "x": -3,
      "y": 5,
      "z": -5,
      "name": "Soil_Sand"
    },
    {
      "x": -3,
      "y": 6,
      "z": -5,
      "name": "Soil_Sand"
    },
    {
      "x": -3,
      "y": 7,
      "z": -5,
      "name": "Soil_Sand"
    },
    {
      "x": -3,
      "y": 8,
      "z": -5,
      "name": "Soil_Sand"
    },
    {
      "x": -3,
      "y": 9,
      "z": -5,
      "name": "Soil_Sand"
    },
    {
      "x": -3,
      "y": 10,
      "z": -5,
      "name": "Soil_Sand"
    },
    {
      "x": -3,
      "y": 11,
      "z": -5,
      "name": "Soil_Sand"
    },
    {
      "x": -3,
      "y": 12,
      "z": -5,
      "name": "Soil_Sand"
    },
    {
      "x": -3,
      "y": 13,
      "z": -5,
      "name": "Plant_Flower_Bushy_Yellow"
    },
    {
      "x": -3,
      "y": 15,
      "z": -5,
      "name": "Soil_Clay_Lime"
    },
    {
      "x": -3,
      "y": 16,
      "z": -5,
      "name": "Plant_Moss_Block_Yellow"
    },
    {
      "x": -3,
      "y": 17,
      "z": -5,
      "name": "Plant_Moss_Block_Yellow"
    },
    {
      "x": -3,
      "y": 18,
      "z": -5,
      "name": "Plant_Moss_Block_Yellow"
    },
    {
      "x": -3,
      "y": 19,
      "z": -5,
      "name": "Soil_Clay_Lime"
    },
    {
      "x": -3,
      "y": 21,
      "z": -5,
      "name": "Rock_Stone_Mossy"
    },
    {
      "x": -3,
      "y": 22,
      "z": -5,
      "name": "Rock_Stone_Mossy"
    },
    {
      "x": -3,
      "y": 23,
      "z": -5,
      "name": "Rock_Stone_Mossy"
    },
    {
      "x": -3,
      "y": 24,
      "z": -5,
      "name": "Rock_Stone_Mossy"
    },
    {
      "x": -3,
      "y": 25,
      "z": -5,
      "name": "Rock_Stone_Mossy"
    },
    {
      "x": -3,
      "y": 26,
      "z": -5,
      "name": "Rock_Stone_Mossy"
    },
    {
      "x": -3,
      "y": 27,
      "z": -5,
      "name": "Soil_Clay_Lime"
    },
    {
      "x": -3,
      "y": 28,
      "z": -5,
      "name": "Soil_Clay_Lime"
    },
    {
      "x": -3,
      "y": 29,
      "z": -5,
      "name": "Soil_Clay_Lime"
    },
    {
      "x": -3,
      "y": 30,
      "z": -5,
      "name": "Soil_Clay_Lime"
    },
    {
      "x": -3,
      "y": 2,
      "z": -4,
      "name": "Soil_Clay_Lime"
    },
    {
      "x": -3,
      "y": 3,
      "z": -4,
      "name": "Soil_Sand"
    },
    {
      "x": -3,
      "y": 4,
      "z": -4,
      "name": "Soil_Sand"
    },
    {
      "x": -3,
      "y": 5,
      "z": -4,
      "name": "Soil_Sand"
    },
    {
      "x": -3,
      "y": 6,
      "z": -4,
      "name": "Soil_Sand"
    },
    {
      "x": -3,
      "y": 7,
      "z": -4,
      "name": "Soil_Sand"
    },
    {
      "x": -3,
      "y": 8,
      "z": -4,
      "name": "Soil_Sand"
    },
    {
      "x": -3,
      "y": 9,
      "z": -4,
      "name": "Soil_Sand"
    },
    {
      "x": -3,
      "y": 10,
      "z": -4,
      "name": "Soil_Sand"
    },
    {
      "x": -3,
      "y": 11,
      "z": -4,
      "name": "Soil_Sand"
    },
    {
      "x": -3,
      "y": 12,
      "z": -4,
      "name": "Soil_Sand"
    },
    {
      "x": -3,
      "y": 13,
      "z": -4,
      "name": "Plant_Flower_Bushy_Yellow"
    },
    {
      "x": -3,
      "y": 15,
      "z": -4,
      "name": "Soil_Sand"
    },
    {
      "x": -3,
      "y": 16,
      "z": -4,
      "name": "Soil_Sand"
    },
    {
      "x": -3,
      "y": 17,
      "z": -4,
      "name": "Soil_Sand"
    },
    {
      "x": -3,
      "y": 18,
      "z": -4,
      "name": "Soil_Sand"
    },
    {
      "x": -3,
      "y": 19,
      "z": -4,
      "name": "Soil_Clay_Lime"
    },
    {
      "x": -3,
      "y": 21,
      "z": -4,
      "name": "Rock_Stone_Mossy"
    },
    {
      "x": -3,
      "y": 22,
      "z": -4,
      "name": "Soil_Sand"
    },
    {
      "x": -3,
      "y": 23,
      "z": -4,
      "name": "Soil_Sand"
    },
    {
      "x": -3,
      "y": 24,
      "z": -4,
      "name": "Soil_Sand"
    },
    {
      "x": -3,
      "y": 25,
      "z": -4,
      "name": "Soil_Sand"
    },
    {
      "x": -3,
      "y": 26,
      "z": -4,
      "name": "Soil_Sand"
    },
    {
      "x": -3,
      "y": 27,
      "z": -4,
      "name": "Soil_Sand"
    },
    {
      "x": -3,
      "y": 28,
      "z": -4,
      "name": "Soil_Sand"
    },
    {
      "x": -3,
      "y": 29,
      "z": -4,
      "name": "Soil_Sand"
    },
    {
      "x": -3,
      "y": 30,
      "z": -4,
      "name": "Soil_Sand"
    },
    {
      "x": -3,
      "y": 31,
      "z": -4,
      "name": "Soil_Sand"
    },
    {
      "x": -3,
      "y": 32,
      "z": -4,
      "name": "Plant_Flower_Bushy_Yellow"
    },
    {
      "x": -3,
      "y": 1,
      "z": -3,
      "name": "Soil_Clay_Lime"
    },
    {
      "x": -3,
      "y": 2,
      "z": -3,
      "name": "Soil_Sand"
    },
    {
      "x": -3,
      "y": 3,
      "z": -3,
      "name": "Soil_Sand"
    },
    {
      "x": -3,
      "y": 4,
      "z": -3,
      "name": "Soil_Sand"
    },
    {
      "x": -3,
      "y": 5,
      "z": -3,
      "name": "Soil_Sand"
    },
    {
      "x": -3,
      "y": 6,
      "z": -3,
      "name": "Soil_Sand"
    },
    {
      "x": -3,
      "y": 7,
      "z": -3,
      "name": "Soil_Sand"
    },
    {
      "x": -3,
      "y": 8,
      "z": -3,
      "name": "Soil_Sand"
    },
    {
      "x": -3,
      "y": 9,
      "z": -3,
      "name": "Soil_Sand"
    },
    {
      "x": -3,
      "y": 10,
      "z": -3,
      "name": "Soil_Sand"
    },
    {
      "x": -3,
      "y": 11,
      "z": -3,
      "name": "Soil_Sand"
    },
    {
      "x": -3,
      "y": 12,
      "z": -3,
      "name": "Rock_Stone_Mossy"
    },
    {
      "x": -3,
      "y": 14,
      "z": -3,
      "name": "Soil_Clay_Lime"
    },
    {
      "x": -3,
      "y": 15,
      "z": -3,
      "name": "Soil_Sand"
    },
    {
      "x": -3,
      "y": 16,
      "z": -3,
      "name": "Soil_Sand"
    },
    {
      "x": -3,
      "y": 17,
      "z": -3,
      "name": "Soil_Sand"
    },
    {
      "x": -3,
      "y": 18,
      "z": -3,
      "name": "Soil_Sand"
    },
    {
      "x": -3,
      "y": 19,
      "z": -3,
      "name": "Soil_Clay_Lime"
    },
    {
      "x": -3,
      "y": 21,
      "z": -3,
      "name": "Rock_Stone_Mossy"
    },
    {
      "x": -3,
      "y": 22,
      "z": -3,
      "name": "Soil_Sand"
    },
    {
      "x": -3,
      "y": 23,
      "z": -3,
      "name": "Soil_Sand"
    },
    {
      "x": -3,
      "y": 24,
      "z": -3,
      "name": "Soil_Sand"
    },
    {
      "x": -3,
      "y": 25,
      "z": -3,
      "name": "Soil_Sand"
    },
    {
      "x": -3,
      "y": 26,
      "z": -3,
      "name": "Soil_Sand"
    },
    {
      "x": -3,
      "y": 27,
      "z": -3,
      "name": "Soil_Sand"
    },
    {
      "x": -3,
      "y": 28,
      "z": -3,
      "name": "Soil_Sand"
    },
    {
      "x": -3,
      "y": 29,
      "z": -3,
      "name": "Soil_Sand"
    },
    {
      "x": -3,
      "y": 30,
      "z": -3,
      "name": "Soil_Sand"
    },
    {
      "x": -3,
      "y": 31,
      "z": -3,
      "name": "Soil_Sand"
    },
    {
      "x": -3,
      "y": 32,
      "z": -3,
      "name": "Plant_Flower_Bushy_Yellow"
    },
    {
      "x": -3,
      "y": 1,
      "z": -2,
      "name": "Soil_Clay_Lime"
    },
    {
      "x": -3,
      "y": 2,
      "z": -2,
      "name": "Soil_Sand"
    },
    {
      "x": -3,
      "y": 3,
      "z": -2,
      "name": "Soil_Sand"
    },
    {
      "x": -3,
      "y": 4,
      "z": -2,
      "name": "Soil_Sand"
    },
    {
      "x": -3,
      "y": 5,
      "z": -2,
      "name": "Soil_Sand"
    },
    {
      "x": -3,
      "y": 6,
      "z": -2,
      "name": "Soil_Sand"
    },
    {
      "x": -3,
      "y": 7,
      "z": -2,
      "name": "Soil_Sand"
    },
    {
      "x": -3,
      "y": 8,
      "z": -2,
      "name": "Soil_Sand"
    },
    {
      "x": -3,
      "y": 9,
      "z": -2,
      "name": "Soil_Sand"
    },
    {
      "x": -3,
      "y": 10,
      "z": -2,
      "name": "Soil_Sand"
    },
    {
      "x": -3,
      "y": 11,
      "z": -2,
      "name": "Soil_Sand"
    },
    {
      "x": -3,
      "y": 12,
      "z": -2,
      "name": "Rock_Stone_Mossy"
    },
    {
      "x": -3,
      "y": 13,
      "z": -2,
      "name": "Rock_Stone_Mossy"
    },
    {
      "x": -3,
      "y": 14,
      "z": -2,
      "name": "Soil_Sand"
    },
    {
      "x": -3,
      "y": 15,
      "z": -2,
      "name": "Soil_Sand"
    },
    {
      "x": -3,
      "y": 16,
      "z": -2,
      "name": "Soil_Sand"
    },
    {
      "x": -3,
      "y": 17,
      "z": -2,
      "name": "Soil_Sand"
    },
    {
      "x": -3,
      "y": 18,
      "z": -2,
      "name": "Soil_Sand"
    },
    {
      "x": -3,
      "y": 19,
      "z": -2,
      "name": "Soil_Sand"
    },
    {
      "x": -3,
      "y": 20,
      "z": -2,
      "name": "Soil_Clay_Lime"
    },
    {
      "x": -3,
      "y": 21,
      "z": -2,
      "name": "Soil_Sand"
    },
    {
      "x": -3,
      "y": 22,
      "z": -2,
      "name": "Soil_Sand"
    },
    {
      "x": -3,
      "y": 23,
      "z": -2,
      "name": "Soil_Sand"
    },
    {
      "x": -3,
      "y": 24,
      "z": -2,
      "name": "Soil_Sand"
    },
    {
      "x": -3,
      "y": 25,
      "z": -2,
      "name": "Soil_Sand"
    },
    {
      "x": -3,
      "y": 26,
      "z": -2,
      "name": "Soil_Sand"
    },
    {
      "x": -3,
      "y": 27,
      "z": -2,
      "name": "Soil_Sand"
    },
    {
      "x": -3,
      "y": 28,
      "z": -2,
      "name": "Soil_Sand"
    },
    {
      "x": -3,
      "y": 29,
      "z": -2,
      "name": "Soil_Sand"
    },
    {
      "x": -3,
      "y": 30,
      "z": -2,
      "name": "Soil_Sand"
    },
    {
      "x": -3,
      "y": 31,
      "z": -2,
      "name": "Soil_Sand"
    },
    {
      "x": -3,
      "y": 32,
      "z": -2,
      "name": "Soil_Sand"
    },
    {
      "x": -3,
      "y": 33,
      "z": -2,
      "name": "Plant_Flower_Bushy_Yellow"
    },
    {
      "x": -3,
      "y": 1,
      "z": -1,
      "name": "Soil_Clay_Lime"
    },
    {
      "x": -3,
      "y": 2,
      "z": -1,
      "name": "Soil_Sand"
    },
    {
      "x": -3,
      "y": 3,
      "z": -1,
      "name": "Soil_Sand"
    },
    {
      "x": -3,
      "y": 4,
      "z": -1,
      "name": "Soil_Sand"
    },
    {
      "x": -3,
      "y": 5,
      "z": -1,
      "name": "Soil_Sand"
    },
    {
      "x": -3,
      "y": 6,
      "z": -1,
      "name": "Soil_Sand"
    },
    {
      "x": -3,
      "y": 7,
      "z": -1,
      "name": "Soil_Sand"
    },
    {
      "x": -3,
      "y": 8,
      "z": -1,
      "name": "Soil_Sand"
    },
    {
      "x": -3,
      "y": 9,
      "z": -1,
      "name": "Soil_Sand"
    },
    {
      "x": -3,
      "y": 10,
      "z": -1,
      "name": "Soil_Sand"
    },
    {
      "x": -3,
      "y": 11,
      "z": -1,
      "name": "Soil_Sand"
    },
    {
      "x": -3,
      "y": 12,
      "z": -1,
      "name": "Soil_Sand"
    },
    {
      "x": -3,
      "y": 13,
      "z": -1,
      "name": "Soil_Sand"
    },
    {
      "x": -3,
      "y": 14,
      "z": -1,
      "name": "Soil_Sand"
    },
    {
      "x": -3,
      "y": 15,
      "z": -1,
      "name": "Soil_Sand"
    },
    {
      "x": -3,
      "y": 16,
      "z": -1,
      "name": "Soil_Sand"
    },
    {
      "x": -3,
      "y": 17,
      "z": -1,
      "name": "Soil_Sand"
    },
    {
      "x": -3,
      "y": 18,
      "z": -1,
      "name": "Soil_Sand"
    },
    {
      "x": -3,
      "y": 19,
      "z": -1,
      "name": "Soil_Sand"
    },
    {
      "x": -3,
      "y": 20,
      "z": -1,
      "name": "Soil_Clay_Lime"
    },
    {
      "x": -3,
      "y": 21,
      "z": -1,
      "name": "Soil_Sand"
    },
    {
      "x": -3,
      "y": 22,
      "z": -1,
      "name": "Soil_Sand"
    },
    {
      "x": -3,
      "y": 23,
      "z": -1,
      "name": "Soil_Sand"
    },
    {
      "x": -3,
      "y": 24,
      "z": -1,
      "name": "Soil_Sand"
    },
    {
      "x": -3,
      "y": 25,
      "z": -1,
      "name": "Soil_Sand"
    },
    {
      "x": -3,
      "y": 26,
      "z": -1,
      "name": "Soil_Sand"
    },
    {
      "x": -3,
      "y": 27,
      "z": -1,
      "name": "Soil_Sand"
    },
    {
      "x": -3,
      "y": 28,
      "z": -1,
      "name": "Soil_Sand"
    },
    {
      "x": -3,
      "y": 29,
      "z": -1,
      "name": "Soil_Sand"
    },
    {
      "x": -3,
      "y": 30,
      "z": -1,
      "name": "Soil_Sand"
    },
    {
      "x": -3,
      "y": 31,
      "z": -1,
      "name": "Soil_Sand"
    },
    {
      "x": -3,
      "y": 32,
      "z": -1,
      "name": "Soil_Sand"
    },
    {
      "x": -3,
      "y": 33,
      "z": -1,
      "name": "Plant_Flower_Bushy_Yellow"
    },
    {
      "x": -3,
      "y": 1,
      "z": 0,
      "name": "Soil_Clay_Lime"
    },
    {
      "x": -3,
      "y": 2,
      "z": 0,
      "name": "Soil_Sand"
    },
    {
      "x": -3,
      "y": 3,
      "z": 0,
      "name": "Soil_Sand"
    },
    {
      "x": -3,
      "y": 4,
      "z": 0,
      "name": "Soil_Sand"
    },
    {
      "x": -3,
      "y": 5,
      "z": 0,
      "name": "Soil_Sand"
    },
    {
      "x": -3,
      "y": 6,
      "z": 0,
      "name": "Soil_Sand"
    },
    {
      "x": -3,
      "y": 7,
      "z": 0,
      "name": "Soil_Sand"
    },
    {
      "x": -3,
      "y": 8,
      "z": 0,
      "name": "Soil_Sand"
    },
    {
      "x": -3,
      "y": 9,
      "z": 0,
      "name": "Soil_Sand"
    },
    {
      "x": -3,
      "y": 10,
      "z": 0,
      "name": "Soil_Sand"
    },
    {
      "x": -3,
      "y": 11,
      "z": 0,
      "name": "Soil_Sand"
    },
    {
      "x": -3,
      "y": 12,
      "z": 0,
      "name": "Soil_Clay_Lime"
    },
    {
      "x": -3,
      "y": 13,
      "z": 0,
      "name": "Soil_Sand"
    },
    {
      "x": -3,
      "y": 14,
      "z": 0,
      "name": "Soil_Sand"
    },
    {
      "x": -3,
      "y": 15,
      "z": 0,
      "name": "Soil_Sand"
    },
    {
      "x": -3,
      "y": 16,
      "z": 0,
      "name": "Soil_Sand"
    },
    {
      "x": -3,
      "y": 17,
      "z": 0,
      "name": "Soil_Sand"
    },
    {
      "x": -3,
      "y": 18,
      "z": 0,
      "name": "Soil_Sand"
    },
    {
      "x": -3,
      "y": 19,
      "z": 0,
      "name": "Soil_Sand"
    },
    {
      "x": -3,
      "y": 20,
      "z": 0,
      "name": "Plant_Moss_Block_Yellow"
    },
    {
      "x": -3,
      "y": 21,
      "z": 0,
      "name": "Soil_Sand"
    },
    {
      "x": -3,
      "y": 22,
      "z": 0,
      "name": "Soil_Sand"
    },
    {
      "x": -3,
      "y": 23,
      "z": 0,
      "name": "Soil_Sand"
    },
    {
      "x": -3,
      "y": 24,
      "z": 0,
      "name": "Soil_Sand"
    },
    {
      "x": -3,
      "y": 25,
      "z": 0,
      "name": "Soil_Sand"
    },
    {
      "x": -3,
      "y": 26,
      "z": 0,
      "name": "Soil_Sand"
    },
    {
      "x": -3,
      "y": 27,
      "z": 0,
      "name": "Soil_Sand"
    },
    {
      "x": -3,
      "y": 28,
      "z": 0,
      "name": "Soil_Sand"
    },
    {
      "x": -3,
      "y": 29,
      "z": 0,
      "name": "Soil_Sand"
    },
    {
      "x": -3,
      "y": 30,
      "z": 0,
      "name": "Soil_Sand"
    },
    {
      "x": -3,
      "y": 31,
      "z": 0,
      "name": "Soil_Sand"
    },
    {
      "x": -3,
      "y": 32,
      "z": 0,
      "name": "Soil_Sand"
    },
    {
      "x": -3,
      "y": 33,
      "z": 0,
      "name": "Plant_Flower_Bushy_Yellow"
    },
    {
      "x": -3,
      "y": 0,
      "z": 1,
      "name": "Soil_Clay_Lime"
    },
    {
      "x": -3,
      "y": 1,
      "z": 1,
      "name": "Soil_Sand"
    },
    {
      "x": -3,
      "y": 2,
      "z": 1,
      "name": "Soil_Sand"
    },
    {
      "x": -3,
      "y": 3,
      "z": 1,
      "name": "Soil_Sand"
    },
    {
      "x": -3,
      "y": 4,
      "z": 1,
      "name": "Soil_Sand"
    },
    {
      "x": -3,
      "y": 5,
      "z": 1,
      "name": "Soil_Sand"
    },
    {
      "x": -3,
      "y": 6,
      "z": 1,
      "name": "Soil_Sand"
    },
    {
      "x": -3,
      "y": 7,
      "z": 1,
      "name": "Soil_Sand"
    },
    {
      "x": -3,
      "y": 8,
      "z": 1,
      "name": "Soil_Sand"
    },
    {
      "x": -3,
      "y": 9,
      "z": 1,
      "name": "Soil_Sand"
    },
    {
      "x": -3,
      "y": 10,
      "z": 1,
      "name": "Soil_Sand"
    },
    {
      "x": -3,
      "y": 11,
      "z": 1,
      "name": "Soil_Sand"
    },
    {
      "x": -3,
      "y": 12,
      "z": 1,
      "name": "Plant_Moss_Block_Yellow"
    },
    {
      "x": -3,
      "y": 13,
      "z": 1,
      "name": "Soil_Sand"
    },
    {
      "x": -3,
      "y": 14,
      "z": 1,
      "name": "Soil_Sand"
    },
    {
      "x": -3,
      "y": 15,
      "z": 1,
      "name": "Soil_Sand"
    },
    {
      "x": -3,
      "y": 16,
      "z": 1,
      "name": "Soil_Sand"
    },
    {
      "x": -3,
      "y": 17,
      "z": 1,
      "name": "Soil_Sand"
    },
    {
      "x": -3,
      "y": 18,
      "z": 1,
      "name": "Soil_Sand"
    },
    {
      "x": -3,
      "y": 19,
      "z": 1,
      "name": "Soil_Sand"
    },
    {
      "x": -3,
      "y": 20,
      "z": 1,
      "name": "Plant_Moss_Block_Yellow"
    },
    {
      "x": -3,
      "y": 21,
      "z": 1,
      "name": "Soil_Sand"
    },
    {
      "x": -3,
      "y": 22,
      "z": 1,
      "name": "Soil_Sand"
    },
    {
      "x": -3,
      "y": 23,
      "z": 1,
      "name": "Soil_Sand"
    },
    {
      "x": -3,
      "y": 24,
      "z": 1,
      "name": "Soil_Sand"
    },
    {
      "x": -3,
      "y": 25,
      "z": 1,
      "name": "Soil_Sand"
    },
    {
      "x": -3,
      "y": 26,
      "z": 1,
      "name": "Soil_Sand"
    },
    {
      "x": -3,
      "y": 27,
      "z": 1,
      "name": "Soil_Sand"
    },
    {
      "x": -3,
      "y": 28,
      "z": 1,
      "name": "Soil_Sand"
    },
    {
      "x": -3,
      "y": 29,
      "z": 1,
      "name": "Soil_Sand"
    },
    {
      "x": -3,
      "y": 30,
      "z": 1,
      "name": "Soil_Sand"
    },
    {
      "x": -3,
      "y": 31,
      "z": 1,
      "name": "Soil_Sand"
    },
    {
      "x": -3,
      "y": 32,
      "z": 1,
      "name": "Soil_Sand"
    },
    {
      "x": -3,
      "y": 33,
      "z": 1,
      "name": "Plant_Flower_Bushy_Yellow"
    },
    {
      "x": -3,
      "y": 0,
      "z": 2,
      "name": "Soil_Clay_Lime"
    },
    {
      "x": -3,
      "y": 1,
      "z": 2,
      "name": "Soil_Sand"
    },
    {
      "x": -3,
      "y": 2,
      "z": 2,
      "name": "Soil_Sand"
    },
    {
      "x": -3,
      "y": 3,
      "z": 2,
      "name": "Soil_Sand"
    },
    {
      "x": -3,
      "y": 4,
      "z": 2,
      "name": "Soil_Sand"
    },
    {
      "x": -3,
      "y": 5,
      "z": 2,
      "name": "Soil_Sand"
    },
    {
      "x": -3,
      "y": 6,
      "z": 2,
      "name": "Soil_Sand"
    },
    {
      "x": -3,
      "y": 7,
      "z": 2,
      "name": "Soil_Sand"
    },
    {
      "x": -3,
      "y": 8,
      "z": 2,
      "name": "Soil_Sand"
    },
    {
      "x": -3,
      "y": 9,
      "z": 2,
      "name": "Soil_Sand"
    },
    {
      "x": -3,
      "y": 10,
      "z": 2,
      "name": "Soil_Sand"
    },
    {
      "x": -3,
      "y": 11,
      "z": 2,
      "name": "Soil_Sand"
    },
    {
      "x": -3,
      "y": 12,
      "z": 2,
      "name": "Plant_Moss_Block_Yellow"
    },
    {
      "x": -3,
      "y": 13,
      "z": 2,
      "name": "Soil_Sand"
    },
    {
      "x": -3,
      "y": 14,
      "z": 2,
      "name": "Soil_Sand"
    },
    {
      "x": -3,
      "y": 15,
      "z": 2,
      "name": "Soil_Sand"
    },
    {
      "x": -3,
      "y": 16,
      "z": 2,
      "name": "Soil_Sand"
    },
    {
      "x": -3,
      "y": 17,
      "z": 2,
      "name": "Soil_Sand"
    },
    {
      "x": -3,
      "y": 18,
      "z": 2,
      "name": "Soil_Sand"
    },
    {
      "x": -3,
      "y": 19,
      "z": 2,
      "name": "Soil_Sand"
    },
    {
      "x": -3,
      "y": 20,
      "z": 2,
      "name": "Soil_Clay_Lime"
    },
    {
      "x": -3,
      "y": 21,
      "z": 2,
      "name": "Soil_Sand"
    },
    {
      "x": -3,
      "y": 22,
      "z": 2,
      "name": "Soil_Sand"
    },
    {
      "x": -3,
      "y": 23,
      "z": 2,
      "name": "Soil_Sand"
    },
    {
      "x": -3,
      "y": 24,
      "z": 2,
      "name": "Soil_Sand"
    },
    {
      "x": -3,
      "y": 25,
      "z": 2,
      "name": "Soil_Sand"
    },
    {
      "x": -3,
      "y": 26,
      "z": 2,
      "name": "Soil_Sand"
    },
    {
      "x": -3,
      "y": 27,
      "z": 2,
      "name": "Soil_Sand"
    },
    {
      "x": -3,
      "y": 28,
      "z": 2,
      "name": "Soil_Sand"
    },
    {
      "x": -3,
      "y": 29,
      "z": 2,
      "name": "Soil_Sand"
    },
    {
      "x": -3,
      "y": 30,
      "z": 2,
      "name": "Soil_Sand"
    },
    {
      "x": -3,
      "y": 31,
      "z": 2,
      "name": "Soil_Sand"
    },
    {
      "x": -3,
      "y": 32,
      "z": 2,
      "name": "Plant_Flower_Bushy_Yellow"
    },
    {
      "x": -3,
      "y": 1,
      "z": 3,
      "name": "Soil_Clay_Lime"
    },
    {
      "x": -3,
      "y": 2,
      "z": 3,
      "name": "Soil_Sand"
    },
    {
      "x": -3,
      "y": 3,
      "z": 3,
      "name": "Soil_Sand"
    },
    {
      "x": -3,
      "y": 4,
      "z": 3,
      "name": "Soil_Sand"
    },
    {
      "x": -3,
      "y": 5,
      "z": 3,
      "name": "Soil_Sand"
    },
    {
      "x": -3,
      "y": 6,
      "z": 3,
      "name": "Soil_Sand"
    },
    {
      "x": -3,
      "y": 7,
      "z": 3,
      "name": "Soil_Sand"
    },
    {
      "x": -3,
      "y": 8,
      "z": 3,
      "name": "Soil_Sand"
    },
    {
      "x": -3,
      "y": 9,
      "z": 3,
      "name": "Soil_Sand"
    },
    {
      "x": -3,
      "y": 10,
      "z": 3,
      "name": "Soil_Sand"
    },
    {
      "x": -3,
      "y": 11,
      "z": 3,
      "name": "Plant_Moss_Block_Yellow"
    },
    {
      "x": -3,
      "y": 12,
      "z": 3,
      "name": "Soil_Sand"
    },
    {
      "x": -3,
      "y": 13,
      "z": 3,
      "name": "Soil_Clay_Lime"
    },
    {
      "x": -3,
      "y": 14,
      "z": 3,
      "name": "Soil_Sand"
    },
    {
      "x": -3,
      "y": 15,
      "z": 3,
      "name": "Soil_Sand"
    },
    {
      "x": -3,
      "y": 16,
      "z": 3,
      "name": "Soil_Sand"
    },
    {
      "x": -3,
      "y": 17,
      "z": 3,
      "name": "Soil_Sand"
    },
    {
      "x": -3,
      "y": 18,
      "z": 3,
      "name": "Soil_Sand"
    },
    {
      "x": -3,
      "y": 19,
      "z": 3,
      "name": "Soil_Clay_Lime"
    },
    {
      "x": -3,
      "y": 21,
      "z": 3,
      "name": "Plant_Moss_Block_Yellow"
    },
    {
      "x": -3,
      "y": 22,
      "z": 3,
      "name": "Soil_Sand"
    },
    {
      "x": -3,
      "y": 23,
      "z": 3,
      "name": "Soil_Sand"
    },
    {
      "x": -3,
      "y": 24,
      "z": 3,
      "name": "Soil_Sand"
    },
    {
      "x": -3,
      "y": 25,
      "z": 3,
      "name": "Soil_Sand"
    },
    {
      "x": -3,
      "y": 26,
      "z": 3,
      "name": "Soil_Sand"
    },
    {
      "x": -3,
      "y": 27,
      "z": 3,
      "name": "Soil_Sand"
    },
    {
      "x": -3,
      "y": 28,
      "z": 3,
      "name": "Soil_Sand"
    },
    {
      "x": -3,
      "y": 29,
      "z": 3,
      "name": "Soil_Sand"
    },
    {
      "x": -3,
      "y": 30,
      "z": 3,
      "name": "Soil_Sand"
    },
    {
      "x": -3,
      "y": 31,
      "z": 3,
      "name": "Soil_Sand"
    },
    {
      "x": -3,
      "y": 32,
      "z": 3,
      "name": "Plant_Flower_Bushy_Yellow"
    },
    {
      "x": -3,
      "y": 2,
      "z": 4,
      "name": "Plant_Moss_Block_Yellow"
    },
    {
      "x": -3,
      "y": 3,
      "z": 4,
      "name": "Soil_Sand"
    },
    {
      "x": -3,
      "y": 4,
      "z": 4,
      "name": "Soil_Sand"
    },
    {
      "x": -3,
      "y": 5,
      "z": 4,
      "name": "Soil_Sand"
    },
    {
      "x": -3,
      "y": 6,
      "z": 4,
      "name": "Soil_Sand"
    },
    {
      "x": -3,
      "y": 7,
      "z": 4,
      "name": "Soil_Sand"
    },
    {
      "x": -3,
      "y": 8,
      "z": 4,
      "name": "Soil_Sand"
    },
    {
      "x": -3,
      "y": 9,
      "z": 4,
      "name": "Soil_Sand"
    },
    {
      "x": -3,
      "y": 10,
      "z": 4,
      "name": "Soil_Sand"
    },
    {
      "x": -3,
      "y": 11,
      "z": 4,
      "name": "Soil_Sand"
    },
    {
      "x": -3,
      "y": 12,
      "z": 4,
      "name": "Soil_Clay_Lime"
    },
    {
      "x": -3,
      "y": 13,
      "z": 4,
      "name": "Rock_Stone_Mossy"
    },
    {
      "x": -3,
      "y": 14,
      "z": 4,
      "name": "Soil_Sand"
    },
    {
      "x": -3,
      "y": 15,
      "z": 4,
      "name": "Soil_Sand"
    },
