{
  "version": 8,
  "blockIdVersion": 10,
  "anchorX": 0,
  "anchorY": 0,
  "anchorZ": 0,
  "blocks": [
    {
      "x": -4,
      "y": 9,
      "z": -3,
      "name": "Plant_Vine_Wall",
      "support": 15,
      "rotation": 3
    },
    {
      "x": -4,
      "y": 10,
      "z": -3,
      "name": "Plant_Vine",
      "support": 15,
      "rotation": 3
    },
    {
      "x": -4,
      "y": 11,
      "z": -3,
      "name": "Plant_Vine",
      "support": 15,
      "rotation": 3
    },
    {
      "x": -4,
      "y": 12,
      "z": -3,
      "name": "Plant_Vine_Wall",
      "support": 15,
      "rotation": 3
    },
    {
      "x": -4,
      "y": 10,
      "z": -2,
      "name": "Plant_Vine_Wall",
      "support": 15,
      "rotation": 3
    },
    {
      "x": -4,
      "y": 0,
      "z": 1,
      "name": "Plant_Vine",
      "support": 15,
      "rotation": 3
    },
    {
      "x": -4,
      "y": 1,
      "z": 1,
      "name": "Plant_Vine_Wall",
      "support": 15,
      "rotation": 3
    },
    {
      "x": -4,
      "y": 22,
      "z": 1,
      "name": "Plant_Vine_Wall",
      "support": 15,
      "rotation": 3
    },
    {
      "x": -4,
      "y": 23,
      "z": 1,
      "name": "Plant_Vine",
      "support": 15,
      "rotation": 3
    },
    {
      "x": -4,
      "y": 24,
      "z": 1,
      "name": "Plant_Vine",
      "support": 15,
      "rotation": 3
    },
    {
      "x": -4,
      "y": 0,
      "z": 2,
      "name": "Plant_Vine",
      "support": 15,
      "rotation": 3
    },
    {
      "x": -4,
      "y": 1,
      "z": 2,
      "name": "Plant_Vine",
      "support": 15,
      "rotation": 3
    },
    {
      "x": -4,
      "y": 2,
      "z": 2,
      "name": "Plant_Vine_Wall",
      "support": 15,
      "rotation": 3
    },
    {
      "x": -4,
      "y": 4,
      "z": 2,
      "name": "Plant_Vine_Wall",
      "support": 15,
      "rotation": 3
    },
    {
      "x": -4,
      "y": 22,
      "z": 2,
      "name": "Plant_Vine_Wall",
      "support": 15,
      "rotation": 3
    },
    {
      "x": -4,
      "y": 23,
      "z": 2,
      "name": "Plant_Vine",
      "support": 15,
      "rotation": 3
    },
    {
      "x": -4,
      "y": 0,
      "z": 3,
      "name": "Plant_Vine",
      "support": 15,
      "rotation": 3
    },
    {
      "x": -4,
      "y": 1,
      "z": 3,
      "name": "Plant_Vine_Wall",
      "support": 15,
      "rotation": 3
    },
    {
      "x": -4,
      "y": 2,
      "z": 3,
      "name": "Plant_Vine_Wall",
      "support": 15,
      "rotation": 3
    },
    {
      "x": -4,
      "y": 3,
      "z": 3,
      "name": "Plant_Vine_Wall",
      "support": 15,
      "rotation": 3
    },
    {
      "x": -4,
      "y": 5,
      "z": 3,
      "name": "Plant_Vine_Wall",
      "support": 15,
      "rotation": 3
    },
    {
      "x": -3,
      "y": 10,
      "z": -4,
      "name": "Plant_Vine_Wall",
      "support": 15,
      "rotation": 2
    },
    {
      "x": -3,
      "y": 11,
      "z": -4,
      "name": "Plant_Vine",
      "support": 15,
      "rotation": 2
    },
    {
      "x": -3,
      "y": 12,
      "z": -4,
      "name": "Plant_Vine_Wall",
      "support": 15,
      "rotation": 2
    },
    {
      "x": -3,
      "y": 9,
      "z": -3,
      "name": "Rock_Runic_Brick"
    },
    {
      "x": -3,
      "y": 10,
      "z": -3,
      "name": "Rock_Runic_Brick"
    },
    {
      "x": -3,
      "y": 11,
      "z": -3,
      "name": "Rock_Runic_Brick"
    },
    {
      "x": -3,
      "y": 12,
      "z": -3,
      "name": "Rock_Runic_Brick"
    },
    {
      "x": -3,
      "y": 13,
      "z": -3,
      "name": "Rock_Runic_Brick"
    },
    {
      "x": -3,
      "y": 0,
      "z": -2,
      "name": "Plant_Vine",
      "support": 15,
      "rotation": 3
    },
    {
      "x": -3,
      "y": 1,
      "z": -2,
      "name": "Plant_Vine",
      "support": 15,
      "rotation": 3
    },
    {
      "x": -3,
      "y": 2,
      "z": -2,
      "name": "Plant_Vine_Wall",
      "support": 15,
      "rotation": 3
    },
    {
      "x": -3,
      "y": 4,
      "z": -2,
      "name": "Plant_Vine_Wall",
      "support": 15,
      "rotation": 3
    },
    {
      "x": -3,
      "y": 5,
      "z": -2,
      "name": "Plant_Vine",
      "support": 15,
      "rotation": 3
    },
    {
      "x": -3,
      "y": 6,
      "z": -2,
      "name": "Plant_Vine_Wall",
      "support": 15,
      "rotation": 3
    },
    {
      "x": -3,
      "y": 7,
      "z": -2,
      "name": "Rock_Runic_Brick_Half",
      "rotation": 7
    },
    {
      "x": -3,
      "y": 8,
      "z": -2,
      "name": "Rock_Runic_Brick_Stairs",
      "rotation": 9
    },
    {
      "x": -3,
      "y": 9,
      "z": -2,
      "name": "Rock_Runic_Brick"
    },
    {
      "x": -3,
      "y": 10,
      "z": -2,
      "name": "Rock_Runic_Brick"
    },
    {
      "x": -3,
      "y": 11,
      "z": -2,
      "name": "Rock_Runic_Brick"
    },
    {
      "x": -3,
      "y": 12,
      "z": -2,
      "name": "Rock_Runic_Brick"
    },
    {
      "x": -3,
      "y": 13,
      "z": -2,
      "name": "Rock_Runic_Brick"
    },
    {
      "x": -3,
      "y": 14,
      "z": -2,
      "name": "Rock_Runic_Brick_Stairs",
      "rotation": 3
    },
    {
      "x": -3,
      "y": 18,
      "z": -2,
      "name": "Plant_Vine_Wall",
      "support": 15,
      "rotation": 3
    },
    {
      "x": -3,
      "y": 19,
      "z": -2,
      "name": "Plant_Vine",
      "support": 15,
      "rotation": 3
    },
    {
      "x": -3,
      "y": 20,
      "z": -2,
      "name": "Plant_Vine_Wall",
      "support": 15,
      "rotation": 3
    },
    {
      "x": -3,
      "y": 24,
      "z": -2,
      "name": "Plant_Vine_Wall",
      "support": 15,
      "rotation": 3
    },
    {
      "x": -3,
      "y": 26,
      "z": -2,
      "name": "Plant_Vine_Wall",
      "support": 15,
      "rotation": 3
    },
    {
      "x": -3,
      "y": 27,
      "z": -2,
      "name": "Plant_Vine",
      "support": 15,
      "rotation": 3
    },
    {
      "x": -3,
      "y": 28,
      "z": -2,
      "name": "Plant_Vine_Wall",
      "support": 15,
      "rotation": 3
    },
    {
      "x": -3,
      "y": 0,
      "z": -1,
      "name": "Plant_Vine",
      "support": 15,
      "rotation": 3
    },
    {
      "x": -3,
      "y": 1,
      "z": -1,
      "name": "Plant_Vine",
      "support": 15,
      "rotation": 3
    },
    {
      "x": -3,
      "y": 2,
      "z": -1,
      "name": "Plant_Vine_Wall",
      "support": 15,
      "rotation": 3
    },
    {
      "x": -3,
      "y": 5,
      "z": -1,
      "name": "Plant_Vine",
      "support": 15,
      "rotation": 3
    },
    {
      "x": -3,
      "y": 6,
      "z": -1,
      "name": "Plant_Vine_Wall",
      "support": 15,
      "rotation": 3
    },
    {
      "x": -3,
      "y": 7,
      "z": -1,
      "name": "Plant_Vine_Wall",
      "support": 15,
      "rotation": 3
    },
    {
      "x": -3,
      "y": 11,
      "z": -1,
      "name": "Plant_Vine_Wall",
      "support": 15,
      "rotation": 3
    },
    {
      "x": -3,
      "y": 12,
      "z": -1,
      "name": "Plant_Vine",
      "support": 15,
      "rotation": 3
    },
    {
      "x": -3,
      "y": 13,
      "z": -1,
      "name": "Plant_Vine_Wall",
      "support": 15,
      "rotation": 3
    },
    {
      "x": -3,
      "y": 19,
      "z": -1,
      "name": "Plant_Vine_Wall",
      "support": 15,
      "rotation": 3
    },
    {
      "x": -3,
      "y": 20,
      "z": -1,
      "name": "Plant_Vine",
      "support": 15,
      "rotation": 3
    },
    {
      "x": -3,
      "y": 21,
      "z": -1,
      "name": "Plant_Vine_Wall",
      "support": 15,
      "rotation": 3
    },
    {
      "x": -3,
      "y": 23,
      "z": -1,
      "name": "Plant_Vine_Wall",
      "support": 15,
      "rotation": 3
    },
    {
      "x": -3,
      "y": 27,
      "z": -1,
      "name": "Plant_Vine",
      "support": 15,
      "rotation": 3
    },
    {
      "x": -3,
      "y": 28,
      "z": -1,
      "name": "Plant_Vine_Wall",
      "support": 15,
      "rotation": 3
    },
    {
      "x": -3,
      "y": 1,
      "z": 0,
      "name": "Plant_Vine_Wall",
      "support": 15,
      "rotation": 3
    },
    {
      "x": -3,
      "y": 2,
      "z": 0,
      "name": "Plant_Vine",
      "support": 15,
      "rotation": 3
    },
    {
      "x": -3,
      "y": 3,
      "z": 0,
      "name": "Plant_Vine_Wall",
      "support": 15,
      "rotation": 3
    },
    {
      "x": -3,
      "y": 4,
      "z": 0,
      "name": "Plant_Vine_Wall",
      "support": 15,
      "rotation": 2
    },
    {
      "x": -3,
      "y": 6,
      "z": 0,
      "name": "Plant_Vine",
      "support": 15,
      "rotation": 3
    },
    {
      "x": -3,
      "y": 8,
      "z": 0,
      "name": "Plant_Vine_Wall",
      "support": 15,
      "rotation": 3
    },
    {
      "x": -3,
      "y": 12,
      "z": 0,
      "name": "Plant_Vine_Wall",
      "support": 15,
      "rotation": 3
    },
    {
      "x": -3,
      "y": 13,
      "z": 0,
      "name": "Plant_Vine",
      "support": 15,
      "rotation": 3
    },
    {
      "x": -3,
      "y": 14,
      "z": 0,
      "name": "Plant_Vine_Wall",
      "support": 15,
      "rotation": 3
    },
    {
      "x": -3,
      "y": 15,
      "z": 0,
      "name": "Rock_Runic_Brick_Stairs",
      "rotation": 9
    },
    {
      "x": -3,
      "y": 16,
      "z": 0,
      "name": "Rock_Runic_Brick"
    },
    {
      "x": -3,
      "y": 17,
      "z": 0,
      "name": "Rock_Runic_Brick"
    },
    {
      "x": -3,
      "y": 18,
      "z": 0,
      "name": "Rock_Runic_Brick"
    },
    {
      "x": -3,
      "y": 19,
      "z": 0,
      "name": "Rock_Runic_Brick_Stairs",
      "rotation": 2
    },
    {
      "x": -3,
      "y": 20,
      "z": 0,
      "name": "Plant_Vine",
      "support": 15,
      "rotation": 3
    },
    {
      "x": -3,
      "y": 21,
      "z": 0,
      "name": "Plant_Vine_Wall",
      "support": 15,
      "rotation": 3
    },
    {
      "x": -3,
      "y": 23,
      "z": 0,
      "name": "Plant_Vine",
      "support": 15,
      "rotation": 2
    },
    {
      "x": -3,
      "y": 24,
      "z": 0,
      "name": "Plant_Vine",
      "support": 15,
      "rotation": 2
    },
    {
      "x": -3,
      "y": 25,
      "z": 0,
      "name": "Plant_Vine_Wall",
      "support": 15,
      "rotation": 3
    },
    {
      "x": -3,
      "y": 26,
      "z": 0,
      "name": "Plant_Vine",
      "support": 15,
      "rotation": 3
    },
    {
      "x": -3,
      "y": 27,
      "z": 0,
      "name": "Plant_Vine_Wall",
      "support": 15,
      "rotation": 3
    },
    {
      "x": -3,
      "y": 0,
      "z": 1,
      "name": "Rock_Runic_Brick"
    },
    {
      "x": -3,
      "y": 1,
      "z": 1,
      "name": "Rock_Runic_Brick"
    },
    {
      "x": -3,
      "y": 2,
      "z": 1,
      "name": "Rock_Runic_Brick"
    },
    {
      "x": -3,
      "y": 3,
      "z": 1,
      "name": "Rock_Runic_Brick"
    },
    {
      "x": -3,
      "y": 4,
      "z": 1,
      "name": "Rock_Runic_Brick"
    },
    {
      "x": -3,
      "y": 5,
      "z": 1,
      "name": "Rock_Runic_Brick"
    },
    {
      "x": -3,
      "y": 6,
      "z": 1,
      "name": "Rock_Runic_Brick_Stairs",
      "rotation": 2
    },
    {
      "x": -3,
      "y": 10,
      "z": 1,
      "name": "Plant_Vine_Wall",
      "support": 15,
      "rotation": 3
    },
    {
      "x": -3,
      "y": 12,
      "z": 1,
      "name": "Plant_Vine_Wall",
      "support": 15,
      "rotation": 3
    },
    {
      "x": -3,
      "y": 13,
      "z": 1,
      "name": "Plant_Vine",
      "support": 15,
      "rotation": 3
    },
    {
      "x": -3,
      "y": 14,
      "z": 1,
      "name": "Plant_Vine_Wall",
      "support": 15,
      "rotation": 3
    },
    {
      "x": -3,
      "y": 15,
      "z": 1,
      "name": "Rock_Runic_Brick_Stairs",
      "rotation": 9
    },
    {
      "x": -3,
      "y": 16,
      "z": 1,
      "name": "Rock_Runic_Brick"
    },
    {
      "x": -3,
      "y": 17,
      "z": 1,
      "name": "Rock_Runic_Brick"
    },
    {
      "x": -3,
      "y": 18,
      "z": 1,
      "name": "Rock_Runic_Brick"
    },
    {
      "x": -3,
      "y": 19,
      "z": 1,
      "name": "Rock_Runic_Brick_Stairs"
    },
    {
      "x": -3,
      "y": 20,
      "z": 1,
      "name": "Plant_Vine",
      "support": 15,
      "rotation": 3
    },
    {
      "x": -3,
      "y": 21,
      "z": 1,
      "name": "*Rock_Runic_Brick_Stairs_State_Definitions_Corner_Right",
      "rotation": 8
    },
    {
      "x": -3,
      "y": 22,
      "z": 1,
      "name": "Rock_Runic_Brick"
    },
    {
      "x": -3,
      "y": 23,
      "z": 1,
      "name": "Rock_Runic_Brick"
    },
    {
      "x": -3,
      "y": 24,
      "z": 1,
      "name": "Rock_Runic_Brick"
    },
    {
      "x": -3,
      "y": 25,
      "z": 1,
      "name": "Rock_Runic_Brick"
    },
    {
      "x": -3,
      "y": 26,
      "z": 1,
      "name": "Rock_Runic_Brick_Stairs",
      "rotation": 2
    },
    {
      "x": -3,
      "y": 0,
      "z": 2,
      "name": "Rock_Runic_Brick"
    },
    {
      "x": -3,
      "y": 1,
      "z": 2,
      "name": "Rock_Runic_Brick"
    },
    {
      "x": -3,
      "y": 2,
      "z": 2,
      "name": "Rock_Runic_Brick"
    },
    {
      "x": -3,
      "y": 3,
      "z": 2,
      "name": "Rock_Runic_Brick"
    },
    {
      "x": -3,
      "y": 4,
      "z": 2,
      "name": "Rock_Runic_Brick"
    },
    {
      "x": -3,
      "y": 5,
      "z": 2,
      "name": "Rock_Runic_Brick"
    },
    {
      "x": -3,
      "y": 6,
      "z": 2,
      "name": "Rock_Runic_Brick"
    },
    {
      "x": -3,
      "y": 7,
      "z": 2,
      "name": "Rock_Runic_Brick_Stairs",
      "rotation": 3
    },
    {
      "x": -3,
      "y": 9,
      "z": 2,
      "name": "Plant_Vine_Wall",
      "support": 15,
      "rotation": 3
    },
    {
      "x": -3,
      "y": 10,
      "z": 2,
      "name": "Plant_Vine",
      "support": 15,
      "rotation": 3
    },
    {
      "x": -3,
      "y": 11,
      "z": 2,
      "name": "Plant_Vine_Wall",
      "support": 15,
      "rotation": 3
    },
    {
      "x": -3,
      "y": 13,
      "z": 2,
      "name": "Plant_Vine_Wall",
      "support": 15,
      "rotation": 3
    },
    {
      "x": -3,
      "y": 14,
      "z": 2,
      "name": "Plant_Vine",
      "support": 15,
      "rotation": 3
    },
    {
      "x": -3,
      "y": 15,
      "z": 2,
      "name": "Plant_Vine_Wall",
      "support": 15,
      "rotation": 3
    },
    {
      "x": -3,
      "y": 17,
      "z": 2,
      "name": "Plant_Vine_Wall",
      "support": 15,
      "rotation": 3
    },
    {
      "x": -3,
      "y": 18,
      "z": 2,
      "name": "Plant_Vine",
      "support": 15,
      "rotation": 3
    },
    {
      "x": -3,
      "y": 19,
      "z": 2,
      "name": "Plant_Vine",
      "support": 15,
      "rotation": 3
    },
    {
      "x": -3,
      "y": 20,
      "z": 2,
      "name": "Plant_Vine_Wall",
      "support": 15,
      "rotation": 3
    },
    {
      "x": -3,
      "y": 21,
      "z": 2,
      "name": "Rock_Runic_Brick_Stairs",
      "rotation": 9
    },
    {
      "x": -3,
      "y": 22,
      "z": 2,
      "name": "Rock_Runic_Brick"
    },
    {
      "x": -3,
      "y": 23,
      "z": 2,
      "name": "Rock_Runic_Brick"
    },
    {
      "x": -3,
      "y": 25,
      "z": 2,
      "name": "Rock_Runic_Brick_Stairs",
      "rotation": 9
    },
    {
      "x": -3,
      "y": 26,
      "z": 2,
      "name": "Rock_Runic_Brick"
    },
    {
      "x": -3,
      "y": 27,
      "z": 2,
      "name": "Rock_Runic_Brick_Half"
    },
    {
      "x": -3,
      "y": 0,
      "z": 3,
      "name": "Rock_Runic_Brick"
    },
    {
      "x": -3,
      "y": 1,
      "z": 3,
      "name": "Rock_Runic_Brick"
    },
    {
      "x": -3,
      "y": 2,
      "z": 3,
      "name": "Rock_Runic_Brick"
    },
    {
      "x": -3,
      "y": 3,
      "z": 3,
      "name": "Rock_Runic_Brick"
    },
    {
      "x": -3,
      "y": 4,
      "z": 3,
      "name": "Rock_Runic_Brick"
    },
    {
      "x": -3,
      "y": 5,
      "z": 3,
      "name": "Rock_Runic_Brick"
    },
    {
      "x": -3,
      "y": 6,
      "z": 3,
      "name": "Rock_Runic_Brick"
    },
    {
      "x": -3,
      "y": 21,
      "z": 3,
      "name": "*Rock_Runic_Brick_Stairs_State_Definitions_Corner_Right",
      "rotation": 9
    },
    {
      "x": -3,
      "y": 22,
      "z": 3,
      "name": "Rock_Runic_Brick"
    },
    {
      "x": -3,
      "y": 23,
      "z": 3,
      "name": "Rock_Runic_Brick_Stairs"
    },
    {
      "x": -3,
      "y": 25,
      "z": 3,
      "name": "*Rock_Runic_Brick_Stairs_State_Definitions_Corner_Left",
      "rotation": 10
    },
    {
      "x": -3,
      "y": 26,
      "z": 3,
      "name": "Rock_Runic_Brick_Stairs"
    },
    {
      "x": -3,
      "y": 0,
      "z": 4,
      "name": "Plant_Vine",
      "support": 15
    },
    {
      "x": -3,
      "y": 1,
      "z": 4,
      "name": "Plant_Vine_Wall",
      "support": 15
    },
    {
      "x": -3,
      "y": 2,
      "z": 4,
      "name": "Plant_Vine_Wall",
      "support": 15
    },
    {
      "x": -3,
      "y": 3,
      "z": 4,
      "name": "Plant_Vine",
      "support": 15
    },
    {
      "x": -3,
      "y": 4,
      "z": 4,
      "name": "Plant_Vine_Wall",
      "support": 15
    },
    {
      "x": -2,
      "y": 11,
      "z": -4,
      "name": "Plant_Vine_Wall",
      "support": 15,
      "rotation": 2
    },
    {
      "x": -2,
      "y": 1,
      "z": -3,
      "name": "Plant_Vine",
      "support": 15,
      "rotation": 2
    },
    {
      "x": -2,
      "y": 2,
      "z": -3,
      "name": "Plant_Vine",
      "support": 15,
      "rotation": 2
    },
    {
      "x": -2,
      "y": 4,
      "z": -3,
      "name": "Plant_Vine_Wall",
      "support": 15,
      "rotation": 3
    },
    {
      "x": -2,
      "y": 5,
      "z": -3,
      "name": "Plant_Vine_Wall",
      "support": 15,
      "rotation": 2
    },
    {
      "x": -2,
      "y": 7,
      "z": -3,
      "name": "Rock_Runic_Brick_Half",
      "rotation": 6
    },
    {
      "x": -2,
      "y": 8,
      "z": -3,
      "name": "Rock_Runic_Brick_Stairs",
      "rotation": 8
    },
    {
      "x": -2,
      "y": 9,
      "z": -3,
      "name": "Rock_Runic_Brick"
    },
    {
      "x": -2,
      "y": 10,
      "z": -3,
      "name": "Rock_Runic_Brick"
    },
    {
      "x": -2,
      "y": 11,
      "z": -3,
      "name": "Rock_Runic_Brick"
    },
    {
      "x": -2,
      "y": 12,
      "z": -3,
      "name": "Rock_Runic_Brick"
    },
    {
      "x": -2,
      "y": 13,
      "z": -3,
      "name": "Rock_Runic_Brick"
    },
    {
      "x": -2,
      "y": 14,
      "z": -3,
      "name": "Rock_Runic_Brick_Stairs",
      "rotation": 2
    },
    {
      "x": -2,
      "y": 18,
      "z": -3,
      "name": "Plant_Vine_Wall",
      "support": 15,
      "rotation": 2
    },
    {
      "x": -2,
      "y": 19,
      "z": -3,
      "name": "Plant_Vine",
      "support": 15,
      "rotation": 2
    },
    {
      "x": -2,
      "y": 20,
      "z": -3,
      "name": "Plant_Vine_Wall",
      "support": 15,
      "rotation": 2
    },
    {
      "x": -2,
      "y": 27,
      "z": -3,
      "name": "Plant_Vine",
      "support": 15,
      "rotation": 2
    },
    {
      "x": -2,
      "y": 28,
      "z": -3,
      "name": "Plant_Vine_Wall",
      "support": 15,
      "rotation": 2
    },
    {
      "x": -2,
      "y": 0,
      "z": -2,
      "name": "Rock_Runic_Brick"
    },
    {
      "x": -2,
      "y": 1,
      "z": -2,
      "name": "Rock_Runic_Brick"
    },
    {
      "x": -2,
      "y": 2,
      "z": -2,
      "name": "Rock_Runic_Brick"
    },
    {
      "x": -2,
      "y": 3,
      "z": -2,
      "name": "Rock_Runic_Brick_Stairs",
      "rotation": 3
    },
    {
      "x": -2,
      "y": 4,
      "z": -2,
      "name": "Rock_Runic_Brick"
    },
    {
      "x": -2,
      "y": 5,
      "z": -2,
      "name": "Rock_Runic_Brick"
    },
    {
      "x": -2,
      "y": 6,
      "z": -2,
      "name": "Rock_Runic_Brick"
    },
    {
      "x": -2,
      "y": 7,
      "z": -2,
      "name": "Rock_Runic_Brick"
    },
    {
      "x": -2,
      "y": 8,
      "z": -2,
      "name": "Rock_Runic_Brick"
    },
    {
      "x": -2,
      "y": 9,
      "z": -2,
      "name": "Rock_Runic_Brick"
    },
    {
      "x": -2,
      "y": 10,
      "z": -2,
      "name": "Rock_Runic_Brick"
    },
    {
      "x": -2,
      "y": 11,
      "z": -2,
      "name": "Rock_Runic_Brick"
    },
    {
      "x": -2,
      "y": 12,
      "z": -2,
      "name": "Rock_Runic_Brick"
    },
    {
      "x": -2,
      "y": 13,
      "z": -2,
      "name": "Rock_Runic_Brick"
    },
    {
      "x": -2,
      "y": 14,
      "z": -2,
      "name": "Rock_Runic_Brick"
    },
    {
      "x": -2,
      "y": 15,
      "z": -2,
      "name": "Rock_Runic_Brick"
    },
    {
      "x": -2,
      "y": 16,
      "z": -2,
      "name": "Rock_Runic_Brick"
    },
    {
      "x": -2,
      "y": 17,
      "z": -2,
      "name": "Rock_Runic_Brick_Half",
      "rotation": 8
    },
    {
      "x": -2,
      "y": 18,
      "z": -2,
      "name": "Rock_Runic_Brick"
    },
    {
      "x": -2,
      "y": 19,
      "z": -2,
      "name": "Rock_Runic_Brick"
    },
    {
      "x": -2,
      "y": 20,
      "z": -2,
      "name": "Rock_Runic_Brick"
    },
    {
      "x": -2,
      "y": 21,
      "z": -2,
      "name": "Rock_Runic_Brick_Stairs",
      "rotation": 3
    },
    {
      "x": -2,
      "y": 22,
      "z": -2,
      "name": "Rock_Runic_Brick"
    },
    {
      "x": -2,
      "y": 23,
      "z": -2,
      "name": "Rock_Runic_Brick"
    },
    {
      "x": -2,
      "y": 24,
      "z": -2,
      "name": "Rock_Runic_Brick"
    },
    {
      "x": -2,
      "y": 25,
      "z": -2,
      "name": "Rock_Runic_Brick_Half"
    },
    {
      "x": -2,
      "y": 26,
      "z": -2,
      "name": "Rock_Runic_Brick"
    },
    {
      "x": -2,
      "y": 27,
      "z": -2,
      "name": "Rock_Runic_Brick"
    },
    {
      "x": -2,
      "y": 28,
      "z": -2,
      "name": "Rock_Runic_Brick"
    },
    {
      "x": -2,
      "y": 29,
      "z": -2,
      "name": "Rock_Runic_Brick"
    },
    {
      "x": -2,
      "y": 30,
      "z": -2,
      "name": "Rock_Runic_Brick"
    },
    {
      "x": -2,
      "y": 0,
      "z": -1,
      "name": "Rock_Runic_Brick"
    },
    {
      "x": -2,
      "y": 1,
      "z": -1,
      "name": "Rock_Runic_Brick"
    },
    {
      "x": -2,
      "y": 2,
      "z": -1,
      "name": "Rock_Runic_Brick"
    },
    {
      "x": -2,
      "y": 3,
      "z": -1,
      "name": "Rock_Runic_Brick"
    },
    {
      "x": -2,
      "y": 4,
      "z": -1,
      "name": "Rock_Runic_Brick_Stairs",
      "rotation": 9
    },
    {
      "x": -2,
      "y": 5,
      "z": -1,
      "name": "Rock_Runic_Brick"
    },
    {
      "x": -2,
      "y": 6,
      "z": -1,
      "name": "Rock_Runic_Brick"
    },
    {
      "x": -2,
      "y": 7,
      "z": -1,
      "name": "Rock_Runic_Brick"
    },
    {
      "x": -2,
      "y": 8,
      "z": -1,
      "name": "Rock_Runic_Brick"
    },
    {
      "x": -2,
      "y": 9,
      "z": -1,
      "name": "Rock_Runic_Brick"
    },
    {
      "x": -2,
      "y": 10,
      "z": -1,
      "name": "Rock_Runic_Brick_Stairs",
      "rotation": 3
    },
    {
      "x": -2,
      "y": 11,
      "z": -1,
      "name": "Rock_Runic_Brick"
    },
    {
      "x": -2,
      "y": 12,
      "z": -1,
      "name": "Rock_Runic_Brick"
    },
    {
      "x": -2,
      "y": 13,
      "z": -1,
      "name": "Rock_Runic_Brick"
    },
    {
      "x": -2,
      "y": 14,
      "z": -1,
      "name": "Rock_Runic_Brick"
    },
    {
      "x": -2,
      "y": 15,
      "z": -1,
      "name": "Rock_Runic_Brick"
    },
    {
      "x": -2,
      "y": 16,
      "z": -1,
      "name": "Rock_Runic_Brick"
    },
    {
      "x": -2,
      "y": 17,
      "z": -1,
      "name": "Rock_Runic_Brick_Stairs",
      "rotation": 3
    },
    {
      "x": -2,
      "y": 18,
      "z": -1,
      "name": "Rock_Runic_Brick"
    },
    {
      "x": -2,
      "y": 19,
      "z": -1,
      "name": "Rock_Runic_Brick"
    },
    {
      "x": -2,
      "y": 20,
      "z": -1,
      "name": "Rock_Runic_Brick"
    },
    {
      "x": -2,
      "y": 21,
      "z": -1,
      "name": "Rock_Runic_Brick"
    },
    {
      "x": -2,
      "y": 22,
      "z": -1,
      "name": "Rock_Runic_Brick_Stairs",
      "rotation": 9
    },
    {
      "x": -2,
      "y": 23,
      "z": -1,
      "name": "Rock_Runic_Brick"
    },
    {
      "x": -2,
      "y": 24,
      "z": -1,
      "name": "Rock_Runic_Brick"
    },
    {
      "x": -2,
      "y": 25,
      "z": -1,
      "name": "Rock_Runic_Brick_Stairs",
      "rotation": 9
    },
    {
      "x": -2,
      "y": 26,
      "z": -1,
      "name": "Rock_Runic_Brick"
    },
    {
      "x": -2,
      "y": 27,
      "z": -1,
      "name": "Rock_Runic_Brick"
    },
    {
      "x": -2,
      "y": 28,
      "z": -1,
      "name": "Rock_Crystal_Cyan_Block",
      "rotation": 5
    },
    {
      "x": -2,
      "y": 29,
      "z": -1,
      "name": "Rock_Runic_Brick"
    },
    {
      "x": -2,
      "y": 30,
      "z": -1,
      "name": "Rock_Runic_Brick"
    },
    {
      "x": -2,
      "y": 31,
      "z": -1,
      "name": "Rock_Runic_Brick_Stairs",
      "rotation": 2
    },
    {
      "x": -2,
      "y": 0,
      "z": 0,
      "name": "Rock_Runic_Brick"
    },
    {
      "x": -2,
      "y": 1,
      "z": 0,
      "name": "Rock_Runic_Brick"
    },
    {
      "x": -2,
      "y": 2,
      "z": 0,
      "name": "Rock_Runic_Brick"
    },
    {
      "x": -2,
      "y": 3,
      "z": 0,
      "name": "Rock_Runic_Brick"
    },
    {
      "x": -2,
      "y": 4,
      "z": 0,
      "name": "Rock_Runic_Brick_Stairs",
      "rotation": 3
    },
    {
      "x": -2,
      "y": 5,
      "z": 0,
      "name": "Rock_Runic_Brick"
    },
    {
      "x": -2,
      "y": 6,
      "z": 0,
      "name": "Rock_Runic_Brick"
    },
    {
      "x": -2,
      "y": 7,
      "z": 0,
      "name": "Rock_Runic_Brick"
    },
    {
      "x": -2,
      "y": 8,
      "z": 0,
      "name": "Rock_Runic_Brick"
    },
    {
      "x": -2,
      "y": 9,
      "z": 0,
      "name": "Rock_Runic_Brick"
    },
    {
      "x": -2,
      "y": 10,
      "z": 0,
      "name": "Rock_Runic_Brick"
    },
    {
      "x": -2,
      "y": 11,
      "z": 0,
      "name": "Rock_Runic_Brick_Stairs",
      "rotation": 9
    },
    {
      "x": -2,
      "y": 12,
      "z": 0,
      "name": "Rock_Runic_Brick"
    },
    {
      "x": -2,
      "y": 13,
      "z": 0,
      "name": "Rock_Runic_Brick"
    },
    {
      "x": -2,
      "y": 14,
      "z": 0,
      "name": "Rock_Runic_Brick"
    },
    {
      "x": -2,
      "y": 15,
      "z": 0,
      "name": "Rock_Runic_Brick"
    },
    {
      "x": -2,
      "y": 16,
      "z": 0,
      "name": "Rock_Runic_Brick"
    },
    {
      "x": -2,
      "y": 17,
      "z": 0,
      "name": "Rock_Runic_Brick"
    },
    {
      "x": -2,
      "y": 18,
      "z": 0,
      "name": "Rock_Runic_Brick"
    },
    {
      "x": -2,
      "y": 19,
      "z": 0,
      "name": "Rock_Runic_Brick"
    },
    {
      "x": -2,
      "y": 20,
      "z": 0,
      "name": "Rock_Runic_Brick"
    },
    {
      "x": -2,
      "y": 21,
      "z": 0,
      "name": "Rock_Runic_Brick"
    },
    {
      "x": -2,
      "y": 22,
      "z": 0,
      "name": "Rock_Runic_Brick_Stairs",
      "rotation": 3
    },
    {
      "x": -2,
      "y": 23,
      "z": 0,
      "name": "Rock_Runic_Brick"
    },
    {
      "x": -2,
      "y": 24,
      "z": 0,
      "name": "Rock_Runic_Brick_Stairs",
      "rotation": 3
    },
    {
      "x": -2,
      "y": 25,
      "z": 0,
      "name": "Rock_Runic_Brick"
    },
    {
      "x": -2,
      "y": 26,
      "z": 0,
      "name": "Rock_Runic_Brick"
    },
    {
      "x": -2,
      "y": 27,
      "z": 0,
      "name": "Rock_Crystal_Cyan_Block",
      "rotation": 5
    },
    {
      "x": -2,
      "y": 28,
      "z": 0,
      "name": "Rock_Crystal_Cyan_Block",
      "rotation": 5
    },
    {
      "x": -2,
      "y": 29,
      "z": 0,
      "name": "Rock_Crystal_Cyan_Block",
      "rotation": 5
    },
    {
      "x": -2,
      "y": 30,
      "z": 0,
      "name": "Rock_Runic_Brick"
    },
    {
      "x": -2,
      "y": 31,
      "z": 0,
      "name": "Rock_Runic_Brick"
    },
    {
      "x": -2,
      "y": 32,
      "z": 0,
      "name": "Rock_Runic_Brick_Stairs",
      "rotation": 3
    },
    {
      "x": -2,
      "y": 0,
      "z": 1,
      "name": "Rock_Runic_Brick"
    },
    {
      "x": -2,
      "y": 1,
      "z": 1,
      "name": "Rock_Runic_Brick"
    },
    {
      "x": -2,
      "y": 2,
      "z": 1,
      "name": "Rock_Runic_Brick"
    },
    {
      "x": -2,
      "y": 3,
      "z": 1,
      "name": "Rock_Runic_Brick"
    },
    {
      "x": -2,
      "y": 4,
      "z": 1,
      "name": "Rock_Runic_Brick"
    },
    {
      "x": -2,
      "y": 5,
      "z": 1,
      "name": "Rock_Runic_Brick"
    },
    {
      "x": -2,
      "y": 6,
      "z": 1,
      "name": "Rock_Runic_Brick"
    },
    {
      "x": -2,
      "y": 7,
      "z": 1,
      "name": "Rock_Runic_Brick"
    },
    {
      "x": -2,
      "y": 8,
      "z": 1,
      "name": "Rock_Runic_Brick"
    },
    {
      "x": -2,
      "y": 9,
      "z": 1,
      "name": "Rock_Runic_Brick"
    },
    {
      "x": -2,
      "y": 10,
      "z": 1,
      "name": "Rock_Runic_Brick"
    },
    {
      "x": -2,
      "y": 11,
      "z": 1,
      "name": "Rock_Runic_Brick_Stairs",
      "rotation": 3
    },
    {
      "x": -2,
      "y": 12,
      "z": 1,
      "name": "Rock_Runic_Brick"
    },
    {
      "x": -2,
      "y": 13,
      "z": 1,
      "name": "Rock_Runic_Brick"
    },
    {
      "x": -2,
      "y": 14,
      "z": 1,
      "name": "Rock_Runic_Brick"
    },
    {
      "x": -2,
      "y": 15,
      "z": 1,
      "name": "Rock_Runic_Brick"
    },
    {
      "x": -2,
      "y": 16,
      "z": 1,
      "name": "Rock_Runic_Brick"
    },
    {
      "x": -2,
      "y": 17,
      "z": 1,
      "name": "Rock_Runic_Brick"
    },
    {
      "x": -2,
      "y": 18,
      "z": 1,
      "name": "Rock_Runic_Brick"
    },
    {
      "x": -2,
      "y": 19,
      "z": 1,
      "name": "Rock_Runic_Brick"
    },
    {
      "x": -2,
      "y": 20,
      "z": 1,
      "name": "Rock_Runic_Brick"
    },
    {
      "x": -2,
      "y": 21,
      "z": 1,
      "name": "Rock_Runic_Brick"
    },
    {
      "x": -2,
      "y": 22,
      "z": 1,
      "name": "Rock_Runic_Brick"
    },
    {
      "x": -2,
      "y": 23,
      "z": 1,
      "name": "Furniture_Human_Ruins_Coffin",
      "filler": 992,
      "rotation": 1
    },
    {
      "x": -2,
      "y": 25,
      "z": 1,
      "name": "Rock_Runic_Brick"
    },
    {
      "x": -2,
      "y": 26,
      "z": 1,
      "name": "Rock_Runic_Brick"
    },
    {
      "x": -2,
      "y": 27,
      "z": 1,
      "name": "Rock_Runic_Brick"
    },
    {
      "x": -2,
      "y": 28,
      "z": 1,
      "name": "Rock_Crystal_Cyan_Block",
      "rotation": 5
    },
    {
      "x": -2,
      "y": 29,
      "z": 1,
      "name": "Rock_Runic_Brick"
    },
    {
      "x": -2,
      "y": 30,
      "z": 1,
      "name": "Rock_Runic_Brick"
    },
    {
      "x": -2,
      "y": 31,
      "z": 1,
      "name": "Rock_Runic_Brick_Stairs"
    },
    {
      "x": -2,
      "y": 0,
      "z": 2,
      "name": "Rock_Runic_Brick"
    },
    {
      "x": -2,
      "y": 1,
      "z": 2,
      "name": "Rock_Runic_Brick"
    },
    {
      "x": -2,
      "y": 2,
      "z": 2,
      "name": "Rock_Runic_Brick"
    },
    {
      "x": -2,
      "y": 3,
      "z": 2,
      "name": "Rock_Runic_Brick"
    },
    {
      "x": -2,
      "y": 4,
      "z": 2,
      "name": "Rock_Runic_Brick"
    },
    {
      "x": -2,
      "y": 5,
      "z": 2,
      "name": "Rock_Runic_Brick"
    },
    {
      "x": -2,
      "y": 6,
      "z": 2,
      "name": "Rock_Runic_Brick"
    },
    {
      "x": -2,
      "y": 7,
      "z": 2,
      "name": "Rock_Runic_Brick"
    },
    {
      "x": -2,
      "y": 8,
      "z": 2,
      "name": "Rock_Runic_Brick"
    },
    {
      "x": -2,
      "y": 9,
      "z": 2,
      "name": "Rock_Runic_Brick"
    },
    {
      "x": -2,
      "y": 10,
      "z": 2,
      "name": "Rock_Runic_Brick"
    },
    {
      "x": -2,
      "y": 11,
      "z": 2,
      "name": "Rock_Runic_Brick"
    },
    {
      "x": -2,
      "y": 12,
      "z": 2,
      "name": "Rock_Runic_Brick_Stairs",
      "rotation": 9
    },
    {
      "x": -2,
      "y": 13,
      "z": 2,
      "name": "Rock_Runic_Brick"
    },
    {
      "x": -2,
      "y": 14,
      "z": 2,
      "name": "Rock_Runic_Brick"
    },
    {
      "x": -2,
      "y": 15,
      "z": 2,
      "name": "Rock_Runic_Brick"
    },
    {
      "x": -2,
      "y": 16,
      "z": 2,
      "name": "Rock_Runic_Brick_Stairs"
    },
    {
      "x": -2,
      "y": 17,
      "z": 2,
      "name": "Rock_Runic_Brick"
    },
    {
      "x": -2,
      "y": 18,
      "z": 2,
      "name": "Rock_Runic_Brick"
    },
    {
      "x": -2,
      "y": 19,
      "z": 2,
      "name": "Rock_Runic_Brick"
    },
    {
      "x": -2,
      "y": 20,
      "z": 2,
      "name": "Rock_Runic_Brick"
    },
    {
      "x": -2,
      "y": 21,
      "z": 2,
      "name": "Rock_Runic_Brick"
    },
    {
      "x": -2,
      "y": 22,
      "z": 2,
      "name": "Rock_Runic_Brick"
    },
    {
      "x": -2,
      "y": 23,
      "z": 2,
      "name": "Furniture_Human_Ruins_Coffin",
      "rotation": 1
    },
    {
      "x": -2,
      "y": 25,
      "z": 2,
      "name": "Rock_Runic_Brick"
    },
    {
      "x": -2,
      "y": 26,
      "z": 2,
      "name": "Rock_Runic_Brick"
    },
    {
      "x": -2,
      "y": 27,
      "z": 2,
      "name": "Rock_Runic_Brick"
    },
    {
      "x": -2,
      "y": 28,
      "z": 2,
      "name": "Rock_Runic_Brick"
    },
    {
      "x": -2,
      "y": 29,
      "z": 2,
      "name": "Rock_Runic_Brick"
    },
    {
      "x": -2,
      "y": 30,
      "z": 2,
      "name": "Rock_Runic_Brick"
    },
    {
      "x": -2,
      "y": 0,
      "z": 3,
      "name": "Rock_Runic_Brick"
    },
    {
      "x": -2,
      "y": 1,
      "z": 3,
      "name": "Rock_Runic_Brick"
    },
    {
      "x": -2,
      "y": 2,
      "z": 3,
      "name": "Rock_Runic_Brick"
    },
    {
      "x": -2,
      "y": 3,
      "z": 3,
      "name": "Rock_Runic_Brick"
    },
    {
      "x": -2,
      "y": 4,
      "z": 3,
      "name": "Rock_Runic_Brick"
    },
    {
      "x": -2,
      "y": 5,
      "z": 3,
      "name": "Rock_Runic_Brick"
    },
    {
      "x": -2,
      "y": 6,
      "z": 3,
      "name": "Rock_Runic_Brick"
    },
    {
      "x": -2,
      "y": 7,
      "z": 3,
      "name": "Rock_Runic_Brick_Stairs"
    },
    {
      "x": -2,
      "y": 9,
      "z": 3,
      "name": "Plant_Vine_Wall",
      "support": 15
    },
    {
      "x": -2,
      "y": 10,
      "z": 3,
      "name": "Plant_Vine",
      "support": 15
    },
    {
      "x": -2,
      "y": 11,
      "z": 3,
      "name": "Plant_Vine_Wall",
      "support": 15,
      "rotation": 3
    },
    {
      "x": -2,
      "y": 12,
      "z": 3,
      "name": "Plant_Vine",
      "support": 15,
      "rotation": 3
    },
    {
      "x": -2,
      "y": 13,
      "z": 3,
      "name": "Plant_Vine_Wall",
      "support": 15,
      "rotation": 3
    },
    {
      "x": -2,
      "y": 14,
      "z": 3,
      "name": "Plant_Vine_Wall",
      "support": 15
    },
    {
      "x": -2,
      "y": 15,
      "z": 3,
      "name": "Plant_Vine_Wall",
      "support": 15,
      "rotation": 3
    },
    {
      "x": -2,
      "y": 16,
      "z": 3,
      "name": "Plant_Vine",
      "support": 15,
      "rotation": 3
    },
    {
      "x": -2,
      "y": 17,
      "z": 3,
      "name": "Plant_Vine_Wall",
      "support": 15,
      "rotation": 3
    },
    {
      "x": -2,
      "y": 18,
      "z": 3,
      "name": "Plant_Vine",
      "support": 15
    },
    {
      "x": -2,
      "y": 19,
      "z": 3,
      "name": "Plant_Vine_Wall",
      "support": 15
    },
    {
      "x": -2,
      "y": 20,
      "z": 3,
      "name": "Plant_Vine_Wall",
      "support": 15
    },
    {
      "x": -2,
      "y": 21,
      "z": 3,
      "name": "Rock_Runic_Brick_Stairs",
      "rotation": 10
    },
    {
      "x": -2,
      "y": 22,
      "z": 3,
      "name": "Rock_Runic_Brick"
    },
    {
      "x": -2,
      "y": 23,
      "z": 3,
      "name": "Rock_Runic_Brick"
    },
    {
      "x": -2,
      "y": 24,
      "z": 3,
      "name": "Rock_Runic_Brick_Ornate"
    },
    {
      "x": -2,
      "y": 25,
      "z": 3,
      "name": "Rock_Runic_Brick"
    },
    {
      "x": -2,
      "y": 26,
      "z": 3,
      "name": "Rock_Runic_Brick"
    },
    {
      "x": -2,
      "y": 27,
      "z": 3,
      "name": "Rock_Runic_Brick_Half"
    },
    {
      "x": -2,
      "y": 0,
      "z": 4,
      "name": "Plant_Vine",
      "support": 15
    },
    {
      "x": -2,
      "y": 1,
      "z": 4,
      "name": "Plant_Vine",
      "support": 15
    },
    {
      "x": -2,
      "y": 2,
      "z": 4,
      "name": "Plant_Vine_Wall",
      "support": 15
    },
    {
      "x": -2,
      "y": 4,
      "z": 4,
      "name": "Plant_Vine_Wall",
      "support": 15
    },
    {
      "x": -2,
      "y": 5,
      "z": 4,
      "name": "Plant_Vine",
      "support": 15
    },
    {
      "x": -2,
      "y": 6,
      "z": 4,
      "name": "Plant_Vine_Wall",
      "support": 15
    },
    {
      "x": -2,
      "y": 11,
      "z": 4,
      "name": "Plant_Vine_Wall",
      "support": 15,
      "rotation": 3
    },
    {
      "x": -2,
      "y": 13,
      "z": 4,
      "name": "Plant_Vine",
      "support": 15,
      "rotation": 3
    },
    {
      "x": -2,
      "y": 14,
      "z": 4,
      "name": "Plant_Vine",
      "support": 15,
      "rotation": 3
    },
    {
      "x": -2,
      "y": 15,
      "z": 4,
      "name": "Plant_Vine_Wall",
      "support": 15,
      "rotation": 3
    },
    {
      "x": -2,
      "y": 24,
      "z": 4,
      "name": "Plant_Vine_Wall",
      "support": 15
    },
    {
      "x": -2,
      "y": 25,
      "z": 4,
      "name": "Plant_Vine",
      "support": 15
    },
    {
      "x": -2,
      "y": 26,
      "z": 4,
      "name": "Plant_Vine_Wall",
      "support": 15
    },
    {
      "x": -1,
      "y": 3,
      "z": -4,
      "name": "Plant_Vine_Wall",
      "support": 15,
      "rotation": 2
    },
    {
      "x": -1,
      "y": 4,
      "z": -4,
      "name": "Plant_Vine",
      "support": 15,
      "rotation": 2
    },
    {
      "x": -1,
      "y": 5,
      "z": -4,
      "name": "Plant_Vine_Wall",
      "support": 15,
      "rotation": 2
    },
    {
      "x": -1,
      "y": 21,
      "z": -4,
      "name": "Plant_Vine_Wall",
      "support": 15,
      "rotation": 2
    },
    {
      "x": -1,
      "y": 0,
      "z": -3,
      "name": "Plant_Vine",
      "support": 15,
      "rotation": 2
    },
    {
      "x": -1,
      "y": 1,
      "z": -3,
      "name": "Plant_Vine_Wall",
      "support": 15,
      "rotation": 2
    },
    {
      "x": -1,
      "y": 2,
      "z": -3,
      "name": "Rock_Runic_Brick_Half",
      "rotation": 6
    },
    {
      "x": -1,
      "y": 3,
      "z": -3,
      "name": "Rock_Runic_Brick"
    },
    {
      "x": -1,
      "y": 4,
      "z": -3,
      "name": "Rock_Runic_Brick"
    },
    {
      "x": -1,
      "y": 5,
      "z": -3,
      "name": "Rock_Runic_Brick"
    },
    {
      "x": -1,
      "y": 6,
      "z": -3,
      "name": "Rock_Runic_Brick_Stairs",
      "rotation": 3
    },
    {
      "x": -1,
      "y": 8,
      "z": -3,
      "name": "Plant_Vine_Wall",
      "support": 15,
      "rotation": 2
    },
    {
      "x": -1,
      "y": 9,
      "z": -3,
      "name": "Plant_Vine",
      "support": 15,
      "rotation": 2
    },
    {
      "x": -1,
      "y": 11,
      "z": -3,
      "name": "Plant_Vine_Wall",
      "support": 15,
      "rotation": 2
    },
    {
      "x": -1,
      "y": 12,
      "z": -3,
      "name": "Plant_Vine",
      "support": 15,
      "rotation": 2
    },
    {
      "x": -1,
      "y": 13,
      "z": -3,
      "name": "Plant_Vine",
      "support": 15,
      "rotation": 2
    },
    {
      "x": -1,
      "y": 14,
      "z": -3,
      "name": "Plant_Vine_Wall",
      "support": 15,
      "rotation": 2
    },
    {
      "x": -1,
      "y": 17,
      "z": -3,
      "name": "Plant_Vine_Wall",
      "support": 15,
      "rotation": 2
    },
    {
      "x": -1,
      "y": 18,
      "z": -3,
      "name": "Plant_Vine",
      "support": 15,
      "rotation": 2
    },
    {
      "x": -1,
      "y": 19,
      "z": -3,
      "name": "Plant_Vine_Wall",
      "support": 15,
      "rotation": 2
    },
    {
      "x": -1,
      "y": 20,
      "z": -3,
      "name": "*Rock_Runic_Brick_Stairs_State_Definitions_Corner_Left",
      "rotation": 9
    },
    {
      "x": -1,
      "y": 21,
      "z": -3,
      "name": "Rock_Runic_Brick"
    },
    {
      "x": -1,
      "y": 22,
      "z": -3,
      "name": "Rock_Runic_Brick"
    },
    {
      "x": -1,
      "y": 23,
      "z": -3,
      "name": "Rock_Runic_Brick_Stairs",
      "rotation": 3
    },
    {
      "x": -1,
      "y": 27,
      "z": -3,
      "name": "Plant_Vine_Wall",
      "support": 15,
      "rotation": 2
    },
    {
      "x": -1,
      "y": 28,
      "z": -3,
      "name": "Plant_Vine",
      "support": 15,
      "rotation": 2
    },
    {
      "x": -1,
      "y": 29,
      "z": -3,
      "name": "Plant_Vine_Wall",
      "support": 15,
      "rotation": 2
    },
    {
      "x": -1,
      "y": 0,
      "z": -2,
      "name": "Rock_Runic_Brick"
    },
    {
      "x": -1,
      "y": 1,
      "z": -2,
      "name": "Rock_Runic_Brick"
    },
    {
      "x": -1,
      "y": 2,
      "z": -2,
      "name": "Rock_Runic_Brick"
    },
    {
      "x": -1,
      "y": 3,
      "z": -2,
      "name": "Rock_Runic_Brick"
    },
    {
      "x": -1,
      "y": 4,
      "z": -2,
      "name": "Rock_Runic_Brick"
    },
    {
      "x": -1,
      "y": 5,
      "z": -2,
      "name": "Rock_Runic_Brick"
    },
    {
      "x": -1,
      "y": 6,
      "z": -2,
      "name": "Rock_Runic_Brick"
    },
    {
      "x": -1,
      "y": 7,
      "z": -2,
      "name": "Rock_Runic_Brick"
    },
    {
      "x": -1,
      "y": 8,
      "z": -2,
      "name": "Rock_Runic_Brick"
    },
    {
      "x": -1,
      "y": 9,
      "z": -2,
      "name": "Rock_Runic_Brick"
    },
    {
      "x": -1,
      "y": 10,
      "z": -2,
      "name": "Rock_Runic_Brick_Stairs"
    },
    {
      "x": -1,
      "y": 11,
      "z": -2,
      "name": "Rock_Runic_Brick"
    },
    {
      "x": -1,
      "y": 12,
      "z": -2,
      "name": "Rock_Runic_Brick"
    },
    {
      "x": -1,
      "y": 13,
      "z": -2,
      "name": "Rock_Runic_Brick_Stairs"
    },
    {
      "x": -1,
      "y": 14,
      "z": -2,
      "name": "Rock_Runic_Brick"
    },
    {
      "x": -1,
      "y": 15,
      "z": -2,
      "name": "Rock_Runic_Brick"
    },
    {
      "x": -1,
      "y": 16,
      "z": -2,
      "name": "Rock_Runic_Brick_Stairs",
      "rotation": 2
    },
    {
      "x": -1,
      "y": 17,
      "z": -2,
      "name": "Rock_Runic_Brick"
    },
    {
      "x": -1,
      "y": 18,
      "z": -2,
      "name": "Rock_Runic_Brick"
    },
    {
      "x": -1,
      "y": 19,
      "z": -2,
      "name": "Rock_Runic_Brick"
    },
    {
      "x": -1,
      "y": 20,
      "z": -2,
      "name": "Rock_Runic_Brick"
    },
    {
      "x": -1,
      "y": 21,
      "z": -2,
      "name": "Rock_Runic_Brick"
    },
    {
      "x": -1,
      "y": 22,
      "z": -2,
      "name": "Rock_Runic_Brick"
    },
    {
      "x": -1,
      "y": 23,
      "z": -2,
      "name": "Rock_Runic_Brick"
    },
    {
      "x": -1,
      "y": 24,
      "z": -2,
      "name": "Rock_Runic_Brick"
    },
    {
      "x": -1,
      "y": 25,
      "z": -2,
      "name": "Rock_Runic_Brick"
    },
    {
      "x": -1,
      "y": 26,
      "z": -2,
      "name": "Rock_Runic_Brick_Stairs",
      "rotation": 8
    },
    {
      "x": -1,
      "y": 27,
      "z": -2,
      "name": "Rock_Runic_Brick"
    },
    {
      "x": -1,
      "y": 28,
      "z": -2,
      "name": "Rock_Crystal_Cyan_Block",
      "rotation": 4
    },
    {
      "x": -1,
      "y": 29,
      "z": -2,
      "name": "Rock_Runic_Brick"
    },
    {
      "x": -1,
      "y": 30,
      "z": -2,
      "name": "Rock_Runic_Brick"
    },
    {
      "x": -1,
      "y": 31,
      "z": -2,
      "name": "Rock_Runic_Brick_Stairs",
      "rotation": 3
    },
    {
      "x": -1,
      "y": 0,
      "z": -1,
      "name": "Rock_Runic_Brick"
    },
    {
      "x": -1,
      "y": 1,
      "z": -1,
      "name": "Rock_Runic_Brick"
    },
    {
      "x": -1,
      "y": 2,
      "z": -1,
      "name": "Soil_Hive_Corrupted_Brick_Smooth"
    },
    {
      "x": -1,
      "y": 8,
      "z": -1,
      "name": "Rock_Runic_Brick"
    },
    {
      "x": -1,
      "y": 12,
      "z": -1,
      "name": "Rock_Runic_Brick"
    },
    {
      "x": -1,
      "y": 16,
      "z": -1,
      "name": "Rock_Runic_Brick"
    },
    {
      "x": -1,
      "y": 18,
      "z": -1,
      "name": "Plant_Vine_Wall",
      "support": 15
    },
    {
      "x": -1,
      "y": 20,
      "z": -1,
      "name": "Rock_Runic_Brick"
    },
    {
      "x": -1,
      "y": 22,
      "z": -1,
      "name": "Plant_Vine_Wall",
      "support": 15
    },
    {
      "x": -1,
      "y": 23,
      "z": -1,
      "name": "Plant_Vine",
      "support": 15,
      "rotation": 1
    },
    {
      "x": -1,
      "y": 24,
      "z": -1,
      "name": "Plant_Vine_Wall",
      "support": 15,
      "rotation": 1
    },
    {
      "x": -1,
      "y": 25,
      "z": -1,
      "name": "Rock_Runic_Brick"
    },
    {
      "x": -1,
      "y": 26,
      "z": -1,
      "name": "Rock_Runic_Brick"
    },
    {
      "x": -1,
      "y": 27,
      "z": -1,
      "name": "Rock_Runic_Brick"
    },
    {
      "x": -1,
      "y": 28,
      "z": -1,
      "name": "Rock_Runic_Brick"
    },
    {
      "x": -1,
      "y": 29,
      "z": -1,
      "name": "Rock_Runic_Brick"
    },
    {
      "x": -1,
      "y": 30,
      "z": -1,
      "name": "Rock_Runic_Brick"
    },
    {
      "x": -1,
      "y": 31,
      "z": -1,
      "name": "Rock_Runic_Brick"
    },
    {
      "x": -1,
      "y": 32,
      "z": -1,
      "name": "Rock_Runic_Brick_Half"
    },
    {
      "x": -1,
      "y": 0,
      "z": 0,
      "name": "Rock_Runic_Brick"
    },
    {
      "x": -1,
      "y": 1,
      "z": 0,
      "name": "Rock_Runic_Brick"
    },
    {
      "x": -1,
      "y": 2,
      "z": 0,
      "name": "Soil_Hive_Corrupted_Brick_Smooth_Half"
    },
    {
      "x": -1,
      "y": 8,
      "z": 0,
      "name": "Rock_Runic_Brick_Stairs",
      "rotation": 10
    },
    {
      "x": -1,
      "y": 9,
      "z": 0,
      "name": "Rock_Runic_Brick_Stairs",
      "rotation": 2
    },
    {
      "x": -1,
      "y": 12,
      "z": 0,
      "name": "Rock_Runic_Brick_Stairs",
      "rotation": 10
    },
    {
      "x": -1,
      "y": 13,
      "z": 0,
      "name": "Rock_Runic_Brick_Stairs",
      "rotation": 2
    },
    {
      "x": -1,
      "y": 16,
      "z": 0,
      "name": "Rock_Runic_Brick_Stairs",
      "rotation": 10
    },
    {
      "x": -1,
      "y": 17,
      "z": 0,
      "name": "Rock_Runic_Brick_Stairs",
      "rotation": 2
    },
    {
      "x": -1,
      "y": 18,
      "z": 0,
      "name": "Plant_Vine_Wall",
      "support": 15,
      "rotation": 1
    },
    {
      "x": -1,
      "y": 19,
      "z": 0,
      "name": "Plant_Vine",
      "support": 15,
      "rotation": 1
    },
    {
      "x": -1,
      "y": 20,
      "z": 0,
      "name": "Rock_Runic_Brick_Stairs",
      "rotation": 10
    },
    {
      "x": -1,
      "y": 21,
      "z": 0,
      "name": "Rock_Runic_Brick_Stairs",
      "rotation": 2
    },
    {
      "x": -1,
      "y": 23,
      "z": 0,
      "name": "Plant_Vine_Wall",
      "support": 15,
      "rotation": 1
    },
    {
      "x": -1,
      "y": 25,
      "z": 0,
      "name": "Rock_Runic_Brick"
    },
    {
      "x": -1,
      "y": 26,
      "z": 0,
      "name": "Rock_Runic_Brick"
    },
    {
      "x": -1,
      "y": 27,
      "z": 0,
      "name": "Rock_Runic_Brick"
    },
    {
      "x": -1,
      "y": 28,
      "z": 0,
      "name": "Rock_Runic_Brick"
    },
    {
      "x": -1,
      "y": 29,
      "z": 0,
      "name": "Rock_Runic_Brick"
    },
    {
      "x": -1,
      "y": 30,
      "z": 0,
      "name": "Rock_Runic_Brick"
    },
    {
      "x": -1,
      "y": 31,
      "z": 0,
      "name": "Rock_Runic_Brick"
    },
    {
      "x": -1,
      "y": 32,
      "z": 0,
      "name": "Rock_Runic_Brick"
    },
    {
      "x": -1,
      "y": 0,
      "z": 1,
      "name": "Rock_Runic_Brick"
    },
    {
      "x": -1,
      "y": 1,
      "z": 1,
      "name": "Soil_Hive_Corrupted"
    },
    {
      "x": -1,
      "y": 5,
      "z": 1,
      "name": "Rock_Runic_Brick"
    },
    {
      "x": -1,
      "y": 9,
      "z": 1,
      "name": "Rock_Runic_Brick"
    },
    {
      "x": -1,
      "y": 13,
      "z": 1,
      "name": "Rock_Runic_Brick"
    },
    {
      "x": -1,
      "y": 17,
      "z": 1,
      "name": "Rock_Runic_Brick"
    },
    {
      "x": -1,
      "y": 19,
      "z": 1,
      "name": "Plant_Vine",
      "support": 15,
      "rotation": 2
    },
    {
      "x": -1,
      "y": 20,
      "z": 1,
      "name": "Plant_Vine_Wall",
      "support": 15,
      "rotation": 1
    },
    {
      "x": -1,
      "y": 21,
      "z": 1,
      "name": "Rock_Runic_Brick"
    },
    {
      "x": -1,
      "y": 22,
      "z": 1,
      "name": "Rock_Runic_Brick_Stairs",
      "rotation": 2
    },
    {
      "x": -1,
      "y": 25,
      "z": 1,
      "name": "Rock_Runic_Brick"
    },
    {
      "x": -1,
      "y": 26,
      "z": 1,
      "name": "Rock_Runic_Brick"
    },
    {
      "x": -1,
      "y": 27,
      "z": 1,
      "name": "Rock_Runic_Brick"
    },
    {
      "x": -1,
      "y": 28,
      "z": 1,
      "name": "Rock_Runic_Brick"
    },
    {
      "x": -1,
      "y": 29,
      "z": 1,
      "name": "Rock_Runic_Brick"
    },
    {
      "x": -1,
      "y": 30,
      "z": 1,
      "name": "Rock_Runic_Brick"
    },
    {
      "x": -1,
      "y": 31,
      "z": 1,
      "name": "Rock_Runic_Brick"
    },
    {
      "x": -1,
      "y": 32,
      "z": 1,
      "name": "Rock_Runic_Brick_Half"
    },
    {
      "x": -1,
      "y": 0,
      "z": 2,
      "name": "Rock_Runic_Brick"
    },
    {
      "x": -1,
      "y": 1,
      "z": 2,
      "name": "Rock_Runic_Brick"
    },
    {
      "x": -1,
      "y": 2,
      "z": 2,
      "name": "Rock_Runic_Brick"
    },
    {
      "x": -1,
      "y": 3,
      "z": 2,
      "name": "Rock_Runic_Brick"
    },
    {
      "x": -1,
      "y": 4,
      "z": 2,
      "name": "Rock_Runic_Brick"
    },
    {
      "x": -1,
      "y": 5,
      "z": 2,
      "name": "Rock_Runic_Brick"
    },
    {
      "x": -1,
      "y": 6,
      "z": 2,
      "name": "Rock_Runic_Brick"
    },
    {
      "x": -1,
      "y": 7,
      "z": 2,
      "name": "Rock_Runic_Brick"
    },
    {
      "x": -1,
      "y": 8,
      "z": 2,
      "name": "Rock_Runic_Brick"
    },
    {
      "x": -1,
      "y": 9,
      "z": 2,
      "name": "Rock_Runic_Brick"
    },
    {
      "x": -1,
      "y": 10,
      "z": 2,
      "name": "Rock_Runic_Brick"
    },
    {
      "x": -1,
      "y": 11,
      "z": 2,
      "name": "Rock_Runic_Brick"
    },
    {
      "x": -1,
      "y": 12,
      "z": 2,
      "name": "Rock_Runic_Brick"
    },
    {
      "x": -1,
      "y": 13,
      "z": 2,
      "name": "Rock_Runic_Brick"
    },
    {
      "x": -1,
      "y": 14,
      "z": 2,
      "name": "Rock_Runic_Brick"
    },
    {
      "x": -1,
      "y": 15,
      "z": 2,
      "name": "Rock_Runic_Brick"
    },
    {
      "x": -1,
      "y": 16,
      "z": 2,
      "name": "Rock_Runic_Brick"
    },
    {
      "x": -1,
      "y": 17,
      "z": 2,
      "name": "Rock_Runic_Brick"
    },
    {
      "x": -1,
      "y": 18,
      "z": 2,
      "name": "Rock_Runic_Brick"
    },
    {
      "x": -1,
      "y": 19,
      "z": 2,
      "name": "Rock_Runic_Brick"
    },
    {
      "x": -1,
      "y": 20,
      "z": 2,
      "name": "Rock_Runic_Brick"
    },
    {
      "x": -1,
      "y": 21,
      "z": 2,
      "name": "Rock_Runic_Brick"
    },
    {
      "x": -1,
      "y": 22,
      "z": 2,
      "name": "Rock_Runic_Brick"
    },
    {
      "x": -1,
      "y": 23,
      "z": 2,
      "name": "Furniture_Human_Ruins_Chest_Small",
      "components": {
        "Components": {
          "PlacedByInteraction": {
            "WhoPlacedUuid": {
              "$binary": "1D6Z0/5hSoOPtypqdFwK+g==",
              "$type": "04"
            }
          },
          "container": {
            "Position": {
              "X": 13,
              "Y": 145,
              "Z": 18
            },
            "Custom": false,
            "AllowViewing": true,
            "ItemContainer": {
              "Capacity": 18,
              "Items": {}
            }
          }
        }
      },
      "rotation": 2
    },
    {
      "x": -1,
      "y": 25,
      "z": 2,
      "name": "Rock_Runic_Brick"
    },
    {
      "x": -1,
      "y": 26,
      "z": 2,
      "name": "Rock_Runic_Brick"
    },
    {
      "x": -1,
      "y": 27,
      "z": 2,
      "name": "Rock_Runic_Brick"
    },
    {
      "x": -1,
      "y": 28,
      "z": 2,
      "name": "Rock_Crystal_Cyan_Block",
      "rotation": 4
    },
    {
      "x": -1,
      "y": 29,
      "z": 2,
      "name": "Rock_Runic_Brick"
    },
    {
      "x": -1,
      "y": 30,
      "z": 2,
      "name": "Rock_Runic_Brick"
    },
    {
      "x": -1,
      "y": 31,
      "z": 2,
      "name": "Rock_Runic_Brick_Stairs",
      "rotation": 3
    },
    {
      "x": -1,
      "y": 0,
      "z": 3,
      "name": "Rock_Runic_Brick"
    },
    {
      "x": -1,
      "y": 1,
      "z": 3,
      "name": "Rock_Runic_Brick"
    },
    {
      "x": -1,
      "y": 2,
      "z": 3,
      "name": "Rock_Runic_Brick"
    },
    {
      "x": -1,
      "y": 3,
      "z": 3,
      "name": "Rock_Runic_Brick"
    },
    {
      "x": -1,
      "y": 4,
      "z": 3,
      "name": "Rock_Runic_Brick"
    },
    {
      "x": -1,
      "y": 5,
      "z": 3,
      "name": "Rock_Runic_Brick"
    },
    {
      "x": -1,
      "y": 6,
      "z": 3,
      "name": "Rock_Runic_Brick_Stairs",
      "rotation": 1
    },
    {
      "x": -1,
      "y": 8,
      "z": 3,
      "name": "Plant_Vine_Wall",
      "support": 15
    },
    {
      "x": -1,
      "y": 9,
      "z": 3,
      "name": "Plant_Vine",
      "support": 15
    },
    {
      "x": -1,
      "y": 10,
      "z": 3,
      "name": "Rock_Runic_Brick_Stairs",
      "rotation": 9
    },
    {
      "x": -1,
      "y": 11,
      "z": 3,
      "name": "Rock_Runic_Brick"
    },
    {
      "x": -1,
      "y": 12,
      "z": 3,
      "name": "Rock_Runic_Brick"
    },
    {
      "x": -1,
      "y": 13,
      "z": 3,
      "name": "Rock_Runic_Brick"
    },
    {
      "x": -1,
      "y": 14,
      "z": 3,
      "name": "Rock_Runic_Brick"
    },
    {
      "x": -1,
      "y": 15,
      "z": 3,
      "name": "Rock_Runic_Brick"
    },
    {
      "x": -1,
      "y": 16,
      "z": 3,
      "name": "Rock_Runic_Brick"
    },
    {
      "x": -1,
      "y": 17,
      "z": 3,
      "name": "Rock_Runic_Brick"
    },
    {
      "x": -1,
      "y": 18,
      "z": 3,
      "name": "Rock_Runic_Brick_Stairs"
    },
    {
      "x": -1,
      "y": 19,
      "z": 3,
      "name": "Plant_Vine_Wall",
      "support": 15
    },
    {
      "x": -1,
      "y": 20,
      "z": 3,
      "name": "Plant_Vine",
      "support": 15
    },
    {
      "x": -1,
      "y": 21,
      "z": 3,
      "name": "*Rock_Runic_Brick_Stairs_State_Definitions_Corner_Left",
      "rotation": 11
    },
    {
      "x": -1,
      "y": 22,
      "z": 3,
      "name": "Rock_Runic_Brick"
    },
    {
      "x": -1,
      "y": 23,
      "z": 3,
      "name": "Rock_Runic_Brick"
    },
    {
      "x": -1,
      "y": 24,
      "z": 3,
      "name": "Rock_Runic_Brick"
    },
    {
      "x": -1,
      "y": 25,
      "z": 3,
      "name": "Rock_Runic_Brick"
    },
    {
      "x": -1,
      "y": 26,
      "z": 3,
      "name": "Rock_Runic_Brick_Stairs",
      "rotation": 1
    },
    {
      "x": -1,
      "y": 27,
      "z": 3,
      "name": "Plant_Vine_Wall",
      "support": 15
    },
    {
      "x": -1,
      "y": 1,
      "z": 4,
      "name": "Plant_Vine_Wall",
      "support": 15
    },
    {
      "x": -1,
      "y": 3,
      "z": 4,
      "name": "Plant_Vine",
      "support": 15
    },
    {
      "x": -1,
      "y": 4,
      "z": 4,
      "name": "Plant_Vine_Wall",
      "support": 15
    },
    {
      "x": -1,
      "y": 10,
      "z": 4,
      "name": "Rock_Runic_Brick_Half",
      "rotation": 8
    },
    {
      "x": -1,
      "y": 11,
      "z": 4,
      "name": "Rock_Runic_Brick"
    },
    {
      "x": -1,
      "y": 12,
      "z": 4,
      "name": "Rock_Runic_Brick"
    },
    {
      "x": -1,
      "y": 13,
      "z": 4,
      "name": "Rock_Runic_Brick"
    },
    {
      "x": -1,
      "y": 14,
      "z": 4,
      "name": "Rock_Runic_Brick"
    },
    {
      "x": -1,
      "y": 15,
      "z": 4,
      "name": "Rock_Runic_Brick"
    },
    {
      "x": -1,
      "y": 16,
      "z": 4,
      "name": "Rock_Runic_Brick"
    },
    {
      "x": -1,
      "y": 17,
      "z": 4,
      "name": "Rock_Runic_Brick_Stairs"
    },
    {
      "x": -1,
      "y": 25,
      "z": 4,
      "name": "Plant_Vine_Wall",
      "support": 15
    },
    {
      "x": -1,
      "y": 11,
      "z": 5,
      "name": "Plant_Vine_Wall",
      "support": 15
    },
    {
      "x": -1,
      "y": 12,
      "z": 5,
      "name": "Plant_Vine",
      "support": 15
    },
    {
      "x": -1,
      "y": 13,
      "z": 5,
      "name": "Plant_Vine",
      "support": 15
    },
    {
      "x": -1,
      "y": 14,
      "z": 5,
      "name": "Plant_Vine_Wall",
      "support": 15
    },
    {
      "x": 0,
      "y": 4,
      "z": -4,
      "name": "Plant_Vine_Wall",
      "support": 15,
      "rotation": 2
    },
    {
      "x": 0,
      "y": 5,
      "z": -4,
      "name": "Plant_Vine",
      "support": 15,
      "rotation": 2
    },
    {
      "x": 0,
      "y": 21,
      "z": -4,
      "name": "Plant_Vine_Wall",
      "support": 15,
      "rotation": 2
    },
    {
      "x": 0,
      "y": 22,
      "z": -4,
      "name": "Plant_Vine",
      "support": 15,
      "rotation": 2
    },
    {
      "x": 0,
      "y": 0,
      "z": -3,
      "name": "Plant_Vine",
      "support": 15,
      "rotation": 2
    },
    {
      "x": 0,
      "y": 1,
      "z": -3,
      "name": "Plant_Vine_Wall",
      "support": 15,
      "rotation": 2
    },
    {
      "x": 0,
      "y": 2,
      "z": -3,
      "name": "Rock_Runic_Brick_Half",
      "rotation": 6
    },
    {
      "x": 0,
      "y": 3,
      "z": -3,
      "name": "Rock_Runic_Brick"
    },
    {
      "x": 0,
      "y": 4,
      "z": -3,
      "name": "Rock_Runic_Brick"
    },
    {
      "x": 0,
      "y": 5,
      "z": -3,
      "name": "Rock_Runic_Brick"
    },
    {
      "x": 0,
      "y": 6,
      "z": -3,
      "name": "Rock_Runic_Brick_Stairs",
      "rotation": 1
    },
    {
      "x": 0,
      "y": 7,
      "z": -3,
      "name": "Plant_Vine_Wall",
      "support": 15,
      "rotation": 2
    },
    {
      "x": 0,
      "y": 8,
      "z": -3,
      "name": "Plant_Vine",
      "support": 15,
      "rotation": 2
    },
    {
      "x": 0,
      "y": 10,
      "z": -3,
      "name": "Plant_Vine_Wall",
      "support": 15,
      "rotation": 2
    },
    {
      "x": 0,
      "y": 11,
      "z": -3,
      "name": "Plant_Vine",
      "support": 15,
      "rotation": 2
    },
    {
      "x": 0,
      "y": 12,
      "z": -3,
      "name": "Plant_Vine",
      "support": 15,
      "rotation": 2
    },
    {
      "x": 0,
      "y": 13,
      "z": -3,
      "name": "Plant_Vine_Wall",
      "support": 15,
      "rotation": 2
    },
    {
      "x": 0,
      "y": 17,
      "z": -3,
      "name": "Plant_Vine_Wall",
      "support": 15,
      "rotation": 2
    },
    {
      "x": 0,
      "y": 18,
      "z": -3,
      "name": "Plant_Vine",
      "support": 15,
      "rotation": 2
    },
    {
      "x": 0,
      "y": 19,
      "z": -3,
      "name": "Rock_Runic_Brick_Half",
      "rotation": 6
    },
    {
      "x": 0,
      "y": 20,
      "z": -3,
      "name": "Rock_Runic_Brick_Stairs",
      "rotation": 8
    },
    {
      "x": 0,
      "y": 21,
      "z": -3,
      "name": "Rock_Runic_Brick"
    },
    {
      "x": 0,
      "y": 22,
      "z": -3,
      "name": "Rock_Runic_Brick"
    },
    {
      "x": 0,
      "y": 23,
      "z": -3,
      "name": "Rock_Runic_Brick_Stairs",
      "rotation": 1
    },
    {
      "x": 0,
      "y": 28,
      "z": -3,
      "name": "Plant_Vine",
      "support": 15,
      "rotation": 2
    },
    {
      "x": 0,
      "y": 29,
      "z": -3,
      "name": "Plant_Vine_Wall",
      "support": 15,
      "rotation": 2
    },
    {
      "x": 0,
      "y": 0,
      "z": -2,
      "name": "Rock_Runic_Brick"
    },
    {
      "x": 0,
      "y": 1,
      "z": -2,
      "name": "Rock_Runic_Brick"
    },
    {
      "x": 0,
      "y": 2,
      "z": -2,
      "name": "Rock_Runic_Brick"
    },
    {
      "x": 0,
      "y": 3,
      "z": -2,
      "name": "Rock_Runic_Brick"
    },
    {
      "x": 0,
      "y": 4,
      "z": -2,
      "name": "Rock_Runic_Brick"
    },
    {
      "x": 0,
      "y": 5,
      "z": -2,
      "name": "Rock_Runic_Brick"
    },
    {
      "x": 0,
      "y": 6,
      "z": -2,
      "name": "Rock_Runic_Brick"
    },
    {
      "x": 0,
      "y": 7,
      "z": -2,
      "name": "Rock_Runic_Brick"
    },
    {
      "x": 0,
      "y": 8,
      "z": -2,
      "name": "Rock_Runic_Brick"
    },
    {
      "x": 0,
      "y": 9,
      "z": -2,
      "name": "Rock_Runic_Brick_Stairs"
    },
    {
      "x": 0,
      "y": 10,
      "z": -2,
      "name": "Rock_Runic_Brick"
    },
    {
      "x": 0,
      "y": 11,
      "z": -2,
      "name": "Rock_Runic_Brick"
    },
    {
      "x": 0,
      "y": 12,
      "z": -2,
      "name": "Rock_Runic_Brick"
    },
    {
      "x": 0,
      "y": 13,
      "z": -2,
      "name": "Rock_Runic_Brick"
    },
    {
      "x": 0,
      "y": 14,
      "z": -2,
      "name": "Rock_Runic_Brick_Stairs"
    },
    {
      "x": 0,
      "y": 15,
      "z": -2,
      "name": "Rock_Runic_Brick"
    },
    {
      "x": 0,
      "y": 16,
      "z": -2,
      "name": "Rock_Runic_Brick_Stairs",
      "rotation": 8
    },
    {
      "x": 0,
      "y": 17,
      "z": -2,
      "name": "Rock_Runic_Brick_Ornate"
    },
    {
      "x": 0,
      "y": 18,
      "z": -2,
      "name": "Rock_Runic_Brick"
    },
    {
      "x": 0,
      "y": 19,
      "z": -2,
      "name": "Rock_Runic_Brick"
    },
    {
      "x": 0,
      "y": 20,
      "z": -2,
      "name": "Rock_Runic_Brick"
    },
    {
      "x": 0,
      "y": 21,
      "z": -2,
      "name": "Rock_Runic_Brick"
    },
    {
      "x": 0,
      "y": 22,
      "z": -2,
      "name": "Rock_Runic_Brick"
    },
    {
      "x": 0,
      "y": 23,
      "z": -2,
      "name": "Rock_Runic_Brick"
    },
    {
      "x": 0,
      "y": 24,
      "z": -2,
      "name": "Rock_Runic_Brick"
    },
    {
      "x": 0,
      "y": 25,
      "z": -2,
      "name": "Rock_Runic_Brick"
    },
    {
      "x": 0,
      "y": 26,
      "z": -2,
      "name": "Rock_Runic_Brick_Stairs",
      "rotation": 2
    },
    {
      "x": 0,
      "y": 27,
      "z": -2,
      "name": "Rock_Crystal_Cyan_Block",
      "rotation": 4
    },
    {
      "x": 0,
      "y": 28,
      "z": -2,
      "name": "Rock_Crystal_Cyan_Block",
      "rotation": 4
    },
    {
      "x": 0,
      "y": 29,
      "z": -2,
      "name": "Rock_Crystal_Cyan_Block",
      "rotation": 4
    },
    {
      "x": 0,
      "y": 30,
      "z": -2,
      "name": "Rock_Runic_Brick"
    },
    {
      "x": 0,
      "y": 31,
      "z": -2,
      "name": "Rock_Runic_Brick"
    },
    {
      "x": 0,
      "y": 32,
      "z": -2,
      "name": "Rock_Runic_Brick_Stairs",
      "rotation": 2
    },
    {
      "x": 0,
      "y": 0,
      "z": -1,
      "name": "Rock_Runic_Brick"
    },
    {
      "x": 0,
      "y": 1,
      "z": -1,
      "name": "Rock_Runic_Brick"
    },
    {
      "x": 0,
      "y": 2,
      "z": -1,
      "name": "Soil_Hive_Corrupted"
    },
    {
      "x": 0,
      "y": 7,
      "z": -1,
      "name": "Rock_Runic_Brick_Stairs",
      "rotation": 9
    },
    {
      "x": 0,
      "y": 8,
      "z": -1,
      "name": "Rock_Runic_Brick_Stairs",
      "rotation": 1
    },
    {
      "x": 0,
      "y": 15,
      "z": -1,
      "name": "Rock_Runic_Brick_Stairs",
      "rotation": 9
    },
    {
      "x": 0,
      "y": 16,
      "z": -1,
      "name": "Rock_Runic_Brick_Stairs",
      "rotation": 1
    },
    {
      "x": 0,
      "y": 17,
      "z": -1,
      "name": "Plant_Vine_Wall",
      "support": 15
    },
    {
      "x": 0,
      "y": 18,
      "z": -1,
      "name": "Plant_Vine",
      "support": 15
    },
    {
      "x": 0,
      "y": 19,
      "z": -1,
      "name": "Rock_Runic_Brick_Stairs",
      "rotation": 9
    },
    {
      "x": 0,
      "y": 20,
      "z": -1,
      "name": "Rock_Runic_Brick_Stairs",
      "rotation": 1
    },
    {
      "x": 0,
      "y": 21,
      "z": -1,
      "name": "Plant_Vine",
      "support": 15
    },
    {
      "x": 0,
      "y": 22,
      "z": -1,
      "name": "Plant_Vine",
      "support": 15
    },
    {
      "x": 0,
      "y": 23,
      "z": -1,
      "name": "Plant_Vine",
      "support": 15
    },
    {
      "x": 0,
      "y": 24,
      "z": -1,
      "name": "Plant_Vine_Wall",
      "support": 15
    },
    {
      "x": 0,
      "y": 25,
      "z": -1,
      "name": "Plant_Vine_Wall",
      "support": 15
    },
    {
      "x": 0,
      "y": 26,
      "z": -1,
      "name": "Rock_Crystal_Cyan_Block"
    },
    {
      "x": 0,
      "y": 27,
      "z": -1,
      "name": "Rock_Crystal_Cyan_Block"
    },
    {
      "x": 0,
      "y": 28,
      "z": -1,
      "name": "Rock_Runic_Brick"
    },
    {
      "x": 0,
      "y": 29,
      "z": -1,
      "name": "Rock_Runic_Brick"
    },
    {
      "x": 0,
      "y": 30,
      "z": -1,
      "name": "Rock_Runic_Brick"
    },
    {
      "x": 0,
      "y": 31,
      "z": -1,
      "name": "Rock_Runic_Brick"
    },
    {
      "x": 0,
      "y": 32,
      "z": -1,
      "name": "Rock_Runic_Brick"
    },
    {
      "x": 0,
      "y": 0,
      "z": 0,
      "name": "Rock_Runic_Brick"
    },
    {
      "x": 0,
      "y": 1,
      "z": 0,
      "name": "Rock_Runic_Brick"
    },
    {
      "x": 0,
      "y": 2,
      "z": 0,
      "name": "Soil_Hive_Corrupted_Brick_Smooth"
    },
    {
      "x": 0,
      "y": 22,
      "z": 0,
      "name": "Deco_Iron_Bars_Platforms"
    },
    {
      "x": 0,
      "y": 27,
      "z": 0,
      "name": "Rock_Crystal_Cyan_Block"
    },
    {
      "x": 0,
      "y": 28,
      "z": 0,
      "name": "Rock_Runic_Brick"
    },
    {
      "x": 0,
      "y": 29,
      "z": 0,
      "name": "Rock_Runic_Brick"
    },
    {
      "x": 0,
      "y": 30,
      "z": 0,
      "name": "Rock_Runic_Brick"
    },
    {
      "x": 0,
      "y": 31,
      "z": 0,
      "name": "Rock_Runic_Brick"
    },
    {
      "x": 0,
      "y": 32,
      "z": 0,
      "name": "Rock_Runic_Brick"
    },
    {
      "x": 0,
      "y": 0,
      "z": 1,
      "name": "Rock_Runic_Brick"
    },
    {
      "x": 0,
      "y": 1,
      "z": 1,
      "name": "Rock_Runic_Brick"
    },
    {
      "x": 0,
      "y": 2,
      "z": 1,
      "name": "Soil_Hive_Corrupted_Brick_Smooth"
    },
    {
      "x": 0,
      "y": 5,
      "z": 1,
      "name": "Rock_Runic_Brick_Stairs",
      "rotation": 11
    },
    {
      "x": 0,
      "y": 6,
      "z": 1,
      "name": "Rock_Runic_Brick_Stairs",
      "rotation": 3
    },
    {
      "x": 0,
      "y": 9,
      "z": 1,
      "name": "Rock_Runic_Brick_Stairs",
      "rotation": 11
    },
    {
      "x": 0,
      "y": 10,
      "z": 1,
      "name": "Rock_Runic_Brick_Stairs",
      "rotation": 3
    },
    {
      "x": 0,
      "y": 13,
      "z": 1,
      "name": "Rock_Runic_Brick_Stairs",
      "rotation": 11
    },
    {
      "x": 0,
      "y": 14,
      "z": 1,
      "name": "Rock_Runic_Brick_Stairs",
      "rotation": 3
    },
    {
      "x": 0,
      "y": 17,
      "z": 1,
      "name": "Rock_Runic_Brick_Stairs",
      "rotation": 11
    },
    {
      "x": 0,
      "y": 18,
      "z": 1,
      "name": "Rock_Runic_Brick_Stairs",
      "rotation": 3
    },
    {
      "x": 0,
      "y": 19,
      "z": 1,
      "name": "Plant_Vine_Wall",
      "support": 15,
      "rotation": 2
    },
    {
      "x": 0,
      "y": 20,
      "z": 1,
      "name": "Plant_Vine",
      "support": 15,
      "rotation": 2
    },
    {
      "x": 0,
      "y": 21,
      "z": 1,
      "name": "Plant_Vine_Wall",
      "support": 15,
      "rotation": 2
    },
    {
      "x": 0,
      "y": 22,
      "z": 1,
      "name": "Deco_Iron_Bars_Platforms"
    },
    {
      "x": 0,
      "y": 25,
      "z": 1,
      "name": "Rock_Runic_Brick"
    },
    {
      "x": 0,
      "y": 26,
      "z": 1,
      "name": "Rock_Runic_Brick"
    },
    {
      "x": 0,
      "y": 27,
      "z": 1,
      "name": "Rock_Runic_Brick"
    },
    {
      "x": 0,
      "y": 28,
      "z": 1,
      "name": "Rock_Runic_Brick"
    },
    {
      "x": 0,
      "y": 29,
      "z": 1,
      "name": "Rock_Runic_Brick"
    },
    {
      "x": 0,
      "y": 30,
      "z": 1,
      "name": "Rock_Runic_Brick"
    },
    {
      "x": 0,
      "y": 31,
      "z": 1,
      "name": "Rock_Runic_Brick"
    },
    {
      "x": 0,
      "y": 32,
      "z": 1,
      "name": "Rock_Runic_Brick"
    },
    {
      "x": 0,
      "y": 0,
      "z": 2,
      "name": "Rock_Runic_Brick"
    },
    {
      "x": 0,
      "y": 1,
      "z": 2,
      "name": "Rock_Runic_Brick"
    },
    {
      "x": 0,
      "y": 2,
      "z": 2,
      "name": "Rock_Runic_Brick"
    },
    {
      "x": 0,
      "y": 3,
      "z": 2,
      "name": "Rock_Runic_Brick"
    },
    {
      "x": 0,
      "y": 4,
      "z": 2,
      "name": "Rock_Runic_Brick_Stairs"
    },
    {
      "x": 0,
      "y": 5,
      "z": 2,
      "name": "Rock_Runic_Brick"
    },
    {
      "x": 0,
      "y": 6,
      "z": 2,
      "name": "Rock_Runic_Brick"
    },
    {
      "x": 0,
      "y": 7,
      "z": 2,
      "name": "Rock_Runic_Brick"
    },
    {
      "x": 0,
      "y": 8,
      "z": 2,
      "name": "Rock_Runic_Brick"
    },
    {
      "x": 0,
      "y": 9,
      "z": 2,
      "name": "Rock_Runic_Brick"
    },
    {
      "x": 0,
      "y": 10,
      "z": 2,
      "name": "Rock_Runic_Brick"
    },
    {
      "x": 0,
      "y": 11,
      "z": 2,
      "name": "Rock_Runic_Brick"
    },
    {
      "x": 0,
      "y": 12,
      "z": 2,
      "name": "Rock_Runic_Brick"
    },
    {
      "x": 0,
      "y": 13,
      "z": 2,
      "name": "Rock_Runic_Brick"
    },
    {
      "x": 0,
      "y": 14,
      "z": 2,
      "name": "Rock_Runic_Brick"
    },
    {
      "x": 0,
      "y": 15,
      "z": 2,
      "name": "Rock_Runic_Brick"
    },
    {
      "x": 0,
      "y": 16,
      "z": 2,
      "name": "Rock_Runic_Brick"
    },
    {
      "x": 0,
      "y": 17,
      "z": 2,
      "name": "Rock_Runic_Brick"
    },
    {
      "x": 0,
      "y": 18,
      "z": 2,
      "name": "Rock_Runic_Brick"
    },
    {
      "x": 0,
      "y": 19,
      "z": 2,
      "name": "Rock_Runic_Brick"
    },
    {
      "x": 0,
      "y": 20,
      "z": 2,
      "name": "Rock_Runic_Brick"
    },
    {
      "x": 0,
      "y": 21,
      "z": 2,
      "name": "Rock_Runic_Brick"
    },
    {
      "x": 0,
      "y": 22,
      "z": 2,
      "name": "Rock_Runic_Brick"
    },
    {
      "x": 0,
      "y": 23,
      "z": 2,
      "name": "Rock_Runic_Brick"
    },
    {
      "x": 0,
      "y": 24,
      "z": 2,
      "name": "Rock_Runic_Brick_Stairs",
      "rotation": 11
    },
    {
      "x": 0,
      "y": 25,
      "z": 2,
      "name": "Rock_Runic_Brick"
    },
    {
      "x": 0,
      "y": 26,
      "z": 2,
      "name": "Rock_Runic_Brick"
    },
    {
      "x": 0,
      "y": 27,
      "z": 2,
      "name": "Rock_Crystal_Cyan_Block",
      "rotation": 4
    },
    {
      "x": 0,
      "y": 28,
      "z": 2,
      "name": "Rock_Crystal_Cyan_Block",
      "rotation": 4
    },
    {
      "x": 0,
      "y": 29,
      "z": 2,
      "name": "Rock_Crystal_Cyan_Block",
      "rotation": 4
    },
    {
      "x": 0,
      "y": 30,
      "z": 2,
      "name": "Rock_Runic_Brick"
    },
    {
      "x": 0,
      "y": 31,
      "z": 2,
      "name": "Rock_Runic_Brick"
    },
    {
      "x": 0,
      "y": 32,
      "z": 2,
      "name": "Rock_Runic_Brick_Stairs"
    },
    {
      "x": 0,
      "y": 0,
      "z": 3,
      "name": "Plant_Vine",
      "support": 15
    },
    {
      "x": 0,
      "y": 1,
      "z": 3,
      "name": "Plant_Vine",
      "support": 15
    },
    {
      "x": 0,
      "y": 2,
      "z": 3,
      "name": "Plant_Vine",
      "support": 15
    },
    {
      "x": 0,
      "y": 3,
      "z": 3,
      "name": "Plant_Vine_Wall",
      "support": 15
    },
    {
      "x": 0,
      "y": 9,
      "z": 3,
      "name": "Rock_Runic_Brick_Half",
      "rotation": 8
    },
    {
      "x": 0,
      "y": 10,
      "z": 3,
      "name": "Rock_Runic_Brick"
    },
    {
      "x": 0,
      "y": 11,
      "z": 3,
      "name": "Rock_Runic_Brick"
    },
    {
      "x": 0,
      "y": 16,
      "z": 3,
      "name": "Rock_Runic_Brick"
    },
    {
      "x": 0,
      "y": 17,
      "z": 3,
      "name": "Rock_Runic_Brick"
    },
    {
      "x": 0,
      "y": 18,
      "z": 3,
      "name": "Rock_Runic_Brick"
    },
    {
      "x": 0,
      "y": 19,
      "z": 3,
      "name": "Rock_Runic_Brick_Half"
    },
    {
      "x": 0,
      "y": 20,
      "z": 3,
      "name": "Plant_Vine",
      "support": 15
    },
    {
      "x": 0,
      "y": 21,
      "z": 3,
      "name": "Plant_Vine_Wall",
      "support": 15
    },
    {
      "x": 0,
      "y": 22,
      "z": 3,
      "name": "Plant_Vine_Wall",
      "support": 15
    },
    {
      "x": 0,
      "y": 25,
      "z": 3,
      "name": "Plant_Vine_Wall",
      "support": 15
    },
    {
      "x": 0,
      "y": 26,
      "z": 3,
      "name": "Plant_Vine",
      "support": 15
    },
    {
      "x": 0,
      "y": 27,
      "z": 3,
      "name": "Plant_Vine_Wall",
      "support": 15
    },
    {
      "x": 0,
      "y": 10,
      "z": 4,
      "name": "Rock_Runic_Brick_Stairs",
      "rotation": 10
    },
    {
      "x": 0,
      "y": 11,
      "z": 4,
      "name": "Rock_Runic_Brick"
    },
    {
      "x": 0,
      "y": 12,
      "z": 4,
      "name": "Rock_Runic_Brick_Stairs"
    },
    {
      "x": 0,
      "y": 15,
      "z": 4,
      "name": "Rock_Runic_Brick_Stairs",
      "rotation": 10
    },
    {
      "x": 0,
      "y": 16,
      "z": 4,
      "name": "Rock_Runic_Brick"
    },
    {
      "x": 0,
      "y": 17,
      "z": 4,
      "name": "Rock_Runic_Brick"
    },
    {
      "x": 0,
      "y": 18,
      "z": 4,
      "name": "Rock_Runic_Brick_Stairs"
    },
    {
      "x": 1,
      "y": 0,
      "z": -3,
      "name": "Plant_Vine",
      "support": 15,
      "rotation": 2
    },
    {
      "x": 1,
      "y": 1,
      "z": -3,
      "name": "Plant_Vine",
      "support": 15,
      "rotation": 2
    },
    {
      "x": 1,
      "y": 2,
      "z": -3,
      "name": "Plant_Vine",
      "support": 15,
      "rotation": 2
    },
    {
      "x": 1,
      "y": 3,
      "z": -3,
      "name": "Plant_Vine_Wall",
      "support": 15,
      "rotation": 2
    },
    {
      "x": 1,
      "y": 4,
      "z": -3,
      "name": "Plant_Vine_Wall",
      "support": 15,
      "rotation": 2
    },
    {
      "x": 1,
      "y": 5,
      "z": -3,
      "name": "Plant_Vine_Wall",
      "support": 15,
      "rotation": 1
    },
    {
      "x": 1,
      "y": 8,
      "z": -3,
      "name": "Plant_Vine_Wall",
      "support": 15,
      "rotation": 2
    },
    {
      "x": 1,
      "y": 10,
      "z": -3,
      "name": "Plant_Vine_Wall",
      "support": 15,
      "rotation": 2
    },
    {
      "x": 1,
      "y": 11,
      "z": -3,
      "name": "Plant_Vine",
      "support": 15,
      "rotation": 2
    },
    {
      "x": 1,
      "y": 12,
      "z": -3,
      "name": "Plant_Vine_Wall",
      "support": 15,
      "rotation": 2
    },
    {
      "x": 1,
      "y": 13,
      "z": -3,
      "name": "Rock_Runic_Brick_Half",
      "rotation": 6
    },
    {
      "x": 1,
      "y": 14,
      "z": -3,
      "name": "Rock_Runic_Brick"
    },
    {
      "x": 1,
      "y": 15,
      "z": -3,
      "name": "Rock_Runic_Brick"
    },
    {
      "x": 1,
      "y": 16,
      "z": -3,
      "name": "Rock_Runic_Brick"
    },
    {
      "x": 1,
      "y": 17,
      "z": -3,
      "name": "Rock_Runic_Brick"
    },
    {
      "x": 1,
      "y": 18,
      "z": -3,
      "name": "Rock_Runic_Brick_Stairs",
      "rotation": 3
    },
    {
      "x": 1,
      "y": 21,
      "z": -3,
      "name": "Plant_Vine_Wall",
      "support": 15,
      "rotation": 2
    },
    {
      "x": 1,
      "y": 22,
      "z": -3,
      "name": "Plant_Vine",
      "support": 15,
      "rotation": 1
    },
    {
      "x": 1,
      "y": 28,
      "z": -3,
      "name": "Plant_Vine_Wall",
      "support": 15,
      "rotation": 2
    },
    {
      "x": 1,
      "y": 29,
      "z": -3,
      "name": "Plant_Vine",
      "support": 15,
      "rotation": 2
    },
    {
      "x": 1,
      "y": 30,
      "z": -3,
      "name": "Plant_Vine_Wall",
      "support": 15,
      "rotation": 2
    },
    {
      "x": 1,
      "y": 0,
      "z": -2,
      "name": "Rock_Runic_Brick"
    },
    {
      "x": 1,
      "y": 1,
      "z": -2,
      "name": "Rock_Runic_Brick"
    },
    {
      "x": 1,
      "y": 2,
      "z": -2,
      "name": "Rock_Runic_Brick"
    },
    {
      "x": 1,
      "y": 3,
      "z": -2,
      "name": "Rock_Runic_Brick"
    },
    {
      "x": 1,
      "y": 4,
      "z": -2,
      "name": "Rock_Runic_Brick_Stairs"
    },
    {
      "x": 1,
      "y": 5,
      "z": -2,
      "name": "Rock_Runic_Brick"
    },
    {
      "x": 1,
      "y": 6,
      "z": -2,
      "name": "Rock_Runic_Brick"
    },
    {
      "x": 1,
      "y": 7,
      "z": -2,
      "name": "Rock_Runic_Brick_Stairs",
      "rotation": 2
    },
    {
      "x": 1,
      "y": 8,
      "z": -2,
      "name": "Rock_Runic_Brick"
    },
    {
      "x": 1,
      "y": 9,
      "z": -2,
      "name": "Rock_Runic_Brick_Stairs"
    },
    {
      "x": 1,
      "y": 10,
      "z": -2,
      "name": "Rock_Runic_Brick"
    },
    {
      "x": 1,
      "y": 11,
      "z": -2,
      "name": "Rock_Runic_Brick"
    },
    {
      "x": 1,
      "y": 12,
      "z": -2,
      "name": "Rock_Runic_Brick"
    },
    {
      "x": 1,
      "y": 13,
      "z": -2,
      "name": "Rock_Runic_Brick"
    },
    {
      "x": 1,
      "y": 14,
      "z": -2,
      "name": "Rock_Runic_Brick"
    },
    {
      "x": 1,
      "y": 16,
      "z": -2,
      "name": "Plant_Vine_Wall",
      "support": 15
    },
    {
      "x": 1,
      "y": 18,
      "z": -2,
      "name": "Rock_Runic_Brick"
    },
    {
      "x": 1,
      "y": 19,
      "z": -2,
      "name": "Rock_Runic_Brick"
    },
    {
      "x": 1,
      "y": 20,
      "z": -2,
      "name": "Rock_Runic_Brick"
    },
    {
      "x": 1,
      "y": 21,
      "z": -2,
      "name": "Rock_Runic_Brick"
    },
    {
      "x": 1,
      "y": 22,
      "z": -2,
      "name": "Rock_Runic_Brick"
    },
    {
      "x": 1,
      "y": 23,
      "z": -2,
      "name": "Rock_Runic_Brick"
    },
    {
      "x": 1,
      "y": 24,
      "z": -2,
      "name": "Rock_Runic_Brick"
    },
    {
      "x": 1,
      "y": 25,
      "z": -2,
      "name": "Rock_Runic_Brick"
    },
    {
      "x": 1,
      "y": 26,
      "z": -2,
      "name": "Rock_Runic_Brick"
    },
    {
      "x": 1,
      "y": 27,
      "z": -2,
      "name": "Rock_Runic_Brick_Ornate"
    },
    {
      "x": 1,
      "y": 28,
      "z": -2,
      "name": "Rock_Crystal_Cyan_Block",
      "rotation": 4
    },
    {
      "x": 1,
      "y": 29,
      "z": -2,
      "name": "Rock_Runic_Brick"
    },
    {
      "x": 1,
      "y": 30,
      "z": -2,
      "name": "Rock_Runic_Brick"
    },
    {
      "x": 1,
      "y": 31,
      "z": -2,
      "name": "Rock_Runic_Brick_Stairs",
      "rotation": 1
    },
    {
      "x": 1,
      "y": 0,
      "z": -1,
      "name": "Rock_Runic_Brick"
    },
    {
      "x": 1,
      "y": 1,
      "z": -1,
      "name": "Rock_Runic_Brick"
    },
    {
      "x": 1,
      "y": 2,
      "z": -1,
      "name": "Soil_Hive_Corrupted"
    },
    {
      "x": 1,
      "y": 3,
      "z": -1,
      "name": "Rock_Runic_Brick"
    },
    {
      "x": 1,
      "y": 7,
      "z": -1,
      "name": "Rock_Runic_Brick"
    },
    {
      "x": 1,
      "y": 14,
      "z": -1,
      "name": "Rock_Runic_Brick_Half",
      "rotation": 8
    },
    {
      "x": 1,
      "y": 19,
      "z": -1,
      "name": "Rock_Runic_Brick"
    },
    {
      "x": 1,
      "y": 20,
      "z": -1,
      "name": "Plant_Vine",
      "support": 15
    },
    {
      "x": 1,
      "y": 21,
      "z": -1,
      "name": "Plant_Vine_Wall",
      "support": 15,
      "rotation": 3
    },
    {
      "x": 1,
      "y": 22,
      "z": -1,
      "name": "Plant_Vine_Wall",
      "support": 15
    },
    {
      "x": 1,
      "y": 23,
      "z": -1,
      "name": "Plant_Vine_Wall",
      "support": 15,
      "rotation": 3
    },
    {
      "x": 1,
      "y": 24,
      "z": -1,
      "name": "Plant_Vine_Wall",
      "support": 15
    },
    {
      "x": 1,
      "y": 25,
      "z": -1,
      "name": "Rock_Crystal_Cyan_Block"
    },
    {
      "x": 1,
      "y": 26,
      "z": -1,
      "name": "Rock_Crystal_Cyan_Block"
    },
    {
      "x": 1,
      "y": 27,
      "z": -1,
      "name": "Rock_Crystal_Cyan_Block",
      "rotation": 5
    },
    {
      "x": 1,
      "y": 28,
      "z": -1,
      "name": "Rock_Runic_Brick"
    },
    {
      "x": 1,
      "y": 29,
      "z": -1,
      "name": "Rock_Runic_Brick"
    },
    {
      "x": 1,
      "y": 30,
      "z": -1,
      "name": "Rock_Runic_Brick"
    },
    {
      "x": 1,
      "y": 31,
      "z": -1,
      "name": "Rock_Runic_Brick"
    },
    {
      "x": 1,
      "y": 32,
      "z": -1,
      "name": "Rock_Runic_Brick_Half"
    },
    {
      "x": 1,
      "y": 0,
      "z": 0,
      "name": "Rock_Runic_Brick"
    },
    {
      "x": 1,
      "y": 1,
      "z": 0,
      "name": "Rock_Runic_Brick"
    },
    {
      "x": 1,
      "y": 2,
      "z": 0,
      "name": "Soil_Hive_Corrupted"
    },
    {
      "x": 1,
      "y": 3,
      "z": 0,
      "name": "Rock_Runic_Brick_Stairs"
    },
    {
      "x": 1,
      "y": 6,
      "z": 0,
      "name": "Rock_Runic_Brick_Stairs",
      "rotation": 8
    },
    {
      "x": 1,
      "y": 7,
      "z": 0,
      "name": "Rock_Runic_Brick_Stairs"
    },
    {
      "x": 1,
      "y": 14,
      "z": 0,
      "name": "Rock_Runic_Brick_Stairs",
      "rotation": 8
    },
    {
      "x": 1,
      "y": 18,
      "z": 0,
      "name": "Rock_Runic_Brick_Stairs",
      "rotation": 8
    },
    {
      "x": 1,
      "y": 19,
      "z": 0,
      "name": "Rock_Runic_Brick_Stairs"
    },
    {
      "x": 1,
      "y": 20,
      "z": 0,
      "name": "Plant_Vine",
      "support": 15,
      "rotation": 3
    },
    {
      "x": 1,
      "y": 21,
      "z": 0,
      "name": "Plant_Vine_Wall",
      "support": 15,
      "rotation": 3
    },
    {
      "x": 1,
      "y": 22,
      "z": 0,
      "name": "Deco_Iron_Bars_Platforms"
    },
    {
      "x": 1,
      "y": 27,
      "z": 0,
      "name": "Rock_Crystal_Cyan_Block"
    },
    {
      "x": 1,
      "y": 28,
      "z": 0,
      "name": "Rock_Runic_Brick"
    },
    {
      "x": 1,
      "y": 29,
      "z": 0,
      "name": "Rock_Runic_Brick"
    },
    {
      "x": 1,
      "y": 30,
      "z": 0,
      "name": "Rock_Runic_Brick"
    },
    {
      "x": 1,
      "y": 31,
      "z": 0,
      "name": "Rock_Runic_Brick"
    },
    {
      "x": 1,
      "y": 32,
      "z": 0,
      "name": "Rock_Runic_Brick"
    },
    {
      "x": 1,
      "y": 0,
      "z": 1,
      "name": "Rock_Runic_Brick"
    },
    {
      "x": 1,
      "y": 1,
      "z": 1,
      "name": "Rock_Runic_Brick"
    },
    {
      "x": 1,
      "y": 2,
      "z": 1,
      "name": "Soil_Hive_Corrupted"
    },
    {
      "x": 1,
      "y": 6,
      "z": 1,
      "name": "Rock_Runic_Brick"
    },
    {
      "x": 1,
      "y": 10,
      "z": 1,
      "name": "Rock_Runic_Brick"
    },
    {
      "x": 1,
      "y": 14,
      "z": 1,
      "name": "Rock_Runic_Brick"
    },
    {
      "x": 1,
      "y": 18,
      "z": 1,
      "name": "Rock_Runic_Brick"
    },
    {
      "x": 1,
      "y": 20,
      "z": 1,
      "name": "Plant_Vine_Wall",
      "support": 15,
      "rotation": 3
    },
    {
      "x": 1,
      "y": 21,
      "z": 1,
      "name": "Plant_Vine_Wall",
      "support": 15,
      "rotation": 2
    },
    {
      "x": 1,
      "y": 22,
      "z": 1,
      "name": "Deco_Iron_Bars_Platforms"
    },
    {
      "x": 1,
      "y": 25,
      "z": 1,
      "name": "Rock_Runic_Brick"
    },
    {
      "x": 1,
      "y": 26,
      "z": 1,
      "name": "Rock_Runic_Brick"
    },
    {
      "x": 1,
      "y": 27,
      "z": 1,
      "name": "Rock_Runic_Brick"
    },
    {
      "x": 1,
      "y": 28,
      "z": 1,
      "name": "*Furniture_Tavern_Chest_Small_State_Definitions_CloseWindow",
      "components": {
        "Components": {
          "PlacedByInteraction": {
            "WhoPlacedUuid": {
              "$binary": "1D6Z0/5hSoOPtypqdFwK+g==",
              "$type": "04"
            }
          },
          "container": {
            "Position": {
              "X": 15,
              "Y": 150,
              "Z": 17
            },
            "Custom": false,
            "AllowViewing": true,
            "ItemContainer": {
              "Capacity": 18,
              "Items": {}
            }
          }
        }
      },
      "rotation": 1
    },
    {
      "x": 1,
      "y": 29,
      "z": 1,
      "name": "Rock_Runic_Brick_Ornate"
    },
    {
      "x": 1,
      "y": 30,
      "z": 1,
      "name": "Rock_Runic_Brick"
    },
    {
      "x": 1,
      "y": 31,
      "z": 1,
      "name": "Rock_Runic_Brick"
    },
    {
      "x": 1,
      "y": 32,
      "z": 1,
      "name": "Rock_Runic_Brick_Half"
    },
    {
      "x": 1,
      "y": 0,
      "z": 2,
      "name": "Rock_Runic_Brick"
    },
    {
      "x": 1,
      "y": 1,
      "z": 2,
      "name": "Rock_Runic_Brick"
    },
    {
      "x": 1,
      "y": 2,
      "z": 2,
      "name": "Rock_Runic_Brick"
    },
    {
      "x": 1,
      "y": 3,
      "z": 2,
      "name": "Rock_Runic_Brick"
    },
    {
      "x": 1,
      "y": 4,
      "z": 2,
      "name": "Rock_Runic_Brick"
    },
    {
      "x": 1,
      "y": 5,
      "z": 2,
      "name": "Rock_Runic_Brick"
    },
    {
      "x": 1,
      "y": 6,
      "z": 2,
      "name": "Rock_Runic_Brick"
    },
    {
      "x": 1,
      "y": 7,
      "z": 2,
      "name": "Rock_Runic_Brick"
    },
    {
      "x": 1,
      "y": 8,
      "z": 2,
      "name": "Rock_Runic_Brick"
    },
    {
      "x": 1,
      "y": 9,
      "z": 2,
      "name": "Rock_Runic_Brick"
    },
    {
      "x": 1,
      "y": 10,
      "z": 2,
      "name": "Rock_Runic_Brick"
    },
    {
      "x": 1,
      "y": 11,
      "z": 2,
      "name": "Rock_Runic_Brick"
    },
    {
      "x": 1,
      "y": 12,
      "z": 2,
      "name": "Rock_Runic_Brick"
    },
    {
      "x": 1,
      "y": 13,
      "z": 2,
      "name": "Rock_Runic_Brick"
    },
    {
      "x": 1,
      "y": 14,
      "z": 2,
      "name": "Rock_Runic_Brick"
    },
    {
      "x": 1,
      "y": 15,
      "z": 2,
      "name": "Rock_Runic_Brick"
    },
    {
      "x": 1,
      "y": 16,
      "z": 2,
      "name": "Rock_Runic_Brick"
    },
    {
      "x": 1,
      "y": 17,
      "z": 2,
      "name": "Rock_Runic_Brick"
    },
    {
      "x": 1,
      "y": 18,
      "z": 2,
      "name": "Rock_Runic_Brick"
    },
    {
      "x": 1,
      "y": 19,
      "z": 2,
      "name": "Rock_Runic_Brick"
    },
    {
      "x": 1,
      "y": 20,
      "z": 2,
      "name": "Rock_Runic_Brick"
    },
    {
      "x": 1,
      "y": 21,
      "z": 2,
      "name": "Rock_Runic_Brick"
    },
    {
      "x": 1,
      "y": 22,
      "z": 2,
      "name": "Rock_Runic_Brick"
    },
    {
      "x": 1,
      "y": 23,
      "z": 2,
      "name": "Rock_Runic_Brick"
    },
    {
      "x": 1,
      "y": 24,
      "z": 2,
      "name": "Rock_Runic_Brick_Stairs"
    },
    {
      "x": 1,
      "y": 25,
      "z": 2,
      "name": "Rock_Runic_Brick"
    },
    {
      "x": 1,
      "y": 26,
      "z": 2,
      "name": "Rock_Runic_Brick"
    },
    {
      "x": 1,
      "y": 27,
      "z": 2,
      "name": "Rock_Runic_Brick"
    },
    {
      "x": 1,
      "y": 28,
      "z": 2,
      "name": "Rock_Crystal_Cyan_Block",
      "rotation": 4
    },
    {
      "x": 1,
      "y": 29,
      "z": 2,
      "name": "Rock_Runic_Brick"
    },
    {
      "x": 1,
      "y": 30,
      "z": 2,
      "name": "Rock_Runic_Brick"
    },
    {
      "x": 1,
      "y": 31,
      "z": 2,
      "name": "Rock_Runic_Brick_Stairs",
      "rotation": 1
    },
    {
      "x": 1,
      "y": 0,
      "z": 3,
      "name": "Plant_Vine",
      "support": 15
    },
    {
      "x": 1,
      "y": 1,
      "z": 3,
      "name": "Rock_Runic_Brick_Half",
      "rotation": 4
    },
    {
      "x": 1,
      "y": 2,
      "z": 3,
      "name": "Rock_Runic_Brick"
    },
    {
      "x": 1,
      "y": 3,
      "z": 3,
      "name": "Rock_Runic_Brick"
    },
    {
      "x": 1,
      "y": 4,
      "z": 3,
      "name": "Rock_Runic_Brick"
    },
    {
      "x": 1,
      "y": 5,
      "z": 3,
      "name": "Rock_Runic_Brick"
    },
    {
      "x": 1,
      "y": 6,
      "z": 3,
      "name": "*Rock_Runic_Brick_Stairs_State_Definitions_Corner_Left",
      "rotation": 3
    },
    {
      "x": 1,
      "y": 9,
      "z": 3,
      "name": "Plant_Vine_Wall",
      "support": 15
    },
    {
      "x": 1,
      "y": 10,
      "z": 3,
      "name": "Rock_Runic_Brick_Stairs",
      "rotation": 11
    },
    {
      "x": 1,
      "y": 11,
      "z": 3,
      "name": "Rock_Runic_Brick"
    },
    {
      "x": 1,
      "y": 12,
      "z": 3,
      "name": "Rock_Runic_Brick"
    },
    {
      "x": 1,
      "y": 13,
      "z": 3,
      "name": "Rock_Runic_Brick"
    },
    {
      "x": 1,
      "y": 14,
      "z": 3,
      "name": "Rock_Runic_Brick"
    },
    {
      "x": 1,
      "y": 15,
      "z": 3,
      "name": "Rock_Runic_Brick"
    },
    {
      "x": 1,
      "y": 16,
      "z": 3,
      "name": "Rock_Runic_Brick"
    },
    {
      "x": 1,
      "y": 17,
      "z": 3,
      "name": "Rock_Runic_Brick"
    },
    {
      "x": 1,
      "y": 18,
      "z": 3,
      "name": "Rock_Runic_Brick_Stairs"
    },
    {
      "x": 1,
      "y": 19,
      "z": 3,
      "name": "Plant_Vine",
      "support": 15
    },
    {
      "x": 1,
      "y": 20,
      "z": 3,
      "name": "Plant_Vine_Wall",
      "support": 15
    },
    {
      "x": 1,
      "y": 21,
      "z": 3,
      "name": "Plant_Vine_Wall",
      "support": 15
    },
    {
      "x": 1,
      "y": 25,
      "z": 3,
      "name": "Plant_Vine_Wall",
      "support": 15
    },
    {
      "x": 1,
      "y": 26,
      "z": 3,
      "name": "Plant_Vine",
      "support": 15
    },
    {
      "x": 1,
      "y": 27,
      "z": 3,
      "name": "Plant_Vine_Wall",
      "support": 15
    },
    {
      "x": 1,
      "y": 10,
      "z": 4,
      "name": "Rock_Runic_Brick_Half",
      "rotation": 8
    },
    {
      "x": 1,
      "y": 11,
      "z": 4,
      "name": "Rock_Runic_Brick"
    },
    {
      "x": 1,
      "y": 12,
      "z": 4,
      "name": "Rock_Runic_Brick"
    },
    {
      "x": 1,
      "y": 13,
      "z": 4,
      "name": "Rock_Runic_Brick"
    },
    {
      "x": 1,
      "y": 14,
      "z": 4,
      "name": "Rock_Runic_Brick"
    },
    {
      "x": 1,
      "y": 15,
      "z": 4,
      "name": "Rock_Runic_Brick"
    },
    {
      "x": 1,
      "y": 16,
      "z": 4,
      "name": "Rock_Runic_Brick"
    },
    {
      "x": 1,
      "y": 17,
      "z": 4,
      "name": "Rock_Runic_Brick_Stairs"
    },
    {
      "x": 1,
      "y": 12,
      "z": 5,
      "name": "Plant_Vine_Wall",
      "support": 15
    },
    {
      "x": 1,
      "y": 13,
      "z": 5,
      "name": "Plant_Vine",
      "support": 15
    },
    {
      "x": 1,
      "y": 14,
      "z": 5,
      "name": "Plant_Vine",
      "support": 15
    },
    {
      "x": 1,
      "y": 15,
      "z": 5,
      "name": "Plant_Vine_Wall",
      "support": 15
    },
    {
      "x": 2,
      "y": 1,
      "z": -4,
      "name": "Plant_Vine_Wall",
      "support": 15,
      "rotation": 2
    },
    {
      "x": 2,
      "y": 2,
      "z": -4,
      "name": "Plant_Vine",
      "support": 15,
      "rotation": 2
    },
    {
      "x": 2,
      "y": 3,
      "z": -4,
      "name": "Plant_Vine_Wall",
      "support": 15,
      "rotation": 2
    },
    {
      "x": 2,
      "y": 0,
      "z": -3,
      "name": "Rock_Runic_Brick"
    },
    {
      "x": 2,
      "y": 1,
      "z": -3,
      "name": "Rock_Runic_Brick"
    },
    {
      "x": 2,
      "y": 2,
      "z": -3,
      "name": "Rock_Runic_Brick"
    },
    {
      "x": 2,
      "y": 3,
      "z": -3,
      "name": "Rock_Runic_Brick"
    },
    {
      "x": 2,
      "y": 4,
      "z": -3,
      "name": "Rock_Runic_Brick"
    },
    {
      "x": 2,
      "y": 5,
      "z": -3,
      "name": "Rock_Runic_Brick_Stairs",
      "rotation": 2
    },
    {
      "x": 2,
      "y": 6,
      "z": -3,
      "name": "Plant_Vine",
      "support": 15,
      "rotation": 2
    },
    {
      "x": 2,
      "y": 10,
      "z": -3,
      "name": "Plant_Vine_Wall",
      "support": 15,
      "rotation": 2
    },
    {
      "x": 2,
      "y": 13,
      "z": -3,
      "name": "Rock_Runic_Brick_Stairs",
      "rotation": 8
    },
    {
      "x": 2,
      "y": 14,
      "z": -3,
      "name": "Rock_Runic_Brick"
    },
    {
      "x": 2,
      "y": 15,
      "z": -3,
      "name": "Rock_Runic_Brick_Stairs",
      "rotation": 2
    },
    {
      "x": 2,
      "y": 17,
      "z": -3,
      "name": "Rock_Runic_Brick_Stairs",
      "rotation": 8
    },
    {
      "x": 2,
      "y": 18,
      "z": -3,
      "name": "Rock_Runic_Brick"
    },
    {
      "x": 2,
      "y": 19,
      "z": -3,
      "name": "Rock_Runic_Brick_Stairs",
      "rotation": 2
    },
    {
      "x": 2,
      "y": 20,
      "z": -3,
      "name": "Plant_Vine_Wall",
      "support": 15,
      "rotation": 2
    },
    {
      "x": 2,
      "y": 21,
      "z": -3,
      "name": "Plant_Vine",
      "support": 15,
      "rotation": 2
    },
    {
      "x": 2,
      "y": 22,
      "z": -3,
      "name": "Plant_Vine_Wall",
      "support": 15,
      "rotation": 2
    },
    {
      "x": 2,
      "y": 30,
      "z": -3,
      "name": "Plant_Vine",
      "support": 15,
      "rotation": 2
    },
    {
      "x": 2,
      "y": 0,
      "z": -2,
      "name": "Rock_Runic_Brick"
    },
    {
      "x": 2,
      "y": 1,
      "z": -2,
      "name": "Rock_Runic_Brick"
    },
    {
      "x": 2,
      "y": 2,
      "z": -2,
      "name": "Rock_Runic_Brick"
    },
    {
      "x": 2,
      "y": 3,
      "z": -2,
      "name": "Rock_Runic_Brick"
    },
    {
      "x": 2,
      "y": 4,
      "z": -2,
      "name": "Rock_Runic_Brick"
    },
    {
      "x": 2,
      "y": 5,
      "z": -2,
      "name": "Rock_Runic_Brick"
    },
    {
      "x": 2,
      "y": 6,
      "z": -2,
      "name": "Rock_Runic_Brick"
    },
    {
      "x": 2,
      "y": 7,
      "z": -2,
      "name": "Rock_Runic_Brick"
    },
    {
      "x": 2,
      "y": 8,
      "z": -2,
      "name": "Rock_Runic_Brick_Stairs",
      "rotation": 8
    },
    {
      "x": 2,
      "y": 9,
      "z": -2,
      "name": "Rock_Runic_Brick"
    },
    {
      "x": 2,
      "y": 10,
      "z": -2,
      "name": "Rock_Runic_Brick"
    },
    {
      "x": 2,
      "y": 11,
      "z": -2,
      "name": "Rock_Runic_Brick"
    },
    {
      "x": 2,
      "y": 12,
      "z": -2,
      "name": "Rock_Runic_Brick"
    },
    {
      "x": 2,
      "y": 13,
      "z": -2,
      "name": "Rock_Runic_Brick"
    },
    {
      "x": 2,
      "y": 14,
      "z": -2,
      "name": "Rock_Runic_Brick"
    },
    {
      "x": 2,
      "y": 18,
      "z": -2,
      "name": "Rock_Runic_Brick"
    },
    {
      "x": 2,
      "y": 19,
      "z": -2,
      "name": "Rock_Runic_Brick"
    },
    {
      "x": 2,
      "y": 20,
      "z": -2,
      "name": "Rock_Runic_Brick"
    },
    {
      "x": 2,
      "y": 21,
      "z": -2,
      "name": "Rock_Runic_Brick"
    },
    {
      "x": 2,
      "y": 22,
      "z": -2,
      "name": "Rock_Runic_Brick"
    },
    {
      "x": 2,
      "y": 23,
      "z": -2,
      "name": "Rock_Runic_Brick"
    },
    {
      "x": 2,
      "y": 24,
      "z": -2,
      "name": "Rock_Runic_Brick"
    },
    {
      "x": 2,
      "y": 25,
      "z": -2,
      "name": "Rock_Runic_Brick"
    },
    {
      "x": 2,
      "y": 26,
      "z": -2,
      "name": "Rock_Runic_Brick"
    },
    {
      "x": 2,
      "y": 27,
      "z": -2,
      "name": "Rock_Runic_Brick"
    },
    {
      "x": 2,
      "y": 28,
      "z": -2,
      "name": "Rock_Runic_Brick_Half",
      "rotation": 8
    },
    {
      "x": 2,
      "y": 29,
      "z": -2,
      "name": "Rock_Runic_Brick"
    },
    {
      "x": 2,
      "y": 30,
      "z": -2,
      "name": "Rock_Runic_Brick"
    },
    {
      "x": 2,
      "y": 0,
      "z": -1,
      "name": "Rock_Runic_Brick"
    },
    {
      "x": 2,
      "y": 1,
      "z": -1,
      "name": "Rock_Runic_Brick"
    },
    {
      "x": 2,
      "y": 2,
      "z": -1,
      "name": "Rock_Runic_Brick"
    },
    {
      "x": 2,
      "y": 3,
      "z": -1,
      "name": "Rock_Runic_Brick_Stairs",
      "rotation": 1
    },
    {
      "x": 2,
      "y": 4,
      "z": -1,
      "name": "Rock_Runic_Brick"
    },
    {
      "x": 2,
      "y": 5,
      "z": -1,
      "name": "Rock_Runic_Brick"
    },
    {
      "x": 2,
      "y": 6,
      "z": -1,
      "name": "Rock_Runic_Brick"
    },
    {
      "x": 2,
      "y": 7,
      "z": -1,
      "name": "Rock_Runic_Brick"
    },
    {
      "x": 2,
      "y": 8,
      "z": -1,
      "name": "Rock_Runic_Brick"
    },
    {
      "x": 2,
      "y": 9,
      "z": -1,
      "name": "Rock_Runic_Brick"
    },
    {
      "x": 2,
      "y": 10,
      "z": -1,
      "name": "Rock_Runic_Brick"
    },
    {
      "x": 2,
      "y": 11,
      "z": -1,
      "name": "Rock_Runic_Brick"
    },
    {
      "x": 2,
      "y": 12,
      "z": -1,
      "name": "Rock_Runic_Brick"
    },
    {
      "x": 2,
      "y": 13,
